File: raw_data/mechanical_tests_Instron_data/Cast_Skin_0035_2.is_tens_RawData/Specimen_RawData_1.csv
Dimension : Area,0.42000,cm^2

Time,Load,Extension,Tensile extension,Tensile strain,Tensile stress
(sec),(N),(mm),(mm),(mm/mm),(MPa)
0.00000,0.09127,0.00000,0.00000,0.00000,0.00217
0.04000,1.15409,0.06029,0.06029,0.00043,0.02748
0.08000,0.56196,0.26041,0.26041,0.00186,0.01338
0.12000,1.15614,0.59164,0.59164,0.00423,0.02753
0.16000,1.94404,0.98306,0.98306,0.00702,0.04629
0.20000,1.80155,1.39146,1.39146,0.00994,0.04289
0.24000,1.70171,1.80948,1.80948,0.01292,0.04052
0.28000,1.83415,2.23382,2.23382,0.01596,0.04367
0.32000,1.96435,2.65259,2.65259,0.01895,0.04677
0.36000,1.19675,3.00806,3.00806,0.02149,0.02849
0.40000,1.27144,3.33619,3.33619,0.02383,0.03027
0.44000,1.38395,3.67130,3.67130,0.02622,0.03295
0.48000,0.82478,4.00754,4.00754,0.02863,0.01964
0.52000,1.09859,4.34143,4.34143,0.03101,0.02616
0.56000,1.33067,4.67467,4.67467,0.03339,0.03168
0.60000,1.70060,5.00831,5.00831,0.03577,0.04049
0.64000,1.60914,5.34150,5.34150,0.03815,0.03831
0.68000,1.41319,5.67509,5.67509,0.04054,0.03365
0.72000,1.35489,6.00827,6.00827,0.04292,0.03226
0.76000,1.44001,6.34176,6.34176,0.04530,0.03429
0.80000,1.34725,6.67502,6.67502,0.04768,0.03208
0.84000,1.30218,7.00829,7.00829,0.05006,0.03100
0.88000,1.27926,7.34169,7.34169,0.05244,0.03046
0.92000,1.28634,7.67493,7.67493,0.05482,0.03063
0.96000,1.26939,8.00844,8.00844,0.05720,0.03022
1.00000,1.51452,8.34160,8.34160,0.05958,0.03606
1.04000,1.13267,8.67500,8.67500,0.06196,0.02697
1.08000,1.46553,9.00819,9.00819,0.06434,0.03489
1.12000,1.60746,9.34175,9.34175,0.06673,0.03827
1.16000,1.27051,9.67502,9.67502,0.06911,0.03025
1.20000,1.69724,10.00832,10.00832,0.07149,0.04041
1.24000,1.84700,10.34172,10.34172,0.07387,0.04398
1.28000,1.71084,10.67493,10.67493,0.07625,0.04073
1.32000,1.71848,11.00847,11.00847,0.07863,0.04092
1.36000,1.53165,11.34160,11.34160,0.08101,0.03647
1.40000,1.43610,11.67508,11.67508,0.08339,0.03419
1.44000,1.61584,12.00825,12.00825,0.08577,0.03847
1.48000,1.87326,12.34173,12.34173,0.08816,0.04460
1.52000,1.61231,12.67502,12.67502,0.09054,0.03839
1.56000,1.70562,13.00832,13.00832,0.09292,0.04061
1.60000,1.60616,13.34172,13.34172,0.09530,0.03824
1.64000,1.52867,13.67488,13.67488,0.09768,0.03640
1.68000,1.79633,14.00841,14.00841,0.10006,0.04277
1.72000,1.85631,14.34157,14.34157,0.10244,0.04420
1.76000,1.59517,14.67511,14.67511,0.10482,0.03798
1.80000,2.42889,15.00824,15.00824,0.10720,0.05783
1.84000,1.70786,15.34172,15.34172,0.10958,0.04066
1.88000,1.47559,15.67502,15.67502,0.11196,0.03513
1.92000,1.67582,16.00829,16.00829,0.11434,0.03990
1.96000,1.30516,16.34174,16.34174,0.11673,0.03108
2.00000,2.03159,16.67493,16.67493,0.11911,0.04837
2.04000,1.97906,17.00847,17.00846,0.12149,0.04712
2.08000,1.66949,17.34155,17.34155,0.12387,0.03975
2.12000,1.54972,17.67505,17.67505,0.12625,0.03690
2.16000,1.20085,18.00827,18.00827,0.12863,0.02859
2.20000,1.68439,18.34170,18.34170,0.13101,0.04010
2.24000,1.79410,18.67497,18.67497,0.13339,0.04272
2.28000,1.57729,19.00834,19.00834,0.13577,0.03755
2.32000,1.66930,19.34174,19.34174,0.13816,0.03975
2.36000,1.85464,19.67493,19.67493,0.14054,0.04416
2.40000,1.59629,20.00844,20.00844,0.14292,0.03801
2.44000,1.54525,20.34154,20.34154,0.14530,0.03679
2.48000,2.00588,20.67513,20.67513,0.14768,0.04776
2.52000,1.64304,21.00829,21.00829,0.15006,0.03912
2.56000,1.91443,21.34167,21.34167,0.15244,0.04558
2.60000,1.52290,21.67502,21.67502,0.15482,0.03626
2.64000,1.31205,22.00834,22.00834,0.15720,0.03124
2.68000,1.29435,22.34174,22.34174,0.15958,0.03082
2.72000,1.34110,22.67493,22.67493,0.16196,0.03193
2.76000,1.61175,23.00841,23.00841,0.16435,0.03837
2.80000,1.96733,23.34157,23.34157,0.16673,0.04684
2.84000,1.72742,23.67511,23.67511,0.16911,0.04113
2.88000,1.61603,24.00827,24.00827,0.17149,0.03848
2.92000,2.07722,24.34167,24.34167,0.17387,0.04946
2.96000,1.76448,24.67496,24.67496,0.17625,0.04201
3.00000,1.98931,25.00831,25.00831,0.17863,0.04736
3.04000,1.78888,25.34177,25.34177,0.18101,0.04259
3.08000,2.03773,25.67493,25.67493,0.18339,0.04852
3.12000,1.82763,26.00841,26.00841,0.18577,0.04351
3.16000,1.64639,26.34157,26.34157,0.18815,0.03920
3.20000,1.01179,26.67508,26.67508,0.19054,0.02409
3.24000,1.34744,27.00829,27.00829,0.19292,0.03208
3.28000,1.25002,27.34175,27.34175,0.19530,0.02976
3.32000,1.28560,27.67496,27.67496,0.19768,0.03061
3.36000,1.49626,28.00831,28.00831,0.20006,0.03563
3.40000,1.47261,28.34174,28.34174,0.20244,0.03506
3.44000,1.78628,28.67492,28.67492,0.20482,0.04253
3.48000,1.64267,29.00838,29.00838,0.20720,0.03911
3.52000,1.34129,29.34154,29.34154,0.20958,0.03194
3.56000,1.47279,29.67508,29.67508,0.21196,0.03507
3.60000,1.61491,30.00829,30.00829,0.21434,0.03845
3.64000,1.19135,30.34177,30.34177,0.21673,0.02837
3.68000,1.48453,30.67504,30.67504,0.21911,0.03535
3.72000,1.52662,31.00831,31.00831,0.22149,0.03635
3.76000,1.50148,31.34171,31.34171,0.22387,0.03575
3.80000,1.54767,31.67498,31.67498,0.22625,0.03685
3.84000,1.41989,32.00843,32.00843,0.22863,0.03381
3.88000,1.00639,32.34159,32.34159,0.23101,0.02396
3.92000,1.27573,32.67505,32.67505,0.23339,0.03037
3.96000,1.06785,33.00818,33.00818,0.23577,0.02543
4.00000,1.33719,33.34174,33.34174,0.23816,0.03184
4.04000,0.99670,33.67501,33.67501,0.24054,0.02373
4.08000,1.39177,34.00831,34.00830,0.24292,0.03314
4.12000,1.02855,34.34165,34.34165,0.24530,0.02449
4.16000,1.05388,34.67490,34.67490,0.24768,0.02509
4.20000,1.13584,35.00848,35.00848,0.25006,0.02704
4.24000,1.04029,35.34162,35.34162,0.25244,0.02477
4.28000,0.93374,35.67507,35.67507,0.25482,0.02223
4.32000,0.80764,36.00826,36.00826,0.25720,0.01923
4.36000,1.34632,36.34172,36.34172,0.25958,0.03206
4.40000,0.81211,36.67504,36.67504,0.26196,0.01934
4.44000,0.84899,37.00836,37.00836,0.26435,0.02021
4.48000,1.16918,37.34168,37.34167,0.26673,0.02784
4.52000,0.86073,37.67492,37.67492,0.26911,0.02049
4.56000,0.66087,38.00840,38.00840,0.27149,0.01573
4.60000,0.62417,38.34154,38.34154,0.27387,0.01486
4.64000,0.49528,38.67505,38.67505,0.27625,0.01179
4.68000,0.97509,39.00826,39.00826,0.27863,0.02322
4.72000,1.18725,39.34174,39.34174,0.28101,0.02827
4.76000,1.22134,39.67506,39.67507,0.28339,0.02908
4.80000,1.31372,40.00836,40.00836,0.28577,0.03128
4.84000,1.01589,40.34176,40.34175,0.28816,0.02419
4.88000,1.03787,40.67494,40.67495,0.29054,0.02471
4.92000,1.27759,41.00840,41.00840,0.29292,0.03042
4.96000,1.17291,41.34156,41.34156,0.29530,0.02793
5.00000,1.22506,41.67512,41.67512,0.29768,0.02917
5.04000,0.87395,42.00828,42.00828,0.30006,0.02081
5.08000,0.96895,42.34174,42.34174,0.30244,0.02307
5.12000,1.02054,42.67493,42.67493,0.30482,0.02430
5.16000,0.89817,43.00830,43.00831,0.30720,0.02138
5.20000,0.80001,43.34173,43.34174,0.30958,0.01905
5.24000,1.25524,43.67492,43.67492,0.31196,0.02989
5.28000,0.96634,44.00842,44.00842,0.31435,0.02301
5.32000,1.19768,44.34159,44.34158,0.31673,0.02852
5.36000,0.94920,44.67512,44.67512,0.31911,0.02260
5.40000,1.12262,45.00828,45.00828,0.32149,0.02673
5.44000,0.74804,45.34168,45.34168,0.32387,0.01781
5.48000,1.17626,45.67498,45.67498,0.32625,0.02801
5.52000,1.49682,46.00833,46.00832,0.32863,0.03564
5.56000,1.12467,46.34176,46.34176,0.33101,0.02678
5.60000,0.95442,46.67494,46.67495,0.33339,0.02272
5.64000,1.21724,47.00840,47.00840,0.33577,0.02898
5.68000,1.21966,47.34156,47.34156,0.33815,0.02904
5.72000,1.39344,47.67509,47.67509,0.34054,0.03318
5.76000,1.47410,48.00828,48.00828,0.34292,0.03510
5.80000,1.10473,48.34174,48.34174,0.34530,0.02630
5.84000,0.92890,48.67500,48.67500,0.34768,0.02212
5.88000,1.23624,49.00827,49.00827,0.35006,0.02943
5.92000,1.19545,49.34178,49.34178,0.35244,0.02846
5.96000,1.59480,49.67491,49.67492,0.35482,0.03797
6.00000,1.91107,50.00840,50.00840,0.35720,0.04550
6.04000,1.35005,50.34158,50.34159,0.35958,0.03214
6.08000,1.03433,50.67509,50.67509,0.36196,0.02463
6.12000,1.64006,51.00831,51.00830,0.36435,0.03905
6.16000,1.62832,51.34168,51.34168,0.36673,0.03877
6.20000,1.56760,51.67498,51.67498,0.36911,0.03732
6.24000,1.68663,52.00833,52.00833,0.37149,0.04016
6.28000,1.45379,52.34172,52.34172,0.37387,0.03461
6.32000,1.36141,52.67494,52.67494,0.37625,0.03241
6.36000,1.59889,53.00848,53.00848,0.37863,0.03807
6.40000,1.54600,53.34155,53.34155,0.38101,0.03681
6.44000,1.74567,53.67507,53.67506,0.38339,0.04156
6.48000,1.85128,54.00825,54.00826,0.38577,0.04408
6.52000,1.82372,54.34171,54.34171,0.38816,0.04342
6.56000,1.46274,54.67505,54.67506,0.39054,0.03483
6.60000,1.75908,55.00833,55.00833,0.39292,0.04188
6.64000,1.52774,55.34167,55.34167,0.39530,0.03637
6.68000,1.39307,55.67497,55.67496,0.39768,0.03317
6.72000,1.81440,56.00845,56.00845,0.40006,0.04320
6.76000,1.97086,56.34158,56.34158,0.40244,0.04693
6.80000,1.74381,56.67509,56.67509,0.40482,0.04152
6.84000,1.44225,57.00825,57.00825,0.40720,0.03434
6.88000,1.53854,57.34176,57.34176,0.40958,0.03663
6.92000,2.01203,57.67503,57.67503,0.41196,0.04791
6.96000,1.82930,58.00833,58.00832,0.41435,0.04355
7.00000,1.83228,58.34169,58.34169,0.41673,0.04363
7.04000,1.84886,58.67491,58.67491,0.41911,0.04402
7.08000,1.87363,59.00844,59.00845,0.42149,0.04461
7.12000,1.99564,59.34164,59.34164,0.42387,0.04752
7.16000,2.19457,59.67504,59.67504,0.42625,0.05225
7.20000,2.01967,60.00825,60.00825,0.42863,0.04809
7.24000,1.90567,60.34170,60.34171,0.43101,0.04537
7.28000,1.80714,60.67502,60.67502,0.43339,0.04303
7.32000,1.76746,61.00835,61.00835,0.43577,0.04208
7.36000,1.74567,61.34172,61.34172,0.43816,0.04156
7.40000,1.72686,61.67494,61.67494,0.44054,0.04112
7.44000,1.85482,62.00844,62.00845,0.44292,0.04416
7.48000,1.99396,62.34160,62.34161,0.44530,0.04748
7.52000,1.81068,62.67512,62.67512,0.44768,0.04311
7.56000,1.72704,63.00828,63.00828,0.45006,0.04112
7.60000,1.67023,63.34167,63.34167,0.45244,0.03977
7.64000,2.24076,63.67499,63.67500,0.45482,0.05335
7.68000,2.13478,64.00832,64.00832,0.45720,0.05083
7.72000,2.23108,64.34175,64.34175,0.45958,0.05312
7.76000,2.15769,64.67491,64.67491,0.46196,0.05137
7.80000,2.12230,65.00839,65.00839,0.46435,0.05053
7.84000,2.40952,65.34160,65.34161,0.46673,0.05737
7.88000,2.20463,65.67516,65.67516,0.46911,0.05249
7.92000,2.37059,66.00830,66.00830,0.47149,0.05644
7.96000,2.44156,66.34173,66.34173,0.47387,0.05813
8.00000,2.49259,66.67494,66.67494,0.47625,0.05935
8.04000,2.45795,67.00832,67.00832,0.47863,0.05852
8.08000,3.07020,67.34180,67.34180,0.48101,0.07310
8.12000,2.89753,67.67493,67.67493,0.48339,0.06899
8.16000,2.59317,68.00842,68.00842,0.48577,0.06174
8.20000,2.97260,68.34152,68.34152,0.48815,0.07078
8.24000,2.81408,68.67508,68.67508,0.49054,0.06700
8.28000,2.77217,69.00827,69.00827,0.49292,0.06600
8.32000,2.53841,69.34170,69.34170,0.49530,0.06044
8.36000,2.60789,69.67499,69.67500,0.49768,0.06209
8.40000,2.70642,70.00832,70.00832,0.50006,0.06444
8.44000,2.68724,70.34174,70.34174,0.50244,0.06398
8.48000,2.71052,70.67499,70.67499,0.50482,0.06454
8.52000,3.16780,71.00847,71.00847,0.50720,0.07542
8.56000,2.86642,71.34154,71.34155,0.50958,0.06825
8.60000,3.03928,71.67514,71.67514,0.51197,0.07236
8.64000,2.82638,72.00830,72.00830,0.51434,0.06729
8.68000,2.79825,72.34170,72.34169,0.51673,0.06663
8.72000,2.70493,72.67499,72.67500,0.51911,0.06440
8.76000,2.60621,73.00829,73.00829,0.52149,0.06205
8.80000,3.14265,73.34172,73.34172,0.52387,0.07483
8.84000,3.13707,73.67493,73.67493,0.52625,0.07469
8.88000,3.27379,74.00844,74.00844,0.52863,0.07795
8.92000,2.97166,74.34160,74.34160,0.53101,0.07075
8.96000,3.16296,74.67508,74.67508,0.53339,0.07531
9.00000,3.08771,75.00827,75.00827,0.53577,0.07352
9.04000,2.80142,75.34170,75.34170,0.53815,0.06670
9.08000,3.20878,75.67502,75.67502,0.54054,0.07640
9.12000,3.37865,76.00834,76.00833,0.54292,0.08044
9.16000,2.73883,76.34177,76.34177,0.54530,0.06521
9.20000,2.85432,76.67490,76.67490,0.54768,0.06796
9.24000,3.05250,77.00847,77.00848,0.55006,0.07268
9.28000,3.38648,77.34160,77.34160,0.55244,0.08063
9.32000,3.22405,77.67506,77.67506,0.55482,0.07676
9.36000,2.86195,78.00827,78.00827,0.55720,0.06814
9.40000,3.46191,78.34175,78.34175,0.55958,0.08243
9.44000,3.23486,78.67499,78.67500,0.56196,0.07702
9.48000,3.46825,79.00832,79.00832,0.56435,0.08258
9.52000,2.81110,79.34171,79.34171,0.56673,0.06693
9.56000,3.11676,79.67492,79.67492,0.56911,0.07421
9.60000,3.39653,80.00847,80.00847,0.57149,0.08087
9.64000,3.05790,80.34160,80.34159,0.57387,0.07281
9.68000,2.74014,80.67511,80.67512,0.57625,0.06524
9.72000,3.01041,81.00823,81.00823,0.57863,0.07168
9.76000,3.14116,81.34173,81.34174,0.58101,0.07479
9.80000,2.98806,81.67504,81.67504,0.58339,0.07114
9.84000,2.82526,82.00833,82.00833,0.58577,0.06727
9.88000,2.57213,82.34174,82.34175,0.58816,0.06124
9.92000,2.83010,82.67490,82.67491,0.59054,0.06738
9.96000,3.03630,83.00843,83.00844,0.59292,0.07229
10.00000,3.16016,83.34163,83.34163,0.59530,0.07524
10.04000,2.92659,83.67505,83.67506,0.59768,0.06968
10.08000,2.66787,84.00827,84.00827,0.60006,0.06352
10.12000,3.03313,84.34172,84.34171,0.60244,0.07222
10.16000,3.01711,84.67502,84.67502,0.60482,0.07184
10.20000,2.98452,85.00833,85.00833,0.60720,0.07106
10.24000,3.44776,85.34171,85.34171,0.60958,0.08209
10.28000,3.39188,85.67492,85.67492,0.61196,0.08076
10.32000,3.03444,86.00846,86.00846,0.61435,0.07225
10.36000,3.22107,86.34162,86.34162,0.61673,0.07669
10.40000,3.37679,86.67513,86.67513,0.61911,0.08040
10.44000,3.40920,87.00829,87.00829,0.62149,0.08117
10.48000,3.41274,87.34169,87.34170,0.62387,0.08126
10.52000,3.08137,87.67498,87.67499,0.62625,0.07337
10.56000,3.29800,88.00833,88.00833,0.62863,0.07852
10.60000,3.54517,88.34174,88.34174,0.63101,0.08441
10.64000,3.13465,88.67495,88.67496,0.63339,0.07463
10.68000,3.56045,89.00840,89.00840,0.63577,0.08477
10.72000,3.25590,89.34154,89.34155,0.63815,0.07752
10.76000,3.59099,89.67513,89.67513,0.64054,0.08550
10.80000,3.95998,90.00826,90.00826,0.64292,0.09429
10.84000,3.88045,90.34172,90.34172,0.64530,0.09239
10.88000,3.82625,90.67502,90.67502,0.64768,0.09110
10.92000,3.40715,91.00831,91.00831,0.65006,0.08112
10.96000,3.21977,91.34179,91.34179,0.65244,0.07666
11.00000,3.34866,91.67497,91.67497,0.65482,0.07973
11.04000,3.22368,92.00843,92.00843,0.65720,0.07675
11.08000,3.02326,92.34151,92.34151,0.65958,0.07198
11.12000,3.41944,92.67507,92.67508,0.66196,0.08142
11.16000,3.68375,93.00834,93.00835,0.66435,0.08771
11.20000,3.69456,93.34177,93.34177,0.66673,0.08797
11.24000,3.59975,93.67493,93.67493,0.66911,0.08571
11.28000,3.50978,94.00831,94.00831,0.67149,0.08357
11.32000,3.42429,94.34173,94.34174,0.67387,0.08153
11.36000,3.54964,94.67492,94.67492,0.67625,0.08452
11.40000,3.80743,95.00846,95.00846,0.67863,0.09065
11.44000,3.63998,95.34159,95.34159,0.68101,0.08667
11.48000,3.74485,95.67510,95.67509,0.68339,0.08916
11.52000,3.52152,96.00831,96.00831,0.68577,0.08385
11.56000,3.45316,96.34174,96.34174,0.68816,0.08222
11.60000,3.59360,96.67500,96.67500,0.69054,0.08556
11.64000,3.63756,97.00831,97.00831,0.69292,0.08661
11.68000,3.37064,97.34171,97.34171,0.69530,0.08025
11.72000,3.77391,97.67495,97.67495,0.69768,0.08985
11.76000,3.41553,98.00843,98.00842,0.70006,0.08132
11.80000,4.11049,98.34156,98.34156,0.70244,0.09787
11.84000,4.53629,98.67507,98.67507,0.70482,0.10801
11.88000,4.45172,99.00823,99.00823,0.70720,0.10599
11.92000,4.95352,99.34177,99.34177,0.70958,0.11794
11.96000,4.76781,99.67504,99.67503,0.71196,0.11352
12.00000,4.93322,100.00831,100.00831,0.71435,0.11746
12.04000,4.99599,100.34173,100.34174,0.71673,0.11895
12.08000,4.91273,100.67492,100.67492,0.71911,0.11697
12.12000,4.77061,101.00848,101.00848,0.72149,0.11359
12.16000,4.63258,101.34164,101.34164,0.72387,0.11030
12.20000,4.90788,101.67510,101.67509,0.72625,0.11685
12.24000,4.91347,102.00826,102.00826,0.72863,0.11699
12.28000,4.80562,102.34169,102.34168,0.73101,0.11442
12.32000,4.84902,102.67500,102.67500,0.73339,0.11545
12.36000,5.06993,103.00833,103.00832,0.73577,0.12071
12.40000,5.50020,103.34170,103.34170,0.73816,0.13096
12.44000,5.25489,103.67489,103.67490,0.74053,0.12512
12.48000,5.34505,104.00846,104.00846,0.74292,0.12726
12.52000,5.38733,104.34159,104.34158,0.74530,0.12827
12.56000,4.98183,104.67510,104.67510,0.74768,0.11862
12.60000,5.32474,105.00826,105.00826,0.75006,0.12678
12.64000,5.09452,105.34170,105.34171,0.75244,0.12130
12.68000,5.12358,105.67509,105.67508,0.75482,0.12199
12.72000,5.47189,106.00832,106.00832,0.75720,0.13028
12.76000,5.31729,106.34173,106.34173,0.75958,0.12660
12.80000,5.24372,106.67494,106.67494,0.76196,0.12485
12.84000,5.26141,107.00839,107.00839,0.76435,0.12527
12.88000,4.72143,107.34162,107.34161,0.76673,0.11242
12.92000,5.17350,107.67510,107.67509,0.76911,0.12318
12.96000,5.34505,108.00826,108.00826,0.77149,0.12726
13.00000,5.76600,108.34170,108.34171,0.77387,0.13729
13.04000,5.68610,108.67498,108.67497,0.77625,0.13538
13.08000,5.22807,109.00827,109.00827,0.77863,0.12448
13.12000,5.28786,109.34173,109.34172,0.78101,0.12590
13.16000,4.96153,109.67494,109.67493,0.78339,0.11813
13.20000,5.45420,110.00845,110.00845,0.78577,0.12986
13.24000,5.42831,110.34164,110.34164,0.78815,0.12925
13.28000,5.70305,110.67510,110.67509,0.79054,0.13579
13.32000,5.41862,111.00831,111.00831,0.79292,0.12901
13.36000,5.36107,111.34170,111.34171,0.79530,0.12764
13.40000,5.55329,111.67498,111.67498,0.79768,0.13222
13.44000,5.65462,112.00835,112.00835,0.80006,0.13463
13.48000,5.40782,112.34172,112.34172,0.80244,0.12876
13.52000,5.64270,112.67492,112.67492,0.80482,0.13435
13.56000,5.44228,113.00842,113.00842,0.80720,0.12958
13.60000,5.64251,113.34153,113.34152,0.80958,0.13435
13.64000,5.38919,113.67509,113.67509,0.81196,0.12831
13.68000,5.73117,114.00828,114.00828,0.81434,0.13646
13.72000,5.83716,114.34171,114.34171,0.81673,0.13898
13.76000,5.72782,114.67497,114.67497,0.81911,0.13638
13.80000,5.15953,115.00826,115.00826,0.82149,0.12285
13.84000,5.38155,115.34175,115.34175,0.82387,0.12813
13.88000,6.11842,115.67496,115.67496,0.82625,0.14568
13.92000,5.65909,116.00845,116.00845,0.82863,0.13474
13.96000,5.56447,116.34161,116.34161,0.83101,0.13249
14.00000,5.19846,116.67510,116.67509,0.83339,0.12377
14.04000,5.48791,117.00831,117.00831,0.83577,0.13066
14.08000,5.50728,117.34177,117.34177,0.83816,0.13113
14.12000,5.36088,117.67493,117.67493,0.84054,0.12764
14.16000,5.54975,118.00830,118.00829,0.84292,0.13214
14.20000,5.61420,118.34174,118.34174,0.84530,0.13367
14.24000,5.51622,118.67496,118.67496,0.84768,0.13134
14.28000,5.28470,119.00842,119.00842,0.85006,0.12583
14.32000,5.42738,119.34155,119.34155,0.85244,0.12922
14.36000,5.36423,119.67506,119.67506,0.85482,0.12772
14.40000,5.21988,120.00830,120.00830,0.85720,0.12428
14.44000,5.41676,120.34173,120.34174,0.85958,0.12897
14.48000,5.73490,120.67505,120.67505,0.86196,0.13655
14.52000,5.55925,121.00832,121.00832,0.86435,0.13236
14.56000,5.37708,121.34170,121.34170,0.86673,0.12803
14.60000,5.42868,121.67496,121.67496,0.86911,0.12925
14.64000,5.27799,122.00844,122.00844,0.87149,0.12567
14.68000,5.45382,122.34158,122.34158,0.87387,0.12985
14.72000,5.32847,122.67511,122.67511,0.87625,0.12687
14.76000,5.82635,123.00822,123.00822,0.87863,0.13872
14.80000,5.90887,123.34173,123.34173,0.88101,0.14069
14.84000,5.39627,123.67502,123.67502,0.88339,0.12848
14.88000,5.46258,124.00827,124.00827,0.88577,0.13006
14.92000,5.37131,124.34169,124.34169,0.88815,0.12789
14.96000,5.82244,124.67490,124.67490,0.89053,0.13863
15.00000,5.82878,125.00847,125.00847,0.89292,0.13878
15.04000,5.45457,125.34163,125.34163,0.89530,0.12987
15.08000,5.32176,125.67509,125.67509,0.89768,0.12671
15.12000,5.53895,126.00822,126.00822,0.90006,0.13188
15.16000,5.28619,126.34171,126.34171,0.90244,0.12586
15.20000,5.15282,126.67505,126.67505,0.90482,0.12269
15.24000,5.35231,127.00837,127.00837,0.90720,0.12744
15.28000,5.41713,127.34174,127.34174,0.90958,0.12898
15.32000,5.35436,127.67486,127.67486,0.91196,0.12748
15.36000,5.27557,128.00845,128.00845,0.91435,0.12561
15.40000,5.14816,128.34158,128.34158,0.91673,0.12258
15.44000,5.20051,128.67508,128.67508,0.91911,0.12382
15.48000,5.42980,129.00824,129.00824,0.92149,0.12928
15.52000,5.51511,129.34165,129.34164,0.92387,0.13131
15.56000,5.32400,129.67502,129.67502,0.92625,0.12676
15.60000,5.40223,130.00835,130.00835,0.92863,0.12862
15.64000,5.57862,130.34174,130.34174,0.93101,0.13282
15.68000,5.37522,130.67493,130.67493,0.93339,0.12798
15.72000,5.61923,131.00840,131.00841,0.93577,0.13379
15.76000,5.68554,131.34160,131.34160,0.93815,0.13537
15.80000,5.50598,131.67511,131.67511,0.94054,0.13109
15.84000,5.48381,132.00827,132.00827,0.94292,0.13057
15.88000,5.19156,132.34171,132.34171,0.94530,0.12361
15.92000,5.30817,132.67497,132.67497,0.94768,0.12638
15.96000,5.36963,133.00830,133.00830,0.95006,0.12785
16.00000,5.76191,133.34176,133.34177,0.95244,0.13719
16.04000,5.27818,133.67490,133.67490,0.95482,0.12567
16.08000,5.61010,134.00838,134.00838,0.95720,0.13357
16.12000,5.38975,134.34157,134.34157,0.95958,0.12833
16.16000,5.50449,134.67504,134.67503,0.96196,0.13106
16.20000,5.51548,135.00829,135.00829,0.96434,0.13132
16.24000,5.71422,135.34175,135.34175,0.96673,0.13605
16.28000,5.69988,135.67502,135.67502,0.96911,0.13571
16.32000,5.83865,136.00831,136.00830,0.97149,0.13902
16.36000,6.03236,136.34174,136.34174,0.97387,0.14363
16.40000,5.51902,136.67497,136.67497,0.97625,0.13141
16.44000,5.76433,137.00844,137.00844,0.97863,0.13725
16.48000,5.59986,137.34155,137.34155,0.98101,0.13333
16.52000,5.82952,137.67511,137.67511,0.98339,0.13880
16.56000,6.05993,138.00829,138.00829,0.98577,0.14428
16.60000,5.64624,138.34171,138.34171,0.98816,0.13443
16.64000,5.71422,138.67500,138.67500,0.99054,0.13605
16.68000,5.98878,139.00826,139.00826,0.99292,0.14259
16.72000,5.73471,139.34173,139.34174,0.99530,0.13654
16.76000,5.91911,139.67499,139.67499,0.99768,0.14093
16.80000,5.94500,140.00841,140.00841,1.00006,0.14155
16.84000,5.82449,140.34161,140.34161,1.00244,0.13868
16.88000,5.80139,140.67513,140.67513,1.00482,0.13813
16.92000,5.82654,141.00829,141.00829,1.00720,0.13873
16.96000,5.71627,141.34175,141.34175,1.00958,0.13610
17.00000,6.11879,141.67499,141.67499,1.01196,0.14569
17.04000,5.85429,142.00831,142.00830,1.01435,0.13939
17.08000,5.71907,142.34174,142.34174,1.01673,0.13617
17.12000,5.63562,142.67495,142.67497,1.01911,0.13418
17.16000,6.04186,143.00840,143.00839,1.02149,0.14385
17.20000,6.08712,143.34155,143.34155,1.02387,0.14493
17.24000,5.97574,143.67505,143.67505,1.02625,0.14228
17.28000,5.94929,144.00828,144.00829,1.02863,0.14165
17.32000,6.07986,144.34174,144.34175,1.03101,0.14476
17.36000,5.65927,144.67500,144.67500,1.03339,0.13474
17.40000,6.08210,145.00833,145.00833,1.03577,0.14481
17.44000,6.02659,145.34172,145.34174,1.03816,0.14349
17.48000,6.04056,145.67495,145.67494,1.04054,0.14382
17.52000,5.94109,146.00848,146.00848,1.04292,0.14145
17.56000,5.73341,146.34161,146.34160,1.04530,0.13651
17.60000,5.74179,146.67510,146.67511,1.04768,0.13671
17.64000,5.75595,147.00826,147.00827,1.05006,0.13705
17.68000,6.16070,147.34169,147.34169,1.05244,0.14668
17.72000,6.46040,147.67502,147.67502,1.05482,0.15382
17.76000,6.06496,148.00831,148.00830,1.05720,0.14440
17.80000,6.13313,148.34171,148.34172,1.05958,0.14603
17.84000,6.34268,148.67487,148.67488,1.06196,0.15102
17.88000,6.02715,149.00840,149.00839,1.06435,0.14350
17.92000,6.26370,149.34162,149.34163,1.06673,0.14914
17.96000,6.51088,149.67511,149.67511,1.06911,0.15502
18.00000,6.24843,150.00827,150.00827,1.07149,0.14877
18.04000,6.02398,150.34174,150.34175,1.07387,0.14343
18.08000,6.30617,150.67503,150.67502,1.07625,0.15015
18.12000,6.22533,151.00836,151.00836,1.07863,0.14822
18.16000,6.17281,151.34173,151.34174,1.08101,0.14697
18.20000,6.41830,151.67488,151.67488,1.08339,0.15282
18.24000,6.36559,152.00846,152.00845,1.08577,0.15156
18.28000,6.07315,152.34162,152.34161,1.08815,0.14460
18.32000,6.26035,152.67513,152.67513,1.09054,0.14906
18.36000,6.09700,153.00822,153.00822,1.09292,0.14517
18.40000,6.18268,153.34163,153.34163,1.09530,0.14721
18.44000,6.58948,153.67499,153.67500,1.09768,0.15689
18.48000,6.32200,154.00833,154.00833,1.10006,0.15052
18.52000,6.14114,154.34174,154.34174,1.10244,0.14622
18.56000,6.35330,154.67494,154.67494,1.10482,0.15127
18.60000,6.26128,155.00842,155.00842,1.10720,0.14908
18.64000,6.33914,155.34158,155.34158,1.10958,0.15093
18.68000,6.59134,155.67517,155.67517,1.11197,0.15694
18.72000,7.12369,156.00827,156.00829,1.11434,0.16961
18.76000,6.43171,156.34170,156.34169,1.11673,0.15314
18.80000,6.38664,156.67501,156.67502,1.11911,0.15206
18.84000,6.56638,157.00830,157.00830,1.12149,0.15634
18.88000,6.37583,157.34176,157.34175,1.12387,0.15181
18.92000,6.49542,157.67492,157.67491,1.12625,0.15465
18.96000,6.68336,158.00840,158.00841,1.12863,0.15913
19.00000,6.84857,158.34156,158.34157,1.13101,0.16306
19.04000,6.91488,158.67510,158.67511,1.13339,0.16464
19.08000,6.58035,159.00829,159.00830,1.13577,0.15668
19.12000,6.80946,159.34175,159.34175,1.13816,0.16213
19.16000,6.70180,159.67497,159.67496,1.14054,0.15957
19.20000,7.11028,160.00828,160.00829,1.14292,0.16929
19.24000,6.87111,160.34176,160.34178,1.14530,0.16360
19.28000,6.89533,160.67496,160.67496,1.14768,0.16417
19.32000,6.59581,161.00849,161.00848,1.15006,0.15704
19.36000,6.92606,161.34156,161.34155,1.15244,0.16491
19.40000,7.05235,161.67507,161.67505,1.15482,0.16791
19.44000,7.08140,162.00833,162.00833,1.15720,0.16860
19.48000,7.16783,162.34170,162.34171,1.15958,0.17066
19.52000,6.82101,162.67498,162.67499,1.16196,0.16240
19.56000,7.04397,163.00830,163.00832,1.16435,0.16771
19.60000,6.80834,163.34170,163.34171,1.16673,0.16210
19.64000,6.90278,163.67497,163.67497,1.16911,0.16435
19.68000,6.97970,164.00843,164.00842,1.17149,0.16618
19.72000,7.18273,164.34156,164.34157,1.17387,0.17102
19.76000,7.03670,164.67506,164.67506,1.17625,0.16754
19.80000,7.33864,165.00825,165.00826,1.17863,0.17473
19.84000,7.20602,165.34176,165.34178,1.18101,0.17157
19.88000,7.09221,165.67504,165.67503,1.18339,0.16886
19.92000,7.16150,166.00830,166.00830,1.18577,0.17051
19.96000,7.16355,166.34172,166.34172,1.18816,0.17056
20.00000,7.11493,166.67494,166.67494,1.19054,0.16940
20.04000,7.01603,167.00849,167.00850,1.19292,0.16705
20.08000,7.23787,167.34161,167.34161,1.19530,0.17233
20.12000,7.53552,167.67507,167.67506,1.19768,0.17942
20.16000,7.37198,168.00825,168.00826,1.20006,0.17552
20.20000,7.12276,168.34170,168.34171,1.20244,0.16959
20.24000,6.76867,168.67495,168.67496,1.20482,0.16116
20.28000,7.60984,169.00835,169.00833,1.20720,0.18119
20.32000,7.69719,169.34172,169.34171,1.20958,0.18327
20.36000,7.52024,169.67494,169.67494,1.21196,0.17905
20.40000,7.47871,170.00844,170.00844,1.21435,0.17806
20.44000,7.41072,170.34159,170.34158,1.21673,0.17645
20.48000,7.89482,170.67513,170.67514,1.21911,0.18797
20.52000,7.90972,171.00829,171.00829,1.22149,0.18833
20.56000,7.51242,171.34171,171.34171,1.22387,0.17887
20.60000,7.46157,171.67505,171.67506,1.22625,0.17766
20.64000,7.55880,172.00834,172.00835,1.22863,0.17997
20.68000,7.68192,172.34172,172.34172,1.23101,0.18290
20.72000,7.84863,172.67488,172.67488,1.23339,0.18687
20.76000,7.91922,173.00840,173.00839,1.23577,0.18855
20.80000,8.02074,173.34163,173.34163,1.23815,0.19097
20.84000,8.16360,173.67508,173.67508,1.24054,0.19437
20.88000,7.85571,174.00820,174.00821,1.24292,0.18704
20.92000,7.67410,174.34167,174.34167,1.24530,0.18272
20.96000,7.38781,174.67503,174.67503,1.24768,0.17590
21.00000,7.27009,175.00832,175.00833,1.25006,0.17310
21.04000,7.91289,175.34174,175.34174,1.25244,0.18840
21.08000,8.11368,175.67497,175.67497,1.25482,0.19318
21.12000,7.81827,176.00844,176.00844,1.25720,0.18615
21.16000,8.27815,176.34163,176.34161,1.25958,0.19710
21.20000,7.89631,176.67515,176.67516,1.26197,0.18801
21.24000,8.09878,177.00825,177.00824,1.26434,0.19283
21.28000,8.36924,177.34171,177.34171,1.26673,0.19927
21.32000,8.32211,177.67500,177.67500,1.26911,0.19815
21.36000,8.31634,178.00834,178.00835,1.27149,0.19801
21.40000,8.08779,178.34172,178.34171,1.27387,0.19257
21.44000,8.43499,178.67488,178.67488,1.27625,0.20083
21.48000,8.69632,179.00842,179.00842,1.27863,0.20706
21.52000,8.62870,179.34152,179.34152,1.28101,0.20545
21.56000,8.04514,179.67511,179.67511,1.28339,0.19155
21.60000,8.38581,180.00833,180.00833,1.28577,0.19966
21.64000,8.36253,180.34173,180.34172,1.28816,0.19911
21.68000,8.53911,180.67506,180.67506,1.29054,0.20331
21.72000,8.42810,181.00835,181.00835,1.29292,0.20067
21.76000,8.62870,181.34178,181.34178,1.29530,0.20545
21.80000,8.35955,181.67497,181.67497,1.29768,0.19904
21.84000,9.07127,182.00844,182.00844,1.30006,0.21598
21.88000,8.90344,182.34155,182.34154,1.30244,0.21199
21.92000,8.75369,182.67509,182.67508,1.30482,0.20842
21.96000,8.63690,183.00827,183.00827,1.30720,0.20564
22.00000,9.09921,183.34171,183.34172,1.30958,0.21665
22.04000,9.06661,183.67494,183.67494,1.31196,0.21587
22.08000,8.49124,184.00826,184.00826,1.31434,0.20217
22.12000,8.66596,184.34176,184.34175,1.31673,0.20633
22.16000,9.00775,184.67496,184.67496,1.31911,0.21447
22.20000,9.30112,185.00847,185.00847,1.32149,0.22146
22.24000,8.78274,185.34158,185.34158,1.32387,0.20911
22.28000,9.20780,185.67507,185.67506,1.32625,0.21923
22.32000,8.77567,186.00836,186.00836,1.32863,0.20894
22.36000,8.87103,186.34179,186.34180,1.33101,0.21122
22.40000,8.91928,186.67502,186.67502,1.33339,0.21236
22.44000,9.02396,187.00828,187.00829,1.33577,0.21486
22.48000,9.27504,187.34169,187.34169,1.33815,0.22083
22.52000,8.99304,187.67497,187.67497,1.34054,0.21412
22.56000,9.14261,188.00841,188.00841,1.34292,0.21768
22.60000,8.63299,188.34152,188.34152,1.34530,0.20555
22.64000,9.18191,188.67506,188.67506,1.34768,0.21862
22.68000,9.19960,189.00825,189.00824,1.35006,0.21904
22.72000,9.21190,189.34178,189.34178,1.35244,0.21933
22.76000,9.30838,189.67507,189.67508,1.35482,0.22163
22.80000,9.14466,190.00829,190.00829,1.35720,0.21773
22.84000,9.39909,190.34175,190.34174,1.35958,0.22379
22.88000,9.42163,190.67496,190.67496,1.36196,0.22432
22.92000,9.40319,191.00847,191.00847,1.36435,0.22389
22.96000,9.35737,191.34163,191.34163,1.36673,0.22279
23.00000,9.27448,191.67508,191.67508,1.36911,0.22082
23.04000,9.33241,192.00823,192.00824,1.37149,0.22220
23.08000,9.17781,192.34172,192.34172,1.37387,0.21852
23.12000,9.67644,192.67499,192.67499,1.37625,0.23039
23.16000,9.59709,193.00832,193.00832,1.37863,0.22850
23.20000,9.43616,193.34171,193.34172,1.38101,0.22467
23.24000,9.54103,193.67487,193.67488,1.38339,0.22717
23.28000,9.37171,194.00840,194.00839,1.38577,0.22314
23.32000,10.02364,194.34162,194.34164,1.38815,0.23866
23.36000,9.82545,194.67511,194.67511,1.39054,0.23394
23.40000,9.59914,195.00830,195.00830,1.39292,0.22855
23.44000,9.75933,195.34167,195.34166,1.39530,0.23236
23.48000,9.66564,195.67503,195.67503,1.39768,0.23013
23.52000,9.69637,196.00836,196.00836,1.40006,0.23087
23.56000,9.98899,196.34172,196.34174,1.40244,0.23783
23.60000,10.10094,196.67492,196.67491,1.40482,0.24050
23.64000,9.54643,197.00840,197.00839,1.40720,0.22730
23.68000,9.64906,197.34160,197.34160,1.40958,0.22974
23.72000,9.69619,197.67510,197.67511,1.41197,0.23086
23.76000,10.00613,198.00826,198.00827,1.41434,0.23824
23.80000,9.99514,198.34170,198.34169,1.41673,0.23798
23.84000,10.41126,198.67499,198.67499,1.41911,0.24789
23.88000,10.18923,199.00834,199.00835,1.42149,0.24260
23.92000,10.05940,199.34174,199.34175,1.42387,0.23951
23.96000,10.16520,199.67492,199.67493,1.42625,0.24203
24.00000,10.63142,200.00840,200.00839,1.42863,0.25313
24.04000,10.54872,200.34160,200.34160,1.43101,0.25116
24.08000,10.52618,200.67512,200.67513,1.43339,0.25062
24.12000,10.43770,201.00831,201.00832,1.43577,0.24852
24.16000,10.64930,201.34174,201.34174,1.43816,0.25355
24.20000,10.48017,201.67497,201.67499,1.44054,0.24953
24.24000,10.12031,202.00836,202.00836,1.44292,0.24096
24.28000,10.58932,202.34174,202.34175,1.44530,0.25213
24.32000,10.60404,202.67488,202.67488,1.44768,0.25248
24.36000,10.79720,203.00847,203.00847,1.45006,0.25708
24.40000,10.50327,203.34156,203.34157,1.45244,0.25008
24.44000,10.62024,203.67510,203.67511,1.45482,0.25286
24.48000,10.73014,204.00826,204.00826,1.45720,0.25548
24.52000,10.64800,204.34168,204.34167,1.45958,0.25352
24.56000,10.93280,204.67501,204.67502,1.46196,0.26030
24.60000,10.85941,205.00830,205.00829,1.46434,0.25856
24.64000,10.47198,205.34176,205.34177,1.46673,0.24933
24.68000,10.89741,205.67498,205.67496,1.46911,0.25946
24.72000,11.02891,206.00842,206.00842,1.47149,0.26259
24.76000,11.17233,206.34156,206.34155,1.47387,0.26601
24.80000,11.16656,206.67511,206.67511,1.47625,0.26587
24.84000,11.20921,207.00827,207.00829,1.47863,0.26689
24.88000,10.71189,207.34174,207.34174,1.48101,0.25504
24.92000,10.68078,207.67499,207.67499,1.48339,0.25430
24.96000,10.56604,208.00826,208.00827,1.48577,0.25157
25.00000,10.91734,208.34176,208.34175,1.48816,0.25994
25.04000,10.95533,208.67494,208.67493,1.49054,0.26084
25.08000,10.95757,209.00840,209.00841,1.49292,0.26089
25.12000,11.15538,209.34156,209.34157,1.49530,0.26560
25.16000,11.49792,209.67506,209.67506,1.49768,0.27376
25.20000,11.54281,210.00831,210.00832,1.50006,0.27483
25.24000,11.48600,210.34177,210.34177,1.50244,0.27348
25.28000,11.56442,210.67501,210.67502,1.50482,0.27534
25.32000,11.81867,211.00830,211.00830,1.50720,0.28140
25.36000,11.68437,211.34174,211.34174,1.50958,0.27820
25.40000,11.60707,211.67495,211.67494,1.51196,0.27636
25.44000,11.54933,212.00849,212.00848,1.51435,0.27498
25.48000,11.37722,212.34154,212.34154,1.51673,0.27089
25.52000,11.24516,212.67507,212.67505,1.51911,0.26774
25.56000,11.25503,213.00827,213.00827,1.52149,0.26798
25.60000,11.35916,213.34170,213.34171,1.52387,0.27046
25.64000,11.69387,213.67501,213.67500,1.52625,0.27843
25.68000,12.13290,214.00832,214.00832,1.52863,0.28888
25.72000,11.79297,214.34170,214.34171,1.53101,0.28078
25.76000,11.94719,214.67494,214.67494,1.53339,0.28446
25.80000,11.88722,215.00848,215.00848,1.53577,0.28303
25.84000,11.94607,215.34163,215.34163,1.53815,0.28443
25.88000,11.96135,215.67513,215.67513,1.54054,0.28479
25.92000,12.10086,216.00826,216.00826,1.54292,0.28812
25.96000,11.90510,216.34171,216.34169,1.54530,0.28345
26.00000,11.74733,216.67501,216.67502,1.54768,0.27970
26.04000,12.04032,217.00833,217.00832,1.55006,0.28667
26.08000,11.78216,217.34176,217.34177,1.55244,0.28053
26.12000,11.54877,217.67490,217.67490,1.55482,0.27497
26.16000,11.90323,218.00842,218.00842,1.55720,0.28341
26.20000,11.79483,218.34158,218.34158,1.55958,0.28083
26.24000,12.14370,218.67511,218.67509,1.56196,0.28914
26.28000,11.93099,219.00827,219.00827,1.56434,0.28407
26.32000,12.09341,219.34169,219.34169,1.56673,0.28794
26.36000,12.36554,219.67500,219.67500,1.56911,0.29442
26.40000,12.38454,220.00843,220.00842,1.57149,0.29487
26.44000,12.22771,220.34174,220.34174,1.57387,0.29114
26.48000,12.07571,220.67495,220.67496,1.57625,0.28752
26.52000,12.35139,221.00840,221.00841,1.57863,0.29408
26.56000,12.19288,221.34159,221.34158,1.58101,0.29031
26.60000,12.35306,221.67511,221.67511,1.58339,0.29412
26.64000,12.26887,222.00825,222.00824,1.58577,0.29212
26.68000,11.98798,222.34169,222.34169,1.58815,0.28543
26.72000,12.35101,222.67501,222.67500,1.59054,0.29407
26.76000,12.35269,223.00830,223.00830,1.59292,0.29411
26.80000,12.70156,223.34172,223.34172,1.59530,0.30242
26.84000,12.68778,223.67491,223.67491,1.59768,0.30209
26.88000,12.91353,224.00838,224.00838,1.60006,0.30747
26.92000,13.25775,224.34165,224.34164,1.60244,0.31566
26.96000,13.05044,224.67515,224.67514,1.60482,0.31072
27.00000,13.05379,225.00825,225.00826,1.60720,0.31080
27.04000,13.17598,225.34173,225.34172,1.60958,0.31371
27.08000,13.24322,225.67499,225.67499,1.61196,0.31531
27.12000,13.03796,226.00833,226.00833,1.61435,0.31043
27.16000,13.43451,226.34178,226.34178,1.61673,0.31987
27.20000,13.29072,226.67497,226.67497,1.61911,0.31645
27.24000,13.35945,227.00844,227.00844,1.62149,0.31808
27.28000,13.44047,227.34155,227.34155,1.62387,0.32001
27.32000,13.20057,227.67510,227.67509,1.62625,0.31430
27.36000,13.51479,228.00826,228.00826,1.62863,0.32178
27.40000,13.53920,228.34173,228.34174,1.63101,0.32236
27.44000,13.63475,228.67500,228.67500,1.63339,0.32464
27.48000,13.29165,229.00834,229.00835,1.63577,0.31647
27.52000,13.45109,229.34173,229.34174,1.63816,0.32026
27.56000,13.30134,229.67497,229.67497,1.64054,0.31670
27.60000,13.67703,230.00845,230.00844,1.64292,0.32564
27.64000,13.66623,230.34158,230.34158,1.64530,0.32539
27.68000,13.59228,230.67511,230.67511,1.64768,0.32363
27.72000,13.60513,231.00829,231.00829,1.65006,0.32393
27.76000,13.72248,231.34174,231.34174,1.65244,0.32673
27.80000,13.54534,231.67500,231.67500,1.65482,0.32251
27.84000,13.69435,232.00827,232.00827,1.65720,0.32606
27.88000,13.42800,232.34171,232.34172,1.65958,0.31971
27.92000,13.62786,232.67498,232.67497,1.66196,0.32447
27.96000,13.92215,233.00848,233.00848,1.66435,0.33148
28.00000,14.41389,233.34159,233.34158,1.66673,0.34319
28.04000,14.10637,233.67506,233.67506,1.66911,0.33587
28.08000,14.43028,234.00827,234.00827,1.67149,0.34358
28.12000,14.62735,234.34174,234.34175,1.67387,0.34827
28.16000,14.36137,234.67501,234.67500,1.67625,0.34194
28.20000,14.29301,235.00833,235.00833,1.67863,0.34031
28.24000,14.26022,235.34175,235.34175,1.68101,0.33953
28.28000,14.39881,235.67493,235.67493,1.68339,0.34283
28.32000,14.61860,236.00851,236.00851,1.68578,0.34806
28.36000,14.71080,236.34154,236.34154,1.68815,0.35026
28.40000,14.67559,236.67507,236.67506,1.69054,0.34942
28.44000,14.49678,237.00828,237.00827,1.69292,0.34516
28.48000,14.35708,237.34172,237.34172,1.69530,0.34184
28.52000,14.60891,237.67501,237.67502,1.69768,0.34783
28.56000,14.55043,238.00831,238.00830,1.70006,0.34644
28.60000,14.90470,238.34173,238.34172,1.70244,0.35487
28.64000,15.01888,238.67491,238.67491,1.70482,0.35759
28.68000,15.01255,239.00844,239.00844,1.70720,0.35744
28.72000,15.09096,239.34160,239.34160,1.70958,0.35931
28.76000,15.43127,239.67512,239.67513,1.71197,0.36741
28.80000,15.15020,240.00828,240.00829,1.71434,0.36072
28.84000,15.48603,240.34173,240.34174,1.71673,0.36872
28.88000,15.45809,240.67502,240.67502,1.71911,0.36805
28.92000,15.20887,241.00831,241.00832,1.72149,0.36212
28.96000,15.27611,241.34176,241.34175,1.72387,0.36372
29.00000,15.23364,241.67492,241.67491,1.72625,0.36271
29.04000,15.01255,242.00842,242.00842,1.72863,0.35744
29.08000,15.29269,242.34163,242.34163,1.73101,0.36411
29.12000,15.22787,242.67510,242.67511,1.73339,0.36257
29.16000,15.41767,243.00826,243.00827,1.73577,0.36709
29.20000,15.78964,243.34168,243.34169,1.73815,0.37594
29.24000,15.38396,243.67500,243.67500,1.74054,0.36628
29.28000,15.53707,244.00837,244.00838,1.74292,0.36993
29.32000,15.50522,244.34176,244.34177,1.74530,0.36917
29.36000,15.77232,244.67492,244.67493,1.74768,0.37553
29.40000,15.90513,245.00840,245.00839,1.75006,0.37869
29.44000,15.84105,245.34164,245.34163,1.75244,0.37717
29.48000,15.79039,245.67516,245.67516,1.75482,0.37596
29.52000,15.75854,246.00830,246.00830,1.75720,0.37520
29.56000,15.81833,246.34164,246.34164,1.75958,0.37663
29.60000,15.99304,246.67501,246.67500,1.76196,0.38079
29.64000,15.75034,247.00832,247.00833,1.76435,0.37501
29.68000,15.97144,247.34174,247.34175,1.76673,0.38027
29.72000,15.93195,247.67493,247.67493,1.76911,0.37933
29.76000,16.23817,248.00843,248.00842,1.77149,0.38662
29.80000,16.44455,248.34154,248.34154,1.77387,0.39154
29.84000,16.23556,248.67514,248.67514,1.77625,0.38656
29.88000,16.53843,249.00828,249.00827,1.77863,0.39377
29.92000,16.15714,249.34170,249.34169,1.78101,0.38469
29.96000,16.55091,249.67501,249.67502,1.78339,0.39407
30.00000,16.47938,250.00833,250.00833,1.78577,0.39237
30.04000,16.67328,250.34178,250.34178,1.78816,0.39698
30.08000,16.47584,250.67494,250.67494,1.79054,0.39228
30.12000,16.58928,251.00844,251.00844,1.79292,0.39498
30.16000,16.29796,251.34154,251.34154,1.79530,0.38805
30.20000,16.21805,251.67507,251.67506,1.79768,0.38614
30.24000,15.99900,252.00833,252.00833,1.80006,0.38093
30.28000,16.12138,252.34173,252.34174,1.80244,0.38384
30.32000,16.16925,252.67497,252.67497,1.80482,0.38498
30.36000,16.15286,253.00834,253.00833,1.80720,0.38459
30.40000,16.77386,253.34170,253.34171,1.80958,0.39938
30.44000,16.97615,253.67497,253.67497,1.81196,0.40419
30.48000,16.96646,254.00844,254.00844,1.81435,0.40396
30.52000,17.24176,254.34158,254.34158,1.81673,0.41052
30.56000,17.36358,254.67508,254.67508,1.81911,0.41342
30.60000,16.85619,255.00829,255.00829,1.82149,0.40134
30.64000,16.97615,255.34176,255.34177,1.82387,0.40419
30.68000,17.08381,255.67503,255.67502,1.82625,0.40676
30.72000,17.18383,256.00832,256.00830,1.82863,0.40914
30.76000,17.06593,256.34171,256.34171,1.83101,0.40633
30.80000,17.18756,256.67495,256.67496,1.83339,0.40923
30.84000,17.19724,257.00845,257.00845,1.83577,0.40946
30.88000,16.68558,257.34158,257.34158,1.83815,0.39728
30.92000,17.05643,257.67506,257.67505,1.84054,0.40611
30.96000,17.57983,258.00824,258.00824,1.84292,0.41857
31.00000,17.69699,258.34177,258.34177,1.84530,0.42136
31.04000,17.64577,258.67498,258.67499,1.84768,0.42014
31.08000,17.75455,259.00827,259.00827,1.85006,0.42273
31.12000,17.72325,259.34177,259.34177,1.85244,0.42198
31.16000,17.98104,259.67493,259.67493,1.85482,0.42812
31.20000,17.63534,260.00851,260.00851,1.85720,0.41989
31.24000,17.76014,260.34161,260.34161,1.85958,0.42286
31.28000,17.65322,260.67511,260.67511,1.86197,0.42031
31.32000,17.81788,261.00830,261.00830,1.86434,0.42424
31.36000,17.96633,261.34172,261.34174,1.86673,0.42777
31.40000,17.59976,261.67499,261.67499,1.86911,0.41904
31.44000,17.57406,262.00830,262.00830,1.87149,0.41843
31.48000,17.66682,262.34175,262.34174,1.87387,0.42064
31.52000,17.91865,262.67494,262.67493,1.87625,0.42663
31.56000,18.08684,263.00846,263.00845,1.87863,0.43064
31.60000,18.15949,263.34157,263.34158,1.88101,0.43237
31.64000,18.24405,263.67509,263.67508,1.88339,0.43438
31.68000,18.50501,264.00825,264.00824,1.88577,0.44060
31.72000,14.62344,264.34173,264.34174,1.88816,0.34818
31.75200,-0.07730,264.60831,264.60831,1.89006,-0.00184