File: raw_data/mechanical_tests_Instron_data/Silicone_0035-Cross_4.is_tens_RawData/Specimen_RawData_1.csv
Dimension : Area,0.42000,cm^2

Time,Load,Extension,Tensile extension,Tensile strain,Tensile stress
(sec),(N),(mm),(mm),(mm/mm),(MPa)
0.00000,0.27400,-2.62296,0.00000,0.00000,0.00652
0.03000,0.63162,-2.59063,0.03233,0.00023,0.01504
0.06000,0.70985,-2.47907,0.14389,0.00103,0.01690
0.09000,0.63498,-2.28897,0.33399,0.00239,0.01512
0.12000,2.14037,-2.02969,0.59328,0.00424,0.05096
0.15000,2.21021,-1.74313,0.87983,0.00628,0.05262
0.18000,1.97906,-1.44734,1.17562,0.00840,0.04712
0.21000,1.96416,-1.14538,1.47758,0.01055,0.04677
0.24000,1.79037,-0.83909,1.78387,0.01274,0.04263
0.27000,1.84942,-0.52993,2.09303,0.01495,0.04403
0.30000,2.35401,-0.21801,2.40495,0.01718,0.05605
0.33000,2.20872,0.09463,2.71760,0.01941,0.05259
0.36000,1.67806,0.38379,3.00675,0.02148,0.03995
0.39000,1.25747,0.63755,3.26052,0.02329,0.02994
0.42000,1.47726,0.88211,3.50507,0.02504,0.03517
0.45000,1.77771,1.13148,3.75444,0.02682,0.04233
0.48000,1.90511,1.38370,4.00666,0.02862,0.04536
0.51000,1.98688,1.63511,4.25807,0.03041,0.04731
0.54000,1.85426,1.88531,4.50827,0.03220,0.04415
0.57000,1.79838,2.13520,4.75816,0.03399,0.04282
0.60000,1.98744,2.38519,5.00815,0.03577,0.04732
0.63000,1.94963,2.63523,5.25819,0.03756,0.04642
0.66000,2.15676,2.88528,5.50824,0.03934,0.05135
0.69000,1.92616,3.13535,5.75831,0.04113,0.04586
0.72000,2.02972,3.38542,6.00838,0.04292,0.04833
0.75000,1.85147,3.63544,6.25840,0.04470,0.04408
0.78000,2.11466,3.88540,6.50836,0.04649,0.05035
0.81000,2.01650,4.13526,6.75822,0.04827,0.04801
0.84000,1.77063,4.38522,7.00818,0.05006,0.04216
0.87000,2.22381,4.63537,7.25834,0.05185,0.05295
0.90000,2.04537,4.88544,7.50841,0.05363,0.04870
0.93000,2.13683,5.13546,7.75842,0.05542,0.05088
0.96000,2.13515,5.38540,8.00836,0.05720,0.05084
0.99000,1.55903,5.63523,8.25819,0.05899,0.03712
1.02000,1.86209,5.88525,8.50821,0.06077,0.04434
1.05000,1.95932,6.13535,8.75831,0.06256,0.04665
1.08000,1.99843,6.38539,9.00835,0.06435,0.04758
1.11000,2.07797,6.63541,9.25837,0.06613,0.04948
1.14000,1.99936,6.88540,9.50836,0.06792,0.04760
1.17000,1.94404,7.13534,9.75830,0.06970,0.04629
1.20000,1.92504,7.38525,10.00821,0.07149,0.04583
1.23000,2.16234,7.63534,10.25831,0.07327,0.05148
1.26000,2.45478,7.88547,10.50843,0.07506,0.05845
1.29000,2.29198,8.13546,10.75842,0.07685,0.05457
1.32000,2.09380,8.38535,11.00831,0.07863,0.04985
1.35000,2.04425,8.63531,11.25827,0.08042,0.04867
1.38000,1.71363,8.88527,11.50823,0.08220,0.04080
1.41000,1.84849,9.13534,11.75831,0.08399,0.04401
1.44000,1.92355,9.38544,12.00840,0.08577,0.04580
1.47000,2.08411,9.63546,12.25842,0.08756,0.04962
1.50000,2.29366,9.88534,12.50831,0.08935,0.05461
1.53000,2.41268,10.13528,12.75824,0.09113,0.05744
1.56000,2.12584,10.38525,13.00821,0.09292,0.05062
1.59000,2.27392,10.63529,13.25825,0.09470,0.05414
1.62000,2.24262,10.88541,13.50838,0.09649,0.05340
1.65000,2.23368,11.13546,13.75842,0.09827,0.05318
1.68000,2.13478,11.38537,14.00833,0.10006,0.05083
1.71000,2.20221,11.63528,14.25824,0.10184,0.05243
1.74000,2.26647,11.88527,14.50823,0.10363,0.05396
1.77000,1.86376,12.13532,14.75828,0.10542,0.04438
1.80000,2.09771,12.38547,15.00843,0.10720,0.04995
1.83000,1.78944,12.63548,15.25845,0.10899,0.04261
1.86000,1.81496,12.88534,15.50830,0.11077,0.04321
1.89000,1.95596,13.13528,15.75824,0.11256,0.04657
1.92000,2.36835,13.38530,16.00826,0.11434,0.05639
1.95000,2.09417,13.63534,16.25830,0.11613,0.04986
1.98000,2.13906,13.88544,16.50840,0.11792,0.05093
2.01000,1.72071,14.13548,16.75845,0.11970,0.04097
2.04000,1.86283,14.38539,17.00836,0.12149,0.04435
2.07000,1.89729,14.63520,17.25816,0.12327,0.04517
2.10000,2.06120,14.88516,17.50813,0.12506,0.04908
2.13000,2.02656,15.13531,17.75828,0.12684,0.04825
2.16000,2.00551,15.38539,18.00835,0.12863,0.04775
2.19000,1.99769,15.63543,18.25839,0.13042,0.04756
2.22000,1.95280,15.88542,18.50838,0.13220,0.04650
2.25000,2.20612,16.13528,18.75824,0.13399,0.05253
2.28000,2.05077,16.38524,19.00821,0.13577,0.04883
2.31000,2.05990,16.63537,19.25833,0.13756,0.04905
2.34000,2.16104,16.88544,19.50840,0.13935,0.05145
2.37000,2.04053,17.13543,19.75839,0.14113,0.04858
2.40000,1.94423,17.38539,20.00836,0.14292,0.04629
2.43000,1.93026,17.63533,20.25830,0.14470,0.04596
2.46000,2.03885,17.88527,20.50823,0.14649,0.04854
2.49000,2.23406,18.13531,20.75828,0.14827,0.05319
2.52000,1.79112,18.38541,21.00837,0.15006,0.04265
2.55000,1.57934,18.63546,21.25842,0.15185,0.03760
2.58000,2.07648,18.88542,21.50838,0.15363,0.04944
2.61000,1.86600,19.13528,21.75824,0.15542,0.04443
2.64000,1.71382,19.38524,22.00821,0.15720,0.04081
2.67000,1.57692,19.63531,22.25828,0.15899,0.03755
2.70000,1.44765,19.88544,22.50840,0.16077,0.03447
2.73000,2.04556,20.13543,22.75839,0.16256,0.04870
2.76000,2.16309,20.38536,23.00833,0.16435,0.05150
2.79000,1.81552,20.63533,23.25829,0.16613,0.04323
2.82000,2.25324,20.88527,23.50823,0.16792,0.05365
2.85000,1.91666,21.13528,23.75825,0.16970,0.04563
2.88000,1.94926,21.38538,24.00835,0.17149,0.04641
2.91000,1.90400,21.63546,24.25842,0.17327,0.04533
2.94000,1.98558,21.88534,24.50830,0.17506,0.04728
2.97000,2.07890,22.13533,24.75829,0.17684,0.04950
3.00000,1.90996,22.38535,25.00831,0.17863,0.04548
3.03000,2.25920,22.63536,25.25833,0.18042,0.05379
3.06000,2.47266,22.88546,25.50842,0.18220,0.05887
3.09000,2.46018,23.13545,25.75842,0.18399,0.05858
3.12000,2.14819,23.38531,26.00827,0.18577,0.05115
3.15000,1.84830,23.63527,26.25824,0.18756,0.04401
3.18000,1.64490,23.88532,26.50828,0.18934,0.03916
3.21000,1.74493,24.13536,26.75833,0.19113,0.04155
3.24000,1.67992,24.38538,27.00834,0.19292,0.04000
3.27000,1.53668,24.63543,27.25839,0.19470,0.03659
3.30000,1.84700,24.88539,27.50835,0.19649,0.04398
3.33000,1.65850,25.13527,27.75824,0.19827,0.03949
3.36000,1.94106,25.38527,28.00823,0.20006,0.04622
3.39000,2.10553,25.63534,28.25830,0.20184,0.05013
3.42000,2.25529,25.88538,28.50834,0.20363,0.05370
3.45000,1.99713,26.13540,28.75836,0.20542,0.04755
3.48000,1.93752,26.38536,29.00833,0.20720,0.04613
3.51000,1.85128,26.63525,29.25821,0.20899,0.04408
3.54000,2.15303,26.88527,29.50823,0.21077,0.05126
3.57000,2.11280,27.13542,29.75838,0.21256,0.05030
3.60000,1.92616,27.38549,30.00845,0.21435,0.04586
3.63000,1.91070,27.63545,30.25841,0.21613,0.04549
3.66000,2.16532,27.88536,30.50833,0.21792,0.05156
3.69000,2.05878,28.13527,30.75823,0.21970,0.04902
3.72000,1.84402,28.38526,31.00822,0.22149,0.04391
3.75000,2.26982,28.63539,31.25836,0.22327,0.05404
3.78000,2.28193,28.88546,31.50842,0.22506,0.05433
3.81000,2.31937,29.13545,31.75842,0.22685,0.05522
3.84000,2.12807,29.38539,32.00835,0.22863,0.05067
3.87000,2.11056,29.63524,32.25821,0.23042,0.05025
3.90000,1.90288,29.88518,32.50815,0.23220,0.04531
3.93000,1.95652,30.13536,32.75832,0.23399,0.04658
3.96000,1.96658,30.38549,33.00845,0.23577,0.04682
3.99000,2.04071,30.63542,33.25839,0.23756,0.04859
4.02000,2.22381,30.88536,33.50832,0.23935,0.05295
4.05000,2.22791,31.13530,33.75826,0.24113,0.05305
4.08000,2.10777,31.38524,34.00820,0.24292,0.05018
4.11000,1.95615,31.63528,34.25824,0.24470,0.04657
4.14000,1.95894,31.88546,34.50842,0.24649,0.04664
4.17000,2.36221,32.13550,34.75847,0.24827,0.05624
4.20000,2.33799,32.38539,35.00835,0.25006,0.05567
4.23000,2.31136,32.63527,35.25823,0.25184,0.05503
4.26000,2.29347,32.88526,35.50823,0.25363,0.05461
4.29000,2.27690,33.13531,35.75827,0.25542,0.05421
4.32000,2.23685,33.38543,36.00839,0.25720,0.05326
4.35000,2.23313,33.63548,36.25844,0.25899,0.05317
4.38000,2.46428,33.88539,36.50835,0.26077,0.05867
4.41000,2.54121,34.13527,36.75823,0.26256,0.06050
4.44000,2.44956,34.38529,37.00826,0.26434,0.05832
4.47000,2.54158,34.63533,37.25830,0.26613,0.06051
4.50000,2.17501,34.88540,37.50837,0.26792,0.05179
4.53000,2.42312,35.13542,37.75838,0.26970,0.05769
4.56000,2.31024,35.38530,38.00827,0.27149,0.05501
4.59000,2.40635,35.63524,38.25821,0.27327,0.05729
4.62000,2.33706,35.88526,38.50822,0.27506,0.05564
4.65000,2.51103,36.13531,38.75827,0.27684,0.05979
4.68000,2.40784,36.38546,39.00842,0.27863,0.05733
4.71000,2.36500,36.63553,39.25849,0.28042,0.05631
4.74000,2.61571,36.88541,39.50837,0.28220,0.06228
4.77000,2.77348,37.13527,39.75823,0.28399,0.06604
4.80000,2.68333,37.38526,40.00823,0.28577,0.06389
4.83000,2.71332,37.63536,40.25832,0.28756,0.06460
4.86000,2.82731,37.88543,40.50839,0.28935,0.06732
4.89000,2.86512,38.13545,40.75842,0.29113,0.06822
4.92000,2.69935,38.38541,41.00837,0.29292,0.06427
4.95000,2.75411,38.63532,41.25829,0.29470,0.06557
4.98000,2.76733,38.88526,41.50822,0.29649,0.06589
5.01000,2.77702,39.13536,41.75832,0.29827,0.06612
5.04000,2.92938,39.38543,42.00839,0.30006,0.06975
5.07000,3.17767,39.63539,42.25835,0.30185,0.07566
5.10000,3.53958,39.88538,42.50835,0.30363,0.08428
5.13000,3.23039,40.13524,42.75821,0.30542,0.07691
5.16000,3.18885,40.38520,43.00816,0.30720,0.07592
5.19000,3.27248,40.63530,43.25827,0.30899,0.07792
5.22000,3.22033,40.88545,43.50842,0.31077,0.07667
5.25000,3.18214,41.13547,43.75844,0.31256,0.07577
5.28000,3.23225,41.38541,44.00837,0.31435,0.07696
5.31000,3.44403,41.63532,44.25829,0.31613,0.08200
5.34000,3.39895,41.88528,44.50825,0.31792,0.08093
5.37000,3.30359,42.13533,44.75829,0.31970,0.07866
5.40000,3.23523,42.38540,45.00837,0.32149,0.07703
5.43000,3.13073,42.63545,45.25841,0.32327,0.07454
5.46000,3.20133,42.88538,45.50835,0.32506,0.07622
5.49000,3.39560,43.13532,45.75828,0.32684,0.08085
5.52000,3.40790,43.38528,46.00825,0.32863,0.08114
5.55000,3.30824,43.63533,46.25829,0.33042,0.07877
5.58000,3.71430,43.88540,46.50836,0.33220,0.08844
5.61000,3.69158,44.13545,46.75841,0.33399,0.08789
5.64000,3.59006,44.38535,47.00832,0.33577,0.08548
5.67000,3.47644,44.63529,47.25826,0.33756,0.08277
5.70000,3.82941,44.88528,47.50824,0.33934,0.09118
5.73000,3.84599,45.13533,47.75829,0.34113,0.09157
5.76000,3.66382,45.38545,48.00841,0.34292,0.08723
5.79000,3.59174,45.63544,48.25841,0.34470,0.08552
5.82000,3.44981,45.88532,48.50829,0.34649,0.08214
5.85000,3.71281,46.13529,48.75825,0.34827,0.08840
5.88000,3.73013,46.38534,49.00830,0.35006,0.08881
5.91000,3.81134,46.63533,49.25829,0.35184,0.09075
5.94000,3.60869,46.88534,49.50830,0.35363,0.08592
5.97000,3.83351,47.13547,49.75843,0.35542,0.09127
6.00000,4.15649,47.38538,50.00835,0.35720,0.09896
6.03000,4.10937,47.63529,50.25825,0.35899,0.09784
6.06000,3.78564,47.88531,50.50827,0.36077,0.09013
6.09000,3.82159,48.13538,50.75834,0.36256,0.09099
6.12000,3.86722,48.38542,51.00838,0.36435,0.09208
6.15000,3.69810,48.63539,51.25835,0.36613,0.08805
6.18000,3.51220,48.88535,51.50831,0.36792,0.08362
6.21000,3.75379,49.13526,51.75823,0.36970,0.08938
6.24000,3.86406,49.38526,52.00822,0.37149,0.09200
6.27000,4.21423,49.63538,52.25834,0.37327,0.10034
6.30000,4.34835,49.88545,52.50841,0.37506,0.10353
6.33000,4.10303,50.13542,52.75838,0.37685,0.09769
6.36000,4.10862,50.38535,53.00832,0.37863,0.09782
6.39000,4.39882,50.63526,53.25822,0.38042,0.10473
6.42000,4.45489,50.88522,53.50819,0.38220,0.10607
6.45000,4.04585,51.13535,53.75831,0.38399,0.09633
6.48000,4.28874,51.38545,54.00841,0.38577,0.10211
6.51000,4.24050,51.63547,54.25843,0.38756,0.10096
6.54000,4.20306,51.88538,54.50834,0.38935,0.10007
6.57000,4.37163,52.13526,54.75823,0.39113,0.10409
6.60000,4.15444,52.38522,55.00818,0.39292,0.09892
6.63000,4.35393,52.63540,55.25837,0.39470,0.10367
6.66000,4.36828,52.88545,55.50841,0.39649,0.10401
6.69000,4.28688,53.13541,55.75837,0.39827,0.10207
6.72000,4.28185,53.38538,56.00834,0.40006,0.10195
6.75000,4.07230,53.63531,56.25828,0.40184,0.09696
6.78000,4.40665,53.88525,56.50822,0.40363,0.10492
6.81000,4.60017,54.13535,56.75831,0.40542,0.10953
6.84000,4.52176,54.38548,57.00844,0.40720,0.10766
6.87000,4.95669,54.63547,57.25843,0.40899,0.11802
6.90000,4.87566,54.88535,57.50831,0.41077,0.11609
6.93000,4.48581,55.13526,57.75823,0.41256,0.10680
6.96000,4.49922,55.38526,58.00822,0.41434,0.10712
6.99000,4.80674,55.63532,58.25829,0.41613,0.11445
7.02000,4.92055,55.88545,58.50841,0.41792,0.11716
7.05000,4.58546,56.13549,58.75846,0.41970,0.10918
7.08000,4.41670,56.38538,59.00834,0.42149,0.10516
7.11000,4.95780,56.63526,59.25822,0.42327,0.11804
7.14000,5.00660,56.88525,59.50822,0.42506,0.11920
7.17000,5.17387,57.13527,59.75823,0.42684,0.12319
7.20000,4.52530,57.38540,60.00836,0.42863,0.10775
7.23000,4.51393,57.63552,60.25849,0.43042,0.10747
7.26000,4.88833,57.88543,60.50840,0.43220,0.11639
7.29000,4.77768,58.13529,60.75825,0.43399,0.11375
7.32000,4.58863,58.38525,61.00821,0.43577,0.10925
7.35000,4.86244,58.63532,61.25829,0.43756,0.11577
7.38000,4.77862,58.88545,61.50841,0.43935,0.11378
7.41000,4.53088,59.13547,61.75842,0.44113,0.10788
7.44000,4.74229,59.38540,62.00837,0.44292,0.11291
7.47000,4.76707,59.63528,62.25825,0.44470,0.11350
7.50000,4.47314,59.88528,62.50824,0.44649,0.10650
7.53000,4.53368,60.13535,62.75832,0.44827,0.10794
7.56000,4.84027,60.38539,63.00835,0.45006,0.11524
7.59000,4.84698,60.63544,63.25840,0.45185,0.11540
7.62000,5.08800,60.88540,63.50837,0.45363,0.12114
7.65000,5.06639,61.13531,63.75827,0.45542,0.12063
7.68000,4.92986,61.38525,64.00822,0.45720,0.11738
7.71000,5.20032,61.63532,64.25829,0.45899,0.12382
7.74000,5.00698,61.88539,64.50835,0.46077,0.11921
7.77000,4.88497,62.13543,64.75840,0.46256,0.11631
7.80000,5.04497,62.38543,65.00839,0.46435,0.12012
7.83000,5.25676,62.63531,65.25828,0.46613,0.12516
7.86000,4.97364,62.88527,65.50824,0.46792,0.11842
7.89000,4.78793,63.13538,65.75834,0.46970,0.11400
7.92000,4.85685,63.38544,66.00840,0.47149,0.11564
7.95000,4.80898,63.63538,66.25835,0.47327,0.11450
7.98000,4.85871,63.88537,66.50834,0.47506,0.11568
8.01000,4.83897,64.13536,66.75832,0.47685,0.11521
8.04000,5.23608,64.38530,67.00826,0.47863,0.12467
8.07000,5.34728,64.63535,67.25831,0.48042,0.12732
8.10000,5.12302,64.88544,67.50840,0.48220,0.12198
8.13000,5.00176,65.13544,67.75840,0.48399,0.11909
8.16000,5.07385,65.38534,68.00830,0.48577,0.12081
8.19000,5.05056,65.63525,68.25822,0.48756,0.12025
8.22000,5.21131,65.88525,68.50822,0.48934,0.12408
8.25000,5.23981,66.13534,68.75831,0.49113,0.12476
8.28000,5.65294,66.38542,69.00838,0.49292,0.13459
8.31000,5.50263,66.63546,69.25842,0.49470,0.13101
8.34000,5.03100,66.88537,69.50834,0.49649,0.11979
8.37000,4.65885,67.13529,69.75826,0.49827,0.11092
8.40000,4.94234,67.38529,70.00826,0.50006,0.11767
8.43000,4.95706,67.63537,70.25832,0.50185,0.11803
8.46000,4.97494,67.88547,70.50843,0.50363,0.11845
8.49000,4.96507,68.13544,70.75840,0.50542,0.11822
8.52000,5.16083,68.38537,71.00833,0.50720,0.12288
8.55000,4.79557,68.63531,71.25827,0.50899,0.11418
8.58000,4.77899,68.88532,71.50829,0.51077,0.11379
8.61000,5.04237,69.13532,71.75828,0.51256,0.12006
8.64000,5.07087,69.38539,72.00835,0.51435,0.12073
8.67000,4.91291,69.63548,72.25845,0.51613,0.11697
8.70000,4.97513,69.88534,72.50831,0.51792,0.11846
8.73000,5.21857,70.13522,72.75818,0.51970,0.12425
8.76000,4.96451,70.38527,73.00824,0.52149,0.11820
8.79000,5.11166,70.63535,73.25831,0.52327,0.12171
8.82000,5.09527,70.88542,73.50838,0.52506,0.12132
8.85000,5.15673,71.13546,73.75842,0.52685,0.12278
8.88000,5.20721,71.38539,74.00835,0.52863,0.12398
8.91000,5.53466,71.63528,74.25824,0.53042,0.13178
8.94000,5.35846,71.88527,74.50823,0.53220,0.12758
8.97000,5.23459,72.13534,74.75830,0.53399,0.12463
9.00000,5.43669,72.38544,75.00840,0.53577,0.12944
9.03000,5.42607,72.63546,75.25842,0.53756,0.12919
9.06000,5.49685,72.88540,75.50836,0.53935,0.13088
9.09000,5.27762,73.13531,75.75827,0.54113,0.12566
9.12000,5.27073,73.38527,76.00824,0.54292,0.12549
9.15000,5.63245,73.63536,76.25833,0.54470,0.13411
9.18000,5.56223,73.88547,76.50844,0.54649,0.13243
9.21000,5.55161,74.13543,76.75839,0.54827,0.13218
9.24000,5.53224,74.38534,77.00831,0.55006,0.13172
9.27000,5.52144,74.63525,77.25821,0.55184,0.13146
9.30000,5.45681,74.88524,77.50821,0.55363,0.12992
9.33000,5.19566,75.13537,77.75833,0.55542,0.12371
9.36000,5.22677,75.38544,78.00841,0.55720,0.12445
9.39000,5.61550,75.63543,78.25839,0.55899,0.13370
9.42000,5.67120,75.88537,78.50833,0.56077,0.13503
9.45000,5.41005,76.13528,78.75824,0.56256,0.12881
9.48000,5.60042,76.38524,79.00820,0.56434,0.13334
9.51000,5.65555,76.63536,79.25833,0.56613,0.13466
9.54000,5.43725,76.88546,79.50843,0.56792,0.12946
9.57000,5.56838,77.13546,79.75842,0.56970,0.13258
9.60000,5.67865,77.38534,80.00831,0.57149,0.13521
9.63000,5.60470,77.63528,80.25824,0.57327,0.13345
9.66000,5.72354,77.88530,80.50826,0.57506,0.13627
9.69000,5.50002,78.13533,80.75830,0.57684,0.13095
9.72000,5.62128,78.38544,81.00841,0.57863,0.13384
9.75000,5.59445,78.63546,81.25842,0.58042,0.13320
9.78000,5.66021,78.88540,81.50836,0.58220,0.13477
9.81000,5.68908,79.13527,81.75824,0.58399,0.13545
9.84000,5.68125,79.38529,82.00825,0.58577,0.13527
9.87000,5.87106,79.63531,82.25828,0.58756,0.13979
9.90000,5.97313,79.88544,82.50839,0.58935,0.14222
9.93000,5.98542,80.13551,82.75847,0.59113,0.14251
9.96000,5.99120,80.38539,83.00835,0.59292,0.14265
9.99000,6.21285,80.63520,83.25816,0.59470,0.14793
10.02000,6.15008,80.88524,83.50820,0.59649,0.14643
10.05000,6.25383,81.13539,83.75835,0.59827,0.14890
10.08000,5.99641,81.38544,84.00840,0.60006,0.14277
10.11000,6.23185,81.63548,84.25845,0.60185,0.14838
10.14000,6.28214,81.88539,84.50836,0.60363,0.14957
10.17000,6.67386,82.13527,84.75823,0.60542,0.15890
10.20000,6.30207,82.38524,85.00820,0.60720,0.15005
10.23000,6.03124,82.63531,85.25828,0.60899,0.14360
10.26000,6.91153,82.88541,85.50838,0.61077,0.16456
10.29000,7.10264,83.13548,85.75845,0.61256,0.16911
10.32000,7.20993,83.38544,86.00840,0.61435,0.17166
10.35000,7.04844,83.63533,86.25829,0.61613,0.16782
10.38000,6.76494,83.88526,86.50822,0.61792,0.16107
10.41000,6.67702,84.13533,86.75829,0.61970,0.15898
10.44000,6.73272,84.38541,87.00836,0.62149,0.16030
10.47000,6.76252,84.63543,87.25839,0.62327,0.16101
10.50000,6.76978,84.88541,87.50838,0.62506,0.16119
10.53000,7.20788,85.13530,87.75826,0.62684,0.17162
10.56000,7.18944,85.38526,88.00823,0.62863,0.17118
10.59000,7.26469,85.63536,88.25833,0.63042,0.17297
10.62000,7.29021,85.88541,88.50838,0.63220,0.17358
10.65000,7.26432,86.13537,88.75833,0.63399,0.17296
10.68000,6.94618,86.38539,89.00835,0.63577,0.16539
10.71000,7.12369,86.63535,89.25832,0.63756,0.16961
10.74000,7.30325,86.88524,89.50821,0.63934,0.17389
10.77000,7.43773,87.13531,89.75828,0.64113,0.17709
10.80000,7.49733,87.38546,90.00842,0.64292,0.17851
10.83000,7.62530,87.63543,90.25839,0.64470,0.18155
10.86000,7.48485,87.88536,90.50832,0.64649,0.17821
10.89000,7.37254,88.13535,90.75832,0.64827,0.17554
10.92000,7.52304,88.38532,91.00828,0.65006,0.17912
10.95000,7.69701,88.63536,91.25832,0.65185,0.18326
10.98000,7.28965,88.88543,91.50839,0.65363,0.17356
11.01000,7.26935,89.13542,91.75838,0.65542,0.17308
11.04000,7.47461,89.38533,92.00829,0.65720,0.17797
11.07000,7.66404,89.63530,92.25826,0.65899,0.18248
11.10000,7.05291,89.88531,92.50828,0.66077,0.16793
11.13000,7.40662,90.13539,92.75835,0.66256,0.17635
11.16000,7.59270,90.38541,93.00837,0.66435,0.18078
11.19000,7.67391,90.63543,93.25838,0.66613,0.18271
11.22000,7.48765,90.88533,93.50829,0.66792,0.17828
11.25000,7.28518,91.13524,93.75820,0.66970,0.17346
11.28000,7.74022,91.38526,94.00823,0.67149,0.18429
11.31000,7.79275,91.63534,94.25830,0.67327,0.18554
11.34000,7.73072,91.88546,94.50842,0.67506,0.18406
11.37000,7.85366,92.13548,94.75845,0.67685,0.18699
11.40000,7.60965,92.38536,95.00832,0.67863,0.18118
11.43000,7.53067,92.63529,95.25826,0.68042,0.17930
11.46000,7.63051,92.88531,95.50828,0.68220,0.18168
11.49000,7.57035,93.13538,95.75835,0.68399,0.18025
11.52000,7.84285,93.38543,96.00839,0.68577,0.18673
11.55000,7.90060,93.63545,96.25841,0.68756,0.18811
11.58000,7.66069,93.88539,96.50835,0.68935,0.18240
11.61000,7.85589,94.13527,96.75822,0.69113,0.18705
11.64000,7.80150,94.38528,97.00825,0.69292,0.18575
11.67000,7.70465,94.63536,97.25832,0.69470,0.18344
11.70000,7.87247,94.88543,97.50839,0.69649,0.18744
11.73000,7.85217,95.13545,97.75842,0.69827,0.18696
11.76000,7.87396,95.38536,98.00832,0.70006,0.18748
11.79000,7.55042,95.63524,98.25820,0.70184,0.17977
11.82000,7.66050,95.88523,98.50820,0.70363,0.18239
11.85000,8.06004,96.13536,98.75832,0.70542,0.19191
11.88000,7.95629,96.38548,99.00845,0.70720,0.18944
11.91000,7.90171,96.63545,99.25842,0.70899,0.18814
11.94000,7.62865,96.88539,99.50835,0.71077,0.18163
11.97000,8.07866,97.13533,99.75829,0.71256,0.19235
12.00000,7.83466,97.38526,100.00822,0.71434,0.18654
12.03000,7.76928,97.63534,100.25829,0.71613,0.18498
12.06000,7.51968,97.88548,100.50845,0.71792,0.17904
12.09000,7.72141,98.13550,100.75846,0.71970,0.18384
12.12000,7.94102,98.38538,101.00835,0.72149,0.18907
12.15000,7.86241,98.63529,101.25825,0.72327,0.18720
12.18000,7.99187,98.88526,101.50822,0.72506,0.19028
12.21000,7.89780,99.13536,101.75832,0.72685,0.18804
12.24000,7.80839,99.38545,102.00841,0.72863,0.18591
12.27000,7.74991,99.63542,102.25838,0.73042,0.18452
12.30000,8.29455,99.88536,102.50832,0.73220,0.19749
12.33000,8.41636,100.13529,102.75826,0.73399,0.20039
12.36000,8.14479,100.38526,103.00822,0.73577,0.19392
12.39000,8.25748,100.63530,103.25826,0.73756,0.19661
12.42000,7.93692,100.88543,103.50838,0.73935,0.18897
12.45000,7.42264,101.13547,103.75843,0.74113,0.17673
12.48000,7.42190,101.38538,104.00835,0.74292,0.17671
12.51000,7.64467,101.63529,104.25825,0.74470,0.18202
12.54000,7.79293,101.88529,104.50825,0.74649,0.18555
12.57000,7.61170,102.13532,104.75829,0.74827,0.18123
12.60000,7.72923,102.38548,105.00845,0.75006,0.18403
12.63000,7.98963,102.63552,105.25848,0.75185,0.19023
12.66000,8.03173,102.88538,105.50834,0.75363,0.19123
12.69000,8.38861,103.13524,105.75820,0.75542,0.19973
12.72000,8.30330,103.38531,106.00827,0.75720,0.19770
12.75000,7.93561,103.63535,106.25832,0.75899,0.18894
12.78000,7.86725,103.88537,106.50834,0.76077,0.18732
12.81000,8.06917,104.13545,106.75841,0.76256,0.19212
12.84000,8.16099,104.38541,107.00837,0.76435,0.19431
12.87000,7.98777,104.63529,107.25826,0.76613,0.19018
12.90000,7.84043,104.88525,107.50822,0.76792,0.18668
12.93000,8.16025,105.13536,107.75832,0.76970,0.19429
12.96000,8.28244,105.38540,108.00836,0.77149,0.19720
12.99000,8.41115,105.63544,108.25840,0.77327,0.20027
13.02000,8.14777,105.88538,108.50835,0.77506,0.19399
13.05000,8.04234,106.13524,108.75821,0.77684,0.19148
13.08000,8.17161,106.38526,109.00822,0.77863,0.19456
13.11000,8.01608,106.63538,109.25835,0.78042,0.19086
13.14000,8.09301,106.88545,109.50841,0.78220,0.19269
13.17000,8.04067,107.13549,109.75845,0.78399,0.19144
13.20000,8.17627,107.38541,110.00837,0.78577,0.19467
13.23000,8.09114,107.63532,110.25828,0.78756,0.19265
13.26000,8.16863,107.88528,110.50824,0.78934,0.19449
13.29000,7.99280,108.13532,110.75829,0.79113,0.19030
13.32000,7.96597,108.38543,111.00838,0.79292,0.18967
13.35000,8.32714,108.63544,111.25840,0.79470,0.19827
13.38000,8.10884,108.88544,111.50840,0.79649,0.19307
13.41000,7.93096,109.13534,111.75830,0.79827,0.18883
13.44000,8.06190,109.38526,112.00822,0.80006,0.19195
13.47000,7.92015,109.63533,112.25830,0.80184,0.18858
13.50000,8.19284,109.88542,112.50838,0.80363,0.19507
13.53000,8.33180,110.13541,112.75838,0.80542,0.19838
13.56000,8.21352,110.38535,113.00832,0.80720,0.19556
13.59000,8.03880,110.63529,113.25825,0.80899,0.19140
13.62000,8.03880,110.88525,113.50821,0.81077,0.19140
13.65000,8.16472,111.13533,113.75829,0.81256,0.19440
13.68000,8.25543,111.38542,114.00838,0.81435,0.19656
13.71000,8.31112,111.63541,114.25837,0.81613,0.19788
13.74000,8.66074,111.88536,114.50832,0.81792,0.20621
13.77000,8.29585,112.13531,114.75826,0.81970,0.19752
13.80000,8.20439,112.38531,115.00828,0.82149,0.19534
13.83000,7.96113,112.63535,115.25832,0.82327,0.18955
13.86000,8.21184,112.88542,115.50838,0.82506,0.19552
13.89000,8.28318,113.13549,115.75846,0.82685,0.19722
13.92000,8.41580,113.38537,116.00833,0.82863,0.20038
13.95000,8.16230,113.63528,116.25824,0.83042,0.19434
13.98000,8.38824,113.88531,116.50827,0.83220,0.19972
14.01000,8.38954,114.13538,116.75833,0.83399,0.19975
14.04000,8.57227,114.38539,117.00835,0.83577,0.20410
14.07000,8.53818,114.63539,117.25835,0.83756,0.20329
14.10000,8.50298,114.88535,117.50831,0.83935,0.20245
14.13000,8.49739,115.13529,117.75826,0.84113,0.20232
14.16000,8.28970,115.38527,118.00823,0.84292,0.19737
14.19000,8.37054,115.63538,118.25834,0.84470,0.19930
14.22000,8.43219,115.88542,118.50838,0.84649,0.20077
14.25000,8.29734,116.13544,118.75840,0.84827,0.19756
14.28000,8.27145,116.38534,119.00831,0.85006,0.19694
14.31000,8.39662,116.63524,119.25821,0.85184,0.19992
14.34000,8.57525,116.88528,119.50825,0.85363,0.20417
14.37000,8.57320,117.13537,119.75832,0.85542,0.20412
14.40000,8.42735,117.38545,120.00842,0.85720,0.20065
14.43000,8.53892,117.63546,120.25843,0.85899,0.20331
14.46000,8.87997,117.88540,120.50835,0.86077,0.21143
14.49000,8.73283,118.13525,120.75821,0.86256,0.20792
14.52000,8.80510,118.38524,121.00820,0.86434,0.20965
14.55000,8.85539,118.63537,121.25833,0.86613,0.21084
14.58000,8.84999,118.88545,121.50841,0.86792,0.21071
14.61000,8.80752,119.13544,121.75841,0.86970,0.20970
14.64000,8.87271,119.38540,122.00835,0.87149,0.21125
14.67000,8.79355,119.63528,122.25826,0.87327,0.20937
14.70000,8.88556,119.88519,122.50815,0.87506,0.21156
14.73000,8.76635,120.13532,122.75828,0.87684,0.20872
14.76000,8.63783,120.38549,123.00845,0.87863,0.20566
14.79000,9.08338,120.63547,123.25842,0.88042,0.21627
14.82000,8.96547,120.88530,123.50826,0.88220,0.21346
14.85000,8.82950,121.13526,123.75822,0.88399,0.21023
14.88000,8.74400,121.38525,124.00822,0.88577,0.20819
14.91000,9.04724,121.63531,124.25827,0.88756,0.21541
14.94000,8.94703,121.88547,124.50843,0.88935,0.21302
14.97000,8.66074,122.13548,124.75844,0.89113,0.20621
15.00000,9.22196,122.38539,125.00835,0.89292,0.21957
15.03000,9.21693,122.63531,125.25827,0.89470,0.21945
15.06000,9.01576,122.88525,125.50821,0.89649,0.21466
15.09000,9.12230,123.13529,125.75825,0.89827,0.21720
15.12000,9.28938,123.38547,126.00843,0.90006,0.22118
15.15000,9.13478,123.63551,126.25847,0.90185,0.21749
15.18000,8.54861,123.88540,126.50837,0.90363,0.20354
15.21000,9.35066,124.13530,126.75826,0.90542,0.22263
15.24000,9.52836,124.38524,127.00821,0.90720,0.22687
15.27000,9.35141,124.63529,127.25825,0.90899,0.22265
15.30000,9.03513,124.88541,127.50838,0.91077,0.21512
15.33000,9.19122,125.13542,127.75839,0.91256,0.21884
15.36000,9.14782,125.38535,128.00832,0.91435,0.21781
15.39000,9.06568,125.63528,128.25824,0.91613,0.21585
15.42000,9.29497,125.88527,128.50822,0.91792,0.22131
15.45000,9.04519,126.13530,128.75826,0.91970,0.21536
15.48000,8.98764,126.38536,129.00833,0.92149,0.21399
15.51000,8.99546,126.63548,129.25844,0.92327,0.21418
15.54000,9.23369,126.88541,129.50839,0.92506,0.21985
15.57000,9.34172,127.13528,129.75824,0.92684,0.22242
15.60000,9.23034,127.38526,130.00822,0.92863,0.21977
15.63000,9.30335,127.63536,130.25833,0.93042,0.22151
15.66000,9.31304,127.88540,130.50838,0.93220,0.22174
15.69000,9.59411,128.13547,130.75842,0.93399,0.22843
15.72000,9.64198,128.38543,131.00839,0.93577,0.22957
15.75000,9.44287,128.63527,131.25824,0.93756,0.22483
15.78000,9.33651,128.88527,131.50824,0.93934,0.22230
15.81000,9.08542,129.13538,131.75833,0.94113,0.21632
15.84000,9.38289,129.38539,132.00835,0.94292,0.22340
15.87000,9.60566,129.63539,132.25836,0.94470,0.22871
15.90000,9.41884,129.88539,132.50835,0.94649,0.22426
15.93000,9.24412,130.13533,132.75830,0.94827,0.22010
15.96000,9.28771,130.38526,133.00822,0.95006,0.22114
15.99000,9.56245,130.63532,133.25827,0.95184,0.22768
16.02000,9.75449,130.88541,133.50836,0.95363,0.23225
16.05000,9.44864,131.13545,133.75841,0.95542,0.22497
16.08000,9.55127,131.38536,134.00833,0.95720,0.22741
16.11000,9.74443,131.63525,134.25821,0.95899,0.23201
16.14000,9.88804,131.88527,134.50822,0.96077,0.23543
16.17000,9.59001,132.13537,134.75833,0.96256,0.22833
16.20000,9.51905,132.38546,135.00844,0.96435,0.22664
16.23000,9.49521,132.63548,135.25845,0.96613,0.22608
16.26000,9.96850,132.88539,135.50835,0.96792,0.23735
16.29000,9.84203,133.13532,135.75830,0.96970,0.23433
16.32000,9.83123,133.38524,136.00821,0.97149,0.23408
16.35000,9.93647,133.63532,136.25829,0.97327,0.23658
16.38000,9.87370,133.88543,136.50839,0.97506,0.23509
16.41000,9.83644,134.13543,136.75841,0.97685,0.23420
16.44000,10.02531,134.38534,137.00830,0.97863,0.23870
16.47000,10.08622,134.63530,137.25827,0.98042,0.24015
16.50000,10.27435,134.88530,137.50826,0.98220,0.24463
16.53000,10.05642,135.13531,137.75827,0.98399,0.23944
16.56000,9.86997,135.38542,138.00838,0.98577,0.23500
16.59000,9.86550,135.63546,138.25842,0.98756,0.23489
16.62000,9.77572,135.88532,138.50827,0.98934,0.23276
16.65000,9.79435,136.13525,138.75822,0.99113,0.23320
16.68000,10.12478,136.38530,139.00826,0.99292,0.24107
16.71000,10.02010,136.63537,139.25833,0.99470,0.23857
16.74000,9.87500,136.88541,139.50838,0.99649,0.23512
16.77000,10.19519,137.13542,139.75838,0.99827,0.24274
16.80000,10.18811,137.38542,140.00838,1.00006,0.24257
16.83000,10.07486,137.63529,140.25826,1.00184,0.23988
16.86000,9.95304,137.88527,140.50822,1.00363,0.23698
16.89000,9.78224,138.13536,140.75833,1.00542,0.23291
16.92000,10.03500,138.38546,141.00844,1.00720,0.23893
16.95000,10.27584,138.63545,141.25841,1.00899,0.24466
16.98000,10.46471,138.88537,141.50833,1.01077,0.24916
17.01000,10.16762,139.13528,141.75826,1.01256,0.24209
17.04000,10.42057,139.38526,142.00822,1.01434,0.24811
17.07000,10.38108,139.63536,142.25833,1.01613,0.24717
17.10000,10.02438,139.88540,142.50838,1.01792,0.23868
17.13000,10.22574,140.13540,142.75836,1.01970,0.24347
17.16000,10.35873,140.38536,143.00833,1.02149,0.24664
17.19000,10.26150,140.63525,143.25821,1.02327,0.24432
17.22000,10.01284,140.88527,143.50824,1.02506,0.23840
17.25000,10.02103,141.13539,143.75835,1.02685,0.23860
17.28000,10.47924,141.38544,144.00841,1.02863,0.24951
17.31000,10.18681,141.63546,144.25842,1.03042,0.24254
17.34000,10.20730,141.88537,144.50833,1.03220,0.24303
17.37000,10.46509,142.13525,144.75822,1.03399,0.24917
17.40000,10.61801,142.38524,145.00819,1.03577,0.25281
17.43000,10.27007,142.63539,145.25836,1.03756,0.24453
17.46000,10.28143,142.88551,145.50847,1.03935,0.24480
17.49000,10.26262,143.13545,145.75841,1.04113,0.24435
17.52000,10.25572,143.38536,146.00832,1.04292,0.24418
17.55000,10.44087,143.63529,146.25826,1.04470,0.24859
17.58000,10.47011,143.88527,146.50822,1.04649,0.24929
17.61000,10.26820,144.13533,146.75830,1.04827,0.24448
17.64000,10.46527,144.38546,147.00842,1.05006,0.24917
17.67000,10.78565,144.63545,147.25841,1.05185,0.25680
17.70000,10.69885,144.88533,147.50830,1.05363,0.25473
17.73000,10.54015,145.13524,147.75819,1.05542,0.25096
17.76000,10.77354,145.38524,148.00821,1.05720,0.25651
17.79000,10.47701,145.63526,148.25821,1.05899,0.24945
17.82000,10.63198,145.88543,148.50839,1.06077,0.25314
17.85000,10.83147,146.13547,148.75842,1.06256,0.25789
17.88000,10.61987,146.38536,149.00832,1.06435,0.25285
17.91000,10.54537,146.63527,149.25824,1.06613,0.25108
17.94000,10.53307,146.88529,149.50824,1.06792,0.25079
17.97000,10.78360,147.13535,149.75832,1.06970,0.25675
18.00000,10.95999,147.38546,150.00842,1.07149,0.26095
18.03000,10.58634,147.63550,150.25847,1.07327,0.25206
18.06000,11.05014,147.88542,150.50839,1.07506,0.26310
18.09000,11.00488,148.13530,150.75826,1.07684,0.26202
18.12000,10.91864,148.38524,151.00819,1.07863,0.25997
18.15000,10.92143,148.63526,151.25822,1.08042,0.26003
18.18000,10.59547,148.88543,151.50839,1.08220,0.25227
18.21000,10.83426,149.13551,151.75848,1.08399,0.25796
18.24000,11.08330,149.38542,152.00839,1.08577,0.26389
18.27000,11.08646,149.63529,152.25826,1.08756,0.26396
18.30000,10.73219,149.88523,152.50819,1.08934,0.25553
18.33000,10.92274,150.13530,152.75827,1.09113,0.26007
18.36000,10.93131,150.38536,153.00833,1.09292,0.26027
18.39000,10.99799,150.63540,153.25836,1.09470,0.26186
18.42000,11.32078,150.88541,153.50836,1.09649,0.26954
18.45000,10.94118,151.13531,153.75829,1.09827,0.26050
18.48000,11.05219,151.38526,154.00821,1.10006,0.26315
18.51000,10.91789,151.63539,154.25836,1.10185,0.25995
18.54000,10.93950,151.88543,154.50839,1.10363,0.26046
18.57000,11.11440,152.13545,154.75841,1.10542,0.26463
18.60000,11.05946,152.38544,155.00839,1.10720,0.26332
18.63000,11.29098,152.63535,155.25830,1.10899,0.26883
18.66000,11.35170,152.88527,155.50822,1.11077,0.27028
18.69000,11.46570,153.13534,155.75830,1.11256,0.27299
18.72000,11.49867,153.38545,156.00841,1.11435,0.27378
18.75000,11.26286,153.63542,156.25839,1.11613,0.26816
18.78000,11.17159,153.88535,156.50832,1.11792,0.26599
18.81000,11.43888,154.13530,156.75826,1.11970,0.27235
18.84000,11.38616,154.38529,157.00824,1.12149,0.27110
18.87000,11.48973,154.63533,157.25829,1.12327,0.27356
18.90000,11.81327,154.88538,157.50835,1.12506,0.28127
18.93000,11.83655,155.13542,157.75838,1.12685,0.28182
18.96000,11.71604,155.38538,158.00833,1.12863,0.27895
18.99000,11.73615,155.63529,158.25826,1.13042,0.27943
19.02000,11.80675,155.88529,158.50826,1.13220,0.28111
19.05000,11.77154,156.13533,158.75829,1.13399,0.28027
19.08000,11.81886,156.38543,159.00839,1.13577,0.28140
19.11000,11.66780,156.63544,159.25841,1.13756,0.27780
19.14000,11.30402,156.88533,159.50829,1.13934,0.26914
19.17000,11.58174,157.13531,159.75827,1.14113,0.27576
19.20000,11.56684,157.38535,160.00830,1.14292,0.27540
19.23000,11.87734,157.63539,160.25835,1.14470,0.28279
19.26000,11.83730,157.88545,160.50841,1.14649,0.28184
19.29000,12.17816,158.13546,160.75842,1.14827,0.28996
19.32000,11.74863,158.38533,161.00829,1.15006,0.27973
19.35000,11.63799,158.63530,161.25827,1.15184,0.27710
19.38000,11.81588,158.88531,161.50827,1.15363,0.28133
19.41000,11.47203,159.13534,161.75830,1.15542,0.27314
19.44000,11.78756,159.38540,162.00836,1.15720,0.28066
19.47000,12.08093,159.63544,162.25839,1.15899,0.28764
19.50000,12.33462,159.88539,162.50836,1.16077,0.29368
19.53000,12.27446,160.13523,162.75819,1.16256,0.29225
19.56000,12.42235,160.38526,163.00822,1.16434,0.29577
19.59000,12.19623,160.63538,163.25833,1.16613,0.29039
19.62000,12.19381,160.88543,163.50841,1.16792,0.29033
19.65000,12.21392,161.13544,163.75841,1.16970,0.29081
19.68000,12.20293,161.38538,164.00833,1.17149,0.29055
19.71000,12.10719,161.63528,164.25824,1.17327,0.28827
19.74000,12.33947,161.88525,164.50822,1.17506,0.29380
19.77000,12.04275,162.13538,164.75835,1.17685,0.28673
19.80000,12.33146,162.38546,165.00842,1.17863,0.29361
19.83000,12.47413,162.63543,165.25841,1.18042,0.29700
19.86000,12.29327,162.88537,165.50833,1.18220,0.29270
19.89000,12.38398,163.13529,165.75826,1.18399,0.29486
19.92000,12.53914,163.38525,166.00822,1.18577,0.29855
19.95000,12.57285,163.63538,166.25835,1.18756,0.29935
19.98000,12.11483,163.88548,166.50844,1.18935,0.28845
20.01000,12.34654,164.13546,166.75842,1.19113,0.29397
20.04000,12.00102,164.38536,167.00833,1.19292,0.28574
20.07000,12.33276,164.63523,167.25819,1.19470,0.29364
20.10000,12.33406,164.88523,167.50819,1.19649,0.29367
20.13000,12.34841,165.13535,167.75830,1.19827,0.29401
20.16000,12.43055,165.38541,168.00839,1.20006,0.29597
20.19000,12.61700,165.63539,168.25836,1.20185,0.30040
20.22000,12.52629,165.88538,168.50835,1.20363,0.29824
20.25000,12.29737,166.13532,168.75829,1.20542,0.29279
20.28000,12.67698,166.38529,169.00824,1.20720,0.30183
20.31000,12.60694,166.63535,169.25832,1.20899,0.30017
20.34000,12.25751,166.88547,169.50844,1.21077,0.29185
20.37000,12.65667,167.13547,169.75842,1.21256,0.30135
20.40000,12.74720,167.38535,170.00832,1.21435,0.30350
20.43000,12.59781,167.63529,170.25824,1.21613,0.29995
20.46000,12.69449,167.88531,170.50827,1.21792,0.30225
20.49000,13.07242,168.13535,170.75832,1.21970,0.31125
20.52000,12.77924,168.38549,171.00845,1.22149,0.30427
20.55000,12.87498,168.63552,171.25850,1.22327,0.30655
20.58000,12.86790,168.88537,171.50833,1.22506,0.30638
20.61000,12.96476,169.13527,171.75822,1.22684,0.30868
20.64000,12.94930,169.38525,172.00821,1.22863,0.30832
20.67000,12.76974,169.63531,172.25827,1.23042,0.30404
20.70000,12.94166,169.88538,172.50836,1.23220,0.30813
20.73000,13.25607,170.13549,172.75845,1.23399,0.31562
20.76000,13.39894,170.38540,173.00836,1.23577,0.31902
20.79000,13.53882,170.63526,173.25822,1.23756,0.32235
20.82000,13.54534,170.88520,173.50816,1.23934,0.32251
20.85000,13.36522,171.13530,173.75827,1.24113,0.31822
20.88000,13.47680,171.38544,174.00841,1.24292,0.32088
20.91000,12.92191,171.63547,174.25842,1.24470,0.30766
20.94000,12.92638,171.88535,174.50832,1.24649,0.30777
20.97000,12.66040,172.13528,174.75824,1.24827,0.30144
21.00000,12.86641,172.38530,175.00826,1.25006,0.30634
21.03000,12.71535,172.63536,175.25833,1.25185,0.30275
21.06000,12.76862,172.88544,175.50841,1.25363,0.30401
21.09000,12.95768,173.13549,175.75847,1.25542,0.30852
21.12000,12.56596,173.38543,176.00841,1.25720,0.29919
21.15000,12.58310,173.63531,176.25827,1.25899,0.29960
21.18000,12.95861,173.88525,176.50821,1.26077,0.30854
21.21000,13.18399,174.13531,176.75829,1.26256,0.31390
21.24000,13.16294,174.38539,177.00835,1.26435,0.31340
21.27000,13.29053,174.63542,177.25838,1.26613,0.31644
21.30000,13.17114,174.88543,177.50841,1.26792,0.31360
21.33000,13.40881,175.13530,177.75827,1.26970,0.31926
21.36000,13.04932,175.38523,178.00819,1.27149,0.31070
21.39000,13.37994,175.63530,178.25826,1.27327,0.31857
21.42000,13.26073,175.88534,178.50830,1.27506,0.31573
21.45000,12.91726,176.13532,178.75827,1.27684,0.30755
21.48000,13.07428,176.38538,179.00836,1.27863,0.31129
21.51000,13.23596,176.63536,179.25833,1.28042,0.31514
21.54000,13.26296,176.88533,179.50829,1.28220,0.31578
21.57000,13.32443,177.13537,179.75833,1.28399,0.31725
21.60000,13.27340,177.38548,180.00845,1.28577,0.31603
21.63000,13.46376,177.63548,180.25845,1.28756,0.32057
21.66000,13.51181,177.88540,180.50838,1.28935,0.32171
21.69000,13.78357,178.13535,180.75830,1.29113,0.32818
21.72000,13.81617,178.38530,181.00827,1.29292,0.32896
21.75000,13.76737,178.63535,181.25830,1.29470,0.32779
21.78000,13.89608,178.88543,181.50839,1.29649,0.33086
21.81000,13.78730,179.13543,181.75841,1.29827,0.32827
21.84000,14.08439,179.38534,182.00832,1.30006,0.33534
21.87000,13.87820,179.63527,182.25824,1.30184,0.33043
21.90000,13.69696,179.88530,182.50827,1.30363,0.32612
21.93000,13.64704,180.13531,182.75827,1.30542,0.32493
21.96000,14.08998,180.38535,183.00832,1.30720,0.33548
21.99000,13.93892,180.63541,183.25836,1.30899,0.33188
22.02000,13.87559,180.88533,183.50829,1.31077,0.33037
22.05000,13.70981,181.13529,183.75826,1.31256,0.32642
22.08000,14.04732,181.38533,184.00829,1.31434,0.33446
22.11000,13.93463,181.63537,184.25835,1.31613,0.33178
22.14000,13.88267,181.88547,184.50844,1.31792,0.33054
22.17000,14.13338,182.13549,184.75844,1.31970,0.33651
22.20000,13.92085,182.38534,185.00830,1.32149,0.33145
22.23000,14.08830,182.63525,185.25821,1.32327,0.33544
22.26000,14.08551,182.88536,185.50832,1.32506,0.33537
22.29000,14.33864,183.13542,185.75839,1.32685,0.34140
22.32000,14.30493,183.38544,186.00839,1.32863,0.34059
22.35000,14.29655,183.63546,186.25842,1.33042,0.34039
22.38000,13.90874,183.88537,186.50835,1.33220,0.33116
22.41000,14.28407,184.13522,186.75818,1.33399,0.34010
22.44000,14.36472,184.38522,187.00819,1.33577,0.34202
22.47000,14.37329,184.63535,187.25830,1.33756,0.34222
22.50000,14.13785,184.88544,187.50839,1.33935,0.33662
22.53000,14.24365,185.13540,187.75838,1.34113,0.33913
22.56000,14.21086,185.38534,188.00830,1.34292,0.33835
22.59000,13.95997,185.63523,188.25819,1.34470,0.33238
22.62000,14.06707,185.88521,188.50816,1.34649,0.33493
22.65000,14.67299,186.13539,188.75836,1.34827,0.34936
22.68000,8.44542,186.38552,189.00848,1.35006,0.20108
22.70800,-0.01509,186.61883,189.24181,1.35173,-0.00036