File: raw_data/mechanical_tests_Instron_data/Silicone_0035-Cross_1.is_tens_RawData/Specimen_RawData_1.csv
Dimension : Area,0.42000,cm^2

Time,Load,Extension,Tensile extension,Tensile strain,Tensile stress
(sec),(N),(mm),(mm),(mm/mm),(MPa)
0.00000,-0.05066,0.00000,0.00000,0.00000,-0.00121
0.05000,0.97323,0.09734,0.09734,0.00070,0.02317
0.10000,1.07195,0.41231,0.41231,0.00295,0.02552
0.15000,2.15620,0.88768,0.88768,0.00634,0.05134
0.20000,2.11690,1.40140,1.40140,0.01001,0.05040
0.25000,1.94293,1.93042,1.93042,0.01379,0.04626
0.30000,1.85203,2.46592,2.46592,0.01761,0.04410
0.35000,1.49179,2.92331,2.92331,0.02088,0.03552
0.40000,1.62348,3.33554,3.33554,0.02383,0.03865
0.45000,1.73245,3.75637,3.75637,0.02683,0.04125
0.50000,1.49217,4.17466,4.17466,0.02982,0.03553
0.55000,1.94628,4.59139,4.59139,0.03280,0.04634
0.60000,1.88816,5.00831,5.00831,0.03577,0.04496
0.65000,2.01575,5.42502,5.42502,0.03875,0.04799
0.70000,2.39871,5.84156,5.84156,0.04173,0.05711
0.75000,2.09715,6.25835,6.25835,0.04470,0.04993
0.80000,2.19401,6.67502,6.67502,0.04768,0.05224
0.85000,2.09007,7.09162,7.09162,0.05065,0.04976
0.90000,2.28081,7.50825,7.50825,0.05363,0.05430
0.95000,2.02265,7.92492,7.92492,0.05661,0.04816
1.00000,2.07368,8.34166,8.34166,0.05958,0.04937
1.05000,1.73617,8.75823,8.75823,0.06256,0.04134
1.10000,1.95689,9.17488,9.17488,0.06553,0.04659
1.15000,2.15080,9.59164,9.59164,0.06851,0.05121
1.20000,1.98316,10.00832,10.00832,0.07149,0.04722
1.25000,2.15042,10.42500,10.42500,0.07446,0.05120
1.30000,1.98353,10.84173,10.84173,0.07744,0.04723
1.35000,2.19103,11.25846,11.25846,0.08042,0.05217
1.40000,1.98502,11.67514,11.67514,0.08339,0.04726
1.45000,2.15992,12.09176,12.09176,0.08637,0.05143
1.50000,2.16458,12.50841,12.50841,0.08935,0.05154
1.55000,2.27839,12.92512,12.92512,0.09232,0.05425
1.60000,2.21692,13.34172,13.34172,0.09530,0.05278
1.65000,1.95708,13.75832,13.75832,0.09827,0.04660
1.70000,2.05692,14.17489,14.17489,0.10125,0.04897
1.75000,2.09324,14.59162,14.59162,0.10423,0.04984
1.80000,2.29925,15.00827,15.00827,0.10720,0.05474
1.85000,2.11392,15.42490,15.42490,0.11018,0.05033
1.90000,2.31620,15.84152,15.84152,0.11315,0.05515
1.95000,1.99284,16.25828,16.25828,0.11613,0.04745
2.00000,1.89748,16.67496,16.67496,0.11911,0.04518
2.05000,1.96192,17.09169,17.09169,0.12208,0.04671
2.10000,2.29124,17.50831,17.50831,0.12506,0.05455
2.15000,2.28230,17.92510,17.92510,0.12804,0.05434
2.20000,2.61404,18.34172,18.34172,0.13101,0.06224
2.25000,2.34805,18.75840,18.75840,0.13399,0.05591
2.30000,1.92691,19.17511,19.17511,0.13697,0.04588
2.35000,2.02451,19.59179,19.59179,0.13994,0.04820
2.40000,2.06064,20.00838,20.00838,0.14292,0.04906
2.45000,2.53096,20.42501,20.42501,0.14589,0.06026
2.50000,2.46651,20.84169,20.84169,0.14887,0.05873
2.55000,2.43187,21.25834,21.25834,0.15185,0.05790
2.60000,2.22903,21.67496,21.67496,0.15482,0.05307
2.65000,2.09734,22.09156,22.09156,0.15780,0.04994
2.70000,2.04891,22.50832,22.50832,0.16077,0.04878
2.75000,2.11503,22.92486,22.92486,0.16375,0.05036
2.80000,2.10423,23.34160,23.34160,0.16673,0.05010
2.85000,1.83154,23.75822,23.75822,0.16970,0.04361
2.90000,1.99601,24.17501,24.17501,0.17268,0.04752
2.95000,2.08523,24.59158,24.59158,0.17565,0.04965
3.00000,2.00476,25.00834,25.00834,0.17863,0.04773
3.05000,2.08523,25.42504,25.42505,0.18161,0.04965
3.10000,2.01389,25.84177,25.84177,0.18458,0.04795
3.15000,1.94833,26.25843,26.25842,0.18756,0.04639
3.20000,1.98632,26.67510,26.67510,0.19054,0.04729
3.25000,1.98223,27.09173,27.09173,0.19351,0.04720
3.30000,1.90288,27.50846,27.50846,0.19649,0.04531
3.35000,1.84346,27.92509,27.92509,0.19946,0.04389
3.40000,1.45454,28.34166,28.34166,0.20244,0.03463
3.45000,1.41449,28.75833,28.75834,0.20542,0.03368
3.50000,1.46925,29.17499,29.17499,0.20839,0.03498
3.55000,2.10404,29.59158,29.59158,0.21137,0.05010
3.60000,2.49743,30.00821,30.00821,0.21434,0.05946
3.65000,2.13590,30.42491,30.42491,0.21732,0.05085
3.70000,1.92802,30.84159,30.84159,0.22030,0.04591
3.75000,2.23946,31.25822,31.25822,0.22327,0.05332
3.80000,2.48533,31.67492,31.67492,0.22625,0.05917
3.85000,2.18507,32.09168,32.09168,0.22923,0.05203
3.90000,2.01855,32.50838,32.50838,0.23220,0.04806
3.95000,2.29739,32.92504,32.92504,0.23518,0.05470
4.00000,2.26051,33.34166,33.34166,0.23815,0.05382
4.05000,2.49576,33.75847,33.75848,0.24113,0.05942
4.10000,2.28062,34.17510,34.17510,0.24411,0.05430
4.15000,2.34023,34.59175,34.59175,0.24708,0.05572
4.20000,2.63415,35.00843,35.00843,0.25006,0.06272
4.25000,2.84594,35.42508,35.42508,0.25304,0.06776
4.30000,2.57753,35.84165,35.84165,0.25601,0.06137
4.35000,2.72933,36.25830,36.25830,0.25899,0.06498
4.40000,2.64421,36.67493,36.67493,0.26196,0.06296
4.45000,2.44956,37.09163,37.09164,0.26494,0.05832
4.50000,2.75541,37.50831,37.50831,0.26792,0.06561
4.55000,2.84873,37.92491,37.92491,0.27089,0.06783
4.60000,2.95993,38.34156,38.34156,0.27387,0.07047
4.65000,2.53990,38.75832,38.75832,0.27685,0.06047
4.70000,2.77534,39.17497,39.17497,0.27982,0.06608
4.75000,3.29800,39.59160,39.59160,0.28280,0.07852
4.80000,2.58666,40.00833,40.00833,0.28577,0.06159
4.85000,3.16072,40.42506,40.42506,0.28875,0.07526
4.90000,3.48780,40.84171,40.84171,0.29173,0.08304
4.95000,3.15811,41.25842,41.25842,0.29470,0.07519
5.00000,3.25516,41.67510,41.67510,0.29768,0.07750
5.05000,3.28962,42.09180,42.09180,0.30066,0.07832
5.10000,2.85041,42.50840,42.50840,0.30363,0.06787
5.15000,3.34512,42.92502,42.92503,0.30661,0.07965
5.20000,3.09423,43.34170,43.34171,0.30958,0.07367
5.25000,3.43174,43.75835,43.75835,0.31256,0.08171
5.30000,3.44515,44.17495,44.17495,0.31554,0.08203
5.35000,3.15569,44.59158,44.59158,0.31851,0.07514
5.40000,3.49451,45.00826,45.00826,0.32149,0.08320
5.45000,2.72971,45.42485,45.42485,0.32446,0.06499
5.50000,3.43043,45.84156,45.84156,0.32744,0.08168
5.55000,3.21511,46.25829,46.25829,0.33042,0.07655
5.60000,3.45446,46.67503,46.67503,0.33339,0.08225
5.65000,3.32091,47.09168,47.09168,0.33637,0.07907
5.70000,3.41851,47.50838,47.50838,0.33935,0.08139
5.75000,3.08380,47.92501,47.92501,0.34232,0.07342
5.80000,3.22759,48.34177,48.34177,0.34530,0.07685
5.85000,3.29707,48.75844,48.75844,0.34827,0.07850
5.90000,3.66922,49.17512,49.17512,0.35125,0.08736
5.95000,3.31812,49.59172,49.59172,0.35423,0.07900
6.00000,3.65600,50.00842,50.00843,0.35720,0.08705
6.05000,3.54648,50.42502,50.42502,0.36018,0.08444
6.10000,3.48762,50.84170,50.84170,0.36315,0.08304
6.15000,3.83686,51.25830,51.25830,0.36613,0.09135
6.20000,4.09856,51.67500,51.67500,0.36911,0.09758
6.25000,3.90057,52.09157,52.09158,0.37208,0.09287
6.30000,3.67835,52.50820,52.50820,0.37506,0.08758
6.35000,3.79104,52.92493,52.92493,0.37804,0.09026
6.40000,4.03970,53.34161,53.34161,0.38101,0.09618
6.45000,3.61968,53.75823,53.75823,0.38399,0.08618
6.50000,3.53754,54.17491,54.17492,0.38696,0.08423
6.55000,3.85493,54.59167,54.59167,0.38994,0.09178
6.60000,3.83072,55.00835,55.00835,0.39292,0.09121
6.65000,3.98569,55.42506,55.42506,0.39589,0.09490
6.70000,3.76329,55.84168,55.84168,0.39887,0.08960
6.75000,4.15035,56.25849,56.25849,0.40185,0.09882
6.80000,3.87430,56.67504,56.67504,0.40482,0.09225
6.85000,4.25037,57.09177,57.09177,0.40780,0.10120
6.90000,4.01735,57.50842,57.50842,0.41077,0.09565
6.95000,4.13600,57.92513,57.92513,0.41375,0.09848
7.00000,4.27086,58.34169,58.34169,0.41673,0.10169
7.05000,4.07733,58.75832,58.75832,0.41970,0.09708
7.10000,4.00897,59.17495,59.17495,0.42268,0.09545
7.15000,3.96036,59.59162,59.59163,0.42565,0.09429
7.20000,4.27384,60.00825,60.00825,0.42863,0.10176
7.25000,3.92087,60.42490,60.42490,0.43161,0.09335
7.30000,4.37647,60.84155,60.84155,0.43458,0.10420
7.35000,4.53163,61.25826,61.25826,0.43756,0.10790
7.40000,4.14047,61.67496,61.67496,0.44054,0.09858
7.45000,4.69368,62.09162,62.09162,0.44351,0.11175
7.50000,4.26639,62.50835,62.50835,0.44649,0.10158
7.55000,4.45433,62.92508,62.92508,0.44946,0.10606
7.60000,4.41596,63.34176,63.34175,0.45244,0.10514
7.65000,4.37908,63.75841,63.75841,0.45542,0.10426
7.70000,4.15407,64.17512,64.17512,0.45839,0.09891
7.75000,4.58304,64.59179,64.59179,0.46137,0.10912
7.80000,4.60483,65.00839,65.00839,0.46435,0.10964
7.85000,4.45135,65.42501,65.42501,0.46732,0.10598
7.90000,4.38076,65.84172,65.84172,0.47030,0.10430
7.95000,4.74826,66.25834,66.25834,0.47327,0.11305
8.00000,4.67096,66.67494,66.67494,0.47625,0.11121
8.05000,4.43235,67.09154,67.09155,0.47923,0.10553
8.10000,4.41149,67.50827,67.50827,0.48220,0.10504
8.15000,4.21535,67.92495,67.92495,0.48518,0.10037
8.20000,4.38113,68.34155,68.34155,0.48815,0.10431
8.25000,4.09912,68.75828,68.75829,0.49113,0.09760
8.30000,4.03300,69.17495,69.17496,0.49411,0.09602
8.35000,4.43738,69.59164,69.59164,0.49708,0.10565
8.40000,4.30923,70.00834,70.00835,0.50006,0.10260
8.45000,4.66201,70.42499,70.42500,0.50304,0.11100
8.50000,4.16040,70.84175,70.84175,0.50601,0.09906
8.55000,4.92521,71.25843,71.25843,0.50899,0.11727
8.60000,4.38131,71.67511,71.67510,0.51197,0.10432
8.65000,4.74676,72.09173,72.09173,0.51494,0.11302
8.70000,4.20772,72.50847,72.50847,0.51792,0.10018
8.75000,4.61303,72.92507,72.92506,0.52089,0.10983
8.80000,4.38951,73.34169,73.34168,0.52387,0.10451
8.85000,4.30811,73.75827,73.75826,0.52684,0.10257
8.90000,4.55230,74.17502,74.17501,0.52982,0.10839
8.95000,4.37591,74.59159,74.59160,0.53280,0.10419
9.00000,4.39007,75.00824,75.00824,0.53577,0.10453
9.05000,4.27160,75.42487,75.42487,0.53875,0.10170
9.10000,4.72181,75.84157,75.84158,0.54173,0.11242
9.15000,4.61359,76.25828,76.25828,0.54470,0.10985
9.20000,4.34406,76.67490,76.67490,0.54768,0.10343
9.25000,4.45507,77.09166,77.09166,0.55065,0.10607
9.30000,4.63352,77.50839,77.50839,0.55363,0.11032
9.35000,4.48860,77.92504,77.92503,0.55661,0.10687
9.40000,4.36418,78.34170,78.34170,0.55958,0.10391
9.45000,4.67300,78.75848,78.75848,0.56256,0.11126
9.50000,4.45116,79.17508,79.17508,0.56554,0.10598
9.55000,4.79799,79.59176,79.59176,0.56851,0.11424
9.60000,4.56702,80.00838,80.00838,0.57149,0.10874
9.65000,4.92651,80.42509,80.42509,0.57446,0.11730
9.70000,4.93880,80.84169,80.84169,0.57744,0.11759
9.75000,4.75980,81.25837,81.25837,0.58042,0.11333
9.80000,5.37299,81.67494,81.67494,0.58339,0.12793
9.85000,4.91291,82.09159,82.09158,0.58637,0.11697
9.90000,5.07608,82.50824,82.50824,0.58934,0.12086
9.95000,5.22938,82.92494,82.92494,0.59232,0.12451
10.00000,4.88739,83.34159,83.34160,0.59530,0.11637
10.05000,5.14183,83.75830,83.75830,0.59827,0.12242
10.10000,5.15599,84.17493,84.17493,0.60125,0.12276
10.15000,5.18039,84.59163,84.59163,0.60423,0.12334
10.20000,5.45420,85.00837,85.00838,0.60720,0.12986
10.25000,5.60079,85.42504,85.42504,0.61018,0.13335
10.30000,5.39087,85.84175,85.84175,0.61316,0.12835
10.35000,4.98760,86.25840,86.25840,0.61613,0.11875
10.40000,5.29997,86.67513,86.67513,0.61911,0.12619
10.45000,5.33089,87.09178,87.09178,0.62208,0.12693
10.50000,5.28712,87.50840,87.50841,0.62506,0.12588
10.55000,5.55720,87.92503,87.92503,0.62804,0.13231
10.60000,5.99623,88.34174,88.34174,0.63101,0.14277
10.65000,5.87255,88.75836,88.75837,0.63399,0.13982
10.70000,6.08917,89.17496,89.17496,0.63696,0.14498
10.75000,6.01839,89.59156,89.59156,0.63994,0.14330
10.80000,6.41923,90.00829,90.00829,0.64292,0.15284
10.85000,6.53639,90.42489,90.42489,0.64589,0.15563
10.90000,6.29500,90.84154,90.84154,0.64887,0.14988
10.95000,6.19814,91.25827,91.25827,0.65184,0.14757
11.00000,6.35181,91.67497,91.67497,0.65482,0.15123
11.05000,6.45090,92.09165,92.09165,0.65780,0.15359
11.10000,6.28419,92.50834,92.50834,0.66077,0.14962
11.15000,6.61779,92.92504,92.92504,0.66375,0.15757
11.20000,6.37025,93.34182,93.34183,0.66673,0.15167
11.25000,6.45891,93.75842,93.75842,0.66970,0.15378
11.30000,6.35237,94.17508,94.17508,0.67268,0.15125
11.35000,6.58464,94.59175,94.59175,0.67566,0.15678
11.40000,6.68764,95.00843,95.00843,0.67863,0.15923
11.45000,6.98157,95.42508,95.42508,0.68161,0.16623
11.50000,6.55353,95.84168,95.84168,0.68458,0.15604
11.55000,6.56508,96.25831,96.25831,0.68756,0.15631
11.60000,6.64592,96.67498,96.67498,0.69054,0.15824
11.65000,6.87744,97.09160,97.09160,0.69351,0.16375
11.70000,6.67535,97.50824,97.50824,0.69649,0.15894
11.75000,6.28922,97.92491,97.92491,0.69946,0.14974
11.80000,6.62673,98.34162,98.34162,0.70244,0.15778
11.85000,6.66175,98.75827,98.75827,0.70542,0.15861
11.90000,6.74203,99.17486,99.17487,0.70839,0.16052
11.95000,6.68336,99.59168,99.59168,0.71137,0.15913
12.00000,6.66250,100.00838,100.00838,0.71435,0.15863
12.05000,7.13170,100.42503,100.42503,0.71732,0.16980
12.10000,6.75954,100.84168,100.84168,0.72030,0.16094
12.15000,6.66659,101.25845,101.25845,0.72327,0.15873
12.20000,7.02348,101.67512,101.67512,0.72625,0.16723
12.25000,6.94171,102.09175,102.09175,0.72923,0.16528
12.30000,6.76010,102.50840,102.50840,0.73220,0.16095
12.35000,6.51851,102.92511,102.92510,0.73518,0.15520
12.40000,6.67758,103.34170,103.34170,0.73816,0.15899
12.45000,6.76457,103.75835,103.75835,0.74113,0.16106
12.50000,6.74874,104.17495,104.17495,0.74411,0.16068
12.55000,6.93500,104.59162,104.59162,0.74708,0.16512
12.60000,7.02385,105.00822,105.00822,0.75006,0.16723
12.65000,6.88694,105.42491,105.42491,0.75304,0.16397
12.70000,6.97635,105.84153,105.84154,0.75601,0.16610
12.75000,7.15852,106.25831,106.25832,0.75899,0.17044
12.80000,6.96592,106.67494,106.67494,0.76196,0.16586
12.85000,6.85137,107.09168,107.09167,0.76494,0.16313
12.90000,6.35032,107.50833,107.50833,0.76792,0.15120
12.95000,6.88210,107.92512,107.92512,0.77089,0.16386
13.00000,7.03074,108.34176,108.34177,0.77387,0.16740
13.05000,6.94916,108.75842,108.75842,0.77685,0.16546
13.10000,6.71148,109.17509,109.17509,0.77982,0.15980
13.15000,7.22501,109.59178,109.59178,0.78280,0.17202
13.20000,6.81579,110.00842,110.00842,0.78577,0.16228
13.25000,7.30120,110.42502,110.42502,0.78875,0.17384
13.30000,7.02329,110.84170,110.84171,0.79173,0.16722
13.35000,7.14455,111.25832,111.25832,0.79470,0.17011
13.40000,7.50553,111.67498,111.67498,0.79768,0.17870
13.45000,6.90147,112.09155,112.09155,0.80065,0.16432
13.50000,7.29226,112.50834,112.50834,0.80363,0.17363
13.55000,6.77481,112.92493,112.92493,0.80661,0.16131
13.60000,7.00448,113.34158,113.34158,0.80958,0.16677
13.65000,7.19633,113.75824,113.75824,0.81256,0.17134
13.70000,7.15088,114.17499,114.17499,0.81554,0.17026
13.75000,7.39489,114.59165,114.59164,0.81851,0.17607
13.80000,7.43307,115.00836,115.00835,0.82149,0.17698
13.85000,7.35112,115.42500,115.42500,0.82446,0.17503
13.90000,7.38725,115.84173,115.84173,0.82744,0.17589
13.95000,6.55018,116.25838,116.25838,0.83042,0.15596
14.00000,7.53049,116.67511,116.67511,0.83339,0.17930
14.05000,7.47070,117.09177,117.09177,0.83637,0.17787
14.10000,6.64238,117.50848,117.50848,0.83935,0.15815
14.15000,7.46865,117.92510,117.92509,0.84232,0.17782
14.20000,7.20788,118.34167,118.34167,0.84530,0.17162
14.25000,7.36434,118.75838,118.75838,0.84827,0.17534
14.30000,7.56234,119.17497,119.17497,0.85125,0.18006
14.35000,7.36360,119.59160,119.59161,0.85423,0.17532
14.40000,7.50013,120.00822,120.00822,0.85720,0.17857
14.45000,7.49137,120.42487,120.42487,0.86018,0.17837
14.50000,7.68192,120.84161,120.84161,0.86315,0.18290
14.55000,7.46660,121.25829,121.25829,0.86613,0.17778
14.60000,7.34497,121.67491,121.67491,0.86911,0.17488
14.65000,7.68267,122.09166,122.09166,0.87208,0.18292
14.70000,7.28089,122.50840,122.50840,0.87506,0.17335
14.75000,7.40606,122.92504,122.92504,0.87804,0.17633
14.80000,7.83410,123.34175,123.34175,0.88101,0.18653
14.85000,7.54390,123.75847,123.75847,0.88399,0.17962
14.90000,7.48411,124.17514,124.17514,0.88697,0.17819
14.95000,7.49435,124.59168,124.59167,0.88994,0.17844
15.00000,7.67689,125.00839,125.00839,0.89292,0.18278
15.05000,7.62288,125.42506,125.42506,0.89589,0.18150
15.10000,7.91773,125.84171,125.84171,0.89887,0.18852
15.15000,7.40346,126.25831,126.25832,0.90185,0.17627
15.20000,8.00937,126.67491,126.67490,0.90482,0.19070
15.25000,7.58301,127.09166,127.09166,0.90780,0.18055
15.30000,7.76853,127.50828,127.50828,0.91077,0.18497
15.35000,7.89650,127.92492,127.92492,0.91375,0.18801
15.40000,7.76164,128.34158,128.34158,0.91673,0.18480
15.45000,8.05650,128.75831,128.75830,0.91970,0.19182
15.50000,7.70930,129.17495,129.17496,0.92268,0.18355
15.55000,7.73035,129.59164,129.59163,0.92565,0.18406
15.60000,7.83801,130.00832,130.00832,0.92863,0.18662
15.65000,8.10493,130.42507,130.42506,0.93161,0.19297
15.70000,8.18111,130.84172,130.84172,0.93458,0.19479
15.75000,8.08965,131.25843,131.25842,0.93756,0.19261
15.80000,8.15671,131.67511,131.67511,0.94054,0.19421
15.85000,8.31541,132.09181,132.09181,0.94351,0.19799
15.90000,7.89762,132.50843,132.50844,0.94649,0.18804
15.95000,7.90507,132.92501,132.92502,0.94946,0.18822
16.00000,8.14851,133.34172,133.34172,0.95244,0.19401
16.05000,8.14404,133.75837,133.75836,0.95542,0.19391
16.10000,8.43331,134.17496,134.17496,0.95839,0.20079
16.15000,8.07568,134.59156,134.59155,0.96137,0.19228
16.20000,8.21725,135.00827,135.00827,0.96434,0.19565
16.25000,8.37017,135.42489,135.42488,0.96732,0.19929
16.30000,8.14591,135.84157,135.84157,0.97030,0.19395
16.35000,8.40593,136.25819,136.25819,0.97327,0.20014
16.40000,8.30349,136.67501,136.67500,0.97625,0.19770
16.45000,8.27629,137.09165,137.09164,0.97923,0.19705
16.50000,8.27294,137.50836,137.50836,0.98220,0.19697
16.55000,8.28858,137.92502,137.92502,0.98518,0.19735
16.60000,8.45473,138.34181,138.34181,0.98816,0.20130
16.65000,8.32248,138.75843,138.75842,0.99113,0.19815
16.70000,8.46498,139.17510,139.17509,0.99411,0.20155
16.75000,8.59145,139.59176,139.59177,0.99708,0.20456
16.80000,8.37129,140.00845,140.00845,1.00006,0.19932
16.85000,8.15261,140.42507,140.42506,1.00304,0.19411
16.90000,8.85502,140.84166,140.84166,1.00601,0.21083
16.95000,8.60486,141.25830,141.25830,1.00899,0.20488
17.00000,9.09232,141.67494,141.67494,1.01196,0.21648
17.05000,8.66111,142.09164,142.09163,1.01494,0.20622
17.10000,8.55774,142.50826,142.50826,1.01792,0.20376
17.15000,8.40947,142.92494,142.92493,1.02089,0.20023
17.20000,8.78163,143.34156,143.34155,1.02387,0.20909
17.25000,8.91574,143.75827,143.75826,1.02684,0.21228
17.30000,8.96640,144.17493,144.17493,1.02982,0.21349
17.35000,9.08822,144.59165,144.59166,1.03280,0.21639
17.40000,8.90363,145.00836,145.00836,1.03577,0.21199
17.45000,8.72985,145.42504,145.42503,1.03875,0.20785
17.50000,8.97720,145.84170,145.84169,1.04173,0.21374
17.55000,8.70712,146.25845,146.25844,1.04470,0.20731
17.60000,9.06680,146.67513,146.67513,1.04768,0.21588
17.65000,9.05432,147.09175,147.09175,1.05066,0.21558
17.70000,8.99974,147.50843,147.50844,1.05363,0.21428
17.75000,9.14019,147.92512,147.92513,1.05661,0.21762
17.80000,9.07723,148.34174,148.34175,1.05958,0.21612
17.85000,9.29441,148.75833,148.75833,1.06256,0.22130
17.90000,9.24747,149.17497,149.17497,1.06554,0.22018
17.95000,9.19029,149.59164,149.59164,1.06851,0.21882
18.00000,9.31919,150.00821,150.00821,1.07149,0.22189
18.05000,9.44883,150.42489,150.42490,1.07446,0.22497
18.10000,9.47434,150.84158,150.84157,1.07744,0.22558
18.15000,9.44417,151.25830,151.25830,1.08042,0.22486
18.20000,9.37488,151.67494,151.67494,1.08339,0.22321
18.25000,8.97367,152.09163,152.09163,1.08637,0.21366
18.30000,9.09362,152.50838,152.50838,1.08935,0.21651
18.35000,9.37283,152.92509,152.92509,1.09232,0.22316
18.40000,9.11895,153.34175,153.34175,1.09530,0.21712
18.45000,9.58294,153.75845,153.75845,1.09827,0.22817
18.50000,9.28268,154.17509,154.17509,1.10125,0.22102
18.55000,9.21004,154.59178,154.59178,1.10423,0.21929
18.60000,9.58145,155.00840,155.00839,1.10720,0.22813
18.65000,9.31155,155.42500,155.42500,1.11018,0.22170
18.70000,9.51998,155.84169,155.84169,1.11315,0.22667
18.75000,9.36370,156.25839,156.25839,1.11613,0.22295
18.80000,9.90015,156.67499,156.67499,1.11911,0.23572
18.85000,9.43355,157.09161,157.09161,1.12208,0.22461
18.90000,9.90406,157.50831,157.50832,1.12506,0.23581
18.95000,9.86569,157.92496,157.92496,1.12804,0.23490
19.00000,9.54960,158.34156,158.34157,1.13101,0.22737
19.05000,9.76939,158.75821,158.75821,1.13399,0.23260
19.10000,9.47751,159.17503,159.17502,1.13696,0.22566
19.15000,10.02178,159.59166,159.59166,1.13994,0.23861
19.20000,9.45162,160.00833,160.00833,1.14292,0.22504
19.25000,9.68911,160.42495,160.42494,1.14589,0.23069
19.30000,9.55407,160.84176,160.84177,1.14887,0.22748
19.35000,9.56673,161.25844,161.25844,1.15185,0.22778
19.40000,9.74126,161.67512,161.67514,1.15482,0.23193
19.45000,10.30769,162.09175,162.09175,1.15780,0.24542
19.50000,9.80273,162.50848,162.50848,1.16077,0.23340
19.55000,9.71798,162.92506,162.92506,1.16375,0.23138
19.60000,10.23449,163.34172,163.34172,1.16673,0.24368
19.65000,10.03984,163.75832,163.75833,1.16970,0.23904
19.70000,10.61298,164.17498,164.17499,1.17268,0.25269
19.75000,10.06797,164.59158,164.59158,1.17565,0.23971
19.80000,10.58429,165.00822,165.00821,1.17863,0.25201
19.85000,10.12422,165.42491,165.42493,1.18161,0.24105
19.90000,10.54518,165.84159,165.84160,1.18458,0.25108
19.95000,10.67258,166.25828,166.25827,1.18756,0.25411
20.00000,10.48408,166.67494,166.67494,1.19054,0.24962
20.05000,10.25423,167.09165,167.09164,1.19351,0.24415
20.10000,10.03742,167.50837,167.50838,1.19649,0.23899
20.15000,10.50010,167.92508,167.92508,1.19946,0.25000
20.20000,10.30900,168.34170,168.34171,1.20244,0.24545
20.25000,10.79477,168.75848,168.75848,1.20542,0.25702
20.30000,10.64204,169.17510,169.17509,1.20839,0.25338
20.35000,10.46173,169.59178,169.59178,1.21137,0.24909
20.40000,10.65768,170.00836,170.00836,1.21435,0.25375
20.45000,10.60683,170.42510,170.42509,1.21732,0.25254
20.50000,10.61521,170.84171,170.84171,1.22030,0.25274
20.55000,10.66737,171.25833,171.25833,1.22327,0.25398
20.60000,11.09671,171.67495,171.67494,1.22625,0.26421
20.65000,10.50662,172.09166,172.09166,1.22923,0.25016
20.70000,10.81862,172.50828,172.50827,1.23220,0.25759
20.75000,11.03804,172.92490,172.92490,1.23518,0.26281
20.80000,10.99017,173.34161,173.34160,1.23815,0.26167
20.85000,11.11720,173.75829,173.75830,1.24113,0.26470
20.90000,10.53512,174.17495,174.17496,1.24411,0.25084
20.95000,10.84246,174.59161,174.59161,1.24708,0.25815
21.00000,10.79589,175.00837,175.00838,1.25006,0.25705
21.05000,10.82551,175.42501,175.42500,1.25304,0.25775
21.10000,11.01755,175.84176,175.84175,1.25601,0.26232
21.15000,11.25932,176.25844,176.25844,1.25899,0.26808
21.20000,11.37163,176.67515,176.67516,1.26197,0.27075
21.25000,11.39566,177.09180,177.09180,1.26494,0.27133
21.30000,11.24404,177.50842,177.50842,1.26792,0.26772
21.35000,11.31352,177.92508,177.92509,1.27089,0.26937
21.40000,11.26658,178.34172,178.34171,1.27387,0.26825
21.45000,11.10025,178.75838,178.75838,1.27685,0.26429
21.50000,11.01848,179.17494,179.17493,1.27982,0.26234
21.55000,10.88344,179.59154,179.59154,1.28280,0.25913
21.60000,11.14402,180.00824,180.00824,1.28577,0.26533
21.65000,11.22784,180.42495,180.42496,1.28875,0.26733
21.70000,11.13676,180.84153,180.84154,1.29173,0.26516
21.75000,11.67301,181.25826,181.25826,1.29470,0.27793
21.80000,11.41783,181.67499,181.67497,1.29768,0.27185
21.85000,11.35170,182.09166,182.09166,1.30065,0.27028
21.90000,11.20716,182.50840,182.50841,1.30363,0.26684
21.95000,11.68828,182.92509,182.92508,1.30661,0.27829
22.00000,11.78533,183.34181,183.34181,1.30958,0.28060
22.05000,11.55715,183.75843,183.75842,1.31256,0.27517
22.10000,11.60875,184.17508,184.17508,1.31554,0.27640
22.15000,11.19394,184.59173,184.59175,1.31851,0.26652
22.20000,11.84475,185.00847,185.00847,1.32149,0.28202
22.25000,11.28260,185.42504,185.42503,1.32446,0.26863
22.30000,11.41373,185.84161,185.84161,1.32744,0.27176
22.35000,11.72237,186.25829,186.25829,1.33042,0.27910
22.40000,11.48265,186.67505,186.67505,1.33339,0.27340
22.45000,11.82556,187.09161,187.09161,1.33637,0.28156
22.50000,11.58975,187.50829,187.50830,1.33934,0.27595
22.55000,11.90323,187.92494,187.92494,1.34232,0.28341
22.60000,11.80191,188.34160,188.34160,1.34530,0.28100
22.65000,11.85238,188.75824,188.75824,1.34827,0.28220
22.70000,11.72684,189.17493,189.17493,1.35125,0.27921
22.75000,11.78365,189.59164,189.59164,1.35423,0.28056
22.80000,11.88926,190.00834,190.00833,1.35720,0.28308
22.85000,12.12861,190.42505,190.42505,1.36018,0.28878
22.90000,11.85127,190.84170,190.84169,1.36316,0.28217
22.95000,11.73541,191.25848,191.25848,1.36613,0.27941
23.00000,11.99599,191.67513,191.67513,1.36911,0.28562
23.05000,11.86002,192.09182,192.09181,1.37208,0.28238
23.10000,11.85052,192.50837,192.50838,1.37506,0.28216
23.15000,11.85704,192.92515,192.92514,1.37804,0.28231
23.20000,12.14016,193.34171,193.34172,1.38101,0.28905
23.25000,12.09434,193.75836,193.75836,1.38399,0.28796
23.30000,12.15413,194.17491,194.17493,1.38696,0.28938
23.35000,11.58211,194.59162,194.59163,1.38994,0.27576
23.40000,11.89187,195.00824,195.00826,1.39292,0.28314
23.45000,10.87524,195.42486,195.42487,1.39589,0.25893
23.50000,11.94235,195.84155,195.84155,1.39887,0.28434
23.55000,12.02524,196.25836,196.25836,1.40185,0.28632
23.60000,12.52312,196.67498,196.67499,1.40482,0.29817
23.65000,12.21094,197.09167,197.09166,1.40780,0.29074
23.70000,12.27371,197.50839,197.50839,1.41077,0.29223
23.75000,12.30091,197.92506,197.92505,1.41375,0.29288
23.80000,12.21728,198.34175,198.34175,1.41673,0.29089
23.85000,12.16363,198.75841,198.75841,1.41970,0.28961
23.90000,12.18971,199.17509,199.17508,1.42268,0.29023
23.95000,12.24410,199.59174,199.59174,1.42566,0.29153
24.00000,12.62501,200.00840,200.00839,1.42863,0.30060
24.05000,12.48904,200.42504,200.42505,1.43161,0.29736
24.10000,12.64047,200.84169,200.84171,1.43458,0.30096
24.15000,12.38585,201.25839,201.25841,1.43756,0.29490
24.20000,12.94818,201.67499,201.67499,1.44054,0.30829
24.25000,12.66524,202.09159,202.09158,1.44351,0.30155
24.30000,12.52517,202.50832,202.50833,1.44649,0.29822
24.35000,12.93030,202.92494,202.92494,1.44946,0.30786
24.40000,12.73025,203.34156,203.34157,1.45244,0.30310
24.45000,12.66357,203.75825,203.75826,1.45542,0.30151
24.50000,12.80326,204.17497,204.17497,1.45839,0.30484
24.55000,12.60340,204.59166,204.59167,1.46137,0.30008
24.60000,12.59465,205.00834,205.00835,1.46435,0.29987
24.65000,12.84014,205.42501,205.42502,1.46732,0.30572
24.70000,12.53374,205.84178,205.84178,1.47030,0.29842
24.75000,12.88243,206.25845,206.25844,1.47327,0.30672
24.80000,13.19051,206.67511,206.67511,1.47625,0.31406
24.85000,13.16518,207.09177,207.09177,1.47923,0.31346
24.90000,13.15493,207.50848,207.50847,1.48220,0.31321
24.95000,12.85914,207.92507,207.92508,1.48518,0.30617
25.00000,13.03367,208.34168,208.34167,1.48815,0.31033
25.05000,13.33151,208.75834,208.75833,1.49113,0.31742
25.10000,13.12084,209.17498,209.17499,1.49411,0.31240
25.15000,12.89360,209.59156,209.59157,1.49708,0.30699
25.20000,12.79116,210.00829,210.00830,1.50006,0.30455
25.25000,13.07297,210.42491,210.42491,1.50304,0.31126
25.30000,13.42520,210.84162,210.84161,1.50601,0.31965
25.35000,13.60066,211.25824,211.25824,1.50899,0.32383
25.40000,13.20280,211.67495,211.67494,1.51196,0.31435
25.45000,13.20839,212.09167,212.09167,1.51494,0.31449
25.50000,13.66343,212.50838,212.50838,1.51792,0.32532
25.55000,13.64965,212.92506,212.92505,1.52089,0.32499
25.60000,13.47121,213.34170,213.34171,1.52387,0.32074
25.65000,13.66381,213.75845,213.75845,1.52685,0.32533
25.70000,13.66884,214.17512,214.17513,1.52982,0.32545
25.75000,13.39000,214.59176,214.59175,1.53280,0.31881
25.80000,13.45109,215.00838,215.00838,1.53577,0.32026
25.85000,13.60457,215.42511,215.42511,1.53875,0.32392
25.90000,13.48890,215.84171,215.84171,1.54173,0.32116
25.95000,13.56807,216.25833,216.25833,1.54470,0.32305
26.00000,13.88472,216.67495,216.67494,1.54768,0.33059
26.05000,13.51386,217.09168,217.09169,1.55065,0.32176
26.10000,13.44942,217.50828,217.50827,1.55363,0.32022
26.15000,13.50548,217.92490,217.92490,1.55661,0.32156
26.20000,13.87000,218.34156,218.34157,1.55958,0.33024
26.25000,13.82343,218.75832,218.75832,1.56256,0.32913
26.30000,13.65226,219.17495,219.17496,1.56554,0.32505
26.35000,13.87317,219.59164,219.59163,1.56851,0.33031
26.40000,13.59116,220.00830,220.00830,1.57149,0.32360
26.45000,13.91787,220.42508,220.42508,1.57446,0.33138
26.50000,13.77072,220.84174,220.84174,1.57744,0.32787
26.55000,14.27103,221.25840,221.25841,1.58042,0.33979
26.60000,13.93966,221.67516,221.67517,1.58339,0.33190
26.65000,14.14493,222.09180,222.09180,1.58637,0.33678
26.70000,14.18926,222.50846,222.50845,1.58935,0.33784
26.75000,14.13897,222.92504,222.92503,1.59232,0.33664
26.80000,14.28165,223.34170,223.34169,1.59530,0.34004
26.85000,14.27997,223.75833,223.75833,1.59827,0.34000
26.90000,14.37701,224.17496,224.17496,1.60125,0.34231
26.95000,14.14400,224.59154,224.59154,1.60423,0.33676
27.00000,13.93575,225.00828,225.00829,1.60720,0.33180
27.05000,13.77873,225.42489,225.42488,1.61018,0.32807
27.10000,14.43122,225.84160,225.84160,1.61315,0.34360
27.15000,14.45357,226.25820,226.25821,1.61613,0.34413
27.20000,14.57594,226.67502,226.67502,1.61911,0.34705
27.25000,14.53254,227.09170,227.09171,1.62208,0.34601
27.30000,14.68509,227.50839,227.50839,1.62506,0.34965
27.35000,14.45320,227.92502,227.92502,1.62804,0.34412
27.40000,14.57557,228.34176,228.34175,1.63101,0.34704
27.45000,14.63667,228.75844,228.75844,1.63399,0.34849
27.50000,14.43550,229.17508,229.17508,1.63696,0.34370
27.55000,14.56812,229.59173,229.59174,1.63994,0.34686
27.60000,14.52304,230.00845,230.00844,1.64292,0.34579
27.65000,14.76184,230.42505,230.42505,1.64589,0.35147
27.70000,14.79015,230.84166,230.84166,1.64887,0.35215
27.75000,14.97492,231.25840,231.25839,1.65185,0.35655
27.80000,14.57725,231.67500,231.67500,1.65482,0.34708
27.85000,14.75606,232.09161,232.09161,1.65780,0.35133
27.90000,14.80505,232.50829,232.50830,1.66077,0.35250
27.95000,15.03490,232.92495,232.92496,1.66375,0.35797
28.00000,14.62903,233.34161,233.34161,1.66673,0.34831
28.05000,15.14535,233.75824,233.75824,1.66970,0.36060
28.10000,14.72607,234.17493,234.17493,1.67268,0.35062
28.15000,15.03527,234.59161,234.59161,1.67565,0.35798
28.20000,15.19173,235.00835,235.00835,1.67863,0.36171
28.25000,15.20235,235.42506,235.42506,1.68161,0.36196
28.30000,15.19192,235.84172,235.84172,1.68458,0.36171
28.35000,15.12375,236.25848,236.25848,1.68756,0.36009
28.40000,14.95034,236.67512,236.67511,1.69054,0.35596
28.45000,15.13585,237.09175,237.09175,1.69351,0.36038
28.50000,15.09301,237.50843,237.50844,1.69649,0.35936
28.55000,15.31616,237.92509,237.92509,1.69946,0.36467
28.60000,15.64734,238.34173,238.34172,1.70244,0.37256
28.65000,15.18521,238.75833,238.75833,1.70542,0.36155
28.70000,15.00864,239.17491,239.17491,1.70839,0.35735
28.75000,15.25078,239.59165,239.59164,1.71137,0.36311
28.80000,15.22992,240.00831,240.00832,1.71435,0.36262
28.85000,15.61120,240.42489,240.42490,1.71732,0.37170
28.90000,15.33628,240.84155,240.84155,1.72030,0.36515
28.95000,15.65162,241.25834,241.25833,1.72327,0.37266
29.00000,15.40091,241.67494,241.67494,1.72625,0.36669
29.05000,15.65740,242.09166,242.09166,1.72923,0.37280
29.10000,15.50838,242.50837,242.50836,1.73220,0.36925
29.15000,15.95803,242.92513,242.92513,1.73518,0.37995
29.20000,15.87272,243.34168,243.34169,1.73815,0.37792
29.25000,15.78014,243.75845,243.75845,1.74113,0.37572
29.30000,15.61362,244.17508,244.17508,1.74411,0.37175
29.35000,15.38657,244.59179,244.59180,1.74708,0.36635
29.40000,15.52012,245.00842,245.00842,1.75006,0.36953
29.45000,15.54303,245.42503,245.42503,1.75304,0.37007
29.50000,15.80641,245.84172,245.84172,1.75601,0.37634
29.55000,15.93810,246.25837,246.25838,1.75899,0.37948
29.60000,16.19682,246.67495,246.67496,1.76196,0.38564
29.65000,15.91425,247.09159,247.09158,1.76494,0.37891
29.70000,16.40208,247.50830,247.50830,1.76792,0.39053
29.75000,16.18210,247.92493,247.92493,1.77089,0.38529
29.80000,16.01968,248.34159,248.34158,1.77387,0.38142
29.85000,16.03123,248.75820,248.75819,1.77684,0.38170
29.90000,16.02359,249.17501,249.17502,1.77982,0.38151
29.95000,16.10108,249.59167,249.59167,1.78280,0.38336
30.00000,16.34937,250.00836,250.00836,1.78577,0.38927
30.05000,16.00366,250.42499,250.42499,1.78875,0.38104
30.10000,16.79119,250.84180,250.84180,1.79173,0.39979
30.15000,16.45535,251.25844,251.25844,1.79470,0.39179
30.20000,16.54141,251.67507,251.67506,1.79768,0.39384
30.25000,16.50061,252.09175,252.09175,1.80066,0.39287
30.30000,16.49074,252.50854,252.50854,1.80363,0.39264
30.35000,16.66825,252.92507,252.92508,1.80661,0.39686
30.40000,16.49652,253.34165,253.34166,1.80958,0.39277
30.45000,16.67812,253.75831,253.75832,1.81256,0.39710
30.50000,16.82770,254.17500,254.17500,1.81554,0.40066
30.55000,16.60194,254.59163,254.59163,1.81851,0.39528
30.60000,16.81186,255.00824,255.00824,1.82149,0.40028
30.65000,16.96907,255.42495,255.42494,1.82446,0.40403
30.70000,16.86234,255.84155,255.84155,1.82744,0.40148
30.75000,17.08176,256.25826,256.25827,1.83042,0.40671
30.80000,17.08325,256.67495,256.67496,1.83339,0.40674
30.85000,17.06760,257.09169,257.09167,1.83637,0.40637
30.90000,16.77573,257.50834,257.50833,1.83935,0.39942
30.95000,16.72357,257.92508,257.92508,1.84232,0.39818
31.00000,17.02476,258.34171,258.34171,1.84530,0.40535
31.05000,16.94039,258.75848,258.75848,1.84827,0.40334
31.10000,16.74276,259.17511,259.17511,1.85125,0.39864
31.15000,16.80162,259.59177,259.59177,1.85423,0.40004
31.20000,17.09275,260.00840,260.00839,1.85720,0.40697
31.25000,17.54332,260.42506,260.42505,1.86018,0.41770
31.30000,17.45652,260.84175,260.84174,1.86316,0.41563
31.35000,17.58244,261.25835,261.25836,1.86613,0.41863
31.40000,17.44088,261.67499,261.67499,1.86911,0.41526
31.45000,17.68786,262.09164,262.09164,1.87208,0.42114
31.50000,17.62081,262.50825,262.50824,1.87506,0.41954
31.55000,17.43622,262.92491,262.92490,1.87804,0.41515
31.60000,16.92474,263.34149,263.34149,1.88101,0.40297
31.65000,17.71059,263.75828,263.75827,1.88399,0.42168
31.70000,17.29485,264.17494,264.17493,1.88696,0.41178
31.75000,17.67278,264.59162,264.59161,1.88994,0.42078
31.80000,18.12931,265.00836,265.00836,1.89292,0.43165
31.85000,17.69103,265.42510,265.42511,1.89589,0.42122
31.90000,17.73592,265.84170,265.84171,1.89887,0.42228
31.95000,18.27031,266.25847,266.25845,1.90185,0.43501
32.00000,18.04996,266.67515,266.67514,1.90482,0.42976
32.05000,17.62901,267.09178,267.09180,1.90780,0.41974
32.10000,17.77019,267.50839,267.50839,1.91077,0.42310
32.15000,17.59231,267.92508,267.92508,1.91375,0.41886
32.20000,18.09280,268.34174,268.34174,1.91673,0.43078
32.25000,17.45112,268.75832,268.75830,1.91970,0.41550
32.30000,17.60051,269.17495,269.17496,1.92268,0.41906
32.35000,17.98887,269.59161,269.59161,1.92565,0.42831
32.40000,18.15092,270.00832,270.00833,1.92863,0.43216
32.45000,18.36177,270.42495,270.42496,1.93161,0.43718
32.50000,18.42640,270.84156,270.84155,1.93458,0.43872
32.55000,18.19469,271.25827,271.25827,1.93756,0.43321
32.60000,18.26435,271.67503,271.67502,1.94054,0.43487
32.65000,18.30403,272.09164,272.09164,1.94351,0.43581
32.70000,18.37909,272.50840,272.50839,1.94649,0.43760
32.75000,18.33271,272.92503,272.92505,1.94946,0.43649
32.80000,18.46366,273.34175,273.34174,1.95244,0.43961
32.85000,18.09895,273.75840,273.75839,1.95542,0.43093
32.90000,18.57560,274.17511,274.17511,1.95839,0.44228
32.95000,18.64955,274.59175,274.59174,1.96137,0.44404
33.00000,18.61770,275.00848,275.00848,1.96435,0.44328
33.05000,18.66538,275.42507,275.42508,1.96732,0.44441
33.10000,18.78981,275.84170,275.84171,1.97030,0.44738
33.15000,19.00978,276.25836,276.25836,1.97327,0.45261
33.20000,18.99544,276.67502,276.67502,1.97625,0.45227
33.25000,19.03381,277.09154,277.09155,1.97923,0.45319
33.30000,19.01835,277.50823,277.50824,1.98220,0.45282
33.35000,19.02971,277.92497,277.92496,1.98518,0.45309
33.40000,19.11912,278.34157,278.34158,1.98815,0.45522
33.45000,19.17165,278.75826,278.75827,1.99113,0.45647
33.50000,19.18413,279.17492,279.17493,1.99411,0.45676
33.55000,19.05691,279.59173,279.59174,1.99708,0.45374
33.60000,19.22771,280.00839,280.00839,2.00006,0.45780
33.65000,19.36350,280.42505,280.42505,2.00304,0.46104
33.70000,19.12750,280.84168,280.84167,2.00601,0.45542
33.75000,19.21989,281.25850,281.25848,2.00899,0.45762
33.80000,19.32923,281.67510,281.67511,2.01197,0.46022
33.85000,19.25044,282.09182,282.09183,2.01494,0.45834
33.90000,19.28136,282.50840,282.50839,2.01792,0.45908
33.95000,19.22697,282.92508,282.92505,2.02089,0.45778
34.00000,19.42813,283.34171,283.34167,2.02387,0.46257
34.05000,19.26962,283.75835,283.75833,2.02685,0.45880
34.10000,19.57882,284.17495,284.17496,2.02982,0.46616
34.15000,19.23926,284.59166,284.59167,2.03280,0.45808
34.20000,19.19251,285.00830,285.00830,2.03577,0.45696
34.25000,19.80513,285.42490,285.42490,2.03875,0.47155
34.30000,19.57510,285.84154,285.84152,2.04173,0.46607
34.35000,19.94967,286.25832,286.25833,2.04470,0.47499
34.40000,19.98991,286.67498,286.67499,2.04768,0.47595
34.45000,19.55498,287.09164,287.09164,2.05065,0.46559
34.50000,19.50953,287.50835,287.50836,2.05363,0.46451
34.55000,19.61607,287.92504,287.92505,2.05661,0.46705
34.60000,19.99140,288.34178,288.34177,2.05958,0.47599
34.65000,19.96476,288.75841,288.75842,2.06256,0.47535
34.70000,20.08472,289.17515,289.17514,2.06554,0.47821
34.75000,19.92136,289.59180,289.59180,2.06851,0.47432
34.80000,19.96290,290.00841,290.00842,2.07149,0.47531
34.85000,20.94153,290.42504,290.42505,2.07446,0.49861
34.90000,20.35834,290.84170,290.84171,2.07744,0.48472
34.95000,20.01803,291.25834,291.25833,2.08042,0.47662
35.00000,20.08360,291.67497,291.67496,2.08339,0.47818
35.05000,20.65450,292.09163,292.09161,2.08637,0.49177
35.10000,19.97836,292.50831,292.50827,2.08934,0.47568
35.15000,19.43391,292.92494,292.92493,2.09232,0.46271
35.20000,19.58143,293.34160,293.34161,2.09530,0.46622
35.25000,19.66637,293.75829,293.75830,2.09827,0.46825
35.30000,20.16257,294.17495,294.17496,2.10125,0.48006
35.35000,20.22032,294.59171,294.59171,2.10423,0.48144
35.40000,19.71815,295.00834,295.00833,2.10720,0.46948
35.45000,20.60160,295.42505,295.42505,2.11018,0.49051
35.50000,20.36542,295.84176,295.84174,2.11316,0.48489
35.55000,20.29724,296.25842,296.25842,2.11613,0.48327
35.60000,20.15308,296.67511,296.67511,2.11911,0.47984
35.65000,19.98730,297.09174,297.09174,2.12208,0.47589
35.70000,19.99568,297.50850,297.50851,2.12506,0.47609
35.75000,19.69337,297.92511,297.92511,2.12804,0.46889
35.80000,19.87647,298.34172,298.34171,2.13101,0.47325
35.85000,19.85021,298.75832,298.75836,2.13399,0.47262
35.90000,19.89026,299.17504,299.17505,2.13696,0.47358
35.95000,19.90851,299.59159,299.59161,2.13994,0.47401
36.00000,20.37715,300.00825,300.00821,2.14292,0.48517
36.05000,20.07205,300.42488,300.42487,2.14589,0.47791
36.10000,20.22628,300.84162,300.84164,2.14887,0.48158
36.15000,20.02008,301.25825,301.25824,2.15184,0.47667
36.20000,20.00891,301.67494,301.67493,2.15482,0.47640
36.25000,19.74441,302.09167,302.09167,2.15780,0.47011
36.30000,18.75069,302.50831,302.50827,2.16077,0.44644
36.35000,19.69263,302.92507,302.92508,2.16375,0.46887
36.40000,19.59223,303.34178,303.34177,2.16673,0.46648
36.45000,19.89901,303.75852,303.75851,2.16970,0.47379
36.50000,19.83754,304.17512,304.17511,2.17268,0.47232
36.55000,20.05808,304.59176,304.59177,2.17566,0.47757
36.60000,20.28942,305.00836,305.00833,2.17863,0.48308
36.65000,19.21188,305.42513,305.42514,2.18161,0.45743
36.70000,19.45980,305.84171,305.84171,2.18458,0.46333
36.75000,19.03921,306.25837,306.25836,2.18756,0.45331
36.80000,19.53002,306.67495,306.67496,2.19054,0.46500
36.85000,18.48787,307.09160,307.09161,2.19351,0.44019
36.90000,16.95529,307.50826,307.50827,2.19649,0.40370
36.95000,17.19370,307.92495,307.92496,2.19946,0.40937
37.00000,18.15408,308.34161,308.34161,2.20244,0.43224
37.05000,18.34165,308.75829,308.75830,2.20542,0.43671
37.10000,18.23921,309.17498,309.17499,2.20839,0.43427
37.15000,18.26920,309.59161,309.59161,2.21137,0.43498
37.20000,18.19674,310.00840,310.00839,2.21435,0.43326
37.25000,18.07753,310.42506,310.42505,2.21732,0.43042
37.30000,18.44857,310.84174,310.84171,2.22030,0.43925
37.35000,17.97229,311.25840,311.25839,2.22327,0.42791
37.40000,17.94267,311.67516,311.67517,2.22625,0.42721
37.45000,18.00247,312.09177,312.09174,2.22923,0.42863
37.50000,17.65918,312.50848,312.50848,2.23220,0.42046
37.55000,18.03767,312.92504,312.92505,2.23518,0.42947
37.60000,18.59143,313.34175,313.34174,2.23816,0.44265
37.65000,18.37276,313.75835,313.75836,2.24113,0.43745
37.70000,18.21108,314.17496,314.17493,2.24411,0.43360
37.75000,18.16228,314.59157,314.59155,2.24708,0.43244
37.80000,18.40424,315.00831,315.00830,2.25006,0.43820
37.85000,18.22989,315.42491,315.42493,2.25304,0.43405
37.90000,18.39772,315.84157,315.84158,2.25601,0.43804
37.95000,18.50761,316.25823,316.25824,2.25899,0.44066
38.00000,17.98235,316.67499,316.67499,2.26196,0.42815
38.05000,18.54580,317.09168,317.09167,2.26494,0.44157
38.10000,17.93969,317.50839,317.50842,2.26792,0.42714
38.15000,18.21984,317.92505,317.92502,2.27089,0.43381
38.20000,18.18854,318.34178,318.34180,2.27387,0.43306
38.25000,18.18649,318.75847,318.75848,2.27685,0.43301
38.30000,18.35283,319.17513,319.17514,2.27982,0.43697
38.35000,18.62235,319.59171,319.59167,2.28280,0.44339
38.40000,18.46701,320.00847,320.00848,2.28577,0.43969
38.45000,19.02767,320.42508,320.42508,2.28875,0.45304
38.50000,18.97812,320.84168,320.84167,2.29173,0.45186
38.55000,18.90566,321.25832,321.25833,2.29470,0.45013
38.60000,18.73989,321.67503,321.67502,2.29768,0.44619
38.65000,18.73672,322.09164,322.09167,2.30065,0.44611
38.70000,18.89579,322.50829,322.50830,2.30363,0.44990
38.75000,18.71865,322.92493,322.92493,2.30661,0.44568
38.80000,18.81644,323.34161,323.34161,2.30958,0.44801
38.85000,19.10347,323.75827,323.75827,2.31256,0.45484
38.90000,18.92820,324.17496,324.17496,2.31554,0.45067
38.95000,19.03642,324.59169,324.59171,2.31851,0.45325
39.00000,18.80061,325.00835,325.00836,2.32149,0.44763
39.05000,18.98073,325.42501,325.42502,2.32446,0.45192
39.10000,19.44546,325.84172,325.84174,2.32744,0.46299
39.15000,19.20853,326.25846,326.25845,2.33042,0.45735
39.20000,19.37933,326.67514,326.67514,2.33339,0.46141
39.25000,18.94180,327.09178,327.09177,2.33637,0.45100
39.30000,19.20592,327.50843,327.50842,2.33935,0.45728
39.35000,19.39312,327.92512,327.92511,2.34232,0.46174
39.40000,19.35065,328.34167,328.34164,2.34530,0.46073
39.45000,19.42459,328.75839,328.75839,2.34827,0.46249
39.50000,19.55535,329.17494,329.17493,2.35125,0.46560
39.55000,19.52164,329.59165,329.59164,2.35423,0.46480
39.60000,19.89473,330.00823,330.00824,2.35720,0.47368
39.65000,5.40987,330.42492,330.42493,2.36018,0.12881
39.67600,-0.02775,330.64156,330.64160,2.36173,-0.00066