File: raw_data/mechanical_tests_Instron_data/3DP_Skin_0035_Horizontal_2.is_tens_RawData/Specimen_RawData_1.csv
Dimension : Area,0.42000,cm^2

Time,Load,Extension,Tensile extension,Tensile strain,Tensile stress
(sec),(N),(mm),(mm),(mm/mm),(MPa)
0.00000,0.32745,0.00000,0.00000,0.00000,0.00780
0.04000,1.12485,0.05995,0.05995,0.00043,0.02678
0.08000,0.75735,0.26057,0.26057,0.00186,0.01803
0.12000,0.80708,0.59226,0.59226,0.00423,0.01922
0.16000,1.35899,0.98250,0.98250,0.00702,0.03236
0.20000,1.58269,1.38935,1.38935,0.00992,0.03768
0.24000,1.82446,1.80560,1.80560,0.01290,0.04344
0.28000,1.82837,2.22801,2.22801,0.01591,0.04353
0.32000,1.83433,2.64862,2.64862,0.01892,0.04367
0.36000,1.29305,3.00978,3.00978,0.02150,0.03079
0.40000,1.33254,3.33702,3.33702,0.02384,0.03173
0.44000,1.63056,3.67130,3.67130,0.02622,0.03882
0.48000,1.19079,4.00749,4.00749,0.02862,0.02835
0.52000,1.72891,4.34156,4.34156,0.03101,0.04116
0.56000,1.51955,4.67469,4.67469,0.03339,0.03618
0.60000,1.30776,5.00826,5.00826,0.03577,0.03114
0.64000,1.37575,5.34158,5.34158,0.03815,0.03276
0.68000,1.18054,5.67493,5.67493,0.04054,0.02811
0.72000,1.10082,6.00838,6.00838,0.04292,0.02621
0.76000,1.36904,6.34160,6.34160,0.04530,0.03260
0.80000,1.61417,6.67513,6.67513,0.04768,0.03843
0.84000,1.55233,7.00816,7.00816,0.05006,0.03696
0.88000,1.66036,7.34175,7.34175,0.05244,0.03953
0.92000,1.82055,7.67496,7.67496,0.05482,0.04335
0.96000,2.01482,8.00836,8.00836,0.05720,0.04797
1.00000,1.87960,8.34171,8.34171,0.05958,0.04475
1.04000,1.49477,8.67498,8.67498,0.06196,0.03559
1.08000,1.75163,9.00838,9.00838,0.06435,0.04171
1.12000,1.75908,9.34162,9.34162,0.06673,0.04188
1.16000,1.74865,9.67510,9.67510,0.06911,0.04163
1.20000,1.77454,10.00824,10.00824,0.07149,0.04225
1.24000,1.63931,10.34172,10.34172,0.07387,0.03903
1.28000,1.44038,10.67496,10.67496,0.07625,0.03429
1.32000,1.78292,11.00839,11.00839,0.07863,0.04245
1.36000,1.82148,11.34166,11.34165,0.08101,0.04337
1.40000,1.80136,11.67495,11.67495,0.08339,0.04289
1.44000,1.68215,12.00832,12.00832,0.08577,0.04005
1.48000,1.94740,12.34157,12.34157,0.08815,0.04637
1.52000,1.75424,12.67513,12.67513,0.09054,0.04177
1.56000,1.92709,13.00826,13.00826,0.09292,0.04588
1.60000,1.82781,13.34174,13.34174,0.09530,0.04352
1.64000,1.64453,13.67496,13.67496,0.09768,0.03916
1.68000,1.65422,14.00839,14.00839,0.10006,0.03939
1.72000,1.97776,14.34165,14.34165,0.10244,0.04709
1.76000,1.73170,14.67500,14.67500,0.10482,0.04123
1.80000,1.65626,15.00838,15.00838,0.10720,0.03943
1.84000,1.53165,15.34162,15.34162,0.10958,0.03647
1.88000,1.40574,15.67510,15.67510,0.11197,0.03347
1.92000,1.50241,16.00821,16.00821,0.11434,0.03577
1.96000,1.72853,16.34174,16.34174,0.11673,0.04116
2.00000,1.64472,16.67490,16.67490,0.11911,0.03916
2.04000,1.71978,17.00839,17.00838,0.12149,0.04095
2.08000,2.00868,17.34168,17.34168,0.12387,0.04783
2.12000,1.87065,17.67495,17.67495,0.12625,0.04454
2.16000,1.79745,18.00840,18.00840,0.12863,0.04280
2.20000,1.91405,18.34159,18.34159,0.13101,0.04557
2.24000,1.92299,18.67510,18.67510,0.13339,0.04579
2.28000,1.99433,19.00829,19.00829,0.13577,0.04748
2.32000,1.90549,19.34177,19.34177,0.13816,0.04537
2.36000,2.25175,19.67490,19.67490,0.14054,0.05361
2.40000,2.00924,20.00838,20.00838,0.14292,0.04784
2.44000,1.91592,20.34168,20.34168,0.14530,0.04562
2.48000,1.64993,20.67495,20.67495,0.14768,0.03928
2.52000,1.80211,21.00838,21.00838,0.15006,0.04291
2.56000,1.97962,21.34156,21.34156,0.15244,0.04713
2.60000,1.65496,21.67510,21.67510,0.15482,0.03940
2.64000,1.88183,22.00828,22.00828,0.15720,0.04481
2.68000,1.98856,22.34174,22.34174,0.15958,0.04735
2.72000,1.76933,22.67490,22.67490,0.16196,0.04213
2.76000,2.00029,23.00836,23.00836,0.16435,0.04763
2.80000,1.78088,23.34168,23.34168,0.16673,0.04240
2.84000,1.75834,23.67503,23.67503,0.16911,0.04187
2.88000,2.01054,24.00840,24.00840,0.17149,0.04787
2.92000,1.86153,24.34159,24.34159,0.17387,0.04432
2.96000,1.90642,24.67507,24.67507,0.17625,0.04539
3.00000,1.57990,25.00823,25.00823,0.17863,0.03762
3.04000,1.73338,25.34185,25.34185,0.18101,0.04127
3.08000,1.72555,25.67493,25.67493,0.18339,0.04108
3.12000,2.10889,26.00833,26.00833,0.18577,0.05021
3.16000,2.22214,26.34165,26.34165,0.18815,0.05291
3.20000,1.52960,26.67497,26.67497,0.19054,0.03642
3.24000,2.40505,27.00837,27.00837,0.19292,0.05726
3.28000,1.92039,27.34156,27.34156,0.19530,0.04572
3.32000,1.81273,27.67504,27.67504,0.19768,0.04316
3.36000,1.71643,28.00823,28.00823,0.20006,0.04087
3.40000,1.77212,28.34179,28.34179,0.20244,0.04219
3.44000,1.73822,28.67501,28.67500,0.20482,0.04139
3.48000,1.83731,29.00841,29.00841,0.20720,0.04375
3.52000,1.85594,29.34162,29.34162,0.20958,0.04419
3.56000,1.44616,29.67494,29.67494,0.21196,0.03443
3.60000,1.47745,30.00843,30.00842,0.21435,0.03518
3.64000,1.41617,30.34161,30.34161,0.21673,0.03372
3.68000,1.39009,30.67512,30.67512,0.21911,0.03310
3.72000,1.67470,31.00817,31.00817,0.22149,0.03987
3.76000,1.54376,31.34174,31.34174,0.22387,0.03676
3.80000,1.50260,31.67498,31.67498,0.22625,0.03578
3.84000,1.46292,32.00838,32.00838,0.22863,0.03483
3.88000,1.53817,32.34164,32.34164,0.23101,0.03662
3.92000,1.67172,32.67491,32.67491,0.23339,0.03980
3.96000,1.52383,33.00840,33.00840,0.23577,0.03628
4.00000,1.44653,33.34166,33.34166,0.23815,0.03444
4.04000,1.65738,33.67512,33.67512,0.24054,0.03946
4.08000,1.55307,34.00825,34.00825,0.24292,0.03698
4.12000,1.71755,34.34174,34.34174,0.24530,0.04089
4.16000,1.87866,34.67492,34.67492,0.24768,0.04473
4.20000,1.50576,35.00840,35.00840,0.25006,0.03585
4.24000,1.69948,35.34167,35.34167,0.25244,0.04046
4.28000,1.86935,35.67494,35.67493,0.25482,0.04451
4.32000,1.41822,36.00837,36.00837,0.25720,0.03377
4.36000,1.67526,36.34158,36.34159,0.25958,0.03989
4.40000,1.34893,36.67504,36.67504,0.26196,0.03212
4.44000,1.34055,37.00820,37.00820,0.26434,0.03192
4.48000,1.82875,37.34173,37.34173,0.26673,0.04354
4.52000,1.71438,37.67497,37.67497,0.26911,0.04082
4.56000,1.56686,38.00843,38.00843,0.27149,0.03731
4.60000,1.65515,38.34170,38.34170,0.27387,0.03941
4.64000,1.44001,38.67499,38.67499,0.27625,0.03429
4.68000,1.76914,39.00839,39.00839,0.27863,0.04212
4.72000,1.94479,39.34158,39.34158,0.28101,0.04630
4.76000,1.81943,39.67512,39.67512,0.28339,0.04332
4.80000,1.85668,40.00828,40.00827,0.28577,0.04421
4.84000,1.80788,40.34178,40.34179,0.28816,0.04304
4.88000,1.80230,40.67494,40.67495,0.29054,0.04291
4.92000,1.54935,41.00832,41.00832,0.29292,0.03689
4.96000,2.34526,41.34167,41.34167,0.29530,0.05584
5.00000,1.97608,41.67496,41.67496,0.29768,0.04705
5.04000,2.01259,42.00836,42.00837,0.30006,0.04792
5.08000,2.29087,42.34161,42.34161,0.30244,0.05454
5.12000,2.32160,42.67511,42.67511,0.30482,0.05528
5.16000,2.41995,43.00827,43.00827,0.30720,0.05762
5.20000,2.53320,43.34178,43.34179,0.30958,0.06031
5.24000,1.92486,43.67492,43.67492,0.31196,0.04583
5.28000,2.29124,44.00837,44.00837,0.31435,0.05455
5.32000,2.33054,44.34169,44.34169,0.31673,0.05549
5.36000,2.31583,44.67499,44.67498,0.31911,0.05514
5.40000,2.24132,45.00839,45.00839,0.32149,0.05336
5.44000,2.17892,45.34158,45.34158,0.32387,0.05188
5.48000,2.37823,45.67509,45.67509,0.32625,0.05662
5.52000,2.18060,46.00825,46.00825,0.32863,0.05192
5.56000,2.17967,46.34176,46.34176,0.33101,0.05190
5.60000,2.59001,46.67497,46.67497,0.33339,0.06167
5.64000,2.34935,47.00835,47.00835,0.33577,0.05594
5.68000,2.16477,47.34164,47.34164,0.33815,0.05154
5.72000,2.49427,47.67501,47.67501,0.34054,0.05939
5.76000,2.47359,48.00836,48.00836,0.34292,0.05890
5.80000,2.64850,48.34158,48.34158,0.34530,0.06306
5.84000,2.65483,48.67511,48.67511,0.34768,0.06321
5.88000,2.32477,49.00825,49.00824,0.35006,0.05535
5.92000,2.34991,49.34178,49.34178,0.35244,0.05595
5.96000,2.38921,49.67494,49.67494,0.35482,0.05689
6.00000,2.43485,50.00837,50.00837,0.35720,0.05797
6.04000,2.88226,50.34166,50.34166,0.35958,0.06863
6.08000,2.57660,50.67498,50.67498,0.36196,0.06135
6.12000,2.87481,51.00844,51.00844,0.36435,0.06845
6.16000,2.99290,51.34157,51.34157,0.36673,0.07126
6.20000,2.86363,51.67506,51.67506,0.36911,0.06818
6.24000,3.02680,52.00822,52.00822,0.37149,0.07207
6.28000,3.02196,52.34175,52.34175,0.37387,0.07195
6.32000,2.82787,52.67494,52.67494,0.37625,0.06733
6.36000,2.71350,53.00842,53.00842,0.37863,0.06461
6.40000,3.07560,53.34166,53.34167,0.38101,0.07323
6.44000,2.83085,53.67493,53.67493,0.38339,0.06740
6.48000,3.00203,54.00844,54.00844,0.38577,0.07148
6.52000,2.74461,54.34160,54.34160,0.38815,0.06535
6.56000,2.95248,54.67508,54.67508,0.39054,0.07030
6.60000,2.81874,55.00824,55.00824,0.39292,0.06711
6.64000,2.99979,55.34175,55.34175,0.39530,0.07142
6.68000,3.01767,55.67499,55.67499,0.39768,0.07185
6.72000,2.87089,56.00839,56.00839,0.40006,0.06835
6.76000,3.09981,56.34164,56.34164,0.40244,0.07381
6.80000,3.15569,56.67493,56.67493,0.40482,0.07514
6.84000,3.56156,57.00836,57.00835,0.40720,0.08480
6.88000,3.44161,57.34159,57.34159,0.40958,0.08194
6.92000,3.27528,57.67513,57.67513,0.41197,0.07798
6.96000,3.51258,58.00819,58.00819,0.41434,0.08363
7.00000,3.05083,58.34172,58.34172,0.41673,0.07264
7.04000,3.17171,58.67491,58.67491,0.41911,0.07552
7.08000,3.47961,59.00842,59.00842,0.42149,0.08285
7.12000,3.32482,59.34172,59.34172,0.42387,0.07916
7.16000,3.50438,59.67495,59.67495,0.42625,0.08344
7.20000,3.16370,60.00838,60.00838,0.42863,0.07533
7.24000,3.07374,60.34163,60.34163,0.43101,0.07318
7.28000,3.18419,60.67511,60.67511,0.43339,0.07581
7.32000,3.45539,61.00824,61.00824,0.43577,0.08227
7.36000,3.52412,61.34175,61.34175,0.43816,0.08391
7.40000,3.70964,61.67491,61.67491,0.44054,0.08832
7.44000,3.95086,62.00837,62.00837,0.44292,0.09407
7.48000,3.74038,62.34168,62.34168,0.44530,0.08906
7.52000,4.11272,62.67498,62.67498,0.44768,0.09792
7.56000,4.18015,63.00838,63.00838,0.45006,0.09953
7.60000,3.93614,63.34155,63.34155,0.45244,0.09372
7.64000,4.26415,63.67513,63.67513,0.45482,0.10153
7.68000,4.38746,64.00829,64.00829,0.45720,0.10446
7.72000,4.21088,64.34177,64.34177,0.45958,0.10026
7.76000,4.05647,64.67496,64.67496,0.46196,0.09658
7.80000,4.23696,65.00831,65.00831,0.46435,0.10088
7.84000,4.48748,65.34168,65.34168,0.46673,0.10684
7.88000,4.14923,65.67503,65.67503,0.46911,0.09879
7.92000,4.40013,66.00841,66.00841,0.47149,0.10476
7.96000,4.32357,66.34157,66.34157,0.47387,0.10294
8.00000,4.47761,66.67505,66.67505,0.47625,0.10661
8.04000,4.58024,67.00824,67.00824,0.47863,0.10905
8.08000,4.64600,67.34177,67.34177,0.48101,0.11062
8.12000,4.83263,67.67493,67.67493,0.48339,0.11506
8.16000,4.65959,68.00836,68.00836,0.48577,0.11094
8.20000,4.88088,68.34166,68.34165,0.48815,0.11621
8.24000,4.54523,68.67498,68.67498,0.49054,0.10822
8.28000,4.73540,69.00846,69.00846,0.49292,0.11275
8.32000,4.65028,69.34159,69.34159,0.49530,0.11072
8.36000,4.62364,69.67508,69.67508,0.49768,0.11009
8.40000,5.04162,70.00829,70.00830,0.50006,0.12004
8.44000,4.82984,70.34177,70.34177,0.50244,0.11500
8.48000,4.83338,70.67493,70.67493,0.50482,0.11508
8.52000,4.91925,71.00838,71.00838,0.50720,0.11712
8.56000,5.10812,71.34160,71.34160,0.50958,0.12162
8.60000,4.73000,71.67498,71.67498,0.51196,0.11262
8.64000,5.09322,72.00837,72.00837,0.51435,0.12127
8.68000,5.15003,72.34159,72.34159,0.51673,0.12262
8.72000,5.00437,72.67512,72.67513,0.51911,0.11915
8.76000,5.20013,73.00824,73.00824,0.52149,0.12381
8.80000,4.76856,73.34174,73.34174,0.52387,0.11354
8.84000,5.00903,73.67496,73.67496,0.52625,0.11926
8.88000,5.15860,74.00842,74.00842,0.52863,0.12282
8.92000,4.66816,74.34168,74.34168,0.53101,0.11115
8.96000,5.15487,74.67498,74.67499,0.53339,0.12274
9.00000,5.18467,75.00837,75.00837,0.53577,0.12344
9.04000,4.30606,75.34162,75.34162,0.53815,0.10253
9.08000,4.62942,75.67507,75.67507,0.54054,0.11022
9.12000,5.12023,76.00821,76.00820,0.54292,0.12191
9.16000,5.02430,76.34177,76.34177,0.54530,0.11963
9.20000,4.68660,76.67493,76.67493,0.54768,0.11159
9.24000,4.55696,77.00836,77.00835,0.55006,0.10850
9.28000,4.59328,77.34168,77.34168,0.55244,0.10936
9.32000,5.18896,77.67494,77.67494,0.55482,0.12355
9.36000,5.00046,78.00840,78.00841,0.55720,0.11906
9.40000,4.64059,78.34162,78.34162,0.55958,0.11049
9.44000,4.45079,78.67512,78.67513,0.56197,0.10597
9.48000,4.71268,79.00826,79.00826,0.56434,0.11221
9.52000,4.60614,79.34174,79.34174,0.56673,0.10967
9.56000,4.55398,79.67496,79.67496,0.56911,0.10843
9.60000,4.64041,80.00838,80.00838,0.57149,0.11049
9.64000,4.57894,80.34168,80.34169,0.57387,0.10902
9.68000,4.77731,80.67500,80.67500,0.57625,0.11375
9.72000,5.07254,81.00837,81.00837,0.57863,0.12077
9.76000,5.16977,81.34161,81.34161,0.58101,0.12309
9.80000,4.94570,81.67512,81.67513,0.58339,0.11775
9.84000,4.90956,82.00818,82.00818,0.58577,0.11689
9.88000,5.00325,82.34176,82.34176,0.58816,0.11913
9.92000,5.53466,82.67496,82.67496,0.59054,0.13178
9.96000,4.82611,83.00840,83.00840,0.59292,0.11491
10.00000,5.17350,83.34168,83.34168,0.59530,0.12318
10.04000,5.48027,83.67494,83.67494,0.59768,0.13048
10.08000,5.13792,84.00840,84.00840,0.60006,0.12233
10.12000,5.29140,84.34159,84.34159,0.60244,0.12599
10.16000,5.52051,84.67512,84.67513,0.60482,0.13144
10.20000,5.43930,85.00828,85.00829,0.60720,0.12951
10.24000,5.56950,85.34174,85.34174,0.60958,0.13261
10.28000,5.73732,85.67490,85.67490,0.61196,0.13660
10.32000,5.33592,86.00838,86.00839,0.61435,0.12705
10.36000,5.62798,86.34167,86.34167,0.61673,0.13400
10.40000,5.47841,86.67499,86.67499,0.61911,0.13044
10.44000,5.67250,87.00842,87.00842,0.62149,0.13506
10.48000,5.93588,87.34153,87.34154,0.62387,0.14133
10.52000,5.53206,87.67509,87.67509,0.62625,0.13172
10.56000,5.88391,88.00828,88.00829,0.62863,0.14009
10.60000,5.84871,88.34174,88.34174,0.63101,0.13925
10.64000,5.92824,88.67495,88.67496,0.63339,0.14115
10.68000,5.70100,89.00835,89.00834,0.63577,0.13574
10.72000,5.64493,89.34170,89.34170,0.63815,0.13440
10.76000,5.78649,89.67502,89.67503,0.64054,0.13777
10.80000,6.02249,90.00842,90.00842,0.64292,0.14339
10.84000,5.51827,90.34156,90.34156,0.64530,0.13139
10.88000,5.57173,90.67504,90.67503,0.64768,0.13266
10.92000,5.44377,91.00825,91.00825,0.65006,0.12961
10.96000,5.47897,91.34181,91.34181,0.65244,0.13045
11.00000,5.83269,91.67495,91.67495,0.65482,0.13887
11.04000,5.57136,92.00833,92.00833,0.65720,0.13265
11.08000,5.48232,92.34165,92.34165,0.65958,0.13053
11.12000,5.73266,92.67497,92.67497,0.66196,0.13649
11.16000,5.60060,93.00840,93.00840,0.66435,0.13335
11.20000,5.59669,93.34161,93.34161,0.66673,0.13325
11.24000,6.06347,93.67507,93.67507,0.66911,0.14437
11.28000,5.91669,94.00825,94.00825,0.67149,0.14087
11.32000,6.35982,94.34181,94.34181,0.67387,0.15142
11.36000,6.85435,94.67495,94.67495,0.67625,0.16320
11.40000,6.33579,95.00838,95.00838,0.67863,0.15085
11.44000,6.40228,95.34165,95.34164,0.68101,0.15244
11.48000,6.98306,95.67497,95.67496,0.68339,0.16626
11.52000,6.97467,96.00842,96.00842,0.68577,0.16606
11.56000,7.08438,96.34158,96.34158,0.68815,0.16868
11.60000,7.70967,96.67509,96.67509,0.69054,0.18356
11.64000,7.03502,97.00818,97.00818,0.69292,0.16750
11.68000,7.57556,97.34173,97.34173,0.69530,0.18037
11.72000,7.64504,97.67500,97.67500,0.69768,0.18202
11.76000,7.35745,98.00837,98.00838,0.70006,0.17518
11.80000,7.40513,98.34167,98.34167,0.70244,0.17631
11.84000,7.50236,98.67497,98.67497,0.70482,0.17863
11.88000,7.44797,99.00836,99.00836,0.70720,0.17733
11.92000,7.77170,99.34166,99.34166,0.70958,0.18504
11.96000,7.44909,99.67511,99.67511,0.71197,0.17736
12.00000,7.20676,100.00825,100.00825,0.71434,0.17159
12.04000,7.08103,100.34173,100.34174,0.71673,0.16860
12.08000,7.77598,100.67495,100.67495,0.71911,0.18514
12.12000,8.01664,101.00840,101.00841,0.72149,0.19087
12.16000,7.64243,101.34167,101.34167,0.72387,0.18196
12.20000,7.92667,101.67493,101.67493,0.72625,0.18873
12.24000,7.67987,102.00836,102.00836,0.72863,0.18285
12.28000,8.21948,102.34157,102.34158,0.73101,0.19570
12.32000,8.13417,102.67511,102.67511,0.73339,0.19367
12.36000,8.09617,103.00825,103.00825,0.73577,0.19277
12.40000,7.97603,103.34173,103.34173,0.73816,0.18991
12.44000,8.23177,103.67495,103.67494,0.74054,0.19599
12.48000,7.97119,104.00846,104.00846,0.74292,0.18979
12.52000,7.81510,104.34167,104.34167,0.74530,0.18607
12.56000,7.64392,104.67499,104.67499,0.74768,0.18200
12.60000,7.82274,105.00836,105.00836,0.75006,0.18626
12.64000,7.81566,105.34157,105.34158,0.75244,0.18609
12.68000,8.10493,105.67514,105.67514,0.75482,0.19297
12.72000,8.25319,106.00825,106.00826,0.75720,0.19650
12.76000,7.64523,106.34175,106.34175,0.75958,0.18203
12.80000,8.20924,106.67491,106.67491,0.76196,0.19546
12.84000,8.17161,107.00837,107.00837,0.76435,0.19456
12.88000,8.34819,107.34164,107.34164,0.76673,0.19877
12.92000,7.79498,107.67496,107.67496,0.76911,0.18559
12.96000,8.14274,108.00841,108.00842,0.77149,0.19387
13.00000,8.15671,108.34163,108.34163,0.77387,0.19421
13.04000,7.95238,108.67513,108.67513,0.77625,0.18934
13.08000,7.79442,109.00827,109.00827,0.77863,0.18558
13.12000,8.26027,109.34178,109.34179,0.78101,0.19667
13.16000,8.26046,109.67491,109.67491,0.78339,0.19668
13.20000,8.05315,110.00837,110.00837,0.78577,0.19174
13.24000,8.33776,110.34171,110.34171,0.78816,0.19852
13.28000,8.68719,110.67497,110.67496,0.79054,0.20684
13.32000,8.49646,111.00839,111.00838,0.79292,0.20230
13.36000,8.03545,111.34157,111.34158,0.79530,0.19132
13.40000,8.40686,111.67506,111.67506,0.79768,0.20016
13.44000,8.14050,112.00825,112.00825,0.80006,0.19382
13.48000,8.54433,112.34176,112.34176,0.80244,0.20344
13.52000,8.21184,112.67494,112.67494,0.80482,0.19552
13.56000,8.19396,113.00834,113.00834,0.80720,0.19509
13.60000,7.82236,113.34167,113.34167,0.80958,0.18625
13.64000,8.20961,113.67504,113.67504,0.81196,0.19547
13.68000,8.28411,114.00841,114.00841,0.81435,0.19724
13.72000,8.43164,114.34161,114.34161,0.81673,0.20075
13.76000,8.14795,114.67510,114.67510,0.81911,0.19400
13.80000,8.36458,115.00826,115.00826,0.82149,0.19916
13.84000,8.52570,115.34180,115.34180,0.82387,0.20299
13.88000,8.65012,115.67491,115.67491,0.82625,0.20596
13.92000,8.10437,116.00829,116.00829,0.82863,0.19296
13.96000,8.65925,116.34166,116.34166,0.83101,0.20617
14.00000,8.64640,116.67500,116.67500,0.83339,0.20587
14.04000,8.30907,117.00841,117.00842,0.83577,0.19784
14.08000,8.46460,117.34160,117.34160,0.83815,0.20154
14.12000,8.12542,117.67508,117.67509,0.84054,0.19346
14.16000,8.45846,118.00822,118.00822,0.84292,0.20139
14.20000,8.63560,118.34180,118.34180,0.84530,0.20561
14.24000,8.31466,118.67496,118.67496,0.84768,0.19797
14.28000,8.55587,119.00842,119.00842,0.85006,0.20371
14.32000,8.86917,119.34163,119.34163,0.85244,0.21117
14.36000,8.59518,119.67496,119.67496,0.85482,0.20465
14.40000,8.35434,120.00843,120.00843,0.85720,0.19891
14.44000,8.10344,120.34159,120.34159,0.85958,0.19294
14.48000,8.53967,120.67510,120.67510,0.86197,0.20333
14.52000,8.47448,121.00824,121.00824,0.86434,0.20177
14.56000,8.52104,121.34172,121.34172,0.86673,0.20288
14.60000,8.46349,121.67499,121.67499,0.86911,0.20151
14.64000,8.47243,122.00838,122.00838,0.87149,0.20172
14.68000,8.58232,122.34163,122.34164,0.87387,0.20434
14.72000,8.53688,122.67495,122.67495,0.87625,0.20326
14.76000,8.76151,123.00841,123.00841,0.87863,0.20861
14.80000,8.63466,123.34165,123.34165,0.88101,0.20559
14.84000,8.66912,123.67512,123.67513,0.88339,0.20641
14.88000,8.71867,124.00823,124.00823,0.88577,0.20759
14.92000,9.09436,124.34172,124.34172,0.88816,0.21653
14.96000,8.63597,124.67496,124.67496,0.89054,0.20562
15.00000,8.58828,125.00842,125.00842,0.89292,0.20448
15.04000,8.83024,125.34171,125.34171,0.89530,0.21024
15.08000,8.80454,125.67496,125.67496,0.89768,0.20963
15.12000,8.69539,126.00835,126.00835,0.90006,0.20703
15.16000,9.14894,126.34162,126.34161,0.90244,0.21783
15.20000,8.81217,126.67510,126.67510,0.90482,0.20981
15.24000,8.63969,127.00824,127.00824,0.90720,0.20571
15.28000,8.68589,127.34174,127.34174,0.90958,0.20681
15.32000,9.04985,127.67488,127.67488,0.91196,0.21547
15.36000,8.89394,128.00838,128.00838,0.91435,0.21176
15.40000,8.98112,128.34171,128.34171,0.91673,0.21384
15.44000,9.10126,128.67498,128.67497,0.91911,0.21670
15.48000,8.86563,129.00837,129.00838,0.92149,0.21109
15.52000,8.98149,129.34160,129.34160,0.92387,0.21384
15.56000,8.91164,129.67512,129.67513,0.92625,0.21218
15.60000,8.60579,130.00826,130.00826,0.92863,0.20490
15.64000,8.48323,130.34177,130.34177,0.93101,0.20198
15.68000,8.89786,130.67493,130.67493,0.93339,0.21185
15.72000,9.19662,131.00836,131.00836,0.93577,0.21897
15.76000,8.92486,131.34169,131.34169,0.93815,0.21250
15.80000,9.01185,131.67502,131.67502,0.94054,0.21457
15.84000,9.05413,132.00838,132.00838,0.94292,0.21557
15.88000,9.27635,132.34156,132.34157,0.94530,0.22087
15.92000,9.34079,132.67508,132.67508,0.94768,0.22240
15.96000,9.17632,133.00820,133.00819,0.95006,0.21848
16.00000,9.26219,133.34183,133.34183,0.95244,0.22053
16.04000,9.23183,133.67499,133.67499,0.95482,0.21981
16.08000,9.32254,134.00838,134.00838,0.95720,0.22197
16.12000,9.38084,134.34167,134.34167,0.95958,0.22335
16.16000,9.38717,134.67500,134.67500,0.96196,0.22350
16.20000,9.11411,135.00840,135.00839,0.96435,0.21700
16.24000,9.06549,135.34160,135.34160,0.96673,0.21585
16.28000,9.08561,135.67508,135.67508,0.96911,0.21632
16.32000,9.09679,136.00826,136.00826,0.97149,0.21659
16.36000,9.35048,136.34174,136.34174,0.97387,0.22263
16.40000,9.49949,136.67493,136.67493,0.97625,0.22618
16.44000,9.10871,137.00836,137.00836,0.97863,0.21687
16.48000,9.15062,137.34160,137.34160,0.98101,0.21787
16.52000,8.91685,137.67499,137.67499,0.98339,0.21231
16.56000,9.12379,138.00842,138.00842,0.98577,0.21723
16.60000,9.31695,138.34156,138.34157,0.98815,0.22183
16.64000,9.43709,138.67513,138.67513,0.99054,0.22469
16.68000,9.22158,139.00826,139.00826,0.99292,0.21956
16.72000,9.16943,139.34176,139.34177,0.99530,0.21832
16.76000,9.63658,139.67499,139.67499,0.99768,0.22944
16.80000,9.25306,140.00838,140.00838,1.00006,0.22031
16.84000,9.43709,140.34167,140.34166,1.00244,0.22469
16.88000,9.45833,140.67500,140.67500,1.00482,0.22520
16.92000,9.57642,141.00840,141.00839,1.00720,0.22801
16.96000,9.53954,141.34156,141.34155,1.00958,0.22713
17.00000,9.58145,141.67509,141.67509,1.01196,0.22813
17.04000,9.43057,142.00820,142.00821,1.01434,0.22454
17.08000,9.59020,142.34179,142.34180,1.01673,0.22834
17.12000,9.62652,142.67495,142.67497,1.01911,0.22920
17.16000,9.75318,143.00839,143.00838,1.02149,0.23222
17.20000,10.04431,143.34168,143.34167,1.02387,0.23915
17.24000,9.91058,143.67494,143.67493,1.02625,0.23597
17.28000,9.78429,144.00845,144.00845,1.02863,0.23296
17.32000,9.53600,144.34164,144.34164,1.03101,0.22705
17.36000,9.58461,144.67510,144.67511,1.03339,0.22821
17.40000,9.66061,145.00826,145.00826,1.03577,0.23001
17.44000,10.22816,145.34173,145.34174,1.03816,0.24353
17.48000,9.93293,145.67495,145.67494,1.04054,0.23650
17.52000,9.96161,146.00838,146.00838,1.04292,0.23718
17.56000,10.30229,146.34164,146.34164,1.04530,0.24529
17.60000,10.13149,146.67493,146.67494,1.04768,0.24123
17.64000,9.94224,147.00832,147.00832,1.05006,0.23672
17.68000,10.02401,147.34158,147.34157,1.05244,0.23867
17.72000,9.87295,147.67512,147.67513,1.05482,0.23507
17.76000,10.08529,148.00824,148.00824,1.05720,0.24013
17.80000,9.91598,148.34177,148.34177,1.05958,0.23609
17.84000,9.84091,148.67498,148.67497,1.06196,0.23431
17.88000,9.83495,149.00842,149.00841,1.06435,0.23417
17.92000,9.65316,149.34173,149.34174,1.06673,0.22984
17.96000,10.15365,149.67498,149.67499,1.06911,0.24175
18.00000,10.04040,150.00835,150.00836,1.07149,0.23906
18.04000,10.24995,150.34164,150.34164,1.07387,0.24405
18.08000,9.91952,150.67514,150.67514,1.07625,0.23618
18.12000,10.16334,151.00826,151.00826,1.07863,0.24198
18.16000,10.22220,151.34172,151.34172,1.08101,0.24339
18.20000,10.20934,151.67488,151.67488,1.08339,0.24308
18.24000,10.11174,152.00835,152.00835,1.08577,0.24076
18.28000,10.57871,152.34170,152.34169,1.08815,0.25187
18.32000,10.27063,152.67500,152.67502,1.09054,0.24454
18.36000,10.51016,153.00842,153.00842,1.09292,0.25024
18.40000,10.77317,153.34155,153.34155,1.09530,0.25650
18.44000,10.72660,153.67517,153.67516,1.09768,0.25540
18.48000,10.49526,154.00830,154.00829,1.10006,0.24989
18.52000,10.53959,154.34174,154.34174,1.10244,0.25094
18.56000,10.37363,154.67494,154.67494,1.10482,0.24699
18.60000,10.42262,155.00836,155.00836,1.10720,0.24816
18.64000,10.48632,155.34165,155.34166,1.10958,0.24967
18.68000,10.96055,155.67502,155.67503,1.11196,0.26097
18.72000,10.83650,156.00840,156.00841,1.11435,0.25801
18.76000,11.16432,156.34156,156.34155,1.11673,0.26582
18.80000,11.20269,156.67510,156.67509,1.11911,0.26673
18.84000,10.99762,157.00828,157.00829,1.12149,0.26185
18.88000,10.78732,157.34178,157.34178,1.12387,0.25684
18.92000,11.05182,157.67494,157.67493,1.12625,0.26314
18.96000,10.76721,158.00834,158.00833,1.12863,0.25636
19.00000,10.90728,158.34164,158.34164,1.13101,0.25970
19.04000,10.98830,158.67504,158.67503,1.13339,0.26163
19.08000,10.99240,159.00845,159.00844,1.13577,0.26172
19.12000,10.99240,159.34163,159.34163,1.13815,0.26172
19.16000,11.13340,159.67505,159.67505,1.14054,0.26508
19.20000,11.08740,160.00824,160.00824,1.14292,0.26399
19.24000,11.20679,160.34180,160.34180,1.14530,0.26683
19.28000,11.17643,160.67492,160.67493,1.14768,0.26611
19.32000,10.99352,161.00837,161.00838,1.15006,0.26175
19.36000,11.30756,161.34165,161.34164,1.15244,0.26923
19.40000,11.28558,161.67497,161.67497,1.15482,0.26870
19.44000,10.97601,162.00841,162.00841,1.15720,0.26133
19.48000,11.21722,162.34157,162.34157,1.15958,0.26708
19.52000,10.97750,162.67508,162.67508,1.16196,0.26137
19.56000,11.44186,163.00822,163.00822,1.16434,0.27243
19.60000,11.47501,163.34178,163.34178,1.16673,0.27321
19.64000,11.16861,163.67497,163.67497,1.16911,0.26592
19.68000,11.28912,164.00840,164.00842,1.17149,0.26879
19.72000,11.51059,164.34167,164.34167,1.17387,0.27406
19.76000,11.36996,164.67498,164.67499,1.17625,0.27071
19.80000,11.54225,165.00842,165.00842,1.17863,0.27482
19.84000,11.33792,165.34162,165.34161,1.18101,0.26995
19.88000,11.56852,165.67512,165.67511,1.18339,0.27544
19.92000,11.75944,166.00821,166.00821,1.18577,0.27999
19.96000,11.40162,166.34178,166.34178,1.18816,0.27147
20.00000,11.42211,166.67492,166.67493,1.19054,0.27196
20.04000,11.41261,167.00834,167.00835,1.19292,0.27173
20.08000,11.70915,167.34169,167.34169,1.19530,0.27879
20.12000,11.85276,167.67495,167.67496,1.19768,0.28221
20.16000,12.04889,168.00841,168.00842,1.20006,0.28688
20.20000,11.43496,168.34160,168.34160,1.20244,0.27226
20.24000,11.40200,168.67512,168.67513,1.20482,0.27148
20.28000,11.83022,169.00828,169.00830,1.20720,0.28167
20.32000,12.00456,169.34176,169.34175,1.20958,0.28582
20.36000,12.11483,169.67497,169.67496,1.21196,0.28845
20.40000,11.99078,170.00843,170.00842,1.21435,0.28549
20.44000,11.92242,170.34167,170.34166,1.21673,0.28387
20.48000,12.41714,170.67496,170.67496,1.21911,0.29565
20.52000,12.03213,171.00833,171.00833,1.22149,0.28648
20.56000,12.12638,171.34158,171.34158,1.22387,0.28872
20.60000,12.25565,171.67517,171.67517,1.22625,0.29180
20.64000,12.23106,172.00821,172.00821,1.22863,0.29122
20.68000,12.56634,172.34170,172.34169,1.23101,0.29920
20.72000,11.96098,172.67494,172.67494,1.23339,0.28479
20.76000,12.02356,173.00836,173.00835,1.23577,0.28628
20.80000,12.17574,173.34169,173.34169,1.23815,0.28990
20.84000,12.56354,173.67500,173.67500,1.24054,0.29913
20.88000,12.44899,174.00841,174.00841,1.24292,0.29640
20.92000,12.62650,174.34162,174.34163,1.24530,0.30063
20.96000,12.40764,174.67516,174.67516,1.24768,0.29542
21.00000,12.42645,175.00827,175.00826,1.25006,0.29587
21.04000,12.60526,175.34174,175.34174,1.25244,0.30013
21.08000,12.51046,175.67494,175.67496,1.25482,0.29787
21.12000,12.31786,176.00836,176.00836,1.25720,0.29328
21.16000,12.61365,176.34172,176.34172,1.25958,0.30032
21.20000,12.80569,176.67493,176.67494,1.26196,0.30490
21.24000,12.81966,177.00835,177.00835,1.26435,0.30523
21.28000,12.74534,177.34154,177.34154,1.26673,0.30346
21.32000,12.63097,177.67505,177.67505,1.26911,0.30074
21.36000,12.67660,178.00830,178.00830,1.27149,0.30182
21.40000,13.08750,178.34180,178.34180,1.27387,0.31161
21.44000,12.86771,178.67496,178.67497,1.27625,0.30637
21.48000,13.33058,179.00842,179.00842,1.27863,0.31739
21.52000,12.89807,179.34171,179.34171,1.28101,0.30710
21.56000,12.96550,179.67500,179.67500,1.28339,0.30870
21.60000,13.30376,180.00841,180.00841,1.28577,0.31676
21.64000,13.02194,180.34160,180.34160,1.28815,0.31005
21.68000,12.91037,180.67508,180.67508,1.29054,0.30739
21.72000,13.09793,181.00824,181.00824,1.29292,0.31186
21.76000,13.06124,181.34178,181.34178,1.29530,0.31098
21.80000,12.87647,181.67490,181.67490,1.29768,0.30658
21.84000,13.13332,182.00831,182.00832,1.30006,0.31270
21.88000,13.15363,182.34165,182.34166,1.30244,0.31318
21.92000,13.07763,182.67502,182.67502,1.30482,0.31137
21.96000,13.38851,183.00844,183.00844,1.30720,0.31877
22.00000,13.40844,183.34164,183.34164,1.30958,0.31925
22.04000,13.52914,183.67507,183.67509,1.31196,0.32212
22.08000,14.03689,184.00824,184.00824,1.31434,0.33421
22.12000,13.73999,184.34185,184.34186,1.31673,0.32714
22.16000,13.73589,184.67499,184.67499,1.31911,0.32705
22.20000,13.91228,185.00838,185.00836,1.32149,0.33124
22.24000,13.77054,185.34163,185.34161,1.32387,0.32787
22.28000,13.53621,185.67497,185.67497,1.32625,0.32229
22.32000,13.63643,186.00840,186.00839,1.32863,0.32468
22.36000,13.72378,186.34156,186.34154,1.33101,0.32676
22.40000,13.74874,186.67508,186.67508,1.33339,0.32735
22.44000,13.47587,187.00822,187.00821,1.33577,0.32085
22.48000,13.72583,187.34174,187.34174,1.33816,0.32681
22.52000,13.87633,187.67500,187.67500,1.34054,0.33039
22.56000,13.78451,188.00841,188.00841,1.34292,0.32820
22.60000,13.98493,188.34169,188.34169,1.34530,0.33297
22.64000,13.87186,188.67502,188.67500,1.34768,0.33028
22.68000,13.53584,189.00845,189.00845,1.35006,0.32228
22.72000,14.53776,189.34161,189.34161,1.35244,0.34614
22.76000,14.11252,189.67513,189.67511,1.35482,0.33601
22.80000,14.42824,190.00823,190.00824,1.35720,0.34353
22.84000,14.63424,190.34172,190.34172,1.35958,0.34843
22.88000,14.44556,190.67496,190.67496,1.36196,0.34394
22.92000,14.10022,191.00835,191.00836,1.36435,0.33572
22.96000,14.48393,191.34168,191.34169,1.36673,0.34486
23.00000,14.31294,191.67497,191.67499,1.36911,0.34078
23.04000,14.31890,192.00836,192.00836,1.37149,0.34093
23.08000,14.65064,192.34159,192.34161,1.37387,0.34882
23.12000,14.20733,192.67516,192.67516,1.37625,0.33827
23.16000,14.52863,193.00825,193.00826,1.37863,0.34592
23.20000,14.60090,193.34177,193.34175,1.38101,0.34764
23.24000,14.53981,193.67493,193.67493,1.38339,0.34619
23.28000,14.85348,194.00844,194.00845,1.38577,0.35365
23.32000,14.92891,194.34170,194.34171,1.38815,0.35545
23.36000,14.39992,194.67495,194.67496,1.39054,0.34286
23.40000,14.60426,195.00840,195.00841,1.39292,0.34772
23.44000,14.63685,195.34160,195.34160,1.39530,0.34850
23.48000,14.91960,195.67510,195.67511,1.39768,0.35523
23.52000,14.79667,196.00826,196.00826,1.40006,0.35230
23.56000,14.57836,196.34175,196.34175,1.40244,0.34710
23.60000,15.03341,196.67491,196.67491,1.40482,0.35794
23.64000,14.94084,197.00838,197.00838,1.40720,0.35573
23.68000,15.21558,197.34171,197.34172,1.40958,0.36228
23.72000,15.16156,197.67500,197.67500,1.41196,0.36099
23.76000,14.95127,198.00839,198.00838,1.41435,0.35598
23.80000,15.24463,198.34159,198.34160,1.41673,0.36297
23.84000,15.51565,198.67512,198.67513,1.41911,0.36942
23.88000,15.48715,199.00825,199.00827,1.42149,0.36874
23.92000,15.24128,199.34180,199.34181,1.42387,0.36289
23.96000,15.48119,199.67496,199.67496,1.42625,0.36860
24.00000,15.02410,200.00836,200.00838,1.42863,0.35772
24.04000,15.29977,200.34173,200.34174,1.43101,0.36428
24.08000,15.11108,200.67494,200.67494,1.43339,0.35979
24.12000,15.47877,201.00837,201.00838,1.43577,0.36854
24.16000,15.77456,201.34161,201.34161,1.43815,0.37558
24.20000,15.71495,201.67510,201.67509,1.44054,0.37417
24.24000,15.66447,202.00826,202.00826,1.44292,0.37296
24.28000,15.54582,202.34174,202.34175,1.44530,0.37014
24.32000,15.87551,202.67492,202.67491,1.44768,0.37799
24.36000,15.76822,203.00838,203.00839,1.45006,0.37543
24.40000,15.68235,203.34167,203.34167,1.45244,0.37339
24.44000,16.14485,203.67502,203.67502,1.45482,0.38440
24.48000,15.57805,204.00846,204.00845,1.45720,0.37091
24.52000,15.88110,204.34158,204.34158,1.45958,0.37812
24.56000,16.00068,204.67509,204.67509,1.46196,0.38097
24.60000,15.76468,205.00825,205.00826,1.46434,0.37535
24.64000,15.80156,205.34176,205.34177,1.46673,0.37623
24.68000,15.97796,205.67498,205.67496,1.46911,0.38043
24.72000,15.58755,206.00836,206.00836,1.47149,0.37113
24.76000,15.61102,206.34165,206.34166,1.47387,0.37169
24.80000,15.84459,206.67502,206.67503,1.47625,0.37725
24.84000,16.07016,207.00837,207.00838,1.47863,0.38262
24.88000,16.01651,207.34157,207.34157,1.48101,0.38135
24.92000,16.02992,207.67510,207.67509,1.48339,0.38166
24.96000,16.27896,208.00822,208.00822,1.48577,0.38759
25.00000,16.22029,208.34182,208.34183,1.48816,0.38620
25.04000,16.20576,208.67498,208.67499,1.49054,0.38585
25.08000,16.35849,209.00838,209.00838,1.49292,0.38949
25.12000,16.09791,209.34164,209.34164,1.49530,0.38328
25.16000,16.30299,209.67500,209.67500,1.49768,0.38817
25.20000,16.18508,210.00846,210.00845,1.50006,0.38536
25.24000,16.47845,210.34162,210.34161,1.50244,0.39234
25.28000,16.42797,210.67506,210.67506,1.50482,0.39114
25.32000,16.22513,211.00825,211.00826,1.50720,0.38631
25.36000,16.23277,211.34174,211.34174,1.50958,0.38649
25.40000,16.66248,211.67495,211.67494,1.51196,0.39673
25.44000,16.36408,212.00840,212.00839,1.51435,0.38962
25.48000,16.61889,212.34165,212.34164,1.51673,0.39569
25.52000,16.93498,212.67496,212.67496,1.51911,0.40321
25.56000,17.08083,213.00844,213.00842,1.52149,0.40669
25.60000,17.09089,213.34164,213.34163,1.52387,0.40693
25.64000,16.88469,213.67514,213.67514,1.52625,0.40202
25.68000,17.33266,214.00828,214.00829,1.52863,0.41268
25.72000,16.91077,214.34173,214.34172,1.53101,0.40264
25.76000,17.17210,214.67494,214.67494,1.53339,0.40886
25.80000,16.98807,215.00838,215.00838,1.53577,0.40448
25.84000,17.15310,215.34167,215.34166,1.53815,0.40841
25.88000,17.19557,215.67500,215.67500,1.54054,0.40942
25.92000,17.36432,216.00834,216.00833,1.54292,0.41344
25.96000,17.05810,216.34164,216.34166,1.54530,0.40615
26.00000,17.03538,216.67512,216.67511,1.54768,0.40560
26.04000,17.42058,217.00822,217.00822,1.55006,0.41478
26.08000,17.45541,217.34176,217.34177,1.55244,0.41560
26.12000,17.57387,217.67490,217.67490,1.55482,0.41843
26.16000,17.21177,218.00842,218.00842,1.55720,0.40980
26.20000,17.40567,218.34175,218.34175,1.55958,0.41442
26.24000,17.40810,218.67502,218.67502,1.56196,0.41448
26.28000,17.59436,219.00842,219.00842,1.56435,0.41891
26.32000,17.59306,219.34158,219.34158,1.56673,0.41888
26.36000,17.41704,219.67511,219.67511,1.56911,0.41469
26.40000,17.51017,220.00827,220.00827,1.57149,0.41691
26.44000,17.41629,220.34172,220.34172,1.57387,0.41467
26.48000,17.55767,220.67490,220.67490,1.57625,0.41804
26.52000,17.15161,221.00838,221.00838,1.57863,0.40837
26.56000,17.63068,221.34167,221.34166,1.58101,0.41978
26.60000,17.24400,221.67498,221.67499,1.58339,0.41057
26.64000,17.81210,222.00838,222.00838,1.58577,0.42410
26.68000,18.17569,222.34159,222.34158,1.58815,0.43275
26.72000,17.88493,222.67517,222.67517,1.59054,0.42583
26.76000,18.06114,223.00828,223.00827,1.59292,0.43003
26.80000,18.33756,223.34172,223.34172,1.59530,0.43661
26.84000,18.01290,223.67499,223.67499,1.59768,0.42888
26.88000,18.17681,224.00836,224.00836,1.60006,0.43278
26.92000,18.16321,224.34170,224.34171,1.60244,0.43246
26.96000,18.31912,224.67501,224.67502,1.60482,0.43617
27.00000,18.41299,225.00841,225.00841,1.60720,0.43840
27.04000,18.39940,225.34160,225.34160,1.60958,0.43808
27.08000,18.64042,225.67507,225.67506,1.61196,0.44382
27.12000,18.74715,226.00826,226.00826,1.61434,0.44636
27.16000,18.57001,226.34175,226.34175,1.61673,0.44214
27.20000,18.23455,226.67494,226.67494,1.61911,0.43416
27.24000,18.31222,227.00836,227.00836,1.62149,0.43601
27.28000,18.72946,227.34165,227.34164,1.62387,0.44594
27.32000,18.50240,227.67499,227.67499,1.62625,0.44053
27.36000,18.63465,228.00844,228.00844,1.62863,0.44368
27.40000,18.70226,228.34158,228.34158,1.63101,0.44529
27.44000,18.48266,228.67510,228.67509,1.63339,0.44006
27.48000,18.79968,229.00829,229.00829,1.63577,0.44761
27.52000,18.73802,229.34181,229.34181,1.63816,0.44614
27.56000,18.74678,229.67495,229.67494,1.64054,0.44635
27.60000,18.85574,230.00839,230.00839,1.64292,0.44895
27.64000,18.39884,230.34161,230.34160,1.64530,0.43807
27.68000,18.98427,230.67497,230.67497,1.64768,0.45201
27.72000,18.91721,231.00845,231.00845,1.65006,0.45041
27.76000,18.87251,231.34163,231.34163,1.65244,0.44935
27.80000,19.34245,231.67511,231.67511,1.65482,0.46053
27.84000,19.27074,232.00822,232.00821,1.65720,0.45883
27.88000,19.40541,232.34177,232.34177,1.65958,0.46203
27.92000,19.48681,232.67498,232.67497,1.66196,0.46397
27.96000,19.48383,233.00837,233.00838,1.66435,0.46390
28.00000,19.54157,233.34172,233.34172,1.66673,0.46528
28.04000,19.40224,233.67498,233.67499,1.66911,0.46196
28.08000,19.45049,234.00845,234.00845,1.67149,0.46311
28.12000,19.43614,234.34161,234.34161,1.67387,0.46277
28.16000,19.44471,234.67503,234.67503,1.67625,0.46297
28.20000,19.23032,235.00825,235.00824,1.67863,0.45786
28.24000,19.19456,235.34175,235.34175,1.68101,0.45701
28.28000,19.57603,235.67496,235.67496,1.68339,0.46610
28.32000,19.34581,236.00838,236.00838,1.68577,0.46061
28.36000,19.83419,236.34167,236.34167,1.68815,0.47224
28.40000,19.95675,236.67496,236.67496,1.69054,0.47516
28.44000,19.85505,237.00838,237.00838,1.69292,0.47274
28.48000,19.89901,237.34162,237.34161,1.69530,0.47379
28.52000,20.09626,237.67512,237.67513,1.69768,0.47848
28.56000,20.23447,238.00828,238.00829,1.70006,0.48177
28.60000,20.19517,238.34175,238.34175,1.70244,0.48084
28.64000,20.17245,238.67496,238.67496,1.70482,0.48030
28.68000,20.08677,239.00841,239.00841,1.70720,0.47826
28.72000,20.37827,239.34168,239.34167,1.70958,0.48520
28.76000,19.98935,239.67502,239.67502,1.71196,0.47594
28.80000,20.37436,240.00836,240.00836,1.71435,0.48510
28.84000,19.93440,240.34160,240.34160,1.71673,0.47463
28.88000,20.31736,240.67515,240.67516,1.71911,0.48375
28.92000,20.12514,241.00821,241.00821,1.72149,0.47917
28.96000,20.50996,241.34176,241.34175,1.72387,0.48833
29.00000,20.21268,241.67494,241.67494,1.72625,0.48125
29.04000,20.05957,242.00837,242.00836,1.72863,0.47761
29.08000,20.31364,242.34173,242.34174,1.73101,0.48366
29.12000,20.73888,242.67497,242.67497,1.73339,0.49378
29.16000,20.93893,243.00839,243.00839,1.73577,0.49855
29.20000,20.65673,243.34155,243.34155,1.73815,0.49183
29.24000,20.77799,243.67516,243.67516,1.74054,0.49471
29.28000,20.61632,244.00832,244.00832,1.74292,0.49086
29.32000,20.93539,244.34176,244.34177,1.74530,0.49846
29.36000,20.54702,244.67490,244.67490,1.74768,0.48921
29.40000,20.73143,245.00840,245.00839,1.75006,0.49361
29.44000,20.69920,245.34169,245.34169,1.75244,0.49284
29.48000,20.72547,245.67498,245.67497,1.75482,0.49346
29.52000,20.77315,246.00840,246.00839,1.75720,0.49460
29.56000,20.93129,246.34156,246.34155,1.75958,0.49836
29.60000,21.26973,246.67511,246.67511,1.76197,0.50642
29.64000,21.13804,247.00830,247.00830,1.76434,0.50329
29.68000,20.88007,247.34174,247.34175,1.76673,0.49714
29.72000,21.37125,247.67496,247.67496,1.76911,0.50884
29.76000,21.36137,248.00838,248.00838,1.77149,0.50860
29.80000,21.25744,248.34169,248.34169,1.77387,0.50613
29.84000,21.79891,248.67504,248.67503,1.77625,0.51902
29.88000,21.38782,249.00843,249.00844,1.77863,0.50923
29.92000,21.16486,249.34159,249.34160,1.78101,0.50393
29.96000,21.00877,249.67504,249.67503,1.78339,0.50021
30.00000,21.07061,250.00823,250.00822,1.78577,0.50168
30.04000,20.96072,250.34178,250.34178,1.78816,0.49906
30.08000,21.07043,250.67494,250.67494,1.79054,0.50168
30.12000,21.19988,251.00838,251.00838,1.79292,0.50476
30.16000,21.34871,251.34165,251.34164,1.79530,0.50830
30.20000,21.40496,251.67497,251.67497,1.79768,0.50964
30.24000,21.51616,252.00841,252.00841,1.80006,0.51229
30.28000,21.65530,252.34160,252.34160,1.80244,0.51560
30.32000,21.67951,252.67512,252.67513,1.80482,0.51618
30.36000,21.60426,253.00823,253.00822,1.80720,0.51439
30.40000,21.88962,253.34178,253.34178,1.80958,0.52118
30.44000,21.76128,253.67500,253.67499,1.81196,0.51813
30.48000,21.67746,254.00842,254.00842,1.81435,0.51613
30.52000,21.16337,254.34165,254.34166,1.81673,0.50389
30.56000,21.52324,254.67497,254.67497,1.81911,0.51246
30.60000,3.62918,255.00842,255.00842,1.82149,0.08641
30.61100,-0.16335,255.10000,255.10001,1.82214,-0.00389