File: raw_data/mechanical_tests_Instron_data/Silicone_0035-Skin_Longitudinal_2.is_tens_RawData/Specimen_RawData_1.csv
Dimension : Area,0.42000,cm^2

Time,Extension,Load,Tensile extension,Tensile stress
(sec),(mm),(N),(mm),(MPa)
0.00000,0.00000,0.00577,0.00000,0.00014
0.04000,0.06078,1.02315,0.06078,0.02436
0.08000,0.26255,0.93449,0.26255,0.02225
0.12000,0.59328,2.12584,0.59328,0.05062
0.16000,0.97567,2.22940,0.97567,0.05308
0.20000,1.37220,2.13552,1.37220,0.05085
0.24000,1.77715,2.17762,1.77715,0.05185
0.28000,2.18772,2.28733,2.18772,0.05446
0.32000,2.60220,2.27466,2.60220,0.05416
0.36000,3.00254,1.88909,3.00254,0.04498
0.40000,3.34331,1.98595,3.34331,0.04728
0.44000,3.67109,2.03829,3.67109,0.04853
0.48000,4.00623,1.78460,4.00623,0.04249
0.52000,4.34153,1.71624,4.34153,0.04086
0.56000,4.67477,1.81515,4.67478,0.04322
0.60000,5.00820,1.99396,5.00820,0.04748
0.64000,5.34163,2.00085,5.34163,0.04764
0.68000,5.67490,2.11690,5.67490,0.05040
0.72000,6.00838,2.11783,6.00838,0.05042
0.76000,6.34151,1.86749,6.34152,0.04446
0.80000,6.67510,2.28118,6.67510,0.05431
0.84000,7.00821,2.21021,7.00821,0.05262
0.88000,7.34169,2.33538,7.34169,0.05560
0.92000,7.67491,2.05915,7.67491,0.04903
0.96000,8.00833,2.14614,8.00834,0.05110
1.00000,8.34174,1.81962,8.34174,0.04332
1.04000,8.67498,1.94181,8.67498,0.04623
1.08000,9.00838,2.06549,9.00838,0.04918
1.12000,9.34157,1.98036,9.34157,0.04715
1.16000,9.67513,2.15638,9.67513,0.05134
1.20000,10.00826,1.85650,10.00826,0.04420
1.24000,10.34175,2.29795,10.34175,0.05471
1.28000,10.67493,2.56542,10.67493,0.06108
1.32000,11.00828,2.16626,11.00828,0.05158
1.36000,11.34168,2.05468,11.34168,0.04892
1.40000,11.67495,2.02283,11.67495,0.04816
1.44000,12.00838,2.53469,12.00838,0.06035
1.48000,12.34154,2.42088,12.34154,0.05764
1.52000,12.67502,2.37152,12.67502,0.05646
1.56000,13.00826,2.49054,13.00826,0.05930
1.60000,13.34172,2.41306,13.34172,0.05745
1.64000,13.67496,2.51904,13.67496,0.05998
1.68000,14.00833,2.67960,14.00833,0.06380
1.72000,14.34168,2.36295,14.34168,0.05626
1.76000,14.67500,2.31247,14.67500,0.05506
1.80000,15.00843,1.85836,15.00843,0.04425
1.84000,15.34154,1.94851,15.34154,0.04639
1.88000,15.67507,2.07331,15.67507,0.04936
1.92000,16.00823,1.77547,16.00823,0.04227
1.96000,16.34174,2.28826,16.34174,0.05448
2.00000,16.67496,2.33222,16.67496,0.05553
2.04000,17.00833,2.46186,17.00833,0.05862
2.08000,17.34163,2.51196,17.34163,0.05981
2.12000,17.67492,2.49036,17.67492,0.05929
2.16000,18.00843,2.80719,18.00843,0.06684
2.20000,18.34156,2.48048,18.34156,0.05906
2.24000,18.67507,2.45944,18.67507,0.05856
2.28000,19.00821,2.52221,19.00821,0.06005
2.32000,19.34179,2.53711,19.34179,0.06041
2.36000,19.67493,2.67122,19.67493,0.06360
2.40000,20.00833,2.29590,20.00833,0.05466
2.44000,20.34168,2.49427,20.34168,0.05939
2.48000,20.67489,2.35494,20.67489,0.05607
2.52000,21.00846,2.00719,21.00846,0.04779
2.56000,21.34156,2.17110,21.34156,0.05169
2.60000,21.67502,2.06381,21.67502,0.04914
2.64000,22.00823,2.19215,22.00823,0.05219
2.68000,22.34169,2.09026,22.34169,0.04977
2.72000,22.67495,1.92318,22.67495,0.04579
2.76000,23.00833,2.43131,23.00833,0.05789
2.80000,23.34168,2.32086,23.34168,0.05526
2.84000,23.67492,2.01054,23.67492,0.04787
2.88000,24.00837,2.08598,24.00837,0.04967
2.92000,24.34161,2.03364,24.34161,0.04842
2.96000,24.67512,2.05096,24.67512,0.04883
3.00000,25.00823,1.90493,25.00823,0.04536
3.04000,25.34171,2.00011,25.34171,0.04762
3.08000,25.67495,2.17576,25.67495,0.05180
3.12000,26.00835,2.14018,26.00835,0.05096
3.16000,26.34168,1.81217,26.34168,0.04315
3.20000,26.67492,2.42703,26.67492,0.05779
3.24000,27.00837,2.50433,27.00837,0.05963
3.28000,27.34159,2.45795,27.34158,0.05852
3.32000,27.67509,2.01575,27.67509,0.04799
3.36000,28.00820,2.11447,28.00820,0.05034
3.40000,28.34171,2.50060,28.34171,0.05954
3.44000,28.67490,2.30260,28.67490,0.05482
3.48000,29.00835,1.83377,29.00835,0.04366
3.52000,29.34173,2.19531,29.34173,0.05227
3.56000,29.67494,2.07759,29.67494,0.04947
3.60000,30.00840,2.21655,30.00840,0.05277
3.64000,30.34153,2.03401,30.34153,0.04843
3.68000,30.67512,1.76597,30.67512,0.04205
3.72000,31.00825,1.93510,31.00826,0.04607
3.76000,31.34171,1.83824,31.34171,0.04377
3.80000,31.67495,2.13142,31.67495,0.05075
3.84000,32.00830,2.46391,32.00830,0.05866
3.88000,32.34167,2.14223,32.34167,0.05101
3.92000,32.67491,2.26256,32.67491,0.05387
3.96000,33.00837,2.31583,33.00837,0.05514
4.00000,33.34153,2.38977,33.34153,0.05690
4.04000,33.67509,2.34824,33.67509,0.05591
4.08000,34.00828,2.17669,34.00828,0.05183
4.12000,34.34176,2.19140,34.34176,0.05218
4.16000,34.67498,2.23219,34.67498,0.05315
4.20000,35.00830,2.14614,35.00830,0.05110
4.24000,35.34170,2.06884,35.34170,0.04926
4.28000,35.67496,2.20966,35.67496,0.05261
4.32000,36.00839,2.49818,36.00839,0.05948
4.36000,36.34158,1.99322,36.34159,0.04746
4.40000,36.67501,2.86363,36.67501,0.06818
4.44000,37.00822,2.66097,37.00822,0.06336
4.48000,37.34176,2.46018,37.34176,0.05858
4.52000,37.67492,2.15713,37.67492,0.05136
4.56000,38.00835,2.66172,38.00835,0.06337
4.60000,38.34164,2.34507,38.34164,0.05584
4.64000,38.67496,2.17073,38.67496,0.05168
4.68000,39.00845,2.33334,39.00844,0.05556
4.72000,39.34158,2.50693,39.34158,0.05969
4.76000,39.67509,2.56523,39.67509,0.06108
4.80000,40.00822,2.41958,40.00823,0.05761
4.84000,40.34176,2.55909,40.34175,0.06093
4.88000,40.67497,2.41008,40.67497,0.05738
4.92000,41.00829,2.16700,41.00829,0.05160
4.96000,41.34167,2.76286,41.34167,0.06578
5.00000,41.67491,2.87220,41.67491,0.06839
5.04000,42.00839,2.96161,42.00839,0.07051
5.08000,42.34150,2.51085,42.34150,0.05978
5.12000,42.67500,2.70363,42.67500,0.06437
5.16000,43.00825,2.99197,43.00824,0.07124
5.20000,43.34178,2.73120,43.34179,0.06503
5.24000,43.67500,2.88188,43.67500,0.06862
5.28000,44.00835,3.12645,44.00835,0.07444
5.32000,44.34169,2.88934,44.34169,0.06879
5.36000,44.67493,2.93013,44.67493,0.06976
5.40000,45.00839,2.88375,45.00839,0.06866
5.44000,45.34161,3.09013,45.34161,0.07357
5.48000,45.67511,3.27080,45.67511,0.07788
5.52000,46.00825,3.27285,46.00825,0.07793
5.56000,46.34170,2.94615,46.34170,0.07015
5.60000,46.67494,3.22759,46.67495,0.07685
5.64000,47.00835,3.47700,47.00835,0.08279
5.68000,47.34164,3.42485,47.34164,0.08154
5.72000,47.67491,3.39095,47.67491,0.08074
5.76000,48.00842,3.15178,48.00842,0.07504
5.80000,48.34163,3.22945,48.34163,0.07689
5.84000,48.67514,3.34885,48.67514,0.07973
5.88000,49.00819,2.97893,49.00819,0.07093
5.92000,49.34170,3.45428,49.34170,0.08224
5.96000,49.67494,3.77223,49.67494,0.08981
6.00000,50.00840,3.17600,50.00840,0.07562
6.04000,50.34169,3.21977,50.34169,0.07666
6.08000,50.67491,3.39430,50.67491,0.08082
6.12000,51.00836,3.13371,51.00836,0.07461
6.16000,51.34155,2.99923,51.34155,0.07141
6.20000,51.67514,3.38312,51.67514,0.08055
6.24000,52.00824,3.77800,52.00824,0.08995
6.28000,52.34172,3.55411,52.34172,0.08462
6.32000,52.67491,3.65246,52.67492,0.08696
6.36000,53.00834,3.30787,53.00834,0.07876
6.40000,53.34175,3.42913,53.34175,0.08165
6.44000,53.67491,3.15253,53.67491,0.07506
6.48000,54.00841,3.21269,54.00841,0.07649
6.52000,54.34157,3.36450,54.34157,0.08011
6.56000,54.67511,3.03034,54.67511,0.07215
6.60000,55.00829,3.15439,55.00829,0.07510
6.64000,55.34169,3.29986,55.34169,0.07857
6.68000,55.67494,3.87412,55.67494,0.09224
6.72000,56.00834,3.48855,56.00834,0.08306
6.76000,56.34169,3.06331,56.34169,0.07294
6.80000,56.67495,3.13111,56.67495,0.07455
6.84000,57.00841,3.83724,57.00841,0.09136
6.88000,57.34154,3.84096,57.34154,0.09145
6.92000,57.67503,3.80371,57.67503,0.09056
6.96000,58.00824,3.90653,58.00824,0.09301
7.00000,58.34175,3.73684,58.34175,0.08897
7.04000,58.67497,3.86126,58.67496,0.09193
7.08000,59.00831,3.83016,59.00831,0.09119
7.12000,59.34166,3.94378,59.34166,0.09390
7.16000,59.67495,3.94285,59.67495,0.09388
7.20000,60.00841,3.65786,60.00841,0.08709
7.24000,60.34159,3.75789,60.34159,0.08947
7.28000,60.67508,4.08050,60.67508,0.09715
7.32000,61.00824,3.75342,61.00824,0.08937
7.36000,61.34178,3.79570,61.34178,0.09037
7.40000,61.67496,3.78191,61.67496,0.09005
7.44000,62.00831,4.06355,62.00831,0.09675
7.48000,62.34163,4.19747,62.34163,0.09994
7.52000,62.67493,4.13302,62.67493,0.09841
7.56000,63.00844,4.11421,63.00844,0.09796
7.60000,63.34157,4.12427,63.34157,0.09820
7.64000,63.67505,4.49941,63.67505,0.10713
7.68000,64.00819,4.26918,64.00819,0.10165
7.72000,64.34172,3.89386,64.34172,0.09271
7.76000,64.67499,4.20623,64.67499,0.10015
7.80000,65.00836,4.00916,65.00836,0.09546
7.84000,65.34166,3.92925,65.34166,0.09355
7.88000,65.67495,4.05665,65.67495,0.09659
7.92000,66.00844,3.94639,66.00844,0.09396
7.96000,66.34153,3.88622,66.34154,0.09253
8.00000,66.67508,4.37498,66.67508,0.10417
8.04000,67.00824,3.96110,67.00824,0.09431
8.08000,67.34169,4.11272,67.34169,0.09792
8.12000,67.67496,3.98699,67.67496,0.09493
8.16000,68.00831,4.18387,68.00831,0.09962
8.20000,68.34168,4.39808,68.34168,0.10472
8.24000,68.67493,4.27589,68.67493,0.10181
8.28000,69.00837,3.72045,69.00838,0.08858
8.32000,69.34162,4.38485,69.34162,0.10440
8.36000,69.67510,4.04213,69.67509,0.09624
8.40000,70.00824,4.44874,70.00824,0.10592
8.44000,70.34172,4.13414,70.34173,0.09843
8.48000,70.67490,4.22355,70.67490,0.10056
8.52000,71.00838,4.06504,71.00838,0.09679
8.56000,71.34168,4.17866,71.34167,0.09949
8.60000,71.67493,4.21032,71.67493,0.10025
8.64000,72.00837,4.54132,72.00837,0.10813
8.68000,72.34153,4.41466,72.34153,0.10511
8.72000,72.67507,4.59012,72.67507,0.10929
8.76000,73.00824,4.58546,73.00824,0.10918
8.80000,73.34172,4.35188,73.34172,0.10362
8.84000,73.67493,4.38839,73.67493,0.10449
8.88000,74.00836,4.39938,74.00836,0.10475
8.92000,74.34171,4.30364,74.34171,0.10247
8.96000,74.67498,4.49754,74.67499,0.10708
9.00000,75.00841,4.45973,75.00842,0.10618
9.04000,75.34157,4.32376,75.34158,0.10295
9.08000,75.67512,4.76018,75.67513,0.11334
9.12000,76.00823,4.46979,76.00823,0.10642
9.16000,76.34168,4.21405,76.34168,0.10033
9.20000,76.67490,4.39696,76.67490,0.10469
9.24000,77.00831,4.37945,77.00831,0.10427
9.28000,77.34171,4.39286,77.34171,0.10459
9.32000,77.67492,4.35002,77.67492,0.10357
9.36000,78.00840,4.41242,78.00841,0.10506
9.40000,78.34157,4.10434,78.34157,0.09772
9.44000,78.67510,4.21554,78.67509,0.10037
9.48000,79.00823,4.30085,79.00823,0.10240
9.52000,79.34171,4.28706,79.34171,0.10207
9.56000,79.67496,3.96743,79.67496,0.09446
9.60000,80.00836,3.77800,80.00835,0.08995
9.64000,80.34171,4.08832,80.34171,0.09734
9.68000,80.67494,3.89069,80.67494,0.09264
9.72000,81.00840,4.20436,81.00840,0.10010
9.76000,81.34153,4.09819,81.34153,0.09758
9.80000,81.67507,4.10955,81.67506,0.09785
9.84000,82.00826,4.14010,82.00826,0.09857
9.88000,82.34174,4.38932,82.34175,0.10451
9.92000,82.67496,4.18555,82.67496,0.09966
9.96000,83.00833,4.35505,83.00833,0.10369
10.00000,83.34165,4.13600,83.34164,0.09848
10.04000,83.67497,4.25596,83.67497,0.10133
10.08000,84.00840,4.18592,84.00840,0.09966
10.12000,84.34156,4.52902,84.34156,0.10783
10.16000,84.67509,4.45917,84.67508,0.10617
10.20000,85.00820,4.13321,85.00819,0.09841
10.24000,85.34176,4.40031,85.34176,0.10477
10.28000,85.67497,4.62681,85.67497,0.11016
10.32000,86.00835,4.37964,86.00835,0.10428
10.36000,86.34167,4.39771,86.34167,0.10471
10.40000,86.67488,4.31836,86.67488,0.10282
10.44000,87.00845,4.72404,87.00845,0.11248
10.48000,87.34156,4.88795,87.34156,0.11638
10.52000,87.67502,4.52343,87.67503,0.10770
10.56000,88.00825,4.67002,88.00825,0.11119
10.60000,88.34174,4.77731,88.34174,0.11375
10.64000,88.67497,4.88888,88.67497,0.11640
10.68000,89.00835,4.78700,89.00834,0.11398
10.72000,89.34165,4.67524,89.34164,0.11132
10.76000,89.67492,4.71901,89.67492,0.11236
10.80000,90.00842,4.61861,90.00842,0.10997
10.84000,90.34161,5.08912,90.34161,0.12117
10.88000,90.67512,5.33704,90.67512,0.12707
10.92000,91.00825,4.76763,91.00825,0.11351
10.96000,91.34168,4.51710,91.34167,0.10755
11.00000,91.67497,4.92651,91.67497,0.11730
11.04000,92.00835,5.35715,92.00835,0.12755
11.08000,92.34170,5.34281,92.34170,0.12721
11.12000,92.67494,5.45606,92.67493,0.12991
11.16000,93.00834,5.54677,93.00835,0.13207
11.20000,93.34158,5.72912,93.34158,0.13641
11.24000,93.67509,5.93457,93.67509,0.14130
11.28000,94.00825,5.88559,94.00825,0.14013
11.32000,94.34173,6.12456,94.34174,0.14582
11.36000,94.67492,6.06868,94.67492,0.14449
11.40000,95.00840,5.70156,95.00840,0.13575
11.44000,95.34172,6.00815,95.34172,0.14305
11.48000,95.67494,5.95972,95.67493,0.14190
11.52000,96.00836,5.99530,96.00836,0.14275
11.56000,96.34152,5.99399,96.34152,0.14271
11.60000,96.67512,5.99511,96.67512,0.14274
11.64000,97.00828,6.25104,97.00828,0.14883
11.68000,97.34173,6.26259,97.34173,0.14911
11.72000,97.67489,6.03497,97.67489,0.14369
11.76000,98.00830,6.34789,98.00829,0.15114
11.80000,98.34167,6.43134,98.34167,0.15313
11.84000,98.67494,6.42482,98.67494,0.15297
11.88000,99.00841,6.25290,99.00842,0.14888
11.92000,99.34158,6.42873,99.34158,0.15307
11.96000,99.67514,6.33467,99.67514,0.15083
12.00000,100.00825,6.26948,100.00825,0.14927
12.04000,100.34173,6.23483,100.34174,0.14845
12.08000,100.67497,6.41383,100.67496,0.15271
12.12000,101.00832,6.37695,101.00832,0.15183
12.16000,101.34169,6.36578,101.34169,0.15157
12.20000,101.67493,6.14189,101.67493,0.14624
12.24000,102.00836,6.41048,102.00836,0.15263
12.28000,102.34156,6.72825,102.34155,0.16020
12.32000,102.67503,6.49747,102.67504,0.15470
12.36000,103.00827,6.42911,103.00827,0.15307
12.40000,103.34175,6.72396,103.34175,0.16009
12.44000,103.67495,6.33374,103.67494,0.15080
12.48000,104.00835,6.31530,104.00835,0.15036
12.52000,104.34167,6.26855,104.34167,0.14925
12.56000,104.67496,6.46878,104.67496,0.15402
12.60000,105.00847,6.49560,105.00848,0.15466
12.64000,105.34157,6.15772,105.34158,0.14661
12.68000,105.67509,6.23595,105.67508,0.14847
12.72000,106.00822,6.36578,106.00822,0.15157
12.76000,106.34173,6.41942,106.34173,0.15284
12.80000,106.67494,6.41532,106.67494,0.15275
12.84000,107.00834,6.53230,107.00834,0.15553
12.88000,107.34164,6.40713,107.34164,0.15255
12.92000,107.67493,6.81262,107.67493,0.16221
12.96000,108.00841,6.55688,108.00842,0.15612
13.00000,108.34157,6.67237,108.34158,0.15887
13.04000,108.67508,7.00057,108.67507,0.16668
13.08000,109.00819,7.02292,109.00819,0.16721
13.12000,109.34180,6.83609,109.34180,0.16276
13.16000,109.67502,6.33243,109.67502,0.15077
13.20000,110.00832,6.40601,110.00832,0.15252
13.24000,110.34169,6.55223,110.34169,0.15601
13.28000,110.67491,6.79530,110.67491,0.16179
13.32000,111.00844,6.50845,111.00844,0.15496
13.36000,111.34160,6.53677,111.34160,0.15564
13.40000,111.67506,6.54440,111.67506,0.15582
13.44000,112.00825,6.86981,112.00825,0.16357
13.48000,112.34171,6.54142,112.34171,0.15575
13.52000,112.67494,6.83274,112.67494,0.16268
13.56000,113.00829,6.27078,113.00829,0.14930
13.60000,113.34168,6.31008,113.34168,0.15024
13.64000,113.67496,6.63735,113.67496,0.15803
13.68000,114.00845,6.76550,114.00845,0.16108
13.72000,114.34163,6.81859,114.34163,0.16235
13.76000,114.67510,6.96220,114.67510,0.16577
13.80000,115.00824,6.63642,115.00824,0.15801
13.84000,115.34172,6.85081,115.34173,0.16311
13.88000,115.67496,6.63120,115.67496,0.15789
13.92000,116.00837,6.83330,116.00837,0.16270
13.96000,116.34169,6.59209,116.34169,0.15695
14.00000,116.67493,6.77742,116.67493,0.16137
14.04000,117.00836,7.15610,117.00836,0.17038
14.08000,117.34155,6.71055,117.34155,0.15978
14.12000,117.67511,6.54403,117.67511,0.15581
14.16000,118.00824,6.85453,118.00825,0.16320
14.20000,118.34174,6.71875,118.34174,0.15997
14.24000,118.67490,6.82473,118.67490,0.16249
14.28000,119.00834,6.90371,119.00834,0.16437
14.32000,119.34173,6.55986,119.34174,0.15619
14.36000,119.67496,6.49672,119.67496,0.15468
14.40000,120.00841,6.55632,120.00841,0.15610
14.44000,120.34157,6.70739,120.34157,0.15970
14.48000,120.67510,6.92979,120.67510,0.16499
14.52000,121.00829,6.95270,121.00829,0.16554
14.56000,121.34170,6.63586,121.34170,0.15800
14.60000,121.67488,6.96480,121.67488,0.16583
14.64000,122.00833,6.73234,122.00833,0.16029
14.68000,122.34171,6.85826,122.34171,0.16329
14.72000,122.67495,6.87428,122.67495,0.16367
14.76000,123.00841,7.18180,123.00841,0.17100
14.80000,123.34152,6.94636,123.34152,0.16539
14.84000,123.67507,6.86478,123.67507,0.16345
14.88000,124.00828,6.72396,124.00829,0.16009
14.92000,124.34174,6.84951,124.34174,0.16308
14.96000,124.67499,7.07265,124.67500,0.16840
15.00000,125.00831,6.71037,125.00831,0.15977
15.04000,125.34169,7.15852,125.34169,0.17044
15.08000,125.67498,6.97281,125.67498,0.16602
15.12000,126.00842,6.80108,126.00842,0.16193
15.16000,126.34159,6.44475,126.34159,0.15345
15.20000,126.67508,6.65132,126.67508,0.15836
15.24000,127.00821,6.99274,127.00821,0.16649
15.28000,127.34174,6.98436,127.34174,0.16629
15.32000,127.67492,7.11773,127.67492,0.16947
15.36000,128.00833,6.88229,128.00833,0.16386
15.40000,128.34169,6.82473,128.34169,0.16249
15.44000,128.67495,7.11810,128.67496,0.16948
15.48000,129.00846,6.71577,129.00847,0.15990
15.52000,129.34160,7.13971,129.34160,0.16999
15.56000,129.67508,6.83628,129.67508,0.16277
15.60000,130.00818,6.70590,130.00818,0.15966
15.64000,130.34181,7.04210,130.34181,0.16767
15.68000,130.67501,6.74669,130.67500,0.16064
15.72000,131.00836,6.88881,131.00836,0.16402
15.76000,131.34165,6.96015,131.34166,0.16572
15.80000,131.67492,7.12499,131.67491,0.16964
15.84000,132.00843,7.15815,132.00842,0.17043
15.88000,132.34156,6.80666,132.34157,0.16206
15.92000,132.67508,6.54999,132.67508,0.15595
15.96000,133.00820,6.97076,133.00819,0.16597
16.00000,133.34172,6.85416,133.34172,0.16319
16.04000,133.67501,6.82063,133.67502,0.16240
16.08000,134.00833,6.88378,134.00833,0.16390
16.12000,134.34167,7.07339,134.34167,0.16841
16.16000,134.67491,6.98436,134.67491,0.16629
16.20000,135.00840,6.94599,135.00839,0.16538
16.24000,135.34162,7.19503,135.34163,0.17131
16.28000,135.67510,7.01603,135.67509,0.16705
16.32000,136.00824,7.11195,136.00824,0.16933
16.36000,136.34172,6.93854,136.34172,0.16520
16.40000,136.67497,7.20453,136.67497,0.17154
16.44000,137.00836,7.12834,137.00836,0.16972
16.48000,137.34168,7.53365,137.34167,0.17937
16.52000,137.67492,7.39451,137.67491,0.17606
16.56000,138.00840,7.02050,138.00841,0.16715
16.60000,138.34156,7.32187,138.34157,0.17433
16.64000,138.67508,7.37607,138.67508,0.17562
16.68000,139.00829,7.24159,139.00829,0.17242
16.72000,139.34173,7.27475,139.34174,0.17321
16.76000,139.67499,7.44630,139.67499,0.17729
16.80000,140.00838,7.40327,140.00838,0.17627
16.84000,140.34167,7.45114,140.34166,0.17741
16.88000,140.67494,7.44350,140.67494,0.17723
16.92000,141.00837,7.14473,141.00838,0.17011
16.96000,141.34153,7.46548,141.34152,0.17775
17.00000,141.67515,7.45654,141.67514,0.17754
17.04000,142.00825,7.36583,142.00826,0.17538
17.08000,142.34171,7.58823,142.34172,0.18067
17.12000,142.67490,7.51186,142.67490,0.17885
17.16000,143.00830,7.44816,143.00830,0.17734
17.20000,143.34176,7.63070,143.34174,0.18168
17.24000,143.67494,7.67540,143.67493,0.18275
17.28000,144.00838,7.77151,144.00838,0.18504
17.32000,144.34157,7.82032,144.34157,0.18620
17.36000,144.67513,7.69701,144.67513,0.18326
17.40000,145.00830,7.72756,145.00829,0.18399
17.44000,145.34176,7.75103,145.34177,0.18455
17.48000,145.67495,7.51279,145.67494,0.17888
17.52000,146.00831,7.50925,146.00832,0.17879
17.56000,146.34171,7.69775,146.34172,0.18328
17.60000,146.67493,7.64113,146.67494,0.18193
17.64000,147.00837,7.72774,147.00836,0.18399
17.68000,147.34153,7.80076,147.34152,0.18573
17.72000,147.67504,7.73892,147.67503,0.18426
17.76000,148.00828,7.75307,148.00829,0.18460
17.80000,148.34174,7.91047,148.34175,0.18834
17.84000,148.67495,7.52658,148.67496,0.17920
17.88000,149.00832,7.42134,149.00832,0.17670
17.92000,149.34169,7.96057,149.34169,0.18954
17.96000,149.67502,8.09748,149.67502,0.19280
18.00000,150.00841,7.84863,150.00841,0.18687
18.04000,150.34157,7.64355,150.34157,0.18199
18.08000,150.67510,7.59345,150.67509,0.18080
18.12000,151.00819,7.63312,151.00819,0.18174
18.16000,151.34176,7.35819,151.34175,0.17520
18.20000,151.67494,8.05184,151.67494,0.19171
18.24000,152.00831,8.01068,152.00832,0.19073
18.28000,152.34164,7.97454,152.34164,0.18987
18.32000,152.67489,7.98013,152.67490,0.19000
18.36000,153.00842,7.95871,153.00842,0.18949
18.40000,153.34163,7.43587,153.34163,0.17704
18.44000,153.67509,7.90469,153.67509,0.18821
18.48000,154.00821,7.54762,154.00821,0.17971
18.52000,154.34178,7.83335,154.34178,0.18651
18.56000,154.67500,7.95703,154.67500,0.18945
18.60000,155.00838,7.99317,155.00839,0.19031
18.64000,155.34165,7.87750,155.34166,0.18756
18.68000,155.67489,8.15671,155.67488,0.19421
18.72000,156.00848,7.77934,156.00848,0.18522
18.76000,156.34157,8.20402,156.34157,0.19533
18.80000,156.67510,7.97510,156.67509,0.18988
18.84000,157.00819,7.73612,157.00819,0.18419
18.88000,157.34163,8.07382,157.34164,0.19223
18.92000,157.67494,8.13827,157.67493,0.19377
18.96000,158.00834,7.56066,158.00833,0.18002
19.00000,158.34173,7.94567,158.34175,0.18918
19.04000,158.67496,7.89054,158.67496,0.18787
19.08000,159.00839,8.15075,159.00839,0.19407
19.12000,159.34163,8.38973,159.34163,0.19976
19.16000,159.67512,7.96411,159.67513,0.18962
19.20000,160.00821,8.08798,160.00821,0.19257
19.24000,160.34176,8.54935,160.34178,0.20356
19.28000,160.67494,8.64770,160.67494,0.20590
19.32000,161.00834,8.48453,161.00835,0.20201
19.36000,161.34169,8.34260,161.34169,0.19863
19.40000,161.67491,8.19825,161.67491,0.19520
19.44000,162.00840,8.52961,162.00839,0.20309
19.48000,162.34156,8.40612,162.34157,0.20015
19.52000,162.67508,8.50428,162.67508,0.20248
19.56000,163.00828,8.57040,163.00829,0.20406
19.60000,163.34172,8.52291,163.34172,0.20293
19.64000,163.67492,8.47802,163.67493,0.20186
19.68000,164.00834,8.78610,164.00833,0.20919
19.72000,164.34175,8.47057,164.34175,0.20168
19.76000,164.67496,8.46498,164.67496,0.20155
19.80000,165.00844,8.58568,165.00844,0.20442
19.84000,165.34155,8.79392,165.34155,0.20938
19.88000,165.67512,8.70824,165.67511,0.20734
19.92000,166.00821,9.18191,166.00821,0.21862
19.96000,166.34170,8.71588,166.34169,0.20752
20.00000,166.67494,8.90866,166.67494,0.21211
20.04000,167.00832,8.67881,167.00832,0.20664
20.08000,167.34171,8.65348,167.34171,0.20604
20.12000,167.67494,8.98354,167.67494,0.21389
20.16000,168.00836,9.16682,168.00835,0.21826
20.20000,168.34157,8.88351,168.34157,0.21151
20.24000,168.67512,8.92505,168.67513,0.21250
20.28000,169.00828,8.78125,169.00830,0.20908
20.32000,169.34178,9.05003,169.34178,0.21548
20.36000,169.67494,8.97907,169.67494,0.21379
20.40000,170.00831,8.66968,170.00832,0.20642
20.44000,170.34172,8.92002,170.34172,0.21238
20.48000,170.67498,8.96435,170.67499,0.21344
20.52000,171.00844,8.83043,171.00842,0.21025
20.56000,171.34158,8.75164,171.34158,0.20837
20.60000,171.67505,8.85483,171.67506,0.21083
20.64000,172.00826,8.81869,172.00827,0.20997
20.68000,172.34170,9.04649,172.34169,0.21539
20.72000,172.67494,9.02824,172.67494,0.21496
20.76000,173.00836,9.11374,173.00835,0.21699
20.80000,173.34169,9.29274,173.34169,0.22126
20.84000,173.67500,9.14056,173.67500,0.21763
20.88000,174.00841,9.17446,174.00841,0.21844
20.92000,174.34153,9.15695,174.34152,0.21802
20.96000,174.67510,8.97981,174.67509,0.21381
21.00000,175.00824,9.18638,175.00824,0.21872
21.04000,175.34178,9.21730,175.34178,0.21946
21.08000,175.67501,9.04948,175.67499,0.21546
21.12000,176.00834,9.37078,176.00833,0.22311
21.16000,176.34163,9.16962,176.34161,0.21832
21.20000,176.67488,9.02060,176.67487,0.21478
21.24000,177.00844,9.48124,177.00844,0.22574
21.28000,177.34160,9.52650,177.34160,0.22682
21.32000,177.67505,9.18470,177.67505,0.21868
21.36000,178.00820,9.12696,178.00819,0.21731
21.40000,178.34172,9.46708,178.34171,0.22541
21.44000,178.67499,9.42703,178.67499,0.22445
21.48000,179.00838,9.28268,179.00838,0.22102
21.52000,179.34171,9.28603,179.34171,0.22110
21.56000,179.67495,9.24878,179.67496,0.22021
21.60000,180.00846,9.69823,180.00847,0.23091
21.64000,180.34162,9.15304,180.34163,0.21793
21.68000,180.67509,9.58517,180.67509,0.22822
21.72000,181.00822,9.72506,181.00821,0.23155
21.76000,181.34169,9.71686,181.34169,0.23135
21.80000,181.67497,9.82825,181.67497,0.23401
21.84000,182.00836,9.55667,182.00835,0.22754
21.88000,182.34165,9.44175,182.34166,0.22480
21.92000,182.67489,9.92976,182.67490,0.23642
21.96000,183.00835,10.06294,183.00835,0.23959
22.00000,183.34160,9.77162,183.34160,0.23266
22.04000,183.67513,9.86587,183.67513,0.23490
22.08000,184.00826,9.60696,184.00826,0.22874
22.12000,184.34180,9.85786,184.34180,0.23471
22.16000,184.67499,9.60268,184.67499,0.22864
22.20000,185.00835,9.74368,185.00836,0.23199
22.24000,185.34171,9.80888,185.34171,0.23354
22.28000,185.67495,9.89959,185.67494,0.23570
22.32000,186.00840,9.67588,186.00839,0.23038
22.36000,186.34153,9.99663,186.34152,0.23802
22.40000,186.67508,10.02792,186.67508,0.23876
22.44000,187.00824,10.22257,187.00824,0.24339
22.48000,187.34171,9.98657,187.34172,0.23778
22.52000,187.67490,10.08846,187.67490,0.24020
22.56000,188.00833,9.80943,188.00835,0.23356
22.60000,188.34173,9.88171,188.34174,0.23528
22.64000,188.67498,9.84389,188.67499,0.23438
22.68000,189.00845,9.85526,189.00845,0.23465
22.72000,189.34154,10.04040,189.34154,0.23906
22.76000,189.67513,10.00073,189.67511,0.23811
22.80000,190.00833,9.74722,190.00833,0.23208
22.84000,190.34175,9.73288,190.34174,0.23174
22.88000,190.67498,9.96944,190.67500,0.23737
22.92000,191.00828,10.09628,191.00827,0.24039
22.96000,191.34164,10.13298,191.34164,0.24126
23.00000,191.67495,9.81595,191.67494,0.23371
23.04000,192.00837,10.20823,192.00836,0.24305
23.08000,192.34153,10.00427,192.34152,0.23820
23.12000,192.67505,10.09982,192.67505,0.24047
23.16000,193.00828,9.99849,193.00827,0.23806
23.20000,193.34180,10.34196,193.34181,0.24624
23.24000,193.67496,10.42727,193.67496,0.24827
23.28000,194.00836,10.21978,194.00836,0.24333
23.32000,194.34173,10.43193,194.34174,0.24838
23.36000,194.67499,10.22834,194.67500,0.24353
23.40000,195.00843,10.47999,195.00844,0.24952
23.44000,195.34156,10.42318,195.34155,0.24817
23.48000,195.67507,10.43864,195.67508,0.24854
23.52000,196.00823,10.55282,196.00824,0.25126
23.56000,196.34175,10.17973,196.34175,0.24237
23.60000,196.67496,10.40716,196.67496,0.24779
23.64000,197.00834,10.75361,197.00835,0.25604
23.68000,197.34164,10.66308,197.34164,0.25388
23.72000,197.67489,10.28832,197.67491,0.24496
23.76000,198.00843,10.72772,198.00844,0.25542
23.80000,198.34162,10.45484,198.34161,0.24892
23.84000,198.67512,10.60050,198.67513,0.25239
23.88000,199.00825,10.67109,199.00827,0.25407
23.92000,199.34176,10.64222,199.34177,0.25339
23.96000,199.67500,10.51556,199.67500,0.25037
24.00000,200.00833,10.90840,200.00833,0.25972
24.04000,200.34168,11.00954,200.34166,0.26213
24.08000,200.67494,10.89275,200.67494,0.25935
24.12000,201.00840,10.61484,201.00839,0.25273
24.16000,201.34160,10.70928,201.34158,0.25498
24.20000,201.67507,10.76180,201.67508,0.25623
24.24000,202.00819,10.96390,202.00819,0.26105
24.28000,202.34172,11.09261,202.34172,0.26411
24.32000,202.67498,11.10919,202.67499,0.26450
24.36000,203.00835,10.91287,203.00835,0.25983
24.40000,203.34171,11.20232,203.34171,0.26672
24.44000,203.67492,11.16656,203.67493,0.26587
24.48000,204.00839,11.12465,204.00839,0.26487
24.52000,204.34164,11.30700,204.34164,0.26921
24.56000,204.67512,10.86555,204.67513,0.25870
24.60000,205.00825,10.84860,205.00826,0.25830
24.64000,205.34171,11.13210,205.34171,0.26505
24.68000,205.67495,11.00041,205.67496,0.26191
24.72000,206.00838,10.80986,206.00838,0.25738
24.76000,206.34162,11.00060,206.34163,0.26192
24.80000,206.67498,10.93633,206.67497,0.26039
24.84000,207.00840,11.35431,207.00839,0.27034
24.88000,207.34156,11.61639,207.34155,0.27658
24.92000,207.67512,11.28558,207.67514,0.26870
24.96000,208.00822,11.34165,208.00822,0.27004
25.00000,208.34172,11.27236,208.34172,0.26839
25.04000,208.67494,11.39101,208.67493,0.27121
25.08000,209.00835,11.27943,209.00835,0.26856
25.12000,209.34176,11.36307,209.34177,0.27055
25.16000,209.67496,11.13415,209.67496,0.26510
25.20000,210.00842,11.01959,210.00841,0.26237
25.24000,210.34153,11.18481,210.34152,0.26631
25.28000,210.67512,11.55250,210.67511,0.27506
25.32000,211.00825,11.40069,211.00826,0.27145
25.36000,211.34174,11.28372,211.34174,0.26866
25.40000,211.67492,11.45452,211.67493,0.27273
25.44000,212.00829,11.58789,212.00829,0.27590
25.48000,212.34173,11.61732,212.34172,0.27660
25.52000,212.67494,11.71269,212.67494,0.27887
25.56000,213.00841,11.47408,213.00841,0.27319
25.60000,213.34156,11.68475,213.34157,0.27821
25.64000,213.67510,11.87716,213.67509,0.28279
25.68000,214.00830,11.84512,214.00832,0.28203
25.72000,214.34178,11.77639,214.34178,0.28039
25.76000,214.67494,11.39808,214.67494,0.27138
25.80000,215.00832,11.80563,215.00833,0.28109
25.84000,215.34169,11.78235,215.34169,0.28053
25.88000,215.67496,12.06901,215.67496,0.28736
25.92000,216.00842,11.72889,216.00842,0.27926
25.96000,216.34155,11.68530,216.34155,0.27822
26.00000,216.67506,11.89336,216.67506,0.28318
26.04000,217.00822,11.60111,217.00822,0.27622
26.08000,217.34174,11.99450,217.34174,0.28558
26.12000,217.67496,12.12992,217.67496,0.28881
26.16000,218.00834,12.11520,218.00835,0.28846
26.20000,218.34169,12.24615,218.34169,0.29157
26.24000,218.67498,12.12358,218.67497,0.28866
26.28000,219.00842,11.90491,219.00842,0.28345
26.32000,219.34158,12.12936,219.34158,0.28879
26.36000,219.67511,12.21113,219.67511,0.29074
26.40000,220.00822,11.73634,220.00821,0.27944
26.44000,220.34172,11.97085,220.34172,0.28502
26.48000,220.67490,11.98109,220.67490,0.28526
26.52000,221.00835,12.24056,221.00835,0.29144
26.56000,221.34169,11.96358,221.34169,0.28485
26.60000,221.67490,12.33052,221.67491,0.29358
26.64000,222.00843,12.22380,222.00842,0.29104
26.68000,222.34154,12.28638,222.34154,0.29253
26.72000,222.67506,12.04815,222.67506,0.28686
26.76000,223.00822,12.29178,223.00822,0.29266
26.80000,223.34167,12.37839,223.34167,0.29472
26.84000,223.67501,12.29458,223.67502,0.29273
26.88000,224.00838,12.21374,224.00838,0.29080
26.92000,224.34170,12.12731,224.34171,0.28875
26.96000,224.67494,12.15395,224.67494,0.28938
27.00000,225.00836,12.45905,225.00836,0.29664
27.04000,225.34154,12.37262,225.34154,0.29459
27.08000,225.67509,12.44154,225.67509,0.29623
27.12000,226.00818,12.23683,226.00818,0.29135
27.16000,226.34170,12.22026,226.34171,0.29096
27.20000,226.67494,12.69951,226.67494,0.30237
27.24000,227.00834,12.54845,227.00833,0.29877
27.28000,227.34165,12.86007,227.34164,0.30619
27.32000,227.67489,12.63209,227.67490,0.30076
27.36000,228.00842,12.67996,228.00842,0.30190
27.40000,228.34165,12.70883,228.34166,0.30259
27.44000,228.67507,12.67139,228.67508,0.30170
27.48000,229.00824,12.44582,229.00824,0.29633
27.52000,229.34173,12.42906,229.34174,0.29593
27.56000,229.67495,12.84461,229.67494,0.30582
27.60000,230.00839,12.68163,230.00839,0.30194
27.64000,230.34168,12.46892,230.34169,0.29688
27.68000,230.67492,12.97612,230.67493,0.30896
27.72000,231.00837,12.63712,231.00838,0.30088
27.76000,231.34153,12.45420,231.34152,0.29653
27.80000,231.67508,12.76042,231.67508,0.30382
27.84000,232.00824,12.84815,232.00824,0.30591
27.88000,232.34171,12.62594,232.34172,0.30062
27.92000,232.67493,12.90739,232.67493,0.30732
27.96000,233.00835,12.83959,233.00835,0.30570
28.00000,233.34172,13.12792,233.34172,0.31257
28.04000,233.67493,12.92676,233.67493,0.30778
28.08000,234.00838,12.52703,234.00838,0.29826
28.12000,234.34156,13.16536,234.34157,0.31346
28.16000,234.67514,12.88000,234.67514,0.30667
28.20000,235.00827,12.74329,235.00827,0.30341
28.24000,235.34172,12.79786,235.34172,0.30471
28.28000,235.67491,12.80662,235.67491,0.30492
28.32000,236.00825,12.58254,236.00826,0.29958
28.36000,236.34167,12.45402,236.34167,0.29652
28.40000,236.67496,12.31749,236.67496,0.29327
28.44000,237.00841,12.65034,237.00841,0.30120
28.48000,237.34154,12.64624,237.34154,0.30110
28.52000,237.67501,12.60936,237.67502,0.30022
28.56000,238.00828,12.79488,238.00829,0.30464
28.60000,238.34175,12.37802,238.34175,0.29471
28.64000,238.67494,12.82338,238.67494,0.30532
28.68000,239.00833,12.71274,239.00833,0.30268
28.72000,239.34168,12.37672,239.34167,0.29468
28.76000,239.67502,12.16587,239.67502,0.28966
28.80000,240.00841,12.24261,240.00841,0.29149
28.84000,240.34147,12.40149,240.34148,0.29527
28.88000,240.67507,12.59297,240.67508,0.29983
28.92000,241.00821,12.13532,241.00821,0.28894
28.96000,241.34176,11.70095,241.34175,0.27859
29.00000,241.67500,12.16959,241.67500,0.28975
29.04000,242.00831,12.22026,242.00832,0.29096
29.08000,242.34163,12.14407,242.34163,0.28914
29.12000,242.67495,12.50710,242.67494,0.29779
29.16000,243.00839,12.41937,243.00839,0.29570
29.20000,243.34158,12.63209,243.34158,0.30076
29.24000,243.67511,12.37635,243.67511,0.29467
29.28000,244.00821,12.07702,244.00821,0.28755
29.32000,244.34174,12.24894,244.34174,0.29164
29.36000,244.67495,12.24019,244.67496,0.29143
29.40000,245.00837,12.19083,245.00838,0.29026
29.44000,245.34169,12.48028,245.34169,0.29715
29.48000,245.67487,12.40484,245.67488,0.29535
29.52000,246.00840,12.06174,246.00839,0.28718
29.56000,246.34156,11.89224,246.34155,0.28315
29.60000,246.67506,12.19921,246.67506,0.29046
29.64000,247.00822,12.82990,247.00822,0.30547
29.68000,247.34167,12.87758,247.34166,0.30661
29.72000,247.67498,12.37560,247.67499,0.29466
29.76000,248.00838,12.41807,248.00838,0.29567
29.80000,248.34167,12.55907,248.34167,0.29903
29.84000,248.67491,12.65258,248.67491,0.30125
29.88000,249.00838,12.69691,249.00838,0.30231
29.92000,249.34162,12.63171,249.34161,0.30076
29.96000,249.67512,12.23646,249.67511,0.29134
30.00000,250.00823,12.47097,250.00822,0.29693
30.04000,250.34170,12.82282,250.34171,0.30531
30.08000,250.67491,12.74236,250.67491,0.30339
30.12000,251.00833,13.08303,251.00833,0.31150
30.16000,251.34167,12.80680,251.34167,0.30492
30.20000,251.67494,12.74515,251.67494,0.30346
30.24000,252.00839,12.81872,252.00839,0.30521
30.28000,252.34155,12.69709,252.34155,0.30231
30.32000,252.67507,13.08192,252.67506,0.31147
30.36000,253.00823,12.85262,253.00822,0.30601
30.40000,253.34176,12.99325,253.34175,0.30936
30.44000,253.67497,13.05006,253.67497,0.31072
30.48000,254.00836,13.11339,254.00836,0.31222
30.52000,254.34171,13.10334,254.34171,0.31198
30.56000,254.67492,13.15121,254.67491,0.31312
30.60000,255.00842,13.11190,255.00842,0.31219
30.64000,255.34155,12.91353,255.34155,0.30747
30.68000,255.67508,12.85579,255.67508,0.30609
30.72000,256.00821,12.96252,256.00821,0.30863
30.76000,256.34171,12.93235,256.34171,0.30791
30.80000,256.67495,13.25943,256.67496,0.31570
30.84000,257.00829,13.44290,257.00830,0.32007
30.88000,257.34163,13.23000,257.34164,0.31500
30.92000,257.67498,13.41887,257.67499,0.31950
30.96000,258.00840,13.28327,258.00839,0.31627
31.00000,258.34156,13.60718,258.34155,0.32398
31.04000,258.67511,13.30394,258.67511,0.31676
31.08000,259.00827,13.57999,259.00827,0.32333
31.12000,259.34172,13.59936,259.34171,0.32379
31.16000,259.67498,13.22720,259.67499,0.31493
31.20000,260.00830,13.17747,260.00830,0.31375
31.24000,260.34169,13.62897,260.34171,0.32450
31.28000,260.67496,13.51181,260.67496,0.32171
31.32000,261.00840,13.42483,261.00839,0.31964
31.36000,261.34156,13.43638,261.34155,0.31991
31.40000,261.67506,13.67629,261.67505,0.32563
31.44000,262.00830,13.58949,262.00830,0.32356
31.48000,262.34175,13.47959,262.34174,0.32094
31.52000,262.67491,13.69324,262.67490,0.32603
31.56000,263.00830,13.52597,263.00830,0.32205
31.60000,263.34167,13.89179,263.34167,0.33076
31.64000,263.67496,13.98735,263.67496,0.33303
31.68000,264.00844,13.59545,264.00842,0.32370
31.72000,264.34154,13.93016,264.34155,0.33167
31.76000,264.67507,13.54590,264.67508,0.32252
31.80000,265.00823,13.95606,265.00824,0.33229
31.84000,265.34173,13.53789,265.34174,0.32233
31.88000,265.67494,13.60327,265.67493,0.32389
31.92000,266.00834,13.56192,266.00833,0.32290
31.96000,266.34170,13.72099,266.34171,0.32669
32.00000,266.67497,13.87298,266.67496,0.33031
32.04000,267.00844,13.87633,267.00845,0.33039
32.08000,267.34158,14.19038,267.34158,0.33787
32.12000,267.67505,14.09966,267.67505,0.33571
32.16000,268.00821,14.25110,268.00821,0.33931
32.20000,268.34176,14.46325,268.34177,0.34436
32.24000,268.67500,14.13450,268.67499,0.33654
32.28000,269.00832,14.24961,269.00833,0.33928
32.32000,269.34168,14.19019,269.34167,0.33786
32.36000,269.67490,13.68150,269.67490,0.32575
32.40000,270.00842,14.16635,270.00842,0.33729
32.44000,270.34161,13.89235,270.34161,0.33077
32.48000,270.67508,14.40682,270.67508,0.34302
32.52000,271.00824,14.28388,271.00824,0.34009
32.56000,271.34169,14.04360,271.34167,0.33437
32.60000,271.67495,14.44668,271.67496,0.34397
32.64000,272.00837,14.36956,272.00836,0.34213
32.68000,272.34172,14.46307,272.34171,0.34436
32.72000,272.67493,14.38763,272.67493,0.34256
32.76000,273.00838,14.62009,273.00836,0.34810
32.80000,273.34161,14.73259,273.34161,0.35078
32.84000,273.67517,14.55154,273.67517,0.34647
32.88000,274.00820,14.55490,274.00821,0.34655
32.92000,274.34164,14.72700,274.34164,0.35064
32.96000,274.67496,14.51392,274.67496,0.34557
33.00000,275.00835,14.28537,275.00836,0.34013
33.04000,275.34170,14.48076,275.34171,0.34478
33.08000,275.67491,14.71657,275.67490,0.35039
33.12000,276.00836,14.47778,276.00836,0.34471
33.16000,276.34157,14.09724,276.34158,0.33565
33.20000,276.67515,14.46847,276.67514,0.34449
33.24000,277.00825,14.77152,277.00824,0.35170
33.28000,277.34173,14.92873,277.34174,0.35545
33.32000,277.67491,14.68919,277.67493,0.34974
33.36000,278.00836,15.04384,278.00836,0.35819
33.40000,278.34173,15.07998,278.34174,0.35905
33.44000,278.67494,15.02316,278.67493,0.35769
33.48000,279.00844,15.10400,279.00845,0.35962
33.52000,279.34160,15.00994,279.34161,0.35738
33.56000,279.67507,14.81082,279.67508,0.35264
33.60000,280.00823,14.58041,280.00824,0.34715
33.64000,280.34171,15.03732,280.34171,0.35803
33.68000,280.67497,14.55341,280.67496,0.34651
33.72000,281.00831,14.82032,281.00830,0.35286
33.76000,281.34168,14.66442,281.34167,0.34915
33.80000,281.67497,14.67112,281.67499,0.34931
33.84000,282.00842,14.95350,282.00842,0.35604
33.88000,282.34155,15.00249,282.34155,0.35720
33.92000,282.67500,15.20384,282.67499,0.36200
33.96000,283.00824,14.94344,283.00824,0.35580
34.00000,283.34174,15.32696,283.34174,0.36493
34.04000,283.67498,15.04924,283.67499,0.35832
34.08000,284.00835,15.12691,284.00833,0.36016
34.12000,284.34166,15.38638,284.34167,0.36634
34.16000,284.67495,15.11332,284.67493,0.35984
34.20000,285.00840,14.76742,285.00839,0.35161
34.24000,285.34156,14.69571,285.34158,0.34990
34.28000,285.67509,14.96971,285.67508,0.35642
34.32000,286.00825,14.80356,286.00824,0.35247
34.36000,286.34180,3.92329,286.34180,0.09341
34.40000,286.67493,-0.83949,286.67493,-0.01999
34.44000,287.00833,0.23693,287.00833,0.00564
34.48000,287.34167,0.19092,287.34167,0.00455
34.52000,287.67491,0.44834,287.67490,0.01067
34.56000,288.00841,0.13914,288.00839,0.00331
34.60000,288.34154,0.20340,288.34155,0.00484
34.64000,288.67509,0.43903,288.67508,0.01045
34.68000,289.00825,-0.01714,289.00824,-0.00041
34.72000,289.34175,0.48410,289.34174,0.01153
34.76000,289.67499,-0.23171,289.67499,-0.00552
34.80000,290.00838,-0.53961,290.00839,-0.01285
34.83900,290.33333,0.29989,290.33334,0.00714