File: raw_data/mechanical_tests_Instron_data/Silicone_0035-Cross_5.is_tens_RawData/Specimen_RawData_1.csv
Dimension : Area,0.42000,cm^2

Time,Load,Extension,Tensile extension,Tensile strain,Tensile stress
(sec),(N),(mm),(mm),(mm/mm),(MPa)
0.00000,0.00019,0.00000,0.00000,0.00000,0.00000
0.04000,0.80187,0.06062,0.06062,0.00043,0.01909
0.08000,0.07618,0.26234,0.26234,0.00187,0.00181
0.12000,1.62553,0.59421,0.59421,0.00424,0.03870
0.16000,1.91368,0.97942,0.97942,0.00700,0.04556
0.20000,1.94237,1.37952,1.37952,0.00985,0.04625
0.24000,2.30558,1.78827,1.78827,0.01277,0.05489
0.28000,2.26554,2.20267,2.20267,0.01573,0.05394
0.32000,2.12733,2.62098,2.62098,0.01872,0.05065
0.36000,1.57543,3.00860,3.00860,0.02149,0.03751
0.40000,1.35489,3.34079,3.34079,0.02386,0.03226
0.44000,1.38301,3.67085,3.67085,0.02622,0.03293
0.48000,1.38804,4.00695,4.00695,0.02862,0.03305
0.52000,1.93622,4.34145,4.34145,0.03101,0.04610
0.56000,1.57580,4.67488,4.67488,0.03339,0.03752
0.60000,1.80546,5.00810,5.00810,0.03577,0.04299
0.64000,1.97589,5.34174,5.34174,0.03816,0.04705
0.68000,1.90269,5.67493,5.67493,0.04054,0.04530
0.72000,1.61100,6.00835,6.00835,0.04292,0.03836
0.76000,1.71438,6.34160,6.34160,0.04530,0.04082
0.80000,1.88686,6.67502,6.67502,0.04768,0.04493
0.84000,1.82856,7.00837,7.00837,0.05006,0.04354
0.88000,2.06213,7.34161,7.34161,0.05244,0.04910
0.92000,1.78013,7.67504,7.67504,0.05482,0.04238
0.96000,2.07443,8.00825,8.00826,0.05720,0.04939
1.00000,1.61044,8.34174,8.34174,0.05958,0.03834
1.04000,1.94572,8.67492,8.67492,0.06196,0.04633
1.08000,1.77789,9.00841,9.00841,0.06435,0.04233
1.12000,1.44634,9.34162,9.34162,0.06673,0.03444
1.16000,2.15322,9.67502,9.67502,0.06911,0.05127
1.20000,1.83471,10.00840,10.00840,0.07149,0.04368
1.24000,1.93808,10.34164,10.34164,0.07387,0.04614
1.28000,2.14800,10.67507,10.67507,0.07625,0.05114
1.32000,2.06474,11.00825,11.00825,0.07863,0.04916
1.36000,1.70358,11.34176,11.34176,0.08101,0.04056
1.40000,1.70004,11.67495,11.67495,0.08339,0.04048
1.44000,1.41636,12.00840,12.00840,0.08577,0.03372
1.48000,1.55047,12.34157,12.34157,0.08815,0.03692
1.52000,1.78572,12.67502,12.67502,0.09054,0.04252
1.56000,1.80956,13.00834,13.00834,0.09292,0.04308
1.60000,2.05729,13.34164,13.34164,0.09530,0.04898
1.64000,1.78926,13.67509,13.67509,0.09768,0.04260
1.68000,2.05822,14.00823,14.00823,0.10006,0.04901
1.72000,1.93659,14.34179,14.34179,0.10244,0.04611
1.76000,1.78032,14.67490,14.67490,0.10482,0.04239
1.80000,2.00737,15.00843,15.00843,0.10720,0.04779
1.84000,1.80732,15.34167,15.34167,0.10958,0.04303
1.88000,1.71829,15.67502,15.67502,0.11196,0.04091
1.92000,1.81030,16.00832,16.00832,0.11435,0.04310
1.96000,1.91778,16.34166,16.34166,0.11673,0.04566
2.00000,1.59051,16.67509,16.67509,0.11911,0.03787
2.04000,1.96006,17.00825,17.00825,0.12149,0.04667
2.08000,2.01352,17.34171,17.34171,0.12387,0.04794
2.12000,1.87382,17.67489,17.67489,0.12625,0.04461
2.16000,1.93827,18.00843,18.00843,0.12863,0.04615
2.20000,1.86190,18.34164,18.34164,0.13101,0.04433
2.24000,1.72425,18.67502,18.67502,0.13339,0.04105
2.28000,1.80099,19.00831,19.00831,0.13577,0.04288
2.32000,2.22921,19.34163,19.34163,0.13815,0.05308
2.36000,2.10088,19.67509,19.67509,0.14054,0.05002
2.40000,1.81254,20.00833,20.00833,0.14292,0.04316
2.44000,1.71568,20.34173,20.34173,0.14530,0.04085
2.48000,1.45603,20.67492,20.67492,0.14768,0.03467
2.52000,1.66837,21.00838,21.00838,0.15006,0.03972
2.56000,1.68029,21.34159,21.34159,0.15244,0.04001
2.60000,1.61547,21.67510,21.67510,0.15482,0.03846
2.64000,1.37538,22.00834,22.00834,0.15720,0.03275
2.68000,1.40909,22.34161,22.34161,0.15958,0.03355
2.72000,1.40239,22.67509,22.67509,0.16196,0.03339
2.76000,1.63186,23.00825,23.00825,0.16434,0.03885
2.80000,1.77380,23.34176,23.34175,0.16673,0.04223
2.84000,1.79894,23.67486,23.67486,0.16911,0.04283
2.88000,1.56853,24.00837,24.00837,0.17149,0.03735
2.92000,1.50055,24.34159,24.34159,0.17387,0.03573
2.96000,1.86190,24.67504,24.67504,0.17625,0.04433
3.00000,1.80993,25.00842,25.00842,0.17863,0.04309
3.04000,1.73356,25.34163,25.34163,0.18101,0.04128
3.08000,1.61380,25.67503,25.67503,0.18339,0.03842
3.12000,1.47223,26.00819,26.00819,0.18577,0.03505
3.16000,1.41058,26.34181,26.34181,0.18816,0.03359
3.20000,1.99582,26.67494,26.67494,0.19054,0.04752
3.24000,1.96975,27.00843,27.00842,0.19292,0.04690
3.28000,1.70749,27.34156,27.34156,0.19530,0.04065
3.32000,1.67266,27.67501,27.67501,0.19768,0.03983
3.36000,2.01166,28.00841,28.00842,0.20006,0.04790
3.40000,1.95019,28.34160,28.34160,0.20244,0.04643
3.44000,2.06921,28.67506,28.67506,0.20482,0.04927
3.48000,1.99340,29.00822,29.00822,0.20720,0.04746
3.52000,2.00532,29.34176,29.34176,0.20958,0.04775
3.56000,1.76970,29.67497,29.67497,0.21196,0.04214
3.60000,1.92448,30.00840,30.00840,0.21435,0.04582
3.64000,1.93827,30.34161,30.34161,0.21673,0.04615
3.68000,1.75089,30.67501,30.67501,0.21911,0.04169
3.72000,2.04984,31.00834,31.00834,0.22149,0.04881
3.76000,1.76262,31.34166,31.34166,0.22387,0.04197
3.80000,2.19103,31.67508,31.67508,0.22625,0.05217
3.84000,2.32551,32.00822,32.00822,0.22863,0.05537
3.88000,2.35625,32.34175,32.34175,0.23101,0.05610
3.92000,2.10237,32.67491,32.67491,0.23339,0.05006
3.96000,2.12714,33.00840,33.00840,0.23577,0.05065
4.00000,2.32030,33.34158,33.34158,0.23815,0.05525
4.04000,2.30875,33.67496,33.67496,0.24054,0.05497
4.08000,2.65520,34.00838,34.00838,0.24292,0.06322
4.12000,2.37189,34.34165,34.34165,0.24530,0.05647
4.16000,2.52686,34.67508,34.67508,0.24768,0.06016
4.20000,2.63285,35.00827,35.00827,0.25006,0.06269
4.24000,2.11131,35.34178,35.34177,0.25244,0.05027
4.28000,2.51811,35.67491,35.67491,0.25482,0.05996
4.32000,2.51792,36.00845,36.00845,0.25720,0.05995
4.36000,2.87835,36.34164,36.34164,0.25958,0.06853
4.40000,2.29366,36.67504,36.67504,0.26196,0.05461
4.44000,2.72058,37.00836,37.00836,0.26435,0.06478
4.48000,2.28826,37.34157,37.34157,0.26673,0.05448
4.52000,2.55648,37.67511,37.67511,0.26911,0.06087
4.56000,2.56915,38.00822,38.00822,0.27149,0.06117
4.60000,2.87965,38.34175,38.34175,0.27387,0.06856
4.64000,2.95490,38.67494,38.67494,0.27625,0.07035
4.68000,2.66284,39.00842,39.00842,0.27863,0.06340
4.72000,2.97166,39.34166,39.34166,0.28101,0.07075
4.76000,2.89641,39.67501,39.67501,0.28339,0.06896
4.80000,2.85190,40.00833,40.00833,0.28577,0.06790
4.84000,2.84985,40.34162,40.34163,0.28815,0.06785
4.88000,2.91336,40.67510,40.67511,0.29054,0.06937
4.92000,3.17041,41.00826,41.00827,0.29292,0.07549
4.96000,3.16426,41.34175,41.34175,0.29530,0.07534
5.00000,2.94987,41.67491,41.67491,0.29768,0.07024
5.04000,3.24044,42.00839,42.00839,0.30006,0.07715
5.08000,3.21548,42.34163,42.34163,0.30244,0.07656
5.12000,3.12943,42.67500,42.67500,0.30482,0.07451
5.16000,3.04040,43.00836,43.00836,0.30720,0.07239
5.20000,3.19891,43.34160,43.34160,0.30958,0.07616
5.24000,3.21083,43.67505,43.67505,0.31196,0.07645
5.28000,3.29800,44.00832,44.00832,0.31435,0.07852
5.32000,3.21735,44.34172,44.34172,0.31673,0.07660
5.36000,2.84985,44.67488,44.67488,0.31911,0.06785
5.40000,3.38275,45.00842,45.00842,0.32149,0.08054
5.44000,3.26242,45.34163,45.34164,0.32387,0.07768
5.48000,3.38610,45.67509,45.67509,0.32625,0.08062
5.52000,3.49674,46.00833,46.00832,0.32863,0.08326
5.56000,3.43695,46.34162,46.34162,0.33101,0.08183
5.60000,3.25479,46.67508,46.67508,0.33339,0.07749
5.64000,3.35909,47.00824,47.00824,0.33577,0.07998
5.68000,3.65376,47.34182,47.34182,0.33816,0.08699
5.72000,3.94247,47.67493,47.67493,0.34054,0.09387
5.76000,3.67444,48.00839,48.00839,0.34292,0.08749
5.80000,3.71374,48.34161,48.34161,0.34530,0.08842
5.84000,3.54480,48.67503,48.67503,0.34768,0.08440
5.88000,3.96017,49.00835,49.00835,0.35006,0.09429
5.92000,3.93167,49.34165,49.34165,0.35244,0.09361
5.96000,3.76403,49.67505,49.67505,0.35482,0.08962
6.00000,4.09819,50.00821,50.00821,0.35720,0.09758
6.04000,3.85102,50.34182,50.34182,0.35958,0.09169
6.08000,3.65805,50.67491,50.67491,0.36196,0.08710
6.12000,3.83016,51.00841,51.00841,0.36435,0.09119
6.16000,3.74373,51.34157,51.34157,0.36673,0.08914
6.20000,3.75640,51.67503,51.67503,0.36911,0.08944
6.24000,3.82923,52.00840,52.00840,0.37149,0.09117
6.28000,3.83072,52.34165,52.34165,0.37387,0.09121
6.32000,4.22727,52.67505,52.67505,0.37625,0.10065
6.36000,4.06802,53.00823,53.00823,0.37863,0.09686
6.40000,4.20604,53.34175,53.34175,0.38101,0.10014
6.44000,4.02313,53.67493,53.67493,0.38339,0.09579
6.48000,3.71169,54.00844,54.00844,0.38577,0.08837
6.52000,4.02015,54.34157,54.34157,0.38815,0.09572
6.56000,4.02797,54.67500,54.67500,0.39054,0.09590
6.60000,3.85791,55.00835,55.00835,0.39292,0.09186
6.64000,4.22113,55.34167,55.34167,0.39530,0.10050
6.68000,4.17810,55.67510,55.67510,0.39768,0.09948
6.72000,3.86797,56.00824,56.00824,0.40006,0.09209
6.76000,4.45209,56.34177,56.34177,0.40244,0.10600
6.80000,4.40869,56.67493,56.67493,0.40482,0.10497
6.84000,4.29191,57.00843,57.00843,0.40720,0.10219
6.88000,3.88473,57.34159,57.34159,0.40958,0.09249
6.92000,4.20064,57.67503,57.67503,0.41196,0.10002
6.96000,3.99519,58.00833,58.00832,0.41435,0.09512
7.00000,4.05721,58.34162,58.34162,0.41673,0.09660
7.04000,4.52939,58.67510,58.67509,0.41911,0.10784
7.08000,4.55938,59.00823,59.00823,0.42149,0.10856
7.12000,4.35710,59.34174,59.34174,0.42387,0.10374
7.16000,4.34145,59.67488,59.67488,0.42625,0.10337
7.20000,4.13749,60.00843,60.00843,0.42863,0.09851
7.24000,4.06113,60.34165,60.34165,0.43101,0.09669
7.28000,3.98718,60.67502,60.67502,0.43339,0.09493
7.32000,4.44781,61.00838,61.00838,0.43577,0.10590
7.36000,4.28651,61.34156,61.34156,0.43815,0.10206
7.40000,4.26322,61.67512,61.67512,0.44054,0.10151
7.44000,4.55584,62.00828,62.00828,0.44292,0.10847
7.48000,4.42900,62.34177,62.34177,0.44530,0.10545
7.52000,4.23416,62.67489,62.67490,0.44768,0.10081
7.56000,4.34332,63.00838,63.00838,0.45006,0.10341
7.60000,4.30197,63.34162,63.34162,0.45244,0.10243
7.64000,4.34350,63.67503,63.67503,0.45482,0.10342
7.68000,4.60576,64.00832,64.00832,0.45720,0.10966
7.72000,4.40590,64.34163,64.34164,0.45958,0.10490
7.76000,4.24255,64.67507,64.67507,0.46196,0.10101
7.80000,4.46029,65.00829,65.00829,0.46434,0.10620
7.84000,4.03561,65.34182,65.34182,0.46673,0.09609
7.88000,4.17642,65.67489,65.67490,0.46911,0.09944
7.92000,4.30159,66.00837,66.00838,0.47149,0.10242
7.96000,4.35654,66.34165,66.34165,0.47387,0.10373
8.00000,4.42900,66.67505,66.67505,0.47625,0.10545
8.04000,4.31351,67.00832,67.00832,0.47863,0.10270
8.08000,4.04716,67.34163,67.34164,0.48101,0.09636
8.12000,4.18052,67.67501,67.67501,0.48339,0.09954
8.16000,4.22895,68.00829,68.00829,0.48577,0.10069
8.20000,4.20883,68.34173,68.34174,0.48816,0.10021
8.24000,4.17382,68.67489,68.67490,0.49053,0.09938
8.28000,4.40404,69.00843,69.00843,0.49292,0.10486
8.32000,4.22336,69.34159,69.34159,0.49530,0.10056
8.36000,4.41633,69.67503,69.67503,0.49768,0.10515
8.40000,4.24813,70.00834,70.00835,0.50006,0.10115
8.44000,4.19766,70.34163,70.34163,0.50244,0.09994
8.48000,4.34425,70.67512,70.67511,0.50482,0.10343
8.52000,4.35933,71.00825,71.00826,0.50720,0.10379
8.56000,4.48767,71.34177,71.34177,0.50958,0.10685
8.60000,4.31128,71.67493,71.67493,0.51196,0.10265
8.64000,4.69964,72.00837,72.00837,0.51435,0.11190
8.68000,4.67598,72.34159,72.34159,0.51673,0.11133
8.72000,4.37051,72.67505,72.67505,0.51911,0.10406
8.76000,4.39715,73.00837,73.00837,0.52149,0.10469
8.80000,4.79203,73.34161,73.34161,0.52387,0.11410
8.84000,4.89093,73.67506,73.67506,0.52625,0.11645
8.88000,4.52939,74.00825,74.00826,0.52863,0.10784
8.92000,4.62960,74.34179,74.34178,0.53101,0.11023
8.96000,4.49605,74.67493,74.67493,0.53339,0.10705
9.00000,4.33605,75.00841,75.00842,0.53577,0.10324
9.04000,4.43328,75.34162,75.34162,0.53815,0.10555
9.08000,4.78569,75.67502,75.67502,0.54054,0.11395
9.12000,4.66816,76.00837,76.00837,0.54292,0.11115
9.16000,4.68623,76.34167,76.34167,0.54530,0.11158
9.20000,4.85182,76.67506,76.67506,0.54768,0.11552
9.24000,4.76670,77.00825,77.00826,0.55006,0.11349
9.28000,4.79724,77.34173,77.34174,0.55244,0.11422
9.32000,4.81121,77.67494,77.67494,0.55482,0.11455
9.36000,4.76427,78.00843,78.00842,0.55720,0.11344
9.40000,4.88423,78.34153,78.34153,0.55958,0.11629
9.44000,4.97624,78.67504,78.67505,0.56196,0.11848
9.48000,5.33964,79.00837,79.00837,0.56435,0.12713
9.52000,5.41676,79.34166,79.34166,0.56673,0.12897
9.56000,5.67213,79.67509,79.67510,0.56911,0.13505
9.60000,5.37615,80.00822,80.00822,0.57149,0.12800
9.64000,5.53634,80.34176,80.34176,0.57387,0.13182
9.68000,5.38453,80.67492,80.67492,0.57625,0.12820
9.72000,5.77699,81.00845,81.00845,0.57863,0.13755
9.76000,5.71907,81.34164,81.34164,0.58101,0.13617
9.80000,5.59948,81.67502,81.67502,0.58339,0.13332
9.84000,5.77401,82.00833,82.00833,0.58577,0.13748
9.88000,5.73061,82.34163,82.34163,0.58815,0.13644
9.92000,5.64046,82.67511,82.67512,0.59054,0.13430
9.96000,5.73602,83.00827,83.00828,0.59292,0.13657
10.00000,5.88577,83.34178,83.34178,0.59530,0.14014
10.04000,5.90943,83.67487,83.67486,0.59768,0.14070
10.08000,6.06291,84.00840,84.00840,0.60006,0.14435
10.12000,6.30431,84.34166,84.34165,0.60244,0.15010
10.16000,6.40433,84.67499,84.67499,0.60482,0.15248
10.20000,6.10501,85.00837,85.00838,0.60720,0.14536
10.24000,5.96996,85.34161,85.34161,0.60958,0.14214
10.28000,5.93364,85.67511,85.67511,0.61197,0.14128
10.32000,6.03050,86.00830,86.00829,0.61434,0.14358
10.36000,5.98729,86.34178,86.34177,0.61673,0.14255
10.40000,6.13965,86.67488,86.67488,0.61911,0.14618
10.44000,6.15790,87.00837,87.00838,0.62149,0.14662
10.48000,5.93606,87.34164,87.34164,0.62387,0.14133
10.52000,6.16983,87.67507,87.67507,0.62625,0.14690
10.56000,5.93811,88.00833,88.00833,0.62863,0.14138
10.60000,6.12680,88.34157,88.34158,0.63101,0.14588
10.64000,6.23371,88.67506,88.67506,0.63339,0.14842
10.68000,5.94575,89.00824,89.00825,0.63577,0.14157
10.72000,6.17187,89.34178,89.34177,0.63816,0.14695
10.76000,6.08880,89.67492,89.67492,0.64054,0.14497
10.80000,6.12773,90.00840,90.00840,0.64292,0.14590
10.84000,6.54366,90.34164,90.34164,0.64530,0.15580
10.88000,6.43171,90.67509,90.67509,0.64768,0.15314
10.92000,5.99045,91.00836,91.00836,0.65006,0.14263
10.96000,5.92396,91.34162,91.34162,0.65244,0.14105
11.00000,6.45462,91.67505,91.67505,0.65482,0.15368
11.04000,6.08359,92.00826,92.00826,0.65720,0.14485
11.08000,6.04428,92.34178,92.34177,0.65958,0.14391
11.12000,6.41849,92.67492,92.67492,0.66196,0.15282
11.16000,6.32629,93.00840,93.00840,0.66435,0.15063
11.20000,6.35181,93.34158,93.34158,0.66673,0.15123
11.24000,6.20484,93.67498,93.67498,0.66911,0.14773
11.28000,6.31195,94.00839,94.00838,0.67149,0.15028
11.32000,6.47884,94.34162,94.34161,0.67387,0.15426
11.36000,6.50361,94.67508,94.67509,0.67625,0.15485
11.40000,6.44587,95.00824,95.00825,0.67863,0.15347
11.44000,5.99679,95.34176,95.34176,0.68101,0.14278
11.48000,6.28959,95.67497,95.67496,0.68339,0.14975
11.52000,6.26873,96.00842,96.00842,0.68577,0.14926
11.56000,6.15679,96.34163,96.34164,0.68815,0.14659
11.60000,6.27227,96.67498,96.67498,0.69054,0.14934
11.64000,6.47716,97.00836,97.00836,0.69292,0.15422
11.68000,6.55428,97.34162,97.34162,0.69530,0.15605
11.72000,6.18026,97.67508,97.67509,0.69768,0.14715
11.76000,6.68578,98.00821,98.00821,0.70006,0.15919
11.80000,6.31679,98.34176,98.34176,0.70244,0.15040
11.84000,6.39521,98.67494,98.67494,0.70482,0.15227
11.88000,6.24321,99.00841,99.00842,0.70720,0.14865
11.92000,6.37341,99.34163,99.34164,0.70958,0.15175
11.96000,6.48294,99.67498,99.67499,0.71196,0.15436
12.00000,6.42780,100.00838,100.00838,0.71435,0.15304
12.04000,6.40955,100.34171,100.34171,0.71673,0.15261
12.08000,6.45667,100.67505,100.67505,0.71911,0.15373
12.12000,6.62543,101.00826,101.00826,0.72149,0.15775
12.16000,6.60252,101.34175,101.34175,0.72387,0.15720
12.20000,6.57253,101.67488,101.67488,0.72625,0.15649
12.24000,6.64759,102.00847,102.00848,0.72863,0.15828
12.28000,6.83628,102.34161,102.34161,0.73101,0.16277
12.32000,7.04937,102.67503,102.67504,0.73339,0.16784
12.36000,7.02627,103.00833,103.00832,0.73577,0.16729
12.40000,6.73216,103.34162,103.34163,0.73815,0.16029
12.44000,6.55614,103.67503,103.67503,0.74054,0.15610
12.48000,6.92736,104.00821,104.00822,0.74292,0.16494
12.52000,7.01211,104.34180,104.34180,0.74530,0.16696
12.56000,6.54235,104.67493,104.67493,0.74768,0.15577
12.60000,6.72210,105.00844,105.00843,0.75006,0.16005
12.64000,6.94040,105.34163,105.34164,0.75244,0.16525
12.68000,6.78431,105.67503,105.67503,0.75482,0.16153
12.72000,7.01696,106.00832,106.00832,0.75720,0.16707
12.76000,6.59265,106.34162,106.34162,0.75958,0.15697
12.80000,6.85137,106.67513,106.67513,0.76197,0.16313
12.84000,6.80443,107.00824,107.00823,0.76434,0.16201
12.88000,6.85919,107.34177,107.34177,0.76673,0.16331
12.92000,7.12089,107.67491,107.67491,0.76911,0.16955
12.96000,7.11307,108.00839,108.00838,0.77149,0.16936
13.00000,6.66585,108.34163,108.34163,0.77387,0.15871
13.04000,7.07861,108.67503,108.67503,0.77625,0.16854
13.08000,6.92345,109.00836,109.00835,0.77863,0.16484
13.12000,7.00317,109.34159,109.34159,0.78101,0.16674
13.16000,6.78468,109.67508,109.67508,0.78339,0.16154
13.20000,7.62735,110.00829,110.00829,0.78577,0.18160
13.24000,7.11139,110.34177,110.34177,0.78816,0.16932
13.28000,7.28648,110.67493,110.67493,0.79054,0.17349
13.32000,7.48374,111.00844,111.00844,0.79292,0.17818
13.36000,7.37365,111.34163,111.34163,0.79530,0.17556
13.40000,7.42450,111.67506,111.67506,0.79768,0.17677
13.44000,7.45878,112.00832,112.00832,0.80006,0.17759
13.48000,7.04173,112.34154,112.34154,0.80244,0.16766
13.52000,7.28108,112.67507,112.67507,0.80482,0.17336
13.56000,7.37552,113.00826,113.00826,0.80720,0.17561
13.60000,7.36006,113.34180,113.34180,0.80958,0.17524
13.64000,7.38893,113.67488,113.67488,0.81196,0.17593
13.68000,7.27829,114.00839,114.00839,0.81435,0.17329
13.72000,7.17957,114.34161,114.34161,0.81673,0.17094
13.76000,7.45878,114.67505,114.67505,0.81911,0.17759
13.80000,7.74134,115.00837,115.00837,0.82149,0.18432
13.84000,7.86595,115.34165,115.34164,0.82387,0.18728
13.88000,7.67820,115.67508,115.67508,0.82625,0.18281
13.92000,7.38259,116.00824,116.00824,0.82863,0.17578
13.96000,7.93301,116.34182,116.34182,0.83101,0.18888
14.00000,8.03582,116.67493,116.67493,0.83339,0.19133
14.04000,7.89743,117.00841,117.00842,0.83577,0.18803
14.08000,7.89724,117.34160,117.34160,0.83815,0.18803
14.12000,8.16081,117.67499,117.67500,0.84054,0.19430
14.16000,7.98367,118.00840,118.00840,0.84292,0.19009
14.20000,8.19657,118.34161,118.34161,0.84530,0.19516
14.24000,7.87936,118.67505,118.67505,0.84768,0.18760
14.28000,8.14162,119.00826,119.00826,0.85006,0.19385
14.32000,8.02949,119.34177,119.34177,0.85244,0.19118
14.36000,8.06656,119.67498,119.67499,0.85482,0.19206
14.40000,8.15727,120.00843,120.00843,0.85720,0.19422
14.44000,8.55718,120.34163,120.34163,0.85958,0.20374
14.48000,8.38283,120.67500,120.67500,0.86196,0.19959
14.52000,8.23680,121.00837,121.00837,0.86435,0.19611
14.56000,8.16528,121.34167,121.34167,0.86673,0.19441
14.60000,8.21799,121.67512,121.67512,0.86911,0.19567
14.64000,8.18484,122.00823,122.00822,0.87149,0.19488
14.68000,8.30088,122.34174,122.34174,0.87387,0.19764
14.72000,8.51024,122.67493,122.67493,0.87625,0.20262
14.76000,8.96621,123.00841,123.00841,0.87863,0.21348
14.80000,8.62926,123.34162,123.34162,0.88101,0.20546
14.84000,8.71364,123.67499,123.67500,0.88339,0.20747
14.88000,8.87476,124.00828,124.00829,0.88577,0.21130
14.92000,8.75052,124.34166,124.34167,0.88815,0.20835
14.96000,8.71159,124.67510,124.67510,0.89054,0.20742
15.00000,8.59462,125.00826,125.00826,0.89292,0.20463
15.04000,8.88426,125.34176,125.34176,0.89530,0.21153
15.08000,8.67229,125.67489,125.67489,0.89768,0.20648
15.12000,8.84850,126.00846,126.00845,0.90006,0.21068
15.16000,8.79150,126.34164,126.34164,0.90244,0.20932
15.20000,8.69744,126.67505,126.67505,0.90482,0.20708
15.24000,8.73357,127.00832,127.00832,0.90720,0.20794
15.28000,8.97963,127.34161,127.34161,0.90958,0.21380
15.32000,8.70060,127.67509,127.67509,0.91196,0.20716
15.36000,8.62684,128.00825,128.00826,0.91434,0.20540
15.40000,9.00757,128.34174,128.34174,0.91673,0.21447
15.44000,9.21544,128.67490,128.67490,0.91911,0.21942
15.48000,9.14522,129.00840,129.00839,0.92149,0.21774
15.52000,8.99024,129.34160,129.34160,0.92387,0.21405
15.56000,9.18917,129.67508,129.67508,0.92625,0.21879
15.60000,9.23388,130.00839,130.00839,0.92863,0.21985
15.64000,9.15453,130.34166,130.34166,0.93101,0.21796
15.68000,9.15378,130.67510,130.67509,0.93339,0.21795
15.72000,9.17427,131.00826,131.00826,0.93577,0.21844
15.76000,9.31062,131.34176,131.34175,0.93816,0.22168
15.80000,9.25884,131.67492,131.67491,0.94054,0.22045
15.84000,9.22196,132.00838,132.00838,0.94292,0.21957
15.88000,9.26256,132.34167,132.34167,0.94530,0.22054
15.92000,9.14093,132.67501,132.67502,0.94768,0.21764
15.96000,9.37320,133.00834,133.00835,0.95006,0.22317
16.00000,9.51458,133.34160,133.34160,0.95244,0.22654
16.04000,9.48533,133.67501,133.67502,0.95482,0.22584
16.08000,9.11020,134.00828,134.00827,0.95720,0.21691
16.12000,9.53469,134.34178,134.34178,0.95958,0.22702
16.16000,9.36538,134.67490,134.67490,0.96196,0.22299
16.20000,9.37823,135.00846,135.00847,0.96435,0.22329
16.24000,9.83737,135.34165,135.34164,0.96673,0.23422
16.28000,9.64887,135.67508,135.67508,0.96911,0.22974
16.32000,9.51346,136.00837,136.00838,0.97149,0.22651
16.36000,9.54848,136.34161,136.34161,0.97387,0.22734
16.40000,9.67216,136.67510,136.67509,0.97625,0.23029
16.44000,9.83737,137.00826,137.00826,0.97863,0.23422
16.48000,9.28175,137.34178,137.34178,0.98101,0.22099
16.52000,9.70270,137.67486,137.67487,0.98339,0.23102
16.56000,9.74555,138.00840,138.00841,0.98577,0.23204
16.60000,9.49949,138.34158,138.34158,0.98815,0.22618
16.64000,9.85451,138.67504,138.67503,0.99054,0.23463
16.68000,9.93870,139.00837,139.00836,0.99292,0.23664
16.72000,9.84557,139.34163,139.34163,0.99530,0.23442
16.76000,9.75002,139.67505,139.67505,0.99768,0.23214
16.80000,9.50359,140.00821,140.00821,1.00006,0.22628
16.84000,9.76119,140.34184,140.34184,1.00244,0.23241
16.88000,9.90015,140.67494,140.67494,1.00482,0.23572
16.92000,9.97335,141.00840,141.00839,1.00720,0.23746
16.96000,9.82806,141.34163,141.34163,1.00958,0.23400
17.00000,10.00576,141.67502,141.67502,1.01196,0.23823
17.04000,9.91356,142.00837,142.00838,1.01435,0.23604
17.08000,9.77349,142.34164,142.34163,1.01673,0.23270
17.12000,9.99235,142.67503,142.67503,1.01911,0.23791
17.16000,10.02122,143.00822,143.00822,1.02149,0.23860
17.20000,10.01768,143.34169,143.34171,1.02387,0.23852
17.24000,10.33898,143.67494,143.67493,1.02625,0.24617
17.28000,9.76473,144.00841,144.00841,1.02863,0.23249
17.32000,10.02252,144.34161,144.34163,1.03101,0.23863
17.36000,10.22127,144.67501,144.67500,1.03339,0.24336
17.40000,10.25647,145.00839,145.00839,1.03577,0.24420
17.44000,10.09423,145.34168,145.34167,1.03815,0.24034
17.48000,9.83849,145.67514,145.67514,1.04054,0.23425
17.52000,10.17526,146.00821,146.00821,1.04292,0.24227
17.56000,10.49824,146.34171,146.34172,1.04530,0.24996
17.60000,10.60590,146.67497,146.67497,1.04768,0.25252
17.64000,10.39226,147.00846,147.00845,1.05006,0.24743
17.68000,10.85158,147.34162,147.34161,1.05244,0.25837
17.72000,10.64297,147.67499,147.67499,1.05482,0.25340
17.76000,10.27733,148.00828,148.00829,1.05720,0.24470
17.80000,10.32427,148.34161,148.34161,1.05958,0.24582
17.84000,10.71226,148.67511,148.67513,1.06197,0.25505
17.88000,10.68488,149.00826,149.00826,1.06434,0.25440
17.92000,10.62397,149.34182,149.34183,1.06673,0.25295
17.96000,10.87822,149.67489,149.67490,1.06911,0.25901
18.00000,10.85289,150.00848,150.00848,1.07149,0.25840
18.04000,10.74858,150.34167,150.34166,1.07387,0.25592
18.08000,10.71431,150.67501,150.67500,1.07625,0.25510
18.12000,10.98774,151.00836,151.00836,1.07863,0.26161
18.16000,10.80316,151.34159,151.34158,1.08101,0.25722
18.20000,11.05424,151.67509,151.67509,1.08339,0.26320
18.24000,11.23212,152.00830,152.00830,1.08577,0.26743
18.28000,11.31035,152.34175,152.34177,1.08816,0.26929
18.32000,10.97545,152.67489,152.67490,1.09053,0.26132
18.36000,11.20567,153.00839,153.00839,1.09292,0.26680
18.40000,11.20381,153.34163,153.34163,1.09530,0.26676
18.44000,11.25243,153.67504,153.67503,1.09768,0.26791
18.48000,11.08665,154.00836,154.00838,1.10006,0.26397
18.52000,11.18463,154.34160,154.34160,1.10244,0.26630
18.56000,11.09615,154.67506,154.67505,1.10482,0.26419
18.60000,11.10379,155.00832,155.00832,1.10720,0.26438
18.64000,11.21499,155.34181,155.34181,1.10958,0.26702
18.68000,11.41783,155.67497,155.67496,1.11196,0.27185
18.72000,11.27850,156.00837,156.00838,1.11435,0.26854
18.76000,11.23212,156.34164,156.34164,1.11673,0.26743
18.80000,11.37406,156.67506,156.67506,1.11911,0.27081
18.84000,11.26546,157.00832,157.00832,1.12149,0.26823
18.88000,11.45396,157.34165,157.34166,1.12387,0.27271
18.92000,11.65327,157.67505,157.67505,1.12625,0.27746
18.96000,11.66463,158.00823,158.00824,1.12863,0.27773
19.00000,11.52400,158.34180,158.34178,1.13101,0.27438
19.04000,11.69983,158.67489,158.67490,1.13339,0.27857
19.08000,11.60447,159.00842,159.00841,1.13577,0.27630
19.12000,11.76428,159.34161,159.34160,1.13815,0.28010
19.16000,11.74528,159.67504,159.67503,1.14054,0.27965
19.20000,11.83152,160.00838,160.00838,1.14292,0.28170
19.24000,12.01387,160.34163,160.34163,1.14530,0.28604
19.28000,12.00382,160.67507,160.67506,1.14768,0.28581
19.32000,11.69704,161.00823,161.00822,1.15006,0.27850
19.36000,11.93732,161.34182,161.34181,1.15244,0.28422
19.40000,11.85667,161.67494,161.67494,1.15482,0.28230
19.44000,11.63930,162.00841,162.00841,1.15720,0.27713
19.48000,11.80619,162.34157,162.34157,1.15958,0.28110
19.52000,11.83264,162.67503,162.67503,1.16196,0.28173
19.56000,12.03902,163.00835,163.00835,1.16435,0.28664
19.60000,12.14258,163.34159,163.34158,1.16673,0.28911
19.64000,12.39721,163.67514,163.67514,1.16911,0.29517
19.68000,12.35697,164.00827,164.00827,1.17149,0.29421
19.72000,12.23795,164.34180,164.34180,1.17387,0.29138
19.76000,12.15674,164.67493,164.67493,1.17625,0.28945
19.80000,12.16996,165.00839,165.00841,1.17863,0.28976
19.84000,12.41323,165.34166,165.34166,1.18101,0.29555
19.88000,12.53430,165.67504,165.67503,1.18339,0.29844
19.92000,12.29029,166.00838,166.00839,1.18577,0.29263
19.96000,12.76620,166.34170,166.34169,1.18815,0.30396
20.00000,12.19474,166.67507,166.67505,1.19054,0.29035
20.04000,12.38473,167.00823,167.00822,1.19292,0.29487
20.08000,12.66338,167.34171,167.34171,1.19530,0.30151
20.12000,12.43204,167.67491,167.67491,1.19768,0.29600
20.16000,12.72429,168.00846,168.00847,1.20006,0.30296
20.20000,12.99474,168.34160,168.34160,1.20244,0.30940
20.24000,12.63134,168.67498,168.67497,1.20482,0.30075
20.28000,12.72000,169.00839,169.00839,1.20720,0.30286
20.32000,12.66766,169.34165,169.34166,1.20958,0.30161
20.36000,12.55441,169.67507,169.67508,1.21196,0.29891
20.40000,12.47991,170.00826,170.00826,1.21434,0.29714
20.44000,12.63376,170.34180,170.34180,1.21673,0.30080
20.48000,12.81053,170.67496,170.67496,1.21911,0.30501
20.52000,13.30730,171.00846,171.00845,1.22149,0.31684
20.56000,13.07130,171.34162,171.34161,1.22387,0.31122
20.60000,13.13817,171.67500,171.67499,1.22625,0.31281
20.64000,13.31698,172.00834,172.00835,1.22863,0.31707
20.68000,12.91241,172.34162,172.34160,1.23101,0.30744
20.72000,12.85393,172.67513,172.67513,1.23339,0.30605
20.76000,12.97295,173.00821,173.00821,1.23577,0.30888
20.80000,13.23745,173.34174,173.34174,1.23816,0.31518
20.84000,13.25794,173.67485,173.67487,1.24053,0.31567
20.88000,12.92340,174.00837,174.00838,1.24292,0.30770
20.92000,13.14413,174.34167,174.34167,1.24530,0.31296
20.96000,13.21863,174.67506,174.67506,1.24768,0.31473
21.00000,13.52318,175.00841,175.00841,1.25006,0.32198
21.04000,13.35982,175.34168,175.34167,1.25244,0.31809
21.08000,13.62264,175.67514,175.67514,1.25482,0.32435
21.12000,13.70832,176.00830,176.00830,1.25720,0.32639
21.16000,13.41943,176.34177,176.34177,1.25958,0.31951
21.20000,13.80723,176.67493,176.67494,1.26196,0.32874
21.24000,13.69398,177.00838,177.00838,1.26435,0.32605
21.28000,13.83033,177.34162,177.34160,1.26673,0.32929
21.32000,13.65468,177.67504,177.67505,1.26911,0.32511
21.36000,14.10656,178.00833,178.00833,1.27149,0.33587
21.40000,13.81338,178.34159,178.34160,1.27387,0.32889
21.44000,14.40607,178.67505,178.67505,1.27625,0.34300
21.48000,14.27103,179.00832,179.00832,1.27863,0.33979
21.52000,14.31815,179.34179,179.34180,1.28101,0.34091
21.56000,14.12518,179.67495,179.67496,1.28339,0.33631
21.60000,13.97431,180.00837,180.00838,1.28577,0.33272
21.64000,14.07657,180.34162,180.34163,1.28815,0.33516
21.68000,14.26917,180.67509,180.67509,1.29054,0.33974
21.72000,14.21925,181.00837,181.00836,1.29292,0.33855
21.76000,14.27196,181.34164,181.34164,1.29530,0.33981
21.80000,14.39825,181.67504,181.67506,1.29768,0.34282
21.84000,14.15778,182.00823,182.00824,1.30006,0.33709
21.88000,14.09836,182.34180,182.34180,1.30244,0.33568
21.92000,13.95121,182.67488,182.67488,1.30482,0.33217
21.96000,13.42911,183.00838,183.00838,1.30720,0.31974
22.00000,13.38590,183.34158,183.34158,1.30958,0.31871
22.04000,13.92756,183.67505,183.67505,1.31196,0.33161
22.08000,14.49753,184.00846,184.00845,1.31435,0.34518
22.12000,14.24216,184.34166,184.34166,1.31673,0.33910
22.16000,14.28369,184.67509,184.67509,1.31911,0.34009
22.20000,14.35615,185.00832,185.00833,1.32149,0.34181
22.24000,14.32970,185.34181,185.34181,1.32387,0.34118
22.28000,14.47089,185.67492,185.67493,1.32625,0.34455
22.32000,14.48356,186.00846,186.00845,1.32863,0.34485
22.36000,14.65380,186.34159,186.34160,1.33101,0.34890
22.40000,14.55378,186.67499,186.67499,1.33339,0.34652
22.44000,14.85758,187.00837,187.00838,1.33577,0.35375
22.48000,14.77543,187.34161,187.34161,1.33815,0.35180
22.52000,14.69366,187.67507,187.67506,1.34054,0.34985
22.56000,14.73818,188.00823,188.00822,1.34292,0.35091
22.60000,14.84342,188.34173,188.34174,1.34530,0.35341
22.64000,15.18894,188.67492,188.67491,1.34768,0.36164
22.68000,14.74153,189.00845,189.00845,1.35006,0.35099
22.72000,15.13511,189.34164,189.34163,1.35244,0.36036
22.76000,15.09897,189.67505,189.67505,1.35482,0.35950
22.80000,15.04179,190.00834,190.00833,1.35720,0.35814
22.84000,14.92221,190.34169,190.34169,1.35958,0.35529
22.88000,15.30182,190.67506,190.67506,1.36196,0.36433
22.92000,15.24501,191.00822,191.00822,1.36434,0.36298
22.96000,15.25860,191.34176,191.34177,1.36673,0.36330
23.00000,15.17870,191.67492,191.67491,1.36911,0.36140
23.04000,15.42754,192.00843,192.00844,1.37149,0.36732
23.08000,15.30293,192.34162,192.34161,1.37387,0.36436
23.12000,15.19639,192.67501,192.67502,1.37625,0.36182
23.16000,15.36701,193.00834,193.00835,1.37863,0.36588
23.20000,15.30964,193.34164,193.34163,1.38101,0.36452
23.24000,15.26624,193.67511,193.67511,1.38339,0.36348
23.28000,15.70750,194.00826,194.00827,1.38577,0.37399
23.32000,15.59258,194.34179,194.34180,1.38816,0.37125
23.36000,15.86135,194.67491,194.67491,1.39054,0.37765
23.40000,15.96659,195.00845,195.00845,1.39292,0.38016
23.44000,15.76543,195.34164,195.34164,1.39530,0.37537
23.48000,15.70527,195.67503,195.67503,1.39768,0.37393
23.52000,15.72054,196.00836,196.00836,1.40006,0.37430
23.56000,15.75332,196.34162,196.34161,1.40244,0.37508
23.60000,15.90028,196.67514,196.67514,1.40482,0.37858
23.64000,15.99342,197.00820,197.00819,1.40720,0.38080
23.68000,16.16832,197.34176,197.34177,1.40958,0.38496
23.72000,16.09158,197.67493,197.67493,1.41196,0.38313
23.76000,16.06401,198.00839,198.00838,1.41435,0.38248
23.80000,16.18490,198.34165,198.34164,1.41673,0.38535
23.84000,16.18583,198.67501,198.67502,1.41911,0.38538
23.88000,16.13405,199.00834,199.00835,1.42149,0.38414
23.92000,16.38085,199.34163,199.34163,1.42387,0.39002
23.96000,16.23612,199.67509,199.67509,1.42625,0.38657
24.00000,16.10443,200.00833,200.00833,1.42863,0.38344
24.04000,16.22774,200.34182,200.34181,1.43101,0.38637
24.08000,16.39556,200.67491,200.67491,1.43339,0.39037
24.12000,16.54532,201.00840,201.00839,1.43577,0.39394
24.16000,16.66583,201.34164,201.34164,1.43815,0.39681
24.20000,16.85750,201.67503,201.67502,1.44054,0.40137
24.24000,16.59896,202.00836,202.00836,1.44292,0.39521
24.28000,16.34359,202.34161,202.34161,1.44530,0.38913
24.32000,16.60138,202.67504,202.67503,1.44768,0.39527
24.36000,16.52762,203.00830,203.00830,1.45006,0.39351
24.40000,16.82937,203.34173,203.34174,1.45244,0.40070
24.44000,16.96087,203.67492,203.67493,1.45482,0.40383
24.48000,16.87314,204.00839,204.00839,1.45720,0.40174
24.52000,16.96832,204.34162,204.34163,1.45958,0.40401
24.56000,17.19072,204.67509,204.67509,1.46196,0.40930
24.60000,17.16912,205.00838,205.00838,1.46435,0.40879
24.64000,17.19557,205.34163,205.34163,1.46673,0.40942
24.68000,17.18402,205.67505,205.67505,1.46911,0.40914
24.72000,17.05009,206.00825,206.00826,1.47149,0.40595
24.76000,17.13149,206.34182,206.34181,1.47387,0.40789
24.80000,16.97093,206.67494,206.67494,1.47625,0.40407
24.84000,17.18923,207.00837,207.00838,1.47863,0.40927
24.88000,17.16558,207.34161,207.34161,1.48101,0.40870
24.92000,16.98900,207.67499,207.67499,1.48339,0.40450
24.96000,17.66440,208.00836,208.00836,1.48577,0.42058
25.00000,17.37718,208.34163,208.34164,1.48815,0.41374
25.04000,17.74337,208.67509,208.67508,1.49054,0.42246
25.08000,17.65024,209.00825,209.00826,1.49292,0.42024
25.12000,17.54165,209.34180,209.34178,1.49530,0.41766
25.16000,17.82030,209.67496,209.67496,1.49768,0.42429
25.20000,17.53960,210.00846,210.00845,1.50006,0.41761
25.24000,17.61969,210.34166,210.34167,1.50244,0.41952
25.28000,17.83930,210.67504,210.67503,1.50482,0.42475
25.32000,17.89555,211.00837,211.00836,1.50720,0.42608
25.36000,18.31986,211.34163,211.34163,1.50958,0.43619
25.40000,18.07828,211.67509,211.67509,1.51196,0.43044
25.44000,17.83967,212.00825,212.00826,1.51434,0.42475
25.48000,18.28168,212.34173,212.34172,1.51673,0.43528
25.52000,17.82104,212.67494,212.67494,1.51911,0.42431
25.56000,17.96558,213.00840,213.00839,1.52149,0.42775
25.60000,17.77019,213.34157,213.34157,1.52387,0.42310
25.64000,17.93038,213.67503,213.67503,1.52625,0.42691
25.68000,18.05089,214.00830,214.00832,1.52863,0.42978
25.72000,18.09765,214.34170,214.34171,1.53101,0.43090
25.76000,17.96503,214.67514,214.67514,1.53339,0.42774
25.80000,18.07082,215.00830,215.00830,1.53577,0.43026
25.84000,18.11273,215.34177,215.34178,1.53816,0.43126
25.88000,18.11869,215.67489,215.67490,1.54053,0.43140
25.92000,18.33346,216.00842,216.00842,1.54292,0.43651
25.96000,18.26175,216.34164,216.34166,1.54530,0.43480
26.00000,17.95888,216.67501,216.67502,1.54768,0.42759
26.04000,18.80135,217.00837,217.00836,1.55006,0.44765
26.08000,18.19748,217.34163,217.34161,1.55244,0.43327
26.12000,17.89797,217.67508,217.67508,1.55482,0.42614
26.16000,18.22133,218.00826,218.00827,1.55720,0.43384
26.20000,18.13620,218.34171,218.34171,1.55958,0.43181
26.24000,18.28596,218.67491,218.67491,1.56196,0.43538
26.28000,18.40051,219.00850,219.00850,1.56435,0.43811
26.32000,18.33737,219.34166,219.34166,1.56673,0.43660
26.36000,18.24126,219.67500,219.67500,1.56911,0.43432
26.40000,18.26957,220.00843,220.00842,1.57149,0.43499
26.44000,18.43721,220.34159,220.34158,1.57387,0.43898
26.48000,18.64433,220.67514,220.67514,1.57625,0.44391
26.52000,18.66184,221.00830,221.00830,1.57863,0.44433
26.56000,18.48023,221.34174,221.34175,1.58101,0.44001
26.60000,18.97663,221.67490,221.67491,1.58339,0.45182
26.64000,18.78496,222.00835,222.00835,1.58577,0.44726
26.68000,18.78720,222.34162,222.34161,1.58815,0.44731
26.72000,18.89169,222.67504,222.67503,1.59054,0.44980
26.76000,19.00699,223.00835,223.00835,1.59292,0.45255
26.80000,19.16308,223.34162,223.34161,1.59530,0.45626
26.84000,19.03716,223.67509,223.67509,1.59768,0.45327
26.88000,19.36741,224.00825,224.00826,1.60006,0.46113
26.92000,19.56448,224.34180,224.34180,1.60244,0.46582
26.96000,19.16364,224.67488,224.67488,1.60482,0.45628
27.00000,19.37002,225.00844,225.00844,1.60720,0.46119
27.04000,19.53579,225.34165,225.34164,1.60958,0.46514
27.08000,19.27484,225.67507,225.67506,1.61196,0.45892
27.12000,19.69561,226.00839,226.00839,1.61435,0.46894
27.16000,19.55181,226.34162,226.34163,1.61673,0.46552
27.20000,19.28639,226.67502,226.67502,1.61911,0.45920
27.24000,19.33221,227.00823,227.00822,1.62149,0.46029
27.28000,19.49500,227.34183,227.34183,1.62387,0.46417
27.32000,19.53840,227.67492,227.67491,1.62625,0.46520
27.36000,19.86194,228.00842,228.00842,1.62863,0.47290
27.40000,19.93924,228.34160,228.34160,1.63101,0.47474
27.44000,19.75391,228.67502,228.67502,1.63339,0.47033
27.48000,19.96048,229.00837,229.00836,1.63577,0.47525
27.52000,19.93366,229.34163,229.34163,1.63815,0.47461
27.56000,20.32146,229.67510,229.67511,1.64054,0.48384
27.60000,20.48407,230.00826,230.00827,1.64292,0.48772
27.64000,20.29911,230.34181,230.34181,1.64530,0.48331
27.68000,20.41254,230.67497,230.67497,1.64768,0.48601
27.72000,20.38069,231.00837,231.00838,1.65006,0.48525
27.76000,20.12979,231.34163,231.34163,1.65244,0.47928
27.80000,20.07410,231.67503,231.67503,1.65482,0.47795
27.84000,20.38982,232.00837,232.00838,1.65720,0.48547
27.88000,20.10260,232.34164,232.34163,1.65958,0.47863
27.92000,20.81860,232.67508,232.67508,1.66196,0.49568
27.96000,20.83778,233.00824,233.00824,1.66434,0.49614
28.00000,20.34716,233.34177,233.34177,1.66673,0.48446
28.04000,20.57347,233.67493,233.67493,1.66911,0.48984
28.08000,20.53306,234.00845,234.00845,1.67149,0.48888
28.12000,20.76011,234.34161,234.34161,1.67387,0.49429
28.16000,20.23447,234.67503,234.67503,1.67625,0.48177
28.20000,20.34120,235.00840,235.00841,1.67863,0.48431
28.24000,21.00859,235.34167,235.34167,1.68101,0.50020
28.28000,20.78004,235.67509,235.67509,1.68339,0.49476
28.32000,20.51666,236.00825,236.00826,1.68577,0.48849
28.36000,20.50176,236.34172,236.34172,1.68816,0.48814
28.40000,20.84486,236.67493,236.67494,1.69054,0.49631
28.44000,20.61017,237.00849,237.00848,1.69292,0.49072
28.48000,20.89478,237.34159,237.34160,1.69530,0.49749
28.52000,20.95029,237.67504,237.67503,1.69768,0.49882
28.56000,20.67741,238.00831,238.00830,1.70006,0.49232
28.60000,20.86442,238.34165,238.34164,1.70244,0.49677
28.64000,21.34237,238.67512,238.67513,1.70482,0.50815
28.68000,20.86945,239.00826,239.00826,1.70720,0.49689
28.72000,20.95494,239.34175,239.34175,1.70958,0.49893
28.76000,21.00877,239.67489,239.67488,1.71196,0.50021
28.80000,21.33958,240.00847,240.00847,1.71435,0.50809
28.84000,21.27420,240.34170,240.34171,1.71673,0.50653
28.88000,21.06167,240.67502,240.67502,1.71911,0.50147
28.92000,21.13786,241.00831,241.00832,1.72149,0.50328
28.96000,21.22279,241.34165,241.34166,1.72387,0.50530
29.00000,21.40496,241.67510,241.67509,1.72625,0.50964
29.04000,21.47350,242.00826,242.00826,1.72863,0.51127
29.08000,21.39639,242.34176,242.34177,1.73101,0.50944
29.12000,21.64841,242.67489,242.67490,1.73339,0.51544
29.16000,21.97586,243.00839,243.00839,1.73577,0.52323
29.20000,21.99616,243.34166,243.34166,1.73815,0.52372
29.24000,21.66331,243.67503,243.67503,1.74054,0.51579
29.28000,22.13325,244.00837,244.00838,1.74292,0.52698
29.32000,21.98480,244.34161,244.34161,1.74530,0.52345
29.36000,21.97381,244.67511,244.67511,1.74768,0.52319
29.40000,22.33703,245.00829,245.00830,1.75006,0.53183
29.44000,22.08110,245.34179,245.34180,1.75244,0.52574
29.48000,21.95854,245.67493,245.67493,1.75482,0.52282
29.52000,22.17069,246.00837,246.00838,1.75720,0.52787
29.56000,22.13717,246.34161,246.34161,1.75958,0.52708
29.60000,22.02671,246.67503,246.67503,1.76196,0.52445
29.64000,21.98312,247.00832,247.00833,1.76435,0.52341
29.68000,21.85516,247.34164,247.34164,1.76673,0.52036
29.72000,22.42159,247.67509,247.67509,1.76911,0.53385
29.76000,22.28506,248.00822,248.00822,1.77149,0.53060
29.80000,22.28022,248.34180,248.34180,1.77387,0.53048
29.84000,22.64455,248.67493,248.67493,1.77625,0.53916
29.88000,22.57153,249.00843,249.00844,1.77863,0.53742
29.92000,22.44767,249.34162,249.34161,1.78101,0.53447
29.96000,22.36310,249.67507,249.67506,1.78339,0.53245
30.00000,22.21763,250.00836,250.00836,1.78577,0.52899
30.04000,22.08967,250.34167,250.34167,1.78815,0.52594
30.08000,22.53745,250.67507,250.67506,1.79054,0.53661
30.12000,22.45940,251.00825,251.00826,1.79292,0.53475
30.16000,22.35807,251.34178,251.34178,1.79530,0.53234
30.20000,22.48455,251.67494,251.67494,1.79768,0.53535
30.24000,22.77605,252.00841,252.00841,1.80006,0.54229
30.28000,22.96120,252.34157,252.34157,1.80244,0.54670
30.32000,22.97778,252.67505,252.67505,1.80482,0.54709
30.36000,23.26611,253.00841,253.00841,1.80720,0.55396
30.40000,23.42146,253.34160,253.34160,1.80958,0.55765
30.44000,23.53303,253.67507,253.67508,1.81196,0.56031
30.48000,23.41494,254.00831,254.00832,1.81435,0.55750
30.52000,23.46020,254.34176,254.34177,1.81673,0.55858
30.56000,23.36744,254.67497,254.67497,1.81911,0.55637
30.60000,23.24414,255.00842,255.00842,1.82149,0.55343
30.64000,23.25326,255.34163,255.34163,1.82387,0.55365
30.68000,23.19869,255.67503,255.67502,1.82625,0.55235
30.72000,23.74612,256.00837,256.00836,1.82863,0.56538
30.76000,23.14933,256.34161,256.34161,1.83101,0.55117
30.80000,23.41401,256.67505,256.67505,1.83339,0.55748
30.84000,23.71501,257.00827,257.00827,1.83577,0.56464
30.88000,23.78486,257.34182,257.34183,1.83816,0.56631
30.92000,24.00540,257.67495,257.67496,1.84054,0.57156
30.96000,23.87557,258.00842,258.00842,1.84292,0.56847
31.00000,24.17639,258.34161,258.34161,1.84530,0.57563
31.04000,23.91692,258.67503,258.67502,1.84768,0.56945
31.08000,24.18570,259.00840,259.00839,1.85006,0.57585
31.12000,24.35148,259.34169,259.34171,1.85244,0.57980
31.16000,24.16186,259.67509,259.67508,1.85482,0.57528
31.20000,24.09182,260.00825,260.00824,1.85720,0.57361
31.24000,24.09108,260.34177,260.34177,1.85958,0.57360
31.28000,24.40978,260.67491,260.67490,1.86196,0.58119
31.32000,24.24661,261.00846,261.00845,1.86435,0.57730
31.36000,24.17229,261.34162,261.34161,1.86673,0.57553
31.40000,24.26133,261.67504,261.67505,1.86911,0.57765
31.44000,24.27176,262.00833,262.00833,1.87149,0.57790
31.48000,24.68675,262.34167,262.34167,1.87387,0.58778
31.52000,24.77244,262.67514,262.67514,1.87625,0.58982
31.56000,24.73202,263.00828,263.00827,1.87863,0.58886
31.60000,24.88568,263.34178,263.34177,1.88101,0.59252
31.64000,25.00769,263.67494,263.67493,1.88339,0.59542
31.68000,24.85849,264.00844,264.00842,1.88577,0.59187
31.72000,24.59418,264.34167,264.34167,1.88815,0.58558
31.76000,24.80093,264.67504,264.67505,1.89054,0.59050
31.80000,24.96336,265.00828,265.00827,1.89292,0.59437
31.84000,24.90822,265.34165,265.34164,1.89530,0.59305
31.88000,24.60331,265.67510,265.67511,1.89768,0.58579
31.92000,23.65597,266.00831,266.00830,1.90006,0.56324
31.96000,0.42468,266.34176,266.34177,1.90244,0.01011
31.96200,-0.05886,266.35839,266.35840,1.90256,-0.00140