File: raw_data/mechanical_tests_Instron_data/Cast_Skin_0035_3.is_tens_RawData/Specimen_RawData_1.csv
Dimension : Area,0.42000,cm^2

Time,Load,Extension,Tensile extension,Tensile strain,Tensile stress
(sec),(N),(mm),(mm),(mm/mm),(MPa)
0.00000,0.21327,0.00000,0.00000,0.00000,0.00508
0.05000,0.84098,0.09721,0.09721,0.00069,0.02002
0.10000,0.57332,0.41255,0.41255,0.00295,0.01365
0.15000,1.62739,0.88331,0.88331,0.00631,0.03875
0.20000,1.74493,1.39079,1.39079,0.00993,0.04155
0.25000,1.93212,1.91368,1.91368,0.01367,0.04600
0.30000,1.77156,2.44529,2.44529,0.01747,0.04218
0.35000,1.56090,2.92377,2.92377,0.02088,0.03716
0.40000,1.23065,3.33603,3.33603,0.02383,0.02930
0.45000,1.44057,3.75552,3.75552,0.02683,0.03430
0.50000,1.51321,4.17455,4.17455,0.02982,0.03603
0.55000,1.38879,4.59126,4.59126,0.03279,0.03307
0.60000,1.23903,5.00812,5.00812,0.03577,0.02950
0.65000,1.18464,5.42491,5.42491,0.03875,0.02821
0.70000,1.26921,5.84153,5.84153,0.04173,0.03022
0.75000,1.12113,6.25824,6.25824,0.04470,0.02669
0.80000,1.38264,6.67497,6.67497,0.04768,0.03292
0.85000,1.02669,7.09165,7.09165,0.05065,0.02445
0.90000,1.46404,7.50833,7.50833,0.05363,0.03486
0.95000,1.48993,7.92500,7.92500,0.05661,0.03547
1.00000,1.29323,8.34176,8.34176,0.05958,0.03079
1.05000,1.42138,8.75842,8.75842,0.06256,0.03384
1.10000,1.30702,9.17507,9.17507,0.06554,0.03112
1.15000,1.27405,9.59177,9.59177,0.06851,0.03033
1.20000,1.12690,10.00842,10.00842,0.07149,0.02683
1.25000,1.48788,10.42505,10.42505,0.07446,0.03543
1.30000,1.13901,10.84170,10.84170,0.07744,0.02712
1.35000,1.25300,11.25833,11.25832,0.08042,0.02983
1.40000,1.17384,11.67498,11.67498,0.08339,0.02795
1.45000,1.04420,12.09158,12.09158,0.08637,0.02486
1.50000,0.89649,12.50823,12.50823,0.08934,0.02135
1.55000,1.38730,12.92488,12.92488,0.09232,0.03303
1.60000,1.39643,13.34161,13.34161,0.09530,0.03325
1.65000,1.40462,13.75823,13.75823,0.09827,0.03344
1.70000,1.27777,14.17494,14.17494,0.10125,0.03042
1.75000,1.69054,14.59164,14.59164,0.10423,0.04025
1.80000,1.22450,15.00840,15.00840,0.10720,0.02915
1.85000,1.30832,15.42503,15.42503,0.11018,0.03115
1.90000,1.44746,15.84171,15.84171,0.11316,0.03446
1.95000,1.31372,16.25847,16.25846,0.11613,0.03128
2.00000,1.44280,16.67509,16.67509,0.11911,0.03435
2.05000,1.29677,17.09174,17.09174,0.12208,0.03088
2.10000,1.12597,17.50837,17.50837,0.12506,0.02681
2.15000,1.31615,17.92507,17.92507,0.12804,0.03134
2.20000,1.58716,18.34170,18.34170,0.13101,0.03779
2.25000,1.52588,18.75827,18.75827,0.13399,0.03633
2.30000,1.07456,19.17492,19.17492,0.13696,0.02558
2.35000,0.70408,19.59165,19.59165,0.13994,0.01676
2.40000,1.43144,20.00825,20.00825,0.14292,0.03408
2.45000,1.36886,20.42490,20.42490,0.14589,0.03259
2.50000,1.37798,20.84155,20.84155,0.14887,0.03281
2.55000,1.41077,21.25829,21.25829,0.15184,0.03359
2.60000,0.96429,21.67494,21.67494,0.15482,0.02296
2.65000,1.06506,22.09162,22.09162,0.15780,0.02536
2.70000,1.32807,22.50837,22.50837,0.16077,0.03162
2.75000,1.18539,22.92503,22.92503,0.16375,0.02822
2.80000,1.19600,23.34170,23.34170,0.16673,0.02848
2.85000,1.06357,23.75838,23.75838,0.16970,0.02532
2.90000,0.90152,24.17511,24.17511,0.17268,0.02146
2.95000,1.01961,24.59182,24.59182,0.17566,0.02428
3.00000,0.88271,25.00844,25.00844,0.17863,0.02102
3.05000,1.33347,25.42504,25.42505,0.18161,0.03175
3.10000,0.64205,25.84169,25.84169,0.18458,0.01529
3.15000,0.84434,26.25835,26.25834,0.18756,0.02010
3.20000,0.59567,26.67497,26.67497,0.19054,0.01418
3.25000,0.84378,27.09151,27.09151,0.19351,0.02009
3.30000,0.61914,27.50827,27.50827,0.19649,0.01474
3.35000,0.53346,27.92493,27.92492,0.19946,0.01270
3.40000,0.94362,28.34155,28.34155,0.20244,0.02247
3.45000,0.54743,28.75820,28.75820,0.20542,0.01303
3.50000,0.34645,29.17499,29.17499,0.20839,0.00825
3.55000,0.71935,29.59169,29.59169,0.21137,0.01713
3.60000,0.99838,30.00834,30.00834,0.21435,0.02377
3.65000,0.82217,30.42502,30.42502,0.21732,0.01958
3.70000,0.49975,30.84176,30.84175,0.22030,0.01190
3.75000,0.66049,31.25843,31.25843,0.22327,0.01573
3.80000,0.79200,31.67506,31.67506,0.22625,0.01886
3.85000,0.65621,32.09174,32.09174,0.22923,0.01562
3.90000,0.84862,32.50838,32.50838,0.23220,0.02021
3.95000,0.42394,32.92501,32.92501,0.23518,0.01009
4.00000,0.56382,33.34166,33.34166,0.23815,0.01342
4.05000,0.97211,33.75837,33.75837,0.24113,0.02315
4.10000,0.97565,34.17499,34.17499,0.24411,0.02323
4.15000,0.57202,34.59159,34.59159,0.24708,0.01362
4.20000,0.65789,35.00824,35.00825,0.25006,0.01566
4.25000,0.95330,35.42489,35.42489,0.25303,0.02270
4.30000,1.18967,35.84160,35.84160,0.25601,0.02833
4.35000,0.75810,36.25830,36.25830,0.25899,0.01805
4.40000,1.04308,36.67496,36.67496,0.26196,0.02484
4.45000,1.01756,37.09161,37.09161,0.26494,0.02423
4.50000,1.03433,37.50837,37.50837,0.26792,0.02463
4.55000,0.39842,37.92499,37.92499,0.27089,0.00949
4.60000,1.01533,38.34173,38.34172,0.27387,0.02417
4.65000,1.11312,38.75846,38.75846,0.27685,0.02650
4.70000,1.10976,39.17513,39.17513,0.27982,0.02642
4.75000,1.22674,39.59173,39.59173,0.28280,0.02921
4.80000,1.32509,40.00838,40.00838,0.28577,0.03155
4.85000,1.36942,40.42509,40.42509,0.28875,0.03261
4.90000,1.41338,40.84168,40.84169,0.29173,0.03365
4.95000,1.33179,41.25828,41.25829,0.29470,0.03171
5.00000,1.43703,41.67494,41.67494,0.29768,0.03422
5.05000,1.54413,42.09161,42.09161,0.30065,0.03677
5.10000,1.46963,42.50824,42.50824,0.30363,0.03499
5.15000,1.33105,42.92489,42.92489,0.30661,0.03169
5.20000,1.48378,43.34154,43.34154,0.30958,0.03533
5.25000,1.59629,43.75830,43.75830,0.31256,0.03801
5.30000,1.73301,44.17490,44.17490,0.31554,0.04126
5.35000,1.70097,44.59166,44.59166,0.31851,0.04050
5.40000,1.33812,45.00836,45.00837,0.32149,0.03186
5.45000,1.15149,45.42507,45.42506,0.32446,0.02742
5.50000,1.47931,45.84172,45.84171,0.32744,0.03522
5.55000,1.14795,46.25843,46.25843,0.33042,0.02733
5.60000,1.24332,46.67510,46.67510,0.33339,0.02960
5.65000,1.38786,47.09181,47.09181,0.33637,0.03304
5.70000,1.60504,47.50841,47.50840,0.33935,0.03822
5.75000,1.32676,47.92503,47.92503,0.34232,0.03159
5.80000,1.45137,48.34168,48.34169,0.34530,0.03456
5.85000,1.47894,48.75833,48.75833,0.34827,0.03521
5.90000,1.98428,49.17496,49.17496,0.35125,0.04724
5.95000,1.64602,49.59153,49.59154,0.35423,0.03919
6.00000,1.65794,50.00829,50.00829,0.35720,0.03947
6.05000,1.64788,50.42489,50.42488,0.36018,0.03924
6.10000,1.40294,50.84159,50.84159,0.36315,0.03340
6.15000,1.58083,51.25822,51.25822,0.36613,0.03764
6.20000,1.61789,51.67500,51.67500,0.36911,0.03852
6.25000,1.80323,52.09165,52.09165,0.37208,0.04293
6.30000,1.72183,52.50833,52.50834,0.37506,0.04100
6.35000,1.96248,52.92501,52.92501,0.37804,0.04673
6.40000,1.96900,53.34177,53.34177,0.38101,0.04688
6.45000,1.84495,53.75845,53.75845,0.38399,0.04393
6.50000,2.16514,54.17505,54.17505,0.38696,0.05155
6.55000,2.12472,54.59173,54.59172,0.38994,0.05059
6.60000,2.03717,55.00843,55.00843,0.39292,0.04850
6.65000,1.95969,55.42508,55.42508,0.39589,0.04666
6.70000,2.06865,55.84166,55.84166,0.39887,0.04925
6.75000,2.07964,56.25833,56.25833,0.40185,0.04952
6.80000,1.69147,56.67495,56.67495,0.40482,0.04027
6.85000,1.79540,57.09161,57.09161,0.40780,0.04275
6.90000,2.29515,57.50821,57.50821,0.41077,0.05465
6.95000,2.23294,57.92489,57.92488,0.41375,0.05317
7.00000,2.37562,58.34159,58.34159,0.41673,0.05656
7.05000,2.57567,58.75824,58.75824,0.41970,0.06133
7.10000,2.59895,59.17492,59.17492,0.42268,0.06188
7.15000,2.43094,59.59165,59.59165,0.42565,0.05788
7.20000,2.26703,60.00838,60.00838,0.42863,0.05398
7.25000,2.10684,60.42506,60.42506,0.43161,0.05016
7.30000,2.18935,60.84171,60.84171,0.43458,0.05213
7.35000,2.58554,61.25842,61.25842,0.43756,0.06156
7.40000,2.67271,61.67515,61.67515,0.44054,0.06364
7.45000,2.57343,62.09175,62.09175,0.44351,0.06127
7.50000,2.77236,62.50837,62.50837,0.44649,0.06601
7.55000,2.59914,62.92502,62.92502,0.44946,0.06188
7.60000,2.95881,63.34170,63.34171,0.45244,0.07045
7.65000,2.97092,63.75830,63.75830,0.45542,0.07074
7.70000,2.74982,64.17495,64.17495,0.45839,0.06547
7.75000,2.84892,64.59160,64.59161,0.46137,0.06783
7.80000,2.75932,65.00829,65.00829,0.46434,0.06570
7.85000,3.14973,65.42487,65.42487,0.46732,0.07499
7.90000,2.64402,65.84156,65.84156,0.47030,0.06295
7.95000,2.48887,66.25832,66.25832,0.47327,0.05926
8.00000,2.68854,66.67492,66.67492,0.47625,0.06401
8.05000,2.70456,67.09165,67.09164,0.47923,0.06439
8.10000,2.83644,67.50830,67.50830,0.48220,0.06753
8.15000,2.37133,67.92506,67.92506,0.48518,0.05646
8.20000,2.99718,68.34171,68.34171,0.48816,0.07136
8.25000,2.96310,68.75844,68.75844,0.49113,0.07055
8.30000,3.04021,69.17509,69.17509,0.49411,0.07239
8.35000,2.45366,69.59177,69.59177,0.49708,0.05842
8.40000,3.10112,70.00842,70.00842,0.50006,0.07384
8.45000,3.04915,70.42507,70.42507,0.50304,0.07260
8.50000,2.79620,70.84167,70.84167,0.50601,0.06658
8.55000,2.43839,71.25833,71.25832,0.50899,0.05806
8.60000,2.53282,71.67493,71.67493,0.51196,0.06031
8.65000,2.58815,72.09155,72.09155,0.51494,0.06162
8.70000,2.45254,72.50828,72.50828,0.51792,0.05839
8.75000,2.51159,72.92488,72.92487,0.52089,0.05980
8.80000,2.80812,73.34156,73.34157,0.52387,0.06686
8.85000,2.65185,73.75821,73.75822,0.52684,0.06314
8.90000,2.78261,74.17500,74.17500,0.52982,0.06625
8.95000,2.28006,74.59165,74.59165,0.53280,0.05429
9.00000,2.46819,75.00835,75.00835,0.53577,0.05877
9.05000,2.42256,75.42503,75.42503,0.53875,0.05768
9.10000,2.93795,75.84179,75.84179,0.54173,0.06995
9.15000,2.74219,76.25844,76.25844,0.54470,0.06529
9.20000,2.55704,76.67509,76.67509,0.54768,0.06088
9.25000,2.68426,77.09171,77.09171,0.55066,0.06391
9.30000,2.44360,77.50848,77.50848,0.55363,0.05818
9.35000,2.63117,77.92502,77.92502,0.55661,0.06265
9.40000,2.95881,78.34167,78.34167,0.55958,0.07045
9.45000,2.48943,78.75835,78.75835,0.56256,0.05927
9.50000,2.61888,79.17497,79.17496,0.56554,0.06235
9.55000,3.19947,79.59157,79.59157,0.56851,0.07618
9.60000,2.93031,80.00822,80.00822,0.57149,0.06977
9.65000,3.19332,80.42493,80.42493,0.57446,0.07603
9.70000,3.09423,80.84160,80.84161,0.57744,0.07367
9.75000,2.84780,81.25829,81.25829,0.58042,0.06780
9.80000,3.06014,81.67491,81.67490,0.58339,0.07286
9.85000,2.46987,82.09164,82.09164,0.58637,0.05881
9.90000,3.14526,82.50834,82.50834,0.58935,0.07489
9.95000,3.18456,82.92508,82.92508,0.59232,0.07582
10.00000,2.91299,83.34168,83.34168,0.59530,0.06936
10.05000,2.55536,83.75843,83.75842,0.59827,0.06084
10.10000,2.93870,84.17511,84.17512,0.60125,0.06997
10.15000,2.98116,84.59173,84.59173,0.60423,0.07098
10.20000,3.20729,85.00839,85.00838,0.60720,0.07636
10.25000,2.83904,85.42506,85.42506,0.61018,0.06760
10.30000,3.14917,85.84172,85.84172,0.61316,0.07498
10.35000,2.96012,86.25832,86.25832,0.61613,0.07048
10.40000,2.89120,86.67492,86.67492,0.61911,0.06884
10.45000,2.68519,87.09162,87.09162,0.62208,0.06393
10.50000,2.87909,87.50827,87.50828,0.62506,0.06855
10.55000,3.33805,87.92484,87.92484,0.62803,0.07948
10.60000,3.28980,88.34155,88.34155,0.63101,0.07833
10.65000,3.20058,88.75826,88.75826,0.63399,0.07620
10.70000,3.10242,89.17496,89.17496,0.63696,0.07387
10.75000,3.68170,89.59163,89.59164,0.63994,0.08766
10.80000,3.79309,90.00836,90.00835,0.64292,0.09031
10.85000,3.92981,90.42510,90.42510,0.64589,0.09357
10.90000,3.94024,90.84173,90.84172,0.64887,0.09382
10.95000,4.15277,91.25841,91.25841,0.65185,0.09888
11.00000,4.01959,91.67510,91.67510,0.65482,0.09570
11.05000,4.04585,92.09176,92.09175,0.65780,0.09633
11.10000,4.25130,92.50839,92.50839,0.66077,0.10122
11.15000,4.69033,92.92501,92.92501,0.66375,0.11167
11.20000,4.34443,93.34166,93.34167,0.66673,0.10344
11.25000,4.51580,93.75834,93.75834,0.66970,0.10752
11.30000,4.30271,94.17494,94.17493,0.67268,0.10245
11.35000,4.67524,94.59159,94.59159,0.67565,0.11132
11.40000,4.25093,95.00821,95.00820,0.67863,0.10121
11.45000,4.54113,95.42495,95.42495,0.68161,0.10812
11.50000,4.65848,95.84160,95.84161,0.68458,0.11092
11.55000,4.08404,96.25822,96.25822,0.68756,0.09724
11.60000,4.53889,96.67493,96.67493,0.69054,0.10807
11.65000,4.71007,97.09166,97.09165,0.69351,0.11214
11.70000,4.99152,97.50834,97.50834,0.69649,0.11885
11.75000,4.70579,97.92499,97.92499,0.69946,0.11204
11.80000,4.70523,98.34176,98.34176,0.70244,0.11203
11.85000,4.45396,98.75843,98.75843,0.70542,0.10605
11.90000,4.86951,99.17508,99.17509,0.70839,0.11594
11.95000,4.57466,99.59173,99.59174,0.71137,0.10892
12.00000,4.55361,100.00850,100.00849,0.71435,0.10842
12.05000,4.63706,100.42503,100.42503,0.71732,0.11041
12.10000,4.66704,100.84172,100.84172,0.72030,0.11112
12.15000,4.44204,101.25828,101.25829,0.72327,0.10576
12.20000,4.89540,101.67499,101.67500,0.72625,0.11656
12.25000,4.35263,102.09156,102.09156,0.72923,0.10363
12.30000,4.71305,102.50824,102.50824,0.73220,0.11222
12.35000,4.58304,102.92489,102.92489,0.73518,0.10912
12.40000,4.95818,103.34154,103.34153,0.73815,0.11805
12.45000,4.60092,103.75825,103.75825,0.74113,0.10955
12.50000,4.62551,104.17495,104.17495,0.74411,0.11013
12.55000,4.51393,104.59169,104.59169,0.74708,0.10747
12.60000,4.86691,105.00836,105.00836,0.75006,0.11588
12.65000,4.92614,105.42507,105.42506,0.75304,0.11729
12.70000,5.02095,105.84172,105.84172,0.75601,0.11955
12.75000,4.86858,106.25848,106.25848,0.75899,0.11592
12.80000,4.65252,106.67510,106.67511,0.76197,0.11077
12.85000,4.78234,107.09175,107.09175,0.76494,0.11387
12.90000,4.98034,107.50835,107.50835,0.76792,0.11858
12.95000,4.56944,107.92503,107.92503,0.77089,0.10880
13.00000,4.65680,108.34168,108.34168,0.77387,0.11088
13.05000,4.78756,108.75830,108.75830,0.77685,0.11399
13.10000,4.31258,109.17490,109.17490,0.77982,0.10268
13.15000,4.21982,109.59163,109.59164,0.78280,0.10047
13.20000,4.40925,110.00829,110.00829,0.78577,0.10498
13.25000,4.73801,110.42491,110.42491,0.78875,0.11281
13.30000,4.65829,110.84160,110.84160,0.79173,0.11091
13.35000,4.62513,111.25830,111.25829,0.79470,0.11012
13.40000,4.66779,111.67498,111.67498,0.79768,0.11114
13.45000,4.66071,112.09157,112.09158,0.80065,0.11097
13.50000,4.77415,112.50839,112.50839,0.80363,0.11367
13.55000,4.57447,112.92506,112.92506,0.80661,0.10892
13.60000,4.67990,113.34173,113.34174,0.80958,0.11143
13.65000,4.57559,113.75839,113.75839,0.81256,0.10894
13.70000,4.77489,114.17510,114.17510,0.81554,0.11369
13.75000,4.50164,114.59180,114.59180,0.81851,0.10718
13.80000,5.02262,115.00846,115.00846,0.82149,0.11959
13.85000,5.09322,115.42503,115.42503,0.82446,0.12127
13.90000,4.71305,115.84171,115.84171,0.82744,0.11222
13.95000,4.61526,116.25833,116.25833,0.83042,0.10989
14.00000,4.94290,116.67495,116.67495,0.83339,0.11769
14.05000,4.42881,117.09158,117.09158,0.83637,0.10545
14.10000,4.32730,117.50823,117.50823,0.83934,0.10303
14.15000,4.68455,117.92493,117.92493,0.84232,0.11154
14.20000,4.62830,118.34154,118.34154,0.84530,0.11020
14.25000,4.50648,118.75823,118.75823,0.84827,0.10730
14.30000,4.95557,119.17497,119.17497,0.85125,0.11799
14.35000,5.00809,119.59171,119.59171,0.85423,0.11924
14.40000,4.56590,120.00835,120.00835,0.85720,0.10871
14.45000,4.10601,120.42501,120.42501,0.86018,0.09776
14.50000,4.42266,120.84179,120.84179,0.86316,0.10530
14.55000,4.49177,121.25847,121.25848,0.86613,0.10695
14.60000,4.31035,121.67509,121.67509,0.86911,0.10263
14.65000,4.59477,122.09173,122.09173,0.87208,0.10940
14.70000,4.74770,122.50845,122.50845,0.87506,0.11304
14.75000,4.39454,122.92504,122.92504,0.87804,0.10463
14.80000,4.41503,123.34168,123.34167,0.88101,0.10512
14.85000,4.59626,123.75828,123.75829,0.88399,0.10943
14.90000,4.48804,124.17503,124.17503,0.88696,0.10686
14.95000,5.01350,124.59157,124.59158,0.88994,0.11937
15.00000,4.61880,125.00826,125.00826,0.89292,0.10997
15.05000,4.66798,125.42492,125.42492,0.89589,0.11114
15.10000,4.67114,125.84160,125.84161,0.89887,0.11122
15.15000,4.34518,126.25826,126.25826,0.90184,0.10346
15.20000,4.63799,126.67495,126.67495,0.90482,0.11043
15.25000,4.45321,127.09162,127.09162,0.90780,0.10603
15.30000,4.52902,127.50838,127.50838,0.91077,0.10783
15.35000,4.93899,127.92503,127.92503,0.91375,0.11759
15.40000,4.64879,128.34171,128.34171,0.91673,0.11069
15.45000,4.96358,128.75842,128.75842,0.91970,0.11818
15.50000,4.61806,129.17508,129.17508,0.92268,0.10995
15.55000,4.59384,129.59179,129.59180,0.92566,0.10938
15.60000,4.41130,130.00843,130.00842,0.92863,0.10503
15.65000,4.94141,130.42507,130.42506,0.93161,0.11765
15.70000,4.58546,130.84169,130.84169,0.93458,0.10918
15.75000,4.23156,131.25832,131.25833,0.93756,0.10075
15.80000,4.19207,131.67492,131.67491,0.94054,0.09981
15.85000,5.01573,132.09163,132.09163,0.94351,0.11942
15.90000,4.64264,132.50825,132.50826,0.94649,0.11054
15.95000,4.56609,132.92491,132.92491,0.94946,0.10872
16.00000,4.55696,133.34150,133.34151,0.95244,0.10850
16.05000,4.45712,133.75828,133.75827,0.95542,0.10612
16.10000,4.65270,134.17496,134.17496,0.95839,0.11078
16.15000,4.84735,134.59165,134.59164,0.96137,0.11541
16.20000,4.60520,135.00837,135.00838,0.96435,0.10965
16.25000,4.80898,135.42508,135.42508,0.96732,0.11450
16.30000,4.60967,135.84177,135.84177,0.97030,0.10975
16.35000,4.75906,136.25841,136.25841,0.97327,0.11331
16.40000,4.83356,136.67511,136.67511,0.97625,0.11508
16.45000,4.76949,137.09176,137.09175,0.97923,0.11356
16.50000,4.78923,137.50840,137.50841,0.98220,0.11403
16.55000,4.70281,137.92502,137.92502,0.98518,0.11197
16.60000,4.84921,138.34172,138.34172,0.98816,0.11546
16.65000,4.84865,138.75833,138.75833,0.99113,0.11544
16.70000,4.84120,139.17497,139.17497,0.99411,0.11527
16.75000,4.67952,139.59159,139.59160,0.99708,0.11142
16.80000,4.83878,140.00830,140.00829,1.00006,0.11521
16.85000,4.61005,140.42492,140.42493,1.00304,0.10976
16.90000,4.72274,140.84158,140.84158,1.00601,0.11245
16.95000,4.72162,141.25827,141.25829,1.00899,0.11242
17.00000,4.55640,141.67495,141.67496,1.01196,0.10849
17.05000,4.68921,142.09166,142.09167,1.01494,0.11165
17.10000,5.08707,142.50835,142.50835,1.01792,0.12112
17.15000,4.68958,142.92501,142.92500,1.02089,0.11166
17.20000,4.51468,143.34173,143.34174,1.02387,0.10749
17.25000,4.84604,143.75847,143.75847,1.02685,0.11538
17.30000,4.57373,144.17511,144.17511,1.02982,0.10890
17.35000,4.63706,144.59177,144.59177,1.03280,0.11041
17.40000,4.72497,145.00847,145.00848,1.03577,0.11250
17.45000,4.86672,145.42511,145.42509,1.03875,0.11587
17.50000,4.92483,145.84163,145.84161,1.04173,0.11726
17.55000,5.31059,146.25832,146.25832,1.04470,0.12644
17.60000,4.70690,146.67503,146.67502,1.04768,0.11207
17.65000,4.96171,147.09159,147.09161,1.05065,0.11814
17.70000,4.96749,147.50820,147.50819,1.05363,0.11827
17.75000,5.03827,147.92487,147.92487,1.05661,0.11996
17.80000,4.82816,148.34161,148.34161,1.05958,0.11496
17.85000,4.64171,148.75828,148.75829,1.06256,0.11052
17.90000,5.34337,149.17498,149.17497,1.06554,0.12722
17.95000,5.24111,149.59166,149.59166,1.06851,0.12479
18.00000,5.16642,150.00841,150.00841,1.07149,0.12301
18.05000,5.25638,150.42502,150.42502,1.07446,0.12515
18.10000,5.27631,150.84174,150.84174,1.07744,0.12563
18.15000,5.17853,151.25843,151.25842,1.08042,0.12330
18.20000,5.18616,151.67514,151.67513,1.08339,0.12348
18.25000,5.02691,152.09173,152.09174,1.08637,0.11969
18.30000,5.35920,152.50838,152.50838,1.08935,0.12760
18.35000,5.28358,152.92506,152.92506,1.09232,0.12580
18.40000,5.31785,153.34172,153.34172,1.09530,0.12662
18.45000,5.05820,153.75834,153.75835,1.09827,0.12043
18.50000,5.19026,154.17491,154.17491,1.10125,0.12358
18.55000,5.10700,154.59165,154.59166,1.10423,0.12160
18.60000,5.12283,155.00829,155.00830,1.10720,0.12197
18.65000,5.53168,155.42494,155.42494,1.11018,0.13171
18.70000,5.38193,155.84152,155.84152,1.11315,0.12814
18.75000,4.98779,156.25831,156.25832,1.11613,0.11876
18.80000,5.19473,156.67496,156.67494,1.11911,0.12368
18.85000,4.88907,157.09165,157.09164,1.12208,0.11641
18.90000,5.24800,157.50831,157.50832,1.12506,0.12495
18.95000,5.49275,157.92507,157.92508,1.12804,0.13078
19.00000,5.29978,158.34173,158.34175,1.13101,0.12619
19.05000,5.26085,158.75842,158.75842,1.13399,0.12526
19.10000,5.37597,159.17510,159.17511,1.13697,0.12800
19.15000,5.56093,159.59181,159.59181,1.13994,0.13240
19.20000,5.16232,160.00843,160.00844,1.14292,0.12291
19.25000,5.70808,160.42503,160.42503,1.14589,0.13591
19.30000,5.64829,160.84171,160.84171,1.14887,0.13448
19.35000,5.68144,161.25836,161.25836,1.15185,0.13527
19.40000,5.66021,161.67497,161.67497,1.15482,0.13477
19.45000,5.47767,162.09156,162.09155,1.15780,0.13042
19.50000,5.49294,162.50828,162.50827,1.16077,0.13078
19.55000,5.79618,162.92484,162.92484,1.16375,0.13800
19.60000,5.86957,163.34161,163.34160,1.16673,0.13975
19.65000,5.73844,163.75825,163.75826,1.16970,0.13663
19.70000,5.75408,164.17498,164.17499,1.17268,0.13700
19.75000,5.52777,164.59167,164.59167,1.17565,0.13161
19.80000,5.62649,165.00835,165.00835,1.17863,0.13396
19.85000,5.65555,165.42504,165.42502,1.18161,0.13466
19.90000,5.58384,165.84180,165.84180,1.18458,0.13295
19.95000,5.57825,166.25845,166.25845,1.18756,0.13282
20.00000,5.63040,166.67507,166.67505,1.19054,0.13406
20.05000,5.43576,167.09170,167.09169,1.19351,0.12942
20.10000,5.94947,167.50844,167.50844,1.19649,0.14165
20.15000,6.19199,167.92508,167.92508,1.19946,0.14743
20.20000,5.80437,168.34162,168.34163,1.20244,0.13820
20.25000,5.26197,168.75833,168.75833,1.20542,0.12529
20.30000,5.83660,169.17499,169.17500,1.20839,0.13897
20.35000,5.83977,169.59164,169.59163,1.21137,0.13904
20.40000,6.08098,170.00826,170.00826,1.21434,0.14479
20.45000,6.12400,170.42494,170.42494,1.21732,0.14581
20.50000,6.05639,170.84164,170.84164,1.22030,0.14420
20.55000,5.86193,171.25825,171.25826,1.22327,0.13957
20.60000,6.17169,171.67495,171.67494,1.22625,0.14694
20.65000,6.20019,172.09166,172.09166,1.22923,0.14762
20.70000,6.29574,172.50838,172.50838,1.23220,0.14990
20.75000,6.31344,172.92500,172.92500,1.23518,0.15032
20.80000,6.20969,173.34169,173.34169,1.23815,0.14785
20.85000,6.21360,173.75842,173.75841,1.24113,0.14794
20.90000,6.02826,174.17519,174.17519,1.24411,0.14353
20.95000,6.49560,174.59177,174.59177,1.24708,0.15466
21.00000,6.48964,175.00845,175.00844,1.25006,0.15452
21.05000,6.65057,175.42507,175.42506,1.25304,0.15835
21.10000,6.49691,175.84173,175.84174,1.25601,0.15469
21.15000,6.41886,176.25834,176.25833,1.25899,0.15283
21.20000,6.61388,176.67493,176.67494,1.26196,0.15747
21.25000,6.61928,177.09160,177.09160,1.26494,0.15760
21.30000,6.73607,177.50826,177.50827,1.26792,0.16038
21.35000,6.62133,177.92485,177.92485,1.27089,0.15765
21.40000,6.38086,178.34153,178.34152,1.27387,0.15193
21.45000,6.43861,178.75832,178.75832,1.27685,0.15330
21.50000,6.36168,179.17500,179.17500,1.27982,0.15147
21.55000,6.60662,179.59167,179.59167,1.28280,0.15730
21.60000,6.74166,180.00833,180.00833,1.28577,0.16052
21.65000,6.58911,180.42515,180.42514,1.28875,0.15688
21.70000,6.56676,180.84177,180.84177,1.29173,0.15635
21.75000,6.66715,181.25841,181.25839,1.29470,0.15874
21.80000,6.51274,181.67507,181.67506,1.29768,0.15507
21.85000,6.65989,182.09178,182.09178,1.30066,0.15857
21.90000,6.62245,182.50838,182.50839,1.30363,0.15768
21.95000,6.83591,182.92502,182.92500,1.30661,0.16276
22.00000,6.75973,183.34168,183.34167,1.30958,0.16095
22.05000,6.88937,183.75840,183.75842,1.31256,0.16403
22.10000,6.96518,184.17495,184.17494,1.31554,0.16584
22.15000,6.73756,184.59163,184.59163,1.31851,0.16042
22.20000,6.95549,185.00832,185.00833,1.32149,0.16561
22.25000,6.85733,185.42494,185.42494,1.32446,0.16327
22.30000,7.22576,185.84161,185.84161,1.32744,0.17204
22.35000,7.01491,186.25820,186.25819,1.33042,0.16702
22.40000,7.33454,186.67496,186.67496,1.33339,0.17463
22.45000,7.07079,187.09164,187.09163,1.33637,0.16835
22.50000,6.87838,187.50836,187.50836,1.33935,0.16377
22.55000,7.47070,187.92503,187.92503,1.34232,0.17787
22.60000,7.33510,188.34173,188.34174,1.34530,0.17465
22.65000,7.48541,188.75847,188.75845,1.34827,0.17822
22.70000,7.53086,189.17513,189.17513,1.35125,0.17931
22.75000,7.27046,189.59174,189.59175,1.35423,0.17311
22.80000,7.43661,190.00847,190.00847,1.35720,0.17706
22.85000,7.62846,190.42508,190.42508,1.36018,0.18163
22.90000,7.22874,190.84167,190.84167,1.36315,0.17211
22.95000,7.30567,191.25831,191.25832,1.36613,0.17394
23.00000,6.97169,191.67497,191.67499,1.36911,0.16599
23.05000,7.48672,192.09159,192.09160,1.37208,0.17826
23.10000,7.21309,192.50823,192.50822,1.37506,0.17174
23.15000,7.71228,192.92490,192.92490,1.37803,0.18363
23.20000,7.41258,193.34161,193.34161,1.38101,0.17649
23.25000,7.58152,193.75829,193.75830,1.38399,0.18051
23.30000,7.96150,194.17494,194.17494,1.38696,0.18956
23.35000,7.91773,194.59166,194.59166,1.38994,0.18852
23.40000,7.91624,195.00840,195.00841,1.39292,0.18848
23.45000,7.88402,195.42509,195.42508,1.39589,0.18771
23.50000,7.78884,195.84174,195.84175,1.39887,0.18545
23.55000,7.79107,196.25847,196.25847,1.40185,0.18550
23.60000,7.66851,196.67509,196.67509,1.40482,0.18258
23.65000,7.61636,197.09173,197.09172,1.40780,0.18134
23.70000,7.94493,197.50842,197.50844,1.41077,0.18916
23.75000,8.12579,197.92506,197.92505,1.41375,0.19347
23.80000,8.03377,198.34170,198.34169,1.41673,0.19128
23.85000,7.86837,198.75832,198.75832,1.41970,0.18734
23.90000,8.22600,199.17496,199.17496,1.42268,0.19586
23.95000,8.16416,199.59162,199.59163,1.42565,0.19438
24.00000,8.34279,200.00829,200.00830,1.42863,0.19864
24.05000,7.96132,200.42490,200.42490,1.43161,0.18956
24.10000,8.45362,200.84157,200.84158,1.43458,0.20128
24.15000,8.12523,201.25828,201.25829,1.43756,0.19346
24.20000,7.95759,201.67497,201.67499,1.44054,0.18947
24.25000,8.22730,202.09161,202.09161,1.44351,0.19589
24.30000,8.00844,202.50834,202.50833,1.44649,0.19068
24.35000,8.38842,202.92507,202.92508,1.44946,0.19972
24.40000,8.41189,203.34173,203.34174,1.45244,0.20028
24.45000,8.43238,203.75842,203.75842,1.45542,0.20077
24.50000,8.16043,204.17510,204.17511,1.45839,0.19430
24.55000,8.38060,204.59181,204.59181,1.46137,0.19954
24.60000,8.23569,205.00841,205.00841,1.46435,0.19609
24.65000,8.64025,205.42503,205.42503,1.46732,0.20572
24.70000,8.69725,205.84171,205.84171,1.47030,0.20708
24.75000,8.52011,206.25837,206.25838,1.47327,0.20286
24.80000,9.07313,206.67491,206.67491,1.47625,0.21603
24.85000,8.80025,207.09160,207.09161,1.47923,0.20953
24.90000,8.70563,207.50824,207.50824,1.48220,0.20728
24.95000,8.80454,207.92493,207.92494,1.48518,0.20963
25.00000,8.96193,208.34157,208.34157,1.48815,0.21338
25.05000,8.88053,208.75826,208.75827,1.49113,0.21144
25.10000,8.93157,209.17501,209.17500,1.49411,0.21266
25.15000,8.82819,209.59167,209.59167,1.49708,0.21020
25.20000,9.19793,210.00839,210.00839,1.50006,0.21900
25.25000,9.14093,210.42504,210.42503,1.50304,0.21764
25.30000,8.65925,210.84175,210.84174,1.50601,0.20617
25.35000,9.03364,211.25843,211.25844,1.50899,0.21509
25.40000,8.69408,211.67511,211.67511,1.51197,0.20700
25.45000,8.86861,212.09174,212.09174,1.51494,0.21116
25.50000,8.78945,212.50846,212.50847,1.51792,0.20927
25.55000,9.13925,212.92504,212.92505,1.52089,0.21760
25.60000,9.33539,213.34170,213.34171,1.52387,0.22227
25.65000,9.48552,213.75826,213.75827,1.52684,0.22585
25.70000,8.74773,214.17505,214.17505,1.52982,0.20828
25.75000,9.04091,214.59165,214.59166,1.53280,0.21526
25.80000,9.07071,215.00827,215.00827,1.53577,0.21597
25.85000,9.69134,215.42489,215.42490,1.53875,0.23075
25.90000,9.43020,215.84160,215.84160,1.54173,0.22453
25.95000,8.98428,216.25829,216.25829,1.54470,0.21391
26.00000,9.08766,216.67493,216.67493,1.54768,0.21637
26.05000,9.53656,217.09166,217.09166,1.55065,0.22706
26.10000,9.26293,217.50837,217.50836,1.55363,0.22055
26.15000,9.38885,217.92504,217.92505,1.55661,0.22354
26.20000,9.16962,218.34169,218.34169,1.55958,0.21832
26.25000,9.53376,218.75850,218.75850,1.56256,0.22699
26.30000,9.83011,219.17511,219.17511,1.56554,0.23405
26.35000,9.75877,219.59177,219.59177,1.56851,0.23235
26.40000,9.55146,220.00843,220.00842,1.57149,0.22742
26.45000,9.75728,220.42511,220.42511,1.57447,0.23232
26.50000,9.75113,220.84172,220.84172,1.57744,0.23217
26.55000,9.94876,221.25835,221.25835,1.58042,0.23688
26.60000,9.83160,221.67493,221.67493,1.58339,0.23409
26.65000,9.66154,222.09159,222.09158,1.58637,0.23004
26.70000,9.83234,222.50827,222.50827,1.58934,0.23410
26.75000,9.77907,222.92491,222.92491,1.59232,0.23284
26.80000,9.90126,223.34159,223.34160,1.59530,0.23574
26.85000,10.08529,223.75828,223.75827,1.59827,0.24013
26.90000,9.93442,224.17501,224.17502,1.60125,0.23653
26.95000,10.06760,224.59165,224.59164,1.60423,0.23970
27.00000,10.19798,225.00838,225.00838,1.60720,0.24281
27.05000,10.10485,225.42507,225.42506,1.61018,0.24059
27.10000,9.98396,225.84178,225.84178,1.61316,0.23771
27.15000,10.33060,226.25839,226.25839,1.61613,0.24597
27.20000,9.73884,226.67507,226.67506,1.61911,0.23188
27.25000,9.97800,227.09181,227.09181,1.62208,0.23757
27.30000,10.42262,227.50844,227.50844,1.62506,0.24816
27.35000,10.32893,227.92502,227.92502,1.62804,0.24593
27.40000,10.54928,228.34171,228.34171,1.63101,0.25117
27.45000,10.44367,228.75836,228.75836,1.63399,0.24866
27.50000,10.72288,229.17495,229.17494,1.63696,0.25531
27.55000,10.56213,229.59160,229.59160,1.63994,0.25148
27.60000,11.26938,230.00829,230.00829,1.64292,0.26832
27.65000,10.74355,230.42495,230.42494,1.64589,0.25580
27.70000,10.60236,230.84150,230.84151,1.64887,0.25244
27.75000,10.57573,231.25827,231.25827,1.65184,0.25180
27.80000,10.44497,231.67498,231.67497,1.65482,0.24869
27.85000,10.55840,232.09164,232.09163,1.65780,0.25139
27.90000,11.13620,232.50832,232.50832,1.66077,0.26515
27.95000,11.23771,232.92503,232.92503,1.66375,0.26756
28.00000,11.09578,233.34177,233.34177,1.66673,0.26419
28.05000,11.29787,233.75848,233.75848,1.66970,0.26900
28.10000,11.00004,234.17509,234.17508,1.67268,0.26191
28.15000,11.27683,234.59174,234.59175,1.67566,0.26850
28.20000,11.11981,235.00846,235.00845,1.67863,0.26476
28.25000,11.03897,235.42509,235.42509,1.68161,0.26283
28.30000,11.20139,235.84170,235.84169,1.68458,0.26670
28.35000,10.86760,236.25828,236.25827,1.68756,0.25875
28.40000,10.93540,236.67504,236.67503,1.69054,0.26037
28.45000,11.42323,237.09159,237.09160,1.69351,0.27198
28.50000,11.17196,237.50825,237.50826,1.69649,0.26600
28.55000,11.32768,237.92489,237.92488,1.69946,0.26971
28.60000,11.50575,238.34162,238.34163,1.70244,0.27395
28.65000,12.02226,238.75828,238.75829,1.70542,0.28624
28.70000,11.51059,239.17491,239.17491,1.70839,0.27406
28.75000,11.57019,239.59168,239.59167,1.71137,0.27548
28.80000,12.01257,240.00844,240.00844,1.71435,0.28601
28.85000,11.80023,240.42507,240.42508,1.71732,0.28096
28.90000,11.97904,240.84171,240.84171,1.72030,0.28522
28.95000,11.81830,241.25847,241.25847,1.72327,0.28139
29.00000,11.65420,241.67510,241.67509,1.72625,0.27748
29.05000,11.99227,242.09176,242.09177,1.72923,0.28553
29.10000,12.28936,242.50839,242.50839,1.73220,0.29260
29.15000,12.19772,242.92510,242.92511,1.73518,0.29042
29.20000,12.14314,243.34168,243.34169,1.73815,0.28912
29.25000,12.05355,243.75834,243.75835,1.74113,0.28699
29.30000,12.37597,244.17495,244.17496,1.74411,0.29467
29.35000,12.49425,244.59166,244.59166,1.74708,0.29748
29.40000,12.11073,245.00829,245.00830,1.75006,0.28835
29.45000,12.45830,245.42493,245.42493,1.75304,0.29663
29.50000,11.98575,245.84156,245.84155,1.75601,0.28537
29.55000,11.74100,246.25830,246.25830,1.75899,0.27955
29.60000,12.34263,246.67495,246.67496,1.76196,0.29387
29.65000,12.40447,247.09164,247.09164,1.76494,0.29534
29.70000,12.39441,247.50832,247.50833,1.76792,0.29511
29.75000,13.03367,247.92506,247.92506,1.77089,0.31033
29.80000,12.66934,248.34180,248.34180,1.77387,0.30165
29.85000,12.96047,248.75846,248.75845,1.77685,0.30858
29.90000,12.59018,249.17509,249.17509,1.77982,0.29977
29.95000,12.79656,249.59180,249.59180,1.78280,0.30468
30.00000,12.98729,250.00843,250.00844,1.78577,0.30922
30.05000,13.00406,250.42504,250.42503,1.78875,0.30962
30.10000,12.53225,250.84170,250.84171,1.79173,0.29839
30.15000,12.74813,251.25836,251.25836,1.79470,0.30353
30.20000,12.39702,251.67497,251.67497,1.79768,0.29517
30.25000,12.99419,252.09155,252.09155,1.80065,0.30939
30.30000,12.78259,252.50828,252.50829,1.80363,0.30435
30.35000,13.02324,252.92494,252.92494,1.80661,0.31008
30.40000,13.79326,253.34157,253.34157,1.80958,0.32841
30.45000,13.52485,253.75829,253.75829,1.81256,0.32202
30.50000,13.47940,254.17500,254.17500,1.81554,0.32094
30.55000,13.55931,254.59168,254.59167,1.81851,0.32284
30.60000,12.89193,255.00831,255.00832,1.82149,0.30695
30.65000,13.41924,255.42508,255.42508,1.82446,0.31951
30.70000,13.23316,255.84174,255.84174,1.82744,0.31508
30.75000,12.73416,256.25837,256.25836,1.83042,0.30319
30.80000,13.26185,256.67511,256.67511,1.83339,0.31576
30.85000,13.48797,257.09179,257.09180,1.83637,0.32114
30.90000,13.69752,257.50840,257.50839,1.83935,0.32613
30.95000,13.83331,257.92508,257.92508,1.84232,0.32936
31.00000,14.08402,258.34169,258.34167,1.84530,0.33533
31.05000,14.17678,258.75835,258.75836,1.84827,0.33754
31.10000,14.13245,259.17501,259.17502,1.85125,0.33649
31.15000,14.10414,259.59159,259.59158,1.85423,0.33581
31.20000,13.90371,260.00830,260.00830,1.85720,0.33104
31.25000,14.07042,260.42493,260.42493,1.86018,0.33501
31.30000,14.33268,260.84159,260.84158,1.86315,0.34125
31.35000,14.14064,261.25825,261.25824,1.86613,0.33668
31.40000,13.88025,261.67493,261.67493,1.86911,0.33048
31.45000,14.21031,262.09167,262.09167,1.87208,0.33834
31.50000,14.63890,262.50841,262.50839,1.87506,0.34855
31.55000,14.36584,262.92504,262.92505,1.87804,0.34204
31.60000,14.10041,263.34172,263.34174,1.88101,0.33572
31.65000,14.46567,263.75849,263.75848,1.88399,0.34442
31.70000,14.51094,264.17515,264.17514,1.88697,0.34550
31.75000,14.48374,264.59170,264.59171,1.88994,0.34485
31.80000,14.62344,265.00841,265.00842,1.89292,0.34818
31.85000,14.43978,265.42512,265.42511,1.89589,0.34380
31.90000,14.73837,265.84170,265.84171,1.89887,0.35091
31.95000,14.51429,266.25828,266.25827,1.90184,0.34558
32.00000,14.78642,266.67497,266.67496,1.90482,0.35206
32.05000,14.43401,267.09168,267.09167,1.90780,0.34367
32.10000,14.88496,267.50829,267.50830,1.91077,0.35440
32.15000,14.70577,267.92492,267.92493,1.91375,0.35014
32.20000,15.31690,268.34155,268.34155,1.91673,0.36469
32.25000,15.40389,268.75832,268.75830,1.91970,0.36676
32.30000,15.49721,269.17495,269.17496,1.92268,0.36898
32.35000,15.40799,269.59171,269.59171,1.92566,0.36686
32.40000,15.42382,270.00834,270.00833,1.92863,0.36723
32.45000,15.13995,270.42506,270.42505,1.93161,0.36048
32.50000,15.35174,270.84177,270.84177,1.93458,0.36552
32.55000,15.64827,271.25845,271.25845,1.93756,0.37258
32.60000,15.25395,271.67511,271.67511,1.94054,0.36319
32.65000,15.57674,272.09182,272.09183,1.94351,0.37087
32.70000,15.74308,272.50843,272.50842,1.94649,0.37484
32.75000,15.82503,272.92501,272.92502,1.94946,0.37679
32.80000,16.01260,273.34167,273.34167,1.95244,0.38125
32.85000,16.11542,273.75835,273.75836,1.95542,0.38370
32.90000,15.81479,274.17501,274.17502,1.95839,0.37654
32.95000,15.98243,274.59154,274.59155,1.96137,0.38053
33.00000,15.90308,275.00830,275.00830,1.96434,0.37864
33.05000,15.51472,275.42491,275.42490,1.96732,0.36940
33.10000,15.84906,275.84159,275.84158,1.97030,0.37736
33.15000,15.81386,276.25825,276.25824,1.97327,0.37652
33.20000,15.97218,276.67502,276.67502,1.97625,0.38029
33.25000,16.22513,277.09167,277.09167,1.97923,0.38631
33.30000,16.41903,277.50833,277.50833,1.98220,0.39093
33.35000,16.55649,277.92502,277.92502,1.98518,0.39420
33.40000,16.48236,278.34178,278.34177,1.98816,0.39244
33.45000,16.72711,278.75844,278.75845,1.99113,0.39826
33.50000,16.79268,279.17513,279.17511,1.99411,0.39983
33.55000,16.57065,279.59173,279.59174,1.99708,0.39454
33.60000,16.42611,280.00844,280.00845,2.00006,0.39110
33.65000,16.63323,280.42510,280.42511,2.00304,0.39603
33.70000,16.21135,280.84168,280.84167,2.00601,0.38598
33.75000,16.42331,281.25837,281.25836,2.00899,0.39103
33.80000,16.78299,281.67497,281.67499,2.01196,0.39960
33.85000,16.43263,282.09163,282.09164,2.01494,0.39125
33.90000,17.04432,282.50824,282.50824,2.01792,0.40582
33.95000,16.99049,282.92490,282.92490,2.02089,0.40454
34.00000,17.26374,283.34161,283.34161,2.02387,0.41104
34.05000,17.13131,283.75827,283.75827,2.02684,0.40789
34.10000,16.67235,284.17495,284.17496,2.02982,0.39696
34.15000,16.77983,284.59169,284.59167,2.03280,0.39952
34.20000,16.55873,285.00837,285.00836,2.03577,0.39426
34.25000,16.91636,285.42509,285.42508,2.03875,0.40277
34.30000,16.69154,285.84174,285.84174,2.04173,0.39742
34.35000,17.07785,286.25843,286.25842,2.04470,0.40662
34.40000,17.30882,286.67517,286.67514,2.04768,0.41211
34.45000,17.37624,287.09172,287.09174,2.05066,0.41372
34.50000,17.66812,287.50843,287.50839,2.05363,0.42067
34.55000,17.77448,287.92504,287.92505,2.05661,0.42320
34.60000,17.92945,288.34172,288.34174,2.05958,0.42689
34.65000,17.93951,288.75828,288.75827,2.06256,0.42713
34.70000,17.40213,289.17499,289.17499,2.06554,0.41434
34.75000,16.79994,289.59160,289.59158,2.06851,0.40000
34.80000,16.54346,290.00820,290.00821,2.07149,0.39389
34.85000,16.70066,290.42489,290.42487,2.07446,0.39763
34.90000,17.53811,290.84168,290.84167,2.07744,0.41757
34.95000,17.91734,291.25834,291.25833,2.08042,0.42660
35.00000,18.10621,291.67497,291.67496,2.08339,0.43110
35.05000,18.39958,292.09165,292.09164,2.08637,0.43809
35.10000,18.08051,292.50831,292.50827,2.08934,0.43049
35.15000,18.43777,292.92510,292.92511,2.09232,0.43899
35.20000,18.21406,293.34173,293.34174,2.09530,0.43367
35.25000,18.35525,293.75844,293.75848,2.09827,0.43703
35.30000,18.10249,294.17510,294.17511,2.10125,0.43101
35.35000,18.18035,294.59179,294.59180,2.10423,0.43287
35.40000,17.80763,295.00845,295.00845,2.10720,0.42399
35.45000,17.84172,295.42508,295.42508,2.11018,0.42480
35.50000,18.22505,295.84171,295.84171,2.11316,0.43393
35.55000,18.83376,296.25837,296.25836,2.11613,0.44842
35.60000,18.67171,296.67495,296.67496,2.11911,0.44456
35.65000,18.75684,297.09158,297.09158,2.12208,0.44659
35.70000,19.27745,297.50830,297.50833,2.12506,0.45899
35.75000,19.22846,297.92495,297.92496,2.12804,0.45782
35.80000,19.39330,298.34156,298.34158,2.13101,0.46175
35.85000,19.15898,298.75822,298.75818,2.13399,0.45617
35.90000,18.81085,299.17504,299.17505,2.13696,0.44788
35.95000,19.00680,299.59167,299.59167,2.13994,0.45254
36.00000,18.66296,300.00835,300.00839,2.14292,0.44436
36.05000,18.85723,300.42504,300.42505,2.14589,0.44898
36.10000,18.88704,300.84180,300.84180,2.14887,0.44969
36.15000,19.43186,301.25843,301.25842,2.15185,0.46266
36.20000,19.74199,301.67512,301.67511,2.15482,0.47005
36.25000,19.33742,302.09173,302.09174,2.15780,0.46041
36.30000,19.68648,302.50849,302.50848,2.16077,0.46873
36.35000,19.56411,302.92504,302.92508,2.16375,0.46581
36.40000,19.82059,303.34168,303.34171,2.16673,0.47192
36.45000,19.34562,303.75833,303.75830,2.16970,0.46061
36.50000,19.83661,304.17497,304.17493,2.17268,0.47230
36.55000,19.50916,304.59165,304.59164,2.17565,0.46450
36.60000,19.56131,305.00821,305.00821,2.17863,0.46575
36.65000,19.60266,305.42494,305.42496,2.18161,0.46673
36.70000,19.89584,305.84160,305.84161,2.18458,0.47371
36.75000,19.96439,306.25831,306.25830,2.18756,0.47534
36.80000,20.35499,306.67495,306.67496,2.19054,0.48464
36.85000,19.98246,307.09163,307.09164,2.19351,0.47577
36.90000,20.32164,307.50839,307.50839,2.19649,0.48385
36.95000,20.43229,307.92505,307.92502,2.19946,0.48648
37.00000,20.07838,308.34166,308.34167,2.20244,0.47806
37.05000,20.28607,308.75845,308.75842,2.20542,0.48300
37.10000,20.34437,309.17516,309.17517,2.20839,0.48439
37.15000,20.04877,309.59177,309.59177,2.21137,0.47735
37.20000,20.19089,310.00843,310.00842,2.21435,0.48074
37.25000,19.97408,310.42508,310.42508,2.21732,0.47557
37.30000,20.43564,310.84174,310.84171,2.22030,0.48656
37.35000,20.60998,311.25832,311.25833,2.22327,0.49071
37.40000,20.68151,311.67496,311.67496,2.22625,0.49242
37.45000,20.56751,312.09164,312.09167,2.22923,0.48970
37.50000,20.91303,312.50827,312.50830,2.23220,0.49793
37.55000,20.54088,312.92488,312.92487,2.23518,0.48907
37.60000,21.04826,313.34154,313.34155,2.23815,0.50115
37.65000,21.10805,313.75830,313.75833,2.24113,0.50257
37.70000,20.81823,314.17501,314.17502,2.24411,0.49567
37.75000,20.88398,314.59162,314.59161,2.24708,0.49724
37.80000,20.91732,315.00838,315.00839,2.25006,0.49803
37.85000,21.40608,315.42509,315.42511,2.25304,0.50967
37.90000,21.29693,315.84175,315.84177,2.25601,0.50707
37.95000,21.40030,316.25846,316.25845,2.25899,0.50953
38.00000,21.41632,316.67512,316.67514,2.26197,0.50991
38.05000,21.78531,317.09178,317.09180,2.26494,0.51870
38.10000,21.50685,317.50841,317.50842,2.26792,0.51207
38.15000,21.65753,317.92502,317.92502,2.27089,0.51566
38.20000,21.50610,318.34168,318.34164,2.27387,0.51205
38.25000,21.69535,318.75839,318.75839,2.27685,0.51656
38.30000,21.53274,319.17497,319.17496,2.27982,0.51268
38.35000,21.72664,319.59163,319.59164,2.28280,0.51730
38.40000,21.47127,320.00826,320.00827,2.28577,0.51122
38.45000,21.81120,320.42503,320.42502,2.28875,0.51931
38.50000,22.03863,320.84155,320.84155,2.29173,0.52473
38.55000,22.01870,321.25829,321.25830,2.29470,0.52425
38.60000,21.91849,321.67498,321.67499,2.29768,0.52187
38.65000,22.33088,322.09166,322.09167,2.30065,0.53169
38.70000,22.37838,322.50835,322.50833,2.30363,0.53282
38.75000,22.32138,322.92498,322.92499,2.30661,0.53146
38.80000,22.22713,323.34177,323.34177,2.30958,0.52922
38.85000,22.27332,323.75843,323.75839,2.31256,0.53032
38.90000,22.24650,324.17509,324.17508,2.31554,0.52968
38.95000,22.18802,324.59177,324.59177,2.31851,0.52829
39.00000,22.52255,325.00853,325.00854,2.32149,0.53625
39.05000,22.24427,325.42506,325.42505,2.32446,0.52963
39.10000,3.27155,325.84172,325.84174,2.32744,0.07789
39.11300,-0.04303,325.95002,325.95001,2.32821,-0.00102