File: raw_data/mechanical_tests_Instron_data/Silicone_0035-Cross_3_1.is_tens_RawData/Specimen_RawData_1.csv
Dimension : Area,0.42000,cm^2

Time,Load,Extension,Tensile extension,Tensile strain,Tensile stress
(sec),(N),(mm),(mm),(mm/mm),(MPa)
0.00000,0.17919,0.00000,0.00000,0.00000,0.00427
0.04000,0.75847,0.06054,0.06054,0.00043,0.01806
0.08000,0.04917,0.26261,0.26261,0.00188,0.00117
0.12000,1.82465,0.59652,0.59652,0.00426,0.04344
0.16000,1.81049,0.98853,0.98853,0.00706,0.04311
0.20000,2.26628,1.39618,1.39618,0.00997,0.05396
0.24000,1.98521,1.81291,1.81291,0.01295,0.04727
0.28000,2.17091,2.23559,2.23559,0.01597,0.05169
0.32000,1.98018,2.65296,2.65296,0.01895,0.04715
0.36000,1.84644,3.00844,3.00844,0.02149,0.04396
0.40000,1.47466,3.33656,3.33656,0.02383,0.03511
0.44000,1.54544,3.67162,3.67162,0.02623,0.03680
0.48000,1.99117,4.00762,4.00762,0.02863,0.04741
0.52000,1.80341,4.34129,4.34129,0.03101,0.04294
0.56000,2.04910,4.67483,4.67483,0.03339,0.04879
0.60000,1.80490,5.00812,5.00812,0.03577,0.04297
0.64000,2.02768,5.34174,5.34174,0.03816,0.04828
0.68000,2.32197,5.67479,5.67479,0.04053,0.05529
0.72000,2.18935,6.00833,6.00833,0.04292,0.05213
0.76000,2.12695,6.34165,6.34165,0.04530,0.05064
0.80000,1.93715,6.67497,6.67497,0.04768,0.04612
0.84000,2.11075,7.00837,7.00837,0.05006,0.05026
0.88000,2.37189,7.34161,7.34161,0.05244,0.05647
0.92000,1.83173,7.67509,7.67509,0.05482,0.04361
0.96000,2.25473,8.00828,8.00828,0.05720,0.05368
1.00000,2.24989,8.34176,8.34176,0.05958,0.05357
1.04000,1.94162,8.67492,8.67492,0.06196,0.04623
1.08000,2.15191,9.00835,9.00835,0.06435,0.05124
1.12000,2.12267,9.34162,9.34162,0.06673,0.05054
1.16000,2.02172,9.67502,9.67502,0.06911,0.04814
1.20000,2.28006,10.00834,10.00834,0.07149,0.05429
1.24000,2.45161,10.34158,10.34158,0.07387,0.05837
1.28000,2.34433,10.67499,10.67499,0.07625,0.05582
1.32000,2.65241,11.00823,11.00823,0.07863,0.06315
1.36000,2.57976,11.34179,11.34179,0.08101,0.06142
1.40000,2.28658,11.67492,11.67492,0.08339,0.05444
1.44000,2.39648,12.00835,12.00835,0.08577,0.05706
1.48000,2.24300,12.34165,12.34165,0.08815,0.05340
1.52000,2.44640,12.67502,12.67502,0.09054,0.05825
1.56000,2.18228,13.00834,13.00834,0.09292,0.05196
1.60000,2.10404,13.34164,13.34164,0.09530,0.05010
1.64000,2.30838,13.67507,13.67507,0.09768,0.05496
1.68000,2.26442,14.00825,14.00825,0.10006,0.05391
1.72000,2.26945,14.34176,14.34176,0.10244,0.05403
1.76000,2.20276,14.67487,14.67487,0.10482,0.05245
1.80000,2.40989,15.00838,15.00838,0.10720,0.05738
1.84000,2.48794,15.34159,15.34159,0.10958,0.05924
1.88000,2.33371,15.67499,15.67499,0.11196,0.05556
1.92000,2.42256,16.00840,16.00839,0.11435,0.05768
1.96000,2.50153,16.34158,16.34158,0.11673,0.05956
2.00000,2.47061,16.67509,16.67509,0.11911,0.05882
2.04000,2.38586,17.00822,17.00822,0.12149,0.05681
2.08000,2.28900,17.34173,17.34173,0.12387,0.05450
2.12000,2.17408,17.67495,17.67495,0.12625,0.05176
2.16000,2.29105,18.00838,18.00838,0.12863,0.05455
2.20000,2.04649,18.34159,18.34159,0.13101,0.04873
2.24000,2.32644,18.67502,18.67502,0.13339,0.05539
2.28000,2.25566,19.00834,19.00834,0.13577,0.05371
2.32000,2.24896,19.34155,19.34155,0.13815,0.05355
2.36000,2.32998,19.67506,19.67506,0.14054,0.05548
2.40000,2.37860,20.00822,20.00822,0.14292,0.05663
2.44000,2.03978,20.34173,20.34173,0.14530,0.04857
2.48000,1.85668,20.67492,20.67492,0.14768,0.04421
2.52000,2.28211,21.00838,21.00838,0.15006,0.05434
2.56000,2.18246,21.34156,21.34156,0.15244,0.05196
2.60000,2.23368,21.67499,21.67499,0.15482,0.05318
2.64000,2.14595,22.00834,22.00834,0.15720,0.05109
2.68000,2.20928,22.34169,22.34169,0.15958,0.05260
2.72000,2.26293,22.67506,22.67506,0.16196,0.05388
2.76000,2.34935,23.00825,23.00825,0.16434,0.05594
2.80000,1.97180,23.34173,23.34173,0.16673,0.04695
2.84000,2.04258,23.67492,23.67492,0.16911,0.04863
2.88000,2.29310,24.00845,24.00845,0.17149,0.05460
2.92000,2.27019,24.34161,24.34161,0.17387,0.05405
2.96000,2.21767,24.67496,24.67496,0.17625,0.05280
3.00000,2.08355,25.00836,25.00836,0.17863,0.04961
3.04000,2.04872,25.34163,25.34163,0.18101,0.04878
3.08000,2.14111,25.67506,25.67506,0.18339,0.05098
3.12000,1.94330,26.00817,26.00817,0.18577,0.04627
3.16000,1.89468,26.34170,26.34170,0.18816,0.04511
3.20000,2.25250,26.67486,26.67486,0.19053,0.05363
3.24000,2.00346,27.00843,27.00842,0.19292,0.04770
3.28000,2.12248,27.34169,27.34169,0.19530,0.05054
3.32000,2.00011,27.67499,27.67499,0.19768,0.04762
3.36000,2.09808,28.00834,28.00834,0.20006,0.04995
3.40000,1.86563,28.34160,28.34160,0.20244,0.04442
3.44000,1.78497,28.67508,28.67508,0.20482,0.04250
3.48000,1.95168,29.00825,29.00825,0.20720,0.04647
3.52000,2.20034,29.34176,29.34176,0.20958,0.05239
3.56000,1.95559,29.67486,29.67486,0.21196,0.04656
3.60000,2.08504,30.00834,30.00834,0.21435,0.04964
3.64000,2.13515,30.34169,30.34169,0.21673,0.05084
3.68000,2.01315,30.67493,30.67493,0.21911,0.04793
3.72000,2.34563,31.00831,31.00831,0.22149,0.05585
3.76000,1.89096,31.34158,31.34158,0.22387,0.04502
3.80000,2.17278,31.67508,31.67508,0.22625,0.05173
3.84000,2.28900,32.00832,32.00832,0.22863,0.05450
3.88000,2.11503,32.34178,32.34178,0.23101,0.05036
3.92000,1.78907,32.67491,32.67491,0.23339,0.04260
3.96000,1.96192,33.00840,33.00840,0.23577,0.04671
4.00000,2.11205,33.34164,33.34164,0.23815,0.05029
4.04000,2.11094,33.67504,33.67504,0.24054,0.05026
4.08000,2.24300,34.00836,34.00836,0.24292,0.05340
4.12000,2.22959,34.34154,34.34155,0.24530,0.05309
4.16000,2.57399,34.67503,34.67503,0.24768,0.06129
4.20000,2.45497,35.00822,35.00822,0.25006,0.05845
4.24000,2.02563,35.34170,35.34170,0.25244,0.04823
4.28000,2.36910,35.67486,35.67486,0.25482,0.05641
4.32000,2.60398,36.00837,36.00837,0.25720,0.06200
4.36000,2.66694,36.34164,36.34164,0.25958,0.06350
4.40000,3.03313,36.67506,36.67506,0.26196,0.07222
4.44000,2.81688,37.00838,37.00838,0.26435,0.06707
4.48000,2.95024,37.34157,37.34157,0.26673,0.07024
4.52000,2.62503,37.67506,37.67506,0.26911,0.06250
4.56000,2.90722,38.00824,38.00824,0.27149,0.06922
4.60000,2.78316,38.34175,38.34175,0.27387,0.06627
4.64000,2.78074,38.67494,38.67494,0.27625,0.06621
4.68000,3.01544,39.00839,39.00839,0.27863,0.07180
4.72000,3.47178,39.34163,39.34163,0.28101,0.08266
4.76000,3.00482,39.67496,39.67496,0.28339,0.07154
4.80000,2.80309,40.00838,40.00838,0.28577,0.06674
4.84000,3.04375,40.34160,40.34160,0.28815,0.07247
4.88000,3.00612,40.67505,40.67505,0.29054,0.07157
4.92000,3.24864,41.00824,41.00824,0.29292,0.07735
4.96000,3.00184,41.34175,41.34175,0.29530,0.07147
5.00000,3.30750,41.67496,41.67496,0.29768,0.07875
5.04000,3.28906,42.00839,42.00839,0.30006,0.07831
5.08000,2.96365,42.34163,42.34163,0.30244,0.07056
5.12000,3.32873,42.67498,42.67498,0.30482,0.07926
5.16000,3.11267,43.00836,43.00836,0.30720,0.07411
5.20000,3.16240,43.34160,43.34160,0.30958,0.07530
5.24000,3.14526,43.67505,43.67505,0.31196,0.07489
5.28000,3.42336,44.00824,44.00824,0.31434,0.08151
5.32000,3.55057,44.34172,44.34172,0.31673,0.08454
5.36000,3.37157,44.67488,44.67488,0.31911,0.08028
5.40000,3.30582,45.00839,45.00839,0.32149,0.07871
5.44000,3.25199,45.34163,45.34164,0.32387,0.07743
5.48000,3.61670,45.67498,45.67498,0.32625,0.08611
5.52000,3.41684,46.00833,46.00832,0.32863,0.08135
5.56000,3.52990,46.34165,46.34165,0.33101,0.08405
5.60000,3.62732,46.67505,46.67505,0.33339,0.08636
5.64000,3.63942,47.00821,47.00821,0.33577,0.08665
5.68000,3.68971,47.34177,47.34177,0.33816,0.08785
5.72000,3.86406,47.67491,47.67491,0.34054,0.09200
5.76000,4.05982,48.00844,48.00844,0.34292,0.09666
5.80000,3.54555,48.34161,48.34161,0.34530,0.08442
5.84000,3.87896,48.67498,48.67498,0.34768,0.09236
5.88000,3.89386,49.00835,49.00835,0.35006,0.09271
5.92000,3.81712,49.34159,49.34159,0.35244,0.09088
5.96000,4.27086,49.67513,49.67513,0.35482,0.10169
6.00000,4.27272,50.00824,50.00824,0.35720,0.10173
6.04000,4.03058,50.34175,50.34175,0.35958,0.09597
6.08000,4.43682,50.67491,50.67491,0.36196,0.10564
6.12000,4.32543,51.00839,51.00838,0.36435,0.10299
6.16000,4.30197,51.34163,51.34163,0.36673,0.10243
6.20000,4.56627,51.67500,51.67500,0.36911,0.10872
6.24000,4.24087,52.00833,52.00833,0.37149,0.10097
6.28000,4.21721,52.34156,52.34156,0.37387,0.10041
6.32000,4.51766,52.67513,52.67513,0.37625,0.10756
6.36000,4.11719,53.00818,53.00818,0.37863,0.09803
6.40000,4.04511,53.34172,53.34172,0.38101,0.09631
6.44000,4.18182,53.67491,53.67491,0.38339,0.09957
6.48000,4.25316,54.00839,54.00839,0.38577,0.10127
6.52000,4.43738,54.34165,54.34165,0.38815,0.10565
6.56000,4.56143,54.67500,54.67500,0.39054,0.10861
6.60000,4.33382,55.00833,55.00833,0.39292,0.10319
6.64000,4.45172,55.34156,55.34156,0.39530,0.10599
6.68000,4.52176,55.67505,55.67505,0.39768,0.10766
6.72000,4.31389,56.00826,56.00826,0.40006,0.10271
6.76000,4.46327,56.34177,56.34177,0.40244,0.10627
6.80000,4.70579,56.67485,56.67485,0.40482,0.11204
6.84000,4.74509,57.00836,57.00835,0.40720,0.11298
6.88000,4.62402,57.34159,57.34159,0.40958,0.11010
6.92000,4.51263,57.67505,57.67505,0.41196,0.10744
6.96000,4.67096,58.00838,58.00838,0.41435,0.11121
7.00000,4.94607,58.34159,58.34159,0.41673,0.11776
7.04000,4.59440,58.67507,58.67507,0.41911,0.10939
7.08000,4.61638,59.00826,59.00826,0.42149,0.10991
7.12000,4.28353,59.34179,59.34179,0.42387,0.10199
7.16000,4.73186,59.67488,59.67488,0.42625,0.11266
7.20000,4.66127,60.00838,60.00838,0.42863,0.11098
7.24000,4.89932,60.34159,60.34159,0.43101,0.11665
7.28000,4.82183,60.67500,60.67500,0.43339,0.11481
7.32000,4.93508,61.00838,61.00838,0.43577,0.11750
7.36000,4.77880,61.34159,61.34159,0.43815,0.11378
7.40000,4.79035,61.67502,61.67502,0.44054,0.11406
7.44000,4.58956,62.00820,62.00820,0.44292,0.10928
7.48000,4.56329,62.34179,62.34179,0.44530,0.10865
7.52000,4.74807,62.67495,62.67495,0.44768,0.11305
7.56000,4.95799,63.00838,63.00838,0.45006,0.11805
7.60000,4.86691,63.34162,63.34162,0.45244,0.11588
7.64000,4.82406,63.67492,63.67492,0.45482,0.11486
7.68000,4.67189,64.00840,64.00840,0.45720,0.11124
7.72000,4.69442,64.34163,64.34164,0.45958,0.11177
7.76000,4.78309,64.67507,64.67507,0.46196,0.11388
7.80000,5.06323,65.00820,65.00820,0.46434,0.12055
7.84000,4.92595,65.34168,65.34168,0.46673,0.11728
7.88000,4.68846,65.67493,65.67493,0.46911,0.11163
7.92000,4.82537,66.00837,66.00838,0.47149,0.11489
7.96000,4.98611,66.34162,66.34162,0.47387,0.11872
8.00000,4.78737,66.67499,66.67500,0.47625,0.11399
8.04000,4.53889,67.00834,67.00835,0.47863,0.10807
8.08000,4.77191,67.34163,67.34164,0.48101,0.11362
8.12000,4.65810,67.67513,67.67513,0.48339,0.11091
8.16000,4.87715,68.00822,68.00822,0.48577,0.11612
8.20000,4.48860,68.34171,68.34171,0.48816,0.10687
8.24000,4.54448,68.67495,68.67495,0.49054,0.10820
8.28000,4.73894,69.00841,69.00841,0.49292,0.11283
8.32000,4.83189,69.34159,69.34159,0.49530,0.11504
8.36000,4.95985,69.67503,69.67503,0.49768,0.11809
8.40000,4.98779,70.00826,70.00826,0.50006,0.11876
8.44000,5.13513,70.34158,70.34158,0.50244,0.12226
8.48000,5.30593,70.67509,70.67509,0.50482,0.12633
8.52000,4.91180,71.00822,71.00822,0.50720,0.11695
8.56000,5.21038,71.34177,71.34177,0.50958,0.12406
8.60000,5.07962,71.67489,71.67490,0.51196,0.12094
8.64000,5.34654,72.00837,72.00837,0.51435,0.12730
8.68000,5.29829,72.34162,72.34162,0.51673,0.12615
8.72000,5.39385,72.67502,72.67502,0.51911,0.12842
8.76000,5.22044,73.00839,73.00839,0.52149,0.12430
8.80000,5.14518,73.34161,73.34161,0.52387,0.12250
8.84000,5.10290,73.67504,73.67504,0.52625,0.12150
8.88000,5.38286,74.00825,74.00826,0.52863,0.12816
8.92000,5.41247,74.34173,74.34174,0.53101,0.12887
8.96000,5.26197,74.67487,74.67487,0.53339,0.12529
9.00000,5.47934,75.00841,75.00842,0.53577,0.13046
9.04000,5.50300,75.34164,75.34164,0.53815,0.13102
9.08000,5.29755,75.67499,75.67500,0.54054,0.12613
9.12000,5.16493,76.00837,76.00837,0.54292,0.12297
9.16000,5.19641,76.34161,76.34162,0.54530,0.12372
9.20000,5.38826,76.67506,76.67506,0.54768,0.12829
9.24000,5.60209,77.00825,77.00826,0.55006,0.13338
9.28000,5.66207,77.34173,77.34174,0.55244,0.13481
9.32000,5.97090,77.67492,77.67492,0.55482,0.14216
9.36000,6.12643,78.00837,78.00837,0.55720,0.14587
9.40000,6.14319,78.34164,78.34164,0.55958,0.14627
9.44000,6.33467,78.67499,78.67500,0.56196,0.15083
9.48000,6.07427,79.00837,79.00837,0.56435,0.14463
9.52000,6.43935,79.34161,79.34160,0.56673,0.15332
9.56000,6.63884,79.67504,79.67504,0.56911,0.15807
9.60000,6.87484,80.00825,80.00826,0.57149,0.16369
9.64000,6.85323,80.34178,80.34178,0.57387,0.16317
9.68000,7.03149,80.67484,80.67485,0.57625,0.16742
9.72000,7.10562,81.00840,81.00840,0.57863,0.16918
9.76000,7.02832,81.34164,81.34164,0.58101,0.16734
9.80000,6.87391,81.67502,81.67502,0.58339,0.16366
9.84000,6.82082,82.00833,82.00833,0.58577,0.16240
9.88000,6.91917,82.34155,82.34155,0.58815,0.16474
9.92000,7.23731,82.67506,82.67506,0.59054,0.17232
9.96000,7.04098,83.00822,83.00822,0.59292,0.16764
10.00000,7.25910,83.34181,83.34181,0.59530,0.17284
10.04000,6.94320,83.67494,83.67494,0.59768,0.16531
10.08000,6.87484,84.00837,84.00837,0.60006,0.16369
10.12000,7.24755,84.34159,84.34159,0.60244,0.17256
10.16000,7.17565,84.67502,84.67502,0.60482,0.17085
10.20000,7.02813,85.00839,85.00838,0.60720,0.16734
10.24000,7.31628,85.34161,85.34161,0.60958,0.17420
10.28000,7.68919,85.67508,85.67509,0.61196,0.18308
10.32000,7.83000,86.00819,86.00819,0.61434,0.18643
10.36000,7.71992,86.34172,86.34172,0.61673,0.18381
10.40000,7.42953,86.67497,86.67497,0.61911,0.17689
10.44000,7.59754,87.00834,87.00834,0.62149,0.18089
10.48000,7.82274,87.34164,87.34164,0.62387,0.18626
10.52000,7.80560,87.67498,87.67499,0.62625,0.18585
10.56000,7.34460,88.00836,88.00835,0.62863,0.17487
10.60000,7.14324,88.34166,88.34166,0.63101,0.17008
10.64000,7.67354,88.67508,88.67509,0.63339,0.18270
10.68000,7.71992,89.00822,89.00822,0.63577,0.18381
10.72000,7.28033,89.34170,89.34170,0.63815,0.17334
10.76000,7.71564,89.67492,89.67492,0.64054,0.18371
10.80000,7.57407,90.00845,90.00845,0.64292,0.18034
10.84000,7.73706,90.34161,90.34161,0.64530,0.18422
10.88000,7.98348,90.67493,90.67493,0.64768,0.19008
10.92000,8.01515,91.00833,91.00833,0.65006,0.19084
10.96000,7.72830,91.34160,91.34161,0.65244,0.18401
11.00000,7.68378,91.67505,91.67505,0.65482,0.18295
11.04000,7.68770,92.00824,92.00825,0.65720,0.18304
11.08000,7.57072,92.34176,92.34176,0.65958,0.18026
11.12000,7.64932,92.67492,92.67492,0.66196,0.18213
11.16000,7.46977,93.00845,93.00845,0.66435,0.17785
11.20000,7.63256,93.34163,93.34163,0.66673,0.18173
11.24000,7.84807,93.67498,93.67498,0.66911,0.18686
11.28000,7.73277,94.00833,94.00833,0.67149,0.18411
11.32000,7.37570,94.34160,94.34161,0.67387,0.17561
11.36000,7.79275,94.67508,94.67509,0.67625,0.18554
11.40000,7.54707,95.00824,95.00825,0.67863,0.17969
11.44000,7.41072,95.34172,95.34172,0.68101,0.17645
11.48000,7.88104,95.67483,95.67484,0.68339,0.18764
11.52000,7.66441,96.00836,96.00836,0.68577,0.18249
11.56000,7.70334,96.34169,96.34168,0.68815,0.18341
11.60000,8.13901,96.67498,96.67498,0.69054,0.19379
11.64000,8.13734,97.00836,97.00836,0.69292,0.19375
11.68000,7.77747,97.34160,97.34161,0.69530,0.18518
11.72000,7.91680,97.67508,97.67509,0.69768,0.18850
11.76000,8.22060,98.00830,98.00829,0.70006,0.19573
11.80000,8.02297,98.34176,98.34176,0.70244,0.19102
11.84000,8.14851,98.67494,98.67494,0.70482,0.19401
11.88000,8.05147,99.00836,99.00836,0.70720,0.19170
11.92000,7.96299,99.34161,99.34161,0.70958,0.18960
11.96000,7.67652,99.67500,99.67500,0.71196,0.18277
12.00000,8.00528,100.00833,100.00832,0.71435,0.19060
12.04000,8.24071,100.34157,100.34158,0.71673,0.19621
12.08000,7.95648,100.67505,100.67505,0.71911,0.18944
12.12000,8.13566,101.00824,101.00824,0.72149,0.19371
12.16000,8.30032,101.34175,101.34175,0.72387,0.19763
12.20000,8.14646,101.67493,101.67493,0.72625,0.19396
12.24000,8.28914,102.00836,102.00836,0.72863,0.19736
12.28000,8.11368,102.34163,102.34164,0.73101,0.19318
12.32000,8.16118,102.67509,102.67509,0.73339,0.19431
12.36000,8.17776,103.00836,103.00835,0.73577,0.19471
12.40000,8.28784,103.34162,103.34163,0.73815,0.19733
12.44000,8.00285,103.67508,103.67509,0.74054,0.19054
12.48000,7.92705,104.00819,104.00819,0.74292,0.18874
12.52000,8.09152,104.34180,104.34180,0.74530,0.19266
12.56000,8.36048,104.67491,104.67491,0.74768,0.19906
12.60000,8.16789,105.00841,105.00842,0.75006,0.19447
12.64000,8.18018,105.34160,105.34159,0.75244,0.19477
12.68000,8.62014,105.67498,105.67498,0.75482,0.20524
12.72000,8.35881,106.00832,106.00832,0.75720,0.19902
12.76000,8.02651,106.34157,106.34157,0.75958,0.19111
12.80000,8.25021,106.67510,106.67511,0.76197,0.19643
12.84000,8.12840,107.00826,107.00827,0.76434,0.19353
12.88000,8.31783,107.34180,107.34180,0.76673,0.19804
12.92000,8.23624,107.67491,107.67491,0.76911,0.19610
12.96000,8.22507,108.00841,108.00842,0.77149,0.19583
13.00000,8.46516,108.34160,108.34160,0.77387,0.20155
13.04000,8.38749,108.67500,108.67500,0.77625,0.19970
13.08000,8.35266,109.00841,109.00841,0.77863,0.19887
13.12000,8.23718,109.34159,109.34159,0.78101,0.19612
13.16000,8.52123,109.67508,109.67508,0.78339,0.20289
13.20000,8.37706,110.00820,110.00820,0.78577,0.19945
13.24000,8.29548,110.34171,110.34171,0.78816,0.19751
13.28000,8.45958,110.67493,110.67493,0.79054,0.20142
13.32000,8.21427,111.00839,111.00838,0.79292,0.19558
13.36000,8.65068,111.34163,111.34163,0.79530,0.20597
13.40000,8.28113,111.67498,111.67498,0.79768,0.19717
13.44000,8.17589,112.00835,112.00835,0.80006,0.19466
13.48000,8.37687,112.34165,112.34165,0.80244,0.19945
13.52000,8.47857,112.67507,112.67507,0.80482,0.20187
13.56000,8.63392,113.00826,113.00826,0.80720,0.20557
13.60000,8.83825,113.34180,113.34180,0.80958,0.21043
13.64000,8.49646,113.67493,113.67493,0.81196,0.20230
13.68000,8.80938,114.00845,114.00845,0.81435,0.20975
13.72000,8.77623,114.34161,114.34161,0.81673,0.20896
13.76000,8.63187,114.67492,114.67492,0.81911,0.20552
13.80000,8.85781,115.00836,115.00835,0.82149,0.21090
13.84000,8.56146,115.34162,115.34162,0.82387,0.20384
13.88000,9.03308,115.67509,115.67509,0.82625,0.21507
13.92000,9.04687,116.00820,116.00820,0.82863,0.21540
13.96000,9.05879,116.34171,116.34171,0.83101,0.21569
14.00000,9.24021,116.67487,116.67487,0.83339,0.22001
14.04000,8.93958,117.00841,117.00842,0.83577,0.21285
14.08000,9.02787,117.34165,117.34165,0.83815,0.21495
14.12000,8.84011,117.67503,117.67503,0.84054,0.21048
14.16000,9.21860,118.00835,118.00835,0.84292,0.21949
14.20000,9.25362,118.34159,118.34159,0.84530,0.22032
14.24000,9.49968,118.67513,118.67513,0.84768,0.22618
14.28000,9.38624,119.00823,119.00823,0.85006,0.22348
14.32000,8.94871,119.34173,119.34174,0.85244,0.21306
14.36000,9.10871,119.67491,119.67490,0.85482,0.21687
14.40000,9.14671,120.00835,120.00835,0.85720,0.21778
14.44000,9.37153,120.34168,120.34168,0.85958,0.22313
14.48000,9.54289,120.67500,120.67500,0.86196,0.22721
14.52000,9.74517,121.00829,121.00829,0.86434,0.23203
14.56000,9.50005,121.34158,121.34158,0.86673,0.22619
14.60000,9.60417,121.67507,121.67506,0.86911,0.22867
14.64000,9.16533,122.00831,122.00831,0.87149,0.21822
14.68000,9.16850,122.34177,122.34177,0.87387,0.21830
14.72000,9.57083,122.67490,122.67490,0.87625,0.22788
14.76000,9.43635,123.00832,123.00832,0.87863,0.22467
14.80000,9.68743,123.34165,123.34165,0.88101,0.23065
14.84000,9.68874,123.67506,123.67506,0.88339,0.23068
14.88000,9.49968,124.00840,124.00840,0.88577,0.22618
14.92000,9.31378,124.34159,124.34158,0.88815,0.22176
14.96000,9.55332,124.67501,124.67501,0.89054,0.22746
15.00000,9.68259,125.00826,125.00826,0.89292,0.23054
15.04000,9.88860,125.34173,125.34174,0.89530,0.23544
15.08000,9.59355,125.67487,125.67487,0.89768,0.22842
15.12000,9.52836,126.00838,126.00838,0.90006,0.22687
15.16000,9.92846,126.34158,126.34158,0.90244,0.23639
15.20000,9.60771,126.67501,126.67501,0.90482,0.22875
15.24000,9.70680,127.00839,127.00839,0.90720,0.23111
15.28000,9.69060,127.34161,127.34161,0.90958,0.23073
15.32000,9.63658,127.67507,127.67506,0.91196,0.22944
15.36000,9.55313,128.00823,128.00822,0.91434,0.22746
15.40000,10.01004,128.34179,128.34180,0.91673,0.23833
15.44000,9.90368,128.67492,128.67493,0.91911,0.23580
15.48000,9.93051,129.00844,129.00844,0.92149,0.23644
15.52000,9.91933,129.34160,129.34160,0.92387,0.23617
15.56000,9.81297,129.67497,129.67497,0.92625,0.23364
15.60000,9.80590,130.00839,130.00839,0.92863,0.23347
15.64000,9.86755,130.34164,130.34164,0.93101,0.23494
15.68000,9.61758,130.67503,130.67503,0.93339,0.22899
15.72000,10.14769,131.00819,131.00819,0.93577,0.24161
15.76000,10.30974,131.34173,131.34174,0.93816,0.24547
15.80000,10.36581,131.67489,131.67490,0.94053,0.24680
15.84000,10.25274,132.00843,132.00842,0.94292,0.24411
15.88000,10.34494,132.34164,132.34164,0.94530,0.24631
15.92000,10.22108,132.67501,132.67502,0.94768,0.24336
15.96000,10.24641,133.00837,133.00836,0.95006,0.24396
16.00000,10.08715,133.34160,133.34160,0.95244,0.24017
16.04000,10.12813,133.67506,133.67506,0.95482,0.24115
16.08000,10.21288,134.00823,134.00822,0.95720,0.24316
16.12000,10.32464,134.34174,134.34174,0.95958,0.24582
16.16000,9.92510,134.67494,134.67494,0.96196,0.23631
16.20000,10.58709,135.00837,135.00838,0.96435,0.25207
16.24000,10.28609,135.34162,135.34163,0.96673,0.24491
16.28000,10.71375,135.67499,135.67499,0.96911,0.25509
16.32000,10.91529,136.00828,136.00829,0.97149,0.25989
16.36000,10.38555,136.34164,136.34164,0.97387,0.24728
16.40000,10.32036,136.67510,136.67509,0.97625,0.24572
16.44000,10.43733,137.00819,137.00819,0.97863,0.24851
16.48000,10.39095,137.34178,137.34178,0.98101,0.24740
16.52000,10.80893,137.67492,137.67491,0.98339,0.25736
16.56000,10.62229,138.00840,138.00841,0.98577,0.25291
16.60000,10.65508,138.34164,138.34164,0.98815,0.25369
16.64000,10.89517,138.67500,138.67500,0.99054,0.25941
16.68000,10.81154,139.00837,139.00836,0.99292,0.25742
16.72000,10.67463,139.34160,139.34160,0.99530,0.25416
16.76000,11.21536,139.67509,139.67509,0.99768,0.26703
16.80000,11.01438,140.00819,140.00818,1.00006,0.26225
16.84000,10.98849,140.34175,140.34175,1.00244,0.26163
16.88000,11.06616,140.67487,140.67487,1.00482,0.26348
16.92000,11.17755,141.00842,141.00842,1.00720,0.26613
16.96000,11.26416,141.34163,141.34163,1.00958,0.26819
17.00000,11.49327,141.67499,141.67499,1.01196,0.27365
17.04000,11.15855,142.00837,142.00838,1.01435,0.26568
17.08000,11.05666,142.34157,142.34157,1.01673,0.26325
17.12000,11.62179,142.67514,142.67513,1.01911,0.27671
17.16000,11.31985,143.00827,143.00827,1.02149,0.26952
17.20000,11.48228,143.34176,143.34174,1.02387,0.27339
17.24000,11.80675,143.67494,143.67493,1.02625,0.28111
17.28000,11.39771,144.00838,144.00838,1.02863,0.27137
17.32000,11.14998,144.34164,144.34164,1.03101,0.26548
17.36000,11.39622,144.67500,144.67500,1.03339,0.27134
17.40000,11.40516,145.00830,145.00829,1.03577,0.27155
17.44000,11.30179,145.34158,145.34158,1.03815,0.26909
17.48000,11.58640,145.67501,145.67502,1.04054,0.27587
17.52000,11.25187,146.00828,146.00827,1.04292,0.26790
17.56000,11.38523,146.34174,146.34174,1.04530,0.27108
17.60000,11.67282,146.67491,146.67491,1.04768,0.27792
17.64000,11.42099,147.00839,147.00838,1.05006,0.27193
17.68000,11.40833,147.34166,147.34166,1.05244,0.27163
17.72000,11.66612,147.67504,147.67503,1.05482,0.27776
17.76000,11.91907,148.00838,148.00838,1.05720,0.28379
17.80000,11.51469,148.34157,148.34155,1.05958,0.27416
17.84000,11.46365,148.67503,148.67503,1.06196,0.27294
17.88000,11.62291,149.00827,149.00827,1.06434,0.27674
17.92000,11.64228,149.34182,149.34183,1.06673,0.27720
17.96000,12.02133,149.67491,149.67491,1.06911,0.28622
18.00000,11.52717,150.00835,150.00836,1.07149,0.27446
18.04000,11.97662,150.34156,150.34157,1.07387,0.28516
18.08000,11.98314,150.67500,150.67499,1.07625,0.28531
18.12000,11.95632,151.00836,151.00836,1.07863,0.28467
18.16000,12.21187,151.34159,151.34158,1.08101,0.29076
18.20000,12.11278,151.67511,151.67511,1.08339,0.28840
18.24000,12.24708,152.00821,152.00819,1.08577,0.29160
18.28000,12.23609,152.34180,152.34180,1.08816,0.29134
18.32000,12.60862,152.67496,152.67496,1.09054,0.30021
18.36000,12.26123,153.00837,153.00838,1.09292,0.29193
18.40000,12.20126,153.34163,153.34163,1.09530,0.29051
18.44000,12.30128,153.67499,153.67500,1.09768,0.29289
18.48000,12.59502,154.00836,154.00838,1.10006,0.29988
18.52000,12.21802,154.34165,154.34164,1.10244,0.29091
18.56000,12.30016,154.67503,154.67503,1.10482,0.29286
18.60000,12.71423,155.00819,155.00819,1.10720,0.30272
18.64000,12.51381,155.34175,155.34175,1.10958,0.29795
18.68000,12.64643,155.67494,155.67494,1.11196,0.30111
18.72000,12.77290,156.00840,156.00841,1.11435,0.30412
18.76000,12.83363,156.34164,156.34164,1.11673,0.30556
18.80000,12.91856,156.67499,156.67499,1.11911,0.30758
18.84000,12.56112,157.00832,157.00832,1.12149,0.29907
18.88000,12.60694,157.34168,157.34167,1.12387,0.30017
18.92000,13.07912,157.67511,157.67513,1.12625,0.31141
18.96000,12.89696,158.00827,158.00827,1.12863,0.30707
19.00000,12.69355,158.34173,158.34175,1.13101,0.30223
19.04000,12.99437,158.67491,158.67491,1.13339,0.30939
19.08000,12.95153,159.00845,159.00844,1.13577,0.30837
19.12000,12.77495,159.34161,159.34160,1.13815,0.30417
19.16000,12.78836,159.67501,159.67502,1.14054,0.30448
19.20000,13.30040,160.00833,160.00833,1.14292,0.31668
19.24000,13.39670,160.34159,160.34158,1.14530,0.31897
19.28000,13.21472,160.67511,160.67511,1.14768,0.31464
19.32000,13.22068,161.00821,161.00819,1.15006,0.31478
19.36000,13.13705,161.34175,161.34177,1.15244,0.31279
19.40000,13.41328,161.67487,161.67488,1.15482,0.31936
19.44000,13.38106,162.00841,162.00841,1.15720,0.31860
19.48000,13.26837,162.34166,162.34166,1.15958,0.31591
19.52000,13.72006,162.67501,162.67500,1.16196,0.32667
19.56000,13.60942,163.00839,163.00839,1.16435,0.32403
19.60000,13.27991,163.34157,163.34157,1.16673,0.31619
19.64000,13.12140,163.67511,163.67511,1.16911,0.31241
19.68000,13.22720,164.00830,164.00830,1.17149,0.31493
19.72000,13.55130,164.34175,164.34175,1.17387,0.32265
19.76000,13.64816,164.67488,164.67488,1.17625,0.32496
19.80000,13.85715,165.00839,165.00841,1.17863,0.32993
19.84000,13.79140,165.34162,165.34161,1.18101,0.32837
19.88000,13.89496,165.67495,165.67494,1.18339,0.33083
19.92000,14.01380,166.00838,166.00839,1.18577,0.33366
19.96000,13.68076,166.34159,166.34160,1.18815,0.32573
20.00000,14.01454,166.67507,166.67505,1.19054,0.33368
20.04000,13.60700,167.00825,167.00824,1.19292,0.32398
20.08000,14.12425,167.34175,167.34175,1.19530,0.33629
20.12000,14.07601,167.67494,167.67494,1.19768,0.33514
20.16000,14.17194,168.00839,168.00839,1.20006,0.33743
20.20000,14.22018,168.34166,168.34167,1.20244,0.33858
20.24000,14.32672,168.67506,168.67506,1.20482,0.34111
20.28000,14.07471,169.00835,169.00833,1.20720,0.33511
20.32000,14.09203,169.34159,169.34158,1.20958,0.33552
20.36000,14.30325,169.67502,169.67503,1.21196,0.34055
20.40000,14.55545,170.00823,170.00824,1.21434,0.34656
20.44000,14.08719,170.34180,170.34180,1.21673,0.33541
20.48000,14.43028,170.67488,170.67488,1.21911,0.34358
20.52000,14.38856,171.00833,171.00833,1.22149,0.34258
20.56000,14.08830,171.34166,171.34166,1.22387,0.33544
20.60000,14.05757,171.67497,171.67497,1.22625,0.33470
20.64000,14.43028,172.00834,172.00835,1.22863,0.34358
20.68000,14.45822,172.34163,172.34163,1.23101,0.34424
20.72000,14.58824,172.67509,172.67509,1.23339,0.34734
20.76000,14.85292,173.00825,173.00826,1.23577,0.35364
20.80000,14.87266,173.34179,173.34180,1.23816,0.35411
20.84000,14.75345,173.67494,173.67494,1.24054,0.35127
20.88000,14.58246,174.00837,174.00838,1.24292,0.34720
20.92000,14.61674,174.34160,174.34160,1.24530,0.34802
20.96000,14.80579,174.67499,174.67499,1.24768,0.35252
21.00000,14.85609,175.00841,175.00841,1.25006,0.35372
21.04000,15.15429,175.34157,175.34158,1.25244,0.36082
21.08000,14.90097,175.67505,175.67505,1.25482,0.35479
21.12000,15.15932,176.00821,176.00821,1.25720,0.36094
21.16000,14.70558,176.34172,176.34172,1.25958,0.35013
21.20000,14.61525,176.67498,176.67499,1.26196,0.34798
21.24000,14.97176,177.00842,177.00842,1.26435,0.35647
21.28000,15.01087,177.34164,177.34164,1.26673,0.35740
21.32000,15.30051,177.67504,177.67505,1.26911,0.36430
21.36000,15.35900,178.00841,178.00842,1.27149,0.36569
21.40000,15.43742,178.34163,178.34163,1.27387,0.36756
21.44000,15.64268,178.67506,178.67506,1.27625,0.37244
21.48000,15.46349,179.00822,179.00822,1.27863,0.36818
21.52000,14.98517,179.34171,179.34171,1.28101,0.35679
21.56000,14.82628,179.67490,179.67488,1.28339,0.35301
21.60000,14.94531,180.00841,180.00841,1.28577,0.35584
21.64000,15.25600,180.34153,180.34154,1.28815,0.36324
21.68000,15.15206,180.67495,180.67496,1.29054,0.36076
21.72000,15.70228,181.00835,181.00835,1.29292,0.37386
21.76000,15.42233,181.34168,181.34169,1.29530,0.36720
21.80000,15.30219,181.67507,181.67506,1.29768,0.36434
21.84000,15.62666,182.00828,182.00829,1.30006,0.37206
21.88000,15.60673,182.34173,182.34172,1.30244,0.37159
21.92000,15.62238,182.67492,182.67490,1.30482,0.37196
21.96000,15.81255,183.00848,183.00848,1.30720,0.37649
22.00000,15.64659,183.34164,183.34164,1.30958,0.37254
22.04000,16.05749,183.67502,183.67500,1.31196,0.38232
22.08000,15.91146,184.00833,184.00835,1.31435,0.37884
22.12000,15.93418,184.34155,184.34155,1.31673,0.37939
22.16000,15.91165,184.67509,184.67509,1.31911,0.37885
22.20000,15.82932,185.00821,185.00821,1.32149,0.37689
22.24000,15.73805,185.34174,185.34174,1.32387,0.37472
22.28000,15.44300,185.67484,185.67485,1.32625,0.36769
22.32000,16.37768,186.00840,186.00839,1.32863,0.38994
22.36000,16.32888,186.34173,186.34172,1.33101,0.38878
22.40000,16.30019,186.67502,186.67502,1.33339,0.38810
22.44000,16.14969,187.00835,187.00836,1.33577,0.38452
22.48000,16.49670,187.34164,187.34163,1.33815,0.39278
22.52000,16.66751,187.67511,187.67511,1.34054,0.39685
22.56000,16.31249,188.00826,188.00826,1.34292,0.38839
22.60000,16.63528,188.34179,188.34180,1.34530,0.39608
22.64000,16.70867,188.67488,188.67488,1.34768,0.39783
22.68000,16.85191,189.00835,189.00835,1.35006,0.40124
22.72000,16.64851,189.34164,189.34163,1.35244,0.39639
22.76000,16.45107,189.67500,189.67500,1.35482,0.39169
22.80000,16.37731,190.00834,190.00833,1.35720,0.38994
22.84000,16.58257,190.34162,190.34163,1.35958,0.39482
22.88000,16.70793,190.67505,190.67506,1.36196,0.39781
22.92000,17.29429,191.00825,191.00826,1.36434,0.41177
22.96000,16.89754,191.34181,191.34181,1.36673,0.40232
23.00000,17.09815,191.67492,191.67491,1.36911,0.40710
23.04000,17.24008,192.00839,192.00839,1.37149,0.41048
23.08000,17.37922,192.34159,192.34161,1.37387,0.41379
23.12000,17.15068,192.67508,192.67509,1.37625,0.40835
23.16000,17.36339,193.00837,193.00838,1.37863,0.41341
23.20000,17.11305,193.34158,193.34157,1.38101,0.40745
23.24000,17.24772,193.67507,193.67508,1.38339,0.41066
23.28000,17.59436,194.00823,194.00822,1.38577,0.41891
23.32000,17.56065,194.34179,194.34180,1.38816,0.41811
23.36000,17.47739,194.67491,194.67491,1.39054,0.41613
23.40000,17.51948,195.00837,195.00838,1.39292,0.41713
23.44000,17.61504,195.34160,195.34160,1.39530,0.41941
23.48000,17.53215,195.67499,195.67499,1.39768,0.41743
23.52000,17.59306,196.00839,196.00839,1.40006,0.41888
23.56000,17.65825,196.34162,196.34161,1.40244,0.42043
23.60000,17.80577,196.67509,196.67509,1.40482,0.42395
23.64000,17.72009,197.00822,197.00821,1.40720,0.42191
23.68000,17.92088,197.34176,197.34177,1.40958,0.42669
23.72000,17.90132,197.67493,197.67493,1.41196,0.42622
23.76000,17.69979,198.00843,198.00844,1.41435,0.42142
23.80000,17.90710,198.34165,198.34164,1.41673,0.42636
23.84000,17.85252,198.67496,198.67496,1.41911,0.42506
23.88000,17.66365,199.00841,199.00841,1.42149,0.42056
23.92000,17.75380,199.34157,199.34155,1.42387,0.42271
23.96000,17.91567,199.67503,199.67503,1.42625,0.42656
24.00000,18.15837,200.00825,200.00826,1.42863,0.43234
24.04000,17.83464,200.34173,200.34174,1.43101,0.42463
24.08000,18.00321,200.67494,200.67494,1.43339,0.42865
24.12000,18.29974,201.00837,201.00838,1.43577,0.43571
24.16000,18.29024,201.34161,201.34161,1.43815,0.43548
24.20000,18.36810,201.67502,201.67502,1.44054,0.43734
24.24000,18.44335,202.00836,202.00836,1.44292,0.43913
24.28000,18.48321,202.34165,202.34166,1.44530,0.44008
24.32000,18.51823,202.67511,202.67511,1.44768,0.44091
24.36000,18.65625,203.00821,203.00819,1.45006,0.44420
24.40000,18.71996,203.34176,203.34177,1.45244,0.44571
24.44000,18.74026,203.67492,203.67493,1.45482,0.44620
24.48000,18.43348,204.00839,204.00839,1.45720,0.43889
24.52000,18.37183,204.34162,204.34163,1.45958,0.43742
24.56000,18.18258,204.67499,204.67500,1.46196,0.43292
24.60000,18.38990,205.00830,205.00829,1.46434,0.43785
24.64000,18.83935,205.34166,205.34166,1.46673,0.44856
24.68000,18.94347,205.67503,205.67503,1.46911,0.45104
24.72000,18.99917,206.00821,206.00821,1.47149,0.45236
24.76000,19.22902,206.34178,206.34177,1.47387,0.45783
24.80000,19.07051,206.67491,206.67491,1.47625,0.45406
24.84000,19.54753,207.00845,207.00844,1.47863,0.46542
24.88000,19.30986,207.34166,207.34166,1.48101,0.45976
24.92000,19.43037,207.67501,207.67502,1.48339,0.46263
24.96000,19.45868,208.00832,208.00832,1.48577,0.46330
25.00000,19.26366,208.34161,208.34161,1.48815,0.45866
25.04000,19.43335,208.67511,208.67513,1.49054,0.46270
25.08000,19.19176,209.00827,209.00827,1.49292,0.45695
25.12000,19.50953,209.34169,209.34169,1.49530,0.46451
25.16000,19.54734,209.67492,209.67493,1.49768,0.46541
25.20000,19.44285,210.00835,210.00835,1.50006,0.46292
25.24000,19.36723,210.34164,210.34164,1.50244,0.46112
25.28000,19.09770,210.67501,210.67502,1.50482,0.45471
25.32000,19.48606,211.00837,211.00836,1.50720,0.46395
25.36000,19.77924,211.34159,211.34158,1.50958,0.47093
25.40000,19.67419,211.67511,211.67511,1.51197,0.46843
25.44000,19.99084,212.00829,212.00829,1.51434,0.47597
25.48000,19.70399,212.34178,212.34178,1.51673,0.46914
25.52000,19.68499,212.67494,212.67494,1.51911,0.46869
25.56000,19.70362,213.00837,213.00839,1.52149,0.46913
25.60000,19.98078,213.34160,213.34160,1.52387,0.47573
25.64000,19.95545,213.67501,213.67500,1.52625,0.47513
25.68000,20.12905,214.00839,214.00839,1.52863,0.47926
25.72000,20.07000,214.34159,214.34158,1.53101,0.47786
25.76000,20.02548,214.67502,214.67502,1.53339,0.47680
25.80000,20.22292,215.00827,215.00827,1.53577,0.48150
25.84000,19.97463,215.34177,215.34178,1.53816,0.47559
25.88000,20.27452,215.67485,215.67484,1.54053,0.48273
25.92000,20.16965,216.00839,216.00841,1.54292,0.48023
25.96000,20.38144,216.34158,216.34158,1.54530,0.48527
26.00000,20.09533,216.67504,216.67503,1.54768,0.47846
26.04000,20.57627,217.00841,217.00841,1.55006,0.48991
26.08000,20.57906,217.34163,217.34161,1.55244,0.48998
26.12000,20.48444,217.67510,217.67511,1.55482,0.48772
26.16000,20.37361,218.00821,218.00821,1.55720,0.48509
26.20000,20.48705,218.34178,218.34178,1.55958,0.48779
26.24000,20.66903,218.67491,218.67491,1.56196,0.49212
26.28000,20.66605,219.00837,219.00838,1.56435,0.49205
26.32000,20.33580,219.34164,219.34163,1.56673,0.48419
26.36000,20.55317,219.67500,219.67500,1.56911,0.48936
26.40000,20.49804,220.00837,220.00838,1.57149,0.48805
26.44000,20.28532,220.34161,220.34161,1.57387,0.48298
26.48000,20.81301,220.67506,220.67506,1.57625,0.49555
26.52000,21.26805,221.00824,221.00824,1.57863,0.50638
26.56000,20.92980,221.34182,221.34183,1.58101,0.49833
26.60000,21.09800,221.67496,221.67496,1.58339,0.50233
26.64000,21.25707,222.00838,222.00838,1.58577,0.50612
26.68000,21.07564,222.34169,222.34169,1.58815,0.50180
26.72000,21.39155,222.67496,222.67496,1.59054,0.50932
26.76000,21.14009,223.00841,223.00841,1.59292,0.50334
26.80000,21.13897,223.34167,223.34167,1.59530,0.50331
26.84000,20.80351,223.67509,223.67509,1.59768,0.49532
26.88000,20.73608,224.00825,224.00826,1.60006,0.49372
26.92000,20.42577,224.34175,224.34175,1.60244,0.48633
26.96000,21.01790,224.67491,224.67491,1.60482,0.50043
27.00000,21.27457,225.00841,225.00841,1.60720,0.50654
27.04000,21.19448,225.34162,225.34163,1.60958,0.50463
27.08000,21.05851,225.67499,225.67499,1.61196,0.50139
27.12000,20.85231,226.00839,226.00839,1.61435,0.49648
27.16000,21.16766,226.34162,226.34163,1.61673,0.50399
27.20000,21.48617,226.67512,226.67513,1.61911,0.51158
27.24000,21.37627,227.00823,227.00822,1.62149,0.50896
27.28000,21.68603,227.34176,227.34175,1.62387,0.51633
27.32000,21.71583,227.67497,227.67497,1.62625,0.51704
27.36000,21.68342,228.00844,228.00844,1.62863,0.51627
27.40000,21.83747,228.34163,228.34163,1.63101,0.51994
27.44000,21.90974,228.67502,228.67502,1.63339,0.52166
27.48000,21.86596,229.00837,229.00836,1.63577,0.52062
27.52000,21.51448,229.34163,229.34163,1.63815,0.51225
27.56000,21.53702,229.67513,229.67513,1.64054,0.51279
27.60000,21.82033,230.00826,230.00827,1.64292,0.51953
27.64000,22.21558,230.34176,230.34177,1.64530,0.52894
27.68000,22.35528,230.67490,230.67490,1.64768,0.53227
27.72000,22.42010,231.00840,231.00839,1.65006,0.53381
27.76000,22.58252,231.34166,231.34166,1.65244,0.53768
27.80000,22.15039,231.67500,231.67500,1.65482,0.52739
27.84000,22.57079,232.00840,232.00839,1.65720,0.53740
27.88000,22.56446,232.34161,232.34161,1.65958,0.53725
27.92000,22.77400,232.67514,232.67514,1.66197,0.54224
27.96000,22.65163,233.00830,233.00830,1.66435,0.53932
28.00000,22.11407,233.34169,233.34169,1.66673,0.52653
28.04000,22.42308,233.67493,233.67493,1.66911,0.53388
28.08000,22.71514,234.00838,234.00838,1.67149,0.54084
28.12000,22.65573,234.34164,234.34164,1.67387,0.53942
28.16000,22.59295,234.67503,234.67503,1.67625,0.53793
28.20000,23.12046,235.00835,235.00835,1.67863,0.55049
28.24000,23.11580,235.34162,235.34161,1.68101,0.55038
28.28000,23.10518,235.67509,235.67509,1.68339,0.55012
28.32000,23.15268,236.00825,236.00826,1.68577,0.55125
28.36000,22.71459,236.34180,236.34180,1.68816,0.54082
28.40000,22.89247,236.67493,236.67494,1.69054,0.54506
28.44000,23.21228,237.00841,237.00841,1.69292,0.55267
28.48000,23.35161,237.34167,237.34167,1.69530,0.55599
28.52000,22.98858,237.67504,237.67503,1.69768,0.54735
28.56000,23.04539,238.00836,238.00836,1.70006,0.54870
28.60000,23.14188,238.34165,238.34164,1.70244,0.55100
28.64000,23.10928,238.67504,238.67505,1.70482,0.55022
28.68000,23.01745,239.00826,239.00826,1.70720,0.54803
28.72000,23.09047,239.34186,239.34186,1.70958,0.54977
28.76000,23.27897,239.67484,239.67484,1.71196,0.55426
28.80000,22.87161,240.00841,240.00841,1.71435,0.54456
28.84000,23.47380,240.34163,240.34163,1.71673,0.55890
28.88000,23.73457,240.67502,240.67502,1.71911,0.56511
28.92000,23.30858,241.00842,241.00842,1.72149,0.55497
28.96000,23.51478,241.34163,241.34163,1.72387,0.55988
29.00000,23.46989,241.67510,241.67509,1.72625,0.55881
29.04000,23.48311,242.00824,242.00824,1.72863,0.55912
29.08000,23.71892,242.34181,242.34181,1.73101,0.56474
29.12000,23.67496,242.67500,242.67500,1.73339,0.56369
29.16000,23.75934,243.00839,243.00839,1.73577,0.56570
29.20000,23.62076,243.34158,243.34158,1.73815,0.56240
29.24000,24.05252,243.67503,243.67503,1.74054,0.57268
29.28000,23.99646,244.00840,244.00839,1.74292,0.57134
29.32000,23.66416,244.34161,244.34161,1.74530,0.56343
29.36000,23.80908,244.67511,244.67511,1.74768,0.56688
29.40000,24.22947,245.00822,245.00821,1.75006,0.57689
29.44000,24.32782,245.34177,245.34177,1.75244,0.57923
29.48000,24.06109,245.67498,245.67497,1.75482,0.57288
29.52000,24.27157,246.00840,246.00839,1.75720,0.57789
29.56000,24.48745,246.34164,246.34164,1.75958,0.58303
29.60000,24.25630,246.67503,246.67503,1.76196,0.57753
29.64000,24.74859,247.00840,247.00841,1.76435,0.58925
29.68000,24.46752,247.34167,247.34166,1.76673,0.58256
29.72000,24.32633,247.67511,247.67511,1.76911,0.57920
29.76000,24.54277,248.00822,248.00822,1.77149,0.58435
29.80000,24.62436,248.34175,248.34175,1.77387,0.58629
29.84000,24.34961,248.67493,248.67493,1.77625,0.57975
29.88000,24.24531,249.00846,249.00845,1.77863,0.57727
29.92000,24.35222,249.34162,249.34161,1.78101,0.57981
29.96000,24.51167,249.67501,249.67502,1.78339,0.58361
30.00000,24.76089,250.00838,250.00838,1.78577,0.58954
30.04000,24.57704,250.34157,250.34157,1.78815,0.58517
30.08000,24.91307,250.67515,250.67514,1.79054,0.59317
30.12000,25.10063,251.00825,251.00826,1.79292,0.59763
30.16000,24.87414,251.34178,251.34178,1.79530,0.59224
30.20000,24.86315,251.67494,251.67494,1.79768,0.59198
30.24000,24.74710,252.00841,252.00841,1.80006,0.58922
30.28000,24.67614,252.34168,252.34167,1.80244,0.58753
30.32000,25.25710,252.67505,252.67505,1.80482,0.60136
30.36000,24.87358,253.00839,253.00839,1.80720,0.59223
30.40000,24.78100,253.34160,253.34160,1.80958,0.59002
30.44000,25.19656,253.67507,253.67508,1.81196,0.59992
30.48000,24.80280,254.00823,254.00824,1.81434,0.59054
30.52000,6.47139,254.34178,254.34178,1.81673,0.15408
30.53900,-0.00969,254.50002,254.50002,1.81786,-0.00023