File: raw_data/mechanical_tests_Instron_data/Cast_Skin_0035_4.is_tens_RawData/Specimen_RawData_1.csv
Dimension : Area,0.42000,cm^2

Time,Load,Extension,Tensile extension,Tensile strain,Tensile stress
(sec),(N),(mm),(mm),(mm/mm),(MPa)
0.00000,0.01155,0.00000,0.00000,0.00000,0.00027
0.05000,0.85346,0.09691,0.09691,0.00069,0.02032
0.10000,0.16801,0.41092,0.41092,0.00294,0.00400
0.15000,1.39195,0.88120,0.88120,0.00629,0.03314
0.20000,1.42418,1.38854,1.38854,0.00992,0.03391
0.25000,1.57598,1.91129,1.91129,0.01365,0.03752
0.30000,1.38748,2.44283,2.44283,0.01745,0.03304
0.35000,0.97286,2.92379,2.92379,0.02088,0.02316
0.40000,1.27312,3.33619,3.33619,0.02383,0.03031
0.45000,1.46367,3.75541,3.75541,0.02682,0.03485
0.50000,1.24574,4.17461,4.17461,0.02982,0.02966
0.55000,1.42679,4.59123,4.59123,0.03279,0.03397
0.60000,0.86911,5.00807,5.00807,0.03577,0.02069
0.65000,1.19694,5.42488,5.42488,0.03875,0.02850
0.70000,0.89481,5.84153,5.84153,0.04173,0.02131
0.75000,1.14907,6.25824,6.25824,0.04470,0.02736
0.80000,0.85738,6.67492,6.67492,0.04768,0.02041
0.85000,1.20401,7.09165,7.09165,0.05065,0.02867
0.90000,1.11628,7.50838,7.50838,0.05363,0.02658
0.95000,1.39195,7.92503,7.92503,0.05661,0.03314
1.00000,1.09598,8.34176,8.34176,0.05958,0.02609
1.05000,1.10529,8.75844,8.75844,0.06256,0.02632
1.10000,1.21519,9.17507,9.17507,0.06554,0.02893
1.15000,1.39680,9.59177,9.59177,0.06851,0.03326
1.20000,1.22376,10.00842,10.00842,0.07149,0.02914
1.25000,1.60709,10.42505,10.42505,0.07446,0.03826
1.30000,1.11498,10.84165,10.84165,0.07744,0.02655
1.35000,1.13994,11.25833,11.25832,0.08042,0.02714
1.40000,0.72531,11.67495,11.67495,0.08339,0.01727
1.45000,1.20774,12.09163,12.09163,0.08637,0.02876
1.50000,1.35209,12.50823,12.50823,0.08934,0.03219
1.55000,1.54581,12.92493,12.92493,0.09232,0.03680
1.60000,1.11498,13.34156,13.34155,0.09530,0.02655
1.65000,1.10902,13.75832,13.75832,0.09827,0.02641
1.70000,1.17552,14.17491,14.17491,0.10125,0.02799
1.75000,1.33850,14.59164,14.59164,0.10423,0.03187
1.80000,1.21221,15.00838,15.00838,0.10720,0.02886
1.85000,1.28672,15.42506,15.42506,0.11018,0.03064
1.90000,1.39214,15.84171,15.84171,0.11316,0.03315
1.95000,1.11274,16.25841,16.25841,0.11613,0.02649
2.00000,1.61137,16.67512,16.67512,0.11911,0.03837
2.05000,1.21482,17.09177,17.09177,0.12208,0.02892
2.10000,1.43498,17.50834,17.50834,0.12506,0.03417
2.15000,1.31149,17.92505,17.92505,0.12804,0.03123
2.20000,0.92685,18.34172,18.34172,0.13101,0.02207
2.25000,1.43312,18.75832,18.75832,0.13399,0.03412
2.30000,1.48378,19.17497,19.17497,0.13696,0.03533
2.35000,1.12057,19.59152,19.59152,0.13994,0.02668
2.40000,1.15018,20.00830,20.00830,0.14292,0.02739
2.45000,1.10604,20.42490,20.42490,0.14589,0.02633
2.50000,0.95349,20.84158,20.84158,0.14887,0.02270
2.55000,1.14553,21.25826,21.25826,0.15184,0.02727
2.60000,1.09859,21.67494,21.67494,0.15482,0.02616
2.65000,1.34464,22.09159,22.09159,0.15780,0.03202
2.70000,1.18669,22.50832,22.50832,0.16077,0.02825
2.75000,0.98255,22.92505,22.92505,0.16375,0.02339
2.80000,1.34818,23.34181,23.34181,0.16673,0.03210
2.85000,1.13528,23.75846,23.75846,0.16970,0.02703
2.90000,0.72718,24.17509,24.17509,0.17268,0.01731
2.95000,0.87023,24.59179,24.59179,0.17566,0.02072
3.00000,1.19805,25.00842,25.00842,0.17863,0.02853
3.05000,0.62510,25.42510,25.42510,0.18161,0.01488
3.10000,0.56997,25.84159,25.84159,0.18458,0.01357
3.15000,0.66403,26.25835,26.25834,0.18756,0.01581
3.20000,0.30994,26.67497,26.67497,0.19054,0.00738
3.25000,0.59213,27.09157,27.09157,0.19351,0.01410
3.30000,0.50757,27.50819,27.50819,0.19649,0.01209
3.35000,0.73165,27.92495,27.92495,0.19946,0.01742
3.40000,0.56308,28.34160,28.34160,0.20244,0.01341
3.45000,0.43288,28.75826,28.75826,0.20542,0.01031
3.50000,1.00397,29.17493,29.17493,0.20839,0.02390
3.55000,0.47367,29.59167,29.59167,0.21137,0.01128
3.60000,0.91102,30.00840,30.00840,0.21435,0.02169
3.65000,0.42357,30.42502,30.42502,0.21732,0.01008
3.70000,0.81118,30.84173,30.84173,0.22030,0.01931
3.75000,0.79907,31.25840,31.25840,0.22327,0.01903
3.80000,-0.42431,31.67503,31.67503,0.22625,-0.01010
3.85000,0.46026,32.09176,32.09176,0.22923,0.01096
3.90000,0.49975,32.50844,32.50844,0.23220,0.01190
3.95000,0.38240,32.92512,32.92512,0.23518,0.00910
4.00000,0.62566,33.34169,33.34169,0.23815,0.01490
4.05000,0.76499,33.75834,33.75834,0.24113,0.01821
4.10000,0.56140,34.17494,34.17494,0.24411,0.01337
4.15000,1.02390,34.59162,34.59162,0.24708,0.02438
4.20000,0.78250,35.00824,35.00825,0.25006,0.01863
4.25000,0.75828,35.42492,35.42492,0.25304,0.01805
4.30000,0.46194,35.84152,35.84151,0.25601,0.01100
4.35000,1.05295,36.25828,36.25828,0.25899,0.02507
4.40000,0.87712,36.67490,36.67490,0.26196,0.02088
4.45000,0.79814,37.09166,37.09167,0.26494,0.01900
4.50000,0.82608,37.50837,37.50837,0.26792,0.01967
4.55000,0.73705,37.92507,37.92507,0.27089,0.01755
4.60000,0.99372,38.34170,38.34170,0.27387,0.02366
4.65000,0.91679,38.75840,38.75841,0.27685,0.02183
4.70000,1.10362,39.17513,39.17513,0.27982,0.02628
4.75000,0.79181,39.59176,39.59176,0.28280,0.01885
4.80000,0.64448,40.00838,40.00838,0.28577,0.01534
4.85000,0.94734,40.42504,40.42504,0.28875,0.02256
4.90000,1.22059,40.84171,40.84171,0.29173,0.02906
4.95000,0.85291,41.25834,41.25834,0.29470,0.02031
5.00000,0.84210,41.67496,41.67496,0.29768,0.02005
5.05000,1.06860,42.09156,42.09156,0.30065,0.02544
5.10000,1.20457,42.50832,42.50832,0.30363,0.02868
5.15000,1.13118,42.92484,42.92484,0.30661,0.02693
5.20000,1.17067,43.34160,43.34160,0.30958,0.02787
5.25000,1.09002,43.75827,43.75827,0.31256,0.02595
5.30000,1.04774,44.17498,44.17498,0.31554,0.02495
5.35000,1.13212,44.59163,44.59163,0.31851,0.02696
5.40000,1.12224,45.00836,45.00837,0.32149,0.02672
5.45000,0.96597,45.42504,45.42504,0.32446,0.02300
5.50000,1.31708,45.84177,45.84177,0.32744,0.03136
5.55000,1.36718,46.25840,46.25840,0.33042,0.03255
5.60000,1.22003,46.67510,46.67510,0.33339,0.02905
5.65000,1.44318,47.09176,47.09175,0.33637,0.03436
5.70000,1.54451,47.50843,47.50843,0.33935,0.03677
5.75000,1.33961,47.92506,47.92506,0.34232,0.03190
5.80000,1.50520,48.34163,48.34163,0.34530,0.03584
5.85000,1.45976,48.75836,48.75836,0.34827,0.03476
5.90000,1.26511,49.17493,49.17493,0.35125,0.03012
5.95000,1.11070,49.59159,49.59158,0.35423,0.02645
6.00000,1.39941,50.00824,50.00824,0.35720,0.03332
6.05000,1.03191,50.42494,50.42494,0.36018,0.02457
6.10000,1.10157,50.84162,50.84162,0.36315,0.02623
6.15000,1.67452,51.25822,51.25822,0.36613,0.03987
6.20000,1.27032,51.67492,51.67492,0.36911,0.03025
6.25000,1.67415,52.09168,52.09168,0.37208,0.03986
6.30000,1.74716,52.50836,52.50836,0.37506,0.04160
6.35000,1.56872,52.92501,52.92501,0.37804,0.03735
6.40000,1.88649,53.34172,53.34172,0.38101,0.04492
6.45000,1.76001,53.75847,53.75847,0.38399,0.04191
6.50000,1.38283,54.17510,54.17510,0.38697,0.03292
6.55000,1.49645,54.59175,54.59175,0.38994,0.03563
6.60000,1.48397,55.00843,55.00843,0.39292,0.03533
6.65000,1.64974,55.42506,55.42506,0.39589,0.03928
6.70000,1.70432,55.84168,55.84168,0.39887,0.04058
6.75000,1.80658,56.25830,56.25830,0.40185,0.04301
6.80000,1.67675,56.67493,56.67493,0.40482,0.03992
6.85000,1.99527,57.09161,57.09161,0.40780,0.04751
6.90000,1.56518,57.50823,57.50823,0.41077,0.03727
6.95000,1.89692,57.92489,57.92488,0.41375,0.04516
7.00000,1.79764,58.34159,58.34159,0.41673,0.04280
7.05000,1.90698,58.75829,58.75829,0.41970,0.04540
7.10000,2.25101,59.17497,59.17497,0.42268,0.05360
7.15000,2.18526,59.59162,59.59163,0.42565,0.05203
7.20000,2.19233,60.00833,60.00833,0.42863,0.05220
7.25000,2.37413,60.42512,60.42512,0.43161,0.05653
7.30000,2.25194,60.84174,60.84174,0.43458,0.05362
7.35000,2.50656,61.25839,61.25839,0.43756,0.05968
7.40000,2.35867,61.67507,61.67507,0.44054,0.05616
7.45000,2.05692,62.09177,62.09177,0.44351,0.04897
7.50000,2.41045,62.50840,62.50840,0.44649,0.05739
7.55000,2.24896,62.92505,62.92505,0.44946,0.05355
7.60000,2.53804,63.34170,63.34171,0.45244,0.06043
7.65000,2.23480,63.75838,63.75838,0.45542,0.05321
7.70000,2.70661,64.17495,64.17495,0.45839,0.06444
7.75000,2.49110,64.59160,64.59161,0.46137,0.05931
7.80000,2.25455,65.00829,65.00829,0.46434,0.05368
7.85000,2.70158,65.42487,65.42487,0.46732,0.06432
7.90000,2.53431,65.84159,65.84158,0.47030,0.06034
7.95000,2.73231,66.25821,66.25821,0.47327,0.06506
8.00000,2.42200,66.67497,66.67496,0.47625,0.05767
8.05000,2.91914,67.09165,67.09164,0.47923,0.06950
8.10000,2.66638,67.50835,67.50835,0.48220,0.06349
8.15000,3.08678,67.92506,67.92506,0.48518,0.07349
8.20000,2.82899,68.34171,68.34171,0.48816,0.06736
8.25000,2.55462,68.75844,68.75844,0.49113,0.06082
8.30000,2.71089,69.17515,69.17515,0.49411,0.06455
8.35000,2.71220,69.59174,69.59174,0.49708,0.06458
8.40000,2.41790,70.00845,70.00845,0.50006,0.05757
8.45000,2.58200,70.42505,70.42506,0.50304,0.06148
8.50000,2.63229,70.84167,70.84167,0.50601,0.06267
8.55000,2.77068,71.25835,71.25835,0.50899,0.06597
8.60000,2.45553,71.67495,71.67494,0.51196,0.05846
8.65000,2.73157,72.09160,72.09160,0.51494,0.06504
8.70000,2.76491,72.50822,72.50822,0.51792,0.06583
8.75000,2.66917,72.92493,72.92492,0.52089,0.06355
8.80000,2.42982,73.34158,73.34158,0.52387,0.05785
8.85000,2.44547,73.75827,73.75826,0.52684,0.05823
8.90000,2.40561,74.17494,74.17493,0.52982,0.05728
8.95000,2.09585,74.59170,74.59170,0.53280,0.04990
9.00000,2.60696,75.00837,75.00837,0.53577,0.06207
9.05000,2.16793,75.42506,75.42506,0.53875,0.05162
9.10000,2.39369,75.84170,75.84171,0.54173,0.05699
9.15000,2.69562,76.25849,76.25850,0.54470,0.06418
9.20000,2.75299,76.67504,76.67505,0.54768,0.06555
9.25000,2.69581,77.09177,77.09177,0.55066,0.06419
9.30000,2.42293,77.50842,77.50842,0.55363,0.05769
9.35000,2.33613,77.92508,77.92508,0.55661,0.05562
9.40000,2.59820,78.34167,78.34167,0.55958,0.06186
9.45000,2.76435,78.75832,78.75831,0.56256,0.06582
9.50000,3.00631,79.17497,79.17496,0.56554,0.07158
9.55000,2.77143,79.59165,79.59165,0.56851,0.06599
9.60000,2.71685,80.00825,80.00826,0.57149,0.06469
9.65000,2.93516,80.42487,80.42487,0.57446,0.06988
9.70000,2.57418,80.84158,80.84159,0.57744,0.06129
9.75000,2.75671,81.25826,81.25825,0.58042,0.06564
9.80000,3.17525,81.67496,81.67496,0.58339,0.07560
9.85000,2.86084,82.09159,82.09158,0.58637,0.06812
9.90000,3.04226,82.50837,82.50838,0.58935,0.07243
9.95000,3.34140,82.92505,82.92505,0.59232,0.07956
10.00000,3.19947,83.34173,83.34174,0.59530,0.07618
10.05000,3.05567,83.75843,83.75842,0.59827,0.07275
10.10000,2.75802,84.17514,84.17514,0.60125,0.06567
10.15000,2.97464,84.59179,84.59179,0.60423,0.07082
10.20000,2.82340,85.00842,85.00842,0.60720,0.06722
10.25000,3.01134,85.42499,85.42499,0.61018,0.07170
10.30000,2.74424,85.84172,85.84172,0.61316,0.06534
10.35000,2.87388,86.25837,86.25836,0.61613,0.06843
10.40000,3.10261,86.67488,86.67488,0.61911,0.07387
10.45000,2.72971,87.09159,87.09159,0.62208,0.06499
10.50000,2.90163,87.50824,87.50824,0.62506,0.06909
10.55000,3.18252,87.92493,87.92493,0.62804,0.07577
10.60000,2.78410,88.34157,88.34158,0.63101,0.06629
10.65000,2.84649,88.75828,88.75827,0.63399,0.06777
10.70000,2.47695,89.17498,89.17498,0.63696,0.05897
10.75000,2.65278,89.59163,89.59164,0.63994,0.06316
10.80000,2.95267,90.00836,90.00835,0.64292,0.07030
10.85000,2.79583,90.42505,90.42505,0.64589,0.06657
10.90000,3.17767,90.84175,90.84176,0.64887,0.07566
10.95000,2.82731,91.25843,91.25843,0.65185,0.06732
11.00000,3.62974,91.67508,91.67509,0.65482,0.08642
11.05000,3.55560,92.09174,92.09174,0.65780,0.08466
11.10000,4.18518,92.50847,92.50847,0.66077,0.09965
11.15000,4.14755,92.92504,92.92504,0.66375,0.09875
11.20000,4.04231,93.34171,93.34171,0.66673,0.09625
11.25000,3.82643,93.75829,93.75829,0.66970,0.09111
11.30000,4.29116,94.17502,94.17503,0.67268,0.10217
11.35000,4.05423,94.59159,94.59159,0.67565,0.09653
11.40000,3.72101,95.00821,95.00820,0.67863,0.08860
11.45000,3.83407,95.42492,95.42492,0.68161,0.09129
11.50000,4.20995,95.84160,95.84161,0.68458,0.10024
11.55000,4.27347,96.25825,96.25826,0.68756,0.10175
11.60000,4.31575,96.67490,96.67490,0.69054,0.10276
11.65000,4.08180,97.09166,97.09165,0.69351,0.09719
11.70000,4.24087,97.50834,97.50834,0.69649,0.10097
11.75000,4.37330,97.92504,97.92504,0.69946,0.10413
11.80000,4.61154,98.34172,98.34172,0.70244,0.10980
11.85000,4.62644,98.75851,98.75850,0.70542,0.11015
11.90000,5.02001,99.17508,99.17509,0.70839,0.11952
11.95000,4.54895,99.59178,99.59178,0.71137,0.10831
12.00000,4.30830,100.00838,100.00838,0.71435,0.10258
12.05000,4.18574,100.42509,100.42509,0.71732,0.09966
12.10000,4.33717,100.84168,100.84168,0.72030,0.10327
12.15000,4.68865,101.25832,101.25832,0.72327,0.11163
12.20000,4.27403,101.67493,101.67493,0.72625,0.10176
12.25000,4.63463,102.09153,102.09155,0.72923,0.11035
12.30000,4.53182,102.50824,102.50824,0.73220,0.10790
12.35000,4.54504,102.92492,102.92492,0.73518,0.10822
12.40000,4.62215,103.34162,103.34163,0.73815,0.11005
12.45000,4.21610,103.75827,103.75828,0.74113,0.10038
12.50000,4.96898,104.17498,104.17498,0.74411,0.11831
12.55000,4.83301,104.59162,104.59162,0.74708,0.11507
12.60000,4.52399,105.00839,105.00838,0.75006,0.10771
12.65000,4.48935,105.42504,105.42504,0.75304,0.10689
12.70000,4.64302,105.84174,105.84174,0.75601,0.11055
12.75000,4.59868,106.25836,106.25836,0.75899,0.10949
12.80000,4.81475,106.67510,106.67511,0.76197,0.11464
12.85000,5.02989,107.09178,107.09178,0.76494,0.11976
12.90000,4.79873,107.50841,107.50840,0.76792,0.11426
12.95000,4.82574,107.92503,107.92503,0.77089,0.11490
13.00000,4.78327,108.34174,108.34174,0.77387,0.11389
13.05000,4.34034,108.75834,108.75834,0.77685,0.10334
13.10000,4.70765,109.17499,109.17499,0.77982,0.11209
13.15000,4.76278,109.59161,109.59161,0.78280,0.11340
13.20000,4.43384,110.00829,110.00829,0.78577,0.10557
13.25000,4.54430,110.42491,110.42491,0.78875,0.10820
13.30000,4.40367,110.84149,110.84149,0.79172,0.10485
13.35000,4.24217,111.25830,111.25829,0.79470,0.10100
13.40000,4.38485,111.67498,111.67498,0.79768,0.10440
13.45000,4.20604,112.09163,112.09163,0.80065,0.10014
13.50000,4.34481,112.50834,112.50834,0.80363,0.10345
13.55000,4.07230,112.92506,112.92506,0.80661,0.09696
13.60000,4.71063,113.34177,113.34177,0.80958,0.11216
13.65000,4.12278,113.75844,113.75845,0.81256,0.09816
13.70000,4.66462,114.17510,114.17510,0.81554,0.11106
13.75000,4.76837,114.59178,114.59177,0.81851,0.11353
13.80000,4.97233,115.00842,115.00842,0.82149,0.11839
13.85000,4.62104,115.42505,115.42506,0.82446,0.11002
13.90000,4.30215,115.84167,115.84167,0.82744,0.10243
13.95000,4.71771,116.25831,116.25831,0.83042,0.11233
14.00000,4.72832,116.67498,116.67498,0.83339,0.11258
14.05000,4.71286,117.09156,117.09156,0.83637,0.11221
14.10000,4.72032,117.50823,117.50823,0.83934,0.11239
14.15000,4.83505,117.92493,117.92493,0.84232,0.11512
14.20000,4.55137,118.34161,118.34161,0.84530,0.10837
14.25000,4.41615,118.75827,118.75827,0.84827,0.10515
14.30000,4.44949,119.17489,119.17489,0.85125,0.10594
14.35000,4.80730,119.59171,119.59171,0.85423,0.11446
14.40000,4.65512,120.00838,120.00838,0.85720,0.11084
14.45000,4.24590,120.42504,120.42504,0.86018,0.10109
14.50000,4.57969,120.84171,120.84171,0.86316,0.10904
14.55000,4.66481,121.25847,121.25848,0.86613,0.11107
14.60000,4.70635,121.67509,121.67509,0.86911,0.11206
14.65000,4.42453,122.09175,122.09175,0.87208,0.10535
14.70000,4.15798,122.50837,122.50837,0.87506,0.09900
14.75000,4.57857,122.92513,122.92513,0.87804,0.10901
14.80000,4.61750,123.34168,123.34167,0.88101,0.10994
14.85000,4.56814,123.75833,123.75833,0.88399,0.10877
14.90000,4.34183,124.17495,124.17496,0.88696,0.10338
14.95000,4.47836,124.59163,124.59163,0.88994,0.10663
15.00000,4.30383,125.00826,125.00826,0.89292,0.10247
15.05000,4.38839,125.42492,125.42492,0.89589,0.10449
15.10000,4.13936,125.84156,125.84156,0.89887,0.09856
15.15000,4.74658,126.25829,126.25829,0.90184,0.11301
15.20000,4.53107,126.67495,126.67495,0.90482,0.10788
15.25000,4.42993,127.09166,127.09166,0.90780,0.10547
15.30000,4.46178,127.50832,127.50832,0.91077,0.10623
15.35000,4.57019,127.92505,127.92506,0.91375,0.10881
15.40000,4.37107,128.34179,128.34180,0.91673,0.10407
15.45000,4.54392,128.75844,128.75844,0.91970,0.10819
15.50000,4.63668,129.17512,129.17513,0.92268,0.11040
15.55000,4.26583,129.59177,129.59177,0.92566,0.10157
15.60000,4.26304,130.00843,130.00842,0.92863,0.10150
15.65000,4.57671,130.42503,130.42503,0.93161,0.10897
15.70000,4.51058,130.84176,130.84175,0.93458,0.10739
15.75000,4.90118,131.25832,131.25833,0.93756,0.11669
15.80000,4.76185,131.67496,131.67496,0.94054,0.11338
15.85000,4.76297,132.09151,132.09151,0.94351,0.11340
15.90000,4.53014,132.50830,132.50830,0.94649,0.10786
15.95000,4.60409,132.92491,132.92491,0.94946,0.10962
16.00000,4.21032,133.34159,133.34160,0.95244,0.10025
16.05000,4.58714,133.75828,133.75827,0.95542,0.10922
16.10000,4.43291,134.17499,134.17499,0.95839,0.10555
16.15000,4.82928,134.59167,134.59167,0.96137,0.11498
16.20000,4.94942,135.00836,135.00836,0.96435,0.11784
16.25000,4.56795,135.42506,135.42505,0.96732,0.10876
16.30000,4.92111,135.84177,135.84177,0.97030,0.11717
16.35000,4.85647,136.25836,136.25836,0.97327,0.11563
16.40000,5.07291,136.67510,136.67509,0.97625,0.12078
16.45000,4.91906,137.09179,137.09180,0.97923,0.11712
16.50000,4.65531,137.50841,137.50841,0.98220,0.11084
16.55000,4.78942,137.92506,137.92506,0.98518,0.11403
16.60000,4.56125,138.34167,138.34166,0.98815,0.10860
16.65000,4.87641,138.75837,138.75836,0.99113,0.11610
16.70000,4.64749,139.17500,139.17500,0.99411,0.11065
16.75000,4.64711,139.59159,139.59160,0.99708,0.11065
16.80000,4.98034,140.00825,140.00826,1.00006,0.11858
16.85000,4.67449,140.42492,140.42493,1.00304,0.11130
16.90000,4.64488,140.84158,140.84158,1.00601,0.11059
16.95000,4.86746,141.25823,141.25822,1.00899,0.11589
17.00000,5.17350,141.67489,141.67488,1.01196,0.12318
17.05000,4.86188,142.09166,142.09167,1.01494,0.11576
17.10000,4.36194,142.50837,142.50838,1.01792,0.10386
17.15000,5.08763,142.92504,142.92505,1.02089,0.12113
17.20000,4.77079,143.34178,143.34178,1.02387,0.11359
17.25000,4.96693,143.75847,143.75847,1.02685,0.11826
17.30000,5.16679,144.17516,144.17517,1.02982,0.12302
17.35000,4.94383,144.59168,144.59167,1.03280,0.11771
17.40000,5.05559,145.00843,145.00842,1.03577,0.12037
17.45000,5.19603,145.42509,145.42509,1.03875,0.12372
17.50000,5.03920,145.84170,145.84169,1.04173,0.11998
17.55000,5.11426,146.25826,146.25827,1.04470,0.12177
17.60000,4.78197,146.67491,146.67491,1.04768,0.11386
17.65000,4.58919,147.09162,147.09161,1.05065,0.10927
17.70000,4.58006,147.50827,147.50827,1.05363,0.10905
17.75000,5.45513,147.92492,147.92494,1.05661,0.12988
17.80000,5.12265,148.34161,148.34161,1.05958,0.12197
17.85000,4.86709,148.75832,148.75833,1.06256,0.11588
17.90000,5.29941,149.17497,149.17497,1.06554,0.12618
17.95000,5.02393,149.59166,149.59166,1.06851,0.11962
18.00000,5.15319,150.00835,150.00836,1.07149,0.12270
18.05000,4.75775,150.42507,150.42508,1.07446,0.11328
18.10000,5.07217,150.84172,150.84172,1.07744,0.12077
18.15000,5.18244,151.25840,151.25841,1.08042,0.12339
18.20000,5.00698,151.67511,151.67511,1.08339,0.11921
18.25000,5.00940,152.09176,152.09177,1.08637,0.11927
18.30000,5.41452,152.50842,152.50842,1.08935,0.12892
18.35000,5.54491,152.92501,152.92502,1.09232,0.13202
18.40000,5.09005,153.34172,153.34172,1.09530,0.12119
18.45000,5.11799,153.75837,153.75836,1.09827,0.12186
18.50000,5.20255,154.17499,154.17499,1.10125,0.12387
18.55000,5.28954,154.59154,154.59154,1.10423,0.12594
18.60000,5.21243,155.00829,155.00830,1.10720,0.12411
18.65000,4.99561,155.42490,155.42490,1.11018,0.11894
18.70000,5.33834,155.84160,155.84160,1.11315,0.12710
18.75000,4.99934,156.25822,156.25822,1.11613,0.11903
18.80000,5.23832,156.67499,156.67499,1.11911,0.12472
18.85000,5.04013,157.09164,157.09164,1.12208,0.12000
18.90000,5.29103,157.50836,157.50836,1.12506,0.12598
18.95000,5.28786,157.92505,157.92505,1.12804,0.12590
19.00000,5.40689,158.34180,158.34178,1.13101,0.12874
19.05000,5.61196,158.75842,158.75842,1.13399,0.13362
19.10000,5.43017,159.17510,159.17511,1.13697,0.12929
19.15000,5.46910,159.59179,159.59178,1.13994,0.13022
19.20000,5.32586,160.00843,160.00844,1.14292,0.12681
19.25000,5.77979,160.42505,160.42505,1.14589,0.13761
19.30000,5.50728,160.84165,160.84164,1.14887,0.13113
19.35000,5.44228,161.25833,161.25833,1.15185,0.12958
19.40000,5.46239,161.67491,161.67491,1.15482,0.13006
19.45000,5.49052,162.09164,162.09164,1.15780,0.13073
19.50000,5.72130,162.50824,162.50824,1.16077,0.13622
19.55000,5.89062,162.92494,162.92494,1.16375,0.14025
19.60000,5.71944,163.34159,163.34158,1.16673,0.13618
19.65000,5.64493,163.75827,163.75827,1.16970,0.13440
19.70000,5.90645,164.17496,164.17496,1.17268,0.14063
19.75000,5.61271,164.59171,164.59171,1.17566,0.13364
19.80000,5.84014,165.00839,165.00841,1.17863,0.13905
19.85000,5.80251,165.42504,165.42502,1.18161,0.13816
19.90000,5.96624,165.84170,165.84169,1.18458,0.14205
19.95000,5.97015,166.25847,166.25847,1.18756,0.14215
20.00000,6.16014,166.67513,166.67513,1.19054,0.14667
20.05000,6.06049,167.09170,167.09169,1.19351,0.14430
20.10000,5.82561,167.50844,167.50844,1.19649,0.13870
20.15000,5.80717,167.92506,167.92505,1.19946,0.13827
20.20000,5.85318,168.34173,168.34172,1.20244,0.13936
20.25000,5.99790,168.75836,168.75838,1.20542,0.14281
20.30000,6.70273,169.17499,169.17500,1.20839,0.15959
20.35000,6.13648,169.59165,169.59166,1.21137,0.14611
20.40000,6.01150,170.00821,170.00822,1.21434,0.14313
20.45000,6.56545,170.42492,170.42491,1.21732,0.15632
20.50000,6.10836,170.84160,170.84161,1.22030,0.14544
20.55000,6.27432,171.25826,171.25826,1.22327,0.14939
20.60000,6.50063,171.67489,171.67490,1.22625,0.15478
20.65000,5.94668,172.09159,172.09160,1.22923,0.14159
20.70000,6.47400,172.50834,172.50835,1.23220,0.15414
20.75000,6.35143,172.92512,172.92513,1.23518,0.15122
20.80000,6.40750,173.34178,173.34180,1.23816,0.15256
20.85000,6.58408,173.75848,173.75848,1.24113,0.15676
20.90000,6.80331,174.17515,174.17514,1.24411,0.16198
20.95000,6.49430,174.59181,174.59181,1.24708,0.15463
21.00000,6.34156,175.00843,175.00842,1.25006,0.15099
21.05000,6.82641,175.42503,175.42503,1.25304,0.16253
21.10000,6.85733,175.84172,175.84174,1.25601,0.16327
21.15000,6.74315,176.25834,176.25833,1.25899,0.16055
21.20000,6.42706,176.67493,176.67494,1.26196,0.15303
21.25000,6.42780,177.09158,177.09158,1.26494,0.15304
21.30000,6.88937,177.50831,177.50832,1.26792,0.16403
21.35000,6.83703,177.92493,177.92493,1.27089,0.16279
21.40000,6.72787,178.34159,178.34160,1.27387,0.16019
21.45000,6.86254,178.75824,178.75822,1.27684,0.16339
21.50000,6.94934,179.17505,179.17503,1.27982,0.16546
21.55000,6.94506,179.59167,179.59167,1.28280,0.16536
21.60000,6.67702,180.00833,180.00833,1.28577,0.15898
21.65000,6.74091,180.42502,180.42503,1.28875,0.16050
21.70000,6.38757,180.84177,180.84177,1.29173,0.15208
21.75000,6.33784,181.25836,181.25836,1.29470,0.15090
21.80000,6.63865,181.67507,181.67506,1.29768,0.15806
21.85000,6.68820,182.09176,182.09175,1.30066,0.15924
21.90000,7.05048,182.50851,182.50850,1.30363,0.16787
21.95000,7.16783,182.92505,182.92505,1.30661,0.17066
22.00000,6.99330,183.34173,183.34174,1.30958,0.16651
22.05000,7.50571,183.75839,183.75839,1.31256,0.17871
22.10000,7.22688,184.17497,184.17497,1.31554,0.17207
22.15000,7.23861,184.59163,184.59163,1.31851,0.17235
22.20000,7.16876,185.00821,185.00821,1.32149,0.17068
22.25000,7.23843,185.42494,185.42494,1.32446,0.17234
22.30000,7.33417,185.84155,185.84155,1.32744,0.17462
22.35000,6.88881,186.25827,186.25827,1.33042,0.16402
22.40000,6.95288,186.67495,186.67496,1.33339,0.16554
22.45000,6.93016,187.09164,187.09163,1.33637,0.16500
22.50000,7.21179,187.50840,187.50839,1.33935,0.17171
22.55000,7.32727,187.92508,187.92508,1.34232,0.17446
22.60000,7.29673,188.34172,188.34172,1.34530,0.17373
22.65000,7.45691,188.75851,188.75850,1.34828,0.17755
22.70000,7.33268,189.17510,189.17508,1.35125,0.17459
22.75000,7.79349,189.59177,189.59177,1.35423,0.18556
22.80000,7.17584,190.00839,190.00839,1.35720,0.17085
22.85000,7.30380,190.42508,190.42508,1.36018,0.17390
22.90000,7.52527,190.84170,190.84169,1.36316,0.17917
22.95000,7.42134,191.25831,191.25832,1.36613,0.17670
23.00000,7.29859,191.67495,191.67494,1.36911,0.17378
23.05000,7.55060,192.09162,192.09161,1.37208,0.17978
23.10000,7.82404,192.50824,192.50824,1.37506,0.18629
23.15000,7.57836,192.92490,192.92490,1.37803,0.18044
23.20000,7.58022,193.34161,193.34161,1.38101,0.18048
23.25000,7.76201,193.75829,193.75830,1.38399,0.18481
23.30000,7.73706,194.17498,194.17497,1.38696,0.18422
23.35000,7.46828,194.59162,194.59163,1.38994,0.17782
23.40000,7.84267,195.00840,195.00841,1.39292,0.18673
23.45000,7.42506,195.42503,195.42503,1.39589,0.17679
23.50000,7.67242,195.84174,195.84175,1.39887,0.18268
23.55000,8.00230,196.25843,196.25842,1.40185,0.19053
23.60000,7.66329,196.67511,196.67511,1.40482,0.18246
23.65000,7.86651,197.09173,197.09172,1.40780,0.18730
23.70000,7.97343,197.50842,197.50844,1.41077,0.18984
23.75000,8.33515,197.92506,197.92505,1.41375,0.19846
23.80000,7.89799,198.34172,198.34172,1.41673,0.18805
23.85000,7.85496,198.75837,198.75836,1.41970,0.18702
23.90000,8.00118,199.17496,199.17496,1.42268,0.19050
23.95000,8.30814,199.59160,199.59160,1.42565,0.19781
24.00000,7.79703,200.00825,200.00826,1.42863,0.18564
24.05000,7.74451,200.42495,200.42496,1.43161,0.18439
24.10000,7.89147,200.84156,200.84155,1.43458,0.18789
24.15000,7.87862,201.25826,201.25826,1.43756,0.18759
24.20000,8.03024,201.67497,201.67499,1.44054,0.19120
24.25000,8.05035,202.09164,202.09164,1.44351,0.19168
24.30000,8.23513,202.50834,202.50833,1.44649,0.19607
24.35000,8.41562,202.92507,202.92508,1.44946,0.20037
24.40000,8.37967,203.34181,203.34180,1.45244,0.19952
24.45000,8.69725,203.75843,203.75844,1.45542,0.20708
24.50000,8.61082,204.17508,204.17508,1.45839,0.20502
24.55000,8.43462,204.59179,204.59178,1.46137,0.20082
24.60000,8.48342,205.00847,205.00848,1.46435,0.20199
24.65000,8.40295,205.42501,205.42502,1.46732,0.20007
24.70000,8.04849,205.84169,205.84171,1.47030,0.19163
24.75000,8.23904,206.25829,206.25830,1.47327,0.19617
24.80000,8.37129,206.67498,206.67497,1.47625,0.19932
24.85000,8.58754,207.09160,207.09161,1.47923,0.20447
24.90000,8.52253,207.50824,207.50824,1.48220,0.20292
24.95000,8.33888,207.92495,207.92496,1.48518,0.19854
25.00000,9.12119,208.34161,208.34161,1.48815,0.21717
25.05000,8.85930,208.75830,208.75830,1.49113,0.21094
25.10000,8.83546,209.17496,209.17497,1.49411,0.21037
25.15000,8.67564,209.59167,209.59167,1.49708,0.20656
25.20000,8.88500,210.00837,210.00836,1.50006,0.21155
25.25000,8.90791,210.42504,210.42503,1.50304,0.21209
25.30000,8.97665,210.84170,210.84169,1.50601,0.21373
25.35000,8.58009,211.25845,211.25844,1.50899,0.20429
25.40000,8.80901,211.67505,211.67505,1.51196,0.20974
25.45000,9.21302,212.09178,212.09177,1.51494,0.21936
25.50000,9.09138,212.50836,212.50836,1.51792,0.21646
25.55000,9.37302,212.92515,212.92514,1.52089,0.22317
25.60000,8.82298,213.34170,213.34171,1.52387,0.21007
25.65000,9.42517,213.75835,213.75835,1.52685,0.22441
25.70000,9.40431,214.17497,214.17497,1.52982,0.22391
25.75000,9.36221,214.59161,214.59161,1.53280,0.22291
25.80000,9.49856,215.00823,215.00822,1.53577,0.22616
25.85000,8.95225,215.42489,215.42490,1.53875,0.21315
25.90000,9.17297,215.84160,215.84160,1.54173,0.21840
25.95000,9.36612,216.25829,216.25829,1.54470,0.22300
26.00000,9.52613,216.67493,216.67493,1.54768,0.22681
26.05000,9.56785,217.09163,217.09163,1.55065,0.22781
26.10000,9.60547,217.50845,217.50845,1.55363,0.22870
26.15000,9.08729,217.92504,217.92505,1.55661,0.21636
26.20000,9.52221,218.34178,218.34178,1.55958,0.22672
26.25000,9.62652,218.75840,218.75839,1.56256,0.22920
26.30000,10.02345,219.17516,219.17516,1.56554,0.23865
26.35000,9.65111,219.59177,219.59177,1.56851,0.22979
26.40000,9.36054,220.00843,220.00842,1.57149,0.22287
26.45000,9.49539,220.42503,220.42503,1.57446,0.22608
26.50000,9.63211,220.84169,220.84169,1.57744,0.22934
26.55000,9.95733,221.25835,221.25835,1.58042,0.23708
26.60000,9.98117,221.67496,221.67496,1.58339,0.23765
26.65000,9.90015,222.09162,222.09161,1.58637,0.23572
26.70000,10.33079,222.50827,222.50827,1.58934,0.24597
26.75000,10.21754,222.92493,222.92493,1.59232,0.24327
26.80000,9.91486,223.34157,223.34157,1.59530,0.23607
26.85000,10.28031,223.75830,223.75830,1.59827,0.24477
26.90000,10.46006,224.17496,224.17496,1.60125,0.24905
26.95000,10.31868,224.59167,224.59167,1.60423,0.24568
27.00000,10.38928,225.00831,225.00830,1.60720,0.24736
27.05000,9.81595,225.42504,225.42505,1.61018,0.23371
27.10000,10.02457,225.84178,225.84178,1.61316,0.23868
27.15000,10.60218,226.25846,226.25847,1.61613,0.25243
27.20000,10.64651,226.67507,226.67506,1.61911,0.25349
27.25000,10.57219,227.09178,227.09178,1.62208,0.25172
27.30000,10.51538,227.50844,227.50844,1.62506,0.25037
27.35000,10.62434,227.92505,227.92505,1.62804,0.25296
27.40000,10.72045,228.34171,228.34171,1.63101,0.25525
27.45000,10.81433,228.75836,228.75836,1.63399,0.25748
27.50000,10.63570,229.17497,229.17497,1.63696,0.25323
27.55000,10.47906,229.59153,229.59152,1.63994,0.24950
27.60000,10.71841,230.00826,230.00827,1.64292,0.25520
27.65000,10.53177,230.42495,230.42494,1.64589,0.25076
27.70000,10.39673,230.84158,230.84158,1.64887,0.24754
27.75000,10.69270,231.25827,231.25827,1.65184,0.25459
27.80000,11.00358,231.67495,231.67496,1.65482,0.26199
27.85000,10.65489,232.09169,232.09169,1.65780,0.25369
27.90000,11.25913,232.50840,232.50839,1.66077,0.26807
27.95000,11.19170,232.92503,232.92503,1.66375,0.26647
28.00000,11.44055,233.34177,233.34177,1.66673,0.27239
28.05000,11.30775,233.75848,233.75848,1.66970,0.26923
28.10000,10.99017,234.17509,234.17508,1.67268,0.26167
28.15000,11.31389,234.59177,234.59177,1.67566,0.26938
28.20000,11.15240,235.00838,235.00838,1.67863,0.26553
28.25000,11.14588,235.42514,235.42514,1.68161,0.26538
28.30000,11.28595,235.84167,235.84167,1.68458,0.26871
28.35000,11.45694,236.25833,236.25833,1.68756,0.27278
28.40000,10.96930,236.67496,236.67496,1.69054,0.26117
28.45000,11.43217,237.09162,237.09161,1.69351,0.27219
28.50000,11.57224,237.50825,237.50826,1.69649,0.27553
28.55000,11.76503,237.92489,237.92488,1.69946,0.28012
28.60000,11.46756,238.34162,238.34163,1.70244,0.27304
28.65000,11.32488,238.75836,238.75836,1.70542,0.26964
28.70000,11.79650,239.17494,239.17494,1.70839,0.28087
28.75000,11.52735,239.59162,239.59163,1.71137,0.27446
28.80000,11.77657,240.00839,240.00839,1.71435,0.28039
28.85000,11.67413,240.42507,240.42508,1.71732,0.27796
28.90000,11.59608,240.84173,240.84174,1.72030,0.27610
28.95000,11.77266,241.25842,241.25842,1.72327,0.28030
29.00000,11.73615,241.67513,241.67513,1.72625,0.27943
29.05000,12.00587,242.09173,242.09174,1.72923,0.28585
29.10000,12.10887,242.50842,242.50842,1.73220,0.28831
29.15000,12.19381,242.92505,242.92505,1.73518,0.29033
29.20000,12.07236,243.34176,243.34177,1.73816,0.28744
29.25000,11.88088,243.75834,243.75835,1.74113,0.28288
29.30000,12.21187,244.17498,244.17497,1.74411,0.29076
29.35000,11.94701,244.59158,244.59158,1.74708,0.28445
29.40000,11.80246,245.00829,245.00830,1.75006,0.28101
29.45000,11.55511,245.42490,245.42490,1.75303,0.27512
29.50000,12.01443,245.84161,245.84161,1.75601,0.28606
29.55000,12.25341,246.25824,246.25824,1.75899,0.29175
29.60000,12.27148,246.67495,246.67496,1.76196,0.29218
29.65000,12.27316,247.09167,247.09166,1.76494,0.29222
29.70000,12.40764,247.50835,247.50835,1.76792,0.29542
29.75000,12.33667,247.92506,247.92506,1.77089,0.29373
29.80000,12.40522,248.34180,248.34180,1.77387,0.29536
29.85000,12.32103,248.75846,248.75845,1.77685,0.29336
29.90000,12.45886,249.17509,249.17509,1.77982,0.29664
29.95000,12.37597,249.59178,249.59178,1.78280,0.29467
30.00000,12.30165,250.00841,250.00841,1.78577,0.29290
30.05000,12.49481,250.42509,250.42509,1.78875,0.29750
30.10000,12.24857,250.84162,250.84161,1.79173,0.29163
30.15000,12.73062,251.25838,251.25838,1.79470,0.30311
30.20000,13.17840,251.67497,251.67497,1.79768,0.31377
30.25000,13.53994,252.09160,252.09160,1.80065,0.32238
30.30000,13.52523,252.50826,252.50826,1.80363,0.32203
30.35000,13.07838,252.92497,252.92497,1.80661,0.31139
30.40000,12.95786,253.34160,253.34160,1.80958,0.30852
30.45000,12.94781,253.75826,253.75826,1.81256,0.30828
30.50000,13.42334,254.17492,254.17491,1.81554,0.31960
30.55000,12.73658,254.59165,254.59166,1.81851,0.30325
30.60000,12.68759,255.00831,255.00832,1.82149,0.30209
30.65000,12.75558,255.42508,255.42508,1.82446,0.30370
30.70000,13.30972,255.84174,255.84174,1.82744,0.31690
30.75000,13.69361,256.25845,256.25845,1.83042,0.32604
30.80000,13.84411,256.67513,256.67514,1.83339,0.32962
30.85000,14.04192,257.09174,257.09174,1.83637,0.33433
30.90000,14.54018,257.50845,257.50845,1.83935,0.34619
30.95000,14.11159,257.92513,257.92514,1.84232,0.33599
31.00000,13.70702,258.34169,258.34167,1.84530,0.32636
31.05000,14.12779,258.75835,258.75836,1.84827,0.33638
31.10000,14.25724,259.17498,259.17499,1.85125,0.33946
31.15000,13.99070,259.59161,259.59161,1.85423,0.33311
31.20000,13.82921,260.00825,260.00824,1.85720,0.32927
31.25000,13.98828,260.42493,260.42493,1.86018,0.33305
31.30000,14.15480,260.84159,260.84158,1.86315,0.33702
31.35000,14.64598,261.25833,261.25833,1.86613,0.34871
31.40000,14.41892,261.67493,261.67493,1.86911,0.34331
31.45000,14.64207,262.09167,262.09167,1.87208,0.34862
31.50000,14.62698,262.50841,262.50839,1.87506,0.34826
31.55000,14.30213,262.92509,262.92508,1.87804,0.34053
31.60000,14.47294,263.34167,263.34167,1.88101,0.34459
31.65000,14.68975,263.75844,263.75842,1.88399,0.34976
31.70000,14.60407,264.17515,264.17514,1.88697,0.34772
31.75000,14.06893,264.59181,264.59180,1.88994,0.33497
31.80000,14.49678,265.00841,265.00842,1.89292,0.34516
31.85000,14.99839,265.42507,265.42508,1.89589,0.35710
31.90000,15.07383,265.84173,265.84174,1.89887,0.35890
31.95000,15.01217,266.25836,266.25836,1.90185,0.35743
32.00000,14.91774,266.67497,266.67496,1.90482,0.35518
32.05000,15.17329,267.09155,267.09155,1.90780,0.36127
32.10000,15.35770,267.50831,267.50830,1.91077,0.36566
32.15000,15.01646,267.92489,267.92490,1.91375,0.35753
32.20000,15.29381,268.34160,268.34161,1.91673,0.36414
32.25000,15.13418,268.75824,268.75824,1.91970,0.36034
32.30000,15.30480,269.17497,269.17499,1.92268,0.36440
32.35000,15.03415,269.59163,269.59164,1.92565,0.35796
32.40000,15.06060,270.00837,270.00836,1.92863,0.35859
32.45000,15.34317,270.42503,270.42502,1.93161,0.36531
32.50000,15.23327,270.84182,270.84183,1.93458,0.36270
32.55000,15.57115,271.25845,271.25845,1.93756,0.37074
32.60000,15.80659,271.67508,271.67508,1.94054,0.37635
32.65000,15.99789,272.09177,272.09177,1.94351,0.38090
32.70000,15.77456,272.50845,272.50845,1.94649,0.37558
32.75000,15.63504,272.92509,272.92508,1.94946,0.37226
32.80000,15.47560,273.34164,273.34164,1.95244,0.36847
32.85000,15.54303,273.75840,273.75839,1.95542,0.37007
32.90000,15.09842,274.17496,274.17496,1.95839,0.35949
32.95000,15.44692,274.59162,274.59161,1.96137,0.36778
33.00000,15.73972,275.00825,275.00824,1.96434,0.37476
33.05000,15.78014,275.42496,275.42496,1.96732,0.37572
33.10000,15.87793,275.84159,275.84158,1.97030,0.37805
33.15000,15.98950,276.25828,276.25827,1.97327,0.38070
33.20000,16.22196,276.67494,276.67493,1.97625,0.38624
33.25000,16.26685,277.09170,277.09171,1.97923,0.38731
33.30000,16.34620,277.50833,277.50833,1.98220,0.38920
33.35000,16.03700,277.92504,277.92505,1.98518,0.38183
33.40000,15.86434,278.34173,278.34174,1.98816,0.37772
33.45000,15.49255,278.75847,278.75845,1.99113,0.36887
33.50000,15.68515,279.17515,279.17514,1.99411,0.37346
33.55000,15.73525,279.59176,279.59177,1.99708,0.37465
33.60000,15.87030,280.00844,280.00845,2.00006,0.37786
33.65000,16.41698,280.42502,280.42499,2.00304,0.39088
33.70000,16.43617,280.84176,280.84180,2.00601,0.39134
33.75000,16.56432,281.25831,281.25830,2.00899,0.39439
33.80000,16.93573,281.67497,281.67499,2.01196,0.40323
33.85000,16.71091,282.09161,282.09161,2.01494,0.39788
33.90000,16.68762,282.50824,282.50824,2.01792,0.39732
33.95000,16.60287,282.92487,282.92487,2.02089,0.39531
34.00000,16.44958,283.34161,283.34161,2.02387,0.39166
34.05000,16.11486,283.75829,283.75830,2.02684,0.38369
34.10000,16.15025,284.17495,284.17496,2.02982,0.38453
34.15000,16.47919,284.59164,284.59164,2.03280,0.39236
34.20000,17.08120,285.00837,285.00836,2.03577,0.40670
34.25000,16.85955,285.42511,285.42511,2.03875,0.40142
34.30000,17.19110,285.84172,285.84171,2.04173,0.40931
34.35000,17.34253,286.25843,286.25842,2.04470,0.41292
34.40000,17.25182,286.67511,286.67511,2.04768,0.41076
34.45000,17.40679,287.09177,287.09177,2.05066,0.41445
34.50000,17.24176,287.50841,287.50839,2.05363,0.41052
34.55000,17.54407,287.92506,287.92508,2.05661,0.41772
34.60000,16.97429,288.34175,288.34174,2.05958,0.40415
34.65000,16.52148,288.75828,288.75827,2.06256,0.39337
34.70000,17.11026,289.17499,289.17499,2.06554,0.40739
34.75000,17.40437,289.59162,289.59158,2.06851,0.41439
34.80000,17.79143,290.00831,290.00830,2.07149,0.42361
34.85000,17.56959,290.42489,290.42487,2.07446,0.41832
34.90000,17.84395,290.84160,290.84158,2.07744,0.42486
34.95000,18.10230,291.25823,291.25824,2.08042,0.43101
35.00000,17.91660,291.67502,291.67505,2.08339,0.42659
35.05000,17.89536,292.09163,292.09161,2.08637,0.42608
35.10000,17.72009,292.50839,292.50839,2.08935,0.42191
35.15000,17.77075,292.92507,292.92508,2.09232,0.42311
35.20000,17.54072,293.34176,293.34177,2.09530,0.41764
35.25000,17.08474,293.75842,293.75842,2.09827,0.40678
35.30000,17.14416,294.17513,294.17514,2.10125,0.40819
35.35000,17.95106,294.59179,294.59180,2.10423,0.42741
35.40000,17.96205,295.00850,295.00851,2.10720,0.42767
35.45000,18.24666,295.42505,295.42505,2.11018,0.43444
35.50000,18.11478,295.84169,295.84167,2.11315,0.43130
35.55000,18.28093,296.25837,296.25836,2.11613,0.43526
35.60000,18.92131,296.67498,296.67499,2.11911,0.45051
35.65000,18.65774,297.09158,297.09158,2.12208,0.44423
35.70000,18.64582,297.50819,297.50818,2.12506,0.44395
35.75000,19.05821,297.92498,297.92499,2.12804,0.45377
35.80000,18.57448,298.34159,298.34158,2.13101,0.44225
35.85000,18.49066,298.75825,298.75824,2.13399,0.44025
35.90000,18.75553,299.17496,299.17499,2.13696,0.44656
35.95000,18.85090,299.59175,299.59174,2.13994,0.44883
36.00000,18.94068,300.00838,300.00839,2.14292,0.45097
36.05000,18.81104,300.42509,300.42508,2.14589,0.44788
36.10000,19.05374,300.84170,300.84171,2.14887,0.45366
36.15000,19.51847,301.25849,301.25848,2.15185,0.46473
36.20000,19.19288,301.67507,301.67508,2.15482,0.45697
36.25000,19.44099,302.09175,302.09177,2.15780,0.46288
36.30000,19.33109,302.50844,302.50842,2.16077,0.46026
36.35000,19.13086,302.92507,302.92508,2.16375,0.45550
36.40000,19.32103,303.34173,303.34174,2.16673,0.46002
36.45000,18.99917,303.75831,303.75830,2.16970,0.45236
36.50000,19.35959,304.17497,304.17493,2.17268,0.46094
36.55000,19.56522,304.59165,304.59164,2.17565,0.46584
36.60000,19.77999,305.00828,305.00827,2.17863,0.47095
36.65000,19.62129,305.42492,305.42493,2.18161,0.46717
36.70000,19.71740,305.84155,305.84155,2.18458,0.46946
36.75000,19.91466,306.25831,306.25830,2.18756,0.47416
36.80000,19.94185,306.67500,306.67499,2.19054,0.47481
36.85000,20.53659,307.09160,307.09161,2.19351,0.48897
36.90000,20.49580,307.50837,307.50836,2.19649,0.48800
36.95000,19.97072,307.92505,307.92502,2.19946,0.47549
37.00000,19.77794,308.34176,308.34177,2.20244,0.47090
37.05000,19.97799,308.75845,308.75842,2.20542,0.47567
37.10000,19.87703,309.17516,309.17517,2.20839,0.47326
37.15000,20.01561,309.59179,309.59180,2.21137,0.47656
37.20000,20.31438,310.00843,310.00842,2.21435,0.48368
37.25000,20.20989,310.42506,310.42505,2.21732,0.48119
37.30000,20.30469,310.84172,310.84171,2.22030,0.48345
37.35000,20.43806,311.25835,311.25836,2.22327,0.48662
37.40000,20.35741,311.67493,311.67493,2.22625,0.48470
37.45000,20.36840,312.09162,312.09161,2.22923,0.48496
37.50000,20.52728,312.50827,312.50830,2.23220,0.48874
37.55000,20.53361,312.92496,312.92496,2.23518,0.48890
37.60000,20.73925,313.34157,313.34155,2.23815,0.49379
37.65000,20.55168,313.75830,313.75833,2.24113,0.48933
37.70000,20.62451,314.17496,314.17493,2.24411,0.49106
37.75000,21.01734,314.59170,314.59174,2.24708,0.50041
37.80000,21.05869,315.00838,315.00839,2.25006,0.50140
37.85000,21.25334,315.42509,315.42511,2.25304,0.50603
37.90000,21.16822,315.84175,315.84177,2.25601,0.50401
37.95000,20.95122,316.25844,316.25842,2.25899,0.49884
38.00000,21.38466,316.67507,316.67508,2.26196,0.50916
38.05000,21.22596,317.09176,317.09180,2.26494,0.50538
38.10000,21.07900,317.50844,317.50845,2.26792,0.50188
38.15000,21.01660,317.92505,317.92502,2.27089,0.50040
38.20000,20.97506,318.34171,318.34171,2.27387,0.49941
38.25000,21.11457,318.75839,318.75839,2.27685,0.50273
38.30000,21.60445,319.17505,319.17505,2.27982,0.51439
38.35000,21.80655,319.59160,319.59161,2.28280,0.51920
38.40000,21.68622,320.00826,320.00827,2.28577,0.51634
38.45000,21.68752,320.42492,320.42493,2.28875,0.51637
38.50000,21.74880,320.84155,320.84155,2.29173,0.51783
38.55000,21.85609,321.25829,321.25830,2.29470,0.52038
38.60000,22.22918,321.67492,321.67493,2.29768,0.52927
38.65000,21.71528,322.09166,322.09167,2.30065,0.51703
38.70000,21.78941,322.50835,322.50833,2.30363,0.51880
38.75000,22.03528,322.92501,322.92502,2.30661,0.52465
38.80000,21.81418,323.34174,323.34174,2.30958,0.51939
38.85000,22.20925,323.75853,323.75854,2.31256,0.52879
38.90000,21.97493,324.17509,324.17508,2.31554,0.52321
38.95000,22.61475,324.59180,324.59180,2.31851,0.53845
39.00000,22.47617,325.00838,325.00839,2.32149,0.53515
39.05000,22.55384,325.42514,325.42514,2.32447,0.53700
39.10000,22.92879,325.84167,325.84167,2.32744,0.54592
39.15000,22.75482,326.25833,326.25833,2.33042,0.54178
39.20000,22.96157,326.67496,326.67496,2.33339,0.54670
39.25000,22.72446,327.09159,327.09158,2.33637,0.54106
39.30000,22.67808,327.50825,327.50824,2.33934,0.53995
39.35000,22.80120,327.92491,327.92490,2.34232,0.54289
39.40000,9.98285,328.34160,328.34158,2.34530,0.23769
39.42600,-0.15181,328.55827,328.55826,2.34684,-0.00361