File: raw_data/mechanical_tests_Instron_data/3DP_Skin_0035_Horizontal_1.is_tens_RawData/Specimen_RawData_1.csv
Dimension : Area,0.42000,cm^2

Time,Load,Extension,Tensile extension,Tensile strain,Tensile stress
(sec),(N),(mm),(mm),(mm/mm),(MPa)
0.00000,0.38166,0.00000,0.00000,0.00000,0.00909
0.03000,0.87135,0.03198,0.03198,0.00023,0.02075
0.06000,0.85849,0.14328,0.14328,0.00102,0.02044
0.09000,0.30417,0.33233,0.33233,0.00237,0.00724
0.12000,0.81863,0.58945,0.58945,0.00421,0.01949
0.15000,1.25077,0.87833,0.87833,0.00627,0.02978
0.18000,1.65291,1.17854,1.17854,0.00842,0.03936
0.21000,2.05394,1.48516,1.48516,0.01061,0.04890
0.24000,1.56108,1.79652,1.79652,0.01283,0.03717
0.27000,1.19861,2.11136,2.11136,0.01508,0.02854
0.30000,1.83228,2.42869,2.42869,0.01735,0.04363
0.33000,2.22102,2.73828,2.73828,0.01956,0.05288
0.36000,1.42511,3.00876,3.00876,0.02149,0.03393
0.39000,1.29640,3.25572,3.25572,0.02326,0.03087
0.42000,1.51023,3.50303,3.50303,0.02502,0.03596
0.45000,1.29379,3.75506,3.75506,0.02682,0.03080
0.48000,1.17663,4.00741,4.00741,0.02862,0.02802
0.51000,1.52141,4.25810,4.25810,0.03041,0.03622
0.54000,1.58884,4.50798,4.50798,0.03220,0.03783
0.57000,1.73263,4.75797,4.75797,0.03399,0.04125
0.60000,1.45808,5.00815,5.00815,0.03577,0.03472
0.63000,1.40909,5.25830,5.25830,0.03756,0.03355
0.66000,1.54190,5.50840,5.50840,0.03935,0.03671
0.69000,1.51675,5.75831,5.75831,0.04113,0.03611
0.72000,1.60243,6.00822,6.00822,0.04292,0.03815
0.75000,1.54115,6.25826,6.25827,0.04470,0.03669
0.78000,1.64993,6.50828,6.50828,0.04649,0.03928
0.81000,1.57505,6.75830,6.75830,0.04827,0.03750
0.84000,1.79391,7.00840,7.00840,0.05006,0.04271
0.87000,1.90102,7.25839,7.25839,0.05185,0.04526
0.90000,1.91964,7.50825,7.50825,0.05363,0.04571
0.93000,1.82819,7.75824,7.75824,0.05542,0.04353
0.96000,1.93249,8.00833,8.00834,0.05720,0.04601
0.99000,1.83620,8.25843,8.25843,0.05899,0.04372
1.02000,1.88556,8.50845,8.50845,0.06077,0.04489
1.05000,1.97664,8.75836,8.75836,0.06256,0.04706
1.08000,2.28416,9.00825,9.00825,0.06434,0.05438
1.11000,1.76933,9.25824,9.25824,0.06613,0.04213
1.14000,1.51675,9.50831,9.50831,0.06792,0.03611
1.17000,1.53072,9.75841,9.75841,0.06970,0.03645
1.20000,1.42232,10.00840,10.00840,0.07149,0.03386
1.23000,1.43442,10.25833,10.25833,0.07327,0.03415
1.26000,1.72779,10.50827,10.50827,0.07506,0.04114
1.29000,1.70339,10.75824,10.75824,0.07684,0.04056
1.32000,1.72071,11.00828,11.00828,0.07863,0.04097
1.35000,1.77640,11.25840,11.25840,0.08042,0.04230
1.38000,1.38897,11.50840,11.50840,0.08220,0.03307
1.41000,1.64993,11.75828,11.75828,0.08399,0.03928
1.44000,1.86432,12.00822,12.00822,0.08577,0.04439
1.47000,1.96099,12.25826,12.25826,0.08756,0.04669
1.50000,2.29981,12.50836,12.50836,0.08935,0.05476
1.53000,2.06418,12.75840,12.75840,0.09113,0.04915
1.56000,2.16775,13.00840,13.00839,0.09292,0.05161
1.59000,1.93771,13.25833,13.25833,0.09470,0.04614
1.62000,1.80751,13.50827,13.50827,0.09649,0.04304
1.65000,1.83601,13.75823,13.75823,0.09827,0.04371
1.68000,1.86581,14.00831,14.00831,0.10006,0.04442
1.71000,1.69799,14.25843,14.25843,0.10185,0.04043
1.74000,1.99620,14.50845,14.50845,0.10363,0.04753
1.77000,2.19513,14.75833,14.75833,0.10542,0.05226
1.80000,1.93324,15.00830,15.00830,0.10720,0.04603
1.83000,2.12919,15.25826,15.25826,0.10899,0.05069
1.86000,1.92951,15.50830,15.50830,0.11077,0.04594
1.89000,1.83135,15.75838,15.75838,0.11256,0.04360
1.92000,1.93827,16.00842,16.00842,0.11435,0.04615
1.95000,1.68197,16.25833,16.25833,0.11613,0.04005
1.98000,1.81124,16.50819,16.50819,0.11792,0.04312
2.01000,1.83005,16.75826,16.75826,0.11970,0.04357
2.04000,2.03028,17.00839,17.00838,0.12149,0.04834
2.07000,2.13757,17.25838,17.25838,0.12327,0.05089
2.10000,2.04332,17.50837,17.50837,0.12506,0.04865
2.13000,2.01948,17.75836,17.75836,0.12685,0.04808
2.16000,2.13776,18.00827,18.00827,0.12863,0.05090
2.19000,2.21077,18.25823,18.25823,0.13042,0.05264
2.22000,2.40281,18.50836,18.50836,0.13220,0.05721
2.25000,2.14837,18.75846,18.75846,0.13399,0.05115
2.28000,2.13850,19.00842,19.00842,0.13577,0.05092
2.31000,2.13720,19.25830,19.25830,0.13756,0.05089
2.34000,2.58684,19.50827,19.50827,0.13934,0.06159
2.37000,2.25715,19.75829,19.75829,0.14113,0.05374
2.40000,2.03624,20.00836,20.00836,0.14292,0.04848
2.43000,1.90791,20.25840,20.25840,0.14470,0.04543
2.46000,2.29515,20.50839,20.50839,0.14649,0.05465
2.49000,2.26609,20.75830,20.75830,0.14827,0.05395
2.52000,1.96006,21.00824,21.00824,0.15006,0.04667
2.55000,1.91219,21.25823,21.25823,0.15184,0.04553
2.58000,2.07908,21.50833,21.50833,0.15363,0.04950
2.61000,2.24691,21.75843,21.75842,0.15542,0.05350
2.64000,2.13012,22.00839,22.00839,0.15720,0.05072
2.67000,2.17427,22.25828,22.25828,0.15899,0.05177
2.70000,2.23927,22.50824,22.50824,0.16077,0.05332
2.73000,2.01724,22.75823,22.75823,0.16256,0.04803
2.76000,1.98390,23.00833,23.00833,0.16435,0.04724
2.79000,2.23722,23.25848,23.25848,0.16613,0.05327
2.82000,2.26367,23.50844,23.50844,0.16792,0.05390
2.85000,2.03475,23.75833,23.75833,0.16970,0.04845
2.88000,1.89394,24.00827,24.00827,0.17149,0.04509
2.91000,1.93939,24.25826,24.25826,0.17327,0.04618
2.94000,1.96658,24.50827,24.50827,0.17506,0.04682
2.97000,1.74809,24.75843,24.75843,0.17685,0.04162
3.00000,1.47931,25.00847,25.00847,0.17863,0.03522
3.03000,1.62013,25.25838,25.25838,0.18042,0.03857
3.06000,1.96286,25.50824,25.50824,0.18220,0.04673
3.09000,1.85873,25.75823,25.75823,0.18399,0.04426
3.12000,1.92728,26.00827,26.00827,0.18577,0.04589
3.15000,1.98837,26.25840,26.25840,0.18756,0.04734
3.18000,1.91536,26.50842,26.50842,0.18935,0.04560
3.21000,2.19345,26.75833,26.75833,0.19113,0.05223
3.24000,2.22698,27.00821,27.00821,0.19292,0.05302
3.27000,2.06418,27.25820,27.25820,0.19470,0.04915
3.30000,2.18023,27.50830,27.50830,0.19649,0.05191
3.33000,1.67005,27.75840,27.75840,0.19827,0.03976
3.36000,1.72965,28.00844,28.00844,0.20006,0.04118
3.39000,1.81887,28.25841,28.25841,0.20185,0.04331
3.42000,1.96844,28.50832,28.50832,0.20363,0.04687
3.45000,1.62441,28.75823,28.75823,0.20542,0.03868
3.48000,1.48583,29.00830,29.00830,0.20720,0.03538
3.51000,1.59349,29.25840,29.25840,0.20899,0.03794
3.54000,1.69780,29.50847,29.50847,0.21077,0.04042
3.57000,1.83564,29.75838,29.75838,0.21256,0.04371
3.60000,1.51601,30.00826,30.00826,0.21434,0.03610
3.63000,1.64080,30.25826,30.25826,0.21613,0.03907
3.66000,1.48583,30.50830,30.50830,0.21792,0.03538
3.69000,1.59536,30.75832,30.75832,0.21970,0.03798
3.72000,1.58343,31.00836,31.00836,0.22149,0.03770
3.75000,1.59368,31.25838,31.25838,0.22327,0.03794
3.78000,1.58064,31.50826,31.50826,0.22506,0.03763
3.81000,1.79801,31.75823,31.75823,0.22684,0.04281
3.84000,1.43852,32.00830,32.00830,0.22863,0.03425
3.87000,1.62553,32.25837,32.25837,0.23042,0.03870
3.90000,1.59405,32.50838,32.50838,0.23220,0.03795
3.93000,1.76802,32.75838,32.75838,0.23399,0.04210
3.96000,1.92262,33.00832,33.00832,0.23577,0.04578
3.99000,1.98986,33.25825,33.25825,0.23756,0.04738
4.02000,1.69426,33.50830,33.50830,0.23934,0.04034
4.05000,1.77585,33.75842,33.75842,0.24113,0.04228
4.08000,1.59461,34.00844,34.00844,0.24292,0.03797
4.11000,1.62628,34.25830,34.25830,0.24470,0.03872
4.14000,1.83992,34.50826,34.50826,0.24649,0.04381
4.17000,1.52737,34.75828,34.75828,0.24827,0.03637
4.20000,1.61193,35.00832,35.00832,0.25006,0.03838
4.23000,1.73151,35.25837,35.25837,0.25185,0.04123
4.26000,1.78739,35.50841,35.50841,0.25363,0.04256
4.29000,1.95410,35.75832,35.75833,0.25542,0.04653
4.32000,1.79671,36.00823,36.00823,0.25720,0.04278
4.35000,1.90083,36.25823,36.25822,0.25899,0.04526
4.38000,1.86786,36.50827,36.50827,0.26077,0.04447
4.41000,1.59014,36.75837,36.75837,0.26256,0.03786
4.44000,1.76076,37.00841,37.00841,0.26435,0.04192
4.47000,1.92076,37.25835,37.25835,0.26613,0.04573
4.50000,1.91815,37.50828,37.50829,0.26792,0.04567
4.53000,2.16030,37.75830,37.75830,0.26970,0.05144
4.56000,1.88444,38.00835,38.00835,0.27149,0.04487
4.59000,1.87848,38.25842,38.25842,0.27327,0.04473
4.62000,1.70507,38.50841,38.50841,0.27506,0.04060
4.65000,1.66651,38.75835,38.75835,0.27685,0.03968
4.68000,1.68514,39.00826,39.00826,0.27863,0.04012
4.71000,1.93343,39.25825,39.25825,0.28042,0.04603
4.74000,2.14241,39.50835,39.50835,0.28220,0.05101
4.77000,2.13459,39.75842,39.75842,0.28399,0.05082
4.80000,1.91126,40.00844,40.00844,0.28577,0.04551
4.83000,2.15899,40.25838,40.25838,0.28756,0.05140
4.86000,2.11019,40.50821,40.50821,0.28934,0.05024
4.89000,1.96602,40.75820,40.75819,0.29113,0.04681
4.92000,2.00626,41.00835,41.00834,0.29292,0.04777
4.95000,1.84756,41.25842,41.25842,0.29470,0.04399
4.98000,1.90120,41.50836,41.50836,0.29649,0.04527
5.01000,1.74437,41.75832,41.75832,0.29827,0.04153
5.04000,2.34060,42.00826,42.00826,0.30006,0.05573
5.07000,2.26125,42.25828,42.25828,0.30184,0.05384
5.10000,2.11596,42.50837,42.50837,0.30363,0.05038
5.13000,2.28193,42.75842,42.75842,0.30542,0.05433
5.16000,2.20854,43.00841,43.00841,0.30720,0.05258
5.19000,1.82632,43.25832,43.25832,0.30899,0.04348
5.22000,1.91573,43.50823,43.50823,0.31077,0.04561
5.25000,1.99005,43.75822,43.75822,0.31256,0.04738
5.28000,2.43019,44.00835,44.00835,0.31435,0.05786
5.31000,2.18302,44.25844,44.25845,0.31613,0.05198
5.34000,2.14949,44.50843,44.50843,0.31792,0.05118
5.37000,2.38381,44.75832,44.75832,0.31970,0.05676
5.40000,2.42963,45.00826,45.00826,0.32149,0.05785
5.43000,2.46018,45.25825,45.25824,0.32327,0.05858
5.46000,2.26926,45.50832,45.50832,0.32506,0.05403
5.49000,2.37804,45.75842,45.75842,0.32685,0.05662
5.52000,2.09305,46.00841,46.00840,0.32863,0.04983
5.55000,2.27429,46.25834,46.25834,0.33042,0.05415
5.58000,2.50358,46.50828,46.50828,0.33220,0.05961
5.61000,2.52239,46.75822,46.75822,0.33399,0.06006
5.64000,2.19382,47.00829,47.00829,0.33577,0.05223
5.67000,2.30670,47.25844,47.25845,0.33756,0.05492
5.70000,2.68072,47.50843,47.50843,0.33935,0.06383
5.73000,2.62205,47.75829,47.75829,0.34113,0.06243
5.76000,2.21077,48.00823,48.00822,0.34292,0.05264
5.79000,2.24281,48.25827,48.25827,0.34470,0.05340
5.82000,2.37003,48.50832,48.50832,0.34649,0.05643
5.85000,2.67848,48.75842,48.75842,0.34827,0.06377
5.88000,2.67141,49.00846,49.00846,0.35006,0.06360
5.91000,2.62316,49.25834,49.25835,0.35185,0.06246
5.94000,2.62968,49.50823,49.50823,0.35363,0.06261
5.97000,2.71387,49.75825,49.75825,0.35542,0.06462
6.00000,2.31173,50.00832,50.00832,0.35720,0.05504
6.03000,2.61497,50.25839,50.25839,0.35899,0.06226
6.06000,3.04002,50.50843,50.50843,0.36077,0.07238
6.09000,3.05455,50.75840,50.75840,0.36256,0.07273
6.12000,3.01637,51.00828,51.00828,0.36434,0.07182
6.15000,2.69096,51.25819,51.25819,0.36613,0.06407
6.18000,2.97949,51.50829,51.50828,0.36792,0.07094
6.21000,2.65948,51.75841,51.75842,0.36970,0.06332
6.24000,2.73418,52.00840,52.00840,0.37149,0.06510
6.27000,3.34419,52.25834,52.25834,0.37327,0.07962
6.30000,3.03872,52.50828,52.50828,0.37506,0.07235
6.33000,3.37716,52.75825,52.75825,0.37684,0.08041
6.36000,3.06796,53.00832,53.00832,0.37863,0.07305
6.39000,2.92994,53.25836,53.25836,0.38042,0.06976
6.42000,3.00892,53.50843,53.50843,0.38220,0.07164
6.45000,3.15029,53.75839,53.75840,0.38399,0.07501
6.48000,3.16482,54.00825,54.00826,0.38577,0.07535
6.51000,2.99737,54.25821,54.25821,0.38756,0.07137
6.54000,3.09870,54.50831,54.50832,0.38935,0.07378
6.57000,3.15402,54.75842,54.75842,0.39113,0.07510
6.60000,2.92119,55.00840,55.00840,0.39292,0.06955
6.63000,3.17674,55.25840,55.25840,0.39470,0.07564
6.66000,3.14601,55.50830,55.50830,0.39649,0.07490
6.69000,3.07821,55.75824,55.75824,0.39827,0.07329
6.72000,3.20487,56.00829,56.00829,0.40006,0.07631
6.75000,3.53400,56.25839,56.25839,0.40185,0.08414
6.78000,3.44198,56.50840,56.50840,0.40363,0.08195
6.81000,3.06629,56.75832,56.75832,0.40542,0.07301
6.84000,3.38890,57.00828,57.00828,0.40720,0.08069
6.87000,3.81563,57.25830,57.25830,0.40899,0.09085
6.90000,3.67649,57.50829,57.50829,0.41077,0.08754
6.93000,3.62098,57.75836,57.75836,0.41256,0.08621
6.96000,3.52990,58.00840,58.00840,0.41435,0.08405
6.99000,3.37865,58.25834,58.25834,0.41613,0.08044
7.02000,3.16575,58.50825,58.50825,0.41792,0.07538
7.05000,3.14079,58.75829,58.75829,0.41970,0.07478
7.08000,3.58224,59.00834,59.00834,0.42149,0.08529
7.11000,3.74820,59.25841,59.25841,0.42327,0.08924
7.14000,3.43099,59.50843,59.50843,0.42506,0.08169
7.17000,3.52059,59.75831,59.75831,0.42685,0.08382
7.20000,3.38741,60.00828,60.00828,0.42863,0.08065
7.23000,3.27602,60.25827,60.25827,0.43042,0.07800
7.26000,3.51798,60.50831,60.50831,0.43220,0.08376
7.29000,3.20934,60.75841,60.75841,0.43399,0.07641
7.32000,3.50829,61.00843,61.00843,0.43577,0.08353
7.35000,3.61018,61.25831,61.25831,0.43756,0.08596
7.38000,3.81768,61.50822,61.50822,0.43934,0.09090
7.41000,3.91435,61.75824,61.75824,0.44113,0.09320
7.44000,3.90913,62.00834,62.00834,0.44292,0.09307
7.47000,3.92701,62.25844,62.25844,0.44470,0.09350
7.50000,3.94937,62.50843,62.50843,0.44649,0.09403
7.53000,4.12557,62.75831,62.75831,0.44827,0.09823
7.56000,3.78732,63.00819,63.00819,0.45006,0.09017
7.59000,4.09614,63.25826,63.25826,0.45184,0.09753
7.62000,3.92739,63.50839,63.50839,0.45363,0.09351
7.65000,3.84264,63.75843,63.75843,0.45542,0.09149
7.68000,4.02927,64.00842,64.00842,0.45720,0.09594
7.71000,4.39454,64.25836,64.25836,0.45899,0.10463
7.74000,4.09372,64.50821,64.50822,0.46077,0.09747
7.77000,3.95924,64.75818,64.75818,0.46256,0.09427
7.80000,4.21125,65.00834,65.00834,0.46435,0.10027
7.83000,4.21759,65.25846,65.25846,0.46613,0.10042
7.86000,4.48562,65.50843,65.50842,0.46792,0.10680
7.89000,4.37573,65.75833,65.75833,0.46970,0.10418
7.92000,4.43291,66.00824,66.00825,0.47149,0.10555
7.95000,4.52660,66.25818,66.25818,0.47327,0.10778
7.98000,4.73578,66.50831,66.50831,0.47506,0.11276
8.01000,4.69331,66.75840,66.75840,0.47685,0.11175
8.04000,4.40832,67.00842,67.00842,0.47863,0.10496
8.07000,4.41559,67.25834,67.25834,0.48042,0.10513
8.10000,4.58565,67.50825,67.50825,0.48220,0.10918
8.13000,4.70970,67.75827,67.75827,0.48399,0.11214
8.16000,4.98556,68.00834,68.00834,0.48577,0.11870
8.19000,4.70821,68.25838,68.25838,0.48756,0.11210
8.22000,4.30308,68.50845,68.50845,0.48935,0.10245
8.25000,4.59123,68.75839,68.75838,0.49113,0.10932
8.28000,4.58378,69.00827,69.00827,0.49292,0.10914
8.31000,4.88535,69.25821,69.25821,0.49470,0.11632
8.34000,4.83971,69.50833,69.50833,0.49649,0.11523
8.37000,4.61694,69.75845,69.75845,0.49827,0.10993
8.40000,4.86597,70.00845,70.00845,0.50006,0.11586
8.43000,5.22900,70.25830,70.25830,0.50185,0.12450
8.46000,5.11259,70.50825,70.50825,0.50363,0.12173
8.49000,4.54709,70.75827,70.75827,0.50542,0.10826
8.52000,4.53275,71.00828,71.00829,0.50720,0.10792
8.55000,4.95110,71.25838,71.25838,0.50899,0.11788
8.58000,4.52232,71.50842,71.50842,0.51077,0.10767
8.61000,4.47556,71.75833,71.75833,0.51256,0.10656
8.64000,4.61005,72.00824,72.00824,0.51434,0.10976
8.67000,5.05485,72.25826,72.25826,0.51613,0.12035
8.70000,5.03901,72.50833,72.50833,0.51792,0.11998
8.73000,4.91645,72.75840,72.75840,0.51970,0.11706
8.76000,5.19045,73.00839,73.00839,0.52149,0.12358
8.79000,4.88944,73.25833,73.25833,0.52327,0.11642
8.82000,4.90528,73.50827,73.50827,0.52506,0.11679
8.85000,5.01350,73.75827,73.75826,0.52684,0.11937
8.88000,4.71324,74.00836,74.00836,0.52863,0.11222
8.91000,4.89801,74.25843,74.25844,0.53042,0.11662
8.94000,4.56870,74.50840,74.50840,0.53220,0.10878
8.97000,4.70094,74.75836,74.75836,0.53399,0.11193
9.00000,5.35827,75.00830,75.00830,0.53577,0.12758
9.03000,5.27017,75.25824,75.25824,0.53756,0.12548
9.06000,4.86672,75.50828,75.50828,0.53934,0.11587
9.09000,4.92446,75.75838,75.75838,0.54113,0.11725
9.12000,5.14537,76.00842,76.00842,0.54292,0.12251
9.15000,5.04814,76.25839,76.25838,0.54470,0.12019
9.18000,5.01573,76.50825,76.50825,0.54649,0.11942
9.21000,5.03175,76.75821,76.75821,0.54827,0.11980
9.24000,5.00679,77.00831,77.00831,0.55006,0.11921
9.27000,4.77247,77.25840,77.25840,0.55185,0.11363
9.30000,4.73242,77.50839,77.50839,0.55363,0.11268
9.33000,4.73913,77.75838,77.75839,0.55542,0.11284
9.36000,4.86467,78.00830,78.00830,0.55720,0.11583
9.39000,4.83245,78.25826,78.25826,0.55899,0.11506
9.42000,5.03883,78.50833,78.50833,0.56077,0.11997
9.45000,5.24782,78.75840,78.75840,0.56256,0.12495
9.48000,4.49587,79.00839,79.00838,0.56435,0.10704
9.51000,4.21591,79.25836,79.25835,0.56613,0.10038
9.54000,4.67934,79.50829,79.50829,0.56792,0.11141
9.57000,5.05392,79.75826,79.75826,0.56970,0.12033
9.60000,4.68325,80.00830,80.00831,0.57149,0.11151
9.63000,4.92465,80.25840,80.25840,0.57327,0.11725
9.66000,4.68735,80.50842,80.50843,0.57506,0.11160
9.69000,4.87231,80.75830,80.75830,0.57684,0.11601
9.72000,4.59533,81.00827,81.00828,0.57863,0.10941
9.75000,4.90341,81.25829,81.25829,0.58042,0.11675
9.78000,4.97438,81.50831,81.50831,0.58220,0.11844
9.81000,4.91850,81.75831,81.75832,0.58399,0.11711
9.84000,4.93117,82.00842,82.00842,0.58577,0.11741
9.87000,5.01350,82.25835,82.25835,0.58756,0.11937
9.90000,5.04795,82.50826,82.50826,0.58934,0.12019
9.93000,4.68753,82.75828,82.75829,0.59113,0.11161
9.96000,5.09601,83.00833,83.00833,0.59292,0.12133
9.99000,5.42998,83.25837,83.25837,0.59470,0.12929
10.02000,5.23981,83.50839,83.50838,0.59649,0.12476
10.05000,5.28414,83.75833,83.75832,0.59827,0.12581
10.08000,5.38751,84.00823,84.00822,0.60006,0.12827
10.11000,5.24372,84.25825,84.25826,0.60184,0.12485
10.14000,5.19920,84.50835,84.50835,0.60363,0.12379
10.17000,5.18598,84.75845,84.75845,0.60542,0.12348
10.20000,4.96823,85.00842,85.00842,0.60720,0.11829
10.23000,5.56856,85.25827,85.25827,0.60899,0.13258
10.26000,5.57415,85.50824,85.50824,0.61077,0.13272
10.29000,5.33294,85.75826,85.75826,0.61256,0.12697
10.32000,5.06993,86.00833,86.00833,0.61435,0.12071
10.35000,5.77904,86.25840,86.25840,0.61613,0.13760
10.38000,5.91055,86.50844,86.50844,0.61792,0.14073
10.41000,5.80680,86.75835,86.75835,0.61970,0.13826
10.44000,5.51920,87.00821,87.00822,0.62149,0.13141
10.47000,5.53373,87.25820,87.25821,0.62327,0.13176
10.50000,5.55832,87.50835,87.50835,0.62506,0.13234
10.53000,5.82822,87.75845,87.75845,0.62685,0.13877
10.56000,5.84889,88.00841,88.00842,0.62863,0.13926
10.59000,5.73993,88.25832,88.25832,0.63042,0.13666
10.62000,5.87031,88.50826,88.50826,0.63220,0.13977
10.65000,5.54454,88.75822,88.75822,0.63399,0.13201
10.68000,5.88838,89.00835,89.00834,0.63577,0.14020
10.71000,6.00405,89.25847,89.25848,0.63756,0.14295
10.74000,5.98282,89.50847,89.50847,0.63935,0.14245
10.77000,5.53075,89.75835,89.75835,0.64113,0.13168
10.80000,5.72056,90.00823,90.00823,0.64292,0.13620
10.83000,5.70472,90.25817,90.25816,0.64470,0.13583
10.86000,4.95836,90.50830,90.50829,0.64649,0.11806
10.89000,5.48530,90.75844,90.75845,0.64827,0.13060
10.92000,6.16573,91.00846,91.00846,0.65006,0.14680
10.95000,5.91185,91.25838,91.25838,0.65185,0.14076
10.98000,5.61401,91.50820,91.50820,0.65363,0.13367
11.01000,5.80233,91.75820,91.75820,0.65542,0.13815
11.04000,6.13742,92.00830,92.00829,0.65720,0.14613
11.07000,6.01560,92.25839,92.25839,0.65899,0.14323
11.10000,5.52572,92.50841,92.50841,0.66077,0.13156
11.13000,5.74253,92.75834,92.75834,0.66256,0.13673
11.16000,6.26836,93.00826,93.00826,0.66434,0.14925
11.19000,6.13872,93.25825,93.25826,0.66613,0.14616
11.22000,5.78631,93.50832,93.50832,0.66792,0.13777
11.25000,5.64493,93.75842,93.75842,0.66970,0.13440
11.28000,5.90011,94.00846,94.00845,0.67149,0.14048
11.31000,6.09625,94.25838,94.25838,0.67327,0.14515
11.34000,5.99101,94.50826,94.50826,0.67506,0.14264
11.37000,5.84535,94.75826,94.75826,0.67684,0.13918
11.40000,5.88037,95.00830,95.00830,0.67863,0.14001
11.43000,6.06421,95.25839,95.25839,0.68042,0.14439
11.46000,6.16573,95.50844,95.50845,0.68220,0.14680
11.49000,6.40191,95.75834,95.75835,0.68399,0.15243
11.52000,6.58743,96.00826,96.00826,0.68577,0.15684
11.55000,6.68224,96.25825,96.25826,0.68756,0.15910
11.58000,6.63213,96.50829,96.50829,0.68934,0.15791
11.61000,6.93928,96.75831,96.75832,0.69113,0.16522
11.64000,6.98157,97.00838,97.00838,0.69292,0.16623
11.67000,7.29542,97.25840,97.25840,0.69470,0.17370
11.70000,7.18795,97.50829,97.50829,0.69649,0.17114
11.73000,7.10879,97.75822,97.75822,0.69827,0.16926
11.76000,7.01584,98.00835,98.00835,0.70006,0.16704
11.79000,7.49435,98.25842,98.25842,0.70185,0.17844
11.82000,7.49175,98.50839,98.50838,0.70363,0.17837
11.85000,6.81821,98.75834,98.75834,0.70542,0.16234
11.88000,6.82715,99.00831,99.00831,0.70720,0.16255
11.91000,7.36620,99.25828,99.25828,0.70899,0.17539
11.94000,7.29971,99.50832,99.50832,0.71077,0.17380
11.97000,7.26767,99.75842,99.75842,0.71256,0.17304
12.00000,7.26935,100.00838,100.00838,0.71435,0.17308
12.03000,6.87111,100.25832,100.25832,0.71613,0.16360
12.06000,7.71228,100.50825,100.50826,0.71792,0.18363
12.09000,7.56979,100.75825,100.75825,0.71970,0.18023
12.12000,7.53570,101.00832,101.00832,0.72149,0.17942
12.15000,7.79089,101.25839,101.25839,0.72327,0.18550
12.18000,7.95256,101.50838,101.50838,0.72506,0.18935
12.21000,7.68527,101.75834,101.75834,0.72685,0.18298
12.24000,7.82665,102.00826,102.00826,0.72863,0.18635
12.27000,7.81566,102.25822,102.25822,0.73042,0.18609
12.30000,7.82814,102.50832,102.50832,0.73220,0.18638
12.33000,7.77282,102.75842,102.75843,0.73399,0.18507
12.36000,7.70800,103.00838,103.00837,0.73577,0.18352
12.39000,7.77747,103.25832,103.25832,0.73756,0.18518
12.42000,7.94996,103.50831,103.50832,0.73935,0.18928
12.45000,7.64336,103.75830,103.75830,0.74113,0.18198
12.48000,7.61468,104.00832,104.00832,0.74292,0.18130
12.51000,7.73128,104.25839,104.25839,0.74470,0.18408
12.54000,7.60481,104.50843,104.50843,0.74649,0.18107
12.57000,7.68378,104.75832,104.75832,0.74827,0.18295
12.60000,8.09990,105.00822,105.00822,0.75006,0.19285
12.63000,7.98088,105.25828,105.25828,0.75184,0.19002
12.66000,7.81957,105.50835,105.50835,0.75363,0.18618
12.69000,7.99391,105.75839,105.75839,0.75542,0.19033
12.72000,8.28933,106.00841,106.00841,0.75720,0.19736
12.75000,8.34577,106.25834,106.25835,0.75899,0.19871
12.78000,8.16118,106.50823,106.50822,0.76077,0.19431
12.81000,8.22023,106.75822,106.75822,0.76256,0.19572
12.84000,7.62250,107.00826,107.00827,0.76434,0.18149
12.87000,7.51428,107.25836,107.25836,0.76613,0.17891
12.90000,7.78604,107.50843,107.50843,0.76792,0.18538
12.93000,7.78232,107.75837,107.75837,0.76970,0.18529
12.96000,8.07289,108.00828,108.00828,0.77149,0.19221
12.99000,8.32696,108.25828,108.25828,0.77327,0.19826
13.02000,8.22712,108.50834,108.50835,0.77506,0.19588
13.05000,8.09170,108.75844,108.75844,0.77685,0.19266
13.08000,8.36886,109.00846,109.00846,0.77863,0.19926
13.11000,8.30907,109.25834,109.25835,0.78042,0.19784
13.14000,8.39084,109.50823,109.50822,0.78220,0.19978
13.17000,8.50633,109.75827,109.75827,0.78399,0.20253
13.20000,8.72016,110.00837,110.00837,0.78577,0.20762
13.23000,8.28840,110.25844,110.25844,0.78756,0.19734
13.26000,7.98628,110.50840,110.50840,0.78935,0.19015
13.29000,8.01496,110.75832,110.75832,0.79113,0.19083
13.32000,8.53594,111.00826,111.00826,0.79292,0.20324
13.35000,8.67937,111.25822,111.25822,0.79470,0.20665
13.38000,8.15932,111.50828,111.50829,0.79649,0.19427
13.41000,8.42381,111.75841,111.75842,0.79827,0.20057
13.44000,8.49776,112.00843,112.00843,0.80006,0.20233
13.47000,8.39420,112.25834,112.25834,0.80185,0.19986
13.50000,8.53557,112.50825,112.50825,0.80363,0.20323
13.53000,8.40072,112.75822,112.75822,0.80542,0.20002
13.56000,8.22376,113.00831,113.00832,0.80720,0.19580
13.59000,8.35694,113.25847,113.25847,0.80899,0.19897
13.62000,8.52644,113.50848,113.50848,0.81077,0.20301
13.65000,8.40500,113.75834,113.75834,0.81256,0.20012
13.68000,8.38097,114.00828,114.00828,0.81434,0.19955
13.71000,8.85352,114.25829,114.25829,0.81613,0.21080
13.74000,8.74642,114.50834,114.50834,0.81792,0.20825
13.77000,8.73450,114.75843,114.75843,0.81970,0.20796
13.80000,8.71290,115.00849,115.00848,0.82149,0.20745
13.83000,8.47094,115.25837,115.25837,0.82327,0.20169
13.86000,8.58586,115.50820,115.50820,0.82506,0.20443
13.89000,8.57078,115.75819,115.75819,0.82684,0.20407
13.92000,8.23736,116.00831,116.00831,0.82863,0.19613
13.95000,8.48956,116.25844,116.25844,0.83042,0.20213
13.98000,8.49478,116.50845,116.50845,0.83220,0.20226
14.01000,8.10754,116.75837,116.75837,0.83399,0.19304
14.04000,8.49366,117.00826,117.00826,0.83577,0.20223
14.07000,8.50670,117.25824,117.25824,0.83756,0.20254
14.10000,8.40258,117.50831,117.50831,0.83935,0.20006
14.13000,8.41171,117.75841,117.75842,0.84113,0.20028
14.16000,8.75983,118.00845,118.00845,0.84292,0.20857
14.19000,9.05693,118.25836,118.25836,0.84470,0.21564
14.22000,9.15248,118.50830,118.50830,0.84649,0.21792
14.25000,8.77902,118.75830,118.75830,0.84827,0.20902
14.28000,8.53837,119.00831,119.00831,0.85006,0.20329
14.31000,9.02265,119.25835,119.25835,0.85185,0.21483
14.34000,9.01166,119.50846,119.50845,0.85363,0.21456
14.37000,8.59015,119.75839,119.75839,0.85542,0.20453
14.40000,8.61995,120.00827,120.00828,0.85720,0.20524
14.43000,9.07499,120.25824,120.25824,0.85899,0.21607
14.46000,9.00142,120.50834,120.50834,0.86077,0.21432
14.49000,8.49403,120.75838,120.75838,0.86256,0.20224
14.52000,8.91462,121.00837,121.00837,0.86435,0.21225
14.55000,9.03215,121.25836,121.25835,0.86613,0.21505
14.58000,8.89990,121.50830,121.50830,0.86792,0.21190
14.61000,8.74102,121.75824,121.75824,0.86970,0.20812
14.64000,9.02377,122.00828,122.00828,0.87149,0.21485
14.67000,9.07555,122.25838,122.25838,0.87327,0.21608
14.70000,8.96547,122.50840,122.50840,0.87506,0.21346
14.73000,8.95634,122.75836,122.75836,0.87685,0.21325
14.76000,9.07443,123.00832,123.00832,0.87863,0.21606
14.79000,8.91462,123.25829,123.25829,0.88042,0.21225
14.82000,8.81366,123.50833,123.50833,0.88220,0.20985
14.85000,9.02526,123.75841,123.75842,0.88399,0.21489
14.88000,8.77343,124.00837,124.00838,0.88577,0.20889
14.91000,8.88854,124.25834,124.25834,0.88756,0.21163
14.94000,8.86433,124.50830,124.50830,0.88934,0.21106
14.97000,8.45548,124.75830,124.75830,0.89113,0.20132
15.00000,8.98317,125.00839,125.00839,0.89292,0.21388
15.03000,9.10107,125.25844,125.25845,0.89470,0.21669
15.06000,8.95504,125.50838,125.50838,0.89649,0.21322
15.09000,8.66316,125.75834,125.75834,0.89827,0.20627
15.12000,9.02005,126.00829,126.00829,0.90006,0.21476
15.15000,9.09623,126.25826,126.25826,0.90184,0.21658
15.18000,8.97478,126.50830,126.50830,0.90363,0.21369
15.21000,8.97571,126.75841,126.75841,0.90542,0.21371
15.24000,8.85688,127.00843,127.00843,0.90720,0.21088
15.27000,8.86060,127.25830,127.25830,0.90899,0.21097
15.30000,9.02750,127.50824,127.50824,0.91077,0.21494
15.33000,9.29385,127.75829,127.75829,0.91256,0.22128
15.36000,9.44380,128.00836,128.00836,0.91435,0.22485
15.39000,9.19383,128.25840,128.25839,0.91613,0.21890
15.42000,9.16235,128.50842,128.50842,0.91792,0.21815
15.45000,8.93977,128.75836,128.75836,0.91970,0.21285
15.48000,9.16794,129.00824,129.00824,0.92149,0.21828
15.51000,9.69972,129.25827,129.25827,0.92327,0.23095
15.54000,9.53600,129.50837,129.50838,0.92506,0.22705
15.57000,8.98428,129.75844,129.75844,0.92685,0.21391
15.60000,9.00757,130.00845,130.00845,0.92863,0.21447
15.63000,8.93511,130.25839,130.25839,0.93042,0.21274
15.66000,9.25008,130.50824,130.50824,0.93220,0.22024
15.69000,9.54233,130.75821,130.75821,0.93399,0.22720
15.72000,9.27430,131.00836,131.00836,0.93577,0.22082
15.75000,9.47379,131.25847,131.25847,0.93756,0.22557
15.78000,9.40412,131.50842,131.50842,0.93935,0.22391
15.81000,9.18228,131.75831,131.75832,0.94113,0.21863
15.84000,9.20352,132.00825,132.00824,0.94292,0.21913
15.87000,9.48068,132.25822,132.25822,0.94470,0.22573
15.90000,9.60473,132.50829,132.50829,0.94649,0.22868
15.93000,9.51197,132.75841,132.75841,0.94827,0.22648
15.96000,9.11541,133.00847,133.00847,0.95006,0.21703
15.99000,9.20761,133.25838,133.25838,0.95185,0.21923
16.02000,9.23667,133.50830,133.50830,0.95363,0.21992
16.05000,9.60752,133.75825,133.75826,0.95542,0.22875
16.08000,9.45777,134.00836,134.00836,0.95720,0.22518
16.11000,9.38345,134.25842,134.25842,0.95899,0.22342
16.14000,9.26256,134.50845,134.50845,0.96077,0.22054
16.17000,9.51011,134.75836,134.75836,0.96256,0.22643
16.20000,9.51961,135.00824,135.00824,0.96434,0.22666
16.23000,9.59001,135.25823,135.25822,0.96613,0.22833
16.26000,9.59951,135.50833,135.50833,0.96792,0.22856
16.29000,9.75393,135.75845,135.75845,0.96970,0.23224
16.32000,10.00576,136.00839,136.00839,0.97149,0.23823
16.35000,9.80515,136.25832,136.25832,0.97327,0.23346
16.38000,9.73474,136.50826,136.50826,0.97506,0.23178
16.41000,9.86997,136.75823,136.75822,0.97684,0.23500
16.44000,9.52706,137.00826,137.00826,0.97863,0.22683
16.47000,9.70904,137.25840,137.25841,0.98042,0.23117
16.50000,9.61572,137.50847,137.50847,0.98220,0.22895
16.53000,9.66471,137.75835,137.75835,0.98399,0.23011
16.56000,9.94951,138.00825,138.00824,0.98577,0.23689
16.59000,10.12124,138.25826,138.25826,0.98756,0.24098
16.62000,9.81949,138.50839,138.50839,0.98935,0.23380
16.65000,9.68259,138.75846,138.75845,0.99113,0.23054
16.68000,9.71518,139.00844,139.00844,0.99292,0.23131
16.71000,9.95807,139.25837,139.25836,0.99470,0.23710
16.74000,9.66638,139.50826,139.50826,0.99649,0.23015
16.77000,9.66452,139.75825,139.75826,0.99827,0.23011
16.80000,10.13391,140.00832,140.00832,1.00006,0.24128
16.83000,10.00371,140.25842,140.25842,1.00185,0.23818
16.86000,10.05270,140.50845,140.50844,1.00363,0.23935
16.89000,10.05121,140.75836,140.75836,1.00542,0.23931
16.92000,10.06741,141.00824,141.00824,1.00720,0.23970
16.95000,9.97894,141.25823,141.25822,1.00899,0.23759
16.98000,10.02010,141.50831,141.50832,1.01077,0.23857
17.01000,9.94746,141.75837,141.75838,1.01256,0.23684
17.04000,10.22201,142.00845,142.00847,1.01435,0.24338
17.07000,10.29670,142.25839,142.25839,1.01613,0.24516
17.10000,10.42243,142.50824,142.50822,1.01792,0.24815
17.13000,10.39114,142.75826,142.75826,1.01970,0.24741
17.16000,9.80105,143.00836,143.00836,1.02149,0.23336
17.19000,9.63490,143.25840,143.25841,1.02327,0.22940
17.22000,9.65595,143.50844,143.50844,1.02506,0.22990
17.25000,10.41964,143.75840,143.75841,1.02685,0.24809
17.28000,10.28981,144.00831,144.00830,1.02863,0.24500
17.31000,9.99570,144.25825,144.25824,1.03042,0.23799
17.34000,10.10895,144.50832,144.50833,1.03220,0.24069
17.37000,10.04618,144.75843,144.75844,1.03399,0.23919
17.40000,10.03370,145.00842,145.00841,1.03577,0.23890
17.43000,9.93013,145.25835,145.25835,1.03756,0.23643
17.46000,10.36003,145.50830,145.50830,1.03935,0.24667
17.49000,10.29819,145.75825,145.75826,1.04113,0.24520
17.52000,10.26951,146.00830,146.00830,1.04292,0.24451
17.55000,10.29968,146.25839,146.25839,1.04470,0.24523
17.58000,10.83557,146.50835,146.50836,1.04649,0.25799
17.61000,10.19966,146.75829,146.75827,1.04827,0.24285
17.64000,9.99235,147.00826,147.00827,1.05006,0.23791
17.67000,10.28720,147.25828,147.25829,1.05184,0.24493
17.70000,10.70704,147.50834,147.50835,1.05363,0.25493
17.73000,10.49172,147.75840,147.75838,1.05542,0.24980
17.76000,10.72865,148.00841,148.00841,1.05720,0.25544
17.79000,10.44609,148.25838,148.25838,1.05899,0.24872
17.82000,10.45428,148.50829,148.50830,1.06077,0.24891
17.85000,10.69792,148.75828,148.75829,1.06256,0.25471
17.88000,10.63235,149.00839,149.00839,1.06435,0.25315
17.91000,10.63682,149.25843,149.25842,1.06613,0.25326
17.94000,10.75529,149.50836,149.50836,1.06792,0.25608
17.97000,10.36357,149.75834,149.75833,1.06970,0.24675
18.00000,10.66439,150.00831,150.00832,1.07149,0.25391
18.03000,10.88325,150.25831,150.25832,1.07327,0.25912
18.06000,10.65694,150.50835,150.50835,1.07506,0.25374
18.09000,10.85382,150.75839,150.75839,1.07685,0.25842
18.12000,10.59081,151.00839,151.00839,1.07863,0.25216
18.15000,10.61279,151.25830,151.25830,1.08042,0.25269
18.18000,10.72343,151.50821,151.50821,1.08220,0.25532
18.21000,10.80129,151.75825,151.75826,1.08399,0.25717
18.24000,10.42131,152.00835,152.00835,1.08577,0.24813
18.27000,10.32334,152.25842,152.25842,1.08756,0.24579
18.30000,10.59677,152.50846,152.50845,1.08935,0.25230
18.33000,10.55673,152.75838,152.75838,1.09113,0.25135
18.36000,10.74933,153.00820,153.00818,1.09292,0.25594
18.39000,10.82309,153.25825,153.25826,1.09470,0.25769
18.42000,10.79421,153.50841,153.50841,1.09649,0.25701
18.45000,10.74225,153.75845,153.75845,1.09827,0.25577
18.48000,10.74988,154.00841,154.00841,1.10006,0.25595
18.51000,11.12670,154.25834,154.25833,1.10185,0.26492
18.54000,10.92255,154.50825,154.50826,1.10363,0.26006
18.57000,10.63999,154.75825,154.75826,1.10542,0.25333
18.60000,10.95161,155.00832,155.00832,1.10720,0.26075
18.63000,11.05685,155.25845,155.25844,1.10899,0.26326
18.66000,10.79924,155.50846,155.50847,1.11077,0.25712
18.69000,11.16209,155.75835,155.75836,1.11256,0.26576
18.72000,11.37704,156.00823,156.00822,1.11434,0.27088
18.75000,11.11887,156.25822,156.25822,1.11613,0.26474
18.78000,11.11180,156.50832,156.50832,1.11792,0.26457
18.81000,11.41466,156.75841,156.75841,1.11970,0.27178
18.84000,11.11906,157.00843,157.00842,1.12149,0.26474
18.87000,10.88697,157.25835,157.25835,1.12327,0.25921
18.90000,11.10956,157.50826,157.50826,1.12506,0.26451
18.93000,11.21257,157.75823,157.75824,1.12684,0.26697
18.96000,11.32544,158.00830,158.00830,1.12863,0.26965
18.99000,11.29806,158.25844,158.25844,1.13042,0.26900
19.02000,11.63054,158.50848,158.50848,1.13220,0.27692
19.05000,11.53052,158.75838,158.75838,1.13399,0.27454
19.08000,11.10435,159.00831,159.00832,1.13577,0.26439
19.11000,11.60856,159.25822,159.25822,1.13756,0.27639
19.14000,11.73541,159.50826,159.50826,1.13934,0.27941
19.17000,11.55250,159.75845,159.75845,1.14113,0.27506
19.20000,11.32805,160.00849,160.00848,1.14292,0.26972
19.23000,11.32842,160.25834,160.25835,1.14470,0.26972
19.26000,11.21648,160.50823,160.50822,1.14649,0.26706
19.29000,11.44465,160.75825,160.75826,1.14827,0.27249
19.32000,11.42658,161.00829,161.00829,1.15006,0.27206
19.35000,11.74808,161.25842,161.25844,1.15185,0.27972
19.38000,12.00475,161.50844,161.50844,1.15363,0.28583
19.41000,11.89914,161.75837,161.75838,1.15542,0.28331
19.44000,11.82146,162.00827,162.00827,1.15720,0.28146
19.47000,11.92521,162.25824,162.25822,1.15899,0.28393
19.50000,11.88368,162.50832,162.50832,1.16077,0.28294
19.53000,11.88293,162.75841,162.75841,1.16256,0.28293
19.56000,11.74882,163.00845,163.00845,1.16435,0.27973
19.59000,11.88740,163.25840,163.25841,1.16613,0.28303
19.62000,12.12470,163.50828,163.50829,1.16792,0.28868
19.65000,11.75143,163.75825,163.75826,1.16970,0.27980
19.68000,11.79054,164.00834,164.00833,1.17149,0.28073
19.71000,11.76447,164.25842,164.25842,1.17327,0.28011
19.74000,11.95334,164.50844,164.50844,1.17506,0.28460
19.77000,11.99935,164.75838,164.75838,1.17685,0.28570
19.80000,12.20517,165.00831,165.00832,1.17863,0.29060
19.83000,11.74156,165.25826,165.25826,1.18042,0.27956
19.86000,11.57559,165.50833,165.50833,1.18220,0.27561
19.89000,11.60074,165.75839,165.75839,1.18399,0.27621
19.92000,11.90919,166.00843,166.00844,1.18577,0.28355
19.95000,12.01574,166.25834,166.25835,1.18756,0.28609
19.98000,11.89914,166.50820,166.50819,1.18934,0.28331
20.01000,11.97699,166.75821,166.75819,1.19113,0.28517
20.04000,12.08838,167.00834,167.00835,1.19292,0.28782
20.07000,12.38529,167.25842,167.25842,1.19470,0.29489
20.10000,12.25527,167.50844,167.50844,1.19649,0.29179
20.13000,11.89355,167.75837,167.75839,1.19827,0.28318
20.16000,12.18934,168.00828,168.00829,1.20006,0.29022
20.19000,12.38342,168.25824,168.25824,1.20184,0.29484
20.22000,7.02459,168.50835,168.50835,1.20363,0.16725
20.24700,-0.04005,168.73339,168.73338,1.20524,-0.00095