File: raw_data/mechanical_tests_Instron_data/Aslan_Test1_a.is_tcyclic_RawData/Specimen_RawData_1.csv
Time,Extension,Extensometer Strain 1,Load,Tensile strain,True strain,Displacement (Strain 1)
(sec),(mm),(mm/mm),(N),(mm/mm),(mm/mm),(mm)
0.00000,0.00000,-0.00014,0.23283,0.00000,0.00000,-0.00178
0.04200,0.06056,-0.00014,0.93877,0.00060,0.00060,-0.00175
0.08400,0.27581,-0.00014,1.02334,0.00271,0.00271,-0.00177
0.12600,0.63404,-0.00014,2.40635,0.00624,0.00622,-0.00177
0.16800,1.04887,-0.00014,1.87270,0.01032,0.01027,-0.00175
0.21000,1.47838,-0.00014,2.18172,0.01455,0.01445,-0.00179
0.25200,1.91681,-0.00014,2.05357,0.01887,0.01869,-0.00177
0.29400,2.36116,-0.00014,2.52556,0.02324,0.02297,-0.00176
0.33600,2.78172,-0.00014,1.80230,0.02738,0.02701,-0.00177
0.37800,3.13757,-0.00014,1.76020,0.03088,0.03041,-0.00178
0.42000,3.48501,-0.00014,2.38642,0.03430,0.03373,-0.00179
0.46200,3.83820,-0.00014,1.69948,0.03778,0.03708,-0.00176
0.50400,4.18971,-0.00014,1.78907,0.04124,0.04041,-0.00174
0.54600,4.53945,-0.00014,2.00812,0.04468,0.04371,-0.00182
0.58800,4.88957,-0.00014,1.97440,0.04813,0.04700,-0.00174
0.63000,5.23963,-0.00014,2.13701,0.05157,0.05029,-0.00181
0.67200,5.58932,-0.00014,1.98353,0.05501,0.05355,-0.00175
0.71400,5.93930,-0.00014,1.99992,0.05846,0.05681,-0.00178
0.75600,6.28918,-0.00014,2.24914,0.06190,0.06006,-0.00178
0.79800,6.63897,-0.00014,2.10963,0.06534,0.06330,-0.00174
0.84000,6.98898,-0.00014,2.12584,0.06879,0.06653,-0.00180
0.88200,7.33869,-0.00014,2.23164,0.07223,0.06974,-0.00178
0.92400,7.68851,-0.00014,2.25790,0.07567,0.07295,-0.00176
0.96600,8.03855,-0.00014,2.52947,0.07912,0.07615,-0.00177
1.00800,8.38829,-0.00014,2.75038,0.08256,0.07933,-0.00175
1.05000,8.73819,-0.00014,2.48384,0.08601,0.08251,-0.00180
1.09200,9.08807,-0.00014,2.16458,0.08945,0.08567,-0.00178
1.13400,9.43781,-0.00014,2.31396,0.09289,0.08883,-0.00176
1.17600,9.78790,-0.00014,2.41455,0.09634,0.09198,-0.00178
1.21800,10.13758,-0.00014,2.55778,0.09978,0.09511,-0.00178
1.26000,10.48743,-0.00014,2.75988,0.10322,0.09824,-0.00177
1.30200,10.83744,-0.00014,2.54642,0.10667,0.10135,-0.00178
1.34400,11.18713,-0.00014,2.19159,0.11011,0.10446,-0.00176
1.38600,11.53711,-0.00014,2.29310,0.11355,0.10756,-0.00180
1.42800,11.88696,-0.00014,2.82023,0.11700,0.11064,-0.00175
1.47000,12.23665,-0.00014,2.53338,0.12044,0.11372,-0.00180
1.51200,12.58665,-0.00014,2.75504,0.12388,0.11679,-0.00178
1.55400,12.93653,-0.00014,2.55555,0.12733,0.11985,-0.00175
1.59600,13.28630,-0.00014,2.74666,0.13077,0.12290,-0.00182
1.63800,13.63631,-0.00014,2.64402,0.13422,0.12594,-0.00175
1.68000,13.98607,-0.00014,2.68519,0.13766,0.12897,-0.00178
1.72200,14.33584,-0.00014,2.66396,0.14110,0.13199,-0.00177
1.76400,14.68593,-0.00014,2.54977,0.14455,0.13501,-0.00175
1.80600,15.03565,-0.00014,2.73734,0.14799,0.13801,-0.00180
1.84800,15.38552,-0.00014,2.26162,0.15143,0.14101,-0.00176
1.89000,15.73539,-0.00014,2.72878,0.15488,0.14399,-0.00180
1.93200,16.08516,-0.00014,2.96291,0.15832,0.14697,-0.00179
1.97400,16.43520,-0.00014,2.11708,0.16176,0.14994,-0.00174
2.01600,16.78499,-0.00014,2.61683,0.16521,0.15290,-0.00179
2.05800,17.13473,-0.00014,2.65315,0.16865,0.15585,-0.00176
2.10000,17.48469,-0.00014,2.46149,0.17209,0.15879,-0.00174
2.14200,17.83454,-0.00014,2.59075,0.17554,0.16172,-0.00181
2.18400,18.18438,-0.00014,2.99048,0.17898,0.16465,-0.00176
2.22600,18.53429,-0.00014,2.63974,0.18242,0.16757,-0.00179
2.26800,18.88400,-0.00014,2.95248,0.18587,0.17047,-0.00177
2.31000,19.23401,-0.00014,2.63304,0.18931,0.17337,-0.00175
2.35200,19.58396,-0.00014,2.72561,0.19276,0.17627,-0.00183
2.39400,19.93365,-0.00014,2.49464,0.19620,0.17915,-0.00174
2.43600,20.28363,-0.00014,2.53040,0.19964,0.18202,-0.00176
2.47800,20.63335,-0.00014,2.17427,0.20308,0.18489,-0.00180
2.52000,20.98322,-0.00014,2.61795,0.20653,0.18775,-0.00174
2.56200,21.33329,-0.00014,2.48346,0.20997,0.19060,-0.00179
2.60400,21.68292,-0.00014,2.38959,0.21341,0.19344,-0.00175
2.64600,22.03285,-0.00014,2.48179,0.21686,0.19627,-0.00176
2.68800,22.38278,-0.00014,2.69413,0.22030,0.19910,-0.00177
2.73000,22.73246,-0.00014,2.56933,0.22374,0.20192,-0.00177
2.77200,23.08247,-0.00014,2.46819,0.22719,0.20473,-0.00179
2.81400,23.43229,-0.00014,2.42684,0.23063,0.20753,-0.00176
2.85600,23.78203,-0.00014,2.66936,0.23408,0.21032,-0.00178
2.89800,24.13212,-0.00014,2.60063,0.23752,0.21311,-0.00176
2.94000,24.48186,-0.00014,2.59858,0.24096,0.21589,-0.00175
2.98200,24.83177,-0.00014,2.71946,0.24441,0.21866,-0.00179
3.02400,25.18172,-0.00014,2.86568,0.24785,0.22142,-0.00179
3.06600,25.53135,-0.00014,2.10032,0.25129,0.22418,-0.00176
3.10800,25.88131,-0.00014,2.44267,0.25474,0.22693,-0.00177
3.15000,26.23124,-0.00014,2.65483,0.25818,0.22967,-0.00174
3.19200,26.58098,-0.00014,2.59429,0.26162,0.23240,-0.00178
3.23400,26.93093,-0.00014,2.57920,0.26507,0.23513,-0.00175
3.27600,27.28070,-0.00014,2.61255,0.26851,0.23784,-0.00177
3.31800,27.63060,-0.00014,2.62558,0.27195,0.24055,-0.00180
3.36000,27.98056,-0.00014,2.63974,0.27540,0.24326,-0.00173
3.40200,28.33030,-0.00014,2.83681,0.27884,0.24595,-0.00177
3.44400,28.68015,-0.00014,2.60472,0.28228,0.24864,-0.00177
3.48600,29.03013,-0.00014,2.93348,0.28573,0.25133,-0.00174
3.52800,29.37990,-0.00014,2.94801,0.28917,0.25400,-0.00182
3.57000,29.72985,-0.00014,2.72486,0.29262,0.25667,-0.00172
3.61200,30.07967,-0.00014,3.13241,0.29606,0.25933,-0.00179
3.65400,30.42942,-0.00014,2.73157,0.29950,0.26198,-0.00179
3.69600,30.77948,-0.00014,2.97632,0.30295,0.26463,-0.00175
3.73800,31.12919,-0.00014,2.78447,0.30639,0.26727,-0.00178
3.78000,31.47898,-0.00014,2.62912,0.30983,0.26990,-0.00176
3.82200,31.82902,-0.00014,2.58014,0.31328,0.27253,-0.00178
3.86400,32.17871,-0.00014,2.52742,0.31672,0.27514,-0.00180
3.90600,32.52864,-0.00014,2.73399,0.32016,0.27776,-0.00175
3.94800,32.87851,-0.00014,2.68500,0.32361,0.28036,-0.00179
3.99000,33.22825,-0.00014,2.43261,0.32705,0.28296,-0.00178
4.03200,33.57832,-0.00014,2.77627,0.33050,0.28555,-0.00176
4.07400,33.92822,-0.00014,2.87928,0.33394,0.28814,-0.00180
4.11600,34.27785,-0.00014,2.64738,0.33738,0.29071,-0.00177
4.15800,34.62791,-0.00014,2.75355,0.34083,0.29329,-0.00177
4.20000,34.97765,-0.00014,2.71425,0.34427,0.29585,-0.00178
4.24200,35.32750,-0.00014,2.52817,0.34771,0.29841,-0.00174
4.28400,35.67748,-0.00014,2.84147,0.35116,0.30096,-0.00179
4.32600,36.02720,-0.00014,2.52649,0.35460,0.30351,-0.00176
4.36800,36.37715,-0.00014,2.51569,0.35804,0.30604,-0.00178
4.41000,36.72700,-0.00014,2.50898,0.36149,0.30858,-0.00178
4.45200,37.07674,-0.00014,2.54586,0.36493,0.31110,-0.00177
4.49400,37.42678,-0.00014,2.70046,0.36837,0.31362,-0.00179
4.53600,37.77649,-0.00014,2.62037,0.37182,0.31614,-0.00174
4.57800,38.12634,-0.00014,2.31434,0.37526,0.31864,-0.00180
4.62000,38.47638,-0.00014,2.60323,0.37870,0.32114,-0.00179
4.66200,38.82612,-0.00014,2.43727,0.38215,0.32364,-0.00178
4.70400,39.17602,-0.00014,2.61609,0.38559,0.32613,-0.00179
4.74600,39.52589,-0.00014,2.62950,0.38903,0.32861,-0.00176
4.78800,39.87558,-0.00014,2.78894,0.39248,0.33108,-0.00178
4.83000,40.22567,-0.00014,2.71853,0.39592,0.33356,-0.00176
4.87200,40.57549,-0.00014,2.68035,0.39937,0.33602,-0.00178
4.91400,40.92520,-0.00014,2.89492,0.40281,0.33848,-0.00180
4.95600,41.27521,-0.00014,2.86307,0.40625,0.34093,-0.00175
4.99800,41.62493,-0.00014,2.52035,0.40969,0.34337,-0.00178
5.04000,41.97488,-0.00014,2.61609,0.41314,0.34581,-0.00180
5.08200,42.32486,-0.00014,2.17464,0.41658,0.34825,-0.00175
5.12400,42.67450,-0.00014,2.61031,0.42002,0.35067,-0.00181
5.16600,43.02443,-0.00014,2.83867,0.42347,0.35310,-0.00177
5.20800,43.37438,-0.00014,2.67867,0.42691,0.35551,-0.00177
5.25000,43.72415,-0.00014,2.57920,0.43036,0.35792,-0.00181
5.29200,44.07405,-0.00014,2.62558,0.43380,0.36033,-0.00174
5.33400,44.42390,-0.00014,2.54884,0.43724,0.36273,-0.00181
5.37600,44.77369,-0.00014,2.39946,0.44069,0.36512,-0.00177
5.41800,45.12376,-0.00014,2.32365,0.44413,0.36751,-0.00177
5.46000,45.47347,-0.00014,2.61832,0.44757,0.36989,-0.00180
5.50200,45.82326,-0.00014,2.68370,0.45102,0.37226,-0.00176
5.54400,46.17325,-0.00014,2.45869,0.45446,0.37464,-0.00180
5.58600,46.52296,-0.00014,2.59373,0.45790,0.37700,-0.00179
5.62800,46.87297,-0.00014,2.43578,0.46135,0.37936,-0.00176
5.67000,47.22285,-0.00014,2.13776,0.46479,0.38171,-0.00180
5.71200,47.57253,-0.00014,2.50805,0.46823,0.38406,-0.00175
5.75400,47.92254,-0.00014,2.44081,0.47168,0.38640,-0.00177
5.79600,48.27231,-0.00014,2.46353,0.47512,0.38874,-0.00180
5.83800,48.62218,-0.00014,2.14390,0.47856,0.39107,-0.00176
5.88000,48.97219,-0.00014,2.46242,0.48201,0.39340,-0.00177
5.92200,49.32185,-0.00014,2.47806,0.48545,0.39572,-0.00177
5.96400,49.67175,-0.00014,2.35401,0.48890,0.39803,-0.00177
6.00600,50.02176,-0.00014,2.08709,0.49234,0.40035,-0.00179
6.04800,50.37145,-0.00014,2.36835,0.49578,0.40265,-0.00176
6.09000,50.72146,-0.00014,2.17333,0.49923,0.40495,-0.00178
6.13200,51.07123,-0.00014,2.31117,0.50267,0.40724,-0.00179
6.17400,51.42097,-0.00014,1.81403,0.50611,0.40953,-0.00175
6.21600,51.77111,-0.00014,1.85370,0.50956,0.41182,-0.00179
6.25800,52.12080,-0.00014,2.45087,0.51300,0.41409,-0.00176
6.30000,52.47062,-0.00014,2.08281,0.51644,0.41637,-0.00178
6.34200,52.82057,-0.00014,2.32067,0.51989,0.41864,-0.00178
6.38400,53.17032,-0.00014,2.39424,0.52333,0.42090,-0.00177
6.42600,53.52032,-0.00014,2.62018,0.52677,0.42316,-0.00180
6.46800,53.87017,-0.00014,2.14353,0.53022,0.42541,-0.00176
6.51000,54.21983,-0.00014,2.26311,0.53366,0.42766,-0.00179
6.55200,54.56987,-0.00014,2.33818,0.53711,0.42990,-0.00177
6.59400,54.91972,-0.00014,2.38772,0.54055,0.43214,-0.00179
6.63600,55.26954,-0.00014,2.12621,0.54399,0.43437,-0.00179
6.67800,55.61952,-0.00014,2.21338,0.54744,0.43660,-0.00176
6.72000,55.96918,-0.00014,2.33632,0.55088,0.43882,-0.00180
6.76200,56.31916,-0.00014,2.52947,0.55432,0.44104,-0.00177
6.80400,56.66906,-0.00014,1.93696,0.55777,0.44325,-0.00175
6.84600,57.01878,-0.00014,2.03121,0.56121,0.44546,-0.00178
6.88800,57.36879,-0.00014,1.85780,0.56465,0.44766,-0.00178
6.93000,57.71858,-0.00014,2.55294,0.56810,0.44986,-0.00179
6.97200,58.06835,-0.00014,2.70307,0.57154,0.45206,-0.00179
7.01400,58.41839,-0.00014,2.22083,0.57498,0.45425,-0.00173
7.05600,58.76815,-0.00014,2.52016,0.57843,0.45643,-0.00181
7.09800,59.11797,-0.00014,2.46540,0.58187,0.45861,-0.00177
7.14000,59.46798,-0.00014,2.43150,0.58531,0.46078,-0.00178
7.18200,59.81767,-0.00014,2.81315,0.58876,0.46295,-0.00180
7.22400,60.16763,-0.00014,2.31620,0.59220,0.46512,-0.00174
7.26600,60.51756,-0.00014,2.48905,0.59565,0.46728,-0.00181
7.30800,60.86716,-0.00014,3.01618,0.59909,0.46943,-0.00177
7.35000,61.21722,-0.00014,3.05343,0.60253,0.47158,-0.00175
7.39200,61.56710,-0.00014,3.09367,0.60598,0.47373,-0.00181
7.43400,61.91684,-0.00014,3.17935,0.60942,0.47587,-0.00177
7.47600,62.26687,-0.00014,2.79862,0.61286,0.47801,-0.00178
7.51800,62.61651,-0.00014,3.46284,0.61630,0.48014,-0.00178
7.56000,62.96644,-0.00014,3.56995,0.61975,0.48227,-0.00178
7.60200,63.31642,-0.00014,3.49898,0.62319,0.48440,-0.00179
7.64400,63.66611,-0.00014,3.64110,0.62663,0.48651,-0.00175
7.68600,64.01606,-0.00014,3.68338,0.63008,0.48863,-0.00179
7.72800,64.36598,-0.00014,3.90448,0.63352,0.49074,-0.00178
7.77000,64.71570,-0.00014,3.64501,0.63697,0.49284,-0.00175
7.81200,65.06577,-0.00014,3.63775,0.64041,0.49495,-0.00178
7.85400,65.41545,-0.00014,3.42578,0.64385,0.49704,-0.00179
7.89600,65.76530,-0.00014,3.32370,0.64730,0.49914,-0.00176
7.93800,66.11539,-0.00014,3.60869,0.65074,0.50122,-0.00178
7.98000,66.46497,-0.00014,3.77186,0.65418,0.50331,-0.00175
8.02200,66.81492,-0.00014,3.50270,0.65763,0.50539,-0.00178
8.06400,67.16483,-0.00014,3.55653,0.66107,0.50746,-0.00178
8.10600,67.51456,-0.00014,3.60794,0.66451,0.50953,-0.00177
8.14800,67.86463,-0.00014,3.63309,0.66796,0.51160,-0.00179
8.19000,68.21435,-0.00014,3.55225,0.67140,0.51366,-0.00176
8.23200,68.56416,-0.00014,3.94378,0.67484,0.51572,-0.00181
8.27400,68.91420,-0.00014,3.97861,0.67829,0.51778,-0.00177
8.31600,69.26392,-0.00014,3.68599,0.68173,0.51982,-0.00177
8.35800,69.61376,-0.00014,3.60254,0.68517,0.52187,-0.00181
8.40000,69.96377,-0.00014,3.63849,0.68862,0.52391,-0.00176
8.44200,70.31346,-0.00014,3.69102,0.69206,0.52595,-0.00179
8.48400,70.66344,-0.00014,3.62936,0.69551,0.52798,-0.00178
8.52600,71.01331,-0.00014,3.93763,0.69895,0.53001,-0.00175
8.56800,71.36303,-0.00014,3.71989,0.70239,0.53203,-0.00179
8.61000,71.71301,-0.00014,3.80632,0.70584,0.53406,-0.00173
8.65200,72.06278,-0.00014,3.74112,0.70928,0.53607,-0.00180
8.69400,72.41265,-0.00014,3.46173,0.71272,0.53808,-0.00176
8.73600,72.76266,-0.00014,3.79384,0.71617,0.54009,-0.00177
8.77800,73.11235,-0.00014,4.07863,0.71961,0.54210,-0.00179
8.82000,73.46225,-0.00014,3.81377,0.72305,0.54410,-0.00176
8.86200,73.81218,-0.00014,3.85828,0.72650,0.54609,-0.00177
8.90400,74.16195,-0.00014,4.18238,0.72994,0.54809,-0.00179
8.94600,74.51191,-0.00014,3.99407,0.73338,0.55008,-0.00173
8.98800,74.86175,-0.00014,4.04660,0.73683,0.55206,-0.00180
9.03000,75.21147,-0.00014,3.84264,0.74027,0.55404,-0.00177
9.07200,75.56153,-0.00014,3.90653,0.74372,0.55602,-0.00176
9.11400,75.91132,-0.00014,4.02927,0.74716,0.55799,-0.00179
9.15600,76.26115,-0.00014,3.98923,0.75060,0.55996,-0.00174
9.19800,76.61107,-0.00014,3.86592,0.75405,0.56193,-0.00179
9.24000,76.96073,-0.00014,3.68841,0.75749,0.56389,-0.00176
9.28200,77.31080,-0.00014,3.79458,0.76093,0.56584,-0.00175
9.32400,77.66070,-0.00014,4.23361,0.76438,0.56780,-0.00179
9.36600,78.01028,-0.00014,3.60236,0.76782,0.56975,-0.00174
9.40800,78.36039,-0.00014,4.03114,0.77126,0.57169,-0.00179
9.45000,78.71019,-0.00014,4.02946,0.77471,0.57364,-0.00176
9.49200,79.06001,-0.00014,3.78061,0.77815,0.57557,-0.00176
9.53400,79.41002,-0.00014,4.45284,0.78159,0.57751,-0.00176
9.57600,79.75965,-0.00014,4.28315,0.78504,0.57944,-0.00174
9.61800,80.10957,-0.00014,3.94229,0.78848,0.58137,-0.00176
9.66000,80.45959,-0.00014,4.19673,0.79193,0.58329,-0.00176
9.70200,80.80927,-0.00014,3.62135,0.79537,0.58521,-0.00177
9.74400,81.15926,-0.00014,3.75062,0.79881,0.58713,-0.00178
9.78600,81.50908,-0.00014,3.99128,0.80225,0.58904,-0.00174
9.82800,81.85880,-0.00014,4.05479,0.80570,0.59095,-0.00178
9.87000,82.20888,-0.00014,4.05405,0.80914,0.59285,-0.00177
9.91200,82.55862,-0.00014,4.10676,0.81258,0.59475,-0.00174
9.95400,82.90847,-0.00014,3.92981,0.81603,0.59665,-0.00179
9.99600,83.25840,-0.00014,4.00431,0.81947,0.59855,-0.00178
10.03800,83.60812,-0.00014,3.73740,0.82291,0.60044,-0.00176
10.08000,83.95809,-0.00014,4.05982,0.82636,0.60232,-0.00179
10.12200,84.30802,-0.00014,4.19877,0.82980,0.60421,-0.00175
10.16400,84.65774,-0.00014,4.13954,0.83325,0.60609,-0.00179
10.20600,85.00770,-0.00014,3.58950,0.83669,0.60796,-0.00173
10.24800,85.35754,-0.00014,3.90019,0.84013,0.60984,-0.00178
10.29000,85.70736,-0.00014,3.91379,0.84358,0.61171,-0.00179
10.33200,86.05737,-0.00014,3.93596,0.84702,0.61357,-0.00174
10.37400,86.40700,-0.00014,3.97563,0.85046,0.61544,-0.00179
10.41600,86.75688,-0.00014,3.76347,0.85391,0.61729,-0.00175
10.45800,87.10694,-0.00014,3.87318,0.85735,0.61915,-0.00176
10.50000,87.45664,-0.00014,3.65265,0.86079,0.62100,-0.00179
10.54200,87.80656,-0.00014,3.54219,0.86424,0.62285,-0.00175
10.58400,88.15637,-0.00014,3.59602,0.86768,0.62470,-0.00179
10.62600,88.50614,-0.00014,3.98010,0.87112,0.62654,-0.00177
10.66800,88.85621,-0.00014,3.80836,0.87457,0.62838,-0.00176
10.71000,89.20597,-0.00014,4.14718,0.87801,0.63021,-0.00180
10.75200,89.55577,-0.00014,3.70741,0.88145,0.63205,-0.00175
10.79400,89.90581,-0.00014,3.61353,0.88490,0.63387,-0.00176
10.83600,90.25555,-0.00014,3.56156,0.88834,0.63570,-0.00179
10.87800,90.60540,-0.00014,3.45316,0.89179,0.63752,-0.00173
10.92000,90.95538,-0.00014,3.79495,0.89523,0.63934,-0.00179
10.96200,91.30504,-0.00014,3.62024,0.89867,0.64115,-0.00179
11.00400,91.65505,-0.00014,3.84320,0.90212,0.64297,-0.00177
11.04600,92.00489,-0.00014,3.67835,0.90556,0.64478,-0.00177
11.08800,92.35461,-0.00014,3.45521,0.90900,0.64658,-0.00175
11.13000,92.70467,-0.00014,3.86555,0.91245,0.64838,-0.00179
11.17200,93.05436,-0.00014,3.59006,0.91589,0.65018,-0.00178
11.21400,93.40429,-0.00014,4.05349,0.91933,0.65198,-0.00176
11.25600,93.75424,-0.00014,3.70815,0.92278,0.65377,-0.00178
11.29800,94.10393,-0.00014,3.79290,0.92622,0.65556,-0.00176
11.34000,94.45391,-0.00014,3.75360,0.92966,0.65735,-0.00180
11.38200,94.80379,-0.00014,3.58410,0.93311,0.65913,-0.00180
11.42400,95.15353,-0.00014,3.74019,0.93655,0.66091,-0.00177
11.46600,95.50356,-0.00014,3.68524,0.94000,0.66269,-0.00177
11.50800,95.85334,-0.00014,3.82829,0.94344,0.66446,-0.00177
11.55000,96.20310,-0.00014,3.52450,0.94688,0.66623,-0.00179
11.59200,96.55314,-0.00014,3.74261,0.95033,0.66800,-0.00176
11.63400,96.90279,-0.00014,3.57851,0.95377,0.66976,-0.00177
11.67600,97.25275,-0.00014,3.48408,0.95721,0.67152,-0.00179
11.71800,97.60268,-0.00014,3.65004,0.96066,0.67328,-0.00176
11.76000,97.95234,-0.00014,3.64352,0.96410,0.67503,-0.00179
11.80200,98.30240,-0.00014,3.77353,0.96754,0.67679,-0.00178
11.84400,98.65223,-0.00014,3.50233,0.97099,0.67853,-0.00175
11.88600,99.00196,-0.00014,3.73181,0.97443,0.68028,-0.00179
11.92800,99.35195,-0.00014,3.99202,0.97787,0.68202,-0.00176
11.97000,99.70180,-0.00014,4.03319,0.98132,0.68376,-0.00178
12.01200,100.05167,-0.00014,3.88827,0.98476,0.68550,-0.00178
12.05400,100.40157,-0.00014,3.39802,0.98820,0.68723,-0.00173
12.09600,100.75129,-0.00014,3.52710,0.99165,0.68896,-0.00179
12.13800,101.10119,-0.00014,3.55896,0.99509,0.69069,-0.00177
12.18000,101.45119,-0.00014,3.56995,0.99854,0.69241,-0.00175
12.22200,101.80088,-0.00014,3.87765,1.00198,0.69414,-0.00181
12.26400,102.15078,-0.00014,3.59286,1.00542,0.69585,-0.00174
12.30600,102.50066,-0.00014,3.85605,1.00886,0.69757,-0.00179
12.34800,102.85043,-0.00014,3.86909,1.01231,0.69928,-0.00176
12.39000,103.20046,-0.00014,3.72883,1.01575,0.70099,-0.00176
12.43200,103.55015,-0.00014,3.73106,1.01919,0.70270,-0.00178
12.47400,103.90008,-0.00014,4.02723,1.02264,0.70440,-0.00175
12.51600,104.25005,-0.00014,3.86480,1.02608,0.70610,-0.00176
12.55800,104.59983,-0.00014,3.80967,1.02953,0.70780,-0.00177
12.60000,104.94975,-0.00014,3.86350,1.03297,0.70950,-0.00177
12.64200,105.29958,-0.00014,3.43174,1.03641,0.71119,-0.00181
12.68400,105.64929,-0.00014,3.82941,1.03986,0.71288,-0.00175
12.72600,105.99933,-0.00014,3.91677,1.04330,0.71457,-0.00177
12.76800,106.34915,-0.00014,3.33898,1.04674,0.71625,-0.00180
12.81000,106.69891,-0.00014,3.68692,1.05019,0.71793,-0.00175
12.85200,107.04893,-0.00014,3.44273,1.05363,0.71961,-0.00179
12.89400,107.39858,-0.00014,3.70387,1.05707,0.72128,-0.00175
12.93600,107.74851,-0.00014,3.79831,1.06052,0.72296,-0.00176
12.97800,108.09852,-0.00014,3.67705,1.06396,0.72463,-0.00180
13.02000,108.44818,-0.00014,4.02462,1.06740,0.72629,-0.00175
13.06200,108.79819,-0.00014,3.98979,1.07085,0.72796,-0.00179
13.10400,109.14795,-0.00014,3.61931,1.07429,0.72962,-0.00176
13.14600,109.49778,-0.00014,3.91193,1.07773,0.73128,-0.00178
13.18800,109.84789,-0.00014,3.54759,1.08118,0.73294,-0.00179
13.23000,110.19759,-0.00014,3.68040,1.08462,0.73459,-0.00175
13.27200,110.54737,-0.00014,3.32873,1.08806,0.73624,-0.00179
13.31400,110.89742,-0.00014,3.45930,1.09151,0.73789,-0.00177
13.35600,111.24712,-0.00014,3.63439,1.09495,0.73953,-0.00176
13.39800,111.59706,-0.00014,3.61726,1.09840,0.74117,-0.00179
13.44000,111.94685,-0.00014,3.41665,1.10184,0.74281,-0.00178
13.48200,112.29662,-0.00014,3.65712,1.10528,0.74445,-0.00177
13.52400,112.64668,-0.00014,3.92590,1.10873,0.74608,-0.00176
13.56600,112.99647,-0.00014,3.56454,1.11217,0.74772,-0.00178
13.60800,113.34627,-0.00014,3.35909,1.11561,0.74934,-0.00181
13.65000,113.69622,-0.00014,4.19375,1.11906,0.75097,-0.00174
13.69200,114.04594,-0.00014,3.58969,1.12250,0.75259,-0.00177
13.73400,114.39595,-0.00014,3.72045,1.12594,0.75422,-0.00178
13.77600,114.74588,-0.00014,3.52655,1.12939,0.75583,-0.00175
13.81800,115.09556,-0.00014,3.93335,1.13283,0.75745,-0.00181
13.86000,115.44550,-0.00014,3.53567,1.13627,0.75906,-0.00176
13.90200,115.79540,-0.00014,3.84022,1.13972,0.76067,-0.00177
13.94400,116.14513,-0.00014,3.84450,1.14316,0.76228,-0.00179
13.98600,116.49515,-0.00014,3.53362,1.14661,0.76389,-0.00175
14.02800,116.84491,-0.00014,3.69344,1.15005,0.76549,-0.00180
14.07000,117.19468,-0.00014,3.66047,1.15349,0.76709,-0.00177
14.11200,117.54474,-0.00014,3.81116,1.15694,0.76869,-0.00177
14.15400,117.89446,-0.00014,3.66364,1.16038,0.77028,-0.00180
14.19600,118.24436,-0.00014,3.72157,1.16382,0.77188,-0.00176
14.23800,118.59429,-0.00014,4.03430,1.16727,0.77347,-0.00180
14.28000,118.94397,-0.00014,4.03877,1.17071,0.77505,-0.00176
14.32200,119.29401,-0.00014,3.88771,1.17415,0.77664,-0.00176
14.36400,119.64386,-0.00014,4.05665,1.17760,0.77822,-0.00181
14.40600,119.99359,-0.00014,3.69418,1.18104,0.77980,-0.00177
14.44800,120.34355,-0.00014,3.70666,1.18448,0.78138,-0.00177
14.49000,120.69337,-0.00014,3.53102,1.18793,0.78295,-0.00177
14.53200,121.04325,-0.00014,3.58857,1.19137,0.78453,-0.00177
14.57400,121.39323,-0.00014,3.63104,1.19482,0.78610,-0.00179
14.61600,121.74287,-0.00014,3.56939,1.19826,0.78766,-0.00175
14.65800,122.09282,-0.00014,3.78061,1.20170,0.78923,-0.00177
14.70000,122.44275,-0.00014,4.15891,1.20515,0.79079,-0.00178
14.74200,122.79244,-0.00014,4.34387,1.20859,0.79235,-0.00177
14.78400,123.14247,-0.00014,3.92143,1.21203,0.79391,-0.00179
14.82600,123.49221,-0.00014,4.07360,1.21547,0.79547,-0.00179
14.86800,123.84205,-0.00014,3.96594,1.21892,0.79702,-0.00177
14.91000,124.19213,-0.00014,4.06634,1.22236,0.79857,-0.00179
14.95200,124.54175,-0.00014,3.89609,1.22580,0.80012,-0.00176
14.99400,124.89171,-0.00014,4.16674,1.22925,0.80166,-0.00177
15.03600,125.24161,-0.00014,3.95607,1.23269,0.80321,-0.00177
15.07800,125.59137,-0.00014,4.06913,1.23614,0.80475,-0.00177
15.12000,125.94136,-0.00014,4.20902,1.23958,0.80629,-0.00177
15.16200,126.29116,-0.00014,4.10322,1.24302,0.80782,-0.00176
15.20400,126.64092,-0.00014,3.96818,1.24647,0.80936,-0.00180
15.24600,126.99096,-0.00014,3.86182,1.24991,0.81089,-0.00175
15.28800,127.34072,-0.00014,4.23659,1.25335,0.81242,-0.00178
15.33000,127.69052,-0.00014,4.17028,1.25680,0.81395,-0.00180
15.37200,128.04050,-0.00014,4.19635,1.26024,0.81547,-0.00176
15.41400,128.39022,-0.00014,4.04101,1.26368,0.81699,-0.00180
15.45600,128.74017,-0.00014,4.26043,1.26713,0.81851,-0.00176
15.49800,129.09004,-0.00014,4.31500,1.27057,0.82003,-0.00177
15.54000,129.43984,-0.00014,4.33624,1.27401,0.82155,-0.00179
15.58200,129.78982,-0.00014,4.06113,1.27746,0.82306,-0.00175
15.62400,130.13965,-0.00014,4.26155,1.28090,0.82457,-0.00178
15.66600,130.48944,-0.00014,3.99351,1.28434,0.82608,-0.00181
15.70800,130.83940,-0.00014,4.03430,1.28779,0.82759,-0.00175
15.75000,131.18913,-0.00014,4.52399,1.29123,0.82909,-0.00179
15.79200,131.53898,-0.00014,4.33587,1.29467,0.83059,-0.00176
15.83400,131.88900,-0.00014,4.45526,1.29812,0.83209,-0.00176
15.87600,132.23870,-0.00014,4.09316,1.30156,0.83359,-0.00180
15.91800,132.58863,-0.00014,4.19412,1.30501,0.83508,-0.00174
15.96000,132.93848,-0.00014,4.34592,1.30845,0.83658,-0.00180
16.00200,133.28820,-0.00014,4.33009,1.31189,0.83807,-0.00177
16.04400,133.63831,-0.00014,4.24832,1.31534,0.83956,-0.00178
16.08600,133.98809,-0.00014,4.23770,1.31878,0.84104,-0.00179
16.12800,134.33781,-0.00014,4.33344,1.32222,0.84252,-0.00175
16.17000,134.68790,-0.00014,4.44632,1.32567,0.84401,-0.00180
16.21200,135.03762,-0.00014,4.58770,1.32911,0.84549,-0.00177
16.25400,135.38756,-0.00014,3.99239,1.33255,0.84696,-0.00177
16.29600,135.73748,-0.00014,4.58285,1.33600,0.84844,-0.00177
16.33800,136.08710,-0.00014,4.04231,1.33944,0.84991,-0.00177
16.38000,136.43712,-0.00014,3.83668,1.34289,0.85138,-0.00180
16.42200,136.78701,-0.00014,4.03952,1.34633,0.85285,-0.00179
16.46400,137.13671,-0.00014,4.29582,1.34977,0.85432,-0.00176
16.50600,137.48672,-0.00014,4.40404,1.35322,0.85578,-0.00177
16.54800,137.83646,-0.00014,4.56758,1.35666,0.85724,-0.00178
16.59000,138.18634,-0.00014,4.42285,1.36010,0.85870,-0.00178
16.63200,138.53640,-0.00014,4.47650,1.36355,0.86016,-0.00178
16.67400,138.88601,-0.00014,4.51691,1.36699,0.86162,-0.00176
16.71600,139.23597,-0.00014,4.28651,1.37043,0.86307,-0.00178
16.75800,139.58584,-0.00014,4.58583,1.37388,0.86452,-0.00177
16.80000,139.93566,-0.00014,4.72572,1.37732,0.86597,-0.00178
16.84200,140.28566,-0.00014,4.44110,1.38076,0.86742,-0.00177
16.88400,140.63540,-0.00014,4.40832,1.38421,0.86887,-0.00176
16.92600,140.98520,-0.00014,4.49549,1.38765,0.87031,-0.00181
16.96800,141.33518,-0.00014,4.39603,1.39109,0.87175,-0.00175
17.01000,141.68493,-0.00014,4.19840,1.39454,0.87319,-0.00178
17.05200,142.03485,-0.00014,4.51319,1.39798,0.87463,-0.00180
17.09400,142.38475,-0.00014,5.05578,1.40142,0.87606,-0.00176
17.13600,142.73441,-0.00014,4.70839,1.40487,0.87749,-0.00180
17.17800,143.08440,-0.00014,4.37051,1.40831,0.87893,-0.00175
17.22000,143.43432,-0.00014,4.47724,1.41176,0.88035,-0.00180
17.26200,143.78413,-0.00014,4.59701,1.41520,0.88178,-0.00178
17.30400,144.13411,-0.00014,4.63463,1.41864,0.88321,-0.00174
17.34600,144.48381,-0.00014,4.90807,1.42208,0.88463,-0.00179
17.38800,144.83371,-0.00014,4.53684,1.42553,0.88605,-0.00177
17.43000,145.18371,-0.00014,4.52101,1.42897,0.88747,-0.00175
17.47200,145.53341,-0.00014,4.82202,1.43242,0.88888,-0.00182
17.51400,145.88328,-0.00014,4.78625,1.43586,0.89030,-0.00176
17.55600,146.23323,-0.00014,4.46066,1.43930,0.89171,-0.00178
17.59800,146.58299,-0.00014,4.22224,1.44275,0.89312,-0.00178
17.64000,146.93294,-0.00014,4.38839,1.44619,0.89453,-0.00174
17.68200,147.28275,-0.00014,4.62439,1.44963,0.89594,-0.00178
17.72400,147.63246,-0.00014,4.62942,1.45308,0.89734,-0.00177
17.76600,147.98252,-0.00014,4.81997,1.45652,0.89875,-0.00176
17.80800,148.33230,-0.00014,4.77005,1.45996,0.90015,-0.00177
17.85000,148.68219,-0.00014,4.60614,1.46341,0.90155,-0.00174
17.89200,149.03217,-0.00014,4.75794,1.46685,0.90294,-0.00178
17.93400,149.38180,-0.00014,4.60744,1.47029,0.90434,-0.00176
17.97600,149.73187,-0.00014,5.00213,1.47374,0.90573,-0.00178
18.01800,150.08169,-0.00014,4.88274,1.47718,0.90712,-0.00178
18.06000,150.43140,-0.00014,4.61247,1.48062,0.90851,-0.00175
18.10200,150.78143,-0.00014,4.59533,1.48407,0.90990,-0.00176
18.14400,151.13117,-0.00014,4.77955,1.48751,0.91128,-0.00176
18.18600,151.48100,-0.00014,4.75664,1.49095,0.91267,-0.00176
18.22800,151.83103,-0.00014,5.01517,1.49440,0.91405,-0.00176
18.27000,152.18070,-0.00014,5.02132,1.49784,0.91543,-0.00175
18.31200,152.53065,-0.00014,5.02747,1.50129,0.91680,-0.00177
18.35400,152.88058,-0.00014,4.94719,1.50473,0.91818,-0.00177
18.39600,153.23023,-0.00014,5.09899,1.50817,0.91955,-0.00178
18.43800,153.58030,-0.00014,5.02225,1.51162,0.92093,-0.00177
18.48000,153.93013,-0.00014,4.82704,1.51506,0.92230,-0.00174
18.52200,154.27983,-0.00014,5.06621,1.51850,0.92366,-0.00176
18.56400,154.62996,-0.00014,5.15655,1.52195,0.92503,-0.00174
18.60600,154.97967,-0.00014,4.96414,1.52539,0.92640,-0.00174
18.64800,155.32954,-0.00014,5.01089,1.52883,0.92776,-0.00176
18.69000,155.67948,-0.00014,5.03287,1.53228,0.92912,-0.00175
18.73200,156.02916,-0.00014,5.09173,1.53572,0.93048,-0.00177
18.77400,156.37914,-0.00014,4.98891,1.53916,0.93184,-0.00176
18.81600,156.72897,-0.00014,4.93433,1.54261,0.93319,-0.00174
18.85800,157.07872,-0.00014,5.05950,1.54605,0.93454,-0.00178
18.90000,157.42874,-0.00014,4.78420,1.54950,0.93590,-0.00175
18.94200,157.77855,-0.00014,5.01685,1.55294,0.93725,-0.00178
18.98400,158.12835,-0.00014,5.15543,1.55638,0.93859,-0.00178
19.02600,158.47833,-0.00014,4.89373,1.55983,0.93994,-0.00173
19.06800,158.82804,-0.00014,5.06006,1.56327,0.94128,-0.00179
19.11000,159.17797,-0.00014,5.23999,1.56671,0.94263,-0.00174
19.15200,159.52795,-0.00014,5.04535,1.57016,0.94397,-0.00179
19.19400,159.87763,-0.00014,4.96637,1.57360,0.94531,-0.00178
19.23600,160.22759,-0.00014,5.21895,1.57704,0.94664,-0.00174
19.27800,160.57744,-0.00014,5.26290,1.58049,0.94798,-0.00179
19.32000,160.92726,-0.00014,5.46537,1.58393,0.94931,-0.00176
19.36200,161.27724,-0.00014,5.08949,1.58737,0.95064,-0.00174
19.40400,161.62696,-0.00014,5.19417,1.59082,0.95197,-0.00178
19.44600,161.97678,-0.00014,4.97829,1.59426,0.95330,-0.00177
19.48800,162.32685,-0.00014,5.19641,1.59771,0.95463,-0.00178
19.53000,162.67651,-0.00014,5.44712,1.60115,0.95595,-0.00178
19.57200,163.02639,-0.00014,5.18523,1.60459,0.95728,-0.00177
19.61400,163.37639,-0.00014,5.35399,1.60804,0.95860,-0.00180
19.65600,163.72605,-0.00014,4.96916,1.61148,0.95992,-0.00175
19.69800,164.07618,-0.00014,5.30034,1.61492,0.96123,-0.00178
19.74000,164.42590,-0.00014,5.48642,1.61837,0.96255,-0.00179
19.78200,164.77564,-0.00014,5.58384,1.62181,0.96386,-0.00175
19.82400,165.12574,-0.00014,5.36554,1.62525,0.96518,-0.00177
19.86600,165.47539,-0.00014,5.40148,1.62869,0.96649,-0.00176
19.90800,165.82536,-0.00014,4.97103,1.63214,0.96780,-0.00179
19.95000,166.17531,-0.00014,5.10067,1.63558,0.96910,-0.00178
19.99200,166.52494,-0.00014,5.11166,1.63902,0.97041,-0.00176
20.03400,166.87489,-0.00014,5.49685,1.64247,0.97171,-0.00177
20.07600,167.22477,-0.00014,5.19585,1.64591,0.97302,-0.00175
20.11800,167.57457,-0.00014,5.80810,1.64936,0.97432,-0.00178
20.16000,167.92457,-0.00014,5.32251,1.65280,0.97562,-0.00176
20.20200,168.27427,-0.00014,4.90844,1.65624,0.97691,-0.00175
20.24400,168.62412,-0.00014,5.62333,1.65969,0.97821,-0.00177
20.28600,168.97420,-0.00014,5.25583,1.66313,0.97950,-0.00176
20.32800,169.32388,-0.00014,5.85932,1.66657,0.98079,-0.00177
20.37000,169.67387,-0.00014,5.55832,1.67002,0.98209,-0.00179
20.41200,170.02368,-0.00014,5.32959,1.67346,0.98337,-0.00177
20.45400,170.37347,-0.00014,5.79078,1.67690,0.98466,-0.00178
20.49600,170.72349,-0.00014,5.35920,1.68035,0.98595,-0.00175
20.53800,171.07323,-0.00014,5.42179,1.68379,0.98723,-0.00174
20.58000,171.42298,-0.00014,5.55683,1.68723,0.98851,-0.00180
20.62200,171.77301,-0.00014,5.45662,1.69068,0.98979,-0.00173
20.66400,172.12278,-0.00014,5.59166,1.69412,0.99107,-0.00179
20.70600,172.47264,-0.00014,5.49182,1.69757,0.99235,-0.00178
20.74800,172.82258,-0.00014,5.56111,1.70101,0.99363,-0.00174
20.79000,173.17224,-0.00014,5.79618,1.70445,0.99490,-0.00180
20.83200,173.52219,-0.00014,5.75390,1.70790,0.99617,-0.00174
20.87400,173.87221,-0.00014,5.83902,1.71134,0.99744,-0.00178
20.91600,174.22193,-0.00014,5.85336,1.71478,0.99871,-0.00178
20.95800,174.57192,-0.00014,5.64791,1.71823,0.99998,-0.00175
21.00000,174.92173,-0.00014,5.74049,1.72167,1.00125,-0.00180
21.04200,175.27152,-0.00014,5.82542,1.72511,1.00251,-0.00175
21.08400,175.62154,-0.00014,5.97909,1.72856,1.00377,-0.00176
21.12600,175.97124,-0.00014,5.80382,1.73200,1.00503,-0.00178
21.16800,176.32112,-0.00014,5.77066,1.73544,1.00629,-0.00177
21.21000,176.67102,-0.00014,5.76042,1.73889,1.00755,-0.00176
21.25200,177.02075,-0.00014,5.94631,1.74233,1.00881,-0.00177
21.29400,177.37073,-0.00014,6.03162,1.74577,1.01006,-0.00175
21.33600,177.72058,-0.00014,6.09383,1.74922,1.01132,-0.00178
21.37800,178.07030,-0.00014,5.58104,1.75266,1.01257,-0.00176
21.42000,178.42034,-0.00014,5.78966,1.75611,1.01382,-0.00177
21.46200,178.77017,-0.00014,5.99157,1.75955,1.01507,-0.00177
21.50400,179.12002,-0.00014,6.20335,1.76299,1.01631,-0.00177
21.54600,179.47000,-0.00014,6.03888,1.76644,1.01756,-0.00181
21.58800,179.81956,-0.00014,6.13369,1.76988,1.01880,-0.00175
21.63000,180.16967,-0.00014,5.80084,1.77332,1.02005,-0.00177
21.67200,180.51956,-0.00014,5.76861,1.77677,1.02129,-0.00177
21.71400,180.86921,-0.00014,6.05397,1.78021,1.02253,-0.00176
21.75600,181.21923,-0.00014,6.25383,1.78365,1.02376,-0.00177
21.79800,181.56898,-0.00014,6.21285,1.78710,1.02500,-0.00175
21.84000,181.91883,-0.00014,5.84293,1.79054,1.02623,-0.00180
21.88200,182.26882,-0.00014,6.09774,1.79398,1.02747,-0.00177
21.92400,182.61851,-0.00014,6.02473,1.79743,1.02870,-0.00177
21.96600,182.96836,-0.00014,6.05471,1.80087,1.02993,-0.00182
22.00800,183.31839,-0.00014,6.01634,1.80431,1.03116,-0.00176
22.05000,183.66819,-0.00014,6.26650,1.80776,1.03239,-0.00177
22.09200,184.01809,-0.00014,6.16759,1.81120,1.03361,-0.00178
22.13400,184.36797,-0.00014,6.28512,1.81465,1.03484,-0.00174
22.17600,184.71771,-0.00014,6.52466,1.81809,1.03606,-0.00178
22.21800,185.06777,-0.00014,6.59246,1.82153,1.03728,-0.00176
22.26000,185.41746,-0.00014,6.12047,1.82498,1.03850,-0.00175
22.30200,185.76730,-0.00014,6.30561,1.82842,1.03972,-0.00176
22.34400,186.11728,-0.00014,6.20708,1.83186,1.04093,-0.00176
22.38600,186.46700,-0.00014,6.22533,1.83531,1.04215,-0.00178
22.42800,186.81691,-0.00014,5.99921,1.83875,1.04336,-0.00178
22.47000,187.16680,-0.00014,6.17579,1.84219,1.04458,-0.00177
22.51200,187.51655,-0.00014,6.11357,1.84564,1.04579,-0.00180
22.55400,187.86653,-0.00014,6.32517,1.84908,1.04700,-0.00175
22.59600,188.21635,-0.00014,6.30356,1.85252,1.04820,-0.00178
22.63800,188.56617,-0.00014,6.56191,1.85597,1.04941,-0.00177
22.68000,188.91618,-0.00014,6.65784,1.85941,1.05062,-0.00174
22.72200,189.26595,-0.00014,6.67274,1.86285,1.05182,-0.00181
22.76400,189.61580,-0.00014,6.45127,1.86630,1.05302,-0.00176
22.80600,189.96578,-0.00014,6.37732,1.86974,1.05422,-0.00179
22.84800,190.31543,-0.00014,6.27749,1.87318,1.05542,-0.00177
22.89000,190.66539,-0.00014,6.32741,1.87663,1.05662,-0.00177
22.93200,191.01526,-0.00014,6.48573,1.88007,1.05782,-0.00180
22.97400,191.36501,-0.00014,6.73141,1.88351,1.05901,-0.00174
23.01600,191.71504,-0.00014,6.30524,1.88696,1.06020,-0.00176
23.05800,192.06485,-0.00014,6.22887,1.89040,1.06140,-0.00177
23.10000,192.41457,-0.00014,6.46319,1.89384,1.06259,-0.00175
23.14200,192.76459,-0.00014,6.51348,1.89729,1.06378,-0.00178
23.18400,193.11436,-0.00014,6.60904,1.90073,1.06496,-0.00177
23.22600,193.46429,-0.00014,6.46636,1.90418,1.06615,-0.00176
23.26800,193.81422,-0.00014,6.82697,1.90762,1.06733,-0.00179
23.31000,194.16386,-0.00015,6.72899,1.91106,1.06852,-0.00185
23.35200,194.51394,-0.00014,6.48741,1.91451,1.06970,-0.00182
23.39400,194.86380,-0.00014,6.76923,1.91795,1.07088,-0.00178
23.43600,195.21351,-0.00014,6.82455,1.92139,1.07206,-0.00177
23.47800,195.56350,-0.00014,6.74333,1.92484,1.07324,-0.00178
23.52000,195.91322,-0.00014,6.80983,1.92828,1.07442,-0.00177
23.56200,196.26316,-0.00014,6.59637,1.93172,1.07559,-0.00179
23.60400,196.61308,-0.00014,6.57961,1.93517,1.07676,-0.00177
23.64600,196.96270,-0.00014,6.74464,1.93861,1.07794,-0.00176
23.68800,197.31275,-0.00015,6.68988,1.94205,1.07911,-0.00185
23.73000,197.66263,-0.00014,6.96965,1.94550,1.08028,-0.00183
23.77200,198.01240,-0.00014,6.91582,1.94894,1.08145,-0.00183
23.81400,198.36235,-0.00014,6.90576,1.95239,1.08261,-0.00176
23.85600,198.71213,-0.00014,6.93649,1.95583,1.08378,-0.00176
23.89800,199.06195,-0.00015,6.62003,1.95927,1.08494,-0.00184
23.94000,199.41200,-0.00014,6.98101,1.96272,1.08611,-0.00178
23.98200,199.76175,-0.00014,6.89216,1.96616,1.08727,-0.00178
24.02400,200.11161,-0.00014,6.84019,1.96960,1.08843,-0.00182
24.06600,200.46155,-0.00014,7.31051,1.97305,1.08959,-0.00174
24.10800,200.81121,-0.00014,6.68466,1.97649,1.09074,-0.00182
24.15000,201.16121,-0.00014,6.90464,1.97993,1.09190,-0.00176
24.19200,201.51111,-0.00014,7.08103,1.98338,1.09306,-0.00178
24.23400,201.86082,-0.00014,7.20676,1.98682,1.09421,-0.00180
24.27600,202.21077,-0.00014,6.91563,1.99026,1.09536,-0.00176
24.31800,202.56060,-0.00014,6.63921,1.99371,1.09651,-0.00175
24.36000,202.91045,-0.00014,6.93873,1.99715,1.09766,-0.00177
24.40200,203.26046,-0.00014,6.98920,2.00060,1.09881,-0.00176
24.44400,203.61014,-0.00014,7.13803,2.00404,1.09996,-0.00180
24.48600,203.95999,-0.00014,7.25426,2.00748,1.10110,-0.00176
24.52800,204.31005,-0.00014,7.08830,2.01093,1.10225,-0.00178
24.57000,204.65975,-0.00014,7.11791,2.01437,1.10339,-0.00178
24.61200,205.00970,-0.00014,7.43270,2.01781,1.10453,-0.00175
24.65400,205.35950,-0.00014,7.03614,2.02125,1.10567,-0.00181
24.69600,205.70929,-0.00014,6.93314,2.02470,1.10681,-0.00177
24.73800,206.05935,-0.00014,7.21663,2.02814,1.10795,-0.00179
24.78000,206.40906,-0.00014,7.00615,2.03159,1.10909,-0.00177
24.82200,206.75888,-0.00014,7.06166,2.03503,1.11022,-0.00175
24.86400,207.10885,-0.00014,6.89421,2.03847,1.11136,-0.00179
24.90600,207.45855,-0.00014,6.89439,2.04191,1.11249,-0.00179
24.94800,207.80853,-0.00014,7.00057,2.04536,1.11362,-0.00178
24.99000,208.15845,-0.00014,6.99200,2.04880,1.11475,-0.00178
25.03200,208.50815,-0.00014,7.27139,2.05225,1.11588,-0.00176
25.07400,208.85819,-0.00014,7.37291,2.05569,1.11701,-0.00179
25.11600,209.20801,-0.00014,7.20341,2.05913,1.11813,-0.00177
25.15800,209.55778,-0.00014,7.22762,2.06258,1.11926,-0.00179
25.20000,209.90781,-0.00014,7.50367,2.06602,1.12038,-0.00178
25.24200,210.25748,-0.00014,7.41817,2.06946,1.12150,-0.00179
25.28400,210.60737,-0.00014,7.39936,2.07291,1.12262,-0.00178
25.32600,210.95732,-0.00014,7.51223,2.07635,1.12374,-0.00177
25.36800,211.30702,-0.00014,7.34571,2.07979,1.12486,-0.00178
25.41000,211.65706,-0.00014,7.18385,2.08324,1.12598,-0.00179
25.45200,212.00684,-0.00014,6.34454,2.08668,1.12710,-0.00179
25.49400,212.35662,-0.00015,6.72005,2.09012,1.12821,-0.00186
25.53600,212.70662,-0.00015,6.86496,2.09357,1.12933,-0.00185
25.57800,213.05639,-0.00015,6.81709,2.09701,1.13044,-0.00187
25.62000,213.40624,-0.00014,7.03242,2.10046,1.13155,-0.00182
25.66200,213.75620,-0.00014,7.54651,2.10390,1.13266,-0.00175
25.70400,214.10599,-0.00014,7.47815,2.10734,1.13377,-0.00180
25.74600,214.45591,-0.00014,7.63610,2.11079,1.13488,-0.00178
25.78800,214.80585,-0.00014,7.36788,2.11423,1.13598,-0.00179
25.83000,215.15550,-0.00014,7.43326,2.11767,1.13709,-0.00177
25.87200,215.50550,-0.00014,7.66870,2.12112,1.13819,-0.00175
25.91400,215.85528,-0.00014,7.34963,2.12456,1.13929,-0.00180
25.95600,216.20509,-0.00014,7.39433,2.12800,1.14039,-0.00180
25.99800,216.55508,-0.00014,7.30120,2.13145,1.14150,-0.00176
26.04000,216.90483,-0.00014,7.10972,2.13489,1.14259,-0.00180
26.08200,217.25474,-0.00014,7.47144,2.13833,1.14369,-0.00180
26.12400,217.60470,-0.00014,7.88327,2.14178,1.14479,-0.00179
26.16600,217.95435,-0.00014,7.92257,2.14522,1.14588,-0.00180
26.20800,218.30433,-0.00014,7.62176,2.14866,1.14698,-0.00181
26.25000,218.65428,-0.00014,7.50925,2.15211,1.14807,-0.00178
26.29200,219.00399,-0.00014,8.07215,2.15555,1.14916,-0.00177
26.33400,219.35394,-0.00014,8.05669,2.15900,1.15025,-0.00175
26.37600,219.70374,-0.00014,7.57668,2.16244,1.15134,-0.00179
26.41800,220.05354,-0.00014,7.81249,2.16588,1.15243,-0.00175
26.46000,220.40365,-0.00014,7.71433,2.16933,1.15352,-0.00178
26.50200,220.75326,-0.00014,7.53142,2.17277,1.15460,-0.00176
26.54400,221.10314,-0.00014,7.74637,2.17621,1.15569,-0.00177
26.58600,221.45309,-0.00014,7.91810,2.17966,1.15677,-0.00179
26.62800,221.80281,-0.00014,7.72569,2.18310,1.15786,-0.00177
26.67000,222.15282,-0.00014,7.78046,2.18654,1.15894,-0.00177
26.71200,222.50267,-0.00014,7.78493,2.18999,1.16002,-0.00178
26.75400,222.85241,-0.00014,7.83559,2.19343,1.16110,-0.00177
26.79600,223.20244,-0.00014,8.27126,2.19687,1.16217,-0.00180
26.83800,223.55222,-0.00014,8.11778,2.20032,1.16325,-0.00176
26.88000,223.90207,-0.00014,8.34353,2.20376,1.16433,-0.00180
26.92200,224.25202,-0.00014,8.09319,2.20720,1.16540,-0.00178
26.96400,224.60169,-0.00014,8.33143,2.21065,1.16647,-0.00177
27.00600,224.95172,-0.00014,8.07345,2.21409,1.16754,-0.00178
27.04800,225.30159,-0.00014,8.06991,2.21754,1.16862,-0.00176
27.09000,225.65129,-0.00014,8.33627,2.22098,1.16968,-0.00176
27.13200,226.00129,-0.00014,8.27946,2.22442,1.17075,-0.00177
27.17400,226.35099,-0.00014,8.22376,2.22786,1.17182,-0.00177
27.21600,226.70086,-0.00014,8.21464,2.23131,1.17289,-0.00180
27.25800,227.05092,-0.00014,8.01124,2.23475,1.17395,-0.00178
27.30000,227.40064,-0.00014,8.26772,2.23820,1.17502,-0.00178
27.34200,227.75049,-0.00014,8.21669,2.24164,1.17608,-0.00178
27.38400,228.10044,-0.00014,8.47187,2.24508,1.17714,-0.00175
27.42600,228.45024,-0.00014,8.55438,2.24853,1.17820,-0.00179
27.46800,228.80019,-0.00014,8.72388,2.25197,1.17926,-0.00176
27.51000,229.15002,-0.00014,8.40630,2.25541,1.18032,-0.00177
27.55200,229.49973,-0.00014,8.84626,2.25886,1.18138,-0.00180
27.59400,229.84979,-0.00014,8.48845,2.26230,1.18243,-0.00176
27.63600,230.19962,-0.00014,8.67788,2.26574,1.18349,-0.00179
27.67800,230.54934,-0.00014,8.35638,2.26919,1.18454,-0.00177
27.72000,230.89932,-0.00014,8.48006,2.27263,1.18559,-0.00177
27.76200,231.24903,-0.00014,8.48118,2.27607,1.18665,-0.00180
27.80400,231.59901,-0.00014,8.11014,2.27952,1.18770,-0.00176
27.84600,231.94894,-0.00014,8.46647,2.28296,1.18875,-0.00178
27.88800,232.29858,-0.00014,8.62796,2.28640,1.18979,-0.00178
27.93000,232.64859,-0.00014,8.30721,2.28985,1.19084,-0.00176
27.97200,232.99844,-0.00014,8.85781,2.29329,1.19189,-0.00178
28.01400,233.34821,-0.00014,8.60337,2.29673,1.19293,-0.00178
28.05600,233.69829,-0.00014,8.57860,2.30018,1.19398,-0.00176
28.09800,234.04799,-0.00014,8.83192,2.30362,1.19502,-0.00179
28.14000,234.39784,-0.00014,9.02805,2.30707,1.19606,-0.00177
28.18200,234.74784,-0.00014,8.70097,2.31051,1.19710,-0.00179
28.22400,235.09753,-0.00014,8.45212,2.31395,1.19814,-0.00179
28.26600,235.44749,-0.00014,8.84999,2.31740,1.19918,-0.00177
28.30800,235.79736,-0.00014,8.50875,2.32084,1.20022,-0.00179
28.35000,236.14701,-0.00014,8.63131,2.32428,1.20125,-0.00177
28.39200,236.49714,-0.00014,8.53837,2.32773,1.20229,-0.00179
28.43400,236.84689,-0.00014,8.64323,2.33117,1.20332,-0.00175
28.47600,237.19671,-0.00014,8.72333,2.33461,1.20436,-0.00176
28.51800,237.54672,-0.00014,8.96845,2.33806,1.20539,-0.00179
28.56000,237.89633,-0.00014,8.98074,2.34150,1.20642,-0.00175
28.60200,238.24636,-0.00014,8.95336,2.34494,1.20745,-0.00179
28.64400,238.59632,-0.00014,9.19737,2.34839,1.20848,-0.00177
28.68600,238.94596,-0.00014,9.02023,2.35183,1.20951,-0.00179
28.72800,239.29591,-0.00014,9.03979,2.35527,1.21053,-0.00179
28.77000,239.64584,-0.00014,9.10740,2.35872,1.21156,-0.00174
28.81200,239.99561,-0.00014,8.99602,2.36216,1.21258,-0.00176
28.85400,240.34562,-0.00014,8.81720,2.36561,1.21361,-0.00175
28.89600,240.69528,-0.00014,8.94591,2.36905,1.21463,-0.00177
28.93800,241.04513,-0.00014,9.12640,2.37249,1.21565,-0.00179
28.98000,241.39519,-0.00014,9.03588,2.37594,1.21667,-0.00177
29.02200,241.74483,-0.00014,9.19104,2.37938,1.21769,-0.00178
29.06400,242.09478,-0.00014,8.99397,2.38282,1.21871,-0.00178
29.10600,242.44469,-0.00014,9.11411,2.38627,1.21973,-0.00176
29.14800,242.79443,-0.00014,9.23704,2.38971,1.22074,-0.00178
29.19000,243.14444,-0.00014,9.22065,2.39315,1.22176,-0.00175
29.23200,243.49418,-0.00014,9.33930,2.39660,1.22277,-0.00177
29.27400,243.84403,-0.00014,9.41437,2.40004,1.22379,-0.00178
29.31600,244.19404,-0.00014,9.33427,2.40348,1.22480,-0.00173
29.35800,244.54378,-0.00014,9.64813,2.40693,1.22581,-0.00180
29.40000,244.89366,-0.00014,9.37302,2.41037,1.22682,-0.00176
29.44200,245.24361,-0.00014,9.23090,2.41382,1.22783,-0.00177
29.48400,245.59331,-0.00014,9.22121,2.41726,1.22884,-0.00179
29.52600,245.94329,-0.00014,9.36352,2.42070,1.22985,-0.00175
29.56800,246.29313,-0.00014,9.12249,2.42414,1.23085,-0.00179
29.61000,246.64288,-0.00014,9.18470,2.42759,1.23186,-0.00179
29.65200,246.99294,-0.00014,9.55053,2.43103,1.23286,-0.00176
29.69400,247.34266,-0.00014,9.58685,2.43447,1.23386,-0.00178
29.73600,247.69245,-0.00014,9.27504,2.43792,1.23487,-0.00177
29.77800,248.04254,-0.00014,9.50769,2.44136,1.23587,-0.00178
29.82000,248.39223,-0.00014,9.67700,2.44481,1.23687,-0.00176
29.86200,248.74219,-0.00014,9.75262,2.44825,1.23787,-0.00178
29.90400,249.09209,-0.00014,9.83402,2.45169,1.23887,-0.00179
29.94600,249.44178,-0.00014,9.45050,2.45514,1.23986,-0.00176
29.98800,249.79181,-0.00014,9.55947,2.45858,1.24086,-0.00176
30.03000,250.14161,-0.00014,9.81819,2.46202,1.24185,-0.00180
30.07200,250.49130,-0.00014,9.64925,2.46547,1.24285,-0.00177
30.11400,250.84141,-0.00014,9.56766,2.46891,1.24384,-0.00179
30.15600,251.19108,-0.00014,9.62708,2.47235,1.24483,-0.00178
30.19800,251.54098,-0.00014,9.59449,2.47580,1.24582,-0.00177
30.24000,251.89094,-0.00014,9.17800,2.47924,1.24681,-0.00178
30.28200,252.24060,-0.00014,9.77349,2.48268,1.24780,-0.00178
30.32400,252.59066,-0.00014,10.04543,2.48613,1.24879,-0.00179
30.36600,252.94046,-0.00014,9.98192,2.48957,1.24978,-0.00176
30.40800,253.29018,-0.00014,9.96627,2.49301,1.25076,-0.00178
30.45000,253.64029,-0.00014,10.00091,2.49646,1.25175,-0.00178
30.49200,253.99006,-0.00014,10.08958,2.49990,1.25274,-0.00175
30.53400,254.33991,-0.00014,9.82378,2.50335,1.25372,-0.00178
30.57600,254.68984,-0.00014,10.02047,2.50679,1.25470,-0.00175
30.61800,255.03953,-0.00014,10.17377,2.51023,1.25568,-0.00178
30.66000,255.38948,-0.00014,9.73400,2.51368,1.25666,-0.00177
30.70200,255.73941,-0.00014,9.92995,2.51712,1.25764,-0.00176
30.74400,256.08905,-0.00014,9.74759,2.52056,1.25862,-0.00178
30.78600,256.43911,-0.00014,9.71071,2.52401,1.25960,-0.00176
30.82800,256.78893,-0.00014,9.86308,2.52745,1.26058,-0.00176
30.87000,257.13873,-0.00014,9.77926,2.53089,1.26155,-0.00180
30.91200,257.48876,-0.00014,9.95584,2.53434,1.26253,-0.00176
30.95400,257.83843,-0.00014,10.13670,2.53778,1.26350,-0.00179
30.99600,258.18828,-0.00014,10.18178,2.54122,1.26447,-0.00182
31.03800,258.53828,-0.00014,10.06071,2.54467,1.26544,-0.00178
31.08000,258.88805,-0.00014,10.05828,2.54811,1.26642,-0.00182
31.12200,259.23796,-0.00014,9.74871,2.55155,1.26739,-0.00178
31.16400,259.58783,-0.00014,10.24287,2.55500,1.26835,-0.00179
31.20600,259.93760,-0.00014,10.16408,2.55844,1.26932,-0.00178
31.24800,260.28753,-0.00014,10.38965,2.56189,1.27029,-0.00173
31.29000,260.63741,-0.00014,10.16073,2.56533,1.27126,-0.00179
31.33200,260.98715,-0.00014,9.96497,2.56877,1.27222,-0.00176
31.37400,261.33718,-0.00014,10.09200,2.57222,1.27319,-0.00177
31.41600,261.68688,-0.00014,9.78429,2.57566,1.27415,-0.00179
31.45800,262.03680,-0.00014,9.98005,2.57910,1.27511,-0.00175
31.50000,262.38681,-0.00014,10.37233,2.58255,1.27607,-0.00179
31.54200,262.73648,-0.00014,10.03724,2.58599,1.27703,-0.00177
31.58400,263.08643,-0.00014,10.37847,2.58943,1.27799,-0.00176
31.62600,263.43623,-0.00014,10.67873,2.59288,1.27895,-0.00177
31.66800,263.78608,-0.00014,10.48874,2.59632,1.27991,-0.00176
31.71000,264.13611,-0.00014,10.78416,2.59976,1.28087,-0.00177
31.75200,264.48575,-0.00014,10.33936,2.60321,1.28182,-0.00179
31.79400,264.83557,-0.00014,10.41964,2.60665,1.28278,-0.00179
31.83600,265.18568,-0.00014,10.38499,2.61010,1.28373,-0.00178
31.87800,265.53538,-0.00014,9.93405,2.61354,1.28469,-0.00177
31.92000,265.88533,-0.00014,10.41815,2.61698,1.28564,-0.00178
31.96200,266.23518,-0.00014,10.25405,2.62042,1.28659,-0.00178
32.00400,266.58482,-0.00014,10.08902,2.62387,1.28754,-0.00176
32.04600,266.93493,-0.00014,10.52581,2.62731,1.28849,-0.00177
32.08800,267.28473,-0.00014,10.39263,2.63076,1.28944,-0.00175
32.13000,267.63453,-0.00014,10.31738,2.63420,1.29039,-0.00177
32.17200,267.98453,-0.00014,10.44199,2.63764,1.29134,-0.00175
32.21400,268.33420,-0.00014,10.24473,2.64108,1.29228,-0.00176
32.25600,268.68418,-0.00014,10.68395,2.64453,1.29323,-0.00179
32.29800,269.03411,-0.00014,10.89983,2.64797,1.29417,-0.00176
32.34000,269.38380,-0.00014,10.59603,2.65142,1.29511,-0.00177
32.38200,269.73381,-0.00014,10.61875,2.65486,1.29606,-0.00178
32.42400,270.08363,-0.00014,10.34457,2.65830,1.29700,-0.00174
32.46600,270.43337,-0.00014,10.21083,2.66175,1.29794,-0.00179
32.50800,270.78341,-0.00014,10.13726,2.66519,1.29888,-0.00174
32.55000,271.13318,-0.00014,10.32483,2.66863,1.29982,-0.00174
32.59200,271.48297,-0.00014,10.30788,2.67208,1.30076,-0.00177
32.63400,271.83301,-0.00014,10.33302,2.67552,1.30170,-0.00176
32.67600,272.18273,-0.00014,10.37866,2.67896,1.30263,-0.00177
32.71800,272.53265,-0.00014,10.66159,2.68241,1.30357,-0.00174
32.76000,272.88250,-0.00014,10.61391,2.68585,1.30450,-0.00175
32.80200,273.23217,-0.00014,10.66662,2.68929,1.30543,-0.00177
32.84400,273.58225,-0.00014,10.39915,2.69274,1.30637,-0.00174
32.88600,273.93210,-0.00014,10.36003,2.69618,1.30730,-0.00178
32.92800,274.28187,-0.00014,10.56064,2.69962,1.30823,-0.00177
32.97000,274.63180,-0.00014,10.63161,2.70307,1.30916,-0.00174
33.01200,274.98160,-0.00014,10.50252,2.70651,1.31009,-0.00179
33.05400,275.33145,-0.00014,10.22574,2.70996,1.31102,-0.00178
33.09600,275.68145,-0.00014,10.37717,2.71340,1.31195,-0.00176
33.13800,276.03112,-0.00014,10.13260,2.71684,1.31287,-0.00178
33.18000,276.38108,-0.00014,10.01395,2.72029,1.31380,-0.00174
33.22200,276.73106,-0.00014,10.33042,2.72373,1.31473,-0.00180
33.26400,277.08067,-0.00014,10.20227,2.72717,1.31565,-0.00176
33.30600,277.43073,-0.00014,10.37158,2.73062,1.31657,-0.00176
33.34800,277.78053,-0.00014,10.55636,2.73406,1.31750,-0.00177
33.39000,278.13030,-0.00014,10.55729,2.73750,1.31842,-0.00173
33.43200,278.48035,-0.00014,10.72045,2.74095,1.31934,-0.00179
33.47400,278.83002,-0.00014,10.18345,2.74439,1.32026,-0.00177
33.51600,279.17992,-0.00014,10.22071,2.74783,1.32118,-0.00175
33.55800,279.52990,-0.00014,10.56325,2.75128,1.32210,-0.00176
33.60000,279.87962,-0.00014,10.40753,2.75472,1.32301,-0.00176
33.64200,280.22958,-0.00014,10.37754,2.75817,1.32393,-0.00177
33.68400,280.57945,-0.00014,10.37773,2.76161,1.32485,-0.00176
33.72600,280.92917,-0.00014,10.17097,2.76505,1.32576,-0.00177
33.76800,281.27918,-0.00014,9.95677,2.76850,1.32668,-0.00178
33.81000,281.62895,-0.00014,9.73158,2.77194,1.32759,-0.00176
33.85200,281.97882,-0.00014,9.61199,2.77538,1.32850,-0.00177
33.89400,282.32878,-0.00014,9.86084,2.77883,1.32941,-0.00177
33.93600,282.67847,-0.00014,10.15067,2.78227,1.33032,-0.00177
33.97800,283.02848,-0.00014,9.60715,2.78571,1.33123,-0.00178
34.02000,283.37833,-0.00014,9.72021,2.78916,1.33214,-0.00176
34.06200,283.72802,-0.00014,9.88375,2.79260,1.33305,-0.00176
34.10400,284.07805,-0.00014,10.09256,2.79604,1.33396,-0.00175
34.14600,284.42787,-0.00014,9.44156,2.79949,1.33487,-0.00175
34.18800,284.77772,-0.00014,9.09511,2.80293,1.33577,-0.00178
34.23000,285.12768,-0.00014,8.97925,2.80637,1.33668,-0.00174
34.27200,285.47742,-0.00014,8.65217,2.80982,1.33758,-0.00178
34.31400,285.82722,-0.00014,4.90528,2.81326,1.33848,-0.00178
34.35600,286.17725,-0.00014,-0.01621,2.81671,1.33939,-0.00178