File: raw_data/mechanical_tests_Instron_data/Cast_Skin_0035_1.is_tens_RawData/Specimen_RawData_1.csv
Dimension : Area,0.42000,cm^2

Time,Load,Extension,Tensile extension,Tensile strain,Tensile stress
(sec),(N),(mm),(mm),(mm/mm),(MPa)
0.00000,0.25332,0.00000,0.00000,0.00000,0.00603
0.05000,1.17943,0.09680,0.09680,0.00069,0.02808
0.10000,0.42766,0.41054,0.41054,0.00293,0.01018
0.15000,1.49310,0.88034,0.88034,0.00629,0.03555
0.20000,1.73245,1.38696,1.38696,0.00991,0.04125
0.25000,1.86861,1.90896,1.90896,0.01364,0.04449
0.30000,1.83843,2.44026,2.44026,0.01743,0.04377
0.35000,1.38637,2.92377,2.92377,0.02088,0.03301
0.40000,1.37165,3.33643,3.33643,0.02383,0.03266
0.45000,1.30273,3.75544,3.75544,0.02682,0.03102
0.50000,1.25077,4.17466,4.17466,0.02982,0.02978
0.55000,0.91884,4.59131,4.59131,0.03280,0.02188
0.60000,1.42641,5.00812,5.00812,0.03577,0.03396
0.65000,1.66800,5.42491,5.42491,0.03875,0.03971
0.70000,1.26977,5.84151,5.84151,0.04173,0.03023
0.75000,1.09579,6.25818,6.25819,0.04470,0.02609
0.80000,1.61361,6.67484,6.67484,0.04768,0.03842
0.85000,1.45100,7.09162,7.09162,0.05065,0.03455
0.90000,1.41878,7.50822,7.50822,0.05363,0.03378
0.95000,1.61510,7.92495,7.92495,0.05661,0.03845
1.00000,1.44728,8.34166,8.34166,0.05958,0.03446
1.05000,1.33328,8.75836,8.75836,0.06256,0.03174
1.10000,1.36402,9.17499,9.17499,0.06554,0.03248
1.15000,1.45603,9.59172,9.59172,0.06851,0.03467
1.20000,1.02613,10.00842,10.00842,0.07149,0.02443
1.25000,1.63652,10.42508,10.42508,0.07446,0.03896
1.30000,1.46460,10.84170,10.84170,0.07744,0.03487
1.35000,1.71363,11.25835,11.25835,0.08042,0.04080
1.40000,1.66278,11.67498,11.67498,0.08339,0.03959
1.45000,1.37947,12.09165,12.09165,0.08637,0.03284
1.50000,1.23456,12.50831,12.50831,0.08935,0.02939
1.55000,1.13286,12.92490,12.92490,0.09232,0.02697
1.60000,0.77002,13.34158,13.34158,0.09530,0.01833
1.65000,1.51694,13.75821,13.75821,0.09827,0.03612
1.70000,1.44597,14.17491,14.17491,0.10125,0.03443
1.75000,1.13938,14.59156,14.59157,0.10423,0.02713
1.80000,1.61547,15.00827,15.00827,0.10720,0.03846
1.85000,0.92015,15.42490,15.42490,0.11018,0.02191
1.90000,1.31335,15.84163,15.84163,0.11315,0.03127
1.95000,1.26772,16.25828,16.25828,0.11613,0.03018
2.00000,1.58064,16.67506,16.67506,0.11911,0.03763
2.05000,1.18893,17.09171,17.09171,0.12208,0.02831
2.10000,1.55214,17.50839,17.50839,0.12506,0.03696
2.15000,1.34967,17.92507,17.92507,0.12804,0.03214
2.20000,1.61212,18.34181,18.34181,0.13101,0.03838
2.25000,1.51116,18.75838,18.75838,0.13399,0.03598
2.30000,1.44038,19.17500,19.17500,0.13696,0.03429
2.35000,1.11591,19.59168,19.59168,0.13994,0.02657
2.40000,1.35433,20.00830,20.00830,0.14292,0.03225
2.45000,1.20271,20.42490,20.42490,0.14589,0.02864
2.50000,1.55400,20.84155,20.84155,0.14887,0.03700
2.55000,1.45938,21.25823,21.25823,0.15184,0.03475
2.60000,1.67750,21.67491,21.67491,0.15482,0.03994
2.65000,1.44709,22.09151,22.09151,0.15780,0.03445
2.70000,1.31726,22.50824,22.50824,0.16077,0.03136
2.75000,1.50315,22.92497,22.92497,0.16375,0.03579
2.80000,1.80863,23.34165,23.34165,0.16673,0.04306
2.85000,1.50148,23.75833,23.75833,0.16970,0.03575
2.90000,1.48080,24.17501,24.17501,0.17268,0.03526
2.95000,1.45063,24.59177,24.59177,0.17566,0.03454
3.00000,1.14813,25.00842,25.00842,0.17863,0.02734
3.05000,1.33812,25.42507,25.42507,0.18161,0.03186
3.10000,1.35805,25.84169,25.84169,0.18458,0.03233
3.15000,1.27833,26.25837,26.25837,0.18756,0.03044
3.20000,1.26939,26.67500,26.67500,0.19054,0.03022
3.25000,1.48527,27.09162,27.09162,0.19351,0.03536
3.30000,1.27163,27.50827,27.50827,0.19649,0.03028
3.35000,1.24592,27.92498,27.92498,0.19946,0.02966
3.40000,1.22376,28.34160,28.34160,0.20244,0.02914
3.45000,1.07437,28.75820,28.75820,0.20542,0.02558
3.50000,0.88587,29.17488,29.17488,0.20839,0.02109
3.55000,1.09319,29.59158,29.59158,0.21137,0.02603
3.60000,1.17030,30.00826,30.00826,0.21434,0.02786
3.65000,0.83707,30.42489,30.42489,0.21732,0.01993
3.70000,1.09356,30.84162,30.84162,0.22030,0.02604
3.75000,0.85253,31.25835,31.25835,0.22327,0.02030
3.80000,0.76853,31.67503,31.67503,0.22625,0.01830
3.85000,0.63423,32.09168,32.09168,0.22923,0.01510
3.90000,0.69384,32.50841,32.50841,0.23220,0.01652
3.95000,0.69700,32.92514,32.92514,0.23518,0.01660
4.00000,0.60052,33.34172,33.34172,0.23816,0.01430
4.05000,0.93766,33.75840,33.75840,0.24113,0.02233
4.10000,0.38110,34.17502,34.17502,0.24411,0.00907
4.15000,0.51185,34.59167,34.59167,0.24708,0.01219
4.20000,0.59549,35.00824,35.00825,0.25006,0.01418
4.25000,0.71023,35.42492,35.42492,0.25304,0.01691
4.30000,0.42822,35.84154,35.84155,0.25601,0.01020
4.35000,0.58468,36.25823,36.25822,0.25899,0.01392
4.40000,0.78734,36.67482,36.67482,0.26196,0.01875
4.45000,0.54501,37.09156,37.09156,0.26494,0.01298
4.50000,0.82701,37.50831,37.50831,0.26792,0.01969
4.55000,0.60946,37.92494,37.92493,0.27089,0.01451
4.60000,0.77598,38.34162,38.34162,0.27387,0.01848
4.65000,0.73817,38.75832,38.75832,0.27685,0.01758
4.70000,0.90729,39.17505,39.17505,0.27982,0.02160
4.75000,0.77449,39.59173,39.59173,0.28280,0.01844
4.80000,0.51018,40.00844,40.00844,0.28577,0.01215
4.85000,0.32783,40.42504,40.42504,0.28875,0.00781
4.90000,0.80001,40.84177,40.84176,0.29173,0.01905
4.95000,0.71805,41.25837,41.25837,0.29470,0.01710
5.00000,0.99782,41.67502,41.67502,0.29768,0.02376
5.05000,0.88476,42.09167,42.09167,0.30065,0.02107
5.10000,0.89779,42.50835,42.50835,0.30363,0.02138
5.15000,0.90469,42.92489,42.92489,0.30661,0.02154
5.20000,0.55246,43.34154,43.34154,0.30958,0.01315
5.25000,0.78753,43.75825,43.75825,0.31256,0.01875
5.30000,0.96485,44.17490,44.17490,0.31554,0.02297
5.35000,0.63088,44.59153,44.59153,0.31851,0.01502
5.40000,1.09114,45.00826,45.00826,0.32149,0.02598
5.45000,0.55283,45.42493,45.42493,0.32446,0.01316
5.50000,1.17440,45.84164,45.84164,0.32744,0.02796
5.55000,0.96131,46.25834,46.25834,0.33042,0.02289
5.60000,1.29472,46.67500,46.67500,0.33339,0.03083
5.65000,1.11777,47.09178,47.09178,0.33637,0.02661
5.70000,1.07903,47.50835,47.50835,0.33935,0.02569
5.75000,0.98068,47.92508,47.92508,0.34232,0.02335
5.80000,1.25021,48.34171,48.34171,0.34530,0.02977
5.85000,1.13156,48.75842,48.75842,0.34827,0.02694
5.90000,0.99465,49.17501,49.17501,0.35125,0.02368
5.95000,1.01514,49.59167,49.59167,0.35423,0.02417
6.00000,1.26343,50.00829,50.00829,0.35720,0.03008
6.05000,1.34669,50.42497,50.42497,0.36018,0.03206
6.10000,1.47577,50.84159,50.84159,0.36315,0.03514
6.15000,1.24276,51.25819,51.25819,0.36613,0.02959
6.20000,1.39568,51.67487,51.67486,0.36911,0.03323
6.25000,1.29845,52.09157,52.09158,0.37208,0.03092
6.30000,1.73226,52.50828,52.50828,0.37506,0.04124
6.35000,1.54190,52.92490,52.92490,0.37804,0.03671
6.40000,1.26716,53.34164,53.34164,0.38101,0.03017
6.45000,1.62758,53.75834,53.75834,0.38399,0.03875
6.50000,1.44485,54.17502,54.17502,0.38696,0.03440
6.55000,1.54693,54.59170,54.59170,0.38994,0.03683
6.60000,1.36271,55.00843,55.00843,0.39292,0.03245
6.65000,1.45379,55.42511,55.42511,0.39589,0.03461
6.70000,1.41673,55.84171,55.84171,0.39887,0.03373
6.75000,1.74008,56.25835,56.25835,0.40185,0.04143
6.80000,1.65738,56.67504,56.67504,0.40482,0.03946
6.85000,1.96919,57.09172,57.09172,0.40780,0.04689
6.90000,1.68998,57.50823,57.50823,0.41077,0.04024
6.95000,1.68905,57.92491,57.92491,0.41375,0.04022
7.00000,1.63950,58.34159,58.34159,0.41673,0.03904
7.05000,1.76206,58.75827,58.75827,0.41970,0.04195
7.10000,1.44131,59.17486,59.17486,0.42268,0.03432
7.15000,1.85724,59.59157,59.59157,0.42565,0.04422
7.20000,1.59349,60.00825,60.00825,0.42863,0.03794
7.25000,1.85091,60.42496,60.42496,0.43161,0.04407
7.30000,2.06120,60.84163,60.84163,0.43458,0.04908
7.35000,1.89226,61.25831,61.25831,0.43756,0.04505
7.40000,2.00309,61.67504,61.67504,0.44054,0.04769
7.45000,2.36258,62.09172,62.09172,0.44351,0.05625
7.50000,1.92802,62.50840,62.50840,0.44649,0.04591
7.55000,1.86358,62.92505,62.92505,0.44946,0.04437
7.60000,1.98670,63.34181,63.34181,0.45244,0.04730
7.65000,2.66768,63.75838,63.75838,0.45542,0.06352
7.70000,2.18246,64.17503,64.17503,0.45839,0.05196
7.75000,2.46633,64.59160,64.59161,0.46137,0.05872
7.80000,2.29757,65.00836,65.00836,0.46435,0.05470
7.85000,2.35699,65.42494,65.42494,0.46732,0.05612
7.90000,2.40095,65.84156,65.84156,0.47030,0.05717
7.95000,2.63322,66.25821,66.25821,0.47327,0.06270
8.00000,2.62745,66.67489,66.67489,0.47625,0.06256
8.05000,2.92677,67.09154,67.09155,0.47923,0.06969
8.10000,2.99923,67.50825,67.50825,0.48220,0.07141
8.15000,2.76323,67.92498,67.92498,0.48518,0.06579
8.20000,2.73138,68.34166,68.34165,0.48815,0.06503
8.25000,2.54158,68.75833,68.75833,0.49113,0.06051
8.30000,2.97800,69.17504,69.17504,0.49411,0.07090
8.35000,2.58554,69.59177,69.59177,0.49708,0.06156
8.40000,2.71983,70.00840,70.00839,0.50006,0.06476
8.45000,2.87332,70.42511,70.42511,0.50304,0.06841
8.50000,2.65408,70.84170,70.84170,0.50601,0.06319
8.55000,2.89343,71.25840,71.25841,0.50899,0.06889
8.60000,2.66228,71.67500,71.67500,0.51196,0.06339
8.65000,3.22051,72.09168,72.09167,0.51494,0.07668
8.70000,2.95695,72.50828,72.50828,0.51792,0.07040
8.75000,2.96179,72.92493,72.92492,0.52089,0.07052
8.80000,2.99793,73.34158,73.34158,0.52387,0.07138
8.85000,2.92603,73.75823,73.75823,0.52684,0.06967
8.90000,2.75262,74.17489,74.17489,0.52982,0.06554
8.95000,2.70512,74.59159,74.59160,0.53280,0.06441
9.00000,2.61087,75.00824,75.00824,0.53577,0.06216
9.05000,2.64384,75.42489,75.42489,0.53875,0.06295
9.10000,2.77814,75.84165,75.84164,0.54173,0.06615
9.15000,2.86866,76.25836,76.25835,0.54470,0.06830
9.20000,2.58479,76.67501,76.67501,0.54768,0.06154
9.25000,2.73772,77.09169,77.09169,0.55065,0.06518
9.30000,2.52500,77.50844,77.50845,0.55363,0.06012
9.35000,2.69040,77.92510,77.92509,0.55661,0.06406
9.40000,2.40169,78.34175,78.34175,0.55958,0.05718
9.45000,2.35885,78.75838,78.75838,0.56256,0.05616
9.50000,2.34656,79.17505,79.17505,0.56554,0.05587
9.55000,2.40635,79.59168,79.59167,0.56851,0.05729
9.60000,2.45571,80.00830,80.00831,0.57149,0.05847
9.65000,2.71145,80.42490,80.42490,0.57446,0.06456
9.70000,2.47881,80.84160,80.84161,0.57744,0.05902
9.75000,2.26069,81.25820,81.25820,0.58042,0.05383
9.80000,2.51587,81.67482,81.67482,0.58339,0.05990
9.85000,2.61869,82.09159,82.09158,0.58637,0.06235
9.90000,2.56021,82.50826,82.50826,0.58934,0.06096
9.95000,3.05325,82.92494,82.92494,0.59232,0.07270
10.00000,2.49613,83.34163,83.34163,0.59530,0.05943
10.05000,2.65036,83.75836,83.75835,0.59827,0.06310
10.10000,2.93199,84.17506,84.17507,0.60125,0.06981
10.15000,2.83793,84.59177,84.59177,0.60423,0.06757
10.20000,2.84184,85.00839,85.00838,0.60720,0.06766
10.25000,2.68966,85.42504,85.42504,0.61018,0.06404
10.30000,3.18773,85.84177,85.84177,0.61316,0.07590
10.35000,2.99849,86.25840,86.25840,0.61613,0.07139
10.40000,3.08156,86.67499,86.67499,0.61911,0.07337
10.45000,3.20598,87.09162,87.09162,0.62208,0.07633
10.50000,3.35928,87.50833,87.50832,0.62506,0.07998
10.55000,3.28682,87.92493,87.92493,0.62804,0.07826
10.60000,2.96030,88.34157,88.34158,0.63101,0.07048
10.65000,2.77609,88.75826,88.75826,0.63399,0.06610
10.70000,2.62633,89.17493,89.17493,0.63696,0.06253
10.75000,3.02438,89.59156,89.59156,0.63994,0.07201
10.80000,3.04878,90.00821,90.00821,0.64292,0.07259
10.85000,2.54214,90.42494,90.42494,0.64589,0.06053
10.90000,2.84631,90.84170,90.84170,0.64887,0.06777
10.95000,3.15476,91.25832,91.25832,0.65185,0.07511
11.00000,2.84817,91.67500,91.67500,0.65482,0.06781
11.05000,2.87686,92.09170,92.09171,0.65780,0.06850
11.10000,2.99010,92.50841,92.50841,0.66077,0.07119
11.15000,3.24901,92.92509,92.92509,0.66375,0.07736
11.20000,3.47793,93.34174,93.34174,0.66673,0.08281
11.25000,3.20654,93.75842,93.75842,0.66970,0.07635
11.30000,3.18810,94.17504,94.17504,0.67268,0.07591
11.35000,3.45260,94.59168,94.59167,0.67565,0.08220
11.40000,3.60813,95.00826,95.00826,0.67863,0.08591
11.45000,3.72883,95.42495,95.42495,0.68161,0.08878
11.50000,4.10918,95.84157,95.84157,0.68458,0.09784
11.55000,4.29582,96.25822,96.25822,0.68756,0.10228
11.60000,4.22020,96.67485,96.67484,0.69053,0.10048
11.65000,4.26024,97.09160,97.09160,0.69351,0.10143
11.70000,4.71566,97.50824,97.50824,0.69649,0.11228
11.75000,4.47836,97.92497,97.92496,0.69946,0.10663
11.80000,3.87374,98.34162,98.34162,0.70244,0.09223
11.85000,4.47482,98.75840,98.75840,0.70542,0.10654
11.90000,4.48935,99.17503,99.17503,0.70839,0.10689
11.95000,4.69815,99.59173,99.59174,0.71137,0.11186
12.00000,4.33698,100.00838,100.00838,0.71435,0.10326
12.05000,4.36921,100.42509,100.42509,0.71732,0.10403
12.10000,4.63687,100.84174,100.84174,0.72030,0.11040
12.15000,4.60688,101.25837,101.25837,0.72327,0.10969
12.20000,4.53461,101.67505,101.67505,0.72625,0.10797
12.25000,4.49400,102.09164,102.09164,0.72923,0.10700
12.30000,4.54523,102.50829,102.50829,0.73220,0.10822
12.35000,4.46569,102.92492,102.92492,0.73518,0.10633
12.40000,4.28762,103.34165,103.34165,0.73815,0.10209
12.45000,4.63836,103.75825,103.75825,0.74113,0.11044
12.50000,4.30960,104.17490,104.17490,0.74411,0.10261
12.55000,4.30085,104.59152,104.59152,0.74708,0.10240
12.60000,4.23566,105.00828,105.00828,0.75006,0.10085
12.65000,4.39826,105.42493,105.42493,0.75304,0.10472
12.70000,4.34425,105.84164,105.84164,0.75601,0.10343
12.75000,4.55528,106.25831,106.25832,0.75899,0.10846
12.80000,4.36027,106.67502,106.67501,0.76196,0.10382
12.85000,4.01214,107.09170,107.09171,0.76494,0.09553
12.90000,4.28241,107.50843,107.50843,0.76792,0.10196
12.95000,5.15450,107.92514,107.92514,0.77089,0.12273
13.00000,4.72702,108.34179,108.34179,0.77387,0.11255
13.05000,4.93955,108.75839,108.75839,0.77685,0.11761
13.10000,4.62327,109.17501,109.17502,0.77982,0.11008
13.15000,4.53889,109.59169,109.59169,0.78280,0.10807
13.20000,4.66593,110.00829,110.00829,0.78577,0.11109
13.25000,4.54616,110.42491,110.42491,0.78875,0.10824
13.30000,5.19473,110.84155,110.84155,0.79173,0.12368
13.35000,5.12190,111.25822,111.25822,0.79470,0.12195
13.40000,4.71137,111.67489,111.67489,0.79768,0.11218
13.45000,4.71100,112.09155,112.09155,0.80065,0.11217
13.50000,4.57093,112.50819,112.50819,0.80363,0.10883
13.55000,4.81550,112.92496,112.92496,0.80661,0.11465
13.60000,4.90975,113.34167,113.34167,0.80958,0.11690
13.65000,4.93955,113.75834,113.75834,0.81256,0.11761
13.70000,4.96153,114.17505,114.17505,0.81554,0.11813
13.75000,4.43235,114.59172,114.59172,0.81851,0.10553
13.80000,4.58006,115.00842,115.00842,0.82149,0.10905
13.85000,4.61675,115.42498,115.42497,0.82446,0.10992
13.90000,4.73708,115.84173,115.84173,0.82744,0.11279
13.95000,4.59943,116.25838,116.25838,0.83042,0.10951
14.00000,4.89298,116.67503,116.67503,0.83339,0.11650
14.05000,5.00642,117.09164,117.09164,0.83637,0.11920
14.10000,4.92968,117.50828,117.50829,0.83934,0.11737
14.15000,4.92819,117.92497,117.92496,0.84232,0.11734
14.20000,4.77284,118.34159,118.34159,0.84530,0.11364
14.25000,4.95147,118.75823,118.75823,0.84827,0.11789
14.30000,5.01182,119.17487,119.17487,0.85125,0.11933
14.35000,4.72181,119.59160,119.59161,0.85423,0.11242
14.40000,4.70020,120.00825,120.00825,0.85720,0.11191
14.45000,4.42136,120.42492,120.42492,0.86018,0.10527
14.50000,4.89485,120.84161,120.84161,0.86315,0.11654
14.55000,4.54895,121.25839,121.25839,0.86613,0.10831
14.60000,4.66499,121.67499,121.67499,0.86911,0.11107
14.65000,4.73633,122.09173,122.09173,0.87208,0.11277
14.70000,4.85685,122.50840,122.50840,0.87506,0.11564
14.75000,4.60669,122.92513,122.92513,0.87804,0.10968
14.80000,4.81661,123.34173,123.34173,0.88101,0.11468
14.85000,4.50257,123.75833,123.75833,0.88399,0.10720
14.90000,4.75906,124.17506,124.17506,0.88696,0.11331
14.95000,4.69778,124.59168,124.59167,0.88994,0.11185
15.00000,4.71324,125.00831,125.00831,0.89292,0.11222
15.05000,4.46234,125.42488,125.42488,0.89589,0.10625
15.10000,4.98760,125.84158,125.84158,0.89887,0.11875
15.15000,5.05727,126.25821,126.25821,0.90184,0.12041
15.20000,4.45619,126.67488,126.67488,0.90482,0.10610
15.25000,4.66406,127.09151,127.09151,0.90780,0.11105
15.30000,4.57987,127.50828,127.50828,0.91077,0.10904
15.35000,4.89578,127.92492,127.92492,0.91375,0.11657
15.40000,4.64767,128.34165,128.34164,0.91673,0.11066
15.45000,4.72330,128.75833,128.75833,0.91970,0.11246
15.50000,4.95054,129.17507,129.17506,0.92268,0.11787
15.55000,4.48041,129.59174,129.59174,0.92566,0.10668
15.60000,4.37908,130.00839,130.00839,0.92863,0.10426
15.65000,5.06155,130.42505,130.42505,0.93161,0.12051
15.70000,4.67449,130.84178,130.84178,0.93458,0.11130
15.75000,4.88479,131.25838,131.25838,0.93756,0.11630
15.80000,4.62979,131.67500,131.67500,0.94054,0.11023
15.85000,4.76278,132.09164,132.09164,0.94351,0.11340
15.90000,4.78588,132.50825,132.50826,0.94649,0.11395
15.95000,4.79706,132.92495,132.92494,0.94946,0.11422
16.00000,4.88572,133.34159,133.34160,0.95244,0.11633
16.05000,4.58993,133.75824,133.75824,0.95542,0.10928
16.10000,4.53256,134.17488,134.17488,0.95839,0.10792
16.15000,4.37777,134.59156,134.59155,0.96137,0.10423
16.20000,4.75254,135.00823,135.00822,0.96434,0.11316
16.25000,4.34071,135.42495,135.42496,0.96732,0.10335
16.30000,4.49307,135.84162,135.84163,0.97030,0.10698
16.35000,4.51040,136.25831,136.25830,0.97327,0.10739
16.40000,4.82146,136.67498,136.67497,0.97625,0.11480
16.45000,4.74993,137.09174,137.09174,0.97923,0.11309
16.50000,4.78625,137.50841,137.50841,0.98220,0.11396
16.55000,4.93955,137.92506,137.92506,0.98518,0.11761
16.60000,4.99804,138.34177,138.34177,0.98816,0.11900
16.65000,4.75552,138.75839,138.75839,0.99113,0.11323
16.70000,4.77657,139.17505,139.17505,0.99411,0.11373
16.75000,4.98630,139.59166,139.59166,0.99708,0.11872
16.80000,5.22006,140.00830,140.00829,1.00006,0.12429
16.85000,4.85592,140.42496,140.42496,1.00304,0.11562
16.90000,4.73857,140.84152,140.84151,1.00601,0.11282
16.95000,4.80507,141.25820,141.25819,1.00899,0.11441
17.00000,4.91906,141.67489,141.67488,1.01196,0.11712
17.05000,4.75459,142.09160,142.09161,1.01494,0.11320
17.10000,4.60576,142.50824,142.50822,1.01792,0.10966
17.15000,4.83803,142.92491,142.92491,1.02089,0.11519
17.20000,4.87603,143.34165,143.34164,1.02387,0.11610
17.25000,5.04423,143.75840,143.75841,1.02685,0.12010
17.30000,5.12451,144.17503,144.17503,1.02982,0.12201
17.35000,4.92688,144.59171,144.59171,1.03280,0.11731
17.40000,4.98164,145.00839,145.00839,1.03577,0.11861
17.45000,4.94979,145.42509,145.42509,1.03875,0.11785
17.50000,4.97438,145.84170,145.84169,1.04173,0.11844
17.55000,5.16251,146.25834,146.25835,1.04470,0.12292
17.60000,4.69815,146.67500,146.67500,1.04768,0.11186
17.65000,4.90583,147.09170,147.09171,1.05066,0.11681
17.70000,4.67896,147.50827,147.50827,1.05363,0.11140
17.75000,5.07347,147.92495,147.92496,1.05661,0.12080
17.80000,5.21056,148.34161,148.34161,1.05958,0.12406
17.85000,5.02635,148.75828,148.75829,1.06256,0.11967
17.90000,5.36330,149.17485,149.17485,1.06553,0.12770
17.95000,5.21131,149.59156,149.59155,1.06851,0.12408
18.00000,5.13382,150.00828,150.00829,1.07149,0.12223
18.05000,5.03007,150.42493,150.42491,1.07446,0.11976
18.10000,5.19548,150.84159,150.84158,1.07744,0.12370
18.15000,5.18598,151.25827,151.25827,1.08042,0.12348
18.20000,4.76167,151.67505,151.67505,1.08339,0.11337
18.25000,5.17443,152.09173,152.09174,1.08637,0.12320
18.30000,5.28842,152.50845,152.50844,1.08935,0.12591
18.35000,5.34914,152.92506,152.92506,1.09232,0.12736
18.40000,5.48102,153.34179,153.34178,1.09530,0.13050
18.45000,4.95408,153.75837,153.75836,1.09827,0.11795
18.50000,5.14165,154.17505,154.17505,1.10125,0.12242
18.55000,5.43073,154.59165,154.59166,1.10423,0.12930
18.60000,5.44507,155.00832,155.00832,1.10720,0.12964
18.65000,5.19436,155.42491,155.42491,1.11018,0.12368
18.70000,5.60079,155.84155,155.84155,1.11315,0.13335
18.75000,5.44824,156.25822,156.25822,1.11613,0.12972
18.80000,5.50784,156.67486,156.67487,1.11911,0.13114
18.85000,5.65331,157.09155,157.09155,1.12208,0.13460
18.90000,5.07720,157.50821,157.50821,1.12506,0.12089
18.95000,5.24558,157.92494,157.92494,1.12804,0.12489
19.00000,5.53727,158.34167,158.34167,1.13101,0.13184
19.05000,5.42905,158.75838,158.75838,1.13399,0.12926
19.10000,5.49983,159.17497,159.17497,1.13696,0.13095
19.15000,5.37261,159.59176,159.59178,1.13994,0.12792
19.20000,5.64586,160.00841,160.00841,1.14292,0.13443
19.25000,5.65089,160.42505,160.42505,1.14589,0.13455
19.30000,5.77569,160.84171,160.84171,1.14887,0.13752
19.35000,5.71795,161.25842,161.25844,1.15185,0.13614
19.40000,5.60880,161.67502,161.67502,1.15482,0.13354
19.45000,5.62388,162.09164,162.09164,1.15780,0.13390
19.50000,5.64605,162.50828,162.50827,1.16077,0.13443
19.55000,6.10817,162.92497,162.92497,1.16375,0.14543
19.60000,5.57974,163.34159,163.34158,1.16673,0.13285
19.65000,5.68349,163.75822,163.75822,1.16970,0.13532
19.70000,6.13723,164.17489,164.17490,1.17268,0.14612
19.75000,6.02324,164.59160,164.59160,1.17565,0.14341
19.80000,5.48344,165.00825,165.00826,1.17863,0.13056
19.85000,6.02622,165.42491,165.42493,1.18161,0.14348
19.90000,5.91017,165.84166,165.84166,1.18458,0.14072
19.95000,5.86268,166.25828,166.25827,1.18756,0.13959
20.00000,5.70528,166.67505,166.67505,1.19054,0.13584
20.05000,6.36857,167.09173,167.09172,1.19351,0.15163
20.10000,6.07986,167.50844,167.50844,1.19649,0.14476
20.15000,6.08228,167.92508,167.92508,1.19946,0.14482
20.20000,5.83325,168.34173,168.34172,1.20244,0.13889
20.25000,6.23707,168.75839,168.75839,1.20542,0.14850
20.30000,6.27171,169.17503,169.17503,1.20839,0.14933
20.35000,6.22664,169.59172,169.59172,1.21137,0.14825
20.40000,6.46748,170.00826,170.00826,1.21434,0.15399
20.45000,6.44438,170.42489,170.42490,1.21732,0.15344
20.50000,6.76028,170.84156,170.84157,1.22030,0.16096
20.55000,6.32517,171.25825,171.25826,1.22327,0.15060
20.60000,6.31679,171.67482,171.67484,1.22625,0.15040
20.65000,6.49542,172.09157,172.09157,1.22923,0.15465
20.70000,6.28307,172.50825,172.50826,1.23220,0.14960
20.75000,5.88559,172.92496,172.92497,1.23518,0.14013
20.80000,6.53788,173.34166,173.34167,1.23815,0.15566
20.85000,6.34957,173.75837,173.75838,1.24113,0.15118
20.90000,6.79046,174.17509,174.17509,1.24411,0.16168
20.95000,6.37695,174.59173,174.59172,1.24708,0.15183
21.00000,6.41104,175.00837,175.00838,1.25006,0.15264
21.05000,6.86701,175.42506,175.42506,1.25304,0.16350
21.10000,6.75544,175.84178,175.84177,1.25601,0.16084
21.15000,6.92662,176.25834,176.25833,1.25899,0.16492
21.20000,6.70236,176.67501,176.67500,1.26196,0.15958
21.25000,6.79828,177.09160,177.09160,1.26494,0.16186
21.30000,6.69546,177.50837,177.50836,1.26792,0.15942
21.35000,6.93630,177.92493,177.92493,1.27089,0.16515
21.40000,6.94431,178.34162,178.34161,1.27387,0.16534
21.45000,7.03391,178.75824,178.75822,1.27684,0.16747
21.50000,6.79791,179.17492,179.17493,1.27982,0.16185
21.55000,6.94897,179.59157,179.59155,1.28280,0.16545
21.60000,7.18851,180.00823,180.00822,1.28577,0.17115
21.65000,6.77034,180.42492,180.42493,1.28875,0.16120
21.70000,6.89588,180.84166,180.84166,1.29173,0.16419
21.75000,7.33156,181.25831,181.25830,1.29470,0.17456
21.80000,7.19950,181.67499,181.67497,1.29768,0.17142
21.85000,6.74073,182.09176,182.09175,1.30066,0.16049
21.90000,6.90073,182.50843,182.50842,1.30363,0.16430
21.95000,7.12462,182.92510,182.92509,1.30661,0.16963
22.00000,7.13449,183.34171,183.34172,1.30958,0.16987
22.05000,7.11866,183.75846,183.75845,1.31256,0.16949
22.10000,7.34795,184.17505,184.17503,1.31554,0.17495
22.15000,6.97486,184.59166,184.59166,1.31851,0.16607
22.20000,7.32504,185.00825,185.00826,1.32149,0.17441
22.25000,6.99274,185.42496,185.42496,1.32446,0.16649
22.30000,7.07116,185.84155,185.84155,1.32744,0.16836
22.35000,6.83665,186.25816,186.25818,1.33042,0.16278
22.40000,7.23619,186.67486,186.67487,1.33339,0.17229
22.45000,7.65398,187.09164,187.09163,1.33637,0.18224
22.50000,7.61338,187.50827,187.50827,1.33934,0.18127
22.55000,7.55768,187.92494,187.92494,1.34232,0.17994
22.60000,7.59065,188.34169,188.34169,1.34530,0.18073
22.65000,7.89519,188.75836,188.75836,1.34827,0.18798
22.70000,7.44164,189.17506,189.17506,1.35125,0.17718
22.75000,7.17100,189.59168,189.59166,1.35423,0.17074
22.80000,7.44332,190.00843,190.00844,1.35720,0.17722
22.85000,7.41072,190.42508,190.42508,1.36018,0.17645
22.90000,7.71265,190.84173,190.84174,1.36316,0.18363
22.95000,7.78772,191.25835,191.25835,1.36613,0.18542
23.00000,7.85943,191.67500,191.67500,1.36911,0.18713
23.05000,7.99894,192.09171,192.09171,1.37208,0.19045
23.10000,8.11256,192.50830,192.50832,1.37506,0.19316
23.15000,8.11890,192.92492,192.92493,1.37804,0.19331
23.20000,8.07941,193.34161,193.34161,1.38101,0.19237
23.25000,8.04532,193.75823,193.75822,1.38399,0.19156
23.30000,8.02800,194.17487,194.17488,1.38696,0.19114
23.35000,7.50888,194.59156,194.59155,1.38994,0.17878
23.40000,8.08425,195.00824,195.00826,1.39292,0.19248
23.45000,7.86558,195.42496,195.42496,1.39589,0.18728
23.50000,7.88383,195.84161,195.84161,1.39887,0.18771
23.55000,8.06991,196.25833,196.25833,1.40185,0.19214
23.60000,8.25822,196.67506,196.67506,1.40482,0.19662
23.65000,8.01254,197.09173,197.09172,1.40780,0.19077
23.70000,8.23811,197.50839,197.50839,1.41077,0.19615
23.75000,8.52998,197.92510,197.92511,1.41375,0.20309
23.80000,8.28728,198.34178,198.34178,1.41673,0.19732
23.85000,8.33645,198.75841,198.75841,1.41970,0.19849
23.90000,8.15317,199.17503,199.17503,1.42268,0.19412
23.95000,8.26549,199.59167,199.59167,1.42565,0.19680
24.00000,8.61008,200.00829,200.00830,1.42863,0.20500
24.05000,8.35750,200.42487,200.42488,1.43161,0.19899
24.10000,8.69352,200.84157,200.84158,1.43458,0.20699
24.15000,8.29790,201.25823,201.25822,1.43756,0.19757
24.20000,8.68458,201.67489,201.67490,1.44053,0.20678
24.25000,8.62814,202.09155,202.09154,1.44351,0.20543
24.30000,8.69371,202.50823,202.50824,1.44649,0.20699
24.35000,8.86992,202.92494,202.92494,1.44946,0.21119
24.40000,8.82410,203.34171,203.34171,1.45244,0.21010
24.45000,8.45958,203.75833,203.75835,1.45542,0.20142
24.50000,8.58195,204.17504,204.17503,1.45839,0.20433
24.55000,8.70582,204.59171,204.59171,1.46137,0.20728
24.60000,8.62610,205.00845,205.00845,1.46435,0.20538
24.65000,8.84291,205.42503,205.42503,1.46732,0.21055
24.70000,8.81292,205.84171,205.84171,1.47030,0.20983
24.75000,8.45008,206.25842,206.25842,1.47327,0.20119
24.80000,8.89059,206.67499,206.67499,1.47625,0.21168
24.85000,8.86265,207.09164,207.09164,1.47923,0.21102
24.90000,9.22102,207.50830,207.50829,1.48220,0.21955
24.95000,9.08822,207.92501,207.92500,1.48518,0.21639
25.00000,9.08338,208.34161,208.34161,1.48815,0.21627
25.05000,8.74549,208.75823,208.75824,1.49113,0.20823
25.10000,9.14522,209.17488,209.17488,1.49411,0.21774
25.15000,9.07779,209.59160,209.59158,1.49708,0.21614
25.20000,9.02731,210.00821,210.00821,1.50006,0.21494
25.25000,9.36221,210.42493,210.42493,1.50304,0.22291
25.30000,9.18303,210.84162,210.84161,1.50601,0.21864
25.35000,9.34564,211.25834,211.25835,1.50899,0.22252
25.40000,9.30708,211.67503,211.67503,1.51196,0.22160
25.45000,9.32142,212.09174,212.09174,1.51494,0.22194
25.50000,9.40915,212.50844,212.50844,1.51792,0.22403
25.55000,9.69246,212.92512,212.92513,1.52089,0.23077
25.60000,9.39760,213.34177,213.34177,1.52387,0.22375
25.65000,9.68818,213.75836,213.75836,1.52685,0.23067
25.70000,9.22848,214.17501,214.17500,1.52982,0.21973
25.75000,9.78019,214.59167,214.59166,1.53280,0.23286
25.80000,9.71742,215.00830,215.00830,1.53577,0.23137
25.85000,9.41437,215.42489,215.42490,1.53875,0.22415
25.90000,9.43057,215.84160,215.84160,1.54173,0.22454
25.95000,9.70624,216.25822,216.25822,1.54470,0.23110
26.00000,9.59747,216.67487,216.67487,1.54768,0.22851
26.05000,9.71239,217.09153,217.09154,1.55065,0.23125
26.10000,10.06313,217.50832,217.50832,1.55363,0.23960
26.15000,10.28515,217.92499,217.92497,1.55661,0.24488
26.20000,9.87537,218.34167,218.34169,1.55958,0.23513
26.25000,9.92045,218.75832,218.75832,1.56256,0.23620
26.30000,10.16092,219.17506,219.17505,1.56554,0.24193
26.35000,10.39114,219.59174,219.59174,1.56851,0.24741
26.40000,10.14527,220.00837,220.00838,1.57149,0.24155
26.45000,10.11975,220.42506,220.42506,1.57446,0.24095
26.50000,10.31179,220.84177,220.84177,1.57744,0.24552
26.55000,10.16892,221.25838,221.25838,1.58042,0.24212
26.60000,10.22499,221.67498,221.67499,1.58339,0.24345
26.65000,10.41498,222.09172,222.09172,1.58637,0.24798
26.70000,10.19742,222.50833,222.50833,1.58935,0.24280
26.75000,10.09889,222.92493,222.92493,1.59232,0.24045
26.80000,9.82378,223.34157,223.34157,1.59530,0.23390
26.85000,10.43696,223.75825,223.75826,1.59827,0.24850
26.90000,10.40865,224.17494,224.17494,1.60125,0.24782
26.95000,10.31402,224.59154,224.59154,1.60423,0.24557
27.00000,10.34327,225.00823,225.00822,1.60720,0.24627
27.05000,10.22294,225.42491,225.42491,1.61018,0.24340
27.10000,10.75286,225.84167,225.84167,1.61315,0.25602
27.15000,11.01978,226.25836,226.25836,1.61613,0.26238
27.20000,10.66085,226.67504,226.67505,1.61911,0.25383
27.25000,11.26640,227.09173,227.09174,1.62208,0.26825
27.30000,10.94546,227.50844,227.50844,1.62506,0.26061
27.35000,10.98458,227.92505,227.92505,1.62804,0.26154
27.40000,11.24796,228.34176,228.34175,1.63101,0.26781
27.45000,10.79869,228.75842,228.75842,1.63399,0.25711
27.50000,11.24423,229.17505,229.17505,1.63696,0.26772
27.55000,10.77335,229.59163,229.59163,1.63994,0.25651
27.60000,10.62546,230.00826,230.00827,1.64292,0.25299
27.65000,10.97061,230.42497,230.42497,1.64589,0.26120
27.70000,11.36288,230.84158,230.84158,1.64887,0.27054
27.75000,11.24665,231.25821,231.25821,1.65184,0.26778
27.80000,11.50351,231.67487,231.67487,1.65482,0.27389
27.85000,11.47725,232.09161,232.09161,1.65780,0.27327
27.90000,11.60000,232.50822,232.50821,1.66077,0.27619
27.95000,11.24684,232.92495,232.92496,1.66375,0.26778
28.00000,11.44689,233.34166,233.34166,1.66673,0.27254
28.05000,11.38914,233.75838,233.75838,1.66970,0.27117
28.10000,11.35841,234.17496,234.17496,1.67268,0.27044
28.15000,11.41857,234.59174,234.59175,1.67566,0.27187
28.20000,11.01792,235.00840,235.00841,1.67863,0.26233
28.25000,11.39883,235.42511,235.42511,1.68161,0.27140
28.30000,11.50407,235.84172,235.84172,1.68458,0.27391
28.35000,11.84773,236.25838,236.25838,1.68756,0.28209
28.40000,11.87585,236.67504,236.67503,1.69054,0.28276
28.45000,12.09434,237.09170,237.09171,1.69351,0.28796
28.50000,12.01723,237.50830,237.50830,1.69649,0.28612
28.55000,11.71473,237.92491,237.92491,1.69946,0.27892
28.60000,11.84139,238.34162,238.34163,1.70244,0.28194
28.65000,11.77359,238.75823,238.75822,1.70542,0.28032
28.70000,11.96936,239.17489,239.17488,1.70839,0.28498
28.75000,12.07031,239.59152,239.59152,1.71137,0.28739
28.80000,11.85965,240.00831,240.00832,1.71435,0.28237
28.85000,12.13476,240.42492,240.42491,1.71732,0.28892
28.90000,12.07627,240.84165,240.84166,1.72030,0.28753
28.95000,12.42254,241.25831,241.25832,1.72327,0.29577
29.00000,12.55590,241.67508,241.67508,1.72625,0.29895
29.05000,12.66673,242.09173,242.09174,1.72923,0.30159
29.10000,12.79265,242.50839,242.50839,1.73220,0.30459
29.15000,12.75279,242.92508,242.92508,1.73518,0.30364
29.20000,12.56205,243.34181,243.34181,1.73816,0.29910
29.25000,12.62538,243.75840,243.75839,1.74113,0.30060
29.30000,12.49444,244.17498,244.17497,1.74411,0.29749
29.35000,12.50077,244.59169,244.59169,1.74708,0.29764
29.40000,12.39832,245.00829,245.00830,1.75006,0.29520
29.45000,12.54156,245.42493,245.42493,1.75304,0.29861
29.50000,12.61253,245.84156,245.84155,1.75601,0.30030
29.55000,12.88243,246.25824,246.25824,1.75899,0.30672
29.60000,12.84909,246.67490,246.67490,1.76196,0.30593
29.65000,12.98226,247.09156,247.09157,1.76494,0.30910
29.70000,13.05770,247.50825,247.50824,1.76792,0.31090
29.75000,13.18119,247.92498,247.92499,1.77089,0.31384
29.80000,13.24546,248.34167,248.34167,1.77387,0.31537
29.85000,13.00108,248.75833,248.75833,1.77685,0.30955
29.90000,12.91502,249.17499,249.17499,1.77982,0.30750
29.95000,13.46320,249.59175,249.59175,1.78280,0.32055
30.00000,13.09142,250.00841,250.00841,1.78577,0.31170
30.05000,13.07596,250.42509,250.42509,1.78875,0.31133
30.10000,13.46022,250.84173,250.84172,1.79173,0.32048
30.15000,13.44830,251.25836,251.25836,1.79470,0.32020
30.20000,13.69864,251.67507,251.67506,1.79768,0.32616
30.25000,13.68951,252.09168,252.09167,1.80065,0.32594
30.30000,14.12686,252.50828,252.50829,1.80363,0.33635
30.35000,13.87727,252.92497,252.92497,1.80661,0.33041
30.40000,13.87242,253.34160,253.34160,1.80958,0.33030
30.45000,13.64145,253.75821,253.75821,1.81256,0.32480
30.50000,13.73086,254.17487,254.17487,1.81553,0.32693
30.55000,13.60066,254.59160,254.59160,1.81851,0.32383
30.60000,13.78693,255.00824,255.00824,1.82149,0.32826
30.65000,13.41924,255.42492,255.42493,1.82446,0.31951
30.70000,13.99033,255.84166,255.84166,1.82744,0.33310
30.75000,14.51503,256.25834,256.25833,1.83042,0.34560
30.80000,14.51857,256.67498,256.67499,1.83339,0.34568
30.85000,14.28090,257.09176,257.09177,1.83637,0.34002
30.90000,14.01547,257.50840,257.50839,1.83935,0.33370
30.95000,14.20230,257.92513,257.92514,1.84232,0.33815
31.00000,14.04341,258.34171,258.34171,1.84530,0.33437
31.05000,14.14828,258.75840,258.75839,1.84827,0.33686
31.10000,14.40495,259.17503,259.17502,1.85125,0.34298
31.15000,13.86832,259.59164,259.59164,1.85423,0.33020
31.20000,14.47629,260.00830,260.00830,1.85720,0.34467
31.25000,14.18255,260.42496,260.42496,1.86018,0.33768
31.30000,14.50833,260.84159,260.84158,1.86315,0.34544
31.35000,14.94624,261.25822,261.25821,1.86613,0.35586
31.40000,14.55154,261.67488,261.67487,1.86911,0.34647
31.45000,15.10307,262.09159,262.09158,1.87208,0.35960
31.50000,15.31038,262.50830,262.50830,1.87506,0.36453
31.55000,15.27444,262.92496,262.92496,1.87804,0.36368
31.60000,14.96486,263.34162,263.34161,1.88101,0.35631
31.65000,15.12561,263.75833,263.75833,1.88399,0.36013
31.70000,15.21725,264.17507,264.17508,1.88696,0.36232
31.75000,14.81101,264.59170,264.59171,1.88994,0.35264
31.80000,14.83094,265.00841,265.00842,1.89292,0.35312
31.85000,15.11108,265.42507,265.42508,1.89589,0.35979
31.90000,15.54321,265.84178,265.84180,1.89887,0.37008
31.95000,15.48752,266.25836,266.25836,1.90185,0.36875
32.00000,16.22401,266.67505,266.67505,1.90482,0.38629
32.05000,15.86545,267.09168,267.09167,1.90780,0.37775
32.10000,15.95374,267.50834,267.50833,1.91077,0.37985
32.15000,15.45101,267.92487,267.92487,1.91375,0.36788
32.20000,15.88408,268.34158,268.34158,1.91673,0.37819
32.25000,15.69968,268.75824,268.75824,1.91970,0.37380
32.30000,15.60766,269.17492,269.17493,1.92268,0.37161
32.35000,15.24482,269.59155,269.59155,1.92565,0.36297
32.40000,15.45139,270.00821,270.00821,1.92863,0.36789
32.45000,15.71309,270.42500,270.42499,1.93161,0.37412
32.50000,15.78238,270.84166,270.84167,1.93458,0.37577
32.55000,16.01297,271.25835,271.25836,1.93756,0.38126
32.60000,15.92152,271.67501,271.67502,1.94054,0.37908
32.65000,16.62169,272.09179,272.09180,1.94351,0.39575
32.70000,16.21470,272.50840,272.50839,1.94649,0.38606
32.75000,16.18546,272.92511,272.92511,1.94947,0.38537
32.80000,16.17819,273.34172,273.34171,1.95244,0.38520
32.85000,15.89786,273.75843,273.75842,1.95542,0.37852
32.90000,15.64734,274.17504,274.17505,1.95839,0.37256
32.95000,15.94946,274.59167,274.59167,1.96137,0.37975
33.00000,16.68613,275.00830,275.00830,1.96434,0.39729
33.05000,15.98001,275.42496,275.42496,1.96732,0.38048
33.10000,16.90108,275.84159,275.84158,1.97030,0.40241
33.15000,16.54867,276.25817,276.25818,1.97327,0.39402
33.20000,16.66788,276.67486,276.67487,1.97625,0.39685
33.25000,16.92083,277.09160,277.09158,1.97923,0.40288
33.30000,16.70290,277.50828,277.50827,1.98220,0.39769
33.35000,16.85787,277.92491,277.92493,1.98518,0.40138
33.40000,16.26275,278.34165,278.34164,1.98815,0.38721
33.45000,16.55873,278.75836,278.75836,1.99113,0.39426
33.50000,16.76138,279.17505,279.17505,1.99411,0.39908
33.55000,16.74090,279.59168,279.59167,1.99708,0.39859
33.60000,16.92325,280.00844,280.00845,2.00006,0.40293
33.65000,17.04991,280.42510,280.42511,2.00304,0.40595
33.70000,17.19240,280.84176,280.84180,2.00601,0.40934
33.75000,17.40046,281.25839,281.25842,2.00899,0.41430
33.80000,17.37364,281.67505,281.67502,2.01196,0.41366
33.85000,17.59902,282.09166,282.09164,2.01494,0.41902
33.90000,17.55040,282.50829,282.50830,2.01792,0.41787
33.95000,17.28162,282.92490,282.92490,2.02089,0.41147
34.00000,17.16912,283.34161,283.34161,2.02387,0.40879
34.05000,17.08437,283.75829,283.75830,2.02684,0.40677
34.10000,16.61982,284.17487,284.17487,2.02982,0.39571
34.15000,17.13596,284.59159,284.59158,2.03280,0.40800
34.20000,17.11715,285.00827,285.00827,2.03577,0.40755
34.25000,17.19873,285.42498,285.42499,2.03875,0.40949
34.30000,18.06971,285.84161,285.84161,2.04173,0.43023
34.35000,17.97453,286.25835,286.25836,2.04470,0.42796
34.40000,17.98868,286.67501,286.67502,2.04768,0.42830
34.45000,18.07194,287.09172,287.09174,2.05066,0.43028
34.50000,18.05909,287.50843,287.50839,2.05363,0.42998
34.55000,17.65117,287.92506,287.92508,2.05661,0.42027
34.60000,17.58151,288.34178,288.34177,2.05958,0.41861
34.65000,17.55096,288.75838,288.75839,2.06256,0.41788
34.70000,17.71227,289.17507,289.17508,2.06554,0.42172
34.75000,18.21052,289.59165,289.59164,2.06851,0.43358
34.80000,18.12223,290.00836,290.00839,2.07149,0.43148
34.85000,18.13546,290.42489,290.42487,2.07446,0.43180
34.90000,18.74398,290.84160,290.84158,2.07744,0.44629
34.95000,18.42547,291.25823,291.25824,2.08042,0.43870
35.00000,18.52419,291.67489,291.67490,2.08339,0.44105
35.05000,18.79800,292.09152,292.09152,2.08637,0.44757
35.10000,18.40554,292.50826,292.50827,2.08934,0.43823
35.15000,17.70407,292.92492,292.92493,2.09232,0.42153
35.20000,17.23021,293.34160,293.34161,2.09530,0.41024
35.25000,17.77112,293.75837,293.75836,2.09827,0.42312
35.30000,18.29807,294.17510,294.17511,2.10125,0.43567
35.35000,18.56685,294.59179,294.59180,2.10423,0.44207
35.40000,18.86506,295.00839,295.00839,2.10720,0.44917
35.45000,18.66650,295.42508,295.42508,2.11018,0.44444
35.50000,19.06678,295.84171,295.84171,2.11316,0.45397
35.55000,19.44266,296.25842,296.25842,2.11613,0.46292
35.60000,19.53375,296.67500,296.67502,2.11911,0.46509
35.65000,18.97085,297.09169,297.09167,2.12208,0.45169
35.70000,19.08522,297.50830,297.50833,2.12506,0.45441
35.75000,19.14334,297.92495,297.92496,2.12804,0.45579
35.80000,18.58585,298.34159,298.34158,2.13101,0.44252
35.85000,18.92578,298.75825,298.75824,2.13399,0.45061
35.90000,19.41863,299.17493,299.17493,2.13696,0.46235
35.95000,19.22995,299.59162,299.59161,2.13994,0.45786
36.00000,19.58832,300.00825,300.00821,2.14292,0.46639
36.05000,19.84462,300.42488,300.42487,2.14589,0.47249
36.10000,19.64532,300.84164,300.84164,2.14887,0.46775
36.15000,20.10167,301.25841,301.25839,2.15185,0.47861
36.20000,20.50996,301.67504,301.67505,2.15482,0.48833
36.25000,19.51978,302.09167,302.09167,2.15780,0.46476
36.30000,20.23056,302.50849,302.50848,2.16077,0.48168
36.35000,19.86139,302.92507,302.92508,2.16375,0.47289
36.40000,19.30892,303.34173,303.34174,2.16673,0.45974
36.45000,19.61980,303.75836,303.75836,2.16970,0.46714
36.50000,20.21492,304.17510,304.17511,2.17268,0.48131
36.55000,19.96215,304.59168,304.59167,2.17565,0.47529
36.60000,20.41366,305.00831,305.00830,2.17863,0.48604
36.65000,20.71261,305.42492,305.42493,2.18161,0.49316
36.70000,20.43750,305.84160,305.84161,2.18458,0.48661
36.75000,20.56267,306.25821,306.25821,2.18756,0.48959
36.80000,20.99704,306.67484,306.67484,2.19053,0.49993
36.85000,20.93595,307.09158,307.09158,2.19351,0.49847
36.90000,20.79923,307.50824,307.50824,2.19649,0.49522
36.95000,20.66325,307.92497,307.92499,2.19946,0.49198
37.00000,20.80332,308.34163,308.34164,2.20244,0.49532
37.05000,20.23932,308.75837,308.75836,2.20542,0.48189
37.10000,20.40844,309.17506,309.17505,2.20839,0.48592
37.15000,20.78786,309.59177,309.59177,2.21137,0.49495
37.20000,20.85455,310.00840,310.00839,2.21435,0.49654
37.25000,21.03746,310.42503,310.42502,2.21732,0.50089
37.30000,21.37292,310.84182,310.84183,2.22030,0.50888
37.35000,21.58973,311.25840,311.25839,2.22327,0.51404
37.40000,21.32561,311.67501,311.67505,2.22625,0.50775
37.45000,21.32114,312.09167,312.09167,2.22923,0.50765
37.50000,20.98549,312.50835,312.50836,2.23220,0.49965
37.55000,21.16933,312.92493,312.92490,2.23518,0.50403
37.60000,21.03690,313.34157,313.34155,2.23815,0.50088
37.65000,21.05813,313.75828,313.75827,2.24113,0.50138
37.70000,21.35448,314.17494,314.17493,2.24411,0.50844
37.75000,21.40719,314.59157,314.59155,2.24708,0.50970
37.80000,21.66107,315.00823,315.00821,2.25006,0.51574
37.85000,22.02112,315.42494,315.42493,2.25304,0.52431
37.90000,21.92259,315.84165,315.84164,2.25601,0.52197
37.95000,21.84100,316.25833,316.25833,2.25899,0.52002
38.00000,22.00678,316.67499,316.67499,2.26196,0.52397
38.05000,22.04161,317.09176,317.09180,2.26494,0.52480
38.10000,21.71881,317.50844,317.50845,2.26792,0.51711
38.15000,21.55118,317.92507,317.92508,2.27089,0.51312
38.20000,22.12431,318.34176,318.34177,2.27387,0.52677
38.25000,21.91123,318.75842,318.75845,2.27685,0.52170
38.30000,22.10271,319.17502,319.17502,2.27982,0.52625
38.35000,22.39030,319.59171,319.59167,2.28280,0.53310
38.40000,22.50392,320.00829,320.00830,2.28577,0.53581
38.45000,22.43202,320.42495,320.42496,2.28875,0.53410
38.50000,22.75854,320.84153,320.84152,2.29173,0.54187
38.55000,22.90048,321.25824,321.25827,2.29470,0.54525
38.60000,22.81982,321.67485,321.67484,2.29768,0.54333
38.65000,22.37670,322.09158,322.09158,2.30065,0.53278
38.70000,22.33032,322.50824,322.50824,2.30363,0.53167
38.75000,22.54229,322.92493,322.92493,2.30661,0.53672
38.80000,22.42364,323.34169,323.34167,2.30958,0.53390
38.85000,22.56483,323.75840,323.75839,2.31256,0.53726
38.90000,22.86248,324.17501,324.17502,2.31554,0.54434
38.95000,23.35012,324.59174,324.59174,2.31851,0.55596
39.00000,23.31734,325.00846,325.00842,2.32149,0.55517
39.05000,23.09680,325.42511,325.42511,2.32447,0.54992
39.10000,23.61480,325.84172,325.84174,2.32744,0.56226
39.15000,23.28269,326.25838,326.25839,2.33042,0.55435
39.20000,23.27207,326.67504,326.67505,2.33339,0.55410
39.25000,23.10704,327.09167,327.09167,2.33637,0.55017
39.30000,23.36223,327.50825,327.50824,2.33934,0.55624
39.35000,23.19720,327.92491,327.92490,2.34232,0.55231
39.40000,23.27152,328.34167,328.34164,2.34530,0.55408
39.45000,23.57978,328.75823,328.75824,2.34827,0.56142
39.50000,23.73960,329.17489,329.17490,2.35125,0.56523
39.55000,23.95567,329.59152,329.59152,2.35423,0.57037
39.60000,23.93331,330.00831,330.00830,2.35720,0.56984
39.65000,24.23991,330.42494,330.42496,2.36018,0.57714
39.70000,23.98621,330.84165,330.84164,2.36315,0.57110
39.75000,24.19259,331.25831,331.25830,2.36613,0.57601
39.80000,24.31013,331.67507,331.67508,2.36911,0.57881
39.85000,23.92326,332.09173,332.09174,2.37208,0.56960
39.90000,24.18328,332.50839,332.50836,2.37506,0.57579
39.95000,23.97038,332.92508,332.92508,2.37804,0.57072
40.00000,24.32913,333.34179,333.34177,2.38101,0.57926
40.05000,24.47441,333.75845,333.75845,2.38399,0.58272
40.10000,24.73071,334.17498,334.17499,2.38696,0.58883
40.15000,24.75809,334.59171,334.59171,2.38994,0.58948
40.20000,24.96205,335.00835,335.00833,2.39292,0.59433
40.25000,25.33551,335.42495,335.42499,2.39589,0.60323
40.30000,24.96988,335.84153,335.84152,2.39887,0.59452
40.35000,24.82049,336.25824,336.25821,2.40184,0.59096
40.40000,24.76741,336.67488,336.67484,2.40482,0.58970
40.45000,25.19824,337.09159,337.09158,2.40780,0.59996
40.50000,24.74375,337.50822,337.50821,2.41077,0.58914
40.55000,19.38511,337.92493,337.92493,2.41375,0.46155
40.58800,-0.00987,338.24174,338.24173,2.41601,-0.00024