File: raw_data/mechanical_tests_Instron_data/3DP_Skin_0035_Horizontal_3.is_tens_RawData/Specimen_RawData_1.csv
Dimension : Area,0.42000,cm^2

Time,Load,Extension,Tensile extension,Tensile strain,Tensile stress
(sec),(N),(mm),(mm),(mm/mm),(MPa)
0.00000,0.14212,0.00000,0.00000,0.00000,0.00338
0.04000,0.95349,0.06011,0.06011,0.00043,0.02270
0.08000,0.47088,0.26068,0.26068,0.00186,0.01121
0.12000,1.46702,0.59237,0.59237,0.00423,0.03493
0.16000,1.83079,0.98210,0.98210,0.00701,0.04359
0.20000,1.76951,1.38833,1.38833,0.00992,0.04213
0.24000,1.93696,1.80420,1.80420,0.01289,0.04612
0.28000,1.59852,2.22629,2.22629,0.01590,0.03806
0.32000,1.85389,2.64710,2.64710,0.01891,0.04414
0.36000,1.31410,3.00948,3.00948,0.02150,0.03129
0.40000,1.05724,3.33702,3.33702,0.02384,0.02517
0.44000,1.29025,3.67119,3.67119,0.02622,0.03072
0.48000,1.41282,4.00754,4.00754,0.02863,0.03364
0.52000,1.22506,4.34135,4.34135,0.03101,0.02917
0.56000,1.53836,4.67475,4.67475,0.03339,0.03663
0.60000,1.80677,5.00815,5.00815,0.03577,0.04302
0.64000,2.04835,5.34171,5.34171,0.03816,0.04877
0.68000,1.73710,5.67493,5.67493,0.04054,0.04136
0.72000,1.82055,6.00841,6.00841,0.04292,0.04335
0.76000,1.96490,6.34162,6.34162,0.04530,0.04678
0.80000,1.83582,6.67510,6.67510,0.04768,0.04371
0.84000,1.91275,7.00834,7.00835,0.05006,0.04554
0.88000,1.60206,7.34164,7.34164,0.05244,0.03814
0.92000,1.70488,7.67504,7.67504,0.05482,0.04059
0.96000,1.81105,8.00828,8.00828,0.05720,0.04312
1.00000,1.76057,8.34179,8.34179,0.05958,0.04192
1.04000,1.82949,8.67490,8.67490,0.06196,0.04356
1.08000,1.76895,9.00841,9.00841,0.06435,0.04212
1.12000,1.67955,9.34157,9.34157,0.06673,0.03999
1.16000,1.37053,9.67505,9.67505,0.06911,0.03263
1.20000,1.22190,10.00837,10.00837,0.07149,0.02909
1.24000,1.64025,10.34167,10.34167,0.07387,0.03905
1.28000,1.85817,10.67507,10.67507,0.07625,0.04424
1.32000,2.12695,11.00828,11.00828,0.07863,0.05064
1.36000,1.84365,11.34182,11.34182,0.08101,0.04390
1.40000,2.08393,11.67490,11.67490,0.08339,0.04962
1.44000,1.69501,12.00846,12.00846,0.08577,0.04036
1.48000,1.77976,12.34159,12.34159,0.08815,0.04238
1.52000,1.67545,12.67507,12.67508,0.09054,0.03989
1.56000,1.82875,13.00837,13.00837,0.09292,0.04354
1.60000,1.30981,13.34158,13.34158,0.09530,0.03119
1.64000,1.55326,13.67507,13.67507,0.09768,0.03698
1.68000,1.88071,14.00825,14.00825,0.10006,0.04478
1.72000,2.10330,14.34176,14.34176,0.10244,0.05008
1.76000,1.82670,14.67495,14.67495,0.10482,0.04349
1.80000,1.78199,15.00840,15.00840,0.10720,0.04243
1.84000,2.19569,15.34162,15.34162,0.10958,0.05228
1.88000,2.01687,15.67505,15.67505,0.11196,0.04802
1.92000,1.74977,16.00834,16.00834,0.11435,0.04166
1.96000,1.86712,16.34171,16.34171,0.11673,0.04446
2.00000,2.11038,16.67509,16.67509,0.11911,0.05025
2.04000,2.16216,17.00825,17.00825,0.12149,0.05148
2.08000,1.79522,17.34176,17.34176,0.12387,0.04274
2.12000,1.74008,17.67495,17.67495,0.12625,0.04143
2.16000,1.65533,18.00843,18.00843,0.12863,0.03941
2.20000,1.77268,18.34159,18.34159,0.13101,0.04221
2.24000,1.83675,18.67505,18.67505,0.13339,0.04373
2.28000,2.21059,19.00834,19.00834,0.13577,0.05263
2.32000,2.07219,19.34166,19.34166,0.13815,0.04934
2.36000,2.35606,19.67506,19.67506,0.14054,0.05610
2.40000,2.04779,20.00820,20.00820,0.14292,0.04876
2.44000,2.00532,20.34176,20.34176,0.14530,0.04775
2.48000,1.74586,20.67489,20.67489,0.14768,0.04157
2.52000,1.90120,21.00851,21.00851,0.15006,0.04527
2.56000,1.66334,21.34162,21.34162,0.15244,0.03960
2.60000,1.96993,21.67507,21.67507,0.15482,0.04690
2.64000,1.88015,22.00831,22.00831,0.15720,0.04477
2.68000,1.66409,22.34163,22.34163,0.15958,0.03962
2.72000,1.93007,22.67514,22.67514,0.16197,0.04595
2.76000,1.57822,23.00825,23.00825,0.16434,0.03758
2.80000,1.90884,23.34176,23.34175,0.16673,0.04545
2.84000,1.86209,23.67492,23.67492,0.16911,0.04434
2.88000,2.15955,24.00843,24.00843,0.17149,0.05142
2.92000,2.20183,24.34161,24.34161,0.17387,0.05242
2.96000,1.73170,24.67499,24.67499,0.17625,0.04123
3.00000,1.92020,25.00831,25.00831,0.17863,0.04572
3.04000,1.64174,25.34163,25.34163,0.18101,0.03909
3.08000,1.99154,25.67511,25.67511,0.18339,0.04742
3.12000,1.98092,26.00833,26.00833,0.18577,0.04716
3.16000,2.00141,26.34181,26.34181,0.18816,0.04765
3.20000,2.32905,26.67489,26.67489,0.19053,0.05545
3.24000,1.97552,27.00843,27.00842,0.19292,0.04704
3.28000,1.77156,27.34167,27.34167,0.19530,0.04218
3.32000,1.75573,27.67504,27.67504,0.19768,0.04180
3.36000,1.82763,28.00836,28.00836,0.20006,0.04351
3.40000,1.45622,28.34160,28.34160,0.20244,0.03467
3.44000,1.34204,28.67501,28.67500,0.20482,0.03195
3.48000,1.39195,29.00830,29.00830,0.20720,0.03314
3.52000,1.59051,29.34176,29.34176,0.20958,0.03787
3.56000,1.53370,29.67489,29.67489,0.21196,0.03652
3.60000,1.43107,30.00837,30.00837,0.21435,0.03407
3.64000,1.70618,30.34161,30.34161,0.21673,0.04062
3.68000,1.66669,30.67512,30.67512,0.21911,0.03968
3.72000,1.73636,31.00839,31.00839,0.22149,0.04134
3.76000,1.44895,31.34163,31.34163,0.22387,0.03450
3.80000,1.56928,31.67508,31.67508,0.22625,0.03736
3.84000,1.87233,32.00827,32.00827,0.22863,0.04458
3.88000,1.59778,32.34180,32.34180,0.23101,0.03804
3.92000,1.79168,32.67491,32.67491,0.23339,0.04266
3.96000,1.76374,33.00840,33.00840,0.23577,0.04199
4.00000,1.64658,33.34161,33.34161,0.23815,0.03920
4.04000,1.51265,33.67504,33.67504,0.24054,0.03602
4.08000,1.34464,34.00831,34.00830,0.24292,0.03202
4.12000,1.31801,34.34160,34.34160,0.24530,0.03138
4.16000,1.55717,34.67506,34.67506,0.24768,0.03708
4.20000,1.52495,35.00827,35.00827,0.25006,0.03631
4.24000,1.75890,35.34183,35.34183,0.25244,0.04188
4.28000,1.76132,35.67494,35.67493,0.25482,0.04194
4.32000,2.02730,36.00845,36.00845,0.25720,0.04827
4.36000,1.32062,36.34161,36.34161,0.25958,0.03144
4.40000,1.96453,36.67504,36.67504,0.26196,0.04677
4.44000,2.10050,37.00836,37.00836,0.26435,0.05001
4.48000,1.81422,37.34168,37.34167,0.26673,0.04320
4.52000,1.99005,37.67508,37.67508,0.26911,0.04738
4.56000,1.87568,38.00827,38.00827,0.27149,0.04466
4.60000,2.08057,38.34173,38.34172,0.27387,0.04954
4.64000,2.27541,38.67494,38.67494,0.27625,0.05418
4.68000,1.78143,39.00842,39.00842,0.27863,0.04242
4.72000,1.84346,39.34158,39.34158,0.28101,0.04389
4.76000,2.18097,39.67504,39.67504,0.28339,0.05193
4.80000,1.92914,40.00836,40.00836,0.28577,0.04593
4.84000,1.91461,40.34170,40.34170,0.28816,0.04559
4.88000,2.05133,40.67508,40.67508,0.29054,0.04884
4.92000,2.02730,41.00824,41.00824,0.29292,0.04827
4.96000,2.09156,41.34175,41.34175,0.29530,0.04980
5.00000,2.16197,41.67494,41.67494,0.29768,0.05148
5.04000,2.08430,42.00847,42.00847,0.30006,0.04963
5.08000,2.07089,42.34161,42.34161,0.30244,0.04931
5.12000,2.21357,42.67503,42.67503,0.30482,0.05270
5.16000,2.16346,43.00833,43.00833,0.30720,0.05151
5.20000,2.12584,43.34168,43.34167,0.30958,0.05062
5.24000,2.31024,43.67508,43.67508,0.31196,0.05501
5.28000,2.25008,44.00826,44.00826,0.31434,0.05357
5.32000,2.10796,44.34177,44.34177,0.31673,0.05019
5.36000,2.38065,44.67488,44.67488,0.31911,0.05668
5.40000,2.28342,45.00850,45.00850,0.32149,0.05437
5.44000,2.43168,45.34161,45.34161,0.32387,0.05790
5.48000,2.38307,45.67503,45.67503,0.32625,0.05674
5.52000,2.33874,46.00838,46.00838,0.32863,0.05568
5.56000,2.28938,46.34165,46.34165,0.33101,0.05451
5.60000,2.82880,46.67510,46.67510,0.33339,0.06735
5.64000,2.65427,47.00826,47.00826,0.33577,0.06320
5.68000,2.75616,47.34175,47.34175,0.33816,0.06562
5.72000,2.51122,47.67491,47.67491,0.34054,0.05979
5.76000,2.62316,48.00842,48.00842,0.34292,0.06246
5.80000,2.70922,48.34163,48.34163,0.34530,0.06451
5.84000,2.95769,48.67508,48.67508,0.34768,0.07042
5.88000,3.15160,49.00833,49.00833,0.35006,0.07504
5.92000,2.76379,49.34162,49.34162,0.35244,0.06580
5.96000,2.94466,49.67505,49.67505,0.35482,0.07011
6.00000,2.70084,50.00829,50.00829,0.35720,0.06431
6.04000,2.96645,50.34180,50.34180,0.35958,0.07063
6.08000,2.94782,50.67491,50.67491,0.36196,0.07019
6.12000,3.14750,51.00839,51.00838,0.36435,0.07494
6.16000,2.95024,51.34163,51.34163,0.36673,0.07024
6.20000,2.88952,51.67506,51.67506,0.36911,0.06880
6.24000,3.39616,52.00835,52.00835,0.37149,0.08086
6.28000,3.19704,52.34165,52.34165,0.37387,0.07612
6.32000,2.73567,52.67505,52.67505,0.37625,0.06513
6.36000,2.76417,53.00832,53.00832,0.37863,0.06581
6.40000,3.23802,53.34180,53.34180,0.38101,0.07710
6.44000,3.04170,53.67491,53.67491,0.38339,0.07242
6.48000,3.22033,54.00841,54.00841,0.38577,0.07667
6.52000,3.18736,54.34157,54.34157,0.38815,0.07589
6.56000,3.37735,54.67508,54.67508,0.39054,0.08041
6.60000,3.18438,55.00838,55.00838,0.39292,0.07582
6.64000,3.51425,55.34159,55.34159,0.39530,0.08367
6.68000,3.11602,55.67505,55.67505,0.39768,0.07419
6.72000,2.82321,56.00824,56.00824,0.40006,0.06722
6.76000,2.83662,56.34182,56.34182,0.40244,0.06754
6.80000,3.42131,56.67495,56.67495,0.40482,0.08146
6.84000,3.17115,57.00841,57.00841,0.40720,0.07550
6.88000,3.49693,57.34163,57.34163,0.40958,0.08326
6.92000,3.37102,57.67508,57.67508,0.41196,0.08026
6.96000,3.51463,58.00838,58.00838,0.41435,0.08368
7.00000,3.59062,58.34164,58.34164,0.41673,0.08549
7.04000,3.49674,58.67507,58.67507,0.41911,0.08326
7.08000,3.18903,59.00823,59.00823,0.42149,0.07593
7.12000,3.40007,59.34177,59.34177,0.42387,0.08095
7.16000,3.37847,59.67493,59.67493,0.42625,0.08044
7.20000,3.50047,60.00841,60.00841,0.42863,0.08334
7.24000,3.82364,60.34159,60.34159,0.43101,0.09104
7.28000,3.70704,60.67502,60.67502,0.43339,0.08826
7.32000,3.89852,61.00838,61.00838,0.43577,0.09282
7.36000,3.74764,61.34169,61.34169,0.43815,0.08923
7.40000,3.86499,61.67507,61.67507,0.44054,0.09202
7.44000,4.43310,62.00831,62.00831,0.44292,0.10555
7.48000,4.04213,62.34171,62.34171,0.44530,0.09624
7.52000,3.96799,62.67493,62.67493,0.44768,0.09448
7.56000,3.89796,63.00849,63.00849,0.45006,0.09281
7.60000,4.12408,63.34162,63.34162,0.45244,0.09819
7.64000,4.20939,63.67505,63.67505,0.45482,0.10022
7.68000,4.44874,64.00829,64.00829,0.45720,0.10592
7.72000,4.95352,64.34163,64.34164,0.45958,0.11794
7.76000,4.66108,64.67507,64.67507,0.46196,0.11098
7.80000,4.76409,65.00825,65.00826,0.46434,0.11343
7.84000,4.64544,65.34177,65.34177,0.46673,0.11061
7.88000,4.54001,65.67493,65.67493,0.46911,0.10810
7.92000,5.03138,66.00846,66.00846,0.47149,0.11979
7.96000,4.23361,66.34165,66.34165,0.47387,0.10080
8.00000,4.71808,66.67508,66.67508,0.47625,0.11234
8.04000,4.97326,67.00832,67.00832,0.47863,0.11841
8.08000,4.95221,67.34169,67.34169,0.48101,0.11791
8.12000,4.73261,67.67513,67.67513,0.48339,0.11268
8.16000,4.71529,68.00822,68.00822,0.48577,0.11227
8.20000,4.78234,68.34177,68.34177,0.48816,0.11387
8.24000,5.07459,68.67487,68.67487,0.49053,0.12082
8.28000,4.81810,69.00843,69.00843,0.49292,0.11472
8.32000,4.72926,69.34162,69.34162,0.49530,0.11260
8.36000,4.85480,69.67505,69.67505,0.49768,0.11559
8.40000,4.71529,70.00837,70.00837,0.50006,0.11227
8.44000,4.43272,70.34163,70.34163,0.50244,0.10554
8.48000,4.82667,70.67506,70.67506,0.50482,0.11492
8.52000,4.84586,71.00825,71.00826,0.50720,0.11538
8.56000,4.80246,71.34179,71.34179,0.50958,0.11434
8.60000,5.08837,71.67495,71.67494,0.51196,0.12115
8.64000,4.75738,72.00846,72.00846,0.51435,0.11327
8.68000,4.48059,72.34159,72.34159,0.51673,0.10668
8.72000,4.87044,72.67507,72.67507,0.51911,0.11596
8.76000,4.68399,73.00834,73.00835,0.52149,0.11152
8.80000,4.71901,73.34163,73.34164,0.52387,0.11236
8.84000,5.11836,73.67506,73.67506,0.52625,0.12187
8.88000,5.09080,74.00831,74.00831,0.52863,0.12121
8.92000,5.08428,74.34177,74.34177,0.53101,0.12105
8.96000,4.87864,74.67493,74.67493,0.53339,0.11616
9.00000,4.73633,75.00841,75.00842,0.53577,0.11277
9.04000,4.93266,75.34162,75.34162,0.53815,0.11744
9.08000,5.03752,75.67510,75.67509,0.54054,0.11994
9.12000,4.83897,76.00834,76.00833,0.54292,0.11521
9.16000,4.53722,76.34167,76.34167,0.54530,0.10803
9.20000,4.22709,76.67506,76.67506,0.54768,0.10064
9.24000,4.71268,77.00831,77.00831,0.55006,0.11221
9.28000,4.62644,77.34184,77.34184,0.55244,0.11015
9.32000,4.89522,77.67492,77.67492,0.55482,0.11655
9.36000,4.83859,78.00843,78.00842,0.55720,0.11520
9.40000,4.75720,78.34159,78.34158,0.55958,0.11327
9.44000,4.64618,78.67507,78.67507,0.56196,0.11062
9.48000,5.02113,79.00839,79.00838,0.56435,0.11955
9.52000,5.05764,79.34158,79.34158,0.56673,0.12042
9.56000,4.83505,79.67506,79.67506,0.56911,0.11512
9.60000,5.22044,80.00828,80.00828,0.57149,0.12430
9.64000,5.27538,80.34178,80.34178,0.57387,0.12560
9.68000,5.13326,80.67494,80.67494,0.57625,0.12222
9.72000,4.98258,81.00840,81.00840,0.57863,0.11863
9.76000,5.08595,81.34161,81.34161,0.58101,0.12109
9.80000,5.25787,81.67504,81.67504,0.58339,0.12519
9.84000,5.31748,82.00839,82.00838,0.58577,0.12661
9.88000,5.41937,82.34171,82.34171,0.58816,0.12903
9.92000,5.38006,82.67509,82.67508,0.59054,0.12810
9.96000,5.39757,83.00822,83.00822,0.59292,0.12851
10.00000,5.29476,83.34176,83.34176,0.59530,0.12607
10.04000,5.09042,83.67494,83.67494,0.59768,0.12120
10.08000,5.60489,84.00845,84.00845,0.60006,0.13345
10.12000,5.59781,84.34164,84.34164,0.60244,0.13328
10.16000,5.83883,84.67499,84.67499,0.60482,0.13902
10.20000,5.59725,85.00831,85.00832,0.60720,0.13327
10.24000,5.62910,85.34168,85.34168,0.60958,0.13403
10.28000,5.68572,85.67506,85.67506,0.61196,0.13537
10.32000,5.85113,86.00827,86.00827,0.61434,0.13931
10.36000,6.06887,86.34176,86.34176,0.61673,0.14450
10.40000,5.81909,86.67494,86.67493,0.61911,0.13855
10.44000,5.21000,87.00850,87.00850,0.62149,0.12405
10.48000,5.65518,87.34164,87.34164,0.62387,0.13465
10.52000,5.88987,87.67504,87.67503,0.62625,0.14024
10.56000,5.88037,88.00828,88.00829,0.62863,0.14001
10.60000,5.66952,88.34166,88.34166,0.63101,0.13499
10.64000,5.62202,88.67511,88.67511,0.63339,0.13386
10.68000,5.67194,89.00827,89.00827,0.63577,0.13505
10.72000,6.04130,89.34172,89.34172,0.63816,0.14384
10.76000,5.96475,89.67488,89.67488,0.64053,0.14202
10.80000,5.89211,90.00842,90.00842,0.64292,0.14029
10.84000,5.77513,90.34161,90.34161,0.64530,0.13750
10.88000,5.87478,90.67507,90.67508,0.64768,0.13988
10.92000,5.60340,91.00836,91.00836,0.65006,0.13341
10.96000,6.02379,91.34166,91.34166,0.65244,0.14342
11.00000,6.29872,91.67514,91.67513,0.65482,0.14997
11.04000,6.04782,92.00826,92.00826,0.65720,0.14400
11.08000,6.50715,92.34178,92.34177,0.65958,0.15493
11.12000,6.49784,92.67492,92.67492,0.66196,0.15471
11.16000,6.71968,93.00845,93.00845,0.66435,0.15999
11.20000,7.27344,93.34163,93.34163,0.66673,0.17318
11.24000,7.16075,93.67504,93.67503,0.66911,0.17049
11.28000,7.33603,94.00833,94.00833,0.67149,0.17467
11.32000,7.56029,94.34160,94.34161,0.67387,0.18001
11.36000,7.26227,94.67505,94.67504,0.67625,0.17291
11.40000,7.29114,95.00833,95.00833,0.67863,0.17360
11.44000,7.23507,95.34181,95.34180,0.68101,0.17226
11.48000,7.57873,95.67494,95.67493,0.68339,0.18045
11.52000,7.42488,96.00845,96.00845,0.68577,0.17678
11.56000,7.01509,96.34161,96.34161,0.68815,0.16703
11.60000,7.35950,96.67512,96.67512,0.69054,0.17523
11.64000,7.46790,97.00836,97.00836,0.69292,0.17781
11.68000,7.54949,97.34166,97.34166,0.69530,0.17975
11.72000,7.45822,97.67505,97.67505,0.69768,0.17758
11.76000,7.73612,98.00826,98.00826,0.70006,0.18419
11.80000,7.64988,98.34178,98.34178,0.70244,0.18214
11.84000,7.89110,98.67494,98.67494,0.70482,0.18788
11.88000,7.84025,99.00841,99.00842,0.70720,0.18667
11.92000,8.04625,99.34158,99.34158,0.70958,0.19158
11.96000,8.08220,99.67506,99.67506,0.71196,0.19243
12.00000,8.22395,100.00836,100.00836,0.71435,0.19581
12.04000,7.91177,100.34166,100.34165,0.71673,0.18838
12.08000,8.41506,100.67505,100.67505,0.71911,0.20036
12.12000,7.92667,101.00826,101.00826,0.72149,0.18873
12.16000,7.99075,101.34185,101.34185,0.72387,0.19026
12.20000,8.28523,101.67493,101.67493,0.72625,0.19727
12.24000,7.95927,102.00841,102.00842,0.72863,0.18951
12.28000,8.07997,102.34161,102.34161,0.73101,0.19238
12.32000,8.08537,102.67500,102.67500,0.73339,0.19251
12.36000,7.83242,103.00838,103.00837,0.73577,0.18649
12.40000,7.82795,103.34165,103.34165,0.73815,0.18638
12.44000,8.36141,103.67508,103.67509,0.74054,0.19908
12.48000,7.95983,104.00826,104.00826,0.74292,0.18952
12.52000,8.32211,104.34177,104.34177,0.74530,0.19815
12.56000,8.18893,104.67488,104.67488,0.74768,0.19497
12.60000,7.82553,105.00841,105.00842,0.75006,0.18632
12.64000,7.96132,105.34165,105.34165,0.75244,0.18956
12.68000,8.16286,105.67506,105.67506,0.75482,0.19435
12.72000,8.31485,106.00838,106.00838,0.75720,0.19797
12.76000,7.94586,106.34167,106.34168,0.75958,0.18919
12.80000,8.31038,106.67510,106.67511,0.76197,0.19787
12.84000,8.25226,107.00826,107.00827,0.76434,0.19648
12.88000,8.09208,107.34177,107.34177,0.76673,0.19267
12.92000,8.25096,107.67496,107.67496,0.76911,0.19645
12.96000,8.15969,108.00844,108.00844,0.77149,0.19428
13.00000,8.08053,108.34160,108.34160,0.77387,0.19239
13.04000,8.19452,108.67503,108.67503,0.77625,0.19511
13.08000,8.57972,109.00829,109.00829,0.77863,0.20428
13.12000,8.29957,109.34165,109.34164,0.78101,0.19761
13.16000,8.18595,109.67509,109.67509,0.78339,0.19490
13.20000,8.45250,110.00825,110.00826,0.78577,0.20125
13.24000,8.33999,110.34177,110.34177,0.78816,0.19857
13.28000,8.02167,110.67491,110.67491,0.79054,0.19099
13.32000,8.32807,111.00849,111.00849,0.79292,0.19829
13.36000,8.04439,111.34163,111.34163,0.79530,0.19153
13.40000,8.12057,111.67506,111.67506,0.79768,0.19335
13.44000,8.35080,112.00838,112.00838,0.80006,0.19883
13.48000,7.99075,112.34167,112.34167,0.80244,0.19026
13.52000,8.32062,112.67513,112.67513,0.80482,0.19811
13.56000,8.60598,113.00829,113.00829,0.80720,0.20490
13.60000,8.42661,113.34168,113.34168,0.80958,0.20063
13.64000,8.37315,113.67491,113.67490,0.81196,0.19936
13.68000,8.44169,114.00847,114.00847,0.81435,0.20099
13.72000,8.35750,114.34166,114.34166,0.81673,0.19899
13.76000,8.75629,114.67505,114.67505,0.81911,0.20848
13.80000,8.22134,115.00832,115.00832,0.82149,0.19575
13.84000,8.43685,115.34162,115.34162,0.82387,0.20088
13.88000,8.38023,115.67513,115.67513,0.82625,0.19953
13.92000,8.42214,116.00829,116.00829,0.82863,0.20053
13.96000,8.35191,116.34179,116.34179,0.83101,0.19886
14.00000,8.56332,116.67493,116.67493,0.83339,0.20389
14.04000,8.91052,117.00841,117.00842,0.83577,0.21216
14.08000,8.87606,117.34165,117.34165,0.83815,0.21133
14.12000,8.34372,117.67506,117.67506,0.84054,0.19866
14.16000,8.41115,118.00835,118.00835,0.84292,0.20027
14.20000,8.35583,118.34167,118.34167,0.84530,0.19895
14.24000,8.40779,118.67501,118.67501,0.84768,0.20019
14.28000,8.68291,119.00831,119.00831,0.85006,0.20674
14.32000,8.39513,119.34180,119.34180,0.85244,0.19988
14.36000,8.45809,119.67488,119.67488,0.85482,0.20138
14.40000,8.25021,120.00841,120.00841,0.85720,0.19643
14.44000,8.43070,120.34163,120.34163,0.85958,0.20073
14.48000,8.71327,120.67510,120.67510,0.86197,0.20746
14.52000,8.67546,121.00837,121.00837,0.86435,0.20656
14.56000,8.80938,121.34167,121.34167,0.86673,0.20975
14.60000,8.42232,121.67501,121.67502,0.86911,0.20053
14.64000,8.67452,122.00828,122.00828,0.87149,0.20654
14.68000,8.73376,122.34184,122.34184,0.87387,0.20795
14.72000,8.39122,122.67498,122.67498,0.87625,0.19979
14.76000,8.43611,123.00844,123.00844,0.87863,0.20086
14.80000,8.68607,123.34157,123.34157,0.88101,0.20681
14.84000,8.62926,123.67507,123.67507,0.88339,0.20546
14.88000,8.49888,124.00835,124.00835,0.88577,0.20235
14.92000,8.68551,124.34164,124.34164,0.88815,0.20680
14.96000,8.75276,124.67507,124.67507,0.89054,0.20840
15.00000,8.54190,125.00821,125.00821,0.89292,0.20338
15.04000,8.92729,125.34182,125.34182,0.89530,0.21255
15.08000,8.59424,125.67496,125.67496,0.89768,0.20462
15.12000,8.79802,126.00843,126.00843,0.90006,0.20948
15.16000,8.54675,126.34162,126.34161,0.90244,0.20349
15.20000,8.33310,126.67505,126.67505,0.90482,0.19841
15.24000,8.37278,127.00839,127.00839,0.90720,0.19935
15.28000,8.74102,127.34170,127.34170,0.90958,0.20812
15.32000,8.76486,127.67509,127.67509,0.91196,0.20869
15.36000,8.68179,128.00825,128.00826,0.91434,0.20671
15.40000,8.60021,128.34174,128.34174,0.91673,0.20477
15.44000,8.73413,128.67495,128.67496,0.91911,0.20796
15.48000,9.15714,129.00846,129.00847,0.92149,0.21803
15.52000,9.06959,129.34160,129.34160,0.92387,0.21594
15.56000,8.77287,129.67502,129.67502,0.92625,0.20888
15.60000,8.96864,130.00835,130.00835,0.92863,0.21354
15.64000,8.67378,130.34161,130.34161,0.93101,0.20652
15.68000,9.12976,130.67511,130.67511,0.93339,0.21738
15.72000,8.87420,131.00830,131.00830,0.93577,0.21129
15.76000,9.11970,131.34180,131.34180,0.93816,0.21714
15.80000,9.14708,131.67496,131.67496,0.94054,0.21779
15.84000,9.01092,132.00846,132.00845,0.94292,0.21455
15.88000,9.09530,132.34162,132.34161,0.94530,0.21655
15.92000,8.85502,132.67504,132.67503,0.94768,0.21083
15.96000,8.62628,133.00830,133.00830,0.95006,0.20539
16.00000,9.21246,133.34170,133.34169,0.95244,0.21934
16.04000,9.12100,133.67509,133.67509,0.95482,0.21717
16.08000,8.93101,134.00825,134.00826,0.95720,0.21264
16.12000,8.94349,134.34178,134.34178,0.95958,0.21294
16.16000,9.23220,134.67483,134.67484,0.96196,0.21981
16.20000,9.22419,135.00846,135.00847,0.96435,0.21962
16.24000,9.33912,135.34166,135.34166,0.96673,0.22236
16.28000,8.98559,135.67502,135.67502,0.96911,0.21394
16.32000,9.20035,136.00837,136.00838,0.97149,0.21906
16.36000,9.48142,136.34168,136.34167,0.97387,0.22575
16.40000,9.51998,136.67511,136.67511,0.97625,0.22667
16.44000,9.40599,137.00830,137.00830,0.97863,0.22395
16.48000,9.56915,137.34178,137.34178,0.98101,0.22784
16.52000,9.25343,137.67492,137.67491,0.98339,0.22032
16.56000,9.42256,138.00842,138.00842,0.98577,0.22435
16.60000,9.37320,138.34164,138.34164,0.98815,0.22317
16.64000,9.49167,138.67501,138.67500,0.99054,0.22599
16.68000,9.72599,139.00830,139.00830,0.99292,0.23157
16.72000,9.57232,139.34163,139.34163,0.99530,0.22791
16.76000,9.25679,139.67509,139.67509,0.99768,0.22040
16.80000,9.66322,140.00830,140.00829,1.00006,0.23008
16.84000,9.31099,140.34178,140.34178,1.00244,0.22169
16.88000,9.59765,140.67494,140.67494,1.00482,0.22852
16.92000,9.89847,141.00842,141.00842,1.00720,0.23568
16.96000,9.53116,141.34166,141.34164,1.00958,0.22693
17.00000,9.86159,141.67509,141.67509,1.01196,0.23480
17.04000,9.87928,142.00835,142.00835,1.01435,0.23522
17.08000,9.59355,142.34168,142.34167,1.01673,0.22842
17.12000,9.74461,142.67506,142.67506,1.01911,0.23201
17.16000,9.66117,143.00827,143.00827,1.02149,0.23003
17.20000,9.84408,143.34178,143.34178,1.02387,0.23438
17.24000,10.06927,143.67489,143.67490,1.02625,0.23974
17.28000,9.80459,144.00840,144.00841,1.02863,0.23344
17.32000,9.23108,144.34154,144.34154,1.03101,0.21979
17.36000,9.80292,144.67504,144.67503,1.03339,0.23340
17.40000,9.95137,145.00839,145.00839,1.03577,0.23694
17.44000,9.57903,145.34166,145.34166,1.03815,0.22807
17.48000,9.69619,145.67509,145.67511,1.04054,0.23086
17.52000,10.16073,146.00830,146.00830,1.04292,0.24192
17.56000,10.45167,146.34184,146.34184,1.04530,0.24885
17.60000,10.00520,146.67497,146.67497,1.04768,0.23822
17.64000,9.70718,147.00842,147.00842,1.05006,0.23112
17.68000,10.24194,147.34155,147.34155,1.05244,0.24386
17.72000,10.27547,147.67509,147.67509,1.05482,0.24465
17.76000,10.27361,148.00838,148.00838,1.05720,0.24461
17.80000,10.25442,148.34166,148.34166,1.05958,0.24415
17.84000,9.93088,148.67506,148.67505,1.06196,0.23645
17.88000,10.33135,149.00822,149.00821,1.06434,0.24598
17.92000,10.18234,149.34175,149.34175,1.06673,0.24244
17.96000,9.99365,149.67494,149.67494,1.06911,0.23794
18.00000,10.04562,150.00845,150.00845,1.07149,0.23918
18.04000,10.27603,150.34167,150.34166,1.07387,0.24467
18.08000,10.64707,150.67501,150.67500,1.07625,0.25350
18.12000,10.28217,151.00839,151.00839,1.07863,0.24481
18.16000,10.36972,151.34172,151.34172,1.08101,0.24690
18.20000,10.65377,151.67509,151.67509,1.08339,0.25366
18.24000,10.74020,152.00830,152.00830,1.08577,0.25572
18.28000,10.53065,152.34177,152.34177,1.08816,0.25073
18.32000,10.50737,152.67491,152.67491,1.09054,0.25018
18.36000,10.86164,153.00847,153.00847,1.09292,0.25861
18.40000,11.00451,153.34162,153.34163,1.09530,0.26201
18.44000,10.83370,153.67504,153.67503,1.09768,0.25795
18.48000,10.85270,154.00833,154.00833,1.10006,0.25840
18.52000,10.72828,154.34165,154.34164,1.10244,0.25544
18.56000,10.81508,154.67511,154.67511,1.10482,0.25750
18.60000,10.88250,155.00827,155.00827,1.10720,0.25911
18.64000,10.74057,155.34175,155.34175,1.10958,0.25573
18.68000,10.91491,155.67491,155.67491,1.11196,0.25988
18.72000,11.00469,156.00850,156.00850,1.11435,0.26202
18.76000,10.62322,156.34166,156.34166,1.11673,0.25293
18.80000,10.64930,156.67510,156.67509,1.11911,0.25355
18.84000,10.51202,157.00830,157.00830,1.12149,0.25029
18.88000,10.62453,157.34165,157.34166,1.12387,0.25296
18.92000,10.71934,157.67514,157.67514,1.12625,0.25522
18.96000,11.15259,158.00827,158.00827,1.12863,0.26554
19.00000,10.79533,158.34177,158.34177,1.13101,0.25703
19.04000,10.81135,158.67491,158.67491,1.13339,0.25741
19.08000,10.95850,159.00842,159.00841,1.13577,0.26092
19.12000,10.96912,159.34166,159.34167,1.13815,0.26117
19.16000,11.13117,159.67504,159.67503,1.14054,0.26503
19.20000,11.13545,160.00834,160.00833,1.14292,0.26513
19.24000,11.57038,160.34165,160.34166,1.14530,0.27549
19.28000,11.03859,160.67511,160.67511,1.14768,0.26282
19.32000,11.24851,161.00832,161.00832,1.15006,0.26782
19.36000,11.32805,161.34178,161.34178,1.15244,0.26972
19.40000,11.10677,161.67494,161.67494,1.15482,0.26445
19.44000,11.49196,162.00844,162.00842,1.15720,0.27362
19.48000,11.54914,162.34166,162.34166,1.15958,0.27498
19.52000,11.38430,162.67508,162.67508,1.16196,0.27105
19.56000,11.60745,163.00835,163.00835,1.16435,0.27637
19.60000,11.91422,163.34161,163.34160,1.16673,0.28367
19.64000,11.74975,163.67507,163.67508,1.16911,0.27976
19.68000,11.61098,164.00827,164.00827,1.17149,0.27645
19.72000,11.50947,164.34172,164.34171,1.17387,0.27404
19.76000,11.67748,164.67493,164.67493,1.17625,0.27804
19.80000,12.05150,165.00844,165.00844,1.17863,0.28694
19.84000,11.95241,165.34162,165.34161,1.18101,0.28458
19.88000,11.62011,165.67508,165.67506,1.18339,0.27667
19.92000,11.95911,166.00834,166.00835,1.18577,0.28474
19.96000,11.72330,166.34167,166.34167,1.18815,0.27913
20.00000,11.83804,166.67509,166.67509,1.19054,0.28186
20.04000,11.75310,167.00825,167.00824,1.19292,0.27984
20.08000,11.91981,167.34186,167.34187,1.19530,0.28381
20.12000,11.94440,167.67494,167.67494,1.19768,0.28439
20.16000,12.16829,168.00841,168.00842,1.20006,0.28972
20.20000,12.11632,168.34157,168.34157,1.20244,0.28848
20.24000,11.78458,168.67503,168.67505,1.20482,0.28059
20.28000,12.05020,169.00841,169.00841,1.20720,0.28691
20.32000,12.29048,169.34165,169.34166,1.20958,0.29263
20.36000,12.21374,169.67502,169.67503,1.21196,0.29080
20.40000,12.36740,170.00826,170.00826,1.21434,0.29446
20.44000,12.45495,170.34180,170.34180,1.21673,0.29655
20.48000,12.38845,170.67493,170.67493,1.21911,0.29496
20.52000,12.17108,171.00846,171.00845,1.22149,0.28979
20.56000,12.37895,171.34166,171.34166,1.22387,0.29474
20.60000,12.18375,171.67508,171.67508,1.22625,0.29009
20.64000,12.49295,172.00841,172.00841,1.22863,0.29745
20.68000,12.94687,172.34167,172.34169,1.23101,0.30826
20.72000,12.53970,172.67505,172.67505,1.23339,0.29856
20.76000,12.55311,173.00825,173.00826,1.23577,0.29888
20.80000,12.49909,173.34178,173.34180,1.23816,0.29760
20.84000,12.78520,173.67498,173.67496,1.24054,0.30441
20.88000,12.86697,174.00841,174.00841,1.24292,0.30636
20.92000,12.92769,174.34157,174.34157,1.24530,0.30780
20.96000,12.61570,174.67497,174.67497,1.24768,0.30037
21.00000,12.67903,175.00830,175.00830,1.25006,0.30188
21.04000,12.56987,175.34172,175.34172,1.25244,0.29928
21.08000,12.78743,175.67514,175.67514,1.25482,0.30446
21.12000,13.01244,176.00831,176.00832,1.25720,0.30982
21.16000,13.18678,176.34182,176.34183,1.25958,0.31397
21.20000,13.31046,176.67496,176.67496,1.26196,0.31692
21.24000,13.31437,177.00848,177.00847,1.26435,0.31701
21.28000,13.34772,177.34164,177.34164,1.26673,0.31780
21.32000,13.50343,177.67505,177.67505,1.26911,0.32151
21.36000,13.46506,178.00833,178.00833,1.27149,0.32060
21.40000,13.31884,178.34163,178.34163,1.27387,0.31712
21.44000,13.23912,178.67506,178.67506,1.27625,0.31522
21.48000,12.92694,179.00825,179.00826,1.27863,0.30778
21.52000,13.02678,179.34174,179.34174,1.28101,0.31016
21.56000,12.87609,179.67487,179.67487,1.28339,0.30657
21.60000,13.30134,180.00849,180.00848,1.28577,0.31670
21.64000,13.18567,180.34165,180.34164,1.28815,0.31394
21.68000,13.25961,180.67509,180.67509,1.29054,0.31571
21.72000,12.97761,181.00835,181.00835,1.29292,0.30899
21.76000,13.46953,181.34164,181.34164,1.29530,0.32070
21.80000,13.40285,181.67518,181.67517,1.29768,0.31912
21.84000,13.76737,182.00831,182.00832,1.30006,0.32779
21.88000,13.86963,182.34182,182.34183,1.30244,0.33023
21.92000,13.52746,182.67489,182.67490,1.30482,0.32208
21.96000,13.66232,183.00838,183.00838,1.30720,0.32529
22.00000,13.71130,183.34164,183.34164,1.30958,0.32646
22.04000,13.65766,183.67502,183.67500,1.31196,0.32518
22.08000,13.33933,184.00833,184.00835,1.31435,0.31760
22.12000,13.47903,184.34162,184.34161,1.31673,0.32093
22.16000,13.24750,184.67506,184.67508,1.31911,0.31542
22.20000,13.90986,185.00835,185.00836,1.32149,0.33119
22.24000,14.03596,185.34181,185.34181,1.32387,0.33419
22.28000,13.67591,185.67492,185.67493,1.32625,0.32562
22.32000,13.81431,186.00849,186.00847,1.32863,0.32891
22.36000,14.40998,186.34166,186.34166,1.33101,0.34309
22.40000,14.11922,186.67508,186.67508,1.33339,0.33617
22.44000,14.24216,187.00838,187.00838,1.33577,0.33910
22.48000,14.02069,187.34164,187.34163,1.33815,0.33383
22.52000,14.16896,187.67504,187.67505,1.34054,0.33736
22.56000,14.24197,188.00828,188.00827,1.34292,0.33909
22.60000,13.89049,188.34176,188.34175,1.34530,0.33073
22.64000,14.40197,188.67492,188.67491,1.34768,0.34290
22.68000,14.69869,189.00844,189.00845,1.35006,0.34997
22.72000,14.37813,189.34157,189.34158,1.35244,0.34234
22.76000,14.18367,189.67505,189.67505,1.35482,0.33771
22.80000,14.41259,190.00839,190.00839,1.35720,0.34316
22.84000,14.32840,190.34166,190.34166,1.35958,0.34115
22.88000,14.46288,190.67512,190.67509,1.36197,0.34435
22.92000,14.29990,191.00825,191.00826,1.36434,0.34047
22.96000,14.35280,191.34184,191.34184,1.36673,0.34173
23.00000,14.81511,191.67495,191.67494,1.36911,0.35274
23.04000,14.32933,192.00839,192.00839,1.37149,0.34117
23.08000,14.35503,192.34162,192.34161,1.37387,0.34179
23.12000,14.60575,192.67505,192.67505,1.37625,0.34776
23.16000,14.58004,193.00837,193.00838,1.37863,0.34714
23.20000,14.51671,193.34166,193.34166,1.38101,0.34564
23.24000,14.63685,193.67507,193.67508,1.38339,0.34850
23.28000,14.83541,194.00826,194.00827,1.38577,0.35322
23.32000,14.70968,194.34179,194.34180,1.38816,0.35023
23.36000,14.94195,194.67495,194.67496,1.39054,0.35576
23.40000,14.82572,195.00845,195.00845,1.39292,0.35299
23.44000,15.04011,195.34161,195.34163,1.39530,0.35810
23.48000,15.29325,195.67503,195.67503,1.39768,0.36412
23.52000,15.45567,196.00839,196.00839,1.40006,0.36799
23.56000,15.61176,196.34169,196.34169,1.40244,0.37171
23.60000,15.43649,196.67511,196.67511,1.40482,0.36754
23.64000,15.42531,197.00830,197.00830,1.40720,0.36727
23.68000,15.50224,197.34176,197.34177,1.40958,0.36910
23.72000,15.38638,197.67497,197.67497,1.41196,0.36634
23.76000,14.98219,198.00843,198.00844,1.41435,0.35672
23.80000,15.19118,198.34159,198.34160,1.41673,0.36169
23.84000,15.04254,198.67508,198.67508,1.41911,0.35816
23.88000,15.44282,199.00834,199.00835,1.42149,0.36769
23.92000,15.62387,199.34167,199.34167,1.42387,0.37200
23.96000,15.56575,199.67507,199.67506,1.42625,0.37061
24.00000,15.62200,200.00825,200.00826,1.42863,0.37195
24.04000,16.07016,200.34178,200.34178,1.43101,0.38262
24.08000,15.70750,200.67491,200.67491,1.43339,0.37399
24.12000,16.29554,201.00848,201.00848,1.43577,0.38799
24.16000,16.00888,201.34166,201.34164,1.43815,0.38116
24.20000,15.89376,201.67503,201.67502,1.44054,0.37842
24.24000,15.56296,202.00834,202.00833,1.44292,0.37055
24.28000,15.88687,202.34168,202.34167,1.44530,0.37826
24.32000,15.57376,202.67509,202.67509,1.44768,0.37080
24.36000,15.29399,203.00830,203.00830,1.45006,0.36414
24.40000,15.85260,203.34176,203.34177,1.45244,0.37744
24.44000,15.92953,203.67489,203.67490,1.45482,0.37927
24.48000,15.86769,204.00848,204.00850,1.45720,0.37780
24.52000,15.59127,204.34164,204.34164,1.45958,0.37122
24.56000,16.32888,204.67504,204.67503,1.46196,0.38878
24.60000,16.35067,205.00837,205.00836,1.46435,0.38930
24.64000,16.35365,205.34163,205.34163,1.46673,0.38937
24.68000,16.48385,205.67513,205.67513,1.46911,0.39247
24.72000,16.46169,206.00832,206.00832,1.47149,0.39194
24.76000,16.49000,206.34178,206.34177,1.47387,0.39262
24.80000,16.75524,206.67491,206.67491,1.47625,0.39893
24.84000,16.64981,207.00841,207.00841,1.47863,0.39642
24.88000,16.17856,207.34166,207.34166,1.48101,0.38520
24.92000,16.38345,207.67510,207.67509,1.48339,0.39008
24.96000,16.78914,208.00831,208.00832,1.48577,0.39974
25.00000,16.51738,208.34165,208.34166,1.48815,0.39327
25.04000,16.40730,208.67503,208.67503,1.49054,0.39065
25.08000,16.42723,209.00827,209.00827,1.49292,0.39112
25.12000,16.49465,209.34180,209.34178,1.49530,0.39273
25.16000,16.70942,209.67492,209.67493,1.49768,0.39784
25.20000,16.82583,210.00842,210.00841,1.50006,0.40062
25.24000,16.93852,210.34166,210.34167,1.50244,0.40330
25.28000,17.19296,210.67509,210.67508,1.50482,0.40936
25.32000,16.88208,211.00838,211.00838,1.50720,0.40195
25.36000,17.45503,211.34167,211.34167,1.50958,0.41560
25.40000,17.01303,211.67509,211.67509,1.51196,0.40507
25.44000,17.10691,212.00827,212.00829,1.51434,0.40731
25.48000,17.07766,212.34180,212.34180,1.51673,0.40661
25.52000,16.87016,212.67494,212.67494,1.51911,0.40167
25.56000,16.85340,213.00844,213.00842,1.52149,0.40127
25.60000,17.27492,213.34156,213.34157,1.52387,0.41131
25.64000,17.47459,213.67510,213.67509,1.52625,0.41606
25.68000,17.10039,214.00839,214.00839,1.52863,0.40715
25.72000,17.07692,214.34163,214.34163,1.53101,0.40659
25.76000,17.56735,214.67507,214.67508,1.53339,0.41827
25.80000,17.30639,215.00821,215.00821,1.53577,0.41206
25.84000,17.52637,215.34180,215.34180,1.53816,0.41729
25.88000,17.25685,215.67500,215.67500,1.54054,0.41088
25.92000,17.36842,216.00844,216.00844,1.54292,0.41353
25.96000,17.56474,216.34166,216.34166,1.54530,0.41821
26.00000,17.40698,216.67504,216.67503,1.54768,0.41445
26.04000,17.80298,217.00837,217.00836,1.55006,0.42388
26.08000,18.02817,217.34167,217.34167,1.55244,0.42924
26.12000,17.75064,217.67505,217.67505,1.55482,0.42263
26.16000,17.62938,218.00826,218.00827,1.55720,0.41975
26.20000,17.44200,218.34178,218.34178,1.55958,0.41529
26.24000,17.69345,218.67494,218.67494,1.56196,0.42127
26.28000,17.49173,219.00845,219.00845,1.56435,0.41647
26.32000,18.13434,219.34158,219.34158,1.56673,0.43177
26.36000,18.28037,219.67500,219.67500,1.56911,0.43525
26.40000,18.11255,220.00843,220.00842,1.57149,0.43125
26.44000,18.00079,220.34172,220.34172,1.57387,0.42859
26.48000,17.87152,220.67506,220.67506,1.57625,0.42551
26.52000,18.16396,221.00830,221.00830,1.57863,0.43248
26.56000,18.23083,221.34174,221.34175,1.58101,0.43407
26.60000,18.31558,221.67493,221.67493,1.58339,0.43609
26.64000,18.04065,222.00848,222.00848,1.58577,0.42954
26.68000,18.13341,222.34162,222.34161,1.58815,0.43175
26.72000,18.27125,222.67506,222.67506,1.59054,0.43503
26.76000,18.11311,223.00830,223.00830,1.59292,0.43126
26.80000,18.19227,223.34164,223.34164,1.59530,0.43315
26.84000,18.33718,223.67509,223.67509,1.59768,0.43660
26.88000,18.67507,224.00825,224.00826,1.60006,0.44464
26.92000,18.57169,224.34178,224.34178,1.60244,0.44218
26.96000,18.67469,224.67491,224.67491,1.60482,0.44464
27.00000,18.68717,225.00844,225.00844,1.60720,0.44493
27.04000,18.71306,225.34165,225.34164,1.60958,0.44555
27.08000,18.82371,225.67502,225.67502,1.61196,0.44818
27.12000,19.00066,226.00833,226.00833,1.61435,0.45240
27.16000,19.17388,226.34168,226.34167,1.61673,0.45652
27.20000,19.20816,226.67510,226.67509,1.61911,0.45734
27.24000,18.74119,227.00826,227.00826,1.62149,0.44622
27.28000,19.12899,227.34176,227.34175,1.62387,0.45545
27.32000,19.00736,227.67486,227.67487,1.62625,0.45256
27.36000,19.04946,228.00842,228.00842,1.62863,0.45356
27.40000,19.05207,228.34165,228.34166,1.63101,0.45362
27.44000,19.23218,228.67507,228.67508,1.63339,0.45791
27.48000,19.14483,229.00837,229.00836,1.63577,0.45583
27.52000,19.62781,229.34160,229.34160,1.63815,0.46733
27.56000,19.18245,229.67508,229.67508,1.64054,0.45673
27.60000,19.05113,230.00832,230.00832,1.64292,0.45360
27.64000,19.30352,230.34176,230.34177,1.64530,0.45961
27.68000,19.50711,230.67492,230.67493,1.64768,0.46446
27.72000,19.71144,231.00845,231.00845,1.65006,0.46932
27.76000,19.72262,231.34166,231.34166,1.65244,0.46959
27.80000,19.40634,231.67511,231.67511,1.65482,0.46206
27.84000,19.50972,232.00827,232.00827,1.65720,0.46452
27.88000,19.58851,232.34161,232.34161,1.65958,0.46639
27.92000,19.52462,232.67508,232.67508,1.66196,0.46487
27.96000,19.32010,233.00830,233.00830,1.66435,0.46000
28.00000,19.82935,233.34179,233.34180,1.66673,0.47213
28.04000,19.56709,233.67490,233.67490,1.66911,0.46588
28.08000,19.85636,234.00840,234.00841,1.67149,0.47277
28.12000,19.78073,234.34161,234.34161,1.67387,0.47097
28.16000,19.77589,234.67503,234.67503,1.67625,0.47085
28.20000,19.95265,235.00838,235.00838,1.67863,0.47506
28.24000,20.20691,235.34167,235.34167,1.68101,0.48112
28.28000,20.06199,235.67504,235.67503,1.68339,0.47767
28.32000,20.25720,236.00825,236.00826,1.68577,0.48231
28.36000,20.20318,236.34183,236.34183,1.68816,0.48103
28.40000,20.05119,236.67493,236.67494,1.69054,0.47741
28.44000,20.10614,237.00843,237.00844,1.69292,0.47872
28.48000,19.82786,237.34157,237.34157,1.69530,0.47209
28.52000,19.60937,237.67501,237.67502,1.69768,0.46689
28.56000,20.35685,238.00841,238.00841,1.70006,0.48469
28.60000,20.13221,238.34162,238.34163,1.70244,0.47934
28.64000,20.35927,238.67507,238.67506,1.70482,0.48474
28.68000,20.29445,239.00823,239.00822,1.70720,0.48320
28.72000,20.57347,239.34175,239.34175,1.70958,0.48984
28.76000,20.69622,239.67494,239.67494,1.71196,0.49277
28.80000,20.62265,240.00847,240.00847,1.71435,0.49102
28.84000,20.59508,240.34160,240.34160,1.71673,0.49036
28.88000,20.86442,240.67502,240.67502,1.71911,0.49677
28.92000,20.96538,241.00836,241.00836,1.72149,0.49918
28.96000,20.60439,241.34173,241.34174,1.72387,0.49058
29.00000,20.69995,241.67510,241.67509,1.72625,0.49286
29.04000,20.83909,242.00824,242.00824,1.72863,0.49617
29.08000,20.71764,242.34176,242.34177,1.73101,0.49328
29.12000,20.61781,242.67492,242.67493,1.73339,0.49090
29.16000,21.28556,243.00842,243.00842,1.73577,0.50680
29.20000,21.04919,243.34163,243.34163,1.73815,0.50117
29.24000,20.78749,243.67503,243.67503,1.74054,0.49494
29.28000,21.21553,244.00832,244.00832,1.74292,0.50513
29.32000,20.97618,244.34169,244.34169,1.74530,0.49943
29.36000,21.18330,244.67506,244.67505,1.74768,0.50436
29.40000,21.16580,245.00827,245.00827,1.75006,0.50395
29.44000,21.73297,245.34177,245.34177,1.75244,0.51745
29.48000,21.75421,245.67493,245.67493,1.75482,0.51796
29.52000,21.45357,246.00848,246.00848,1.75720,0.51080
29.56000,21.39695,246.34164,246.34164,1.75958,0.50945
29.60000,21.28389,246.67503,246.67503,1.76196,0.50676
29.64000,21.32189,247.00832,247.00833,1.76435,0.50766
29.68000,21.19765,247.34161,247.34161,1.76673,0.50471
29.72000,21.25297,247.67511,247.67511,1.76911,0.50602
29.76000,21.50610,248.00825,248.00826,1.77149,0.51205
29.80000,21.46028,248.34177,248.34177,1.77387,0.51096
29.84000,21.66871,248.67493,248.67493,1.77625,0.51592
29.88000,21.80114,249.00838,249.00838,1.77863,0.51907
29.92000,21.78624,249.34164,249.34164,1.78101,0.51872
29.96000,21.68901,249.67507,249.67506,1.78339,0.51641
30.00000,21.89763,250.00836,250.00836,1.78577,0.52137
30.04000,21.81325,250.34165,250.34164,1.78815,0.51936
30.08000,21.78252,250.67509,250.67509,1.79054,0.51863
30.12000,22.02038,251.00831,251.00830,1.79292,0.52429
30.16000,21.99914,251.34178,251.34178,1.79530,0.52379
30.20000,21.51355,251.67491,251.67491,1.79768,0.51223
30.24000,21.48394,252.00839,252.00839,1.80006,0.51152
30.28000,21.35504,252.34165,252.34164,1.80244,0.50845
30.32000,21.56179,252.67505,252.67505,1.80482,0.51338
30.36000,21.95705,253.00834,253.00833,1.80720,0.52279
30.40000,22.04645,253.34163,253.34163,1.80958,0.52492
30.44000,22.20720,253.67505,253.67505,1.81196,0.52874
30.48000,22.48455,254.00834,254.00833,1.81435,0.53535
30.52000,22.46443,254.34176,254.34177,1.81673,0.53487
30.56000,22.56464,254.67489,254.67490,1.81911,0.53725
30.60000,22.56241,255.00847,255.00847,1.82149,0.53720
30.64000,22.43463,255.34160,255.34160,1.82387,0.53416
30.68000,22.43482,255.67508,255.67508,1.82625,0.53416
30.72000,22.53857,256.00837,256.00836,1.82863,0.53663
30.76000,22.31896,256.34166,256.34164,1.83101,0.53140
30.80000,22.54378,256.67505,256.67505,1.83339,0.53676
30.84000,22.86676,257.00827,257.00827,1.83577,0.54445
30.88000,22.48175,257.34179,257.34180,1.83816,0.53528
30.92000,22.29866,257.67487,257.67487,1.84053,0.53092
30.96000,22.28972,258.00845,258.00845,1.84292,0.53071
31.00000,22.96660,258.34161,258.34161,1.84530,0.54682
31.04000,22.64027,258.67511,258.67511,1.84768,0.53905
31.08000,22.68497,259.00832,259.00833,1.85006,0.54012
31.12000,22.77978,259.34166,259.34167,1.85244,0.54238
31.16000,22.86527,259.67506,259.67505,1.85482,0.54441
31.20000,23.07128,260.00830,260.00830,1.85720,0.54932
31.24000,23.20558,260.34182,260.34183,1.85958,0.55251
31.28000,23.13517,260.67491,260.67490,1.86196,0.55084
31.32000,23.22551,261.00840,261.00839,1.86435,0.55299
31.36000,22.95040,261.34164,261.34164,1.86673,0.54644
31.40000,23.16386,261.67501,261.67502,1.86911,0.55152
31.44000,22.91258,262.00838,262.00839,1.87149,0.54554
31.48000,22.90998,262.34167,262.34167,1.87387,0.54548
31.52000,23.16907,262.67507,262.67508,1.87625,0.55164
31.56000,23.25717,263.00825,263.00824,1.87863,0.55374
31.60000,23.39687,263.34178,263.34177,1.88101,0.55707
31.64000,23.64237,263.67496,263.67496,1.88339,0.56291
31.68000,23.70868,264.00844,264.00842,1.88577,0.56449
31.72000,24.15068,264.34157,264.34158,1.88815,0.57502
31.76000,23.83310,264.67507,264.67508,1.89054,0.56745
31.80000,23.94170,265.00836,265.00836,1.89292,0.57004
31.84000,23.75506,265.34173,265.34174,1.89530,0.56560
31.88000,23.73606,265.67507,265.67508,1.89768,0.56514
31.92000,24.12684,266.00818,266.00818,1.90006,0.57445
31.96000,23.89103,266.34178,266.34180,1.90244,0.56883
32.00000,23.94598,266.67494,266.67496,1.90482,0.57014
32.04000,23.84316,267.00847,267.00845,1.90720,0.56769
32.08000,23.92810,267.34160,267.34161,1.90958,0.56972
32.12000,23.67664,267.67502,267.67502,1.91196,0.56373
32.16000,24.08307,268.00834,268.00833,1.91435,0.57341
32.20000,23.88079,268.34168,268.34167,1.91673,0.56859
32.24000,24.36340,268.67510,268.67511,1.91911,0.58008
32.28000,24.05103,269.00829,269.00830,1.92149,0.57264
32.32000,24.17043,269.34174,269.34174,1.92387,0.57549
32.36000,24.29448,269.67487,269.67487,1.92625,0.57844
32.40000,24.35520,270.00847,270.00848,1.92863,0.57989
32.44000,24.38128,270.34163,270.34164,1.93101,0.58051
32.48000,24.55469,270.67506,270.67505,1.93339,0.58464
32.52000,24.04824,271.00835,271.00833,1.93577,0.57258
32.56000,23.84689,271.34161,271.34161,1.93815,0.56778
32.60000,24.00521,271.67511,271.67511,1.94054,0.57155
32.64000,24.00782,272.00827,272.00827,1.94292,0.57161
32.68000,22.68869,272.34174,272.34174,1.94530,0.54021
32.72000,8.55234,272.67493,272.67493,1.94768,0.20363
32.74200,-0.15888,272.85828,272.85828,1.94899,-0.00378