File: raw_data/mechanical_tests_Instron_data/Silicone_0035-Skin_Longitudinal_3.is_tens_RawData/Specimen_RawData_1.csv
Dimension : Area,0.42000,cm^2

Time,Load,Extension,Tensile extension,Tensile strain,Tensile stress
(sec),(N),(mm),(mm),(%),(MPa)
0.00000,0.14137,0.00000,0.00000,0.00000,0.00337
0.04000,0.90729,0.06027,0.06027,0.04305,0.02160
0.08000,0.96783,0.26108,0.26108,0.18649,0.02304
0.12000,1.96937,0.59312,0.59312,0.42365,0.04689
0.16000,1.87475,0.98328,0.98328,0.70234,0.04464
0.20000,1.91499,1.38884,1.38884,0.99203,0.04559
0.24000,1.75349,1.80345,1.80345,1.28818,0.04175
0.28000,1.84961,2.22423,2.22423,1.58874,0.04404
0.32000,2.07797,2.64423,2.64423,1.88874,0.04948
0.36000,1.48602,3.00830,3.00830,2.14879,0.03538
0.40000,1.66800,3.33680,3.33680,2.38343,0.03971
0.44000,1.96695,3.67106,3.67106,2.62219,0.04683
0.48000,1.58213,4.00738,4.00738,2.86242,0.03767
0.52000,1.86134,4.34127,4.34127,3.10090,0.04432
0.56000,2.10386,4.67472,4.67472,3.33909,0.05009
0.60000,2.09678,5.00810,5.00810,3.57721,0.04992
0.64000,1.87773,5.34171,5.34171,3.81551,0.04471
0.68000,2.07312,5.67490,5.67490,4.05350,0.04936
0.72000,1.92877,6.00838,6.00838,4.29170,0.04592
0.76000,1.80397,6.34162,6.34162,4.52973,0.04295
0.80000,1.92057,6.67505,6.67505,4.76789,0.04573
0.84000,2.24151,7.00837,7.00837,5.00598,0.05337
0.88000,1.99042,7.34167,7.34167,5.24405,0.04739
0.92000,2.01371,7.67504,7.67504,5.48217,0.04795
0.96000,2.05971,8.00823,8.00823,5.72016,0.04904
1.00000,1.81589,8.34176,8.34176,5.95840,0.04324
1.04000,1.90716,8.67492,8.67492,6.19637,0.04541
1.08000,2.09939,9.00835,9.00835,6.43454,0.04999
1.12000,2.53431,9.34162,9.34162,6.67259,0.06034
1.16000,2.21860,9.67500,9.67500,6.91071,0.05282
1.20000,2.29608,10.00829,10.00829,7.14878,0.05467
1.24000,2.18321,10.34164,10.34164,7.38688,0.05198
1.28000,2.32849,10.67504,10.67504,7.62503,0.05544
1.32000,2.27541,11.00825,11.00825,7.86304,0.05418
1.36000,1.91126,11.34179,11.34179,8.10128,0.04551
1.40000,1.85370,11.67492,11.67492,8.33923,0.04414
1.44000,1.95485,12.00846,12.00846,8.57747,0.04654
1.48000,2.12677,12.34157,12.34157,8.81540,0.05064
1.52000,2.28416,12.67499,12.67499,9.05357,0.05438
1.56000,2.40710,13.00834,13.00834,9.29167,0.05731
1.60000,2.26162,13.34164,13.34164,9.52974,0.05385
1.64000,2.26889,13.67507,13.67507,9.76790,0.05402
1.68000,2.36928,14.00820,14.00820,10.00586,0.05641
1.72000,2.36444,14.34173,14.34173,10.24410,0.05630
1.76000,2.42982,14.67490,14.67490,10.48207,0.05785
1.80000,2.32793,15.00840,15.00840,10.72029,0.05543
1.84000,2.12956,15.34162,15.34162,10.95830,0.05070
1.88000,2.26069,15.67502,15.67502,11.19644,0.05383
1.92000,2.19196,16.00832,16.00832,11.43451,0.05219
1.96000,2.15340,16.34164,16.34163,11.67260,0.05127
2.00000,1.99899,16.67512,16.67512,11.91080,0.04760
2.04000,2.09697,17.00828,17.00828,12.14877,0.04993
2.08000,1.91629,17.34171,17.34171,12.38693,0.04563
2.12000,2.05506,17.67487,17.67487,12.62490,0.04893
2.16000,1.88891,18.00843,18.00843,12.86316,0.04497
2.20000,2.11671,18.34164,18.34164,13.10117,0.05040
2.24000,2.08560,18.67497,18.67497,13.33926,0.04966
2.28000,2.07592,19.00831,19.00831,13.57737,0.04943
2.32000,2.20649,19.34163,19.34163,13.81545,0.05254
2.36000,2.30037,19.67504,19.67504,14.05360,0.05477
2.40000,2.29478,20.00828,20.00828,14.29163,0.05464
2.44000,1.89282,20.34176,20.34176,14.52983,0.04507
2.48000,2.11317,20.67489,20.67489,14.76778,0.05031
2.52000,1.72947,21.00840,21.00840,15.00600,0.04118
2.56000,1.84309,21.34159,21.34159,15.24399,0.04388
2.60000,1.67210,21.67507,21.67507,15.48219,0.03981
2.64000,1.71848,22.00834,22.00834,15.72024,0.04092
2.68000,1.21891,22.34161,22.34161,15.95829,0.02902
2.72000,1.79186,22.67506,22.67506,16.19647,0.04266
2.76000,1.53482,23.00828,23.00828,16.43448,0.03654
2.80000,1.43908,23.34176,23.34175,16.67268,0.03426
2.84000,1.84905,23.67486,23.67486,16.91062,0.04402
2.88000,1.73524,24.00840,24.00840,17.14886,0.04132
2.92000,1.89748,24.34159,24.34159,17.38685,0.04518
2.96000,1.89245,24.67504,24.67504,17.62503,0.04506
3.00000,1.89710,25.00834,25.00834,17.86310,0.04517
3.04000,1.86916,25.34160,25.34160,18.10115,0.04450
3.08000,1.95038,25.67503,25.67503,18.33931,0.04644
3.12000,1.88500,26.00819,26.00819,18.57728,0.04488
3.16000,1.62665,26.34181,26.34181,18.81558,0.03873
3.20000,2.05375,26.67494,26.67494,19.05353,0.04890
3.24000,2.17743,27.00840,27.00840,19.29171,0.05184
3.28000,2.11019,27.34159,27.34158,19.52970,0.05024
3.32000,1.46870,27.67499,27.67499,19.76785,0.03497
3.36000,1.83973,28.00839,28.00839,20.00599,0.04380
3.40000,1.69687,28.34163,28.34163,20.24402,0.04040
3.44000,1.98409,28.67503,28.67503,20.48216,0.04724
3.48000,1.96621,29.00827,29.00827,20.72020,0.04681
3.52000,2.19028,29.34173,29.34173,20.95838,0.05215
3.56000,2.29441,29.67489,29.67489,21.19635,0.05463
3.60000,2.30074,30.00837,30.00837,21.43455,0.05478
3.64000,2.30521,30.34159,30.34159,21.67256,0.05489
3.68000,2.69152,30.67501,30.67501,21.91072,0.06408
3.72000,2.16924,31.00834,31.00834,22.14881,0.05165
3.76000,2.27857,31.34166,31.34166,22.38690,0.05425
3.80000,2.60323,31.67511,31.67511,22.62508,0.06198
3.84000,2.51830,32.00824,32.00824,22.86303,0.05996
3.88000,2.67997,32.34175,32.34175,23.10125,0.06381
3.92000,2.73194,32.67494,32.67494,23.33924,0.06505
3.96000,2.91280,33.00842,33.00842,23.57745,0.06935
4.00000,2.62000,33.34161,33.34161,23.81544,0.06238
4.04000,2.89902,33.67498,33.67498,24.05356,0.06902
4.08000,2.71499,34.00828,34.00828,24.29163,0.06464
4.12000,2.71834,34.34163,34.34163,24.52973,0.06472
4.16000,2.69488,34.67506,34.67506,24.76790,0.06416
4.20000,3.01693,35.00824,35.00825,25.00589,0.07183
4.24000,2.90144,35.34175,35.34175,25.24411,0.06908
4.28000,2.87499,35.67486,35.67486,25.48204,0.06845
4.32000,2.99551,36.00845,36.00845,25.72032,0.07132
4.36000,2.98042,36.34164,36.34164,25.95831,0.07096
4.40000,3.03034,36.67501,36.67501,26.19644,0.07215
4.44000,3.11211,37.00836,37.00836,26.43454,0.07410
4.48000,3.03052,37.34163,37.34163,26.67259,0.07216
4.52000,2.90964,37.67508,37.67508,26.91077,0.06928
4.56000,2.65837,38.00824,38.00824,27.14874,0.06329
4.60000,2.79173,38.34173,38.34172,27.38695,0.06647
4.64000,2.88878,38.67491,38.67491,27.62494,0.06878
4.68000,3.16072,39.00839,39.00839,27.86314,0.07526
4.72000,3.12887,39.34158,39.34158,28.10113,0.07450
4.76000,3.05194,39.67493,39.67493,28.33924,0.07267
4.80000,3.09199,40.00831,40.00830,28.57736,0.07362
4.84000,3.04747,40.34168,40.34168,28.81548,0.07256
4.88000,3.29949,40.67513,40.67513,29.05366,0.07856
4.92000,3.06368,41.00826,41.00827,29.29162,0.07294
4.96000,3.21008,41.34175,41.34175,29.52982,0.07643
5.00000,2.94819,41.67491,41.67491,29.76779,0.07020
5.04000,2.82526,42.00839,42.00839,30.00599,0.06727
5.08000,3.00128,42.34163,42.34163,30.24402,0.07146
5.12000,3.03648,42.67503,42.67503,30.48217,0.07230
5.16000,3.07392,43.00830,43.00831,30.72022,0.07319
5.20000,3.24417,43.34165,43.34165,30.95832,0.07724
5.24000,2.60025,43.67505,43.67505,31.19647,0.06191
5.28000,2.89902,44.00824,44.00824,31.43446,0.06902
5.32000,3.07728,44.34172,44.34172,31.67266,0.07327
5.36000,3.33358,44.67485,44.67485,31.91061,0.07937
5.40000,2.95397,45.00842,45.00842,32.14887,0.07033
5.44000,3.01041,45.34163,45.34164,32.38688,0.07168
5.48000,3.46955,45.67506,45.67506,32.62504,0.08261
5.52000,3.30415,46.00835,46.00835,32.86311,0.07867
5.56000,2.56691,46.34157,46.34156,33.10112,0.06112
5.60000,3.24380,46.67505,46.67505,33.33932,0.07723
5.64000,3.16426,47.00826,47.00826,33.57733,0.07534
5.68000,3.45744,47.34180,47.34180,33.81557,0.08232
5.72000,3.69009,47.67491,47.67491,34.05350,0.08786
5.76000,3.38554,48.00836,48.00836,34.29169,0.08061
5.80000,3.15811,48.34158,48.34158,34.52970,0.07519
5.84000,3.38778,48.67508,48.67508,34.76792,0.08066
5.88000,3.30452,49.00835,49.00835,35.00597,0.07868
5.92000,3.73200,49.34162,49.34162,35.24401,0.08886
5.96000,3.66755,49.67505,49.67505,35.48218,0.08732
6.00000,3.68487,50.00821,50.00821,35.72015,0.08774
6.04000,3.69493,50.34180,50.34180,35.95843,0.08797
6.08000,3.78918,50.67491,50.67491,36.19636,0.09022
6.12000,3.61279,51.00836,51.00836,36.43454,0.08602
6.16000,3.88008,51.34160,51.34160,36.67257,0.09238
6.20000,3.94173,51.67503,51.67503,36.91074,0.09385
6.24000,3.78452,52.00840,52.00840,37.14886,0.09011
6.28000,3.75528,52.34162,52.34162,37.38687,0.08941
6.32000,3.67071,52.67502,52.67502,37.62501,0.08740
6.36000,3.80650,53.00823,53.00823,37.86303,0.09063
6.40000,3.80967,53.34175,53.34175,38.10125,0.09071
6.44000,3.90355,53.67493,53.67493,38.33924,0.09294
6.48000,4.03691,54.00844,54.00844,38.57746,0.09612
6.52000,4.44334,54.34157,54.34157,38.81541,0.10579
6.56000,4.23547,54.67500,54.67500,39.05357,0.10084
6.60000,4.27663,55.00829,55.00829,39.29164,0.10182
6.64000,4.19933,55.34162,55.34162,39.52973,0.09998
6.68000,3.82755,55.67510,55.67510,39.76793,0.09113
6.72000,3.92161,56.00824,56.00824,40.00588,0.09337
6.76000,4.06522,56.34172,56.34172,40.24408,0.09679
6.80000,3.91230,56.67490,56.67490,40.48207,0.09315
6.84000,3.79812,57.00843,57.00843,40.72031,0.09043
6.88000,3.64147,57.34163,57.34163,40.95831,0.08670
6.92000,3.57367,57.67503,57.67503,41.19645,0.08509
6.96000,4.15798,58.00833,58.00832,41.43452,0.09900
7.00000,3.67798,58.34164,58.34164,41.67260,0.08757
7.04000,3.50643,58.67510,58.67509,41.91078,0.08349
7.08000,3.57050,59.00823,59.00823,42.14874,0.08501
7.12000,3.97507,59.34174,59.34174,42.38696,0.09464
7.16000,4.04604,59.67485,59.67485,42.62489,0.09633
7.20000,3.97954,60.00841,60.00841,42.86315,0.09475
7.24000,4.55379,60.34165,60.34165,43.10118,0.10842
7.28000,4.23510,60.67500,60.67500,43.33928,0.10084
7.32000,3.91249,61.00829,61.00829,43.57735,0.09315
7.36000,4.03337,61.34159,61.34159,43.81542,0.09603
7.40000,3.81880,61.67509,61.67509,44.05364,0.09092
7.44000,3.90895,62.00828,62.00828,44.29163,0.09307
7.48000,4.06206,62.34177,62.34177,44.52983,0.09672
7.52000,4.16432,62.67493,62.67493,44.76781,0.09915
7.56000,4.07733,63.00841,63.00841,45.00600,0.09708
7.60000,3.89889,63.34160,63.34160,45.24400,0.09283
7.64000,4.22020,63.67503,63.67503,45.48216,0.10048
7.68000,4.11756,64.00832,64.00832,45.72023,0.09804
7.72000,3.99034,64.34161,64.34161,45.95830,0.09501
7.76000,4.02555,64.67504,64.67504,46.19646,0.09585
7.80000,4.12744,65.00825,65.00826,46.43447,0.09827
7.84000,4.09093,65.34177,65.34177,46.67269,0.09740
7.88000,4.24348,65.67493,65.67493,46.91066,0.10104
7.92000,4.12688,66.00837,66.00838,47.14884,0.09826
7.96000,4.11496,66.34162,66.34162,47.38687,0.09798
8.00000,4.04418,66.67508,66.67508,47.62506,0.09629
8.04000,3.72417,67.00834,67.00835,47.86310,0.08867
8.08000,3.67872,67.34167,67.34167,48.10119,0.08759
8.12000,3.42913,67.67501,67.67501,48.33929,0.08165
8.16000,3.55951,68.00825,68.00826,48.57732,0.08475
8.20000,3.66624,68.34177,68.34177,48.81555,0.08729
8.24000,3.36971,68.67489,68.67490,49.05350,0.08023
8.28000,3.89162,69.00843,69.00843,49.29174,0.09266
8.32000,3.73293,69.34157,69.34157,49.52969,0.08888
8.36000,3.97824,69.67499,69.67500,49.76785,0.09472
8.40000,3.74429,70.00834,70.00835,50.00596,0.08915
8.44000,3.78657,70.34161,70.34161,50.24401,0.09016
8.48000,4.04362,70.67506,70.67506,50.48218,0.09628
8.52000,3.60869,71.00825,71.00826,50.72018,0.08592
8.56000,3.84077,71.34177,71.34177,50.95841,0.09145
8.60000,3.89237,71.67495,71.67494,51.19639,0.09268
8.64000,3.78117,72.00841,72.00841,51.43458,0.09003
8.68000,3.58932,72.34159,72.34159,51.67257,0.08546
8.72000,3.47942,72.67505,72.67505,51.91075,0.08284
8.76000,3.61372,73.00837,73.00837,52.14884,0.08604
8.80000,3.60701,73.34158,73.34158,52.38684,0.08588
8.84000,3.78657,73.67504,73.67504,52.62503,0.09016
8.88000,4.56180,74.00822,74.00822,52.86301,0.10861
8.92000,4.33922,74.34177,74.34177,53.10126,0.10331
8.96000,4.17735,74.67489,74.67490,53.33921,0.09946
9.00000,4.35784,75.00841,75.00842,53.57744,0.10376
9.04000,4.25652,75.34164,75.34164,53.81546,0.10135
9.08000,4.25559,75.67502,75.67502,54.05359,0.10132
9.12000,4.32599,76.00832,76.00832,54.29165,0.10300
9.16000,4.46029,76.34161,76.34162,54.52973,0.10620
9.20000,4.55994,76.67504,76.67505,54.76789,0.10857
9.24000,3.89963,77.00825,77.00826,55.00590,0.09285
9.28000,4.16953,77.34178,77.34178,55.24413,0.09927
9.32000,4.28073,77.67492,77.67492,55.48208,0.10192
9.36000,4.38187,78.00843,78.00842,55.72031,0.10433
9.40000,3.96855,78.34157,78.34157,55.95826,0.09449
9.44000,4.09503,78.67499,78.67500,56.19642,0.09750
9.48000,4.41857,79.00834,79.00834,56.43452,0.10520
9.52000,4.71044,79.34166,79.34166,56.67261,0.11215
9.56000,4.59757,79.67506,79.67506,56.91076,0.10947
9.60000,4.68288,80.00825,80.00826,57.14875,0.11150
9.64000,4.36194,80.34173,80.34174,57.38695,0.10386
9.68000,4.54746,80.67492,80.67492,57.62494,0.10827
9.72000,4.82202,81.00845,81.00845,57.86318,0.11481
9.76000,4.66164,81.34161,81.34161,58.10115,0.11099
9.80000,4.93769,81.67502,81.67502,58.33930,0.11756
9.84000,4.56180,82.00832,82.00832,58.57737,0.10861
9.88000,5.01554,82.34163,82.34163,58.81545,0.11942
9.92000,5.22714,82.67514,82.67514,59.05367,0.12446
9.96000,4.90770,83.00825,83.00824,59.29160,0.11685
10.00000,5.01890,83.34176,83.34176,59.52983,0.11950
10.04000,5.16269,83.67489,83.67490,59.76778,0.12292
10.08000,5.20702,84.00843,84.00843,60.00602,0.12398
10.12000,5.37317,84.34166,84.34165,60.24404,0.12793
10.16000,5.44861,84.67496,84.67496,60.48211,0.12973
10.20000,5.32418,85.00833,85.00833,60.72024,0.12677
10.24000,5.22379,85.34161,85.34161,60.95829,0.12438
10.28000,5.56577,85.67508,85.67509,61.19649,0.13252
10.32000,5.53001,86.00830,86.00829,61.43450,0.13167
10.36000,5.40279,86.34172,86.34172,61.67266,0.12864
10.40000,5.67064,86.67488,86.67488,61.91063,0.13502
10.44000,5.50337,87.00840,87.00840,62.14886,0.13103
10.48000,5.55124,87.34164,87.34164,62.38689,0.13217
10.52000,5.62482,87.67507,87.67507,62.62505,0.13392
10.56000,5.57229,88.00833,88.00833,62.86309,0.13267
10.60000,5.55795,88.34160,88.34161,63.10115,0.13233
10.64000,5.56149,88.67503,88.67503,63.33931,0.13242
10.68000,6.15325,89.00827,89.00827,63.57734,0.14651
10.72000,6.04652,89.34178,89.34177,63.81555,0.14396
10.76000,6.04205,89.67492,89.67492,64.05351,0.14386
10.80000,6.22682,90.00836,90.00835,64.29169,0.14826
10.84000,5.98598,90.34156,90.34156,64.52968,0.14252
10.88000,6.10873,90.67504,90.67503,64.76789,0.14545
10.92000,5.84759,91.00836,91.00836,65.00597,0.13923
10.96000,6.20596,91.34162,91.34162,65.24402,0.14776
11.00000,6.22310,91.67505,91.67505,65.48218,0.14817
11.04000,5.81276,92.00824,92.00825,65.72018,0.13840
11.08000,5.91166,92.34181,92.34181,65.95843,0.14075
11.12000,5.84330,92.67494,92.67493,66.19638,0.13913
11.16000,5.80084,93.00840,93.00840,66.43457,0.13812
11.20000,6.11171,93.34158,93.34158,66.67256,0.14552
11.24000,6.21956,93.67498,93.67498,66.91070,0.14808
11.28000,6.45220,94.00836,94.00836,67.14883,0.15362
11.32000,6.13555,94.34166,94.34166,67.38690,0.14608
11.36000,6.23446,94.67505,94.67504,67.62503,0.14844
11.40000,6.44270,95.00821,95.00820,67.86301,0.15340
11.44000,6.48350,95.34176,95.34176,68.10126,0.15437
11.48000,6.52559,95.67492,95.67492,68.33923,0.15537
11.52000,6.65318,96.00840,96.00839,68.57743,0.15841
11.56000,6.18193,96.34163,96.34164,68.81545,0.14719
11.60000,5.92098,96.67504,96.67503,69.05360,0.14098
11.64000,6.06216,97.00838,97.00838,69.29170,0.14434
11.68000,5.90254,97.34162,97.34162,69.52973,0.14054
11.72000,6.33951,97.67508,97.67509,69.76792,0.15094
11.76000,6.30487,98.00824,98.00824,70.00589,0.15012
11.80000,6.15530,98.34176,98.34176,70.24411,0.14655
11.84000,6.00964,98.67492,98.67492,70.48208,0.14309
11.88000,6.10948,99.00840,99.00840,70.72029,0.14546
11.92000,6.24135,99.34161,99.34161,70.95829,0.14860
11.96000,6.13146,99.67504,99.67503,71.19645,0.14599
12.00000,6.42482,100.00831,100.00831,71.43450,0.15297
12.04000,6.45313,100.34166,100.34165,71.67261,0.15365
12.08000,6.17448,100.67508,100.67508,71.91077,0.14701
12.12000,6.24787,101.00824,101.00824,72.14875,0.14876
12.16000,6.03031,101.34177,101.34177,72.38698,0.14358
12.20000,6.35125,101.67488,101.67488,72.62492,0.15122
12.24000,6.01169,102.00845,102.00844,72.86317,0.14314
12.28000,6.13797,102.34161,102.34161,73.10115,0.14614
12.32000,6.18305,102.67503,102.67504,73.33931,0.14722
12.36000,6.31586,103.00836,103.00835,73.57740,0.15038
12.40000,5.90831,103.34162,103.34163,73.81545,0.14067
12.44000,6.03609,103.67505,103.67506,74.05361,0.14372
12.48000,6.25029,104.00824,104.00824,74.29160,0.14882
12.52000,6.31232,104.34175,104.34175,74.52982,0.15029
12.56000,6.64890,104.67488,104.67488,74.76777,0.15831
12.60000,6.41048,105.00841,105.00842,75.00601,0.15263
12.64000,6.62897,105.34163,105.34164,75.24402,0.15783
12.68000,6.52857,105.67503,105.67503,75.48217,0.15544
12.72000,6.53118,106.00832,106.00832,75.72023,0.15550
12.76000,6.33653,106.34162,106.34162,75.95830,0.15087
12.80000,6.58538,106.67515,106.67516,76.19654,0.15679
12.84000,6.10445,107.00826,107.00827,76.43448,0.14534
12.88000,6.36391,107.34172,107.34173,76.67266,0.15152
12.92000,6.48946,107.67491,107.67491,76.91065,0.15451
12.96000,6.27190,108.00841,108.00842,77.14887,0.14933
13.00000,6.02622,108.34163,108.34163,77.38688,0.14348
13.04000,6.51944,108.67500,108.67500,77.62500,0.15522
13.08000,6.39278,109.00832,109.00833,77.86309,0.15221
13.12000,6.24955,109.34162,109.34162,78.10116,0.14880
13.16000,6.44065,109.67504,109.67504,78.33931,0.15335
13.20000,6.79530,110.00820,110.00820,78.57729,0.16179
13.24000,6.42501,110.34175,110.34175,78.81554,0.15298
13.28000,6.53286,110.67487,110.67487,79.05348,0.15554
13.32000,6.83349,111.00841,111.00842,79.29173,0.16270
13.36000,6.36633,111.34165,111.34165,79.52975,0.15158
13.40000,6.29798,111.67506,111.67506,79.76790,0.14995
13.44000,6.71074,112.00835,112.00835,80.00596,0.15978
13.48000,6.51553,112.34161,112.34161,80.24401,0.15513
13.52000,6.37714,112.67507,112.67507,80.48220,0.15184
13.56000,6.56303,113.00826,113.00826,80.72019,0.15626
13.60000,6.04447,113.34177,113.34177,80.95841,0.14392
13.64000,6.28810,113.67488,113.67488,81.19634,0.14972
13.68000,6.33262,114.00839,114.00839,81.43457,0.15078
13.72000,6.56191,114.34155,114.34155,81.67254,0.15624
13.76000,6.49840,114.67503,114.67503,81.91074,0.15472
13.80000,6.38999,115.00836,115.00835,82.14883,0.15214
13.84000,6.37826,115.34162,115.34162,82.38687,0.15186
13.88000,6.62077,115.67504,115.67504,82.62503,0.15764
13.92000,6.49262,116.00820,116.00820,82.86300,0.15459
13.96000,7.01547,116.34182,116.34182,83.10130,0.16703
14.00000,6.55018,116.67495,116.67495,83.33925,0.15596
14.04000,6.15418,117.00839,117.00838,83.57742,0.14653
14.08000,6.71800,117.34162,117.34162,83.81544,0.15995
14.12000,6.33076,117.67503,117.67503,84.05359,0.15073
14.16000,6.42724,118.00838,118.00838,84.29170,0.15303
14.20000,6.19739,118.34164,118.34164,84.52975,0.14756
14.24000,6.47604,118.67500,118.67500,84.76785,0.15419
14.28000,6.83684,119.00821,119.00821,85.00586,0.16278
14.32000,6.61276,119.34173,119.34174,85.24410,0.15745
14.36000,6.70794,119.67493,119.67493,85.48210,0.15971
14.40000,6.56117,120.00843,120.00843,85.72031,0.15622
14.44000,6.60326,120.34159,120.34159,85.95828,0.15722
14.48000,6.51758,120.67497,120.67497,86.19641,0.15518
14.52000,6.61556,121.00836,121.00835,86.43454,0.15751
14.56000,6.72936,121.34165,121.34164,86.67260,0.16022
14.60000,6.54571,121.67509,121.67509,86.91078,0.15585
14.64000,6.44084,122.00825,122.00826,87.14875,0.15335
14.68000,6.54124,122.34174,122.34174,87.38695,0.15574
14.72000,7.07861,122.67493,122.67493,87.62495,0.16854
14.76000,7.23545,123.00841,123.00841,87.86315,0.17227
14.80000,6.61500,123.34160,123.34160,88.10114,0.15750
14.84000,6.64108,123.67502,123.67502,88.33930,0.15812
14.88000,6.76773,124.00828,124.00829,88.57734,0.16114
14.92000,6.78450,124.34164,124.34164,88.81546,0.16154
14.96000,6.86515,124.67505,124.67505,89.05361,0.16346
15.00000,6.89812,125.00823,125.00823,89.29160,0.16424
15.04000,7.00876,125.34176,125.34176,89.52982,0.16688
15.08000,6.94357,125.67487,125.67487,89.76776,0.16532
15.12000,6.89700,126.00843,126.00843,90.00602,0.16421
15.16000,6.87502,126.34164,126.34164,90.24403,0.16369
15.20000,6.72080,126.67501,126.67501,90.48215,0.16002
15.24000,6.82604,127.00829,127.00829,90.72021,0.16252
15.28000,6.91097,127.34163,127.34163,90.95831,0.16455
15.32000,6.81300,127.67507,127.67506,91.19648,0.16221
15.36000,7.07358,128.00828,128.00829,91.43448,0.16842
15.40000,6.70459,128.34175,128.34175,91.67268,0.15963
15.44000,6.81803,128.67487,128.67487,91.91062,0.16233
15.48000,6.93500,129.00840,129.00839,92.14885,0.16512
15.52000,7.40364,129.34160,129.34160,92.38685,0.17628
15.56000,7.06986,129.67499,129.67499,92.62499,0.16833
15.60000,7.17472,130.00832,130.00832,92.86309,0.17083
15.64000,7.07470,130.34159,130.34158,93.10113,0.16845
15.68000,7.28648,130.67507,130.67508,93.33934,0.17349
15.72000,7.00559,131.00826,131.00826,93.57733,0.16680
15.76000,7.07228,131.34173,131.34174,93.81552,0.16839
15.80000,7.05868,131.67492,131.67491,94.05351,0.16806
15.84000,7.04695,132.00840,132.00841,94.29172,0.16778
15.88000,6.97095,132.34164,132.34164,94.52974,0.16597
15.92000,6.96275,132.67504,132.67503,94.76788,0.16578
15.96000,7.09724,133.00830,133.00830,95.00593,0.16898
16.00000,6.94562,133.34163,133.34163,95.24402,0.16537
16.04000,7.13225,133.67506,133.67506,95.48219,0.16982
16.08000,7.19447,134.00825,134.00826,95.72018,0.17130
16.12000,7.24979,134.34178,134.34178,95.95841,0.17261
16.16000,7.45952,134.67487,134.67487,96.19634,0.17761
16.20000,7.45822,135.00837,135.00838,96.43455,0.17758
16.24000,7.51633,135.34160,135.34160,96.67257,0.17896
16.28000,7.34311,135.67502,135.67502,96.91073,0.17484
16.32000,7.51708,136.00835,136.00835,97.14882,0.17898
16.36000,7.58171,136.34164,136.34164,97.38688,0.18052
16.40000,7.17510,136.67510,136.67509,97.62507,0.17084
16.44000,7.33137,137.00827,137.00827,97.86305,0.17456
16.48000,6.93034,137.34176,137.34175,98.10125,0.16501
16.52000,7.30492,137.67489,137.67490,98.33921,0.17393
16.56000,7.38725,138.00842,138.00842,98.57744,0.17589
16.60000,7.51466,138.34156,138.34157,98.81540,0.17892
16.64000,7.59568,138.67504,138.67503,99.05360,0.18085
16.68000,7.38241,139.00837,139.00836,99.29169,0.17577
16.72000,7.51372,139.34160,139.34160,99.52972,0.17890
16.76000,7.81324,139.67502,139.67502,99.76788,0.18603
16.80000,7.48206,140.00817,140.00818,100.00584,0.17814
16.84000,7.71023,140.34178,140.34178,100.24413,0.18358
16.88000,7.91941,140.67494,140.67494,100.48209,0.18856
16.92000,7.84472,141.00840,141.00839,100.72029,0.18678
16.96000,7.84751,141.34158,141.34158,100.95828,0.18685
17.00000,7.32820,141.67504,141.67505,101.19646,0.17448
17.04000,7.60388,142.00838,142.00838,101.43456,0.18104
17.08000,7.55936,142.34166,142.34166,101.67261,0.17998
17.12000,7.57873,142.67503,142.67503,101.91073,0.18045
17.16000,8.00733,143.00826,143.00827,102.14876,0.19065
17.20000,7.71265,143.34176,143.34174,102.38696,0.18363
17.24000,7.48653,143.67492,143.67491,102.62494,0.17825
17.28000,7.72420,144.00838,144.00838,102.86312,0.18391
17.32000,7.91419,144.34157,144.34157,103.10112,0.18843
17.36000,7.71135,144.67496,144.67496,103.33925,0.18360
17.40000,7.91606,145.00833,145.00833,103.57738,0.18848
17.44000,7.78958,145.34168,145.34167,103.81548,0.18547
17.48000,7.93897,145.67505,145.67505,104.05360,0.18902
17.52000,7.82833,146.00821,146.00821,104.29158,0.18639
17.56000,8.06805,146.34174,146.34174,104.52981,0.19210
17.60000,7.99168,146.67493,146.67494,104.76781,0.19028
17.64000,8.17031,147.00847,147.00847,105.00605,0.19453
17.68000,7.75177,147.34162,147.34161,105.24402,0.18457
17.72000,7.81324,147.67504,147.67503,105.48217,0.18603
17.76000,8.13585,148.00831,148.00830,105.72022,0.19371
17.80000,7.66218,148.34164,148.34163,105.95831,0.18243
17.84000,7.60388,148.67510,148.67509,106.19650,0.18104
17.88000,8.02763,149.00822,149.00821,106.43444,0.19113
17.92000,8.16230,149.34173,149.34174,106.67267,0.19434
17.96000,7.69850,149.67484,149.67484,106.91060,0.18330
18.00000,8.14497,150.00840,150.00841,107.14886,0.19393
18.04000,7.79498,150.34167,150.34166,107.38690,0.18559
18.08000,8.24593,150.67503,150.67502,107.62502,0.19633
18.12000,8.01608,151.00832,151.00833,107.86309,0.19086
18.16000,8.05520,151.34165,151.34166,108.10118,0.19179
18.20000,8.17701,151.67511,151.67511,108.33937,0.19469
18.24000,8.28095,152.00830,152.00830,108.57736,0.19717
18.28000,8.21613,152.34175,152.34177,108.81554,0.19562
18.32000,8.24127,152.67486,152.67485,109.05347,0.19622
18.36000,8.02688,153.00839,153.00839,109.29171,0.19112
18.40000,8.10046,153.34163,153.34163,109.52973,0.19287
18.44000,8.23922,153.67504,153.67503,109.76789,0.19617
18.48000,8.18931,154.00833,154.00833,110.00595,0.19498
18.52000,8.46665,154.34154,154.34155,110.24396,0.20159
18.56000,8.42493,154.67500,154.67500,110.48214,0.20059
18.60000,8.34335,155.00827,155.00827,110.72019,0.19865
18.64000,8.33459,155.34178,155.34177,110.95841,0.19844
18.68000,8.46200,155.67494,155.67494,111.19639,0.20148
18.72000,8.15596,156.00841,156.00841,111.43458,0.19419
18.76000,8.37334,156.34164,156.34164,111.67260,0.19937
18.80000,8.40239,156.67506,156.67506,111.91076,0.20006
18.84000,8.48509,157.00832,157.00832,112.14880,0.20203
18.88000,8.74475,157.34165,157.34166,112.38689,0.20821
18.92000,8.78051,157.67505,157.67505,112.62504,0.20906
18.96000,8.37948,158.00823,158.00824,112.86303,0.19951
19.00000,8.11834,158.34177,158.34177,113.10127,0.19329
19.04000,8.43983,158.67489,158.67490,113.33921,0.20095
19.08000,8.38116,159.00842,159.00841,113.57744,0.19955
19.12000,8.75816,159.34158,159.34158,113.81541,0.20853
19.16000,8.79914,159.67501,159.67502,114.05358,0.20950
19.20000,8.72426,160.00834,160.00833,114.29167,0.20772
19.24000,8.89376,160.34163,160.34163,114.52974,0.21176
19.28000,8.94256,160.67505,160.67505,114.76790,0.21292
19.32000,9.06158,161.00821,161.00819,115.00586,0.21575
19.36000,8.81571,161.34179,161.34180,115.24414,0.20990
19.40000,8.66707,161.67491,161.67491,115.48208,0.20636
19.44000,8.66968,162.00844,162.00842,115.72031,0.20642
19.48000,8.61287,162.34160,162.34160,115.95829,0.20507
19.52000,8.91220,162.67501,162.67500,116.19643,0.21220
19.56000,9.06121,163.00835,163.00835,116.43454,0.21574
19.60000,8.77511,163.34161,163.34160,116.67258,0.20893
19.64000,8.83993,163.67505,163.67505,116.91074,0.21047
19.68000,9.18284,164.00823,164.00822,117.14873,0.21864
19.72000,9.18116,164.34175,164.34175,117.38696,0.21860
19.76000,8.77585,164.67493,164.67493,117.62495,0.20895
19.80000,8.78274,165.00839,165.00841,117.86314,0.20911
19.84000,9.32068,165.34160,165.34160,118.10114,0.22192
19.88000,9.13944,165.67504,165.67503,118.33931,0.21761
19.92000,9.16831,166.00834,166.00835,118.57738,0.21829
19.96000,9.03066,166.34165,166.34164,118.81546,0.21502
20.00000,9.27020,166.67505,166.67505,119.05361,0.22072
20.04000,8.97981,167.00823,167.00822,119.29159,0.21381
20.08000,9.07276,167.34178,167.34178,119.52984,0.21602
20.12000,9.19290,167.67495,167.67496,119.76782,0.21888
20.16000,9.29926,168.00844,168.00844,120.00602,0.22141
20.20000,9.09399,168.34160,168.34160,120.24400,0.21652
20.24000,9.34806,168.67498,168.67497,120.48212,0.22257
20.28000,9.20538,169.00832,169.00832,120.72023,0.21918
20.32000,9.53861,169.34161,169.34161,120.95829,0.22711
20.36000,9.46447,169.67499,169.67499,121.19642,0.22534
20.40000,9.33520,170.00823,170.00824,121.43445,0.22227
20.44000,9.33781,170.34177,170.34177,121.67269,0.22233
20.48000,9.51365,170.67493,170.67493,121.91067,0.22652
20.52000,9.53320,171.00846,171.00845,122.14890,0.22698
20.56000,9.36519,171.34160,171.34160,122.38686,0.22298
20.60000,9.53544,171.67504,171.67503,122.62503,0.22703
20.64000,9.30484,172.00834,172.00835,122.86310,0.22154
20.68000,9.68482,172.34163,172.34163,123.10116,0.23059
20.72000,9.54643,172.67513,172.67513,123.33938,0.22730
20.76000,9.59579,173.00825,173.00826,123.57732,0.22847
20.80000,9.64478,173.34174,173.34174,123.81552,0.22964
20.84000,9.66694,173.67485,173.67487,124.05347,0.23017
20.88000,9.66154,174.00836,174.00836,124.29168,0.23004
20.92000,9.77628,174.34166,174.34166,124.52976,0.23277
20.96000,9.98527,174.67503,174.67503,124.76788,0.23774
21.00000,9.98899,175.00830,175.00830,125.00592,0.23783
21.04000,10.13242,175.34159,175.34158,125.24399,0.24125
21.08000,9.88264,175.67507,175.67508,125.48219,0.23530
21.12000,9.41306,176.00830,176.00830,125.72021,0.22412
21.16000,9.74257,176.34180,176.34181,125.95843,0.23197
21.20000,9.98285,176.67493,176.67494,126.19638,0.23769
21.24000,9.94336,177.00844,177.00844,126.43460,0.23675
21.28000,9.77200,177.34164,177.34164,126.67260,0.23267
21.32000,9.99812,177.67505,177.67505,126.91075,0.23805
21.36000,9.99197,178.00833,178.00833,127.14881,0.23790
21.40000,10.16986,178.34162,178.34161,127.38687,0.24214
21.44000,10.10001,178.67501,178.67502,127.62501,0.24048
21.48000,9.96757,179.00828,179.00827,127.86305,0.23732
21.52000,10.18606,179.34178,179.34178,128.10127,0.24253
21.56000,10.21810,179.67485,179.67485,128.33917,0.24329
21.60000,9.97167,180.00836,180.00836,128.57740,0.23742
21.64000,9.84240,180.34153,180.34154,128.81538,0.23434
21.68000,9.68780,180.67506,180.67506,129.05362,0.23066
21.72000,10.35687,181.00837,181.00836,129.29169,0.24659
21.76000,10.09572,181.34168,181.34169,129.52977,0.24037
21.80000,10.21791,181.67510,181.67509,129.76793,0.24328
21.84000,9.98173,182.00826,182.00826,130.00590,0.23766
21.88000,10.58038,182.34180,182.34180,130.24414,0.25191
21.92000,10.63328,182.67492,182.67490,130.48208,0.25317
21.96000,10.70853,183.00842,183.00842,130.72029,0.25497
22.00000,10.35687,183.34160,183.34160,130.95828,0.24659
22.04000,10.20283,183.67500,183.67500,131.19643,0.24292
22.08000,10.41126,184.00833,184.00835,131.43452,0.24789
22.12000,10.99240,184.34163,184.34163,131.67260,0.26172
22.16000,10.62751,184.67505,184.67505,131.91075,0.25304
22.20000,10.67631,185.00821,185.00821,132.14872,0.25420
22.24000,10.81247,185.34179,185.34178,132.38699,0.25744
22.28000,10.74541,185.67492,185.67493,132.62495,0.25584
22.32000,10.60870,186.00846,186.00845,132.86319,0.25259
22.36000,10.88679,186.34162,186.34161,133.10115,0.25921
22.40000,10.62807,186.67499,186.67499,133.33927,0.25305
22.44000,10.63459,187.00838,187.00838,133.57742,0.25320
22.48000,11.28577,187.34166,187.34164,133.81547,0.26871
22.52000,11.03170,187.67507,187.67506,134.05362,0.26266
22.56000,11.01904,188.00826,188.00826,134.29161,0.26236
22.60000,10.94844,188.34172,188.34172,134.52979,0.26068
22.64000,10.54183,188.67489,188.67490,134.76778,0.25100
22.68000,10.70518,189.00841,189.00841,135.00601,0.25489
22.72000,11.06970,189.34157,189.34158,135.24399,0.26356
22.76000,10.82644,189.67500,189.67500,135.48214,0.25777
22.80000,10.88046,190.00833,190.00833,135.72023,0.25906
22.84000,11.26528,190.34169,190.34169,135.95835,0.26822
22.88000,11.29452,190.67509,190.67509,136.19649,0.26892
22.92000,11.40293,191.00822,191.00822,136.43445,0.27150
22.96000,10.99855,191.34179,191.34180,136.67271,0.26187
23.00000,11.11347,191.67495,191.67494,136.91068,0.26461
23.04000,11.05219,192.00843,192.00844,137.14888,0.26315
23.08000,11.29527,192.34162,192.34161,137.38687,0.26893
23.12000,11.16078,192.67501,192.67502,137.62501,0.26573
23.16000,11.06914,193.00832,193.00832,137.86309,0.26355
23.20000,11.21927,193.34164,193.34163,138.10117,0.26713
23.24000,11.03934,193.67507,193.67508,138.33934,0.26284
23.28000,11.42770,194.00826,194.00827,138.57733,0.27209
23.32000,11.37182,194.34173,194.34174,138.81552,0.27076
23.36000,11.29080,194.67488,194.67490,139.05349,0.26883
23.40000,11.24982,195.00843,195.00844,139.29174,0.26785
23.44000,11.29527,195.34161,195.34163,139.52973,0.26893
23.48000,11.07287,195.67502,195.67502,139.76787,0.26364
23.52000,11.52791,196.00836,196.00836,140.00597,0.27447
23.56000,11.72349,196.34163,196.34163,140.24402,0.27913
23.60000,11.36605,196.67511,196.67511,140.48222,0.27062
23.64000,11.46477,197.00825,197.00826,140.72018,0.27297
23.68000,11.70281,197.34173,197.34174,140.95838,0.27864
23.72000,11.55548,197.67489,197.67491,141.19636,0.27513
23.76000,11.70803,198.00839,198.00838,141.43456,0.27876
23.80000,11.49792,198.34165,198.34164,141.67260,0.27376
23.84000,11.71920,198.67504,198.67503,141.91074,0.27903
23.88000,11.93676,199.00830,199.00830,142.14879,0.28421
23.92000,11.78142,199.34161,199.34161,142.38687,0.28051
23.96000,11.62514,199.67507,199.67506,142.62505,0.27679
24.00000,11.94868,200.00827,200.00827,142.86305,0.28449
24.04000,11.90472,200.34178,200.34178,143.10127,0.28345
24.08000,11.72945,200.67489,200.67488,143.33920,0.27927
24.12000,11.96302,201.00837,201.00838,143.57741,0.28483
24.16000,12.14109,201.34166,201.34164,143.81547,0.28907
24.20000,11.57429,201.67507,201.67508,144.05363,0.27558
24.24000,11.77881,202.00836,202.00836,144.29169,0.28045
24.28000,11.90100,202.34163,202.34163,144.52974,0.28336
24.32000,11.84233,202.67504,202.67503,144.76788,0.28196
24.36000,12.14202,203.00827,203.00827,145.00591,0.28910
24.40000,11.86337,203.34176,203.34177,145.24411,0.28246
24.44000,11.80433,203.67487,203.67487,145.48205,0.28106
24.48000,11.63129,204.00842,204.00842,145.72030,0.27694
24.52000,11.97103,204.34158,204.34158,145.95827,0.28502
24.56000,12.25155,204.67508,204.67508,146.19648,0.29170
24.60000,12.28303,205.00834,205.00835,146.43453,0.29245
24.64000,12.00642,205.34157,205.34157,146.67255,0.28587
24.68000,12.05076,205.67505,205.67505,146.91075,0.28692
24.72000,12.03623,206.00825,206.00826,147.14875,0.28658
24.76000,11.98817,206.34178,206.34177,147.38698,0.28543
24.80000,12.07814,206.67498,206.67497,147.62498,0.28757
24.84000,11.80470,207.00840,207.00839,147.86314,0.28106
24.88000,12.08931,207.34157,207.34157,148.10113,0.28784
24.92000,12.07814,207.67501,207.67502,148.33930,0.28757
24.96000,12.26105,208.00836,208.00836,148.57740,0.29193
25.00000,12.24577,208.34165,208.34166,148.81546,0.29157
25.04000,12.26924,208.67505,208.67505,149.05361,0.29212
25.08000,12.26347,209.00819,209.00819,149.29156,0.29199
25.12000,12.85132,209.34176,209.34177,149.52983,0.30598
25.16000,12.56969,209.67492,209.67493,149.76780,0.29928
25.20000,12.62799,210.00839,210.00839,150.00600,0.30067
25.24000,12.59446,210.34162,210.34161,150.24401,0.29987
25.28000,12.54529,210.67501,210.67502,150.48215,0.29870
25.32000,12.79861,211.00838,211.00838,150.72027,0.30473
25.36000,12.58645,211.34167,211.34167,150.95834,0.29968
25.40000,12.46408,211.67509,211.67509,151.19649,0.29676
25.44000,12.48270,212.00825,212.00826,151.43447,0.29721
25.48000,12.66394,212.34173,212.34172,151.67266,0.30152
25.52000,12.60173,212.67491,212.67491,151.91065,0.30004
25.56000,12.62538,213.00844,213.00842,152.14888,0.30060
25.60000,12.67344,213.34160,213.34160,152.38686,0.30175
25.64000,12.40466,213.67501,213.67500,152.62500,0.29535
25.68000,12.55684,214.00828,214.00829,152.86306,0.29897
25.72000,12.53113,214.34163,214.34163,153.10116,0.29836
25.76000,13.18138,214.67505,214.67505,153.33931,0.31384
25.80000,12.68275,215.00823,215.00822,153.57730,0.30197
25.84000,13.03274,215.34177,215.34178,153.81556,0.31030
25.88000,12.85169,215.67493,215.67493,154.05352,0.30599
25.92000,13.01095,216.00844,216.00844,154.29175,0.30978
25.96000,12.95116,216.34164,216.34166,154.52975,0.30836
26.00000,12.85598,216.67506,216.67506,154.76791,0.30609
26.04000,12.78277,217.00833,217.00832,155.00594,0.30435
26.08000,13.32108,217.34163,217.34161,155.24402,0.31717
26.12000,12.95321,217.67505,217.67505,155.48218,0.30841
26.16000,12.81574,218.00824,218.00824,155.72017,0.30514
26.20000,13.04969,218.34178,218.34178,155.95841,0.31071
26.24000,13.00890,218.67485,218.67485,156.19632,0.30974
26.28000,12.60396,219.00842,219.00842,156.43458,0.30009
26.32000,12.73099,219.34164,219.34163,156.67260,0.30312
26.36000,12.87740,219.67500,219.67500,156.91072,0.30660
26.40000,12.93104,220.00837,220.00838,157.14884,0.30788
26.44000,12.78501,220.34159,220.34158,157.38685,0.30441
26.48000,13.22199,220.67511,220.67511,157.62508,0.31481
26.52000,13.26110,221.00830,221.00830,157.86307,0.31574
26.56000,13.07819,221.34180,221.34180,158.10128,0.31139
26.60000,13.22143,221.67496,221.67496,158.33925,0.31480
26.64000,13.06571,222.00838,222.00838,158.57742,0.31109
26.68000,12.91707,222.34159,222.34158,158.81542,0.30755
26.72000,13.30879,222.67504,222.67503,159.05360,0.31688
26.76000,13.31922,223.00835,223.00835,159.29168,0.31712
26.80000,13.02417,223.34164,223.34164,159.52975,0.31010
26.84000,12.84927,223.67509,223.67509,159.76793,0.30594
26.88000,12.95563,224.00825,224.00826,160.00589,0.30847
26.92000,13.78693,224.34178,224.34178,160.24413,0.32826
26.96000,13.70050,224.67488,224.67488,160.48206,0.32620
27.00000,13.32890,225.00841,225.00841,160.72029,0.31735
27.04000,13.46413,225.34170,225.34171,160.95836,0.32057
27.08000,13.35312,225.67512,225.67513,161.19652,0.31793
27.12000,13.29966,226.00833,226.00833,161.43452,0.31666
27.16000,13.51815,226.34165,226.34164,161.67260,0.32186
27.20000,13.59154,226.67510,226.67509,161.91078,0.32361
27.24000,13.41477,227.00828,227.00829,162.14877,0.31940
27.28000,13.66735,227.34183,227.34183,162.38703,0.32541
27.32000,13.56527,227.67489,227.67490,162.62492,0.32298
27.36000,13.57589,228.00842,228.00842,162.86316,0.32324
27.40000,13.67647,228.34158,228.34158,163.10112,0.32563
27.44000,13.38609,228.67500,228.67500,163.33928,0.31872
27.48000,13.12550,229.00837,229.00836,163.57740,0.31251
27.52000,13.47456,229.34163,229.34163,163.81545,0.32082
27.56000,13.87931,229.67505,229.67505,164.05361,0.33046
27.60000,13.72620,230.00826,230.00827,164.29162,0.32681
27.64000,13.59656,230.34181,230.34181,164.52987,0.32373
27.68000,13.53752,230.67492,230.67493,164.76780,0.32232
27.72000,13.45053,231.00840,231.00839,165.00599,0.32025
27.76000,13.61109,231.34163,231.34163,165.24402,0.32407
27.80000,13.61798,231.67508,231.67508,165.48220,0.32424
27.84000,13.49989,232.00840,232.00839,165.72028,0.32143
27.88000,13.83144,232.34166,232.34166,165.95833,0.32932
27.92000,14.15014,232.67508,232.67508,166.19649,0.33691
27.96000,13.69826,233.00819,233.00819,166.43442,0.32615
28.00000,13.65785,233.34174,233.34174,166.67267,0.32519
28.04000,13.45985,233.67495,233.67496,166.91068,0.32047
28.08000,13.59135,234.00845,234.00845,167.14890,0.32360
28.12000,14.14828,234.34161,234.34161,167.38687,0.33686
28.16000,14.14977,234.67498,234.67499,167.62499,0.33690
28.20000,14.13450,235.00835,235.00835,167.86311,0.33654
28.24000,14.32560,235.34172,235.34172,168.10123,0.34109
28.28000,13.96723,235.67509,235.67509,168.33935,0.33255
28.32000,13.92607,236.00825,236.00826,168.57733,0.33157
28.36000,14.38335,236.34180,236.34180,168.81558,0.34246
28.40000,13.85212,236.67493,236.67494,169.05353,0.32981
28.44000,14.15238,237.00849,237.00848,169.29177,0.33696
28.48000,14.07694,237.34157,237.34157,169.52969,0.33517
28.52000,13.98660,237.67499,237.67499,169.76784,0.33301
28.56000,14.49957,238.00831,238.00830,170.00593,0.34523
28.60000,14.04621,238.34165,238.34164,170.24404,0.33443
28.64000,13.90129,238.67512,238.67513,170.48223,0.33098
28.68000,14.28518,239.00826,239.00826,170.72018,0.34012
28.72000,14.03410,239.34175,239.34175,170.95840,0.33415
28.76000,14.35950,239.67489,239.67488,171.19635,0.34189
28.80000,14.39527,240.00847,240.00847,171.43462,0.34274
28.84000,14.72663,240.34168,240.34167,171.67263,0.35063
28.88000,14.34404,240.67505,240.67505,171.91075,0.34152
28.92000,14.59774,241.00834,241.00833,172.14881,0.34757
28.96000,14.56030,241.34165,241.34166,172.38690,0.34667
29.00000,14.51615,241.67513,241.67513,172.62509,0.34562
29.04000,14.75085,242.00826,242.00826,172.86304,0.35121
29.08000,14.69832,242.34179,242.34178,173.10128,0.34996
29.12000,14.33678,242.67487,242.67487,173.33919,0.34135
29.16000,14.75979,243.00839,243.00839,173.57743,0.35142
29.20000,14.22632,243.34166,243.34166,173.81546,0.33872
29.24000,14.54093,243.67505,243.67505,174.05361,0.34621
29.28000,14.56253,244.00837,244.00838,174.29169,0.34673
29.32000,14.76333,244.34161,244.34161,174.52972,0.35151
29.36000,14.80263,244.67503,244.67503,174.76788,0.35244
29.40000,14.74898,245.00829,245.00830,175.00592,0.35117
29.44000,15.01217,245.34179,245.34180,175.24414,0.35743
29.48000,14.84677,245.67493,245.67493,175.48209,0.35349
29.52000,14.66516,246.00840,246.00839,175.72029,0.34917
29.56000,15.12580,246.34161,246.34161,175.95830,0.36014
29.60000,14.76649,246.67511,246.67511,176.19650,0.35158
29.64000,14.59215,247.00840,247.00841,176.43458,0.34743
29.68000,14.84808,247.34161,247.34161,176.67258,0.35353
29.72000,14.98312,247.67504,247.67503,176.91073,0.35674
29.76000,14.76109,248.00825,248.00826,177.14875,0.35145
29.80000,14.93301,248.34180,248.34180,177.38700,0.35555
29.84000,14.47946,248.67493,248.67493,177.62495,0.34475
29.88000,14.64523,249.00843,249.00844,177.86317,0.34870
29.92000,14.95592,249.34162,249.34161,178.10116,0.35609
29.96000,14.86894,249.67507,249.67506,178.33934,0.35402
30.00000,15.00770,250.00833,250.00833,178.57738,0.35733
30.04000,15.57767,250.34165,250.34164,178.81546,0.37090
30.08000,15.21930,250.67509,250.67509,179.05364,0.36236
30.12000,15.21427,251.00825,251.00826,179.29161,0.36224
30.16000,15.08966,251.34180,251.34181,179.52986,0.35928
30.20000,15.25879,251.67494,251.67494,179.76781,0.36330
30.24000,15.19155,252.00841,252.00841,180.00600,0.36170
30.28000,15.28598,252.34160,252.34160,180.24399,0.36395
30.32000,15.19043,252.67502,252.67502,180.48216,0.36168
30.36000,15.33721,253.00839,253.00839,180.72028,0.36517
30.40000,15.48938,253.34165,253.34166,180.95832,0.36879
30.44000,14.99318,253.67505,253.67505,181.19646,0.35698
30.48000,15.09264,254.00829,254.00829,181.43449,0.35935
30.52000,15.40501,254.34173,254.34174,181.67267,0.36679
30.56000,15.45362,254.67495,254.67494,181.91067,0.36794
30.60000,15.81628,255.00844,255.00844,182.14889,0.37658
30.64000,15.65535,255.34163,255.34163,182.38688,0.37275
30.68000,15.47392,255.67503,255.67502,182.62502,0.36843
30.72000,15.69763,256.00837,256.00836,182.86312,0.37375
30.76000,15.32827,256.34166,256.34164,183.10119,0.36496
30.80000,15.37781,256.67508,256.67508,183.33935,0.36614
30.84000,15.45083,257.00824,257.00824,183.57731,0.36788
30.88000,15.39253,257.34176,257.34177,183.81555,0.36649
30.92000,15.18670,257.67495,257.67496,184.05354,0.36159
30.96000,15.50280,258.00842,258.00842,184.29173,0.36911
31.00000,15.20347,258.34158,258.34158,184.52970,0.36199
31.04000,15.80287,258.67506,258.67505,184.76790,0.37626
31.08000,15.77605,259.00835,259.00836,185.00596,0.37562
31.12000,15.88278,259.34169,259.34171,185.24406,0.37816
31.16000,15.72799,259.67506,259.67505,185.48218,0.37448
31.20000,15.60878,260.00819,260.00818,185.72013,0.37164
31.24000,15.55085,260.34177,260.34177,185.95841,0.37026
31.28000,16.03123,260.67493,260.67493,186.19637,0.38170
31.32000,15.62424,261.00851,261.00851,186.43465,0.37201
31.36000,15.67304,261.34164,261.34164,186.67260,0.37317
31.40000,15.69912,261.67504,261.67505,186.91074,0.37379
31.44000,15.76543,262.00835,262.00836,187.14882,0.37537
31.48000,15.89861,262.34167,262.34167,187.38691,0.37854
31.52000,15.89004,262.67509,262.67508,187.62506,0.37833
31.56000,15.83658,263.00825,263.00824,187.86304,0.37706
31.60000,15.72464,263.34178,263.34177,188.10127,0.37440
31.64000,15.89023,263.67494,263.67493,188.33925,0.37834
31.68000,16.04091,264.00846,264.00845,188.57747,0.38193
31.72000,16.20147,264.34162,264.34161,188.81545,0.38575
31.76000,16.39128,264.67499,264.67499,189.05356,0.39027
31.80000,16.37693,265.00836,265.00836,189.29169,0.38993
31.84000,16.50099,265.34165,265.34164,189.52975,0.39288
31.88000,16.27747,265.67515,265.67514,189.76797,0.38756
31.92000,16.27579,266.00831,266.00830,190.00593,0.38752
31.96000,16.43188,266.34176,266.34177,190.24411,0.39124
32.00000,16.38196,266.67492,266.67493,190.48208,0.39005
32.04000,16.02527,267.00842,267.00842,190.72030,0.38155
32.08000,16.10201,267.34165,267.34164,190.95832,0.38338
32.12000,16.55221,267.67502,267.67502,191.19644,0.39410
32.16000,16.34657,268.00834,268.00833,191.43453,0.38920
32.20000,16.20632,268.34160,268.34161,191.67258,0.38586
32.24000,16.24133,268.67505,268.67505,191.91076,0.38670
32.28000,16.58332,269.00832,269.00833,192.14879,0.39484
32.32000,16.47845,269.34184,269.34183,192.38703,0.39234
32.36000,16.73605,269.67487,269.67487,192.62490,0.39848
32.40000,16.55053,270.00842,270.00842,192.86315,0.39406
32.44000,16.71147,270.34163,270.34164,193.10117,0.39789
32.48000,16.92213,270.67511,270.67511,193.33936,0.40291
32.52000,16.87743,271.00837,271.00836,193.57741,0.40184
32.56000,16.64143,271.34158,271.34158,193.81542,0.39622
32.60000,16.77945,271.67508,271.67508,194.05363,0.39951
32.64000,16.60604,272.00827,272.00827,194.29162,0.39538
32.68000,16.71407,272.34182,272.34183,194.52987,0.39795
32.72000,16.50322,272.67493,272.67493,194.76781,0.39293
32.76000,16.59468,273.00838,273.00836,195.00599,0.39511
32.80000,16.54774,273.34161,273.34161,195.24401,0.39399
32.84000,16.47901,273.67506,273.67505,195.48218,0.39236
32.88000,16.83775,274.00838,274.00839,195.72027,0.40090
32.92000,17.10746,274.34170,274.34171,195.95835,0.40732
32.96000,17.23580,274.67509,274.67508,196.19650,0.41038
33.00000,17.10895,275.00825,275.00824,196.43446,0.40736
33.04000,17.28274,275.34180,275.34180,196.67271,0.41149
33.08000,17.72195,275.67491,275.67490,196.91064,0.42195
33.12000,17.24027,276.00841,276.00842,197.14886,0.41048
33.16000,17.11138,276.34162,276.34161,197.38687,0.40741
33.20000,17.46342,276.67502,276.67502,197.62502,0.41580
33.24000,16.95976,277.00836,277.00836,197.86311,0.40380
33.28000,17.40623,277.34165,277.34164,198.10117,0.41443
33.32000,17.26281,277.67507,277.67508,198.33933,0.41102
33.36000,17.35520,278.00828,278.00827,198.57734,0.41322
33.40000,17.49787,278.34176,278.34177,198.81554,0.41662
33.44000,17.50272,278.67497,278.67496,199.05355,0.41673
33.48000,17.21513,279.00847,279.00845,199.29177,0.40988
33.52000,17.49732,279.34163,279.34161,199.52973,0.41660
33.56000,17.47720,279.67500,279.67499,199.76785,0.41612
33.60000,17.35967,280.00834,280.00833,200.00596,0.41333
33.64000,17.50197,280.34166,280.34164,200.24405,0.41671
33.68000,17.79068,280.67510,280.67514,200.48223,0.42359
33.72000,17.49601,281.00829,281.00830,200.72021,0.41657
33.76000,17.73573,281.34174,281.34171,200.95837,0.42228
33.80000,17.57555,281.67492,281.67496,201.19638,0.41847
33.84000,17.44293,282.00845,282.00845,201.43461,0.41531
33.88000,17.72381,282.34163,282.34164,201.67260,0.42200
33.92000,17.92330,282.67508,282.67511,201.91078,0.42675
33.96000,17.41108,283.00834,283.00833,202.14882,0.41455
34.00000,17.40009,283.34169,283.34167,202.38693,0.41429
34.04000,17.51687,283.67508,283.67508,202.62506,0.41707
34.08000,17.64875,284.00824,284.00824,202.86303,0.42021
34.12000,17.98514,284.34177,284.34177,203.10125,0.42822
34.16000,18.12112,284.67490,284.67490,203.33922,0.43146
34.20000,17.95199,285.00845,285.00845,203.57747,0.42743
34.24000,17.86649,285.34164,285.34164,203.81546,0.42539
34.28000,17.83129,285.67503,285.67505,204.05359,0.42455
34.32000,17.91231,286.00835,286.00836,204.29168,0.42648
34.36000,17.82365,286.34164,286.34164,204.52974,0.42437
34.40000,17.72586,286.67511,286.67511,204.76794,0.42204
34.44000,17.44051,287.00833,287.00833,205.00596,0.41525
34.48000,17.31589,287.34175,287.34174,205.24411,0.41228
34.52000,17.81452,287.67491,287.67490,205.48208,0.42416
34.56000,17.52656,288.00846,288.00845,205.72033,0.41730
34.60000,17.14379,288.34162,288.34161,205.95829,0.40819
34.64000,9.38587,288.67504,288.67505,206.19645,0.22347
34.68000,0.03260,289.00836,289.00836,206.43454,0.00078
34.68200,-0.01024,289.02505,289.02505,206.44646,-0.00024