File: raw_data/mechanical_tests_Instron_data/Aslan_Test1_a_1.is_tcyclic_RawData/Specimen_RawData_1.csv
Time,Extension,Extensometer Strain 1,Load,Tensile strain,True strain,Displacement (Strain 1)
(sec),(mm),(mm/mm),(N),(mm/mm),(mm/mm),(mm)
0.00000,-2.97479,-0.00014,0.11157,-0.02928,-0.02972,-0.00175
0.05400,-2.86770,-0.00014,1.00788,-0.02823,-0.02863,-0.00178
0.10800,-2.50645,-0.00014,1.71475,-0.02467,-0.02498,-0.00175
0.16200,-1.98437,-0.00014,2.22269,-0.01953,-0.01972,-0.00174
0.21600,-1.43194,-0.00014,2.32197,-0.01409,-0.01419,-0.00176
0.27000,-0.86529,-0.00014,2.69469,-0.00852,-0.00855,-0.00172
0.32400,-0.30265,-0.00014,2.32570,-0.00298,-0.00298,-0.00172
0.37800,0.16323,-0.00014,1.96397,0.00161,0.00161,-0.00178
0.43200,0.61122,-0.00014,1.78441,0.00602,0.00600,-0.00172
0.48600,1.06460,-0.00014,2.25566,0.01048,0.01042,-0.00175
0.54000,1.51462,-0.00014,2.18730,0.01491,0.01480,-0.00174
0.59400,1.96470,-0.00014,2.24840,0.01934,0.01915,-0.00174
0.64800,2.41468,-0.00014,2.46670,0.02377,0.02349,-0.00171
0.70200,2.86454,-0.00014,2.43466,0.02819,0.02780,-0.00178
0.75600,3.31441,-0.00014,2.40970,0.03262,0.03210,-0.00171
0.81000,3.76427,-0.00014,2.72896,0.03705,0.03638,-0.00172
0.86400,4.21411,-0.00014,2.44193,0.04148,0.04064,-0.00175
0.91800,4.66385,-0.00014,2.57343,0.04590,0.04488,-0.00173
0.97200,5.11369,-0.00014,2.63527,0.05033,0.04911,-0.00174
1.02600,5.56344,-0.00014,2.67997,0.05476,0.05331,-0.00176
1.08000,6.01315,-0.00014,2.54847,0.05918,0.05750,-0.00173
1.13400,6.46304,-0.00014,2.29590,0.06361,0.06167,-0.00174
1.18800,6.91291,-0.00014,2.62056,0.06804,0.06583,-0.00178
1.24200,7.36277,-0.00014,2.37711,0.07247,0.06996,-0.00174
1.29600,7.81259,-0.00014,3.06200,0.07690,0.07408,-0.00175
1.35000,8.26248,-0.00014,2.69059,0.08132,0.07819,-0.00175
1.40400,8.71232,-0.00014,2.85506,0.08575,0.08227,-0.00175
1.45800,9.16210,-0.00014,2.64626,0.09018,0.08634,-0.00172
1.51200,9.61184,-0.00014,2.47005,0.09460,0.09039,-0.00175
1.56600,10.06162,-0.00014,2.69003,0.09903,0.09443,-0.00173
1.62000,10.51143,-0.00014,3.04077,0.10346,0.09845,-0.00175
1.67400,10.96122,-0.00014,2.71648,0.10789,0.10245,-0.00177
1.72800,11.41116,-0.00014,2.68184,0.11231,0.10644,-0.00175
1.78200,11.86095,-0.00014,2.82843,0.11674,0.11042,-0.00175
1.83600,12.31084,-0.00014,2.98824,0.12117,0.11437,-0.00177
1.89000,12.76063,-0.00014,2.80775,0.12560,0.11831,-0.00173
1.94400,13.21055,-0.00014,2.98787,0.13003,0.12224,-0.00175
1.99800,13.66025,-0.00014,2.94596,0.13445,0.12615,-0.00174
2.05200,14.11004,-0.00014,3.05530,0.13888,0.13004,-0.00176
2.10600,14.55977,-0.00014,2.92752,0.14330,0.13392,-0.00173
2.16000,15.00966,-0.00014,2.87667,0.14773,0.13779,-0.00177
2.21400,15.45942,-0.00014,2.73902,0.15216,0.14164,-0.00173
2.26800,15.90926,-0.00014,3.00854,0.15659,0.14547,-0.00177
2.32200,16.35923,-0.00014,2.76528,0.16102,0.14930,-0.00172
2.37600,16.80902,-0.00014,2.92044,0.16544,0.15310,-0.00178
2.43000,17.25886,-0.00014,3.36468,0.16987,0.15689,-0.00175
2.48400,17.70870,-0.00014,3.04040,0.17430,0.16067,-0.00177
2.53800,18.15851,-0.00014,3.08640,0.17873,0.16443,-0.00174
2.59200,18.60819,-0.00014,3.09795,0.18315,0.16818,-0.00175
2.64600,19.05797,-0.00014,3.17376,0.18758,0.17192,-0.00171
2.70000,19.50787,-0.00014,3.15160,0.19201,0.17564,-0.00177
2.75400,19.95768,-0.00014,2.98247,0.19643,0.17935,-0.00173
2.80800,20.40749,-0.00014,3.27360,0.20086,0.18304,-0.00179
2.86200,20.85733,-0.00014,3.01693,0.20529,0.18672,-0.00175
2.91600,21.30730,-0.00014,3.02903,0.20972,0.19039,-0.00178
2.97000,21.75709,-0.00014,3.12310,0.21414,0.19404,-0.00172
3.02400,22.20687,-0.00014,3.21940,0.21857,0.19768,-0.00178
3.07800,22.65666,-0.00014,3.44012,0.22300,0.20131,-0.00173
3.13200,23.10642,-0.00014,3.48724,0.22743,0.20492,-0.00179
3.18600,23.55618,-0.00014,3.35351,0.23185,0.20852,-0.00173
3.24000,24.00596,-0.00014,3.45744,0.23628,0.21211,-0.00176
3.29400,24.45585,-0.00014,3.25851,0.24071,0.21568,-0.00172
3.34800,24.90575,-0.00014,3.69623,0.24514,0.21924,-0.00178
3.40200,25.35556,-0.00014,3.29427,0.24956,0.22279,-0.00174
3.45600,25.80543,-0.00014,3.42689,0.25399,0.22633,-0.00178
3.51000,26.25532,-0.00014,3.07001,0.25842,0.22986,-0.00171
3.56400,26.70510,-0.00014,3.12626,0.26285,0.23337,-0.00176
3.61800,27.15478,-0.00014,3.04207,0.26727,0.23687,-0.00171
3.67200,27.60473,-0.00014,3.34438,0.27170,0.24035,-0.00178
3.72600,28.05441,-0.00014,3.40231,0.27613,0.24383,-0.00173
3.78000,28.50422,-0.00014,3.26224,0.28055,0.24729,-0.00178
3.83400,28.95398,-0.00014,3.23094,0.28498,0.25074,-0.00173
3.88800,29.40395,-0.00014,3.56790,0.28941,0.25418,-0.00180
3.94200,29.85376,-0.00014,3.21809,0.29384,0.25761,-0.00174
3.99600,30.30363,-0.00014,3.56827,0.29826,0.26103,-0.00179
4.05000,30.75352,-0.00014,3.35127,0.30269,0.26443,-0.00173
4.10400,31.20331,-0.00014,3.13856,0.30712,0.26783,-0.00178
4.15800,31.65307,-0.00014,2.96012,0.31155,0.27121,-0.00173
4.21200,32.10282,-0.00014,3.08566,0.31597,0.27458,-0.00177
4.26600,32.55261,-0.00014,3.51761,0.32040,0.27793,-0.00174
4.32000,33.00234,-0.00014,3.20375,0.32483,0.28128,-0.00177
4.37400,33.45223,-0.00014,3.32203,0.32925,0.28462,-0.00175
4.42800,33.90216,-0.00014,3.53903,0.33368,0.28794,-0.00178
4.48200,34.35194,-0.00014,3.27807,0.33811,0.29126,-0.00171
4.53600,34.80183,-0.00014,3.68636,0.34254,0.29456,-0.00177
4.59000,35.25167,-0.00014,3.42261,0.34697,0.29785,-0.00174
4.64400,35.70151,-0.00014,3.32594,0.35139,0.30114,-0.00177
4.69800,36.15132,-0.00014,3.42745,0.35582,0.30441,-0.00174
4.75200,36.60108,-0.00014,3.27639,0.36025,0.30767,-0.00175
4.80600,37.05079,-0.00014,2.99048,0.36467,0.31091,-0.00171
4.86000,37.50060,-0.00014,3.72883,0.36910,0.31415,-0.00179
4.91400,37.95038,-0.00014,3.60440,0.37353,0.31738,-0.00175
4.96800,38.40025,-0.00014,3.48072,0.37796,0.32060,-0.00180
5.02200,38.85020,-0.00014,3.05045,0.38238,0.32381,-0.00174
5.07600,39.30003,-0.00014,3.28459,0.38681,0.32701,-0.00179
5.13000,39.74982,-0.00014,3.29353,0.39124,0.33019,-0.00175
5.18400,40.19974,-0.00014,3.12757,0.39567,0.33337,-0.00176
5.23800,40.64953,-0.00014,2.97464,0.40009,0.33654,-0.00175
5.29200,41.09923,-0.00014,3.21418,0.40452,0.33970,-0.00177
5.34600,41.54899,-0.00014,2.78633,0.40895,0.34284,-0.00172
5.40000,41.99888,-0.00014,2.93199,0.41337,0.34598,-0.00178
5.45400,42.44862,-0.00014,3.06610,0.41780,0.34911,-0.00174
5.50800,42.89845,-0.00014,3.05381,0.42223,0.35223,-0.00177
5.56200,43.34829,-0.00014,3.44329,0.42666,0.35533,-0.00174
5.61600,43.79827,-0.00014,3.13316,0.43109,0.35843,-0.00177
5.67000,44.24802,-0.00014,3.25348,0.43551,0.36152,-0.00173
5.72400,44.69792,-0.00014,3.28645,0.43994,0.36460,-0.00178
5.77800,45.14773,-0.00014,3.04338,0.44437,0.36767,-0.00171
5.83200,45.59749,-0.00014,2.88263,0.44879,0.37073,-0.00176
5.88600,46.04722,-0.00013,3.08547,0.45322,0.37378,-0.00171
5.94000,46.49700,-0.00014,3.00165,0.45765,0.37682,-0.00175
5.99400,46.94685,-0.00014,2.77981,0.46208,0.37986,-0.00177
6.04800,47.39668,-0.00014,3.26112,0.46650,0.38288,-0.00178
6.10200,47.84652,-0.00014,3.15495,0.47093,0.38590,-0.00175
6.15600,48.29636,-0.00014,2.98787,0.47536,0.38890,-0.00176
6.21000,48.74631,-0.00014,3.36803,0.47979,0.39190,-0.00174
6.26400,49.19612,-0.00014,3.11788,0.48421,0.39489,-0.00177
6.31800,49.64585,-0.00014,3.54256,0.48864,0.39786,-0.00174
6.37200,50.09572,-0.00014,3.52375,0.49307,0.40083,-0.00175
6.42600,50.54545,-0.00014,2.98731,0.49749,0.40379,-0.00174
6.48000,50.99524,-0.00014,3.17898,0.50192,0.40675,-0.00178
6.53400,51.44499,-0.00014,3.10689,0.50635,0.40969,-0.00174
6.58800,51.89489,-0.00014,2.97036,0.51078,0.41262,-0.00178
6.64200,52.34470,-0.00014,3.19500,0.51520,0.41555,-0.00174
6.69600,52.79456,-0.00014,3.67519,0.51963,0.41847,-0.00178
6.75000,53.24451,-0.00014,3.17711,0.52406,0.42138,-0.00175
6.80400,53.69432,-0.00014,3.29148,0.52849,0.42428,-0.00176
6.85800,54.14408,-0.00014,3.20133,0.53291,0.42717,-0.00172
6.91200,54.59384,-0.00014,3.26037,0.53734,0.43005,-0.00174
6.96600,55.04368,-0.00014,3.00352,0.54177,0.43293,-0.00172
7.02000,55.49344,-0.00014,3.14210,0.54620,0.43580,-0.00176
7.07400,55.94320,-0.00014,2.92193,0.55062,0.43866,-0.00176
7.12800,56.39309,-0.00014,3.04952,0.55505,0.44151,-0.00175
7.18200,56.84288,-0.00014,2.90591,0.55948,0.44435,-0.00175
7.23600,57.29282,-0.00014,3.17302,0.56391,0.44719,-0.00174
7.29000,57.74263,-0.00014,3.01227,0.56833,0.45001,-0.00174
7.34400,58.19253,-0.00014,3.33842,0.57276,0.45283,-0.00173
7.39800,58.64231,-0.00014,2.85562,0.57719,0.45564,-0.00173
7.45200,59.09210,-0.00014,2.90386,0.58162,0.45845,-0.00174
7.50600,59.54186,-0.00013,2.94223,0.58604,0.46124,-0.00170
7.56000,59.99164,-0.00014,2.78112,0.59047,0.46403,-0.00174
7.61400,60.44146,-0.00014,3.09106,0.59490,0.46681,-0.00173
7.66800,60.89119,-0.00014,3.00854,0.59932,0.46958,-0.00177
7.72200,61.34116,-0.00014,2.45646,0.60375,0.47235,-0.00176
7.77600,61.79103,-0.00014,2.95173,0.60818,0.47510,-0.00176
7.83000,62.24089,-0.00014,3.05120,0.61261,0.47785,-0.00175
7.88400,62.69065,-0.00014,2.77068,0.61703,0.48059,-0.00173
7.93800,63.14051,-0.00014,3.02028,0.62146,0.48333,-0.00176
7.99200,63.59030,-0.00014,3.30154,0.62589,0.48605,-0.00172
8.04600,64.04003,-0.00014,3.16221,0.63032,0.48877,-0.00175
8.10000,64.48988,-0.00014,2.94801,0.63474,0.49149,-0.00175
8.15400,64.93966,-0.00014,2.99960,0.63917,0.49419,-0.00175
8.20800,65.38942,-0.00014,3.55057,0.64360,0.49689,-0.00175
8.26200,65.83931,-0.00014,3.43733,0.64802,0.49958,-0.00175
8.31600,66.28922,-0.00014,3.48892,0.65245,0.50226,-0.00173
8.37000,66.73904,-0.00014,3.67351,0.65688,0.50494,-0.00177
8.42400,67.18887,-0.00014,3.89833,0.66131,0.50761,-0.00176
8.47800,67.63874,-0.00014,3.79570,0.66574,0.51027,-0.00174
8.53200,68.08847,-0.00014,3.81973,0.67016,0.51292,-0.00172
8.58600,68.53826,-0.00014,3.83146,0.67459,0.51557,-0.00174
8.64000,68.98802,-0.00014,4.00562,0.67902,0.51821,-0.00174
8.69400,69.43784,-0.00014,4.09838,0.68344,0.52084,-0.00175
8.74800,69.88767,-0.00014,4.09335,0.68787,0.52347,-0.00175
8.80200,70.33751,-0.00014,3.94508,0.69230,0.52609,-0.00178
8.85600,70.78740,-0.00014,4.10117,0.69673,0.52870,-0.00173
8.91000,71.23727,-0.00014,4.10471,0.70115,0.53131,-0.00175
8.96400,71.68705,-0.00014,3.83798,0.70558,0.53391,-0.00174
9.01800,72.13687,-0.00014,3.83947,0.71001,0.53650,-0.00174
9.07200,72.58674,-0.00014,4.08217,0.71444,0.53908,-0.00171
9.12600,73.03644,-0.00014,4.16525,0.71886,0.54166,-0.00175
9.18000,73.48623,-0.00013,4.01922,0.72329,0.54424,-0.00171
9.23400,73.93598,-0.00014,4.24795,0.72772,0.54680,-0.00176
9.28800,74.38587,-0.00014,4.16674,0.73214,0.54936,-0.00174
9.34200,74.83569,-0.00014,4.45172,0.73657,0.55191,-0.00174
9.39600,75.28556,-0.00014,4.52921,0.74100,0.55446,-0.00175
9.45000,75.73553,-0.00014,3.86965,0.74543,0.55700,-0.00175
9.50400,76.18534,-0.00014,4.34481,0.74986,0.55953,-0.00173
9.55800,76.63510,-0.00014,4.23286,0.75428,0.56206,-0.00176
9.61200,77.08486,-0.00014,4.23361,0.75871,0.56458,-0.00173
9.66600,77.53472,-0.00014,4.08627,0.76314,0.56709,-0.00176
9.72000,77.98435,-0.00014,4.13824,0.76756,0.56960,-0.00174
9.77400,78.43424,-0.00014,4.17829,0.77199,0.57210,-0.00178
9.82800,78.88408,-0.00014,4.11011,0.77642,0.57460,-0.00175
9.88200,79.33392,-0.00014,4.31389,0.78085,0.57709,-0.00179
9.93600,79.78376,-0.00014,4.27142,0.78527,0.57957,-0.00177
9.99000,80.23362,-0.00014,4.05926,0.78970,0.58205,-0.00179
10.04400,80.68354,-0.00014,4.34518,0.79413,0.58452,-0.00176
10.09800,81.13335,-0.00014,4.36362,0.79856,0.58698,-0.00176
10.15200,81.58308,-0.00014,4.43198,0.80298,0.58944,-0.00175
10.20600,82.03285,-0.00014,4.22020,0.80741,0.59189,-0.00175
10.26000,82.48263,-0.00014,4.61023,0.81184,0.59434,-0.00176
10.31400,82.93245,-0.00014,4.28446,0.81626,0.59678,-0.00179
10.36800,83.38218,-0.00014,4.53666,0.82069,0.59922,-0.00177
10.42200,83.83212,-0.00014,4.20474,0.82512,0.60165,-0.00179
10.47600,84.28198,-0.00014,4.29172,0.82955,0.60407,-0.00174
10.53000,84.73188,-0.00014,4.32469,0.83398,0.60649,-0.00178
10.58400,85.18166,-0.00014,3.89945,0.83840,0.60890,-0.00175
10.63800,85.63158,-0.00014,4.35468,0.84283,0.61130,-0.00178
10.69200,86.08131,-0.00014,4.51226,0.84726,0.61370,-0.00173
10.74600,86.53099,-0.00014,3.95402,0.85168,0.61609,-0.00179
10.80000,86.98086,-0.00014,3.91100,0.85611,0.61848,-0.00174
10.85400,87.43068,-0.00014,4.02816,0.86054,0.62087,-0.00178
10.90800,87.88043,-0.00014,4.44930,0.86496,0.62324,-0.00176
10.96200,88.33024,-0.00014,4.24348,0.86939,0.62561,-0.00179
11.01600,88.78019,-0.00014,3.93167,0.87382,0.62798,-0.00176
11.07000,89.23006,-0.00014,4.44688,0.87825,0.63034,-0.00180
11.12400,89.67989,-0.00014,4.42471,0.88268,0.63269,-0.00174
11.17800,90.12979,-0.00014,4.31240,0.88710,0.63504,-0.00178
11.23200,90.57952,-0.00014,4.14569,0.89153,0.63739,-0.00173
11.28600,91.02931,-0.00014,4.28353,0.89596,0.63972,-0.00178
11.34000,91.47902,-0.00014,4.17717,0.90038,0.64206,-0.00176
11.39400,91.92885,-0.00014,4.06522,0.90481,0.64438,-0.00179
11.44800,92.37861,-0.00014,4.15836,0.90924,0.64670,-0.00173
11.50200,92.82850,-0.00014,4.35058,0.91367,0.64902,-0.00180
11.55600,93.27834,-0.00014,4.22746,0.91809,0.65133,-0.00173
11.61000,93.72827,-0.00014,4.33549,0.92252,0.65364,-0.00177
11.66400,94.17810,-0.00014,4.70188,0.92695,0.65594,-0.00174
11.71800,94.62794,-0.00014,4.47631,0.93138,0.65823,-0.00180
11.77200,95.07773,-0.00014,4.19021,0.93580,0.66052,-0.00174
11.82600,95.52754,-0.00014,4.56348,0.94023,0.66281,-0.00179
11.88000,95.97725,-0.00014,4.02611,0.94466,0.66509,-0.00173
11.93400,96.42703,-0.00014,4.29079,0.94908,0.66736,-0.00178
11.98800,96.87684,-0.00014,3.65246,0.95351,0.66963,-0.00175
12.04200,97.32668,-0.00014,4.19579,0.95794,0.67189,-0.00180
12.09600,97.77652,-0.00014,4.32879,0.96237,0.67415,-0.00175
12.15000,98.22646,-0.00014,4.19114,0.96680,0.67641,-0.00179
12.20400,98.67630,-0.00014,4.28911,0.97122,0.67865,-0.00174
12.25800,99.12611,-0.00014,4.19728,0.97565,0.68090,-0.00179
12.31200,99.57590,-0.00014,4.02797,0.98008,0.68314,-0.00175
12.36600,100.02579,-0.00014,4.39733,0.98451,0.68537,-0.00178
12.42000,100.47544,-0.00014,4.27142,0.98893,0.68760,-0.00176
12.47400,100.92521,-0.00014,4.34183,0.99336,0.68982,-0.00180
12.52800,101.37504,-0.00014,4.38523,0.99779,0.69204,-0.00173
12.58200,101.82490,-0.00014,3.84320,1.00221,0.69425,-0.00178
12.63600,102.27472,-0.00014,4.22299,1.00664,0.69646,-0.00172
12.69000,102.72461,-0.00014,4.33400,1.01107,0.69867,-0.00179
12.74400,103.17448,-0.00014,4.19300,1.01550,0.70087,-0.00175
12.79800,103.62429,-0.00014,4.12650,1.01992,0.70306,-0.00178
12.85200,104.07415,-0.00014,4.34052,1.02435,0.70525,-0.00173
12.90600,104.52395,-0.00014,4.16376,1.02878,0.70743,-0.00178
12.96000,104.97370,-0.00014,4.23286,1.03321,0.70961,-0.00174
13.01400,105.42343,-0.00014,4.29917,1.03763,0.71179,-0.00180
13.06800,105.87319,-0.00014,4.05312,1.04206,0.71396,-0.00177
13.12200,106.32313,-0.00014,4.34797,1.04649,0.71612,-0.00180
13.17600,106.77295,-0.00014,4.29731,1.05091,0.71829,-0.00176
13.23000,107.22284,-0.00014,4.30532,1.05534,0.72044,-0.00179
13.28400,107.67263,-0.00014,4.23901,1.05977,0.72259,-0.00175
13.33800,108.12255,-0.00014,4.17195,1.06420,0.72474,-0.00180
13.39200,108.57233,-0.00014,4.22597,1.06863,0.72688,-0.00174
13.44600,109.02206,-0.00014,3.85642,1.07305,0.72902,-0.00180
13.50000,109.47188,-0.00014,4.39472,1.07748,0.73116,-0.00174
13.55400,109.92169,-0.00014,3.97824,1.08191,0.73328,-0.00179
13.60800,110.37144,-0.00014,4.11700,1.08633,0.73541,-0.00176
13.66200,110.82126,-0.00014,4.17717,1.09076,0.73753,-0.00179
13.71600,111.27120,-0.00014,4.24627,1.09519,0.73964,-0.00176
13.77000,111.72099,-0.00014,4.36995,1.09962,0.74175,-0.00180
13.82400,112.17084,-0.00014,3.96799,1.10404,0.74386,-0.00176
13.87800,112.62076,-0.00014,3.98923,1.10847,0.74596,-0.00178
13.93200,113.07053,-0.00014,3.99761,1.11290,0.74806,-0.00176
13.98600,113.52030,-0.00014,4.14830,1.11733,0.75015,-0.00178
14.04000,113.97003,-0.00014,4.04418,1.12175,0.75224,-0.00174
14.09400,114.41989,-0.00014,4.15593,1.12618,0.75433,-0.00181
14.14800,114.86968,-0.00014,4.48544,1.13061,0.75641,-0.00175
14.20200,115.31949,-0.00014,4.30178,1.13503,0.75848,-0.00178
14.25600,115.76935,-0.00014,4.46457,1.13946,0.76055,-0.00175
14.31000,116.21920,-0.00014,4.23025,1.14389,0.76262,-0.00178
14.36400,116.66911,-0.00014,4.27552,1.14832,0.76469,-0.00174
14.41800,117.11890,-0.00014,4.21330,1.15275,0.76674,-0.00180
14.47200,117.56874,-0.00014,4.49289,1.15717,0.76880,-0.00175
14.52600,118.01849,-0.00014,4.13805,1.16160,0.77085,-0.00179
14.58000,118.46826,-0.00014,4.26881,1.16603,0.77289,-0.00174
14.63400,118.91805,-0.00014,4.57503,1.17045,0.77494,-0.00179
14.68800,119.36786,-0.00014,4.71361,1.17488,0.77697,-0.00177
14.74200,119.81769,-0.00014,4.27738,1.17931,0.77901,-0.00179
14.79600,120.26751,-0.00014,4.19803,1.18374,0.78104,-0.00178
14.85000,120.71745,-0.00014,4.43403,1.18816,0.78306,-0.00179
14.90400,121.16732,-0.00014,4.48972,1.19259,0.78508,-0.00175
14.95800,121.61712,-0.00014,4.23100,1.19702,0.78710,-0.00179
15.01200,122.06689,-0.00014,4.42583,1.20145,0.78911,-0.00176
15.06600,122.51673,-0.00014,4.48693,1.20587,0.79112,-0.00178
15.12000,122.96645,-0.00014,4.52101,1.21030,0.79313,-0.00176
15.17400,123.41622,-0.00014,4.65680,1.21473,0.79513,-0.00179
15.22800,123.86603,-0.00014,4.42378,1.21915,0.79713,-0.00178
15.28200,124.31590,-0.00014,4.69927,1.22358,0.79912,-0.00178
15.33600,124.76570,-0.00014,4.51952,1.22801,0.80111,-0.00177
15.39000,125.21561,-0.00014,4.36101,1.23244,0.80309,-0.00179
15.44400,125.66556,-0.00014,4.35840,1.23687,0.80508,-0.00177
15.49800,126.11533,-0.00014,4.24609,1.24129,0.80705,-0.00176
15.55200,126.56515,-0.00014,4.18406,1.24572,0.80903,-0.00176
15.60600,127.01491,-0.00014,4.39025,1.25015,0.81100,-0.00178
15.66000,127.46469,-0.00014,4.33959,1.25457,0.81296,-0.00176
15.71400,127.91441,-0.00014,4.69740,1.25900,0.81492,-0.00179
15.76800,128.36424,-0.00014,4.85554,1.26343,0.81688,-0.00178
15.82200,128.81405,-0.00014,4.80860,1.26785,0.81883,-0.00178
15.87600,129.26394,-0.00014,4.49736,1.27228,0.82078,-0.00177
15.93000,129.71386,-0.00014,4.51915,1.27671,0.82273,-0.00179
15.98400,130.16371,-0.00014,4.56590,1.28114,0.82467,-0.00176
16.03800,130.61354,-0.00014,4.70616,1.28557,0.82661,-0.00177
16.09200,131.06335,-0.00014,4.47873,1.28999,0.82855,-0.00175
16.14600,131.51308,-0.00014,4.63016,1.29442,0.83048,-0.00178
16.20000,131.96291,-0.00014,4.22448,1.29885,0.83241,-0.00176
16.25400,132.41264,-0.00014,4.82481,1.30327,0.83433,-0.00178
16.30800,132.86244,-0.00014,4.66425,1.30770,0.83625,-0.00178
16.36200,133.31218,-0.00014,4.87994,1.31213,0.83817,-0.00177
16.41600,133.76218,-0.00014,5.07440,1.31656,0.84008,-0.00177
16.47000,134.21198,-0.00014,4.72814,1.32098,0.84199,-0.00177
16.52400,134.66187,-0.00014,4.54877,1.32541,0.84390,-0.00179
16.57800,135.11177,-0.00014,4.96488,1.32984,0.84580,-0.00176
16.63200,135.56158,-0.00014,4.86672,1.33427,0.84770,-0.00177
16.68600,136.01131,-0.00014,5.00251,1.33869,0.84959,-0.00178
16.74000,136.46107,-0.00014,4.65121,1.34312,0.85148,-0.00177
16.79400,136.91087,-0.00014,4.79352,1.34755,0.85337,-0.00176
16.84800,137.36060,-0.00014,5.04050,1.35197,0.85526,-0.00177
16.90200,137.81046,-0.00014,4.77899,1.35640,0.85714,-0.00177
16.95600,138.26032,-0.00014,4.99077,1.36083,0.85901,-0.00180
17.01000,138.71024,-0.00014,5.01443,1.36526,0.86089,-0.00178
17.06400,139.16006,-0.00014,4.78085,1.36969,0.86276,-0.00179
17.11800,139.60990,-0.00014,4.97773,1.37411,0.86462,-0.00177
17.17200,140.05983,-0.00014,5.02914,1.37854,0.86649,-0.00177
17.22600,140.50954,-0.00014,4.84511,1.38297,0.86835,-0.00176
17.28000,140.95933,-0.00014,4.98369,1.38740,0.87020,-0.00178
17.33400,141.40903,-0.00014,5.06490,1.39182,0.87206,-0.00178
17.38800,141.85887,-0.00014,4.86709,1.39625,0.87390,-0.00180
17.44200,142.30862,-0.00014,4.77973,1.40068,0.87575,-0.00175
17.49600,142.75846,-0.00014,4.89615,1.40510,0.87759,-0.00179
17.55000,143.20833,-0.00014,4.81699,1.40953,0.87943,-0.00174
17.60400,143.65833,-0.00014,5.07515,1.41396,0.88127,-0.00178
17.65800,144.10815,-0.00014,5.12768,1.41839,0.88310,-0.00175
17.71200,144.55792,-0.00014,5.18449,1.42281,0.88493,-0.00179
17.76600,145.00776,-0.00014,4.96935,1.42724,0.88676,-0.00173
17.82000,145.45753,-0.00014,4.85592,1.43167,0.88858,-0.00179
17.87400,145.90721,-0.00014,5.05652,1.43609,0.89040,-0.00176
17.92800,146.35708,-0.00014,5.13233,1.44052,0.89221,-0.00178
17.98200,146.80686,-0.00014,5.13550,1.44495,0.89402,-0.00176
18.03600,147.25670,-0.00014,5.20702,1.44938,0.89583,-0.00179
18.09000,147.70649,-0.00014,5.20907,1.45380,0.89764,-0.00177
18.14400,148.15649,-0.00014,5.08595,1.45823,0.89944,-0.00178
18.19800,148.60632,-0.00014,5.09843,1.46266,0.90124,-0.00175
18.25200,149.05619,-0.00014,5.17648,1.46709,0.90304,-0.00178
18.30600,149.50595,-0.00014,5.39869,1.47152,0.90483,-0.00175
18.36000,149.95575,-0.00014,5.51119,1.47594,0.90662,-0.00178
18.41400,150.40548,-0.00014,5.38416,1.48037,0.90841,-0.00174
18.46800,150.85525,-0.00014,4.82909,1.48480,0.91019,-0.00180
18.52200,151.30507,-0.00014,5.01517,1.48922,0.91197,-0.00175
18.57600,151.75491,-0.00014,5.29625,1.49365,0.91375,-0.00179
18.63000,152.20478,-0.00014,5.58626,1.49808,0.91552,-0.00174
18.68400,152.65466,-0.00014,5.34877,1.50251,0.91729,-0.00179
18.73800,153.10450,-0.00014,5.31524,1.50693,0.91906,-0.00173
18.79200,153.55437,-0.00014,5.29792,1.51136,0.92083,-0.00179
18.84600,154.00411,-0.00014,5.38006,1.51579,0.92259,-0.00175
18.90000,154.45391,-0.00014,5.61457,1.52022,0.92434,-0.00179
18.95400,154.90371,-0.00014,5.61848,1.52464,0.92610,-0.00174
19.00800,155.35348,-0.00014,5.11315,1.52907,0.92785,-0.00180
19.06200,155.80321,-0.00014,5.77606,1.53350,0.92960,-0.00175
19.11600,156.25313,-0.00014,5.55571,1.53792,0.93135,-0.00178
19.17000,156.70297,-0.00014,5.77159,1.54235,0.93309,-0.00175
19.22400,157.15287,-0.00014,5.72596,1.54678,0.93483,-0.00181
19.27800,157.60271,-0.00014,5.64344,1.55121,0.93657,-0.00173
19.33200,158.05257,-0.00014,5.46630,1.55564,0.93830,-0.00179
19.38600,158.50230,-0.00014,5.71348,1.56006,0.94003,-0.00174
19.44000,158.95209,-0.00014,5.97555,1.56449,0.94176,-0.00179
19.49400,159.40193,-0.00014,5.82114,1.56892,0.94348,-0.00175
19.54800,159.85166,-0.00014,5.31208,1.57334,0.94521,-0.00180
19.60200,160.30144,-0.00014,5.39515,1.57777,0.94692,-0.00174
19.65600,160.75133,-0.00014,5.72745,1.58220,0.94864,-0.00180
19.71000,161.20120,-0.00014,5.61923,1.58663,0.95035,-0.00174
19.76400,161.65104,-0.00014,5.79599,1.59105,0.95206,-0.00179
19.81800,162.10087,-0.00014,5.96251,1.59548,0.95377,-0.00176
19.87200,162.55078,-0.00014,5.77513,1.59991,0.95548,-0.00178
19.92600,163.00047,-0.00014,6.00722,1.60434,0.95718,-0.00173
19.98000,163.45034,-0.00014,6.03646,1.60876,0.95888,-0.00178
20.03400,163.90007,-0.00014,6.14226,1.61319,0.96057,-0.00175
20.08800,164.34989,-0.00014,6.04782,1.61762,0.96226,-0.00180
20.14200,164.79966,-0.00014,5.92507,1.62204,0.96395,-0.00174
20.19600,165.24949,-0.00014,6.26817,1.62647,0.96564,-0.00179
20.25000,165.69939,-0.00014,5.91855,1.63090,0.96733,-0.00174
20.30400,166.14930,-0.00014,5.94649,1.63533,0.96901,-0.00179
20.35800,166.59912,-0.00014,6.17038,1.63976,0.97069,-0.00176
20.41200,167.04887,-0.00014,6.22720,1.64418,0.97236,-0.00180
20.46600,167.49879,-0.00014,5.94594,1.64861,0.97404,-0.00174
20.52000,167.94853,-0.00014,6.19516,1.65304,0.97570,-0.00178
20.57400,168.39822,-0.00014,6.25290,1.65746,0.97737,-0.00175
20.62800,168.84807,-0.00014,6.14971,1.66189,0.97904,-0.00178
20.68200,169.29788,-0.00014,6.23539,1.66632,0.98070,-0.00175
20.73600,169.74775,-0.00014,6.34547,1.67075,0.98236,-0.00179
20.79000,170.19758,-0.00014,6.39241,1.67517,0.98401,-0.00177
20.84400,170.64750,-0.00014,6.49784,1.67960,0.98567,-0.00179
20.89800,171.09729,-0.00014,6.23651,1.68403,0.98732,-0.00176
20.95200,171.54712,-0.00014,6.58855,1.68846,0.98897,-0.00179
21.00600,171.99695,-0.00014,6.32852,1.69288,0.99061,-0.00175
21.06000,172.44675,-0.00014,6.52745,1.69731,0.99226,-0.00177
21.11400,172.89645,-0.00014,6.34100,1.70174,0.99389,-0.00171
21.16800,173.34616,-0.00014,6.12456,1.70616,0.99553,-0.00179
21.22200,173.79610,-0.00014,6.35553,1.71059,0.99717,-0.00175
21.27600,174.24595,-0.00014,6.67404,1.71502,0.99880,-0.00180
21.33000,174.69581,-0.00014,6.60997,1.71945,1.00043,-0.00176
21.38400,175.14568,-0.00014,6.78301,1.72387,1.00206,-0.00179
21.43800,175.59551,-0.00014,6.59265,1.72830,1.00368,-0.00174
21.49200,176.04535,-0.00014,6.71111,1.73273,1.00530,-0.00179
21.54600,176.49514,-0.00014,6.78115,1.73716,1.00692,-0.00177
21.60000,176.94493,-0.00014,6.33318,1.74158,1.00854,-0.00178
21.65400,177.39468,-0.00014,7.06874,1.74601,1.01015,-0.00176
21.70800,177.84445,-0.00014,6.97896,1.75044,1.01176,-0.00178
21.76200,178.29421,-0.00014,6.62953,1.75486,1.01337,-0.00176
21.81600,178.74413,-0.00014,6.53099,1.75929,1.01497,-0.00177
21.87000,179.19400,-0.00014,7.11177,1.76372,1.01658,-0.00175
21.92400,179.64380,-0.00014,6.92662,1.76815,1.01818,-0.00177
21.97800,180.09371,-0.00014,6.92457,1.77258,1.01978,-0.00174
22.03200,180.54361,-0.00014,6.77258,1.77700,1.02137,-0.00178
22.08600,180.99337,-0.00014,6.92606,1.78143,1.02297,-0.00177
22.14000,181.44308,-0.00014,6.80815,1.78586,1.02456,-0.00179
22.19400,181.89291,-0.00014,6.91712,1.79028,1.02614,-0.00178
22.24800,182.34264,-0.00014,6.97915,1.79471,1.02773,-0.00177
22.30200,182.79243,-0.00014,6.93109,1.79914,1.02931,-0.00175
22.35600,183.24224,-0.00014,7.16429,1.80357,1.03089,-0.00178
22.41000,183.69223,-0.00014,7.14976,1.80799,1.03247,-0.00177
22.46400,184.14204,-0.00014,7.14995,1.81242,1.03405,-0.00177
22.51800,184.59193,-0.00014,7.45784,1.81685,1.03562,-0.00177
22.57200,185.04182,-0.00014,7.47442,1.82128,1.03719,-0.00176
22.62600,185.49157,-0.00014,7.38390,1.82570,1.03876,-0.00176
22.68000,185.94136,-0.00014,7.32392,1.83013,1.04032,-0.00176
22.73400,186.39109,-0.00014,7.29393,1.83456,1.04189,-0.00175
22.78800,186.84088,-0.00014,7.37589,1.83899,1.04345,-0.00176
22.84200,187.29063,-0.00014,7.58916,1.84341,1.04500,-0.00177
22.89600,187.74048,-0.00014,7.55154,1.84784,1.04656,-0.00176
22.95000,188.19033,-0.00014,7.49398,1.85227,1.04811,-0.00175
23.00400,188.64023,-0.00014,7.64858,1.85670,1.04967,-0.00174
23.05800,189.09013,-0.00014,7.65845,1.86112,1.05121,-0.00175
23.11200,189.53997,-0.00014,7.95405,1.86555,1.05276,-0.00174
23.16600,189.98980,-0.00014,7.71396,1.86998,1.05430,-0.00176
23.22000,190.43954,-0.00014,7.95629,1.87440,1.05585,-0.00174
23.27400,190.88930,-0.00014,8.14479,1.87883,1.05738,-0.00175
23.32800,191.33909,-0.00014,7.82814,1.88326,1.05892,-0.00174
23.38200,191.78887,-0.00014,7.76444,1.88769,1.06046,-0.00175
23.43600,192.23865,-0.00014,7.62101,1.89211,1.06199,-0.00175
23.49000,192.68848,-0.00014,8.08202,1.89654,1.06352,-0.00177
23.54400,193.13844,-0.00014,8.01831,1.90097,1.06504,-0.00174
23.59800,193.58831,-0.00014,8.02912,1.90540,1.06657,-0.00175
23.65200,194.03815,-0.00014,8.19191,1.90982,1.06809,-0.00174
23.70600,194.48798,-0.00014,8.38526,1.91425,1.06961,-0.00176
23.76000,194.93778,-0.00014,8.18912,1.91868,1.07113,-0.00175
23.81400,195.38755,-0.00014,8.13510,1.92311,1.07265,-0.00175
23.86800,195.83723,-0.00014,8.21389,1.92753,1.07416,-0.00174
23.92200,196.28711,-0.00014,7.95852,1.93196,1.07567,-0.00176
23.97600,196.73684,-0.00014,8.30404,1.93639,1.07718,-0.00173
24.03000,197.18675,-0.00014,8.19806,1.94081,1.07869,-0.00176
24.08400,197.63659,-0.00014,8.01384,1.94524,1.08019,-0.00173
24.13800,198.08653,-0.00014,8.36737,1.94967,1.08169,-0.00175
24.19200,198.53628,-0.00014,8.60635,1.95410,1.08319,-0.00174
24.24600,198.98615,-0.00014,8.68812,1.95853,1.08469,-0.00176
24.30000,199.43597,-0.00014,8.65236,1.96295,1.08619,-0.00172
24.35400,199.88578,-0.00014,8.31317,1.96738,1.08768,-0.00175
24.40800,200.33548,-0.00014,8.83639,1.97181,1.08917,-0.00174
24.46200,200.78525,-0.00014,8.43126,1.97623,1.09066,-0.00175
24.51600,201.23507,-0.00014,8.92375,1.98066,1.09214,-0.00173
24.57000,201.68494,-0.00014,8.81441,1.98509,1.09363,-0.00177
24.62400,202.13477,-0.00014,8.71550,1.98952,1.09511,-0.00175
24.67800,202.58467,-0.00014,8.65459,1.99394,1.09659,-0.00177
24.73200,203.03455,-0.00014,8.95485,1.99837,1.09807,-0.00174
24.78600,203.48440,-0.00014,8.99695,2.00280,1.09954,-0.00177
24.84000,203.93413,-0.00014,8.93548,2.00723,1.10102,-0.00175
24.89400,204.38401,-0.00014,9.14373,2.01165,1.10249,-0.00178
24.94800,204.83373,-0.00014,9.06494,2.01608,1.10396,-0.00173
25.00200,205.28346,-0.00014,9.03420,2.02051,1.10542,-0.00178
25.05600,205.73330,-0.00014,9.14447,2.02493,1.10689,-0.00175
25.11000,206.18317,-0.00014,9.08002,2.02936,1.10835,-0.00180
25.16400,206.63299,-0.00014,9.01669,2.03379,1.10981,-0.00176
25.21800,207.08284,-0.00014,9.29665,2.03822,1.11127,-0.00181
25.27200,207.53273,-0.00014,9.32012,2.04264,1.11273,-0.00174
25.32600,207.98256,-0.00014,9.54811,2.04707,1.11418,-0.00178
25.38000,208.43237,-0.00014,9.60138,2.05150,1.11563,-0.00175
25.43400,208.88214,-0.00014,9.42387,2.05593,1.11708,-0.00180
25.48800,209.33193,-0.00014,9.54699,2.06035,1.11853,-0.00175
25.54200,209.78170,-0.00014,9.30279,2.06478,1.11998,-0.00179
25.59600,210.23147,-0.00014,9.61460,2.06921,1.12142,-0.00177
25.65000,210.68130,-0.00014,9.89381,2.07363,1.12286,-0.00178
25.70400,211.13116,-0.00014,9.52203,2.07806,1.12430,-0.00176
25.75800,211.58112,-0.00014,9.95733,2.08249,1.12574,-0.00180
25.81200,212.03090,-0.00014,9.51849,2.08692,1.12717,-0.00174
25.86600,212.48079,-0.00014,9.71798,2.09135,1.12861,-0.00179
25.92000,212.93056,-0.00014,9.91821,2.09577,1.13004,-0.00173
25.97400,213.38035,-0.00014,9.90834,2.10020,1.13147,-0.00180
26.02800,213.83007,-0.00014,10.22127,2.10463,1.13289,-0.00173
26.08200,214.27994,-0.00014,9.98620,2.10905,1.13432,-0.00180
26.13600,214.72972,-0.00014,9.90834,2.11348,1.13574,-0.00173
26.19000,215.17951,-0.00014,9.94727,2.11791,1.13716,-0.00180
26.24400,215.62939,-0.00014,10.21251,2.12234,1.13858,-0.00174
26.29800,216.07926,-0.00014,9.97651,2.12676,1.14000,-0.00177
26.35200,216.52911,-0.00014,10.20469,2.13119,1.14141,-0.00174
26.40600,216.97898,-0.00014,10.27938,2.13562,1.14283,-0.00178
26.46000,217.42878,-0.00014,9.78746,2.14005,1.14424,-0.00175
26.51400,217.87852,-0.00014,10.49303,2.14447,1.14565,-0.00178
26.56800,218.32828,-0.00014,10.51575,2.14890,1.14705,-0.00176
26.62200,218.77816,-0.00014,10.46434,2.15333,1.14846,-0.00179
26.67600,219.22781,-0.00014,10.50904,2.15775,1.14986,-0.00174
26.73000,219.67772,-0.00014,10.58709,2.16218,1.15126,-0.00180
26.78400,220.12757,-0.00014,10.75380,2.16661,1.15266,-0.00176
26.83800,220.57750,-0.00014,10.98085,2.17104,1.15406,-0.00178
26.89200,221.02728,-0.00014,10.86518,2.17547,1.15545,-0.00174
26.94600,221.47711,-0.00014,10.87505,2.17989,1.15685,-0.00182
27.00000,221.92696,-0.00014,10.47105,2.18432,1.15824,-0.00174
27.05400,222.37674,-0.00014,10.97098,2.18875,1.15963,-0.00179
27.10800,222.82647,-0.00014,10.80465,2.19317,1.16102,-0.00174
27.16200,223.27627,-0.00014,11.20195,2.19760,1.16240,-0.00180
27.21600,223.72610,-0.00014,10.97973,2.20203,1.16378,-0.00176
27.27000,224.17590,-0.00014,11.32768,2.20646,1.16517,-0.00178
27.32400,224.62578,-0.00014,10.66756,2.21088,1.16655,-0.00175
27.37800,225.07566,-0.00014,11.49736,2.21531,1.16792,-0.00179
27.43200,225.52554,-0.00014,11.22784,2.21974,1.16930,-0.00175
27.48600,225.97537,-0.00014,11.06728,2.22417,1.17067,-0.00176
27.54000,226.42507,-0.00014,11.35916,2.22859,1.17205,-0.00175
27.59400,226.87498,-0.00014,10.98476,2.23302,1.17342,-0.00176
27.64800,227.32470,-0.00014,11.10267,2.23745,1.17479,-0.00173
27.70200,227.77448,-0.00014,11.39678,2.24187,1.17615,-0.00177
27.75600,228.22426,-0.00014,11.44540,2.24630,1.17752,-0.00175
27.81000,228.67414,-0.00014,11.47203,2.25073,1.17888,-0.00177
27.86400,229.12399,-0.00014,11.44223,2.25516,1.18024,-0.00175
27.91800,229.57382,-0.00014,11.43813,2.25958,1.18160,-0.00179
27.97200,230.02378,-0.00014,11.54635,2.26401,1.18296,-0.00175
28.02600,230.47356,-0.00014,11.53816,2.26844,1.18431,-0.00178
28.08000,230.92333,-0.00014,11.40609,2.27287,1.18567,-0.00174
28.13400,231.37314,-0.00014,11.35357,2.27729,1.18702,-0.00179
28.18800,231.82294,-0.00014,11.07026,2.28172,1.18837,-0.00175
28.24200,232.27266,-0.00014,11.50928,2.28615,1.18972,-0.00180
28.29600,232.72244,-0.00014,12.01257,2.29058,1.19106,-0.00173
28.35000,233.17229,-0.00014,11.49960,2.29500,1.19241,-0.00177
28.40400,233.62220,-0.00014,11.74770,2.29943,1.19375,-0.00174
28.45800,234.07206,-0.00014,11.53573,2.30386,1.19509,-0.00179
28.51200,234.52191,-0.00014,11.85071,2.30829,1.19643,-0.00175
28.56600,234.97179,-0.00014,11.75553,2.31271,1.19777,-0.00177
28.62000,235.42159,-0.00014,11.71269,2.31714,1.19910,-0.00174
28.67400,235.87132,-0.00014,11.86877,2.32157,1.20044,-0.00179
28.72800,236.32110,-0.00014,12.15115,2.32599,1.20177,-0.00175
28.78200,236.77090,-0.00014,11.56162,2.33042,1.20310,-0.00179
28.83600,237.22067,-0.00014,11.49941,2.33485,1.20443,-0.00175
28.89000,237.67045,-0.00014,12.08074,2.33928,1.20575,-0.00182
28.94400,238.12038,-0.00014,12.09788,2.34370,1.20708,-0.00176
28.99800,238.57027,-0.00014,12.09043,2.34813,1.20840,-0.00180
29.05200,239.02009,-0.00014,12.26515,2.35256,1.20972,-0.00174
29.10600,239.46995,-0.00014,11.91385,2.35699,1.21104,-0.00180
29.16000,239.91983,-0.00014,12.04349,2.36142,1.21236,-0.00176
29.21400,240.36958,-0.00014,12.00046,2.36584,1.21368,-0.00179
29.26800,240.81928,-0.00014,12.18766,2.37027,1.21499,-0.00177
29.32200,241.26908,-0.00014,11.82389,2.37470,1.21631,-0.00179
29.37600,241.71888,-0.00014,11.79613,2.37912,1.21762,-0.00176
29.43000,242.16871,-0.00014,12.05914,2.38355,1.21893,-0.00181
29.48400,242.61854,-0.00014,12.19548,2.38798,1.22023,-0.00177
29.53800,243.06845,-0.00014,11.95669,2.39241,1.22154,-0.00177
29.59200,243.51828,-0.00014,12.02486,2.39683,1.22284,-0.00177
29.64600,243.96816,-0.00014,12.00624,2.40126,1.22415,-0.00182
29.70000,244.41801,-0.00014,12.16587,2.40569,1.22545,-0.00177
29.75400,244.86779,-0.00014,12.11204,2.41012,1.22675,-0.00176
29.80800,245.31754,-0.00014,12.40205,2.41454,1.22804,-0.00177
29.86200,245.76724,-0.00014,11.99543,2.41897,1.22934,-0.00181
29.91600,246.21709,-0.00014,12.04051,2.42340,1.23063,-0.00177
29.97000,246.66687,-0.00014,11.57206,2.42782,1.23193,-0.00180
30.02400,247.11678,-0.00014,12.00307,2.43225,1.23322,-0.00177
30.07800,247.56658,-0.00014,12.05560,2.43668,1.23451,-0.00178
30.13200,248.01654,-0.00014,12.05001,2.44111,1.23579,-0.00180
30.18600,248.46637,-0.00014,12.02822,2.44554,1.23708,-0.00176
30.24000,248.91617,-0.00014,12.19418,2.44996,1.23836,-0.00177
30.29400,249.36600,-0.00014,12.14314,2.45439,1.23965,-0.00176
30.34800,249.81575,-0.00014,12.16568,2.45882,1.24093,-0.00178
30.40200,250.26550,-0.00014,12.02971,2.46324,1.24221,-0.00179
30.45600,250.71523,-0.00014,11.76223,2.46767,1.24348,-0.00180
30.51000,251.16511,-0.00014,11.98314,2.47210,1.24476,-0.00176
30.56400,251.61494,-0.00014,12.03511,2.47653,1.24603,-0.00176
30.61800,252.06474,-0.00014,12.16382,2.48095,1.24731,-0.00179
30.67200,252.51475,-0.00014,12.01089,2.48538,1.24858,-0.00177
30.72600,252.96450,-0.00014,11.92130,2.48981,1.24985,-0.00178
30.78000,253.41436,-0.00014,11.85145,2.49424,1.25111,-0.00177
30.83400,253.86421,-0.00014,12.09117,2.49866,1.25238,-0.00177
30.88800,254.31401,-0.00014,11.96694,2.50309,1.25365,-0.00178
30.94200,254.76369,-0.00014,12.22137,2.50752,1.25491,-0.00177
30.99600,255.21349,-0.00014,12.26626,2.51194,1.25617,-0.00179
31.05000,255.66329,-0.00014,12.24838,2.51637,1.25743,-0.00179
31.10400,256.11312,-0.00014,11.97290,2.52080,1.25869,-0.00178
31.15800,256.56303,-0.00014,11.93117,2.52523,1.25994,-0.00176
31.21200,257.01291,-0.00014,12.38976,2.52965,1.26120,-0.00179
31.26600,257.46281,-0.00014,11.83283,2.53408,1.26245,-0.00177
31.32000,257.91257,-0.00014,12.39274,2.53851,1.26371,-0.00179
31.37400,258.36234,-0.00014,12.55590,2.54294,1.26496,-0.00177
31.42800,258.81217,-0.00014,12.59763,2.54736,1.26620,-0.00180
31.48200,259.26195,-0.00014,12.40857,2.55179,1.26745,-0.00177
31.53600,259.71167,-0.00014,12.39218,2.55622,1.26870,-0.00178
31.59000,260.16147,-0.00014,12.47413,2.56064,1.26994,-0.00178
31.64400,260.61136,-0.00014,12.56689,2.56507,1.27118,-0.00178
31.69800,261.06121,-0.00014,12.35120,2.56950,1.27243,-0.00178
31.75200,261.51109,-0.00014,12.43725,2.57393,1.27367,-0.00180
31.80600,261.96095,-0.00014,12.45122,2.57836,1.27490,-0.00176
31.86000,262.41085,-0.00014,12.96978,2.58278,1.27614,-0.00180
31.91400,262.86058,-0.00014,12.55274,2.58721,1.27737,-0.00175
31.96800,263.31030,-0.00014,12.52834,2.59164,1.27861,-0.00180
32.02200,263.76016,-0.00014,12.90068,2.59606,1.27984,-0.00178
32.07600,264.20993,-0.00014,12.96122,2.60049,1.28107,-0.00179
32.13000,264.65963,-0.00014,13.21267,2.60492,1.28230,-0.00176
32.18400,265.10954,-0.00014,12.76974,2.60935,1.28353,-0.00179
32.23800,265.55942,-0.00014,12.88354,2.61377,1.28475,-0.00176
32.29200,266.00930,-0.00014,12.64978,2.61820,1.28598,-0.00180
32.34600,266.45905,-0.00014,12.66915,2.62263,1.28720,-0.00176
32.40000,266.90901,-0.00014,12.52517,2.62706,1.28842,-0.00179
32.45400,267.35879,-0.00014,13.08266,2.63148,1.28964,-0.00176
32.50800,267.80856,-0.00014,12.95656,2.63591,1.29086,-0.00181
32.56200,268.25826,-0.00014,13.07614,2.64034,1.29208,-0.00175
32.61600,268.70812,-0.00014,13.27302,2.64476,1.29329,-0.00182
32.67000,269.15789,-0.00014,13.09607,2.64919,1.29451,-0.00179
32.72400,269.60777,-0.00014,13.08806,2.65362,1.29572,-0.00179
32.77800,270.05758,-0.00014,12.95265,2.65805,1.29693,-0.00175
32.83200,270.50748,-0.00014,13.00015,2.66248,1.29814,-0.00180
32.88600,270.95734,-0.00014,12.96680,2.66690,1.29935,-0.00177
32.94000,271.40719,-0.00014,12.93719,2.67133,1.30055,-0.00178
32.99400,271.85697,-0.00014,13.13854,2.67576,1.30176,-0.00175
33.04800,272.30677,-0.00014,13.19069,2.68018,1.30296,-0.00181
33.10200,272.75650,-0.00014,13.11079,2.68461,1.30417,-0.00175
33.15600,273.20625,-0.00014,13.30934,2.68904,1.30537,-0.00180
33.21000,273.65610,-0.00014,13.51871,2.69347,1.30657,-0.00179
33.26400,274.10596,-0.00014,13.41105,2.69789,1.30776,-0.00181
33.31800,274.55576,-0.00014,13.29295,2.70232,1.30896,-0.00177
33.37200,275.00567,-0.00014,12.91297,2.70675,1.31016,-0.00180
33.42600,275.45555,-0.00014,13.10855,2.71118,1.31135,-0.00176
33.48000,275.90540,-0.00014,13.30152,2.71560,1.31254,-0.00178
33.53400,276.35515,-0.00014,13.14413,2.72003,1.31373,-0.00173
33.58800,276.80504,-0.00014,13.29239,2.72446,1.31492,-0.00181
33.64200,277.25471,-0.00014,13.65859,2.72888,1.31611,-0.00178
33.69600,277.70446,-0.00014,13.53007,2.73331,1.31730,-0.00180
33.75000,278.15429,-0.00014,13.82716,2.73774,1.31848,-0.00174
33.80400,278.60409,-0.00014,13.85603,2.74217,1.31966,-0.00180
33.85800,279.05397,-0.00014,13.74818,2.74659,1.32085,-0.00177
33.91200,279.50390,-0.00014,13.50492,2.75102,1.32203,-0.00181
33.96600,279.95379,-0.00014,13.61184,2.75545,1.32321,-0.00174
34.02000,280.40359,-0.00014,13.65952,2.75988,1.32439,-0.00180
34.07400,280.85339,-0.00014,13.51181,2.76431,1.32556,-0.00178
34.12800,281.30317,-0.00014,13.88285,2.76873,1.32674,-0.00177
34.18200,281.75292,-0.00014,13.29277,2.77316,1.32791,-0.00176
34.23600,282.20272,-0.00014,13.90167,2.77759,1.32909,-0.00180
34.29000,282.65247,-0.00014,14.17547,2.78201,1.33026,-0.00176
34.34400,283.10235,-0.00014,13.74986,2.78644,1.33143,-0.00180
34.39800,283.55213,-0.00014,14.04155,2.79087,1.33259,-0.00174
34.45200,284.00209,-0.00014,14.01529,2.79530,1.33376,-0.00179
34.50600,284.45192,-0.00014,13.95382,2.79972,1.33493,-0.00175
34.56000,284.90185,-0.00014,14.41389,2.80415,1.33609,-0.00181
34.61400,285.35163,-0.00014,13.75116,2.80858,1.33726,-0.00176
34.66800,285.80135,-0.00014,14.09128,2.81301,1.33842,-0.00181
34.72200,286.25118,-0.00014,14.14362,2.81743,1.33958,-0.00176
34.77600,286.70090,-0.00014,14.35317,2.82186,1.34074,-0.00179
34.83000,287.15065,-0.00014,14.26637,2.82629,1.34189,-0.00175
34.88400,287.60051,-0.00014,14.23135,2.83071,1.34305,-0.00182
34.93800,288.05042,-0.00014,14.44314,2.83514,1.34421,-0.00177
34.99200,288.50027,-0.00014,14.52696,2.83957,1.34536,-0.00179
35.04600,288.95013,-0.00014,14.49566,2.84400,1.34651,-0.00179
35.10000,289.40003,-0.00014,14.41352,2.84843,1.34766,-0.00179
35.15400,289.84973,-0.00014,14.24588,2.85285,1.34881,-0.00173
35.20800,290.29959,-0.00014,13.70367,2.85728,1.34996,-0.00180
35.26200,290.74936,-0.00014,14.36360,2.86171,1.35111,-0.00178
35.31600,291.19919,-0.00014,14.85236,2.86613,1.35225,-0.00179
35.37000,291.64886,-0.00014,14.48207,2.87056,1.35340,-0.00176
35.42400,292.09867,-0.00014,14.76444,2.87499,1.35454,-0.00179
35.47800,292.54855,-0.00014,14.86540,2.87941,1.35568,-0.00176
35.53200,292.99846,-0.00014,14.67913,2.88384,1.35683,-0.00182
35.58600,293.44834,-0.00014,14.82535,2.88827,1.35796,-0.00176
35.64000,293.89819,-0.00014,15.07942,2.89270,1.35910,-0.00181
35.69400,294.34799,-0.00014,14.67653,2.89713,1.36024,-0.00176
35.74800,294.79782,-0.00014,14.35857,2.90155,1.36137,-0.00178
35.80200,295.24755,-0.00014,14.86614,2.90598,1.36251,-0.00174
35.85600,295.69730,-0.00014,14.66982,2.91041,1.36364,-0.00180
35.91000,296.14715,-0.00014,14.84174,2.91483,1.36477,-0.00178
35.96400,296.59693,-0.00014,14.77487,2.91926,1.36590,-0.00180
36.01800,297.04671,-0.00014,14.90153,2.92369,1.36703,-0.00179
36.07200,297.49669,-0.00014,15.56408,2.92812,1.36816,-0.00178
36.12600,297.94655,-0.00014,15.19080,2.93254,1.36929,-0.00177
36.18000,298.39632,-0.00014,14.94158,2.93697,1.37041,-0.00176
36.23400,298.84618,-0.00014,15.31504,2.94140,1.37154,-0.00178
36.28800,299.29601,-0.00014,15.08519,2.94583,1.37266,-0.00179
36.34200,299.74578,-0.00014,15.08519,2.95025,1.37378,-0.00177
36.39600,300.19551,-0.00014,15.13753,2.95468,1.37490,-0.00178
36.45000,300.64528,-0.00014,15.07606,2.95911,1.37602,-0.00175
36.50400,301.09514,-0.00014,15.37129,2.96353,1.37714,-0.00180
36.55800,301.54502,-0.00014,15.20980,2.96796,1.37825,-0.00178
36.61200,301.99480,-0.00014,15.33944,2.97239,1.37937,-0.00178
36.66600,302.44478,-0.00014,15.45120,2.97682,1.38048,-0.00177
36.72000,302.89456,-0.00014,15.55663,2.98125,1.38159,-0.00179
36.77400,303.34441,-0.00014,15.39178,2.98567,1.38271,-0.00178
36.82800,303.79419,-0.00014,15.38098,2.99010,1.38382,-0.00178
36.88200,304.24394,-0.00014,15.71141,2.99453,1.38493,-0.00177
36.93600,304.69374,-0.00014,15.63560,2.99895,1.38603,-0.00177
36.99000,305.14349,-0.00014,15.74475,3.00338,1.38714,-0.00177
37.04400,305.59332,-0.00014,15.76785,3.00781,1.38824,-0.00177
37.09800,306.04315,-0.00014,15.52776,3.01224,1.38935,-0.00178
37.15200,306.49306,-0.00014,15.78312,3.01666,1.39045,-0.00178
37.20600,306.94286,-0.00014,15.56780,3.02109,1.39155,-0.00178
37.26000,307.39279,-0.00014,15.99472,3.02552,1.39265,-0.00178
37.31400,307.84260,-0.00014,16.09698,3.02995,1.39375,-0.00177
37.36800,308.29237,-0.00014,15.70527,3.03437,1.39485,-0.00179
37.42200,308.74212,-0.00014,15.75481,3.03880,1.39595,-0.00178
37.47600,309.19193,-0.00014,15.81889,3.04323,1.39704,-0.00179
37.53000,309.64170,-0.00014,16.32813,3.04765,1.39814,-0.00178
37.58400,310.09153,-0.00014,15.95691,3.05208,1.39923,-0.00180
37.63800,310.54144,-0.00014,16.15789,3.05651,1.40032,-0.00177
37.69200,310.99124,-0.00014,16.14224,3.06094,1.40141,-0.00177
37.74600,311.44110,-0.00014,16.23482,3.06537,1.40250,-0.00179
37.80000,311.89095,-0.00014,16.12566,3.06979,1.40359,-0.00177
37.85400,312.34081,-0.00014,16.27784,3.07422,1.40468,-0.00176
37.90800,312.79056,-0.00014,16.32776,3.07865,1.40577,-0.00178
37.96200,313.24031,-0.00014,16.59095,3.08307,1.40685,-0.00180
38.01600,313.69016,-0.00014,16.27840,3.08750,1.40793,-0.00176
38.07000,314.13989,-0.00014,16.77182,3.09193,1.40902,-0.00179
38.12400,314.58972,-0.00014,16.15696,3.09636,1.41010,-0.00179
38.17800,315.03962,-0.00014,16.38439,3.10078,1.41118,-0.00176
38.23200,315.48943,-0.00014,16.47472,3.10521,1.41226,-0.00179
38.28600,315.93936,-0.00014,16.63808,3.10964,1.41334,-0.00178
38.34000,316.38916,-0.00014,16.53172,3.11407,1.41441,-0.00175
38.39400,316.83910,-0.00014,16.61945,3.11849,1.41549,-0.00175
38.44800,317.28874,-0.00014,17.08642,3.12292,1.41656,-0.00177
38.50200,317.73854,-0.00014,16.67812,3.12735,1.41764,-0.00179
38.55600,318.18827,-0.00014,16.99906,3.13177,1.41871,-0.00178
38.61000,318.63812,-0.00014,17.04395,3.13620,1.41978,-0.00178
38.66400,319.08790,-0.00014,16.88171,3.14063,1.42085,-0.00176
38.71800,319.53770,-0.00014,16.83123,3.14506,1.42192,-0.00180
38.77200,319.98766,-0.00014,16.80404,3.14948,1.42298,-0.00176
38.82600,320.43757,-0.00014,17.11771,3.15391,1.42405,-0.00176
38.88000,320.88735,-0.00014,17.25890,3.15834,1.42512,-0.00174
38.93400,321.33717,-0.00014,16.96292,3.16277,1.42618,-0.00177
38.98800,321.78706,-0.00014,16.73140,3.16720,1.42724,-0.00176
39.04200,322.23678,-0.00014,17.10039,3.17162,1.42830,-0.00179
39.09600,322.68650,-0.00014,17.29596,3.17605,1.42937,-0.00175
39.15000,323.13628,-0.00014,17.35911,3.18048,1.43042,-0.00178
39.20400,323.58611,-0.00014,17.11361,3.18490,1.43148,-0.00176
39.25800,324.03589,-0.00014,17.29578,3.18933,1.43254,-0.00179
39.31200,324.48582,-0.00014,17.41778,3.19376,1.43360,-0.00176
39.36600,324.93581,-0.00014,17.31440,3.19819,1.43465,-0.00178
39.42000,325.38561,-0.00014,17.73741,3.20261,1.43571,-0.00175
39.47400,325.83538,-0.00014,17.25592,3.20704,1.43676,-0.00179
39.52800,326.28516,-0.00014,17.72419,3.21147,1.43781,-0.00175
39.58200,326.73502,-0.00014,17.28386,3.21590,1.43886,-0.00177
39.63600,327.18471,-0.00014,17.74281,3.22032,1.43991,-0.00176
39.69000,327.63446,-0.00014,18.01979,3.22475,1.44096,-0.00178
39.74400,328.08427,-0.00014,17.73592,3.22918,1.44201,-0.00177
39.79800,328.53415,-0.00014,17.72381,3.23360,1.44305,-0.00180
39.85200,328.98403,-0.00014,17.98291,3.23803,1.44410,-0.00173
39.90600,329.43383,-0.00014,17.29447,3.24246,1.44514,-0.00177
39.96000,329.88379,-0.00014,17.88028,3.24689,1.44619,-0.00174
40.01400,330.33367,-0.00014,17.82384,3.25132,1.44723,-0.00178
40.06800,330.78337,-0.00014,17.88214,3.25574,1.44827,-0.00174
40.12200,331.23323,-0.00014,17.89387,3.26017,1.44931,-0.00177
40.17600,331.68298,-0.00014,18.04028,3.26460,1.45035,-0.00174
40.23000,332.13270,-0.00014,17.88922,3.26902,1.45138,-0.00181
40.28400,332.58243,-0.00014,18.48470,3.27345,1.45242,-0.00179
40.33800,333.03241,-0.00014,18.23064,3.27788,1.45346,-0.00177
40.39200,333.48219,-0.00014,18.33718,3.28231,1.45449,-0.00174
40.44600,333.93207,-0.00014,18.37350,3.28673,1.45552,-0.00179
40.50000,334.38192,-0.00014,18.34631,3.29116,1.45656,-0.00175
40.55400,334.83183,-0.00014,18.33402,3.29559,1.45759,-0.00177
40.60800,335.28163,-0.00014,17.93038,3.30002,1.45862,-0.00174
40.66200,335.73141,-0.00014,18.06635,3.30444,1.45965,-0.00181
40.71600,336.18119,-0.00014,18.27609,3.30887,1.46068,-0.00176
40.77000,336.63096,-0.00014,18.33886,3.31330,1.46170,-0.00178
40.82400,337.08066,-0.00014,18.18165,3.31772,1.46273,-0.00176
40.87800,337.53054,-0.00014,18.21890,3.32215,1.46375,-0.00178
40.93200,337.98040,-0.00014,18.30328,3.32658,1.46478,-0.00177
40.98600,338.43028,-0.00014,18.45285,3.33101,1.46580,-0.00179
41.04000,338.88013,-0.00014,18.26603,3.33543,1.46682,-0.00174
41.09400,339.33001,-0.00014,18.10510,3.33986,1.46784,-0.00178
41.14800,339.77982,-0.00014,18.20978,3.34429,1.46886,-0.00177
41.20200,340.22962,-0.00014,17.81918,3.34872,1.46988,-0.00176
41.25600,340.67929,-0.00014,18.43479,3.35314,1.47090,-0.00173
41.31000,341.12915,-0.00014,18.36121,3.35757,1.47191,-0.00176
41.36400,341.57895,-0.00014,18.42044,3.36200,1.47293,-0.00177
41.41800,342.02878,-0.00014,18.27907,3.36643,1.47394,-0.00181
41.47200,342.47861,-0.00014,18.40089,3.37085,1.47496,-0.00174
41.52600,342.92846,-0.00014,18.26268,3.37528,1.47597,-0.00178
41.58000,343.37829,-0.00014,18.26547,3.37971,1.47698,-0.00175
41.63400,343.82820,-0.00014,18.20587,3.38414,1.47799,-0.00180
41.68800,344.27805,-0.00014,18.58659,3.38856,1.47900,-0.00176
41.74200,344.72783,-0.00014,18.37127,3.39299,1.48001,-0.00178
41.79600,345.17755,-0.00014,18.10677,3.39742,1.48102,-0.00174
41.85000,345.62738,-0.00014,18.27963,3.40184,1.48202,-0.00176
41.90400,346.07711,-0.00014,18.18016,3.40627,1.48303,-0.00175
41.95800,346.52694,-0.00014,18.18221,3.41070,1.48403,-0.00177
42.01200,346.97676,-0.00014,17.89741,3.41513,1.48504,-0.00176
42.06600,347.42672,-0.00014,18.11627,3.41955,1.48604,-0.00177
42.12000,347.87653,-0.00014,18.35655,3.42398,1.48704,-0.00176
42.17400,348.32638,-0.00014,18.11199,3.42841,1.48804,-0.00180
42.22800,348.77624,-0.00014,18.08535,3.43284,1.48904,-0.00175
42.28200,349.22601,-0.00014,18.17849,3.43726,1.49004,-0.00178
42.33600,349.67574,-0.00014,18.25728,3.44169,1.49104,-0.00178
42.39000,350.12557,-0.00014,17.66887,3.44612,1.49203,-0.00178
42.44400,350.57539,-0.00014,17.82458,3.45055,1.49303,-0.00176
42.49800,351.02515,-0.00014,17.66849,3.45497,1.49402,-0.00178
42.55200,351.47497,-0.00014,17.91175,3.45940,1.49501,-0.00176
42.60600,351.92483,-0.00014,17.40828,3.46383,1.49601,-0.00178
42.66000,352.37481,-0.00014,17.76293,3.46826,1.49700,-0.00175
42.71400,352.82459,-0.00014,17.69308,3.47268,1.49799,-0.00180
42.76800,353.27439,-0.00014,17.66998,3.47711,1.49898,-0.00176
42.82200,353.72420,-0.00014,17.23878,3.48154,1.49997,-0.00178
42.87600,354.17397,-0.00014,17.03110,3.48596,1.50095,-0.00177
42.93000,354.62375,-0.00014,17.11100,3.49039,1.50194,-0.00180
42.98400,355.07350,-0.00014,16.68893,3.49482,1.50293,-0.00175
43.03800,355.52338,-0.00014,16.58872,3.49925,1.50391,-0.00179
43.09200,355.97321,-0.00014,16.43915,3.50367,1.50489,-0.00177
43.14600,356.42307,-0.00014,16.08357,3.50810,1.50588,-0.00176
43.20000,356.87297,-0.00014,15.36831,3.51253,1.50686,-0.00175
43.25400,357.32283,-0.00014,15.22899,3.51696,1.50784,-0.00181
43.30800,357.77258,-0.00014,14.44910,3.52138,1.50882,-0.00177
43.36200,358.22235,-0.00014,4.53331,3.52581,1.50980,-0.00178
43.41600,358.67221,-0.00014,1.59685,3.53024,1.51077,-0.00177
43.47000,359.12196,-0.00014,1.74847,3.53466,1.51175,-0.00182
43.52400,359.57168,-0.00014,1.19675,3.53909,1.51273,-0.00177
43.57800,360.02154,-0.00014,1.44187,3.54352,1.51370,-0.00178
43.63200,360.47139,-0.00014,1.29286,3.54795,1.51468,-0.00178
43.68600,360.92125,-0.00014,1.55158,3.55237,1.51565,-0.00175
43.74000,361.37110,-0.00014,1.22823,3.55680,1.51662,-0.00178
43.74900,361.44608,-0.00014,1.20010,3.55754,1.51678,-0.00177