File: raw_data/mechanical_tests_Instron_data/Silicone_0035-Skin_Longitudinal_4.is_tens_RawData/Specimen_RawData_1.csv
Dimension : Area,0.42000,cm^2

Time,Load,Extension,Tensile extension,Tensile strain,Tensile stress
(sec),(N),(mm),(mm),(%),(MPa)
0.00000,0.15795,0.00000,0.00000,0.00000,0.00376
0.04000,0.94175,0.06083,0.06083,0.04345,0.02242
0.08000,0.85812,0.26269,0.26269,0.18763,0.02043
0.12000,2.01892,0.59652,0.59652,0.42608,0.04807
0.16000,1.75349,0.98842,0.98842,0.70601,0.04175
0.20000,2.22269,1.39532,1.39532,0.99666,0.05292
0.24000,1.71587,1.81090,1.81090,1.29350,0.04085
0.28000,1.90977,2.23245,2.23245,1.59461,0.04547
0.32000,1.78851,2.65087,2.65087,1.89348,0.04258
0.36000,1.49496,3.00921,3.00921,2.14944,0.03559
0.40000,1.80025,3.33712,3.33712,2.38366,0.04286
0.44000,1.75554,3.67136,3.67136,2.62240,0.04180
0.48000,1.71941,4.00770,4.00770,2.86265,0.04094
0.52000,1.95224,4.34140,4.34140,3.10100,0.04648
0.56000,2.07089,4.67469,4.67469,3.33907,0.04931
0.60000,2.07368,5.00823,5.00823,3.57731,0.04937
0.64000,2.10535,5.34150,5.34150,3.81536,0.05013
0.68000,2.20072,5.67506,5.67506,4.05361,0.05240
0.72000,2.36500,6.00817,6.00817,4.29155,0.05631
0.76000,1.98055,6.34168,6.34168,4.52977,0.04716
0.80000,1.93138,6.67486,6.67486,4.76776,0.04599
0.84000,2.24113,7.00834,7.00835,5.00596,0.05336
0.88000,2.27708,7.34167,7.34167,5.24405,0.05422
0.92000,2.63937,7.67499,7.67499,5.48213,0.06284
0.96000,2.34302,8.00839,8.00839,5.72028,0.05579
1.00000,2.54028,8.34160,8.34160,5.95829,0.06048
1.04000,2.29478,8.67511,8.67511,6.19651,0.05464
1.08000,2.70773,9.00825,9.00825,6.43446,0.06447
1.12000,2.62354,9.34178,9.34178,6.67270,0.06247
1.16000,2.05748,9.67492,9.67492,6.91065,0.04899
1.20000,2.32253,10.00832,10.00832,7.14880,0.05530
1.24000,2.28360,10.34164,10.34164,7.38688,0.05437
1.28000,2.16756,10.67496,10.67496,7.62497,0.05161
1.32000,2.13571,11.00836,11.00836,7.86312,0.05085
1.36000,2.35289,11.34155,11.34155,8.10111,0.05602
1.40000,2.40710,11.67500,11.67500,8.33929,0.05731
1.44000,2.33650,12.00825,12.00825,8.57732,0.05563
1.48000,2.57008,12.34173,12.34173,8.81552,0.06119
1.52000,2.65352,12.67491,12.67491,9.05351,0.06318
1.56000,2.55704,13.00837,13.00837,9.29169,0.06088
1.60000,2.23666,13.34164,13.34164,9.52974,0.05325
1.64000,2.62875,13.67501,13.67501,9.76786,0.06259
1.68000,2.24914,14.00839,14.00839,10.00599,0.05355
1.72000,2.31825,14.34155,14.34155,10.24396,0.05520
1.76000,2.57976,14.67506,14.67506,10.48218,0.06142
1.80000,2.72859,15.00822,15.00822,10.72015,0.06497
1.84000,2.45720,15.34175,15.34175,10.95839,0.05850
1.88000,2.36463,15.67491,15.67491,11.19637,0.05630
1.92000,2.23778,16.00834,16.00834,11.43453,0.05328
1.96000,2.17631,16.34161,16.34161,11.67258,0.05182
2.00000,2.49818,16.67496,16.67496,11.91068,0.05948
2.04000,2.51960,17.00839,17.00838,12.14885,0.05999
2.08000,2.41455,17.34155,17.34155,12.38682,0.05749
2.12000,2.41175,17.67508,17.67508,12.62506,0.05742
2.16000,2.30428,18.00821,18.00821,12.86301,0.05486
2.20000,2.09548,18.34178,18.34178,13.10127,0.04989
2.24000,2.34582,18.67491,18.67491,13.33922,0.05585
2.28000,2.34935,19.00837,19.00836,13.57740,0.05594
2.32000,2.61441,19.34166,19.34166,13.81547,0.06225
2.36000,2.49352,19.67493,19.67493,14.05352,0.05937
2.40000,2.32570,20.00841,20.00841,14.29172,0.05537
2.44000,2.22623,20.34157,20.34157,14.52969,0.05301
2.48000,2.56933,20.67503,20.67503,14.76788,0.06117
2.52000,2.35420,21.00821,21.00821,15.00587,0.05605
2.56000,2.14297,21.34172,21.34172,15.24409,0.05102
2.60000,2.31490,21.67491,21.67491,15.48208,0.05512
2.64000,2.14037,22.00836,22.00837,15.72026,0.05096
2.68000,2.06959,22.34163,22.34163,15.95831,0.04928
2.72000,2.06120,22.67495,22.67495,16.19640,0.04908
2.76000,2.07070,23.00833,23.00833,16.43452,0.04930
2.80000,2.52798,23.34162,23.34162,16.67259,0.06019
2.84000,1.91275,23.67513,23.67513,16.91081,0.04554
2.88000,1.90903,24.00821,24.00821,17.14872,0.04545
2.92000,1.88109,24.34172,24.34172,17.38694,0.04479
2.96000,1.89468,24.67494,24.67493,17.62495,0.04511
3.00000,2.11205,25.00839,25.00839,17.86314,0.05029
3.04000,2.02544,25.34163,25.34163,18.10116,0.04822
3.08000,1.86097,25.67493,25.67493,18.33923,0.04431
3.12000,2.07033,26.00833,26.00833,18.57738,0.04929
3.16000,2.51643,26.34160,26.34160,18.81543,0.05992
3.20000,2.29385,26.67508,26.67508,19.05363,0.05462
3.24000,2.43858,27.00818,27.00818,19.29156,0.05806
3.28000,2.32235,27.34172,27.34172,19.52980,0.05529
3.32000,2.50731,27.67488,27.67488,19.76777,0.05970
3.36000,2.21878,28.00839,28.00839,20.00599,0.05283
3.40000,2.06307,28.34169,28.34169,20.24406,0.04912
3.44000,1.92318,28.67498,28.67498,20.48213,0.04579
3.48000,1.99843,29.00835,29.00835,20.72025,0.04758
3.52000,1.94833,29.34154,29.34154,20.95824,0.04639
3.56000,2.32793,29.67508,29.67508,21.19648,0.05543
3.60000,2.09883,30.00826,30.00826,21.43447,0.04997
3.64000,2.06474,30.34172,30.34172,21.67266,0.04916
3.68000,2.53804,30.67493,30.67493,21.91066,0.06043
3.72000,2.68929,31.00836,31.00836,22.14883,0.06403
3.76000,2.35401,31.34160,31.34160,22.38686,0.05605
3.80000,2.34172,31.67495,31.67495,22.62496,0.05576
3.84000,2.61441,32.00832,32.00832,22.86309,0.06225
3.88000,2.40076,32.34154,32.34154,23.10110,0.05716
3.92000,2.40766,32.67508,32.67508,23.33934,0.05733
3.96000,2.44752,33.00824,33.00824,23.57731,0.05827
4.00000,2.45254,33.34180,33.34180,23.81557,0.05839
4.04000,2.20370,33.67496,33.67496,24.05354,0.05247
4.08000,2.53133,34.00833,34.00833,24.29167,0.06027
4.12000,2.50507,34.34160,34.34160,24.52971,0.05964
4.16000,2.71015,34.67500,34.67500,24.76786,0.06453
4.20000,2.35345,35.00840,35.00840,25.00600,0.05603
4.24000,2.58982,35.34159,35.34159,25.24399,0.06166
4.28000,2.87462,35.67499,35.67499,25.48214,0.06844
4.32000,2.71872,36.00823,36.00823,25.72016,0.06473
4.36000,2.96310,36.34174,36.34174,25.95839,0.07055
4.40000,2.67606,36.67482,36.67482,26.19630,0.06372
4.44000,3.30620,37.00838,37.00838,26.43456,0.07872
4.48000,2.79676,37.34163,37.34163,26.67259,0.06659
4.52000,2.92715,37.67497,37.67497,26.91069,0.06969
4.56000,3.22033,38.00843,38.00843,27.14888,0.07667
4.60000,2.47229,38.34159,38.34159,27.38685,0.05886
4.64000,3.11770,38.67510,38.67510,27.62507,0.07423
4.68000,3.20282,39.00821,39.00821,27.86300,0.07626
4.72000,2.89083,39.34177,39.34177,28.10127,0.06883
4.76000,2.94000,39.67493,39.67493,28.33924,0.07000
4.80000,2.94205,40.00836,40.00836,28.57740,0.07005
4.84000,3.17264,40.34162,40.34163,28.81545,0.07554
4.88000,3.10093,40.67494,40.67495,29.05353,0.07383
4.92000,3.12869,41.00835,41.00834,29.29167,0.07449
4.96000,3.34214,41.34153,41.34153,29.52967,0.07957
5.00000,3.34140,41.67504,41.67505,29.76789,0.07956
5.04000,3.61707,42.00823,42.00823,30.00588,0.08612
5.08000,3.11099,42.34179,42.34179,30.24414,0.07407
5.12000,3.12552,42.67495,42.67495,30.48211,0.07442
5.16000,3.00743,43.00838,43.00838,30.72027,0.07161
5.20000,3.11062,43.34165,43.34165,30.95832,0.07406
5.24000,3.18438,43.67494,43.67495,31.19639,0.07582
5.28000,3.03965,44.00837,44.00837,31.43455,0.07237
5.32000,3.01693,44.34159,44.34158,31.67256,0.07183
5.36000,3.10838,44.67510,44.67509,31.91078,0.07401
5.40000,3.04226,45.00826,45.00826,32.14875,0.07243
5.44000,3.08100,45.34171,45.34171,32.38693,0.07336
5.48000,3.22983,45.67490,45.67490,32.62493,0.07690
5.52000,3.23616,46.00835,46.00835,32.86311,0.07705
5.56000,3.42373,46.34159,46.34159,33.10114,0.08152
5.60000,3.29223,46.67494,46.67495,33.33925,0.07839
5.64000,3.26261,47.00837,47.00837,33.57741,0.07768
5.68000,3.42689,47.34161,47.34161,33.81544,0.08159
5.72000,3.31365,47.67509,47.67509,34.05364,0.07890
5.76000,3.35518,48.00820,48.00820,34.29157,0.07989
5.80000,3.25814,48.34168,48.34169,34.52978,0.07757
5.84000,3.28701,48.67490,48.67490,34.76779,0.07826
5.88000,3.14340,49.00840,49.00840,35.00600,0.07484
5.92000,3.64389,49.34165,49.34165,35.24403,0.08676
5.96000,3.83202,49.67494,49.67494,35.48210,0.09124
6.00000,3.71169,50.00834,50.00835,35.72025,0.08837
6.04000,3.59062,50.34158,50.34159,35.95828,0.08549
6.08000,3.45446,50.67509,50.67509,36.19649,0.08225
6.12000,3.85866,51.00823,51.00822,36.43445,0.09187
6.16000,4.17326,51.34174,51.34174,36.67267,0.09936
6.20000,3.94788,51.67490,51.67490,36.91064,0.09400
6.24000,4.18834,52.00835,52.00835,37.14882,0.09972
6.28000,4.05777,52.34167,52.34167,37.38691,0.09661
6.32000,3.77260,52.67491,52.67492,37.62494,0.08982
6.36000,4.54262,53.00837,53.00837,37.86312,0.10816
6.40000,4.02685,53.34158,53.34158,38.10113,0.09588
6.44000,3.85158,53.67509,53.67509,38.33935,0.09170
6.48000,3.92068,54.00828,54.00828,38.57734,0.09335
6.52000,3.80930,54.34171,54.34171,38.81550,0.09070
6.56000,3.85139,54.67490,54.67490,39.05350,0.09170
6.60000,4.10434,55.00838,55.00838,39.29170,0.09772
6.64000,3.96986,55.34164,55.34164,39.52974,0.09452
6.68000,3.76571,55.67499,55.67499,39.76785,0.08966
6.72000,4.07621,56.00837,56.00837,40.00598,0.09705
6.76000,3.82345,56.34155,56.34155,40.24397,0.09103
6.80000,4.09540,56.67504,56.67504,40.48217,0.09751
6.84000,3.79384,57.00823,57.00822,40.72016,0.09033
6.88000,3.82327,57.34176,57.34176,40.95840,0.09103
6.92000,4.25689,57.67492,57.67492,41.19637,0.10135
6.96000,3.67258,58.00835,58.00835,41.43454,0.08744
7.00000,3.83444,58.34162,58.34162,41.67258,0.09130
7.04000,4.23919,58.67499,58.67499,41.91071,0.10093
7.08000,4.04231,59.00839,59.00839,42.14885,0.09625
7.12000,3.97339,59.34161,59.34161,42.38687,0.09460
7.16000,4.59570,59.67506,59.67506,42.62505,0.10942
7.20000,4.13340,60.00823,60.00822,42.86302,0.09841
7.24000,4.09950,60.34178,60.34178,43.10127,0.09761
7.28000,3.87952,60.67492,60.67492,43.33923,0.09237
7.32000,4.29358,61.00835,61.00835,43.57739,0.10223
7.36000,4.34220,61.34159,61.34159,43.81542,0.10339
7.40000,4.03523,61.67496,61.67496,44.05355,0.09608
7.44000,4.42136,62.00842,62.00842,44.29173,0.10527
7.48000,4.71901,62.34158,62.34158,44.52970,0.11236
7.52000,4.48320,62.67506,62.67506,44.76790,0.10674
7.56000,4.48208,63.00817,63.00817,45.00584,0.10672
7.60000,4.31426,63.34173,63.34173,45.24409,0.10272
7.64000,4.46644,63.67498,63.67498,45.48213,0.10634
7.68000,4.18015,64.00837,64.00837,45.72026,0.09953
7.72000,4.24795,64.34163,64.34164,45.95831,0.10114
7.76000,4.27607,64.67499,64.67499,46.19642,0.10181
7.80000,4.48916,65.00839,65.00839,46.43457,0.10688
7.84000,4.09000,65.34155,65.34155,46.67254,0.09738
7.88000,4.36734,65.67506,65.67506,46.91076,0.10398
7.92000,4.44967,66.00824,66.00825,47.14875,0.10594
7.96000,4.42062,66.34173,66.34173,47.38695,0.10525
8.00000,4.36623,66.67492,66.67492,47.62494,0.10396
8.04000,4.62495,67.00834,67.00835,47.86310,0.11012
8.08000,4.43142,67.34167,67.34167,48.10119,0.10551
8.12000,4.50816,67.67496,67.67496,48.33925,0.10734
8.16000,4.41298,68.00836,68.00836,48.57740,0.10507
8.20000,4.19095,68.34163,68.34163,48.81545,0.09978
8.24000,4.16916,68.67508,68.67508,49.05363,0.09927
8.28000,4.30122,69.00822,69.00822,49.29158,0.10241
8.32000,4.06913,69.34173,69.34173,49.52981,0.09688
8.36000,4.04045,69.67486,69.67486,49.76776,0.09620
8.40000,4.48767,70.00840,70.00839,50.00600,0.10685
8.44000,4.06094,70.34167,70.34167,50.24405,0.09669
8.48000,4.55528,70.67496,70.67496,50.48211,0.10846
8.52000,4.19579,71.00836,71.00836,50.72026,0.09990
8.56000,4.09707,71.34154,71.34155,50.95825,0.09755
8.60000,4.27030,71.67506,71.67506,51.19647,0.10167
8.64000,4.43123,72.00822,72.00822,51.43444,0.10551
8.68000,4.21237,72.34173,72.34173,51.67266,0.10029
8.72000,4.40683,72.67491,72.67491,51.91065,0.10492
8.76000,4.24478,73.00837,73.00837,52.14884,0.10107
8.80000,4.10751,73.34163,73.34164,52.38688,0.09780
8.84000,4.03747,73.67501,73.67501,52.62501,0.09613
8.88000,4.17810,74.00836,74.00836,52.86312,0.09948
8.92000,4.11235,74.34158,74.34158,53.10113,0.09791
8.96000,4.31202,74.67514,74.67514,53.33939,0.10267
9.00000,4.16543,75.00822,75.00822,53.57730,0.09918
9.04000,4.35691,75.34173,75.34173,53.81552,0.10374
9.08000,4.36008,75.67491,75.67490,54.05350,0.10381
9.12000,4.47966,76.00834,76.00833,54.29167,0.10666
9.16000,4.58900,76.34167,76.34167,54.52976,0.10926
9.20000,4.70188,76.67493,76.67493,54.76781,0.11195
9.24000,4.64395,77.00838,77.00838,55.00599,0.11057
9.28000,4.52306,77.34160,77.34160,55.24400,0.10769
9.32000,5.04684,77.67506,77.67506,55.48218,0.12016
9.36000,4.89615,78.00822,78.00822,55.72016,0.11657
9.40000,4.48469,78.34175,78.34175,55.95839,0.10678
9.44000,4.55398,78.67494,78.67494,56.19639,0.10843
9.48000,4.53237,79.00837,79.00837,56.43455,0.10791
9.52000,4.99357,79.34163,79.34164,56.67260,0.11889
9.56000,4.84884,79.67501,79.67501,56.91072,0.11545
9.60000,4.70355,80.00838,80.00838,57.14884,0.11199
9.64000,5.01052,80.34154,80.34155,57.38682,0.11930
9.68000,4.62905,80.67506,80.67506,57.62504,0.11022
9.72000,4.81959,81.00823,81.00823,57.86303,0.11475
9.76000,4.87175,81.34175,81.34174,58.10125,0.11599
9.80000,4.79948,81.67491,81.67490,58.33922,0.11427
9.84000,4.70281,82.00837,82.00837,58.57741,0.11197
9.88000,4.76614,82.34161,82.34161,58.81543,0.11348
9.92000,4.70653,82.67497,82.67497,59.05355,0.11206
9.96000,4.92837,83.00835,83.00835,59.29168,0.11734
10.00000,4.70132,83.34158,83.34158,59.52970,0.11194
10.04000,4.74807,83.67507,83.67506,59.76791,0.11305
10.08000,4.52325,84.00821,84.00822,60.00587,0.10770
10.12000,4.79370,84.34180,84.34180,60.24414,0.11414
10.16000,4.98649,84.67493,84.67493,60.48210,0.11873
10.20000,5.00195,85.00837,85.00838,60.72026,0.11909
10.24000,5.53522,85.34161,85.34161,60.95829,0.13179
10.28000,5.17797,85.67495,85.67496,61.19640,0.12328
10.32000,5.49424,86.00843,86.00843,61.43460,0.13082
10.36000,5.42421,86.34156,86.34156,61.67254,0.12915
10.40000,5.44339,86.67499,86.67499,61.91071,0.12960
10.44000,5.57154,87.00823,87.00823,62.14874,0.13266
10.48000,5.34039,87.34175,87.34174,62.38696,0.12715
10.52000,5.76079,87.67493,87.67493,62.62495,0.13716
10.56000,5.81648,88.00839,88.00839,62.86314,0.13849
10.60000,5.89695,88.34160,88.34161,63.10115,0.14040
10.64000,5.83529,88.67495,88.67496,63.33925,0.13894
10.68000,5.68759,89.00838,89.00838,63.57741,0.13542
10.72000,6.20577,89.34162,89.34162,63.81544,0.14776
10.76000,5.73602,89.67510,89.67510,64.05364,0.13657
10.80000,5.68181,90.00823,90.00823,64.29160,0.13528
10.84000,6.06515,90.34172,90.34172,64.52980,0.14441
10.88000,6.01802,90.67491,90.67490,64.76779,0.14329
10.92000,5.91222,91.00839,91.00838,65.00599,0.14077
10.96000,5.94035,91.34166,91.34166,65.24404,0.14144
11.00000,6.11003,91.67497,91.67497,65.48212,0.14548
11.04000,6.24768,92.00830,92.00829,65.72021,0.14875
11.08000,6.35646,92.34156,92.34156,65.95826,0.15134
11.12000,6.15399,92.67510,92.67510,66.19650,0.14652
11.16000,6.38496,93.00823,93.00824,66.43445,0.15202
11.20000,6.23483,93.34177,93.34177,66.67269,0.14845
11.24000,6.09085,93.67488,93.67488,66.91063,0.14502
11.28000,6.16740,94.00841,94.00841,67.14886,0.14684
11.32000,6.20093,94.34168,94.34167,67.38691,0.14764
11.36000,6.13350,94.67497,94.67497,67.62498,0.14604
11.40000,6.63828,95.00833,95.00833,67.86309,0.15805
11.44000,6.36000,95.34156,95.34156,68.10111,0.15143
11.48000,6.27749,95.67510,95.67509,68.33935,0.14946
11.52000,6.57700,96.00826,96.00826,68.57733,0.15660
11.56000,6.32629,96.34174,96.34174,68.81553,0.15063
11.60000,6.03627,96.67488,96.67488,69.05348,0.14372
11.64000,6.56825,97.00833,97.00832,69.29166,0.15639
11.68000,6.44177,97.34162,97.34162,69.52973,0.15338
11.72000,6.50827,97.67497,97.67497,69.76784,0.15496
11.76000,6.48871,98.00837,98.00838,70.00598,0.15449
11.80000,6.60736,98.34159,98.34158,70.24399,0.15732
11.84000,6.28140,98.67512,98.67513,70.48223,0.14956
11.88000,6.31381,99.00823,99.00823,70.72017,0.15033
11.92000,6.44606,99.34174,99.34173,70.95838,0.15348
11.96000,6.59730,99.67493,99.67493,71.19638,0.15708
12.00000,6.21732,100.00833,100.00832,71.43452,0.14803
12.04000,6.53733,100.34166,100.34165,71.67261,0.15565
12.08000,6.58631,100.67497,100.67496,71.91069,0.15682
12.12000,6.66473,101.00835,101.00835,72.14882,0.15868
12.16000,6.87558,101.34159,101.34158,72.38685,0.16370
12.20000,6.71707,101.67505,101.67505,72.62504,0.15993
12.24000,6.62580,102.00823,102.00822,72.86302,0.15776
12.28000,6.75470,102.34177,102.34177,73.10126,0.16083
12.32000,6.86552,102.67490,102.67490,73.33921,0.16346
12.36000,6.72862,103.00838,103.00837,73.57741,0.16021
12.40000,6.86273,103.34162,103.34163,73.81545,0.16340
12.44000,6.53677,103.67500,103.67500,74.05357,0.15564
12.48000,6.47102,104.00843,104.00842,74.29173,0.15407
12.52000,6.72247,104.34159,104.34158,74.52970,0.16006
12.56000,6.57011,104.67506,104.67506,74.76791,0.15643
12.60000,6.48890,105.00821,105.00820,75.00586,0.15450
12.64000,6.61239,105.34174,105.34174,75.24410,0.15744
12.68000,6.57011,105.67490,105.67490,75.48207,0.15643
12.72000,6.89551,106.00836,106.00835,75.72026,0.16418
12.76000,6.94543,106.34159,106.34159,75.95828,0.16537
12.80000,6.78059,106.67496,106.67496,76.19640,0.16144
12.84000,6.34622,107.00837,107.00837,76.43455,0.15110
12.88000,6.67665,107.34158,107.34158,76.67256,0.15897
12.92000,6.73216,107.67506,107.67506,76.91076,0.16029
12.96000,6.48256,108.00817,108.00817,77.14869,0.15435
13.00000,6.82529,108.34179,108.34179,77.38699,0.16251
13.04000,6.72080,108.67498,108.67497,77.62498,0.16002
13.08000,6.62431,109.00836,109.00835,77.86311,0.15772
13.12000,6.53043,109.34165,109.34164,78.10118,0.15549
13.16000,6.63456,109.67494,109.67493,78.33924,0.15797
13.20000,6.85416,110.00840,110.00840,78.57743,0.16319
13.24000,7.02813,110.34161,110.34161,78.81544,0.16734
13.28000,6.69621,110.67504,110.67504,79.05360,0.15943
13.32000,6.74054,111.00823,111.00823,79.29159,0.16049
13.36000,6.92550,111.34170,111.34171,79.52979,0.16489
13.40000,6.93779,111.67489,111.67489,79.76778,0.16519
13.44000,6.59414,112.00832,112.00832,80.00594,0.15700
13.48000,6.87931,112.34161,112.34161,80.24401,0.16379
13.52000,6.70627,112.67500,112.67500,80.48214,0.15967
13.56000,6.53528,113.00839,113.00839,80.72028,0.15560
13.60000,6.26054,113.34163,113.34163,80.95831,0.14906
13.64000,6.66827,113.67509,113.67509,81.19649,0.15877
13.68000,7.08625,114.00822,114.00822,81.43445,0.16872
13.72000,6.87484,114.34174,114.34174,81.67267,0.16369
13.76000,6.87651,114.67492,114.67492,81.91066,0.16373
13.80000,6.82399,115.00841,115.00841,82.14886,0.16248
13.84000,6.33560,115.34165,115.34164,82.38689,0.15085
13.88000,6.80480,115.67496,115.67496,82.62497,0.16202
13.92000,7.10562,116.00831,116.00831,82.86307,0.16918
13.96000,6.91134,116.34156,116.34156,83.10111,0.16456
14.00000,7.07339,116.67510,116.67509,83.33935,0.16841
14.04000,7.14865,117.00822,117.00822,83.57730,0.17021
14.08000,7.03000,117.34177,117.34177,83.81555,0.16738
14.12000,7.14231,117.67486,117.67487,84.05347,0.17006
14.16000,6.91563,118.00838,118.00838,84.29170,0.16466
14.20000,6.62804,118.34172,118.34172,84.52980,0.15781
14.24000,6.80126,118.67496,118.67496,84.76782,0.16193
14.28000,7.07339,119.00839,119.00839,85.00599,0.16841
14.32000,6.91488,119.34158,119.34158,85.24398,0.16464
14.36000,6.88601,119.67511,119.67512,85.48223,0.16395
14.40000,7.13896,120.00825,120.00825,85.72018,0.16998
14.44000,7.05309,120.34170,120.34170,85.95836,0.16793
14.48000,6.90408,120.67486,120.67486,86.19633,0.16438
14.52000,6.94413,121.00836,121.00835,86.43454,0.16534
14.56000,7.29319,121.34165,121.34164,86.67260,0.17365
14.60000,6.99311,121.67496,121.67496,86.91069,0.16650
14.64000,6.90650,122.00837,122.00837,87.14883,0.16444
14.68000,6.75209,122.34154,122.34155,87.38682,0.16076
14.72000,7.00857,122.67506,122.67506,87.62504,0.16687
14.76000,6.83870,123.00825,123.00826,87.86304,0.16283
14.80000,6.92122,123.34178,123.34178,88.10127,0.16479
14.84000,6.29183,123.67494,123.67494,88.33925,0.14981
14.88000,6.79307,124.00835,124.00835,88.57739,0.16174
14.92000,6.94711,124.34164,124.34164,88.81546,0.16541
14.96000,6.83907,124.67499,124.67500,89.05357,0.16284
15.00000,6.98641,125.00836,125.00836,89.29169,0.16634
15.04000,6.99516,125.34160,125.34160,89.52972,0.16655
15.08000,7.16001,125.67506,125.67506,89.76790,0.17048
15.12000,6.90948,126.00818,126.00819,90.00584,0.16451
15.16000,7.26674,126.34175,126.34174,90.24410,0.17302
15.20000,7.16373,126.67491,126.67490,90.48207,0.17057
15.24000,7.08774,127.00837,127.00837,90.72026,0.16876
15.28000,7.47405,127.34163,127.34163,90.95831,0.17795
15.32000,6.98250,127.67496,127.67496,91.19640,0.16625
15.36000,7.36360,128.00842,128.00842,91.43459,0.17532
15.40000,7.50218,128.34161,128.34161,91.67258,0.17862
15.44000,6.85118,128.67508,128.67508,91.91077,0.16312
15.48000,7.36564,129.00819,129.00819,92.14871,0.17537
15.52000,7.07991,129.34175,129.34175,92.38697,0.16857
15.56000,6.78580,129.67495,129.67496,92.62497,0.16157
15.60000,6.92494,130.00839,130.00839,92.86313,0.16488
15.64000,6.99833,130.34161,130.34161,93.10115,0.16663
15.68000,7.31163,130.67493,130.67493,93.33923,0.17409
15.72000,7.43028,131.00839,131.00839,93.57742,0.17691
15.76000,7.58953,131.34156,131.34157,93.81540,0.18070
15.80000,7.55712,131.67506,131.67506,94.05361,0.17993
15.84000,7.47703,132.00818,132.00818,94.29156,0.17802
15.88000,7.46958,132.34172,132.34172,94.52980,0.17785
15.92000,7.60872,132.67497,132.67497,94.76784,0.18116
15.96000,7.53570,133.00837,133.00836,95.00598,0.17942
16.00000,7.59568,133.34163,133.34163,95.24402,0.18085
16.04000,7.59885,133.67496,133.67496,95.48212,0.18092
16.08000,7.23153,134.00838,134.00838,95.72027,0.17218
16.12000,7.67093,134.34162,134.34161,95.95830,0.18264
16.16000,7.68621,134.67508,134.67508,96.19648,0.18300
16.20000,7.42134,135.00823,135.00822,96.43445,0.17670
16.24000,7.81529,135.34175,135.34175,96.67268,0.18608
16.28000,7.81901,135.67491,135.67491,96.91065,0.18617
16.32000,7.81249,136.00839,136.00839,97.14885,0.18601
16.36000,7.76965,136.34164,136.34164,97.38688,0.18499
16.40000,7.65231,136.67497,136.67497,97.62498,0.18220
16.44000,8.04011,137.00836,137.00836,97.86311,0.19143
16.48000,7.87135,137.34156,137.34157,98.10112,0.18741
16.52000,8.05296,137.67509,137.67508,98.33935,0.19174
16.56000,7.81864,138.00827,138.00827,98.57734,0.18616
16.60000,7.60891,138.34177,138.34177,98.81555,0.18116
16.64000,7.68900,138.67493,138.67493,99.05352,0.18307
16.68000,7.72122,139.00842,139.00842,99.29173,0.18384
16.72000,7.95238,139.34163,139.34163,99.52974,0.18934
16.76000,8.11834,139.67499,139.67499,99.76785,0.19329
16.80000,8.17031,140.00835,140.00836,100.00597,0.19453
16.84000,8.16844,140.34154,140.34154,100.24396,0.19449
16.88000,8.10921,140.67513,140.67513,100.48224,0.19308
16.92000,7.76462,141.00820,141.00819,100.72014,0.18487
16.96000,7.73184,141.34173,141.34172,100.95837,0.18409
17.00000,7.90022,141.67485,141.67484,101.19631,0.18810
17.04000,8.17236,142.00835,142.00835,101.43453,0.19458
17.08000,8.03396,142.34168,142.34167,101.67263,0.19128
17.12000,8.09859,142.67498,142.67497,101.91070,0.19282
17.16000,8.02856,143.00836,143.00836,102.14883,0.19116
17.20000,8.16882,143.34159,143.34158,102.38684,0.19450
17.24000,8.26027,143.67511,143.67511,102.62508,0.19667
17.28000,8.60896,144.00828,144.00829,102.86306,0.20498
17.32000,8.33329,144.34177,144.34177,103.10127,0.19841
17.36000,8.20570,144.67490,144.67491,103.33922,0.19537
17.40000,8.02521,145.00836,145.00836,103.57740,0.19108
17.44000,7.96113,145.34166,145.34166,103.81547,0.18955
17.48000,8.48770,145.67495,145.67494,104.05353,0.20209
17.52000,8.61678,146.00831,146.00832,104.29165,0.20516
17.56000,8.45399,146.34157,146.34157,104.52969,0.20129
17.60000,8.58027,146.67504,146.67503,104.76788,0.20429
17.64000,8.54898,147.00826,147.00827,105.00591,0.20355
17.68000,8.45548,147.34176,147.34175,105.24411,0.20132
17.72000,8.52067,147.67491,147.67491,105.48208,0.20287
17.76000,8.18446,148.00834,148.00835,105.72025,0.19487
17.80000,8.44263,148.34164,148.34163,105.95831,0.20101
17.84000,8.47112,148.67503,148.67503,106.19645,0.20169
17.88000,8.42940,149.00840,149.00839,106.43457,0.20070
17.92000,8.51452,149.34159,149.34158,106.67256,0.20273
17.96000,8.52086,149.67511,149.67511,106.91079,0.20288
18.00000,8.58288,150.00818,150.00818,107.14869,0.20435
18.04000,8.84179,150.34177,150.34177,107.38698,0.21052
18.08000,8.35620,150.67493,150.67493,107.62495,0.19896
18.12000,8.65422,151.00836,151.00836,107.86312,0.20605
18.16000,8.79001,151.34159,151.34158,108.10113,0.20929
18.20000,8.29715,151.67489,151.67491,108.33921,0.19755
18.24000,8.40276,152.00840,152.00841,108.57743,0.20007
18.28000,8.52495,152.34164,152.34164,108.81546,0.20298
18.32000,8.61268,152.67506,152.67505,109.05361,0.20506
18.36000,8.62461,153.00822,153.00822,109.29159,0.20535
18.40000,8.68421,153.34179,153.34178,109.52985,0.20677
18.44000,8.42586,153.67495,153.67494,109.76782,0.20062
18.48000,9.02694,154.00838,154.00838,110.00599,0.21493
18.52000,8.92412,154.34160,154.34160,110.24400,0.21248
18.56000,8.97776,154.67492,154.67493,110.48208,0.21376
18.60000,8.89152,155.00840,155.00839,110.72029,0.21170
18.64000,8.84123,155.34158,155.34158,110.95828,0.21051
18.68000,8.85073,155.67507,155.67506,111.19648,0.21073
18.72000,9.13441,156.00818,156.00818,111.43441,0.21749
18.76000,9.04649,156.34166,156.34166,111.67262,0.21539
18.80000,9.00682,156.67490,156.67490,111.91064,0.21445
18.84000,8.95280,157.00839,157.00839,112.14885,0.21316
18.88000,8.64230,157.34165,157.34166,112.38689,0.20577
18.92000,9.04761,157.67501,157.67500,112.62500,0.21542
18.96000,9.10424,158.00834,158.00833,112.86310,0.21677
19.00000,9.04258,158.34164,158.34164,113.10117,0.21530
19.04000,9.11821,158.67510,158.67511,113.33936,0.21710
19.08000,9.16831,159.00822,159.00822,113.57731,0.21829
19.12000,8.90754,159.34176,159.34177,113.81555,0.21208
19.16000,9.14633,159.67491,159.67493,114.05351,0.21777
19.20000,9.23667,160.00838,160.00838,114.29170,0.21992
19.24000,9.25101,160.34165,160.34166,114.52975,0.22026
19.28000,9.38065,160.67496,160.67496,114.76783,0.22335
19.32000,9.66098,161.00834,161.00835,115.00596,0.23002
19.36000,9.37674,161.34156,161.34155,115.24397,0.22326
19.40000,9.37134,161.67507,161.67505,115.48219,0.22313
19.44000,9.31546,162.00827,162.00827,115.72019,0.22180
19.48000,9.29069,162.34174,162.34175,115.95839,0.22121
19.52000,9.27523,162.67486,162.67487,116.19633,0.22084
19.56000,9.47118,163.00839,163.00839,116.43456,0.22550
19.60000,9.27057,163.34170,163.34171,116.67265,0.22073
19.64000,9.29479,163.67502,163.67502,116.91073,0.22130
19.68000,9.31863,164.00840,164.00842,117.14886,0.22187
19.72000,9.66843,164.34156,164.34157,117.38683,0.23020
19.76000,9.49875,164.67509,164.67508,117.62506,0.22616
19.80000,9.60734,165.00822,165.00821,117.86301,0.22875
19.84000,9.29888,165.34175,165.34175,118.10125,0.22140
19.88000,9.78895,165.67492,165.67493,118.33923,0.23307
19.92000,9.70252,166.00834,166.00835,118.57738,0.23101
19.96000,10.05940,166.34165,166.34164,118.81546,0.23951
20.00000,9.43299,166.67496,166.67496,119.05354,0.22460
20.04000,9.88916,167.00832,167.00832,119.29165,0.23546
20.08000,9.41306,167.34158,167.34158,119.52970,0.22412
20.12000,9.87370,167.67507,167.67506,119.76790,0.23509
20.16000,9.96031,168.00828,168.00829,120.00592,0.23715
20.20000,9.83756,168.34177,168.34177,120.24412,0.23423
20.24000,9.69619,168.67489,168.67488,120.48206,0.23086
20.28000,9.69283,169.00835,169.00833,120.72024,0.23078
20.32000,9.99309,169.34168,169.34167,120.95834,0.23793
20.36000,9.89325,169.67502,169.67503,121.19645,0.23555
20.40000,9.61386,170.00840,170.00841,121.43457,0.22890
20.44000,10.03034,170.34159,170.34158,121.67256,0.23882
20.48000,10.34923,170.67504,170.67503,121.91074,0.24641
20.52000,9.97316,171.00825,171.00826,122.14875,0.23746
20.56000,9.79267,171.34171,171.34171,122.38693,0.23316
20.60000,10.15253,171.67489,171.67490,122.62492,0.24173
20.64000,10.39729,172.00841,172.00841,122.86315,0.24755
20.68000,10.15123,172.34163,172.34163,123.10116,0.24170
20.72000,10.08715,172.67503,172.67503,123.33931,0.24017
20.76000,10.25070,173.00840,173.00839,123.57743,0.24406
20.80000,10.32706,173.34156,173.34155,123.81539,0.24588
20.84000,10.02345,173.67511,173.67511,124.05365,0.23865
20.88000,10.19817,174.00823,174.00822,124.29159,0.24281
20.92000,10.52860,174.34179,174.34180,124.52985,0.25068
20.96000,10.51575,174.67497,174.67497,124.76783,0.25037
21.00000,10.57163,175.00837,175.00838,125.00598,0.25171
21.04000,10.16855,175.34161,175.34161,125.24401,0.24211
21.08000,10.35631,175.67490,175.67490,125.48207,0.24658
21.12000,10.59864,176.00840,176.00841,125.72029,0.25235
21.16000,10.44031,176.34160,176.34160,125.95829,0.24858
21.20000,10.79217,176.67503,176.67503,126.19646,0.25696
21.24000,10.64241,177.00817,177.00816,126.43441,0.25339
21.28000,10.57684,177.34173,177.34172,126.67266,0.25183
21.32000,10.39468,177.67495,177.67494,126.91067,0.24749
21.36000,10.75473,178.00841,178.00842,127.14887,0.25606
21.40000,10.41945,178.34167,178.34167,127.38690,0.24808
21.44000,10.24436,178.67499,178.67499,127.62499,0.24391
21.48000,10.60721,179.00842,179.00842,127.86316,0.25255
21.52000,10.81452,179.34163,179.34163,128.10117,0.25749
21.56000,11.06244,179.67508,179.67508,128.33934,0.26339
21.60000,10.50588,180.00823,180.00822,128.57730,0.25014
21.64000,10.36916,180.34173,180.34172,128.81552,0.24688
21.68000,10.68413,180.67495,180.67496,129.05353,0.25438
21.72000,10.83333,181.00837,181.00836,129.29169,0.25794
21.76000,10.89107,181.34161,181.34161,129.52973,0.25931
21.80000,10.83706,181.67494,181.67494,129.76781,0.25803
21.84000,11.01084,182.00831,182.00832,130.00593,0.26216
21.88000,10.84283,182.34160,182.34161,130.24400,0.25816
21.92000,10.71505,182.67515,182.67517,130.48226,0.25512
21.96000,11.06411,183.00825,183.00824,130.72017,0.26343
22.00000,10.79701,183.34178,183.34178,130.95841,0.25707
22.04000,10.72921,183.67494,183.67494,131.19639,0.25546
22.08000,10.94341,184.00839,184.00838,131.43456,0.26056
22.12000,11.17345,184.34166,184.34166,131.67261,0.26603
22.16000,11.25615,184.67499,184.67499,131.91071,0.26800
22.20000,10.87990,185.00835,185.00836,132.14883,0.25905
22.24000,10.95571,185.34154,185.34154,132.38682,0.26085
22.28000,10.81862,185.67507,185.67506,132.62504,0.25759
22.32000,11.32227,186.00823,186.00822,132.86302,0.26958
22.36000,11.45676,186.34175,186.34175,133.10125,0.27278
22.40000,11.16600,186.67486,186.67487,133.33919,0.26586
22.44000,10.92423,187.00835,187.00836,133.57739,0.26010
22.48000,11.30085,187.34169,187.34169,133.81549,0.26907
22.52000,11.37648,187.67498,187.67497,134.05355,0.27087
22.56000,11.33233,188.00841,188.00841,134.29172,0.26982
22.60000,11.22486,188.34155,188.34155,134.52967,0.26726
22.64000,11.14514,188.67511,188.67511,134.76794,0.26536
22.68000,11.28055,189.00831,189.00832,135.00594,0.26858
22.72000,11.33867,189.34174,189.34175,135.24411,0.26997
22.76000,11.18425,189.67494,189.67493,135.48210,0.26629
22.80000,11.07659,190.00833,190.00833,135.72023,0.26373
22.84000,11.39324,190.34162,190.34163,135.95830,0.27127
22.88000,11.67078,190.67498,190.67500,136.19642,0.27788
22.92000,11.30085,191.00834,191.00835,136.43453,0.26907
22.96000,10.79496,191.34154,191.34154,136.67253,0.25702
23.00000,11.14830,191.67503,191.67503,136.91074,0.26544
23.04000,11.51469,192.00826,192.00827,137.14876,0.27416
23.08000,11.44577,192.34183,192.34184,137.38703,0.27252
23.12000,11.37182,192.67491,192.67490,137.62493,0.27076
23.16000,11.55138,193.00838,193.00838,137.86314,0.27503
23.20000,11.96321,193.34169,193.34169,138.10121,0.28484
23.24000,11.78551,193.67500,193.67500,138.33929,0.28061
23.28000,11.55008,194.00839,194.00838,138.57741,0.27500
23.32000,12.23795,194.34160,194.34160,138.81543,0.29138
23.36000,12.10496,194.67508,194.67508,139.05363,0.28821
23.40000,11.87511,195.00822,195.00822,139.29158,0.28274
23.44000,11.80433,195.34174,195.34175,139.52981,0.28106
23.48000,12.00233,195.67489,195.67490,139.76778,0.28577
23.52000,12.00791,196.00836,196.00836,140.00597,0.28590
23.56000,12.04200,196.34162,196.34161,140.24401,0.28671
23.60000,11.93061,196.67492,196.67491,140.48208,0.28406
23.64000,12.03269,197.00838,197.00838,140.72027,0.28649
23.68000,12.13681,197.34163,197.34163,140.95831,0.28897
23.72000,12.05448,197.67510,197.67511,141.19650,0.28701
23.76000,12.18840,198.00822,198.00822,141.43444,0.29020
23.80000,12.09676,198.34178,198.34178,141.67269,0.28802
23.84000,11.86822,198.67496,198.67496,141.91068,0.28258
23.88000,11.84195,199.00837,199.00838,142.14884,0.28195
23.92000,12.07106,199.34163,199.34163,142.38688,0.28741
23.96000,12.22603,199.67496,199.67496,142.62497,0.29110
24.00000,11.85667,200.00838,200.00839,142.86313,0.28230
24.04000,12.34096,200.34160,200.34160,143.10114,0.29383
24.08000,12.51176,200.67508,200.67508,143.33935,0.29790
24.12000,12.34841,201.00820,201.00821,143.57729,0.29401
24.16000,12.40298,201.34172,201.34174,143.81552,0.29531
24.20000,12.43670,201.67493,201.67493,144.05352,0.29611
24.24000,12.45141,202.00839,202.00839,144.29171,0.29646
24.28000,12.39125,202.34165,202.34166,144.52975,0.29503
24.32000,12.48848,202.67494,202.67494,144.76782,0.29734
24.36000,12.67921,203.00838,203.00839,145.00599,0.30189
24.40000,12.77477,203.34164,203.34164,145.24403,0.30416
24.44000,12.36778,203.67510,203.67511,145.48222,0.29447
24.48000,12.38789,204.00824,204.00824,145.72017,0.29495
24.52000,12.84238,204.34175,204.34175,145.95839,0.30577
24.56000,12.96215,204.67491,204.67491,146.19637,0.30862
24.60000,12.68107,205.00838,205.00838,146.43456,0.30193
24.64000,12.57882,205.34161,205.34161,146.67258,0.29950
24.68000,12.62203,205.67498,205.67496,146.91069,0.30052
24.72000,13.03088,206.00838,206.00838,147.14885,0.31026
24.76000,12.68871,206.34156,206.34155,147.38683,0.30211
24.80000,12.77048,206.67511,206.67511,147.62508,0.30406
24.84000,12.87032,207.00820,207.00821,147.86301,0.30644
24.88000,13.08993,207.34174,207.34174,148.10125,0.31166
24.92000,13.24154,207.67493,207.67493,148.33924,0.31527
24.96000,12.95973,208.00839,208.00839,148.57742,0.30856
25.00000,12.74142,208.34172,208.34172,148.81551,0.30337
25.04000,12.77830,208.67501,208.67500,149.05357,0.30425
25.08000,12.77421,209.00838,209.00838,149.29169,0.30415
25.12000,12.86063,209.34156,209.34157,149.52968,0.30621
25.16000,13.00368,209.67506,209.67506,149.76790,0.30961
25.20000,12.89640,210.00822,210.00822,150.00588,0.30706
25.24000,12.65835,210.34177,210.34177,150.24413,0.30139
25.28000,12.71814,210.67488,210.67488,150.48206,0.30281
25.32000,12.98003,211.00833,211.00833,150.72024,0.30905
25.36000,12.99214,211.34166,211.34166,150.95832,0.30934
25.40000,12.93123,211.67496,211.67494,151.19640,0.30789
25.44000,13.38962,212.00838,212.00839,151.43456,0.31880
25.48000,13.45966,212.34156,212.34155,151.67254,0.32047
25.52000,13.58949,212.67507,212.67505,151.91076,0.32356
25.56000,13.15549,213.00828,213.00829,152.14877,0.31323
25.60000,13.31270,213.34179,213.34180,152.38700,0.31697
25.64000,13.27563,213.67490,213.67490,152.62493,0.31609
25.68000,13.17412,214.00836,214.00838,152.86312,0.31367
25.72000,13.19256,214.34165,214.34164,153.10118,0.31411
25.76000,13.41030,214.67501,214.67500,153.33929,0.31929
25.80000,13.53789,215.00838,215.00838,153.57741,0.32233
25.84000,13.33077,215.34156,215.34157,153.81540,0.31740
25.88000,13.48760,215.67505,215.67505,154.05360,0.32113
25.92000,13.56900,216.00821,216.00821,154.29158,0.32307
25.96000,13.56266,216.34175,216.34175,154.52982,0.32292
26.00000,13.62376,216.67493,216.67493,154.76781,0.32438
26.04000,13.42800,217.00838,217.00839,155.00599,0.31971
26.08000,13.65170,217.34166,217.34166,155.24404,0.32504
26.12000,13.64183,217.67500,217.67502,155.48215,0.32481
26.16000,13.65375,218.00840,218.00839,155.72028,0.32509
26.20000,13.64499,218.34161,218.34161,155.95829,0.32488
26.24000,13.54162,218.67511,218.67509,156.19650,0.32242
26.28000,13.53696,219.00821,219.00821,156.43444,0.32231
26.32000,13.59992,219.34171,219.34172,156.67266,0.32381
26.36000,13.78041,219.67487,219.67488,156.91062,0.32810
26.40000,13.72285,220.00837,220.00838,157.14884,0.32673
26.44000,13.62953,220.34164,220.34164,157.38689,0.32451
26.48000,13.79531,220.67490,220.67490,157.62494,0.32846
26.52000,13.38590,221.00838,221.00838,157.86313,0.31871
26.56000,13.58483,221.34156,221.34157,158.10112,0.32345
26.60000,13.71074,221.67506,221.67506,158.33933,0.32645
26.64000,13.65058,222.00822,222.00822,158.57730,0.32501
26.68000,13.98157,222.34172,222.34172,158.81552,0.33289
26.72000,14.13785,222.67498,222.67499,159.05356,0.33662
26.76000,14.05980,223.00841,223.00841,159.29172,0.33476
26.80000,13.80984,223.34164,223.34164,159.52975,0.32881
26.84000,13.77054,223.67496,223.67496,159.76783,0.32787
26.88000,13.79754,224.00836,224.00836,160.00596,0.32851
26.92000,13.99480,224.34159,224.34160,160.24400,0.33321
26.96000,13.85268,224.67509,224.67509,160.48220,0.32983
27.00000,13.54013,225.00820,225.00819,160.72015,0.32238
27.04000,13.88304,225.34173,225.34172,160.95837,0.33055
27.08000,13.56639,225.67491,225.67491,161.19636,0.32301
27.12000,13.85268,226.00839,226.00839,161.43456,0.32983
27.16000,14.25967,226.34162,226.34163,161.67259,0.33952
27.20000,13.95345,226.67494,226.67494,161.91068,0.33222
27.24000,13.81561,227.00839,227.00839,162.14885,0.32894
27.28000,14.26376,227.34165,227.34164,162.38689,0.33961
27.32000,14.34814,227.67507,227.67508,162.62505,0.34162
27.36000,13.81747,228.00821,228.00821,162.86300,0.32899
27.40000,14.16821,228.34176,228.34175,163.10126,0.33734
27.44000,13.51647,228.67492,228.67491,163.33923,0.32182
27.48000,13.58837,229.00839,229.00839,163.57743,0.32353
27.52000,13.88453,229.34166,229.34166,163.81547,0.33058
27.56000,14.11662,229.67497,229.67497,164.05355,0.33611
27.60000,14.32505,230.00837,230.00836,164.29169,0.34107
27.64000,14.11512,230.34155,230.34155,164.52968,0.33607
27.68000,13.96816,230.67508,230.67508,164.76791,0.33258
27.72000,14.19019,231.00824,231.00824,165.00589,0.33786
27.76000,14.36360,231.34174,231.34174,165.24410,0.34199
27.80000,14.13673,231.67490,231.67490,165.48207,0.33659
27.84000,14.27252,232.00835,232.00835,165.72025,0.33982
27.88000,14.22074,232.34166,232.34166,165.95833,0.33859
27.92000,14.47741,232.67498,232.67497,166.19642,0.34470
27.96000,13.68374,233.00835,233.00835,166.43454,0.32580
28.00000,13.99182,233.34161,233.34161,166.67258,0.33314
28.04000,14.16858,233.67511,233.67511,166.91079,0.33735
28.08000,13.94562,234.00825,234.00824,167.14875,0.33204
28.12000,14.26786,234.34174,234.34175,167.38696,0.33971
28.16000,14.48598,234.67490,234.67491,167.62493,0.34490
28.20000,14.15759,235.00830,235.00830,167.86307,0.33709
28.24000,13.98530,235.34164,235.34164,168.10117,0.33298
28.28000,14.22074,235.67498,235.67499,168.33928,0.33859
28.32000,14.30046,236.00838,236.00838,168.57741,0.34049
28.36000,14.39136,236.34154,236.34154,168.81539,0.34265
28.40000,14.64970,236.67504,236.67503,169.05360,0.34880
28.44000,14.50945,237.00828,237.00827,169.29163,0.34546
28.48000,14.48356,237.34178,237.34178,169.52984,0.34485
28.52000,14.84398,237.67491,237.67491,169.76780,0.35343
28.56000,14.61357,238.00838,238.00838,170.00599,0.34794
28.60000,14.52044,238.34162,238.34163,170.24401,0.34572
28.64000,14.49324,238.67502,238.67502,170.48216,0.34508
28.68000,14.41874,239.00836,239.00836,170.72026,0.34330
28.72000,14.62661,239.34149,239.34149,170.95821,0.34825
28.76000,14.54130,239.67510,239.67509,171.19650,0.34622
28.80000,14.67150,240.00821,240.00821,171.43443,0.34932
28.84000,14.71415,240.34176,240.34175,171.67268,0.35034
28.88000,14.96319,240.67494,240.67494,171.91067,0.35627
28.92000,14.94642,241.00834,241.00833,172.14881,0.35587
28.96000,14.97176,241.34163,241.34163,172.38687,0.35647
29.00000,15.08873,241.67494,241.67494,172.62496,0.35926
29.04000,14.68416,242.00839,242.00839,172.86314,0.34962
29.08000,14.88235,242.34163,242.34163,173.10116,0.35434
29.12000,15.16398,242.67510,242.67511,173.33935,0.36105
29.16000,15.25227,243.00821,243.00821,173.57730,0.36315
29.20000,15.13567,243.34176,243.34177,173.81555,0.36037
29.24000,15.15709,243.67492,243.67493,174.05351,0.36088
29.28000,15.18745,244.00840,244.00839,174.29171,0.36161
29.32000,15.25339,244.34163,244.34163,174.52974,0.36318
29.36000,15.04272,244.67490,244.67490,174.76778,0.35816
29.40000,15.26196,245.00840,245.00839,175.00600,0.36338
29.44000,15.18652,245.34158,245.34158,175.24399,0.36158
29.48000,15.22191,245.67508,245.67508,175.48220,0.36243
29.52000,15.29567,246.00824,246.00824,175.72018,0.36418
29.56000,15.27797,246.34169,246.34169,175.95835,0.36376
29.60000,15.53893,246.67493,246.67493,176.19637,0.36997
29.64000,15.32305,247.00840,247.00841,176.43458,0.36483
29.68000,15.55737,247.34164,247.34164,176.67260,0.37041
29.72000,15.62368,247.67493,247.67493,176.91066,0.37199
29.76000,15.71439,248.00838,248.00838,177.14884,0.37415
29.80000,15.72743,248.34164,248.34164,177.38689,0.37446
29.84000,15.29437,248.67514,248.67514,177.62510,0.36415
29.88000,15.64156,249.00822,249.00822,177.86301,0.37242
29.92000,15.34801,249.34170,249.34169,178.10121,0.36543
29.96000,15.58047,249.67488,249.67488,178.33921,0.37096
30.00000,15.62797,250.00836,250.00836,178.57740,0.37209
30.04000,15.64957,250.34165,250.34164,178.81546,0.37261
30.08000,15.85986,250.67496,250.67496,179.05354,0.37762
30.12000,16.05097,251.00833,251.00833,179.29167,0.38217
30.16000,16.08245,251.34160,251.34160,179.52971,0.38292
30.20000,15.82801,251.67507,251.67506,179.76791,0.37686
30.24000,15.89917,252.00818,252.00818,180.00584,0.37855
30.28000,15.96399,252.34178,252.34178,180.24412,0.38009
30.32000,16.34173,252.67491,252.67491,180.48208,0.38909
30.36000,16.15547,253.00841,253.00841,180.72029,0.38465
30.40000,16.04650,253.34165,253.34166,180.95832,0.38206
30.44000,15.82727,253.67497,253.67497,181.19640,0.37684
30.48000,16.16646,254.00839,254.00839,181.43456,0.38492
30.52000,16.14355,254.34155,254.34155,181.67254,0.38437
30.56000,16.17037,254.67508,254.67508,181.91077,0.38501
30.60000,16.21880,255.00824,255.00824,182.14874,0.38616
30.64000,16.29777,255.34176,255.34177,182.38697,0.38804
30.68000,15.98727,255.67495,255.67494,182.62496,0.38065
30.72000,16.23705,256.00834,256.00833,182.86310,0.38660
30.76000,16.10797,256.34161,256.34161,183.10115,0.38352
30.80000,16.20296,256.67503,256.67502,183.33931,0.38578
30.84000,16.22997,257.00840,257.00839,183.57743,0.38643
30.88000,16.42089,257.34161,257.34161,183.81543,0.39097
30.92000,16.14019,257.67508,257.67508,184.05364,0.38429
30.96000,16.45088,258.00824,258.00824,184.29160,0.39169
31.00000,16.52539,258.34177,258.34177,184.52983,0.39346
31.04000,16.48627,258.67493,258.67493,184.76781,0.39253
31.08000,16.38755,259.00832,259.00833,185.00594,0.39018
31.12000,16.31789,259.34166,259.34167,185.24405,0.38852
31.16000,16.55910,259.67496,259.67496,185.48211,0.39426
31.20000,16.62634,260.00838,260.00836,185.72026,0.39587
31.24000,16.66769,260.34156,260.34155,185.95825,0.39685
31.28000,16.17838,260.67504,260.67505,186.19646,0.38520
31.32000,16.49708,261.00827,261.00827,186.43448,0.39279
31.36000,16.65261,261.34172,261.34174,186.67266,0.39649
31.40000,16.80125,261.67485,261.67487,186.91061,0.40003
31.44000,16.88078,262.00835,262.00836,187.14882,0.40192
31.48000,16.95901,262.34167,262.34167,187.38691,0.40379
31.52000,16.86960,262.67504,262.67505,187.62503,0.40166
31.56000,16.95026,263.00841,263.00842,187.86315,0.40358
31.60000,17.06388,263.34152,263.34152,188.10108,0.40628
31.64000,16.71799,263.67507,263.67508,188.33933,0.39805
31.68000,16.67161,264.00820,264.00821,188.57728,0.39694
31.72000,17.11119,264.34178,264.34177,188.81556,0.40741
31.76000,17.02886,264.67489,264.67490,189.05349,0.40545
31.80000,17.23524,265.00833,265.00833,189.29167,0.41036
31.84000,17.29652,265.34168,265.34167,189.52976,0.41182
31.88000,17.11994,265.67499,265.67499,189.76785,0.40762
31.92000,17.49713,266.00841,266.00842,190.00601,0.41660
31.96000,17.31534,266.34157,266.34158,190.24398,0.41227
32.00000,17.01266,266.67505,266.67505,190.48218,0.40506
32.04000,17.50235,267.00821,267.00821,190.72015,0.41672
32.08000,17.57257,267.34179,267.34180,190.95842,0.41839
32.12000,17.46267,267.67500,267.67499,191.19643,0.41578
32.16000,17.67371,268.00837,268.00836,191.43455,0.42080
32.20000,17.61056,268.34160,268.34161,191.67258,0.41930
32.24000,17.33638,268.67495,268.67496,191.91067,0.41277
32.28000,17.19687,269.00837,269.00836,192.14883,0.40945
32.32000,17.21270,269.34163,269.34164,192.38688,0.40983
32.36000,17.56754,269.67505,269.67505,192.62503,0.41827
32.40000,17.71729,270.00821,270.00821,192.86301,0.42184
32.44000,17.56158,270.34169,270.34167,193.10120,0.41813
32.48000,17.77019,270.67493,270.67493,193.33923,0.42310
32.52000,18.06933,271.00845,271.00845,193.57747,0.43022
32.56000,17.89220,271.34166,271.34167,193.81547,0.42600
32.60000,17.79255,271.67495,271.67496,194.05354,0.42363
32.64000,17.83445,272.00837,272.00836,194.29170,0.42463
32.68000,17.41610,272.34161,272.34161,194.52972,0.41467
32.72000,17.91492,272.67514,272.67514,194.76795,0.42655
32.76000,18.05779,273.00817,273.00818,195.00583,0.42995
32.80000,17.69252,273.34169,273.34171,195.24406,0.42125
32.84000,17.91436,273.67491,273.67490,195.48208,0.42653
32.88000,18.25746,274.00840,274.00839,195.72029,0.43470
32.92000,18.08759,274.34164,274.34164,195.95832,0.43066
32.96000,18.07939,274.67496,274.67496,196.19640,0.43046
33.00000,17.78118,275.00833,275.00833,196.43452,0.42336
33.04000,17.73257,275.34159,275.34158,196.67257,0.42220
33.08000,17.96428,275.67517,275.67517,196.91083,0.42772
33.12000,18.21052,276.00823,276.00824,197.14873,0.43358
33.16000,18.12167,276.34178,276.34177,197.38698,0.43147
33.20000,17.83539,276.67489,276.67490,197.62492,0.42465
33.24000,18.37853,277.00836,277.00836,197.86311,0.43758
33.28000,18.38543,277.34170,277.34171,198.10121,0.43775
33.32000,18.38487,277.67497,277.67496,198.33926,0.43773
33.36000,18.57467,278.00839,278.00839,198.57742,0.44225
33.40000,18.35674,278.34157,278.34158,198.81541,0.43707
33.44000,18.06170,278.67507,278.67508,199.05362,0.43004
33.48000,18.16861,279.00826,279.00827,199.29161,0.43259
33.52000,18.33122,279.34173,279.34174,199.52980,0.43646
33.56000,18.19246,279.67497,279.67496,199.76784,0.43315
33.60000,18.29788,280.00839,280.00839,200.00598,0.43566
33.64000,17.78901,280.34163,280.34161,200.24402,0.42355
33.68000,18.55474,280.67502,280.67502,200.48215,0.44178
33.72000,18.53462,281.00839,281.00839,200.72029,0.44130
33.76000,18.46664,281.34160,281.34164,200.95830,0.43968
33.80000,18.41243,281.67500,281.67499,201.19643,0.43839
33.84000,18.78664,282.00824,282.00821,201.43445,0.44730
33.88000,18.64973,282.34179,282.34177,201.67270,0.44404
33.92000,18.94441,282.67492,282.67493,201.91066,0.45106
33.96000,18.71623,283.00834,283.00833,202.14882,0.44562
34.00000,18.42175,283.34164,283.34164,202.38688,0.43861
34.04000,18.46179,283.67500,283.67502,202.62501,0.43957
34.08000,18.54356,284.00837,284.00836,202.86312,0.44151
34.12000,18.78198,284.34161,284.34161,203.10116,0.44719
34.16000,18.55250,284.67511,284.67511,203.33936,0.44173
34.20000,18.58808,285.00824,285.00827,203.57733,0.44257
34.24000,18.70729,285.34182,285.34183,203.81558,0.44541
34.28000,18.89355,285.67488,285.67487,204.05347,0.44985
34.32000,18.62571,286.00835,286.00836,204.29168,0.44347
34.36000,18.93174,286.34162,286.34158,204.52971,0.45076
34.40000,19.04834,286.67493,286.67493,204.76780,0.45353
34.44000,19.01388,287.00838,287.00839,205.00598,0.45271
34.48000,18.99358,287.34154,287.34152,205.24395,0.45223
34.52000,19.08354,287.67506,287.67505,205.48220,0.45437
34.56000,19.13942,288.00822,288.00821,205.72016,0.45570
34.60000,18.72778,288.34178,288.34177,205.95841,0.44590
34.64000,18.61770,288.67496,288.67496,206.19640,0.44328
34.68000,18.52438,289.00836,289.00836,206.43454,0.44106
34.72000,18.79707,289.34165,289.34164,206.67260,0.44755
34.76000,19.20518,289.67499,289.67499,206.91071,0.45727
34.80000,18.91442,290.00838,290.00839,207.14884,0.45034
34.84000,18.90007,290.34157,290.34158,207.38683,0.45000
34.88000,18.83768,290.67510,290.67511,207.62508,0.44852
34.92000,19.64457,291.00820,291.00821,207.86300,0.46773
34.96000,19.70232,291.34173,291.34171,208.10122,0.46910
35.00000,19.43335,291.67492,291.67490,208.33921,0.46270
35.04000,19.76211,292.00836,292.00836,208.57739,0.47053
35.08000,19.71349,292.34163,292.34161,208.81546,0.46937
35.12000,19.48625,292.67497,292.67496,209.05354,0.46396
35.16000,19.78800,293.00834,293.00833,209.29167,0.47114
35.20000,19.40671,293.34166,293.34164,209.52976,0.46206
35.24000,19.41305,293.67510,293.67511,209.76794,0.46222
35.28000,19.59559,294.00821,294.00821,210.00586,0.46656
35.32000,19.65389,294.34171,294.34171,210.24408,0.46795
35.36000,19.59186,294.67490,294.67490,210.48207,0.46647
35.40000,19.24466,295.00845,295.00845,210.72032,0.45821
35.44000,19.44043,295.34166,295.34167,210.95834,0.46287
35.48000,19.62464,295.67492,295.67493,211.19637,0.46725
35.52000,19.81389,296.00837,296.00836,211.43456,0.47176
35.56000,19.80066,296.34161,296.34158,211.67257,0.47144
35.60000,19.84723,296.67511,296.67511,211.91080,0.47255
35.64000,20.20616,297.00824,297.00824,212.14874,0.48110
35.68000,19.80495,297.34172,297.34171,212.38694,0.47155
35.72000,19.99177,297.67490,297.67490,212.62493,0.47599
35.76000,19.77589,298.00840,298.00839,212.86314,0.47085
35.80000,19.35195,298.34164,298.34164,213.10117,0.46076
35.84000,19.27093,298.67493,298.67493,213.33923,0.45883
35.88000,19.60788,299.00840,299.00839,213.57744,0.46685
35.92000,19.64811,299.34162,299.34164,213.81545,0.46781
35.96000,20.01300,299.67519,299.67520,214.05370,0.47650
36.00000,19.57174,300.00822,300.00821,214.29160,0.46599
36.04000,19.62371,300.34175,300.34174,214.52982,0.46723
36.08000,20.05920,300.67491,300.67490,214.76779,0.47760
36.12000,19.59093,301.00835,301.00836,215.00597,0.46645
36.16000,8.29417,301.34170,301.34171,215.24408,0.19748
36.20000,0.09611,301.67499,301.67499,215.48214,0.00229
36.20400,-0.01788,301.70824,301.70822,215.50589,-0.00043