File: raw_data/mechanical_tests_Instron_data/Silicone_0035-Skin_Longitudinal.is_tens_RawData/Specimen_RawData_1.csv
Dimension : Area,0.42000,cm^2

Time,Extension,Load,Tensile extension,Tensile stress
(sec),(mm),(N),(mm),(MPa)
0.00000,3.50030,0.07711,0.00000,0.00184
0.04000,3.56105,0.59996,0.06075,0.01428
0.08000,3.76291,0.76033,0.26261,0.01810
0.12000,4.09382,2.14167,0.59352,0.05099
0.16000,4.47554,1.84067,0.97524,0.04383
0.20000,4.87090,1.49067,1.37060,0.03549
0.24000,5.27437,1.98409,1.77407,0.04724
0.28000,5.68334,1.99545,2.18303,0.04751
0.32000,6.09613,1.81831,2.59583,0.04329
0.36000,6.49934,2.34134,2.99903,0.05575
0.40000,6.84434,2.06381,3.34403,0.04914
0.44000,7.17155,1.79261,3.67125,0.04268
0.48000,7.50637,1.69668,4.00607,0.04040
0.52000,7.84181,1.74493,4.34151,0.04155
0.56000,8.17505,1.97478,4.67475,0.04702
0.60000,8.50856,1.81403,5.00826,0.04319
0.64000,8.84183,2.01724,5.34152,0.04803
0.68000,9.17536,2.10349,5.67506,0.05008
0.72000,9.50858,2.01482,6.00827,0.04797
0.76000,9.84190,2.07592,6.34160,0.04943
0.80000,10.17535,1.94013,6.67505,0.04619
0.84000,10.50857,1.85650,7.00826,0.04420
0.88000,10.84208,2.07815,7.34177,0.04948
0.92000,11.17521,2.11839,7.67491,0.05044
0.96000,11.50877,2.02525,8.00847,0.04822
1.00000,11.84199,2.14018,8.34168,0.05096
1.04000,12.17539,2.06027,8.67509,0.04905
1.08000,12.50855,1.98260,9.00825,0.04720
1.12000,12.84198,1.91778,9.34167,0.04566
1.16000,13.17538,2.18265,9.67508,0.05197
1.20000,13.50859,1.89729,10.00829,0.04517
1.24000,13.84205,2.47825,10.34175,0.05901
1.28000,14.17518,2.23015,10.67488,0.05310
1.32000,14.50872,2.01967,11.00841,0.04809
1.36000,14.84190,2.33892,11.34160,0.05569
1.40000,15.17536,2.10237,11.67506,0.05006
1.44000,15.50863,2.61012,12.00832,0.06215
1.48000,15.84197,2.32644,12.34167,0.05539
1.52000,16.17535,2.60770,12.67505,0.06209
1.56000,16.50864,2.76100,13.00834,0.06574
1.60000,16.84205,2.58908,13.34174,0.06164
1.64000,17.17523,2.58628,13.67493,0.06158
1.68000,17.50874,2.34973,14.00844,0.05595
1.72000,17.84188,2.41324,14.34157,0.05746
1.76000,18.17544,1.94702,14.67514,0.04636
1.80000,18.50860,2.12640,15.00830,0.05063
1.84000,18.84192,2.32253,15.34162,0.05530
1.88000,19.17535,2.48905,15.67505,0.05926
1.92000,19.50856,2.55778,16.00826,0.06090
1.96000,19.84210,2.38437,16.34180,0.05677
2.00000,20.17523,2.48514,16.67493,0.05917
2.04000,20.50874,2.42125,17.00844,0.05765
2.08000,20.84185,2.54903,17.34155,0.06069
2.12000,21.17536,2.76603,17.67505,0.06586
2.16000,21.50868,2.49650,18.00838,0.05944
2.20000,21.84203,2.33538,18.34173,0.05560
2.24000,22.17532,2.25604,18.67502,0.05372
2.28000,22.50856,2.45478,19.00826,0.05845
2.32000,22.84210,2.10684,19.34179,0.05016
2.36000,23.17523,2.19531,19.67493,0.05227
2.40000,23.50874,2.30856,20.00844,0.05497
2.44000,23.84187,2.59448,20.34157,0.06177
2.48000,24.17533,2.57846,20.67503,0.06139
2.52000,24.50865,2.59597,21.00834,0.06181
2.56000,24.84200,2.64440,21.34170,0.06296
2.60000,25.17532,2.40784,21.67502,0.05733
2.64000,25.50856,2.44807,22.00826,0.05829
2.68000,25.84204,2.56505,22.34174,0.06107
2.72000,26.17528,2.58200,22.67498,0.06148
2.76000,26.50879,2.46707,23.00849,0.05874
2.80000,26.84190,2.57082,23.34160,0.06121
2.84000,27.17535,2.53171,23.67505,0.06028
2.88000,27.50857,2.14763,24.00826,0.05113
2.92000,27.84202,2.35196,24.34172,0.05600
2.96000,28.17537,2.24151,24.67507,0.05337
3.00000,28.50858,2.39536,25.00828,0.05703
3.04000,28.84207,2.21636,25.34177,0.05277
3.08000,29.17520,2.56132,25.67490,0.06098
3.12000,29.50871,2.43671,26.00841,0.05802
3.16000,29.84190,2.58405,26.34159,0.06152
3.20000,30.17535,2.51681,26.67505,0.05992
3.24000,30.50857,2.69692,27.00826,0.06421
3.28000,30.84199,2.33334,27.34169,0.05556
3.32000,31.17540,2.61720,27.67509,0.06231
3.36000,31.50864,2.62614,28.00834,0.06253
3.40000,31.84209,2.36277,28.34179,0.05626
3.44000,32.17520,2.21301,28.67490,0.05269
3.48000,32.50876,2.39611,29.00846,0.05705
3.52000,32.84190,2.42479,29.34160,0.05773
3.56000,33.17538,2.14893,29.67508,0.05117
3.60000,33.50862,2.26554,30.00831,0.05394
3.64000,33.84189,2.07089,30.34159,0.04931
3.68000,34.17539,2.11485,30.67509,0.05035
3.72000,34.50861,2.08039,31.00831,0.04953
3.76000,34.84204,2.46577,31.34173,0.05871
3.80000,35.17522,2.27243,31.67492,0.05411
3.84000,35.50870,2.09212,32.00840,0.04981
3.88000,35.84192,2.39424,32.34162,0.05701
3.92000,36.17543,2.40263,32.67513,0.05721
3.96000,36.50864,2.15042,33.00834,0.05120
4.00000,36.84199,1.93417,33.34169,0.04605
4.04000,37.17537,2.32086,33.67506,0.05526
4.08000,37.50864,2.25026,34.00834,0.05358
4.12000,37.84204,1.92281,34.34173,0.04578
4.16000,38.17520,2.00905,34.67489,0.04783
4.20000,38.50873,2.27038,35.00843,0.05406
4.24000,38.84189,1.81645,35.34159,0.04325
4.28000,39.17535,2.28230,35.67505,0.05434
4.32000,39.50856,2.29068,36.00826,0.05454
4.36000,39.84194,2.02898,36.34164,0.04831
4.40000,40.17536,2.45888,36.67506,0.05854
4.44000,40.50866,2.13869,37.00836,0.05092
4.48000,40.84211,1.96043,37.34182,0.04668
4.52000,41.17525,2.02674,37.67495,0.04826
4.56000,41.50876,2.13962,38.00845,0.05094
4.60000,41.84189,2.46279,38.34159,0.05864
4.64000,42.17537,2.42293,38.67507,0.05769
4.68000,42.50864,2.47546,39.00834,0.05894
4.72000,42.84199,2.41529,39.34169,0.05751
4.76000,43.17536,2.30558,39.67506,0.05489
4.80000,43.50858,2.41324,40.00827,0.05746
4.84000,43.84209,2.34358,40.34178,0.05580
4.88000,44.17522,2.32346,40.67492,0.05532
4.92000,44.50870,2.63732,41.00840,0.06279
4.96000,44.84189,2.42572,41.34159,0.05776
5.00000,45.17537,2.37282,41.67507,0.05650
5.04000,45.50867,2.35103,42.00837,0.05598
5.08000,45.84204,2.45199,42.34174,0.05838
5.12000,46.17531,2.37171,42.67501,0.05647
5.16000,46.50855,2.49688,43.00825,0.05945
5.20000,46.84208,2.89176,43.34179,0.06885
5.24000,47.17527,2.71741,43.67497,0.06470
5.28000,47.50876,2.58237,44.00845,0.06149
5.32000,47.84186,2.61795,44.34156,0.06233
5.36000,48.17534,2.69171,44.67504,0.06409
5.40000,48.50864,2.51364,45.00834,0.05985
5.44000,48.84201,2.73120,45.34171,0.06503
5.48000,49.17536,2.83625,45.67506,0.06753
5.52000,49.50858,3.17711,46.00827,0.07565
5.56000,49.84203,3.02438,46.34173,0.07201
5.60000,50.17524,3.01041,46.67494,0.07168
5.64000,50.50878,3.03052,47.00848,0.07216
5.68000,50.84186,3.10652,47.34155,0.07396
5.72000,51.17540,2.93218,47.67509,0.06981
5.76000,51.50861,2.87425,48.00831,0.06843
5.80000,51.84201,2.51755,48.34171,0.05994
5.84000,52.17539,2.55741,48.67508,0.06089
5.88000,52.50855,2.77888,49.00824,0.06616
5.92000,52.84206,3.13949,49.34175,0.07475
5.96000,53.17522,2.94261,49.67492,0.07006
6.00000,53.50875,2.73008,50.00845,0.06500
6.04000,53.84194,2.69916,50.34164,0.06427
6.08000,54.17539,2.90629,50.67509,0.06920
6.12000,54.50861,3.21642,51.00831,0.07658
6.16000,54.84193,3.13818,51.34163,0.07472
6.20000,55.17536,3.17078,51.67506,0.07549
6.24000,55.50863,2.98321,52.00833,0.07103
6.28000,55.84208,2.73101,52.34178,0.06502
6.32000,56.17516,3.11360,52.67486,0.07413
6.36000,56.50875,3.18959,53.00845,0.07594
6.40000,56.84194,3.15588,53.34164,0.07514
6.44000,57.17539,3.08491,53.67509,0.07345
6.48000,57.50864,2.93721,54.00834,0.06993
6.52000,57.84195,2.95639,54.34165,0.07039
6.56000,58.17536,2.72878,54.67506,0.06497
6.60000,58.50863,2.67811,55.00833,0.06376
6.64000,58.84208,2.94466,55.34178,0.07011
6.68000,59.17519,3.05250,55.67489,0.07268
6.72000,59.50872,3.12980,56.00842,0.07452
6.76000,59.84191,3.35928,56.34161,0.07998
6.80000,60.17542,3.23597,56.67512,0.07705
6.84000,60.50864,3.20077,57.00834,0.07621
6.88000,60.84195,3.01786,57.34165,0.07185
6.92000,61.17533,3.18997,57.67503,0.07595
6.96000,61.50859,3.02289,58.00829,0.07197
7.00000,61.84211,3.30135,58.34180,0.07860
7.04000,62.17524,3.32650,58.67494,0.07920
7.08000,62.50875,3.48035,59.00845,0.08287
7.12000,62.84193,3.31122,59.34163,0.07884
7.16000,63.17536,2.73697,59.67506,0.06517
7.20000,63.50860,3.16706,60.00830,0.07541
7.24000,63.84201,3.57479,60.34171,0.08511
7.28000,64.17535,3.52394,60.67505,0.08390
7.32000,64.50857,3.25721,61.00827,0.07755
7.36000,64.84205,3.16352,61.34175,0.07532
7.40000,65.17521,3.41050,61.67491,0.08120
7.44000,65.50877,3.42205,62.00847,0.08148
7.48000,65.84188,3.53903,62.34158,0.08426
7.52000,66.17536,3.51965,62.67506,0.08380
7.56000,66.50866,3.26987,63.00835,0.07785
7.60000,66.84200,3.16985,63.34171,0.07547
7.64000,67.17537,3.33786,63.67507,0.07947
7.68000,67.50855,3.21101,64.00825,0.07645
7.72000,67.84203,3.22796,64.34172,0.07686
7.76000,68.17529,3.20040,64.67498,0.07620
7.80000,68.50874,2.91727,65.00845,0.06946
7.84000,68.84190,3.12012,65.34161,0.07429
7.88000,69.17536,3.43490,65.67506,0.08178
7.92000,69.50860,3.52282,66.00829,0.08388
7.96000,69.84198,3.16203,66.34167,0.07529
8.00000,70.17535,3.26652,66.67506,0.07777
8.04000,70.50857,3.42149,67.00826,0.08146
8.08000,70.84208,3.62135,67.34177,0.08622
8.12000,71.17526,3.40380,67.67496,0.08104
8.16000,71.50877,3.67109,68.00846,0.08741
8.20000,71.84190,3.39933,68.34161,0.08094
8.24000,72.17536,3.30042,68.67506,0.07858
8.28000,72.50863,3.49954,69.00833,0.08332
8.32000,72.84203,3.68394,69.34173,0.08771
8.36000,73.17532,3.54294,69.67502,0.08436
8.40000,73.50853,3.23430,70.00822,0.07701
8.44000,73.84204,3.44310,70.34174,0.08198
8.48000,74.17524,3.32110,70.67493,0.07907
8.52000,74.50877,3.43993,71.00847,0.08190
8.56000,74.84188,3.58708,71.34158,0.08541
8.60000,75.17538,3.50233,71.67508,0.08339
8.64000,75.50863,3.52450,72.00832,0.08392
8.68000,75.84198,3.79570,72.34167,0.09037
8.72000,76.17532,3.12217,72.67502,0.07434
8.76000,76.50859,3.39989,73.00829,0.08095
8.80000,76.84207,3.52897,73.34177,0.08402
8.84000,77.17523,3.38014,73.67493,0.08048
8.88000,77.50877,3.49861,74.00847,0.08330
8.92000,77.84193,3.39840,74.34163,0.08091
8.96000,78.17536,3.31961,74.67506,0.07904
9.00000,78.50858,3.31756,75.00828,0.07899
9.04000,78.84197,3.62992,75.34167,0.08643
9.08000,79.17537,3.58075,75.67507,0.08526
9.12000,79.50859,3.38182,76.00829,0.08052
9.16000,79.84210,3.41292,76.34179,0.08126
9.20000,80.17518,3.25572,76.67488,0.07752
9.24000,80.50871,3.42000,77.00840,0.08143
9.28000,80.84195,3.31588,77.34165,0.07895
9.32000,81.17541,3.33861,77.67511,0.07949
9.36000,81.50863,3.67705,78.00832,0.08755
9.40000,81.84194,3.25069,78.34164,0.07740
9.44000,82.17532,3.06498,78.67501,0.07298
9.48000,82.50866,3.35649,79.00836,0.07992
9.52000,82.84210,3.36263,79.34180,0.08006
9.56000,83.17520,2.88896,79.67490,0.06878
9.60000,83.50871,3.00910,80.00841,0.07165
9.64000,83.84187,2.88785,80.34157,0.06876
9.68000,84.17543,3.25795,80.67513,0.07757
9.72000,84.50859,3.12552,81.00829,0.07442
9.76000,84.84192,3.07877,81.34161,0.07330
9.80000,85.17537,3.12068,81.67506,0.07430
9.84000,85.50859,3.22666,82.00829,0.07683
9.88000,85.84209,3.01562,82.34179,0.07180
9.92000,86.17523,3.40007,82.67493,0.08095
9.96000,86.50874,3.23709,83.00844,0.07707
10.00000,86.84190,3.04207,83.34160,0.07243
10.04000,87.17540,3.52934,83.67509,0.08403
10.08000,87.50867,3.31104,84.00837,0.07883
10.12000,87.84202,3.61614,84.34171,0.08610
10.16000,88.17534,2.70642,84.67504,0.06444
10.20000,88.50853,2.88766,85.00823,0.06875
10.24000,88.84207,3.15588,85.34176,0.07514
10.28000,89.17523,3.57088,85.67492,0.08502
10.32000,89.50876,3.66718,86.00846,0.08731
10.36000,89.84190,3.48259,86.34159,0.08292
10.40000,90.17533,3.30638,86.67502,0.07872
10.44000,90.50865,3.33712,87.00834,0.07946
10.48000,90.84199,3.52617,87.34169,0.08396
10.52000,91.17536,3.49563,87.67506,0.08323
10.56000,91.50859,3.43341,88.00829,0.08175
10.60000,91.84204,3.47234,88.34174,0.08267
10.64000,92.17528,3.33209,88.67497,0.07934
10.68000,92.50879,3.54648,89.00848,0.08444
10.72000,92.84189,3.42783,89.34159,0.08161
10.76000,93.17533,3.20114,89.67503,0.07622
10.80000,93.50859,3.37660,90.00829,0.08040
10.84000,93.84202,3.45986,90.34172,0.08238
10.88000,94.17540,3.62899,90.67509,0.08640
10.92000,94.50859,3.71486,91.00828,0.08845
10.96000,94.84204,3.60664,91.34174,0.08587
11.00000,95.17520,3.65339,91.67490,0.08699
11.04000,95.50876,3.91155,92.00845,0.09313
11.08000,95.84192,3.72920,92.34161,0.08879
11.12000,96.17540,4.20082,92.67509,0.10002
11.16000,96.50864,4.41652,93.00835,0.10516
11.20000,96.84205,4.39901,93.34174,0.10474
11.24000,97.17534,3.96129,93.67504,0.09432
11.28000,97.50861,4.12557,94.00830,0.09823
11.32000,97.84209,4.19281,94.34179,0.09983
11.36000,98.17520,4.15836,94.67489,0.09901
11.40000,98.50876,4.11458,95.00846,0.09797
11.44000,98.84189,4.24869,95.34159,0.10116
11.48000,99.17535,4.12427,95.67505,0.09820
11.52000,99.50862,4.26695,96.00831,0.10159
11.56000,99.84197,4.25056,96.34167,0.10120
11.60000,100.17539,4.46271,96.67509,0.10626
11.64000,100.50861,4.77303,97.00831,0.11364
11.68000,100.84206,4.65829,97.34175,0.11091
11.72000,101.17525,4.58770,97.67494,0.10923
11.76000,101.50873,4.54299,98.00843,0.10817
11.80000,101.84192,4.63892,98.34162,0.11045
11.84000,102.17542,4.89373,98.67513,0.11652
11.88000,102.50862,4.75980,99.00832,0.11333
11.92000,102.84199,4.79650,99.34168,0.11420
11.96000,103.17536,4.50425,99.67506,0.10724
12.00000,103.50857,4.18164,100.00827,0.09956
12.04000,103.84206,4.62458,100.34176,0.11011
12.08000,104.17522,4.88907,100.67492,0.11641
12.12000,104.50870,4.83058,101.00839,0.11501
12.16000,104.84191,4.93824,101.34161,0.11758
12.20000,105.17540,4.59552,101.67509,0.10942
12.24000,105.50862,4.81624,102.00832,0.11467
12.28000,105.84196,5.01759,102.34166,0.11947
12.32000,106.17534,4.81773,102.67503,0.11471
12.36000,106.50868,4.92930,103.00838,0.11736
12.40000,106.84211,4.76595,103.34181,0.11348
12.44000,107.17519,4.93340,103.67490,0.11746
12.48000,107.50873,5.13513,104.00842,0.12226
12.52000,107.84189,4.98500,104.34159,0.11869
12.56000,108.17542,4.58397,104.67512,0.10914
12.60000,108.50864,4.57708,105.00834,0.10898
12.64000,108.84196,4.28930,105.34165,0.10213
12.68000,109.17533,4.64804,105.67503,0.11067
12.72000,109.50857,4.98965,106.00826,0.11880
12.76000,109.84207,4.92074,106.34176,0.11716
12.80000,110.17519,4.77992,106.67489,0.11381
12.84000,110.50875,4.62234,107.00845,0.11006
12.88000,110.84191,4.62160,107.34161,0.11004
12.92000,111.17542,4.65587,107.67512,0.11085
12.96000,111.50871,4.80562,108.00842,0.11442
13.00000,111.84198,4.56236,108.34167,0.10863
13.04000,112.17533,4.74602,108.67503,0.11300
13.08000,112.50857,4.62048,109.00827,0.11001
13.12000,112.84208,4.53610,109.34178,0.10800
13.16000,113.17527,4.70020,109.67496,0.11191
13.20000,113.50876,4.51580,110.00846,0.10752
13.24000,113.84192,4.85368,110.34162,0.11556
13.28000,114.17529,4.69927,110.67500,0.11189
13.32000,114.50862,4.81587,111.00831,0.11466
13.36000,114.84201,4.80413,111.34171,0.11438
13.40000,115.17539,4.40143,111.67510,0.10480
13.44000,115.50860,4.70541,112.00831,0.11203
13.48000,115.84203,4.61787,112.34172,0.10995
13.52000,116.17524,4.75682,112.67493,0.11326
13.56000,116.50883,4.52138,113.00852,0.10765
13.60000,116.84191,4.34890,113.34161,0.10355
13.64000,117.17540,4.42546,113.67510,0.10537
13.68000,117.50863,4.39100,114.00833,0.10455
13.72000,117.84204,4.56739,114.34175,0.10875
13.76000,118.17541,4.55938,114.67512,0.10856
13.80000,118.50855,4.37796,115.00824,0.10424
13.84000,118.84203,4.86616,115.34174,0.11586
13.88000,119.17524,4.60297,115.67495,0.10959
13.92000,119.50874,4.52735,116.00844,0.10779
13.96000,119.84194,4.62867,116.34164,0.11021
14.00000,120.17539,4.67058,116.67508,0.11120
14.04000,120.50858,4.55864,117.00829,0.10854
14.08000,120.84198,4.73633,117.34167,0.11277
14.12000,121.17540,4.62476,117.67511,0.11011
14.16000,121.50863,4.43477,118.00832,0.10559
14.20000,121.84210,4.64953,118.34180,0.11070
14.24000,122.17521,4.43310,118.67492,0.10555
14.28000,122.50875,4.40981,119.00845,0.10500
14.32000,122.84191,4.60632,119.34161,0.10967
14.36000,123.17538,4.13600,119.67508,0.09848
14.40000,123.50866,4.20697,120.00835,0.10017
14.44000,123.84195,4.33475,120.34164,0.10321
14.48000,124.17536,4.28278,120.67506,0.10197
14.52000,124.50862,4.43812,121.00832,0.10567
14.56000,124.84206,4.59030,121.34175,0.10929
14.60000,125.17524,4.41875,121.67493,0.10521
14.64000,125.50874,4.40218,122.00844,0.10481
14.68000,125.84194,4.18574,122.34164,0.09966
14.72000,126.17541,4.35505,122.67511,0.10369
14.76000,126.50865,4.29377,123.00835,0.10223
14.80000,126.84196,4.32227,123.34166,0.10291
14.84000,127.17533,4.74192,123.67503,0.11290
14.88000,127.50864,4.64097,124.00834,0.11050
14.92000,127.84210,4.39957,124.34180,0.10475
14.96000,128.17526,4.35580,124.67496,0.10371
15.00000,128.50872,4.16301,125.00842,0.09912
15.04000,128.84190,4.29768,125.34160,0.10233
15.08000,129.17538,4.31966,125.67507,0.10285
15.12000,129.50863,4.38411,126.00834,0.10438
15.16000,129.84198,4.45247,126.34168,0.10601
15.20000,130.17533,4.59403,126.67503,0.10938
15.24000,130.50860,4.60483,127.00830,0.10964
15.28000,130.84212,4.35878,127.34181,0.10378
15.32000,131.17518,4.56683,127.67487,0.10873
15.36000,131.50874,4.34853,128.00844,0.10354
15.40000,131.84190,4.40776,128.34160,0.10495
15.44000,132.17540,4.59421,128.67509,0.10939
15.48000,132.50865,4.17065,129.00835,0.09930
15.52000,132.84198,4.14737,129.34167,0.09875
15.56000,133.17535,4.22895,129.67505,0.10069
15.60000,133.50859,4.20175,130.00830,0.10004
15.64000,133.84210,4.24981,130.34181,0.10119
15.68000,134.17526,4.58527,130.67497,0.10917
15.72000,134.50873,4.18033,131.00842,0.09953
15.76000,134.84188,4.50183,131.34158,0.10719
15.80000,135.17538,4.44222,131.67508,0.10577
15.84000,135.50861,4.63277,132.00830,0.11030
15.88000,135.84200,4.58155,132.34169,0.10908
15.92000,136.17537,4.14625,132.67506,0.09872
15.96000,136.50862,4.42490,133.00832,0.10535
16.00000,136.84212,4.51878,133.34183,0.10759
16.04000,137.17525,4.45768,133.67496,0.10614
16.08000,137.50874,4.21666,134.00845,0.10040
16.12000,137.84190,4.28390,134.34161,0.10200
16.16000,138.17536,4.47351,134.67506,0.10651
16.20000,138.50863,4.14494,135.00832,0.09869
16.24000,138.84205,4.23286,135.34174,0.10078
16.28000,139.17538,4.52902,135.67508,0.10783
16.32000,139.50856,4.40013,136.00826,0.10476
16.36000,139.84201,4.29787,136.34171,0.10233
16.40000,140.17523,4.15090,136.67493,0.09883
16.44000,140.50882,4.38616,137.00853,0.10443
16.48000,140.84189,4.75124,137.34160,0.11312
16.52000,141.17538,4.32581,137.67508,0.10300
16.56000,141.50864,4.67058,138.00833,0.11120
16.60000,141.84203,4.63743,138.34174,0.11041
16.64000,142.17542,4.53945,138.67511,0.10808
16.68000,142.50862,4.37386,139.00833,0.10414
16.72000,142.84208,4.36809,139.34178,0.10400
16.76000,143.17524,4.61638,139.67494,0.10991
16.80000,143.50879,4.70150,140.00850,0.11194
16.84000,143.84190,4.46793,140.34160,0.10638
16.88000,144.17532,4.36790,140.67502,0.10400
16.92000,144.50859,4.41317,141.00829,0.10508
16.96000,144.84198,4.52846,141.34169,0.10782
17.00000,145.17541,4.55566,141.67511,0.10847
17.04000,145.50861,4.57466,142.00830,0.10892
17.08000,145.84207,4.28744,142.34178,0.10208
17.12000,146.17519,4.42676,142.67490,0.10540
17.16000,146.50876,4.74602,143.00847,0.11300
17.20000,146.84198,4.62588,143.34167,0.11014
17.24000,147.17541,4.42173,143.67509,0.10528
17.28000,147.50864,4.49345,144.00833,0.10699
17.32000,147.84200,4.56590,144.34171,0.10871
17.36000,148.17532,4.76465,144.67500,0.11344
17.40000,148.50862,4.67040,145.00833,0.11120
17.44000,148.84205,4.47333,145.34175,0.10651
17.48000,149.17520,4.54932,145.67490,0.10832
17.52000,149.50867,4.72721,146.00836,0.11255
17.56000,149.84187,4.52083,146.34157,0.10764
17.60000,150.17542,4.48264,146.67511,0.10673
17.64000,150.50868,4.61265,147.00836,0.10983
17.68000,150.84198,4.30774,147.34167,0.10257
17.72000,151.17537,4.27198,147.67508,0.10171
17.76000,151.50864,4.95873,148.00835,0.11807
17.80000,151.84212,4.62793,148.34183,0.11019
17.84000,152.17528,4.54616,148.67497,0.10824
17.88000,152.50872,4.71510,149.00841,0.11226
17.92000,152.84189,4.46439,149.34158,0.10629
17.96000,153.17543,4.63575,149.67513,0.11038
18.00000,153.50864,4.92577,150.00833,0.11728
18.04000,153.84200,4.35524,150.34169,0.10370
18.08000,154.17532,4.69219,150.67500,0.11172
18.12000,154.50853,4.63128,151.00824,0.11027
18.16000,154.84209,4.63072,151.34178,0.11026
18.20000,155.17525,4.64451,151.67494,0.11058
18.24000,155.50878,4.52790,152.00847,0.10781
18.28000,155.84192,4.65587,152.34161,0.11085
18.32000,156.17540,4.88460,152.67509,0.11630
18.36000,156.50867,4.81792,153.00838,0.11471
18.40000,156.84199,4.84288,153.34169,0.11531
18.44000,157.17537,4.72665,153.67508,0.11254
18.48000,157.50860,4.67971,154.00829,0.11142
18.52000,157.84206,4.63389,154.34175,0.11033
18.56000,158.17526,4.52362,154.67496,0.10771
18.60000,158.50876,4.25447,155.00845,0.10130
18.64000,158.84189,4.87380,155.34158,0.11604
18.68000,159.17538,4.67729,155.67506,0.11136
18.72000,159.50860,5.20051,156.00830,0.12382
18.76000,159.84200,4.65475,156.34169,0.11083
18.80000,160.17539,4.86504,156.67509,0.11583
18.84000,160.50860,4.91589,157.00830,0.11705
18.88000,160.84204,4.65624,157.34174,0.11086
18.92000,161.17524,4.75273,157.67493,0.11316
18.96000,161.50880,4.51319,158.00851,0.10746
19.00000,161.84194,4.97848,158.34164,0.11854
19.04000,162.17540,4.98835,158.67509,0.11877
19.08000,162.50858,4.79687,159.00827,0.11421
19.12000,162.84202,4.68846,159.34171,0.11163
19.16000,163.17537,4.85666,159.67506,0.11563
19.20000,163.50860,4.58881,160.00830,0.10926
19.24000,163.84208,4.88311,160.34180,0.11626
19.28000,164.17522,5.08204,160.67493,0.12100
19.32000,164.50878,4.75850,161.00847,0.11330
19.36000,164.84192,4.62327,161.34161,0.11008
19.40000,165.17534,5.05261,161.67503,0.12030
19.44000,165.50860,4.92670,162.00830,0.11730
19.48000,165.84202,4.60669,162.34172,0.10968
19.52000,166.17539,4.94588,162.67508,0.11776
19.56000,166.50860,5.40446,163.00832,0.12868
19.60000,166.84205,5.10737,163.34175,0.12160
19.64000,167.17524,4.85424,163.67494,0.11558
19.68000,167.50880,4.92036,164.00850,0.11715
19.72000,167.84194,4.85480,164.34163,0.11559
19.76000,168.17540,5.09284,164.67509,0.12126
19.80000,168.50861,5.37075,165.00830,0.12788
19.84000,168.84195,5.01871,165.34166,0.11949
19.88000,169.17538,4.81606,165.67509,0.11467
19.92000,169.50856,4.82723,166.00826,0.11493
19.96000,169.84206,5.18523,166.34177,0.12346
20.00000,170.17524,5.21857,166.67494,0.12425
20.04000,170.50876,5.25452,167.00845,0.12511
20.08000,170.84197,5.40391,167.34166,0.12866
20.12000,171.17540,5.04367,167.67509,0.12009
20.16000,171.50863,5.22137,168.00832,0.12432
20.20000,171.84202,5.13550,168.34172,0.12227
20.24000,172.17535,5.04274,168.67506,0.12007
20.28000,172.50868,5.57303,169.00838,0.13269
20.32000,172.84214,5.39701,169.34184,0.12850
20.36000,173.17521,5.57303,169.67491,0.13269
20.40000,173.50867,5.40707,170.00836,0.12874
20.44000,173.84186,4.91664,170.34155,0.11706
20.48000,174.17542,5.20777,170.67511,0.12399
20.52000,174.50866,5.62742,171.00835,0.13399
20.56000,174.84194,5.25713,171.34164,0.12517
20.60000,175.17531,5.13922,171.67502,0.12236
20.64000,175.50862,5.13382,172.00833,0.12223
20.68000,175.84213,5.07794,172.34183,0.12090
20.72000,176.17527,5.11426,172.67496,0.12177
20.76000,176.50878,5.29047,173.00848,0.12596
20.80000,176.84190,5.47003,173.34160,0.13024
20.84000,177.17544,5.37168,173.67514,0.12790
20.88000,177.50867,5.31469,174.00836,0.12654
20.92000,177.84198,5.35101,174.34167,0.12740
20.96000,178.17532,5.15021,174.67503,0.12262
21.00000,178.50858,5.45718,175.00829,0.12993
21.04000,178.84210,5.47618,175.34180,0.13039
21.08000,179.17524,5.46966,175.67493,0.13023
21.12000,179.50872,5.55236,176.00841,0.13220
21.16000,179.84183,5.50169,176.34152,0.13099
21.20000,180.17532,5.46537,176.67502,0.13013
21.24000,180.50868,5.47748,177.00839,0.13042
21.28000,180.84207,5.40297,177.34177,0.12864
21.32000,181.17541,5.55180,177.67511,0.13219
21.36000,181.50865,5.27762,178.00835,0.12566
21.40000,181.84209,5.54770,178.34180,0.13209
21.44000,182.17525,5.63953,178.67494,0.13427
21.48000,182.50881,5.60693,179.00850,0.13350
21.52000,182.84190,5.82393,179.34161,0.13867
21.56000,183.17536,5.53243,179.67505,0.13172
21.60000,183.50860,5.59147,180.00829,0.13313
21.64000,183.84198,5.82505,180.34167,0.13869
21.68000,184.17535,5.65238,180.67505,0.13458
21.72000,184.50860,5.62947,181.00830,0.13404
21.76000,184.84202,5.89173,181.34172,0.14028
21.80000,185.17523,5.66896,181.67494,0.13498
21.84000,185.50876,5.63357,182.00845,0.13413
21.88000,185.84196,5.70938,182.34166,0.13594
21.92000,186.17542,5.64978,182.67511,0.13452
21.96000,186.50858,5.85373,183.00827,0.13937
22.00000,186.84207,6.00982,183.34175,0.14309
22.04000,187.17539,5.94780,183.67509,0.14161
22.08000,187.50862,5.75967,184.00832,0.13714
22.12000,187.84209,5.77196,184.34178,0.13743
22.16000,188.17518,5.59371,184.67487,0.13318
22.20000,188.50874,5.91986,185.00845,0.14095
22.24000,188.84190,6.18529,185.34160,0.14727
22.28000,189.17533,6.14114,185.67503,0.14622
22.32000,189.50860,6.16759,186.00829,0.14685
22.36000,189.84195,5.94929,186.34164,0.14165
22.40000,190.17544,6.18268,186.67514,0.14721
22.44000,190.50864,6.22068,187.00833,0.14811
22.48000,190.84207,5.75837,187.34177,0.13710
22.52000,191.17526,6.21490,187.67496,0.14797
22.56000,191.50880,5.98542,188.00848,0.14251
22.60000,191.84192,6.05602,188.34161,0.14419
22.64000,192.17542,6.37509,188.67511,0.15179
22.68000,192.50864,6.42817,189.00835,0.15305
22.72000,192.84197,6.10594,189.34166,0.14538
22.76000,193.17537,6.18510,189.67508,0.14726
22.80000,193.50859,6.04689,190.00829,0.14397
22.84000,193.84208,6.46692,190.34177,0.15397
22.88000,194.17524,6.32759,190.67494,0.15066
22.92000,194.50871,6.20540,191.00841,0.14775
22.96000,194.84187,6.55949,191.34158,0.15618
23.00000,195.17540,6.31437,191.67511,0.15034
23.04000,195.50865,6.20093,192.00836,0.14764
23.08000,195.84202,6.54124,192.34172,0.15574
23.12000,196.17537,6.55148,192.67506,0.15599
23.16000,196.50864,6.39427,193.00835,0.15224
23.20000,196.84210,6.69062,193.34180,0.15930
23.24000,197.17519,6.50529,193.67490,0.15489
23.28000,197.50874,6.38980,194.00845,0.15214
23.32000,197.84191,6.28587,194.34160,0.14966
23.36000,198.17538,6.20913,194.67508,0.14784
23.40000,198.50867,6.14412,195.00838,0.14629
23.44000,198.84197,6.35609,195.34166,0.15134
23.48000,199.17533,6.34026,195.67502,0.15096
23.52000,199.50859,6.44643,196.00829,0.15349
23.56000,199.84212,6.67423,196.34181,0.15891
23.60000,200.17525,6.45295,196.67494,0.15364
23.64000,200.50874,6.87987,197.00844,0.16381
23.68000,200.84187,6.87037,197.34157,0.16358
23.72000,201.17544,6.51181,197.67513,0.15504
23.76000,201.50870,6.79791,198.00841,0.16185
23.80000,201.84202,6.74501,198.34172,0.16060
23.84000,202.17537,6.90762,198.67508,0.16447
23.88000,202.50856,6.72340,199.00827,0.16008
23.92000,202.84210,6.55130,199.34180,0.15598
23.96000,203.17526,7.03428,199.67496,0.16748
24.00000,203.50868,6.79530,200.00839,0.16179
24.04000,203.84192,6.64555,200.34163,0.15823
24.08000,204.17535,6.90706,200.67506,0.16445
24.12000,204.50864,7.23600,201.00833,0.17229
24.16000,204.84202,6.82455,201.34174,0.16249
24.20000,205.17535,7.06315,201.67505,0.16817
24.24000,205.50858,6.89831,202.00829,0.16425
24.28000,205.84209,7.02124,202.34178,0.16717
24.32000,206.17525,7.06334,202.67494,0.16817
24.36000,206.50882,7.11158,203.00851,0.16932
24.40000,206.84195,7.39079,203.34166,0.17597
24.44000,207.17538,6.90892,203.67509,0.16450
24.48000,207.50858,7.02906,204.00827,0.16736
24.52000,207.84199,7.48578,204.34169,0.17823
24.56000,208.17540,6.90203,204.67509,0.16433
24.60000,208.50861,6.73570,205.00832,0.16037
24.64000,208.84201,7.18739,205.34171,0.17113
24.68000,209.17522,7.18739,205.67493,0.17113
24.72000,209.50878,6.98846,206.00848,0.16639
24.76000,209.84192,7.19335,206.34163,0.17127
24.80000,210.17538,7.13263,206.67506,0.16982
24.84000,210.50863,7.24476,207.00832,0.17249
24.88000,210.84202,7.20285,207.34174,0.17150
24.92000,211.17542,7.41929,207.67511,0.17665
24.96000,211.50864,7.28425,208.00835,0.17343
25.00000,211.84206,7.27773,208.34177,0.17328
25.04000,212.17522,7.48616,208.67491,0.17824
25.08000,212.50876,7.39228,209.00845,0.17601
25.12000,212.84195,7.68900,209.34164,0.18307
25.16000,213.17538,7.53328,209.67508,0.17936
25.20000,213.50862,7.40569,210.00832,0.17633
25.24000,213.84194,7.50665,210.34163,0.17873
25.28000,214.17533,7.50348,210.67503,0.17865
25.32000,214.50860,7.67857,211.00830,0.18282
25.36000,214.84210,7.26860,211.34178,0.17306
25.40000,215.17526,7.51093,211.67494,0.17883
25.44000,215.50878,7.80281,212.00847,0.18578
25.48000,215.84194,7.73594,212.34164,0.18419
25.52000,216.17540,7.75624,212.67509,0.18467
25.56000,216.50867,8.12188,213.00836,0.19338
25.60000,216.84202,7.71526,213.34172,0.18370
25.64000,217.17534,7.20248,213.67503,0.17149
25.68000,217.50855,7.44574,214.00826,0.17728
25.72000,217.84206,7.61040,214.34175,0.18120
25.76000,218.17528,7.80467,214.67497,0.18583
25.80000,218.50876,7.51112,215.00845,0.17884
25.84000,218.84190,7.67801,215.34158,0.18281
25.88000,219.17539,7.79703,215.67509,0.18564
25.92000,219.50858,7.74544,216.00829,0.18442
25.96000,219.84198,7.51559,216.34167,0.17894
26.00000,220.17534,8.12877,216.67503,0.19354
26.04000,220.50858,8.32342,217.00829,0.19818
26.08000,220.84213,7.97790,217.34184,0.18995
26.12000,221.17527,7.76481,217.67496,0.18488
26.16000,221.50879,8.43033,218.00850,0.20072
26.20000,221.84190,8.14367,218.34160,0.19390
26.24000,222.17537,7.86986,218.67506,0.18738
26.28000,222.50864,8.14516,219.00835,0.19393
26.32000,222.84198,8.24127,219.34169,0.19622
26.36000,223.17535,8.01664,219.67506,0.19087
26.40000,223.50862,7.84695,220.00830,0.18683
26.44000,223.84211,7.92854,220.34183,0.18877
26.48000,224.17525,8.27406,220.67496,0.19700
26.52000,224.50870,8.37836,221.00841,0.19948
26.56000,224.84186,8.17254,221.34154,0.19458
26.60000,225.17543,8.21315,221.67514,0.19555
26.64000,225.50870,8.28579,222.00841,0.19728
26.68000,225.84199,8.64957,222.34169,0.20594
26.72000,226.17536,8.49161,222.67506,0.20218
26.76000,226.50860,8.58810,223.00830,0.20448
26.80000,226.84212,8.57189,223.34180,0.20409
26.84000,227.17528,8.76822,223.67499,0.20877
26.88000,227.50875,8.46349,224.00845,0.20151
26.92000,227.84191,8.61604,224.34161,0.20514
26.96000,228.17536,8.66503,224.67503,0.20631
27.00000,228.50860,8.59275,225.00830,0.20459
27.04000,228.84197,8.44765,225.34167,0.20113
27.08000,229.17536,8.72277,225.67506,0.20768
27.12000,229.50860,8.58456,226.00829,0.20439
27.16000,229.84207,8.72854,226.34178,0.20782
27.20000,230.17526,8.71122,226.67497,0.20741
27.24000,230.50879,8.89041,227.00850,0.21168
27.28000,230.84192,9.14093,227.34163,0.21764
27.32000,231.17539,8.94312,227.67509,0.21293
27.36000,231.50866,9.06158,228.00836,0.21575
27.40000,231.84203,8.96510,228.34174,0.21345
27.44000,232.17539,9.02545,228.67509,0.21489
27.48000,232.50863,8.89860,229.00835,0.21187
27.52000,232.84203,8.72444,229.34174,0.20772
27.56000,233.17519,8.92412,229.67490,0.21248
27.60000,233.50882,8.94591,230.00853,0.21300
27.64000,233.84193,9.06009,230.34163,0.21572
27.68000,234.17540,8.93958,230.67508,0.21285
27.72000,234.50861,9.03066,231.00832,0.21502
27.76000,234.84195,9.32105,231.34166,0.22193
27.80000,235.17545,9.54885,231.67514,0.22735
27.84000,235.50864,9.26089,232.00832,0.22050
27.88000,235.84209,9.18843,232.34180,0.21877
27.92000,236.17525,9.37954,232.67496,0.22332
27.96000,236.50875,9.17651,233.00842,0.21849
28.00000,236.84198,9.17781,233.34169,0.21852
28.04000,237.17538,9.41791,233.67508,0.22424
28.08000,237.50857,9.24021,234.00827,0.22001
28.12000,237.84199,9.54624,234.34166,0.22729
28.16000,238.17535,9.15434,234.67503,0.21796
28.20000,238.50862,9.19346,235.00833,0.21889
28.24000,238.84212,9.26536,235.34183,0.22060
28.28000,239.17520,9.67830,235.67491,0.23044
28.32000,239.50873,9.52221,236.00844,0.22672
28.36000,239.84191,9.60529,236.34161,0.22870
28.40000,240.17541,9.63733,236.67511,0.22946
28.44000,240.50868,9.85153,237.00838,0.23456
28.48000,240.84202,9.83384,237.34172,0.23414
28.52000,241.17536,9.90238,237.67506,0.23577
28.56000,241.50863,9.64925,238.00830,0.22974
28.60000,241.84210,9.78261,238.34181,0.23292
28.64000,242.17526,10.24567,238.67496,0.24394
28.68000,242.50876,10.15384,239.00847,0.24176
28.72000,242.84184,9.99793,239.34155,0.23805
28.76000,243.17542,9.89549,239.67513,0.23561
28.80000,243.50866,9.86699,240.00833,0.23493
28.84000,243.84200,10.21717,240.34171,0.24327
28.88000,244.17539,10.34644,240.67508,0.24634
28.92000,244.50855,10.23449,241.00826,0.24368
28.96000,244.84210,10.13428,241.34181,0.24129
29.00000,245.17526,10.27938,241.67494,0.24475
29.04000,245.50876,10.41740,242.00847,0.24803
29.08000,245.84187,10.35929,242.34158,0.24665
29.12000,246.17540,10.28739,242.67511,0.24494
29.16000,246.50871,10.37866,243.00842,0.24711
29.20000,246.84206,10.36953,243.34177,0.24689
29.24000,247.17537,10.32874,243.67508,0.24592
29.28000,247.50856,10.29521,244.00827,0.24512
29.32000,247.84206,10.50122,244.34177,0.25003
29.36000,248.17527,10.56921,244.67497,0.25165
29.40000,248.50874,10.63030,245.00845,0.25310
29.44000,248.84190,10.47980,245.34158,0.24952
29.48000,249.17538,10.55021,245.67508,0.25120
29.52000,249.50867,10.66662,246.00838,0.25397
29.56000,249.84196,10.71077,246.34166,0.25502
29.60000,250.17533,11.00060,246.67503,0.26192
29.64000,250.50864,10.87692,247.00835,0.25897
29.68000,250.84212,10.48464,247.34180,0.24963
29.72000,251.17530,10.70090,247.67499,0.25478
29.76000,251.50875,10.87971,248.00845,0.25904
29.80000,251.84191,11.20232,248.34161,0.26672
29.84000,252.17541,10.92665,248.67509,0.26016
29.88000,252.50862,11.17624,249.00833,0.26610
29.92000,252.84196,11.23939,249.34164,0.26760
29.96000,253.17539,11.09075,249.67509,0.26407
30.00000,253.50857,10.80725,250.00827,0.25732
30.04000,253.84210,11.10267,250.34180,0.26435
30.08000,254.17520,11.33811,250.67488,0.26995
30.12000,254.50878,11.32134,251.00848,0.26956
30.16000,254.84197,11.68866,251.34167,0.27830
30.20000,255.17539,11.42547,251.67509,0.27203
30.24000,255.50865,11.47967,252.00836,0.27333
30.28000,255.84202,11.42137,252.34174,0.27194
30.32000,256.17539,11.49438,252.67509,0.27368
30.36000,256.50863,11.33140,253.00833,0.26980
30.40000,256.84208,11.55678,253.34178,0.27516
30.44000,257.17518,11.40498,253.67490,0.27155
30.48000,257.50876,11.51394,254.00847,0.27414
30.52000,257.84192,11.85387,254.34163,0.28224
30.56000,258.17540,11.74919,254.67508,0.27974
30.60000,258.50863,11.65345,255.00835,0.27746
30.64000,258.84198,11.74454,255.34169,0.27963
30.68000,259.17542,11.48563,255.67513,0.27347
30.72000,259.50861,11.86449,256.00830,0.28249
30.76000,259.84206,11.78570,256.34174,0.28061
30.80000,260.17527,11.67338,256.67499,0.27794
30.84000,260.50877,12.19548,257.00848,0.29037
30.88000,260.84198,11.94850,257.34167,0.28449
30.92000,261.17540,11.85462,257.67511,0.28225
30.96000,261.50861,12.10626,258.00833,0.28824
31.00000,261.84198,11.86170,258.34167,0.28242
31.04000,262.17535,12.12284,258.67505,0.28864
31.08000,262.50862,12.02766,259.00833,0.28637
31.12000,262.84206,11.91907,259.34177,0.28379
31.16000,263.17522,11.95911,259.67493,0.28474
31.20000,263.50875,12.24149,260.00845,0.29146
31.24000,263.84193,12.31134,260.34164,0.29313
31.28000,264.17543,12.28284,260.67511,0.29245
31.32000,264.50862,12.48345,261.00830,0.29722
31.36000,264.84196,12.59390,261.34167,0.29985
31.40000,265.17536,12.59260,261.67505,0.29982
31.44000,265.50862,12.43949,262.00833,0.29618
31.48000,265.84215,12.65798,262.34186,0.30138
31.52000,266.17526,12.86436,262.67496,0.30629
31.56000,266.50881,12.68368,263.00851,0.30199
31.60000,266.84186,13.01095,263.34158,0.30978
31.64000,267.17541,13.12196,263.67511,0.31243
31.68000,267.50868,12.92974,264.00839,0.30785
31.72000,267.84197,12.79917,264.34167,0.30474
31.76000,268.17536,12.73137,264.67508,0.30313
31.80000,268.50858,12.67977,265.00827,0.30190
31.84000,268.84210,12.93160,265.34180,0.30790
31.88000,269.17531,13.28476,265.67499,0.31630
31.92000,269.50876,13.41552,266.00845,0.31942
31.96000,269.84189,13.38702,266.34161,0.31874
32.00000,270.17537,13.58241,266.67508,0.32339
32.04000,270.50868,13.29370,267.00839,0.31652
32.08000,270.84205,13.15363,267.34177,0.31318
32.12000,271.17532,13.21528,267.67502,0.31465
32.16000,271.50856,13.30953,268.00827,0.31689
32.20000,271.84208,13.21808,268.34177,0.31472
32.24000,272.17527,13.27433,268.67496,0.31606
32.28000,272.50879,13.31605,269.00848,0.31705
32.32000,272.84187,13.66436,269.34158,0.32534
32.36000,273.17535,13.34399,269.67505,0.31771
32.40000,273.50864,13.36373,270.00833,0.31818
32.44000,273.84206,13.69230,270.34174,0.32601
32.48000,274.17538,13.63624,270.67508,0.32467
32.52000,274.50864,13.76346,271.00833,0.32770
32.56000,274.84204,13.60197,271.34174,0.32386
32.60000,275.17525,13.60457,271.67496,0.32392
32.64000,275.50877,13.17114,272.00848,0.31360
32.68000,275.84191,13.56471,272.34158,0.32297
32.72000,276.17538,13.42669,272.67508,0.31968
32.76000,276.50862,13.77966,273.00833,0.32809
32.80000,276.84199,13.69361,273.34171,0.32604
32.84000,277.17538,13.78600,273.67505,0.32824
32.88000,277.50859,13.23838,274.00830,0.31520
32.92000,277.84212,13.46432,274.34180,0.32058
32.96000,278.17525,13.34138,274.67493,0.31765
33.00000,278.50880,13.15568,275.00848,0.31323
33.04000,278.84196,12.96811,275.34167,0.30876
33.08000,279.17541,13.02734,275.67511,0.31017
33.12000,279.50860,13.30599,276.00830,0.31681
33.16000,279.84194,13.01002,276.34164,0.30976
33.20000,280.17544,13.59601,276.67514,0.32371
33.24000,280.50865,13.46488,277.00833,0.32059
33.28000,280.84210,13.00927,277.34180,0.30974
33.32000,281.17521,12.93961,277.67493,0.30809
33.36000,281.50876,13.23093,278.00845,0.31502
33.40000,281.84194,12.84033,278.34164,0.30572
33.44000,282.17539,12.81369,278.67511,0.30509
33.48000,282.50863,12.96811,279.00830,0.30876
33.52000,282.84200,13.13277,279.34167,0.31268
33.56000,283.17539,12.76359,279.67511,0.30389
33.60000,283.50863,12.77253,280.00833,0.30411
33.64000,283.84208,12.38417,280.34177,0.29486
33.68000,284.17524,12.84964,280.67496,0.30594
33.72000,284.50874,12.56820,281.00845,0.29924
33.76000,284.84190,12.70846,281.34158,0.30258
33.80000,285.17542,12.90515,281.67514,0.30727
33.84000,285.50861,12.94594,282.00833,0.30824
33.88000,285.84201,13.03963,282.34171,0.31047
33.92000,286.17537,12.99009,282.67505,0.30929
33.96000,286.50864,12.39758,283.00833,0.29518
34.00000,286.84214,12.83437,283.34186,0.30558
34.04000,287.17525,12.59986,283.67496,0.30000
34.08000,287.50874,12.72019,284.00842,0.30286
34.12000,287.84193,12.89863,284.34161,0.30711
34.16000,288.17535,12.56671,284.67502,0.29921
34.20000,288.50867,12.56894,285.00836,0.29926
34.24000,288.84201,12.71516,285.34171,0.30274
34.28000,289.17535,12.78892,285.67505,0.30450
34.32000,289.50862,12.91074,286.00833,0.30740
34.36000,289.84209,13.29053,286.34180,0.31644
34.40000,290.17520,13.02995,286.67487,0.31024
34.44000,290.50878,12.85300,287.00848,0.30602
34.48000,290.84191,13.16108,287.34161,0.31336
34.52000,291.17538,12.88746,287.67505,0.30684
34.56000,291.50867,12.98748,288.00836,0.30923
34.60000,291.84202,12.62706,288.34174,0.30064
34.64000,292.17539,13.08210,288.67508,0.31148
34.68000,292.50860,13.08303,289.00827,0.31150
34.72000,292.84207,13.19163,289.34177,0.31409
34.76000,293.17528,13.02157,289.67499,0.31004
34.80000,293.50876,12.99586,290.00842,0.30943
34.84000,293.84189,12.94464,290.34158,0.30821
34.88000,294.17536,13.26669,290.67508,0.31587
34.92000,294.50865,13.39857,291.00836,0.31901
34.96000,294.84202,13.11712,291.34171,0.31231
35.00000,295.17537,13.56788,291.67508,0.32304
35.04000,295.50858,13.23931,292.00827,0.31522
35.08000,295.84210,13.19461,292.34180,0.31416
35.12000,296.17529,13.33542,292.67499,0.31751
35.16000,296.50874,13.15027,293.00845,0.31310
35.20000,296.84187,12.87982,293.34155,0.30666
35.24000,297.17542,13.36299,293.67511,0.31817
35.28000,297.50866,13.72918,294.00836,0.32689
35.32000,297.84211,13.70013,294.34183,0.32619
35.36000,298.17537,13.61351,294.67508,0.32413
35.40000,298.50861,13.62152,295.00833,0.32432
35.44000,298.84203,13.29165,295.34174,0.31647
35.48000,299.17522,13.72043,295.67493,0.32668
35.52000,299.50880,13.95997,296.00848,0.33238
35.56000,299.84190,13.82325,296.34158,0.32912
35.60000,300.17538,13.86888,296.67508,0.33021
35.64000,300.50867,14.17398,297.00836,0.33748
35.68000,300.84198,14.27308,297.34167,0.33984
35.72000,301.17535,13.78190,297.67502,0.32814
35.76000,301.50859,13.58241,298.00830,0.32339
35.80000,301.84212,13.55466,298.34180,0.32273
35.84000,302.17525,13.79270,298.67496,0.32840
35.88000,302.50878,13.96891,299.00848,0.33259
35.92000,302.84199,14.30623,299.34171,0.34062
35.96000,303.17541,14.07508,299.67511,0.33512
36.00000,303.50859,14.03429,300.00830,0.33415
36.04000,303.84196,14.03261,300.34164,0.33411
36.08000,304.17538,14.28556,300.67508,0.34013
36.12000,304.50862,14.57129,301.00833,0.34694
36.16000,304.84210,14.38763,301.34180,0.34256
36.20000,305.17518,14.32020,301.67487,0.34096
36.24000,305.50876,14.48225,302.00842,0.34482
36.28000,305.84199,14.47517,302.34171,0.34465
36.32000,306.17539,14.30996,302.67508,0.34071
36.36000,306.50865,14.23135,303.00833,0.33884
36.40000,306.84202,14.36006,303.34174,0.34191
36.44000,307.17536,14.39359,303.67508,0.34270
36.48000,307.50863,14.59457,304.00833,0.34749
36.52000,307.84210,14.82237,304.34180,0.35291
36.56000,308.17526,14.64207,304.67496,0.34862
36.60000,308.50876,14.50274,305.00845,0.34530
36.64000,308.84190,14.52547,305.34161,0.34584
36.68000,309.17542,14.51150,305.67514,0.34551
36.72000,309.50863,14.95313,306.00833,0.35603
36.76000,309.84198,15.04757,306.34164,0.35828
36.80000,310.17537,14.53180,306.67508,0.34600
36.84000,310.50858,1.16266,307.00830,0.02768
36.88000,310.84208,-0.12275,307.34180,-0.00292
36.92000,311.17527,0.44350,307.67499,0.01056
36.96000,311.50877,0.41183,308.00845,0.00981
37.00000,311.84193,0.11697,308.34164,0.00279
37.04000,312.17540,0.51744,308.67508,0.01232
37.08000,312.50867,0.32522,309.00836,0.00774
37.12000,312.84203,0.54538,309.34171,0.01299
37.16000,313.17538,0.57705,309.67508,0.01374
37.20000,313.50856,0.25276,310.00827,0.00602
37.24000,313.84211,0.30138,310.34183,0.00718
37.28000,314.17527,0.53197,310.67499,0.01267
37.32000,314.50875,0.36713,311.00845,0.00874
37.36000,314.84191,0.40252,311.34161,0.00958
37.40000,315.17538,0.53812,311.67508,0.01281
37.44000,315.50867,0.67391,312.00839,0.01605
37.48000,315.84196,0.34906,312.34167,0.00831
37.52000,316.17538,0.23581,312.67508,0.00561
37.56000,316.50859,0.32578,313.00830,0.00776
37.60000,316.84209,0.53234,313.34177,0.01267
37.64000,317.17531,0.37998,313.67502,0.00905
37.68000,317.50878,0.42412,314.00848,0.01010
37.72000,317.84191,0.22687,314.34161,0.00540
37.76000,318.17541,0.59418,314.67511,0.01415
37.80000,318.50865,0.56904,315.00836,0.01355
37.84000,318.84205,0.66329,315.34174,0.01579
37.88000,319.17539,0.30920,315.67511,0.00736
37.92000,319.50855,0.46622,316.00824,0.01110
37.96000,319.84205,0.52527,316.34177,0.01251
38.00000,320.17523,0.37178,316.67493,0.00885
38.04000,320.50879,0.45095,317.00848,0.01074
38.08000,320.84192,0.61020,317.34161,0.01453
38.12000,321.17542,0.35912,317.67511,0.00855
38.16000,321.50866,0.28145,318.00833,0.00670
38.20000,321.84208,0.27344,318.34177,0.00651
38.24000,322.17534,0.45504,318.67505,0.01083
38.28000,322.50866,0.40941,319.00836,0.00975
38.32000,322.84211,0.25239,319.34180,0.00601
38.36000,323.17527,0.40326,319.67496,0.00960
38.40000,323.50879,0.47479,320.00848,0.01130
38.44000,323.84193,0.45374,320.34161,0.01080
38.48000,324.17535,0.66329,320.67502,0.01579
38.52000,324.50861,0.62566,321.00833,0.01490
38.56000,324.84193,0.46752,321.34164,0.01113
38.60000,325.17540,0.58506,321.67508,0.01393
38.64000,325.50861,0.29597,322.00830,0.00705
38.68000,325.84209,0.70073,322.34180,0.01668
38.72000,326.17522,0.78604,322.67490,0.01872
38.76000,326.50877,0.45169,323.00845,0.01075
38.80000,326.84198,0.17658,323.34167,0.00420
38.84000,327.17548,0.62417,323.67517,0.01486
38.88000,327.50862,0.67409,324.00833,0.01605
38.92000,327.84196,0.52713,324.34167,0.01255
38.96000,328.17538,0.17583,324.67508,0.00419
39.00000,328.50862,0.26692,325.00830,0.00636
39.04000,328.84209,0.81155,325.34180,0.01932
39.08000,329.17523,0.57369,325.67490,0.01366
39.12000,329.50873,0.68601,326.00842,0.01633
39.16000,329.84194,0.36675,326.34164,0.00873
39.20000,330.17541,0.74804,326.67508,0.01781
39.24000,330.50860,0.60163,327.00827,0.01432
39.28000,330.84199,0.45989,327.34171,0.01095
39.32000,331.17536,0.09015,327.67508,0.00215
39.36000,331.50868,0.31311,328.00839,0.00746
39.40000,331.84218,0.93281,328.34186,0.02221
39.44000,332.17523,0.50999,328.67493,0.01214
39.48000,332.50876,0.92816,329.00845,0.02210
39.52000,332.84189,0.81360,329.34158,0.01937
39.56000,333.17544,0.46603,329.67511,0.01110
39.60000,333.50866,0.69365,330.00836,0.01652
39.64000,333.84200,0.93505,330.34171,0.02226
39.68000,334.17537,0.60964,330.67505,0.01452
39.72000,334.50855,0.64187,331.00824,0.01528
39.76000,334.84208,0.46100,331.34177,0.01098
39.80000,335.17526,0.36284,331.67496,0.00864
39.84000,335.50879,0.52061,332.00848,0.01240
39.88000,335.84190,0.73928,332.34158,0.01760
39.92000,336.17540,0.63144,332.67511,0.01503
39.96000,336.50869,0.70352,333.00839,0.01675
40.00000,336.84208,0.36918,333.34177,0.00879
40.04000,337.17537,0.19688,333.67505,0.00469
40.08000,337.50859,0.86296,334.00830,0.02055
40.12000,337.84211,0.81547,334.34180,0.01942
40.14200,338.02541,0.83596,334.52512,0.01990