File: raw_data/mechanical_tests_Instron_data/Silicone_0035-Cross_2.is_tens_RawData/Specimen_RawData_1.csv
Dimension : Area,0.42000,cm^2

Time,Load,Extension,Tensile extension,Tensile strain,Tensile stress
(sec),(N),(mm),(mm),(mm/mm),(MPa)
0.00000,0.28573,0.00000,0.00000,0.00000,0.00680
0.04000,0.82739,0.06027,0.06027,0.00043,0.01970
0.08000,0.44815,0.26076,0.26076,0.00186,0.01067
0.12000,2.06828,0.59309,0.59309,0.00424,0.04924
0.16000,2.10050,0.98764,0.98764,0.00705,0.05001
0.20000,1.99880,1.39891,1.39891,0.00999,0.04759
0.24000,2.39499,1.81993,1.81993,0.01300,0.05702
0.28000,2.35494,2.24748,2.24748,0.01605,0.05607
0.32000,1.91610,2.66003,2.66003,0.01900,0.04562
0.36000,1.84737,3.00605,3.00605,0.02147,0.04399
0.40000,1.81217,3.33562,3.33562,0.02383,0.04315
0.44000,1.54860,3.67181,3.67181,0.02623,0.03687
0.48000,1.87214,4.00768,4.00768,0.02863,0.04457
0.52000,2.27168,4.34124,4.34124,0.03101,0.05409
0.56000,2.37506,4.67464,4.67464,0.03339,0.05655
0.60000,1.96826,5.00828,5.00828,0.03577,0.04686
0.64000,1.90809,5.34152,5.34152,0.03815,0.04543
0.68000,1.70749,5.67495,5.67495,0.04054,0.04065
0.72000,1.76206,6.00811,6.00811,0.04292,0.04195
0.76000,2.25250,6.34178,6.34178,0.04530,0.05363
0.80000,1.99955,6.67497,6.67497,0.04768,0.04761
0.84000,1.72555,7.00837,7.00837,0.05006,0.04108
0.88000,2.16104,7.34167,7.34167,0.05244,0.05145
0.92000,2.06567,7.67491,7.67491,0.05482,0.04918
0.96000,2.15266,8.00842,8.00842,0.05720,0.05125
1.00000,2.45087,8.34163,8.34163,0.05958,0.05835
1.04000,2.25399,8.67506,8.67506,0.06196,0.05367
1.08000,2.03550,9.00819,9.00819,0.06434,0.04846
1.12000,2.22884,9.34167,9.34167,0.06673,0.05307
1.16000,2.18768,9.67494,9.67494,0.06911,0.05209
1.20000,1.98707,10.00834,10.00834,0.07149,0.04731
1.24000,2.07201,10.34158,10.34158,0.07387,0.04933
1.28000,2.14111,10.67493,10.67493,0.07625,0.05098
1.32000,2.28435,11.00833,11.00833,0.07863,0.05439
1.36000,2.28565,11.34163,11.34163,0.08101,0.05442
1.40000,2.51904,11.67511,11.67511,0.08339,0.05998
1.44000,2.11541,12.00822,12.00822,0.08577,0.05037
1.48000,2.35718,12.34173,12.34173,0.08816,0.05612
1.52000,2.58740,12.67494,12.67494,0.09054,0.06160
1.56000,2.57585,13.00842,13.00842,0.09292,0.06133
1.60000,2.35755,13.34166,13.34166,0.09530,0.05613
1.64000,2.42963,13.67496,13.67496,0.09768,0.05785
1.68000,2.51774,14.00833,14.00833,0.10006,0.05995
1.72000,2.50489,14.34152,14.34152,0.10244,0.05964
1.76000,2.57213,14.67511,14.67511,0.10482,0.06124
1.80000,2.55294,15.00822,15.00822,0.10720,0.06078
1.84000,2.30167,15.34175,15.34175,0.10958,0.05480
1.88000,2.64198,15.67483,15.67483,0.11196,0.06290
1.92000,2.46130,16.00832,16.00832,0.11435,0.05860
1.96000,2.38381,16.34166,16.34166,0.11673,0.05676
2.00000,2.20910,16.67496,16.67496,0.11911,0.05260
2.04000,2.68798,17.00844,17.00844,0.12149,0.06400
2.08000,2.46353,17.34152,17.34152,0.12387,0.05866
2.12000,2.45310,17.67513,17.67514,0.12625,0.05841
2.16000,2.49017,18.00827,18.00827,0.12863,0.05929
2.20000,2.36575,18.34172,18.34172,0.13101,0.05633
2.24000,2.57790,18.67491,18.67491,0.13339,0.06138
2.28000,2.21115,19.00834,19.00834,0.13577,0.05265
2.32000,2.41324,19.34169,19.34169,0.13815,0.05746
2.36000,2.93404,19.67496,19.67496,0.14054,0.06986
2.40000,2.49911,20.00836,20.00836,0.14292,0.05950
2.44000,2.24467,20.34154,20.34154,0.14530,0.05344
2.48000,2.52817,20.67505,20.67505,0.14768,0.06019
2.52000,2.52370,21.00827,21.00827,0.15006,0.06009
2.56000,2.76938,21.34175,21.34175,0.15244,0.06594
2.60000,2.75690,21.67491,21.67491,0.15482,0.06564
2.64000,2.64514,22.00831,22.00831,0.15720,0.06298
2.68000,2.88971,22.34169,22.34169,0.15958,0.06880
2.72000,2.82377,22.67498,22.67498,0.16196,0.06723
2.76000,2.58926,23.00836,23.00836,0.16435,0.06165
2.80000,2.72989,23.34160,23.34160,0.16673,0.06500
2.84000,2.36686,23.67505,23.67505,0.16911,0.05635
2.88000,2.28472,24.00827,24.00827,0.17149,0.05440
2.92000,2.58107,24.34175,24.34175,0.17387,0.06145
2.96000,2.33296,24.67483,24.67483,0.17625,0.05555
3.00000,2.56468,25.00836,25.00836,0.17863,0.06106
3.04000,2.78298,25.34166,25.34166,0.18101,0.06626
3.08000,2.77292,25.67498,25.67498,0.18339,0.06602
3.12000,2.66805,26.00838,26.00838,0.18577,0.06353
3.16000,2.75057,26.34154,26.34154,0.18815,0.06549
3.20000,2.68556,26.67510,26.67510,0.19054,0.06394
3.24000,2.60081,27.00818,27.00818,0.19292,0.06192
3.28000,2.79285,27.34177,27.34177,0.19530,0.06650
3.32000,2.44677,27.67499,27.67499,0.19768,0.05826
3.36000,2.79732,28.00836,28.00836,0.20006,0.06660
3.40000,2.60249,28.34163,28.34163,0.20244,0.06196
3.44000,2.30893,28.67495,28.67495,0.20482,0.05497
3.48000,2.34190,29.00843,29.00843,0.20720,0.05576
3.52000,2.47918,29.34157,29.34157,0.20958,0.05903
3.56000,2.64458,29.67505,29.67505,0.21196,0.06297
3.60000,2.68798,30.00818,30.00818,0.21434,0.06400
3.64000,2.60528,30.34172,30.34172,0.21673,0.06203
3.68000,2.71816,30.67496,30.67496,0.21911,0.06472
3.72000,2.43429,31.00834,31.00834,0.22149,0.05796
3.76000,2.63155,31.34160,31.34160,0.22387,0.06266
3.80000,2.72337,31.67492,31.67492,0.22625,0.06484
3.84000,1.97198,32.00838,32.00838,0.22863,0.04695
3.88000,2.14893,32.34164,32.34164,0.23101,0.05117
3.92000,2.64011,32.67510,32.67510,0.23339,0.06286
3.96000,2.67643,33.00824,33.00824,0.23577,0.06372
4.00000,2.77627,33.34169,33.34169,0.23815,0.06610
4.04000,2.32104,33.67493,33.67493,0.24054,0.05526
4.08000,2.29273,34.00844,34.00844,0.24292,0.05459
4.12000,2.52891,34.34157,34.34158,0.24530,0.06021
4.16000,2.37692,34.67495,34.67495,0.24768,0.05659
4.20000,2.46931,35.00838,35.00838,0.25006,0.05879
4.24000,2.13273,35.34156,35.34156,0.25244,0.05078
4.28000,2.13366,35.67507,35.67507,0.25482,0.05080
4.32000,2.08300,36.00818,36.00818,0.25720,0.04960
4.36000,2.50451,36.34169,36.34169,0.25958,0.05963
4.40000,2.08076,36.67488,36.67488,0.26196,0.04954
4.44000,2.22567,37.00841,37.00841,0.26435,0.05299
4.48000,2.08449,37.34170,37.34171,0.26673,0.04963
4.52000,2.24989,37.67500,37.67500,0.26911,0.05357
4.56000,2.04798,38.00835,38.00835,0.27149,0.04876
4.60000,1.64676,38.34156,38.34156,0.27387,0.03921
4.64000,1.74418,38.67512,38.67512,0.27625,0.04153
4.68000,2.09287,39.00823,39.00823,0.27863,0.04983
4.72000,2.05804,39.34177,39.34177,0.28101,0.04900
4.76000,2.06120,39.67485,39.67485,0.28339,0.04908
4.80000,2.53245,40.00831,40.00830,0.28577,0.06030
4.84000,2.31434,40.34170,40.34170,0.28816,0.05510
4.88000,2.14502,40.67494,40.67495,0.29054,0.05107
4.92000,2.47378,41.00837,41.00837,0.29292,0.05890
4.96000,2.49110,41.34151,41.34150,0.29530,0.05931
5.00000,2.33576,41.67507,41.67507,0.29768,0.05561
5.04000,2.28696,42.00828,42.00828,0.30006,0.05445
5.08000,2.38139,42.34177,42.34177,0.30244,0.05670
5.12000,2.23313,42.67490,42.67490,0.30482,0.05317
5.16000,2.17669,43.00830,43.00831,0.30720,0.05183
5.20000,2.35774,43.34168,43.34167,0.30958,0.05614
5.24000,2.17836,43.67497,43.67497,0.31196,0.05187
5.28000,2.55294,44.00837,44.00837,0.31435,0.06078
5.32000,2.20612,44.34156,44.34156,0.31673,0.05253
5.36000,2.30912,44.67507,44.67507,0.31911,0.05498
5.40000,2.29627,45.00820,45.00821,0.32149,0.05467
5.44000,2.14614,45.34168,45.34168,0.32387,0.05110
5.48000,2.32272,45.67487,45.67487,0.32625,0.05530
5.52000,2.81036,46.00835,46.00835,0.32863,0.06691
5.56000,2.77776,46.34167,46.34167,0.33101,0.06614
5.60000,2.80999,46.67503,46.67503,0.33339,0.06690
5.64000,2.65203,47.00840,47.00840,0.33577,0.06314
5.68000,2.53562,47.34156,47.34156,0.33815,0.06037
5.72000,3.06088,47.67507,47.67506,0.34054,0.07288
5.76000,3.02196,48.00820,48.00820,0.34292,0.07195
5.80000,3.02978,48.34177,48.34177,0.34530,0.07214
5.84000,2.76901,48.67495,48.67495,0.34768,0.06593
5.88000,2.99886,49.00838,49.00838,0.35006,0.07140
5.92000,3.11118,49.34162,49.34162,0.35244,0.07408
5.96000,3.37251,49.67491,49.67492,0.35482,0.08030
6.00000,2.95974,50.00840,50.00840,0.35720,0.07047
6.04000,3.36356,50.34153,50.34153,0.35958,0.08008
6.08000,3.17786,50.67507,50.67507,0.36196,0.07566
6.12000,3.23951,51.00823,51.00822,0.36434,0.07713
6.16000,3.45837,51.34174,51.34174,0.36673,0.08234
6.20000,3.28980,51.67495,51.67495,0.36911,0.07833
6.24000,3.06461,52.00835,52.00835,0.37149,0.07297
6.28000,3.05828,52.34162,52.34162,0.37387,0.07282
6.32000,3.21809,52.67491,52.67492,0.37625,0.07662
6.36000,3.50215,53.00842,53.00842,0.37863,0.08338
6.40000,3.48333,53.34161,53.34161,0.38101,0.08294
6.44000,3.21157,53.67507,53.67506,0.38339,0.07647
6.48000,3.09739,54.00820,54.00820,0.38577,0.07375
6.52000,3.42224,54.34173,54.34173,0.38816,0.08148
6.56000,3.23579,54.67497,54.67497,0.39054,0.07704
6.60000,3.54126,55.00835,55.00835,0.39292,0.08432
6.64000,3.49153,55.34164,55.34164,0.39530,0.08313
6.68000,3.18438,55.67494,55.67494,0.39768,0.07582
6.72000,3.17004,56.00834,56.00834,0.40006,0.07548
6.76000,3.41665,56.34164,56.34164,0.40244,0.08135
6.80000,3.34717,56.67504,56.67504,0.40482,0.07969
6.84000,3.33209,57.00820,57.00820,0.40720,0.07934
6.88000,3.58578,57.34173,57.34173,0.40958,0.08538
6.92000,3.55467,57.67492,57.67492,0.41196,0.08464
6.96000,3.55355,58.00840,58.00840,0.41435,0.08461
7.00000,3.39262,58.34164,58.34164,0.41673,0.08078
7.04000,3.40827,58.67494,58.67494,0.41911,0.08115
7.08000,3.63402,59.00837,59.00837,0.42149,0.08652
7.12000,3.61465,59.34158,59.34158,0.42387,0.08606
7.16000,3.48929,59.67512,59.67512,0.42625,0.08308
7.20000,3.31886,60.00823,60.00822,0.42863,0.07902
7.24000,3.43807,60.34173,60.34173,0.43101,0.08186
7.28000,3.79458,60.67489,60.67489,0.43339,0.09035
7.32000,3.91956,61.00835,61.00835,0.43577,0.09332
7.36000,3.39951,61.34167,61.34167,0.43815,0.08094
7.40000,3.90187,61.67499,61.67499,0.44054,0.09290
7.44000,3.81544,62.00837,62.00837,0.44292,0.09084
7.48000,3.36654,62.34153,62.34153,0.44530,0.08016
7.52000,4.05964,62.67512,62.67512,0.44768,0.09666
7.56000,3.78676,63.00824,63.00824,0.45006,0.09016
7.60000,3.59174,63.34176,63.34175,0.45244,0.08552
7.64000,4.38131,63.67492,63.67492,0.45482,0.10432
7.68000,4.09503,64.00834,64.00835,0.45720,0.09750
7.72000,3.91938,64.34170,64.34170,0.45958,0.09332
7.76000,3.95216,64.67496,64.67496,0.46196,0.09410
7.80000,3.94266,65.00836,65.00836,0.46435,0.09387
7.84000,4.32916,65.34152,65.34152,0.46673,0.10308
7.88000,4.51263,65.67506,65.67506,0.46911,0.10744
7.92000,4.06932,66.00827,66.00827,0.47149,0.09689
7.96000,4.20231,66.34176,66.34176,0.47387,0.10006
8.00000,4.17829,66.67489,66.67489,0.47625,0.09948
8.04000,4.08944,67.00832,67.00832,0.47863,0.09737
8.08000,4.21833,67.34163,67.34164,0.48101,0.10044
8.12000,4.20157,67.67501,67.67501,0.48339,0.10004
8.16000,3.97060,68.00842,68.00842,0.48577,0.09454
8.20000,3.95253,68.34155,68.34155,0.48815,0.09411
8.24000,4.26155,68.67508,68.67508,0.49054,0.10147
8.28000,4.25372,69.00824,69.00824,0.49292,0.10128
8.32000,4.30439,69.34175,69.34175,0.49530,0.10249
8.36000,4.24143,69.67491,69.67491,0.49768,0.10099
8.40000,4.16022,70.00834,70.00835,0.50006,0.09905
8.44000,4.52325,70.34161,70.34161,0.50244,0.10770
8.48000,4.28818,70.67496,70.67496,0.50482,0.10210
8.52000,4.20567,71.00838,71.00838,0.50720,0.10013
8.56000,4.41913,71.34158,71.34158,0.50958,0.10522
8.60000,4.36604,71.67508,71.67508,0.51196,0.10395
8.64000,3.92925,72.00819,72.00819,0.51434,0.09355
8.68000,4.11440,72.34178,72.34178,0.51673,0.09796
8.72000,4.35468,72.67494,72.67494,0.51911,0.10368
8.76000,4.48581,73.00837,73.00837,0.52149,0.10680
8.80000,4.26508,73.34167,73.34167,0.52387,0.10155
8.84000,4.01940,73.67488,73.67488,0.52625,0.09570
8.88000,4.42490,74.00844,74.00844,0.52863,0.10535
8.92000,4.26266,74.34160,74.34160,0.53101,0.10149
8.96000,4.41298,74.67508,74.67508,0.53339,0.10507
9.00000,4.51077,75.00822,75.00822,0.53577,0.10740
9.04000,4.54206,75.34170,75.34170,0.53815,0.10814
9.08000,4.52232,75.67491,75.67490,0.54054,0.10767
9.12000,4.31407,76.00837,76.00837,0.54292,0.10272
9.16000,4.59943,76.34167,76.34167,0.54530,0.10951
9.20000,4.68660,76.67490,76.67490,0.54768,0.11159
9.24000,4.46942,77.00838,77.00838,0.55006,0.10641
9.28000,4.47612,77.34160,77.34160,0.55244,0.10657
9.32000,4.66704,77.67514,77.67514,0.55482,0.11112
9.36000,4.59850,78.00824,78.00823,0.55720,0.10949
9.40000,4.98835,78.34170,78.34170,0.55958,0.11877
9.44000,4.60092,78.67496,78.67495,0.56196,0.10955
9.48000,4.64078,79.00837,79.00837,0.56435,0.11049
9.52000,4.37927,79.34163,79.34164,0.56673,0.10427
9.56000,4.69796,79.67492,79.67492,0.56911,0.11186
9.60000,4.86597,80.00833,80.00833,0.57149,0.11586
9.64000,4.49307,80.34160,80.34159,0.57387,0.10698
9.68000,4.50090,80.67506,80.67506,0.57625,0.10716
9.72000,4.68437,81.00822,81.00822,0.57863,0.11153
9.76000,4.46811,81.34178,81.34178,0.58101,0.10638
9.80000,4.61973,81.67491,81.67490,0.58339,0.10999
9.84000,4.94383,82.00837,82.00837,0.58577,0.11771
9.88000,4.63314,82.34166,82.34165,0.58815,0.11031
9.92000,4.74323,82.67496,82.67496,0.59054,0.11293
9.96000,4.84958,83.00838,83.00838,0.59292,0.11547
10.00000,4.33028,83.34158,83.34158,0.59530,0.10310
10.04000,4.71752,83.67513,83.67513,0.59768,0.11232
10.08000,4.61880,84.00823,84.00822,0.60006,0.10997
10.12000,4.44427,84.34169,84.34170,0.60244,0.10582
10.16000,4.56050,84.67491,84.67491,0.60482,0.10858
10.20000,4.67766,85.00837,85.00838,0.60720,0.11137
10.24000,4.63929,85.34166,85.34166,0.60958,0.11046
10.28000,4.60241,85.67495,85.67496,0.61196,0.10958
10.32000,4.65699,86.00838,86.00839,0.61435,0.11088
10.36000,5.03212,86.34151,86.34151,0.61673,0.11981
10.40000,4.58471,86.67511,86.67511,0.61911,0.10916
10.44000,4.61917,87.00823,87.00823,0.62149,0.10998
10.48000,4.89894,87.34175,87.34174,0.62387,0.11664
10.52000,4.87883,87.67493,87.67493,0.62625,0.11616
10.56000,5.18877,88.00831,88.00831,0.62863,0.12354
10.60000,4.93452,88.34168,88.34167,0.63101,0.11749
10.64000,5.19380,88.67497,88.67497,0.63339,0.12366
10.68000,5.36107,89.00838,89.00838,0.63577,0.12764
10.72000,5.10495,89.34156,89.34156,0.63815,0.12155
10.76000,5.00865,89.67502,89.67503,0.64054,0.11925
10.80000,4.92819,90.00829,90.00829,0.64292,0.11734
10.84000,5.22267,90.34177,90.34177,0.64530,0.12435
10.88000,5.32474,90.67482,90.67482,0.64768,0.12678
10.92000,5.27576,91.00836,91.00836,0.65006,0.12561
10.96000,5.43520,91.34166,91.34166,0.65244,0.12941
11.00000,5.40800,91.67497,91.67497,0.65482,0.12876
11.04000,5.79488,92.00840,92.00840,0.65720,0.13797
11.08000,5.43613,92.34154,92.34155,0.65958,0.12943
11.12000,5.35510,92.67505,92.67504,0.66196,0.12750
11.16000,5.76135,93.00823,93.00824,0.66434,0.13717
11.20000,5.47636,93.34179,93.34179,0.66673,0.13039
11.24000,5.31841,93.67493,93.67493,0.66911,0.12663
11.28000,5.47785,94.00833,94.00833,0.67149,0.13043
11.32000,5.54360,94.34160,94.34161,0.67387,0.13199
11.36000,5.34989,94.67495,94.67495,0.67625,0.12738
11.40000,5.35101,95.00840,95.00840,0.67863,0.12740
11.44000,5.79748,95.34159,95.34159,0.68101,0.13804
11.48000,5.68349,95.67510,95.67509,0.68339,0.13532
11.52000,5.76824,96.00815,96.00815,0.68577,0.13734
11.56000,5.97145,96.34171,96.34172,0.68816,0.14218
11.60000,5.71869,96.67495,96.67495,0.69054,0.13616
11.64000,6.24508,97.00836,97.00836,0.69292,0.14869
11.68000,6.41961,97.34168,97.34167,0.69530,0.15285
11.72000,5.92172,97.67492,97.67493,0.69768,0.14099
11.76000,6.14822,98.00843,98.00842,0.70006,0.14639
11.80000,6.53937,98.34162,98.34162,0.70244,0.15570
11.84000,6.43227,98.67510,98.67509,0.70482,0.15315
11.88000,6.45462,99.00821,99.00821,0.70720,0.15368
11.92000,6.60885,99.34166,99.34166,0.70958,0.15735
11.96000,6.66119,99.67495,99.67495,0.71196,0.15860
12.00000,6.67833,100.00838,100.00838,0.71435,0.15901
12.04000,6.79623,100.34166,100.34165,0.71673,0.16182
12.08000,6.44326,100.67492,100.67492,0.71911,0.15341
12.12000,6.54757,101.00835,101.00835,0.72149,0.15589
12.16000,6.82399,101.34156,101.34157,0.72387,0.16248
12.20000,6.95456,101.67510,101.67509,0.72625,0.16558
12.24000,7.12406,102.00823,102.00822,0.72863,0.16962
12.28000,7.05216,102.34171,102.34171,0.73101,0.16791
12.32000,6.90259,102.67495,102.67495,0.73339,0.16435
12.36000,6.83255,103.00841,103.00841,0.73577,0.16268
12.40000,6.72899,103.34165,103.34165,0.73815,0.16021
12.44000,7.48411,103.67496,103.67496,0.74054,0.17819
12.48000,7.08941,104.00835,104.00835,0.74292,0.16880
12.52000,6.93891,104.34156,104.34156,0.74530,0.16521
12.56000,7.06632,104.67510,104.67510,0.74768,0.16825
12.60000,7.11102,105.00821,105.00820,0.75006,0.16931
12.64000,7.18813,105.34174,105.34174,0.75244,0.17115
12.68000,7.14771,105.67486,105.67487,0.75482,0.17018
12.72000,7.31312,106.00836,106.00835,0.75720,0.17412
12.76000,7.48914,106.34167,106.34168,0.75958,0.17831
12.80000,7.69738,106.67494,106.67494,0.76196,0.18327
12.84000,7.35428,107.00839,107.00839,0.76435,0.17510
12.88000,7.39060,107.34155,107.34155,0.76673,0.17597
12.92000,7.40420,107.67506,107.67506,0.76911,0.17629
12.96000,7.32783,108.00828,108.00828,0.77149,0.17447
13.00000,7.32765,108.34176,108.34177,0.77387,0.17447
13.04000,7.58301,108.67492,108.67493,0.77625,0.18055
13.08000,6.99852,109.00836,109.00835,0.77863,0.16663
13.12000,7.30548,109.34167,109.34167,0.78101,0.17394
13.16000,7.37123,109.67494,109.67493,0.78339,0.17551
13.20000,7.35167,110.00840,110.00840,0.78577,0.17504
13.24000,7.41333,110.34156,110.34156,0.78815,0.17651
13.28000,7.29598,110.67504,110.67504,0.79054,0.17371
13.32000,7.26711,111.00826,111.00826,0.79292,0.17303
13.36000,7.39843,111.34173,111.34173,0.79530,0.17615
13.40000,7.27195,111.67493,111.67493,0.79768,0.17314
13.44000,7.26152,112.00830,112.00830,0.80006,0.17289
13.48000,7.31293,112.34171,112.34171,0.80244,0.17412
13.52000,7.50851,112.67505,112.67505,0.80482,0.17877
13.56000,7.43922,113.00839,113.00839,0.80720,0.17712
13.60000,7.55116,113.34158,113.34158,0.80958,0.17979
13.64000,7.33063,113.67506,113.67506,0.81196,0.17454
13.68000,7.40029,114.00822,114.00822,0.81434,0.17620
13.72000,7.75587,114.34179,114.34179,0.81673,0.18466
13.76000,7.55861,114.67492,114.67492,0.81911,0.17997
13.80000,7.27549,115.00836,115.00835,0.82149,0.17323
13.84000,7.60835,115.34162,115.34162,0.82387,0.18115
13.88000,7.52024,115.67494,115.67493,0.82625,0.17905
13.92000,7.39917,116.00835,116.00835,0.82863,0.17617
13.96000,6.93649,116.34158,116.34158,0.83101,0.16515
14.00000,7.62586,116.67511,116.67511,0.83339,0.18157
14.04000,7.37216,117.00822,117.00822,0.83577,0.17553
14.08000,7.46399,117.34182,117.34182,0.83816,0.17771
14.12000,7.29132,117.67498,117.67498,0.84054,0.17360
14.16000,7.47815,118.00838,118.00838,0.84292,0.17805
14.20000,7.64951,118.34164,118.34164,0.84530,0.18213
14.24000,7.46269,118.67496,118.67496,0.84768,0.17768
14.28000,7.59512,119.00844,119.00845,0.85006,0.18084
14.32000,7.75158,119.34155,119.34155,0.85244,0.18456
14.36000,7.42488,119.67509,119.67509,0.85482,0.17678
14.40000,7.67112,120.00820,120.00819,0.85720,0.18265
14.44000,7.84677,120.34170,120.34170,0.85958,0.18683
14.48000,7.88663,120.67495,120.67495,0.86196,0.18778
14.52000,7.95629,121.00837,121.00837,0.86435,0.18944
14.56000,7.96560,121.34167,121.34167,0.86673,0.18966
14.60000,7.82702,121.67494,121.67493,0.86911,0.18636
14.64000,7.94977,122.00833,122.00833,0.87149,0.18928
14.68000,7.58320,122.34166,122.34166,0.87387,0.18055
14.72000,7.83335,122.67511,122.67511,0.87625,0.18651
14.76000,8.11871,123.00825,123.00826,0.87863,0.19330
14.80000,7.81193,123.34175,123.34175,0.88101,0.18600
14.84000,7.76462,123.67494,123.67494,0.88339,0.18487
14.88000,8.08798,124.00843,124.00842,0.88577,0.19257
14.92000,8.20290,124.34164,124.34164,0.88815,0.19531
14.96000,7.73985,124.67488,124.67487,0.89053,0.18428
15.00000,7.83820,125.00836,125.00836,0.89292,0.18662
15.04000,8.08518,125.34160,125.34160,0.89530,0.19250
15.08000,7.81864,125.67509,125.67509,0.89768,0.18616
15.12000,7.98721,126.00822,126.00822,0.90006,0.19017
15.16000,7.93710,126.34172,126.34172,0.90244,0.18898
15.20000,8.20551,126.67488,126.67488,0.90482,0.19537
15.24000,8.29455,127.00843,127.00843,0.90720,0.19749
15.28000,8.38954,127.34170,127.34170,0.90958,0.19975
15.32000,8.01496,127.67499,127.67499,0.91196,0.19083
15.36000,8.23643,128.00838,128.00838,0.91435,0.19611
15.40000,8.00099,128.34158,128.34158,0.91673,0.19050
15.44000,7.69552,128.67513,128.67514,0.91911,0.18323
15.48000,7.81901,129.00823,129.00822,0.92149,0.18617
15.52000,8.34335,129.34175,129.34175,0.92387,0.19865
15.56000,8.40202,129.67491,129.67491,0.92625,0.20005
15.60000,7.93897,130.00832,130.00832,0.92863,0.18902
15.64000,8.15820,130.34169,130.34169,0.93101,0.19424
15.68000,8.08481,130.67497,130.67497,0.93339,0.19250
15.72000,8.17608,131.00836,131.00836,0.93577,0.19467
15.76000,8.42307,131.34155,131.34155,0.93815,0.20055
15.80000,8.50223,131.67509,131.67508,0.94054,0.20243
15.84000,8.54861,132.00827,132.00827,0.94292,0.20354
15.88000,8.46926,132.34177,132.34177,0.94530,0.20165
15.92000,8.03322,132.67493,132.67493,0.94768,0.19127
15.96000,8.12635,133.00830,133.00830,0.95006,0.19348
16.00000,8.30945,133.34170,133.34169,0.95244,0.19784
16.04000,8.03731,133.67501,133.67502,0.95482,0.19136
16.08000,8.23550,134.00845,134.00845,0.95720,0.19608
16.12000,8.43089,134.34157,134.34157,0.95958,0.20074
16.16000,8.06022,134.67503,134.67503,0.96196,0.19191
16.20000,8.38879,135.00824,135.00824,0.96434,0.19973
16.24000,8.56295,135.34173,135.34172,0.96673,0.20388
16.28000,8.62628,135.67494,135.67494,0.96911,0.20539
16.32000,8.50242,136.00831,136.00830,0.97149,0.20244
16.36000,8.65962,136.34161,136.34161,0.97387,0.20618
16.40000,8.82111,136.67503,136.67503,0.97625,0.21003
16.44000,8.49292,137.00839,137.00839,0.97863,0.20221
16.48000,8.66689,137.34156,137.34157,0.98101,0.20635
16.52000,8.85967,137.67511,137.67511,0.98339,0.21094
16.56000,8.87085,138.00821,138.00821,0.98577,0.21121
16.60000,8.93138,138.34181,138.34181,0.98816,0.21265
16.64000,8.83471,138.67497,138.67497,0.99054,0.21035
16.68000,8.61157,139.00837,139.00836,0.99292,0.20504
16.72000,9.02712,139.34166,139.34166,0.99530,0.21493
16.76000,8.99397,139.67495,139.67494,0.99768,0.21414
16.80000,8.56873,140.00841,140.00841,1.00006,0.20402
16.84000,8.80081,140.34161,140.34161,1.00244,0.20954
16.88000,8.49981,140.67508,140.67508,1.00482,0.20238
16.92000,8.93399,141.00820,141.00819,1.00720,0.21271
16.96000,8.83359,141.34173,141.34172,1.00958,0.21032
17.00000,9.25492,141.67491,141.67490,1.01196,0.22036
17.04000,8.98577,142.00838,142.00838,1.01435,0.21395
17.08000,9.02954,142.34168,142.34167,1.01673,0.21499
17.12000,9.03904,142.67498,142.67497,1.01911,0.21522
17.16000,8.77306,143.00843,143.00842,1.02149,0.20888
17.20000,9.03849,143.34156,143.34155,1.02387,0.21520
17.24000,9.23984,143.67509,143.67508,1.02625,0.22000
17.28000,8.90698,144.00825,144.00826,1.02863,0.21207
17.32000,8.96528,144.34172,144.34172,1.03101,0.21346
17.36000,9.10554,144.67496,144.67496,1.03339,0.21680
17.40000,9.20426,145.00836,145.00836,1.03577,0.21915
17.44000,9.27281,145.34166,145.34166,1.03815,0.22078
17.48000,9.28044,145.67492,145.67491,1.04054,0.22096
17.52000,9.37879,146.00831,146.00832,1.04292,0.22330
17.56000,9.67514,146.34162,146.34161,1.04530,0.23036
17.60000,9.42908,146.67513,146.67513,1.04768,0.22450
17.64000,9.68874,147.00820,147.00819,1.05006,0.23068
17.68000,9.40412,147.34175,147.34175,1.05244,0.22391
17.72000,9.29683,147.67492,147.67493,1.05482,0.22135
17.76000,9.25753,148.00841,148.00841,1.05720,0.22042
17.80000,9.49427,148.34167,148.34167,1.05958,0.22605
17.84000,9.27076,148.67495,148.67496,1.06196,0.22073
17.88000,9.42126,149.00839,149.00839,1.06435,0.22432
17.92000,9.46391,149.34159,149.34158,1.06673,0.22533
17.96000,9.21488,149.67511,149.67511,1.06911,0.21940
18.00000,9.70941,150.00818,150.00818,1.07149,0.23118
18.04000,9.40021,150.34172,150.34174,1.07387,0.22381
18.08000,9.50545,150.67488,150.67488,1.07625,0.22632
18.12000,9.72301,151.00839,151.00839,1.07863,0.23150
18.16000,9.69227,151.34172,151.34172,1.08101,0.23077
18.20000,9.50582,151.67498,151.67499,1.08339,0.22633
18.24000,9.56412,152.00838,152.00839,1.08577,0.22772
18.28000,9.84538,152.34157,152.34157,1.08815,0.23441
18.32000,9.70438,152.67517,152.67517,1.09054,0.23106
18.36000,9.76659,153.00826,153.00827,1.09292,0.23254
18.40000,9.86662,153.34175,153.34175,1.09530,0.23492
18.44000,9.82434,153.67495,153.67494,1.09768,0.23391
18.48000,9.80701,154.00833,154.00833,1.10006,0.23350
18.52000,10.03388,154.34167,154.34166,1.10244,0.23890
18.56000,10.08436,154.67496,154.67496,1.10482,0.24010
18.60000,9.98676,155.00838,155.00839,1.10720,0.23778
18.64000,9.95584,155.34155,155.34155,1.10958,0.23704
18.68000,9.89381,155.67502,155.67503,1.11196,0.23557
18.72000,9.89363,156.00823,156.00822,1.11434,0.23556
18.76000,9.96850,156.34179,156.34180,1.11673,0.23735
18.80000,10.29018,156.67496,156.67494,1.11911,0.24500
18.84000,9.72524,157.00832,157.00832,1.12149,0.23155
18.88000,9.99849,157.34168,157.34167,1.12387,0.23806
18.92000,10.17097,157.67501,157.67500,1.12625,0.24217
18.96000,10.07281,158.00843,158.00842,1.12863,0.23983
19.00000,10.24064,158.34156,158.34157,1.13101,0.24382
19.04000,10.11677,158.67502,158.67502,1.13339,0.24088
19.08000,10.65675,159.00829,159.00830,1.13577,0.25373
19.12000,10.08399,159.34176,159.34177,1.13816,0.24009
19.16000,10.75156,159.67492,159.67493,1.14054,0.25599
19.20000,10.34737,160.00834,160.00833,1.14292,0.24637
19.24000,10.24399,160.34157,160.34157,1.14530,0.24390
19.28000,10.28888,160.67494,160.67494,1.14768,0.24497
19.32000,10.22089,161.00840,161.00839,1.15006,0.24335
19.36000,9.94615,161.34158,161.34157,1.15244,0.23681
19.40000,10.28366,161.67512,161.67514,1.15482,0.24485
19.44000,10.06424,162.00820,162.00821,1.15720,0.23962
19.48000,10.47812,162.34182,162.34183,1.15958,0.24948
19.52000,10.33694,162.67498,162.67499,1.16196,0.24612
19.56000,10.27398,163.00832,163.00832,1.16435,0.24462
19.60000,10.48204,163.34168,163.34167,1.16673,0.24957
19.64000,10.35202,163.67494,163.67494,1.16911,0.24648
19.68000,10.65899,164.00840,164.00842,1.17149,0.25379
19.72000,10.85810,164.34159,164.34158,1.17387,0.25853
19.76000,10.62099,164.67509,164.67508,1.17625,0.25288
19.80000,10.97098,165.00822,165.00821,1.17863,0.26121
19.84000,10.50364,165.34175,165.34175,1.18101,0.25009
19.88000,10.59417,165.67492,165.67493,1.18339,0.25224
19.92000,10.53642,166.00838,166.00839,1.18577,0.25087
19.96000,10.67873,166.34167,166.34167,1.18815,0.25426
20.00000,10.62341,166.67494,166.67494,1.19054,0.25294
20.04000,11.06635,167.00836,167.00836,1.19292,0.26348
20.08000,10.83091,167.34165,167.34164,1.19530,0.25788
20.12000,11.01568,167.67512,167.67513,1.19768,0.26228
20.16000,10.79235,168.00825,168.00826,1.20006,0.25696
20.20000,10.66439,168.34170,168.34171,1.20244,0.25391
20.24000,10.80297,168.67493,168.67493,1.20482,0.25721
20.28000,10.72884,169.00839,169.00839,1.20720,0.25545
20.32000,10.77838,169.34165,169.34166,1.20958,0.25663
20.36000,10.73591,169.67499,169.67499,1.21196,0.25562
20.40000,11.03617,170.00834,170.00833,1.21435,0.26277
20.44000,11.23883,170.34159,170.34158,1.21673,0.26759
20.48000,11.20716,170.67513,170.67514,1.21911,0.26684
20.52000,11.09093,171.00820,171.00821,1.22149,0.26407
20.56000,11.14551,171.34176,171.34177,1.22387,0.26537
20.60000,11.15017,171.67489,171.67490,1.22625,0.26548
20.64000,11.45378,172.00837,172.00836,1.22863,0.27271
20.68000,11.55920,172.34170,172.34169,1.23101,0.27522
20.72000,11.19021,172.67496,172.67496,1.23339,0.26643
20.76000,11.20027,173.00836,173.00835,1.23577,0.26667
20.80000,11.74733,173.34158,173.34158,1.23815,0.27970
20.84000,11.58882,173.67515,173.67516,1.24054,0.27592
20.88000,11.34668,174.00824,174.00824,1.24292,0.27016
20.92000,11.30123,174.34173,174.34172,1.24530,0.26908
20.96000,10.85158,174.67489,174.67488,1.24768,0.25837
21.00000,11.24181,175.00835,175.00835,1.25006,0.26766
21.04000,11.27496,175.34164,175.34163,1.25244,0.26845
21.08000,11.64246,175.67490,175.67490,1.25482,0.27720
21.12000,11.35338,176.00843,176.00844,1.25720,0.27032
21.16000,11.36605,176.34156,176.34157,1.25958,0.27062
21.20000,11.87380,176.67511,176.67509,1.26197,0.28271
21.24000,11.67245,177.00827,177.00827,1.26434,0.27792
21.28000,11.43534,177.34173,177.34172,1.26673,0.27227
21.32000,11.72181,177.67495,177.67494,1.26911,0.27909
21.36000,11.61378,178.00837,178.00836,1.27149,0.27652
21.40000,11.84884,178.34170,178.34169,1.27387,0.28212
21.44000,11.74342,178.67501,178.67502,1.27625,0.27961
21.48000,11.68251,179.00838,179.00838,1.27863,0.27815
21.52000,11.95818,179.34154,179.34154,1.28101,0.28472
21.56000,11.62849,179.67500,179.67500,1.28339,0.27687
21.60000,11.68661,180.00824,180.00824,1.28577,0.27825
21.64000,11.93527,180.34180,180.34181,1.28816,0.28417
21.68000,11.95967,180.67491,180.67491,1.29054,0.28475
21.72000,12.13793,181.00828,181.00829,1.29292,0.28900
21.76000,12.13122,181.34164,181.34164,1.29530,0.28884
21.80000,11.66575,181.67499,181.67497,1.29768,0.27776
21.84000,11.81215,182.00843,182.00842,1.30006,0.28124
21.88000,11.76540,182.34163,182.34163,1.30244,0.28013
21.92000,11.68996,182.67511,182.67511,1.30482,0.27833
21.96000,11.97997,183.00827,183.00827,1.30720,0.28524
22.00000,11.94756,183.34181,183.34181,1.30958,0.28447
22.04000,11.85425,183.67494,183.67494,1.31196,0.28224
22.08000,11.88517,184.00834,184.00835,1.31435,0.28298
22.12000,11.79818,184.34163,184.34163,1.31673,0.28091
22.16000,11.92056,184.67496,184.67496,1.31911,0.28382
22.20000,12.22771,185.00845,185.00845,1.32149,0.29114
22.24000,12.08466,185.34154,185.34154,1.32387,0.28773
22.28000,11.92428,185.67503,185.67503,1.32625,0.28391
22.32000,12.06547,186.00813,186.00813,1.32863,0.28727
22.36000,11.63762,186.34175,186.34175,1.33101,0.27709
22.40000,11.96451,186.67502,186.67502,1.33339,0.28487
22.44000,12.06696,187.00838,187.00838,1.33577,0.28731
22.48000,12.07720,187.34171,187.34172,1.33816,0.28755
22.52000,12.22044,187.67500,187.67500,1.34054,0.29096
22.56000,12.04088,188.00841,188.00841,1.34292,0.28669
22.60000,12.04293,188.34160,188.34160,1.34530,0.28674
22.64000,12.33555,188.67509,188.67508,1.34768,0.29370
22.68000,11.86095,189.00822,189.00822,1.35006,0.28240
22.72000,12.03325,189.34171,189.34171,1.35244,0.28651
22.76000,12.30799,189.67494,189.67493,1.35482,0.29305
22.80000,12.23553,190.00834,190.00833,1.35720,0.29132
22.84000,12.59185,190.34166,190.34166,1.35958,0.29981
22.88000,12.35865,190.67491,190.67491,1.36196,0.29425
22.92000,12.25099,191.00835,191.00836,1.36435,0.29169
22.96000,12.72298,191.34163,191.34163,1.36673,0.30293
23.00000,12.49369,191.67510,191.67511,1.36911,0.29747
23.04000,12.50710,192.00826,192.00827,1.37149,0.29779
23.08000,12.50617,192.34170,192.34171,1.37387,0.29777
23.12000,12.45029,192.67495,192.67496,1.37625,0.29644
23.16000,12.60042,193.00848,193.00847,1.37863,0.30001
23.20000,12.81258,193.34169,193.34169,1.38101,0.30506
23.24000,12.37895,193.67498,193.67497,1.38339,0.29474
23.28000,12.95358,194.00836,194.00836,1.38577,0.30842
23.32000,12.85579,194.34155,194.34155,1.38815,0.30609
23.36000,12.83493,194.67508,194.67508,1.39054,0.30559
23.40000,12.66431,195.00822,195.00822,1.39292,0.30153
23.44000,12.51958,195.34173,195.34175,1.39530,0.29809
23.48000,12.74124,195.67489,195.67490,1.39768,0.30336
23.52000,12.42403,196.00836,196.00836,1.40006,0.29581
23.56000,12.66859,196.34175,196.34175,1.40244,0.30163
23.60000,12.63395,196.67498,196.67499,1.40482,0.30081
23.64000,13.01002,197.00838,197.00838,1.40720,0.30976
23.68000,13.10892,197.34163,197.34163,1.40958,0.31212
23.72000,13.20355,197.67517,197.67517,1.41197,0.31437
23.76000,13.26185,198.00824,198.00824,1.41434,0.31576
23.80000,13.08955,198.34175,198.34175,1.41673,0.31166
23.84000,12.78948,198.67494,198.67494,1.41911,0.30451
23.88000,12.90683,199.00834,199.00835,1.42149,0.30731
23.92000,12.71795,199.34167,199.34167,1.42387,0.30281
23.96000,12.75316,199.67496,199.67496,1.42625,0.30365
24.00000,13.06552,200.00838,200.00839,1.42863,0.31108
24.04000,12.91949,200.34156,200.34154,1.43101,0.30761
24.08000,12.96755,200.67504,200.67503,1.43339,0.30875
24.12000,13.20783,201.00824,201.00824,1.43577,0.31447
24.16000,13.26725,201.34181,201.34181,1.43816,0.31589
24.20000,13.36858,201.67497,201.67499,1.44054,0.31830
24.24000,13.34660,202.00836,202.00836,1.44292,0.31778
24.28000,13.27135,202.34165,202.34166,1.44530,0.31598
24.32000,13.28364,202.67504,202.67503,1.44768,0.31628
24.36000,13.63065,203.00840,203.00841,1.45006,0.32454
24.40000,13.50306,203.34156,203.34157,1.45244,0.32150
24.44000,13.22888,203.67510,203.67511,1.45482,0.31497
24.48000,13.13891,204.00821,204.00821,1.45720,0.31283
24.52000,12.88187,204.34175,204.34175,1.45958,0.30671
24.56000,13.27489,204.67493,204.67493,1.46196,0.31607
24.60000,13.43712,205.00837,205.00836,1.46435,0.31993
24.64000,13.35032,205.34163,205.34163,1.46673,0.31786
24.68000,13.51852,205.67498,205.67496,1.46911,0.32187
24.72000,13.49878,206.00840,206.00839,1.47149,0.32140
24.76000,13.39167,206.34158,206.34158,1.47387,0.31885
24.80000,13.72863,206.67511,206.67511,1.47625,0.32687
24.84000,13.54981,207.00820,207.00821,1.47863,0.32261
24.88000,13.86981,207.34183,207.34183,1.48101,0.33023
24.92000,13.70758,207.67495,207.67494,1.48339,0.32637
24.96000,13.42688,208.00839,208.00839,1.48577,0.31969
25.00000,13.63140,208.34165,208.34166,1.48815,0.32456
25.04000,13.35312,208.67492,208.67491,1.49054,0.31793
25.08000,13.49598,209.00847,209.00847,1.49292,0.32133
25.12000,13.53957,209.34154,209.34154,1.49530,0.32237
25.16000,13.55354,209.67506,209.67506,1.49768,0.32270
25.20000,13.46730,210.00826,210.00826,1.50006,0.32065
25.24000,13.65133,210.34172,210.34174,1.50244,0.32503
25.28000,13.92066,210.67499,210.67499,1.50482,0.33144
25.32000,13.89571,211.00837,211.00836,1.50720,0.33085
25.36000,13.90651,211.34166,211.34166,1.50958,0.33111
25.40000,13.93780,211.67496,211.67494,1.51196,0.33185
25.44000,13.98884,212.00840,212.00839,1.51435,0.33307
25.48000,14.32709,212.34162,212.34163,1.51673,0.34112
25.52000,13.89049,212.67512,212.67514,1.51911,0.33073
25.56000,14.16244,213.00823,213.00822,1.52149,0.33720
25.60000,14.25557,213.34174,213.34175,1.52387,0.33942
25.64000,13.90148,213.67493,213.67494,1.52625,0.33099
25.68000,13.79400,214.00836,214.00838,1.52863,0.32843
25.72000,13.96351,214.34168,214.34167,1.53101,0.33246
25.76000,13.81841,214.67492,214.67493,1.53339,0.32901
25.80000,13.90614,215.00834,215.00833,1.53577,0.33110
25.84000,14.11904,215.34163,215.34163,1.53815,0.33617
25.88000,14.32020,215.67510,215.67509,1.54054,0.34096
25.92000,14.33101,216.00822,216.00821,1.54292,0.34121
25.96000,13.99871,216.34175,216.34175,1.54530,0.33330
26.00000,14.30567,216.67493,216.67493,1.54768,0.34061
26.04000,14.54819,217.00843,217.00844,1.55006,0.34639
26.08000,14.14232,217.34170,217.34169,1.55244,0.33672
26.12000,14.34125,217.67496,217.67496,1.55482,0.34146
26.16000,14.55154,218.00838,218.00838,1.55720,0.34647
26.20000,14.53273,218.34156,218.34157,1.55958,0.34602
26.24000,14.50852,218.67515,218.67514,1.56197,0.34544
26.28000,14.42302,219.00824,219.00824,1.56434,0.34341
26.32000,14.71229,219.34171,219.34172,1.56673,0.35029
26.36000,14.34702,219.67490,219.67490,1.56911,0.34160
26.40000,14.28984,220.00830,220.00830,1.57149,0.34023
26.44000,14.54428,220.34164,220.34164,1.57387,0.34629
26.48000,14.32560,220.67495,220.67496,1.57625,0.34109
26.52000,14.51857,221.00835,221.00835,1.57863,0.34568
26.56000,14.73837,221.34156,221.34157,1.58101,0.35091
26.60000,15.04607,221.67511,221.67511,1.58339,0.35824
26.64000,14.82647,222.00825,222.00824,1.58577,0.35301
26.68000,15.03266,222.34177,222.34177,1.58816,0.35792
26.72000,14.81175,222.67496,222.67496,1.59054,0.35266
26.76000,15.15020,223.00833,223.00833,1.59292,0.36072
26.80000,15.00677,223.34164,223.34164,1.59530,0.35730
26.84000,15.11350,223.67496,223.67496,1.59768,0.35985
26.88000,14.94903,224.00838,224.00838,1.60006,0.35593
26.92000,14.91494,224.34162,224.34161,1.60244,0.35512
26.96000,14.74973,224.67504,224.67503,1.60482,0.35118
27.00000,14.77171,225.00823,225.00822,1.60720,0.35171
27.04000,14.90097,225.34170,225.34171,1.60958,0.35479
27.08000,15.07457,225.67489,225.67488,1.61196,0.35892
27.12000,14.77022,226.00836,226.00836,1.61435,0.35167
27.16000,15.33721,226.34160,226.34160,1.61673,0.36517
27.20000,15.16622,226.67502,226.67502,1.61911,0.36110
27.24000,14.86558,227.00844,227.00844,1.62149,0.35394
27.28000,14.83373,227.34160,227.34160,1.62387,0.35318
27.32000,14.99373,227.67510,227.67509,1.62625,0.35699
27.36000,14.98554,228.00821,228.00821,1.62863,0.35680
27.40000,15.20347,228.34173,228.34174,1.63101,0.36199
27.44000,15.40948,228.67492,228.67491,1.63339,0.36689
27.48000,14.91066,229.00837,229.00836,1.63577,0.35502
27.52000,15.12635,229.34163,229.34163,1.63815,0.36015
27.56000,15.17776,229.67495,229.67494,1.64054,0.36138
27.60000,15.12412,230.00839,230.00839,1.64292,0.36010
27.64000,15.07290,230.34155,230.34155,1.64530,0.35888
27.68000,15.33311,230.67503,230.67503,1.64768,0.36507
27.72000,15.38172,231.00819,231.00819,1.65006,0.36623
27.76000,15.46927,231.34182,231.34181,1.65244,0.36832
27.80000,15.29474,231.67495,231.67496,1.65482,0.36416
27.84000,15.39066,232.00832,232.00832,1.65720,0.36644
27.88000,15.52794,232.34171,232.34172,1.65958,0.36971
27.92000,15.50112,232.67493,232.67493,1.66196,0.36907
27.96000,15.53837,233.00843,233.00842,1.66435,0.36996
28.00000,15.25953,233.34159,233.34158,1.66673,0.36332
28.04000,15.42624,233.67509,233.67508,1.66911,0.36729
28.08000,15.64045,234.00822,234.00822,1.67149,0.37239
28.12000,15.34410,234.34172,234.34172,1.67387,0.36534
28.16000,15.16528,234.67493,234.67493,1.67625,0.36108
28.20000,15.67695,235.00835,235.00835,1.67863,0.37326
28.24000,15.88874,235.34164,235.34164,1.68101,0.37830
28.28000,15.91537,235.67493,235.67493,1.68339,0.37894
28.32000,15.64696,236.00838,236.00838,1.68577,0.37255
28.36000,15.88445,236.34162,236.34161,1.68815,0.37820
28.40000,15.67677,236.67509,236.67509,1.69054,0.37326
28.44000,15.77139,237.00820,237.00819,1.69292,0.37551
28.48000,16.17465,237.34175,237.34175,1.69530,0.38511
28.52000,16.09493,237.67499,237.67499,1.69768,0.38321
28.56000,15.93865,238.00838,238.00838,1.70006,0.37949
28.60000,15.91481,238.34167,238.34167,1.70244,0.37892
28.64000,16.25754,238.67496,238.67496,1.70482,0.38708
28.68000,16.02266,239.00831,239.00830,1.70720,0.38149
28.72000,15.64231,239.34155,239.34155,1.70958,0.37244
28.76000,16.01949,239.67512,239.67513,1.71197,0.38142
28.80000,16.11803,240.00826,240.00826,1.71434,0.38376
28.84000,16.25754,240.34173,240.34174,1.71673,0.38708
28.88000,16.30373,240.67486,240.67487,1.71911,0.38818
28.92000,16.33968,241.00839,241.00839,1.72149,0.38904
28.96000,16.06531,241.34173,241.34174,1.72387,0.38251
29.00000,16.41642,241.67494,241.67494,1.72625,0.39087
29.04000,16.48180,242.00839,242.00839,1.72863,0.39242
29.08000,16.52967,242.34155,242.34155,1.73101,0.39356
29.12000,16.60362,242.67513,242.67513,1.73339,0.39532
29.16000,16.55072,243.00826,243.00827,1.73577,0.39406
29.20000,16.70867,243.34166,243.34166,1.73815,0.39783
29.24000,16.40897,243.67492,243.67493,1.74054,0.39069
29.28000,16.22736,244.00834,244.00835,1.74292,0.38637
29.32000,16.45181,244.34166,244.34166,1.74530,0.39171
29.36000,16.62280,244.67500,244.67500,1.74768,0.39578
29.40000,16.38923,245.00840,245.00839,1.75006,0.39022
29.44000,16.70662,245.34153,245.34154,1.75244,0.39778
29.48000,16.84427,245.67506,245.67506,1.75482,0.40105
29.52000,16.87035,246.00827,246.00827,1.75720,0.40167
29.56000,16.86793,246.34177,246.34177,1.75958,0.40162
29.60000,16.85377,246.67493,246.67493,1.76196,0.40128
29.64000,16.45405,247.00832,247.00833,1.76435,0.39176
29.68000,16.54848,247.34167,247.34166,1.76673,0.39401
29.72000,16.41307,247.67498,247.67499,1.76911,0.39079
29.76000,16.83421,248.00838,248.00838,1.77149,0.40081
29.80000,16.68930,248.34156,248.34157,1.77387,0.39736
29.84000,17.09051,248.67504,248.67503,1.77625,0.40692
29.88000,16.64888,249.00822,249.00822,1.77863,0.39640
29.92000,16.75449,249.34177,249.34178,1.78101,0.39892
29.96000,16.74127,249.67491,249.67491,1.78339,0.39860
30.00000,16.77349,250.00836,250.00836,1.78577,0.39937
30.04000,16.75077,250.34159,250.34160,1.78815,0.39883
30.08000,17.01377,250.67494,250.67494,1.79054,0.40509
30.12000,17.35091,251.00841,251.00841,1.79292,0.41312
30.16000,17.13987,251.34160,251.34160,1.79530,0.40809
30.20000,17.10039,251.67507,251.67506,1.79768,0.40715
30.24000,16.95938,252.00818,252.00818,1.80006,0.40379
30.28000,17.12684,252.34181,252.34181,1.80244,0.40778
30.32000,16.78839,252.67497,252.67497,1.80482,0.39972
30.36000,17.18104,253.00839,253.00839,1.80720,0.40907
30.40000,16.95435,253.34163,253.34163,1.80958,0.40368
30.44000,16.91431,253.67494,253.67494,1.81196,0.40272
30.48000,17.06425,254.00839,254.00839,1.81435,0.40629
30.52000,17.23655,254.34158,254.34158,1.81673,0.41039
30.56000,17.12162,254.67508,254.67508,1.81911,0.40766
30.60000,17.20116,255.00821,255.00821,1.82149,0.40955
30.64000,17.53010,255.34171,255.34171,1.82387,0.41738
30.68000,17.55916,255.67497,255.67497,1.82625,0.41808
30.72000,17.14434,256.00834,256.00833,1.82863,0.40820
30.76000,17.31273,256.34166,256.34164,1.83101,0.41221
30.80000,17.35147,256.67495,256.67496,1.83339,0.41313
30.84000,6.54068,257.00842,257.00842,1.83577,0.15573
30.86400,-0.13188,257.20841,257.20840,1.83720,-0.00314