File: raw_data/mechanical_tests_Instron_data/3DP_Skin_0035_Horizontal_4.is_tens_RawData/Specimen_RawData_1.csv
Dimension : Area,0.42000,cm^2

Time,Load,Extension,Tensile extension,Tensile strain,Tensile stress
(sec),(N),(mm),(mm),(mm/mm),(MPa)
0.00000,0.30287,0.00000,0.00000,0.00000,0.00721
0.04000,1.05929,0.06040,0.06040,0.00043,0.02522
0.08000,0.59567,0.26084,0.26084,0.00186,0.01418
0.12000,1.31428,0.59215,0.59215,0.00423,0.03129
0.16000,2.11913,0.98167,0.98167,0.00701,0.05046
0.20000,2.04835,1.38769,1.38769,0.00991,0.04877
0.24000,2.31154,1.80308,1.80308,0.01288,0.05504
0.28000,2.06288,2.22474,2.22474,0.01589,0.04912
0.32000,2.02972,2.64509,2.64509,0.01889,0.04833
0.36000,1.51433,3.00790,3.00790,0.02149,0.03606
0.40000,1.59442,3.33661,3.33661,0.02383,0.03796
0.44000,1.50241,3.67093,3.67093,0.02622,0.03577
0.48000,1.42697,4.00741,4.00741,0.02862,0.03398
0.52000,1.88053,4.34137,4.34137,0.03101,0.04477
0.56000,1.33086,4.67459,4.67459,0.03339,0.03169
0.60000,1.31670,5.00826,5.00826,0.03577,0.03135
0.64000,1.68886,5.34152,5.34152,0.03815,0.04021
0.68000,1.70413,5.67506,5.67506,0.04054,0.04057
0.72000,1.04476,6.00819,6.00819,0.04292,0.02488
0.76000,1.52551,6.34170,6.34170,0.04530,0.03632
0.80000,1.69855,6.67492,6.67492,0.04768,0.04044
0.84000,1.70134,7.00829,7.00829,0.05006,0.04051
0.88000,1.19042,7.34172,7.34172,0.05244,0.02834
0.92000,1.84160,7.67493,7.67493,0.05482,0.04385
0.96000,1.90642,8.00839,8.00839,0.05720,0.04539
1.00000,1.66520,8.34160,8.34160,0.05958,0.03965
1.04000,1.10529,8.67508,8.67508,0.06196,0.02632
1.08000,1.95112,9.00822,9.00822,0.06434,0.04646
1.12000,1.27945,9.34173,9.34173,0.06673,0.03046
1.16000,1.39866,9.67497,9.67497,0.06911,0.03330
1.20000,1.57598,10.00834,10.00834,0.07149,0.03752
1.24000,1.39382,10.34172,10.34172,0.07387,0.03319
1.28000,1.35321,10.67488,10.67488,0.07625,0.03222
1.32000,1.47689,11.00839,11.00839,0.07863,0.03516
1.36000,1.88239,11.34155,11.34155,0.08101,0.04482
1.40000,1.36532,11.67508,11.67508,0.08339,0.03251
1.44000,1.77156,12.00827,12.00827,0.08577,0.04218
1.48000,1.61100,12.34170,12.34170,0.08816,0.03836
1.52000,1.95298,12.67497,12.67497,0.09054,0.04650
1.56000,2.06251,13.00829,13.00829,0.09292,0.04911
1.60000,1.39363,13.34169,13.34169,0.09530,0.03318
1.64000,1.43163,13.67498,13.67498,0.09768,0.03409
1.68000,1.84719,14.00841,14.00841,0.10006,0.04398
1.72000,1.40388,14.34152,14.34152,0.10244,0.03343
1.76000,1.48453,14.67508,14.67508,0.10482,0.03535
1.80000,1.54302,15.00827,15.00827,0.10720,0.03674
1.84000,1.62162,15.34167,15.34167,0.10958,0.03861
1.88000,1.72779,15.67494,15.67494,0.11196,0.04114
1.92000,1.38655,16.00829,16.00829,0.11434,0.03301
1.96000,1.58995,16.34169,16.34169,0.11673,0.03786
2.00000,1.84570,16.67496,16.67496,0.11911,0.04395
2.04000,1.79075,17.00841,17.00841,0.12149,0.04264
2.08000,2.02507,17.34147,17.34146,0.12387,0.04822
2.12000,2.02563,17.67505,17.67505,0.12625,0.04823
2.16000,1.42157,18.00824,18.00824,0.12863,0.03385
2.20000,1.86674,18.34178,18.34178,0.13101,0.04445
2.24000,1.71661,18.67497,18.67497,0.13339,0.04087
2.28000,2.02414,19.00831,19.00831,0.13577,0.04819
2.32000,1.88556,19.34169,19.34169,0.13815,0.04489
2.36000,1.69668,19.67490,19.67490,0.14054,0.04040
2.40000,1.79894,20.00847,20.00846,0.14292,0.04283
2.44000,1.32099,20.34154,20.34154,0.14530,0.03145
2.48000,1.48341,20.67505,20.67505,0.14768,0.03532
2.52000,1.80695,21.00824,21.00824,0.15006,0.04302
2.56000,1.91312,21.34170,21.34170,0.15244,0.04555
2.60000,2.09771,21.67496,21.67496,0.15482,0.04995
2.64000,1.69091,22.00828,22.00828,0.15720,0.04026
2.68000,1.93100,22.34166,22.34166,0.15958,0.04598
2.72000,1.80956,22.67487,22.67487,0.16196,0.04308
2.76000,1.32341,23.00844,23.00844,0.16435,0.03151
2.80000,1.96658,23.34162,23.34162,0.16673,0.04682
2.84000,1.71121,23.67511,23.67511,0.16911,0.04074
2.88000,1.65980,24.00821,24.00821,0.17149,0.03952
2.92000,1.23121,24.34172,24.34172,0.17387,0.02931
2.96000,1.28690,24.67502,24.67502,0.17625,0.03064
3.00000,1.32844,25.00831,25.00831,0.17863,0.03163
3.04000,1.28075,25.34171,25.34171,0.18101,0.03049
3.08000,1.41822,25.67485,25.67484,0.18339,0.03377
3.12000,0.89109,26.00833,26.00833,0.18577,0.02122
3.16000,1.46851,26.34162,26.34162,0.18815,0.03496
3.20000,1.55270,26.67508,26.67508,0.19054,0.03697
3.24000,1.58828,27.00821,27.00821,0.19292,0.03782
3.28000,1.26455,27.34167,27.34167,0.19530,0.03011
3.32000,1.45007,27.67496,27.67496,0.19768,0.03453
3.36000,1.49626,28.00839,28.00839,0.20006,0.03563
3.40000,1.29119,28.34171,28.34171,0.20244,0.03074
3.44000,1.39698,28.67492,28.67492,0.20482,0.03326
3.48000,1.58027,29.00843,29.00843,0.20720,0.03763
3.52000,1.47671,29.34157,29.34157,0.20958,0.03516
3.56000,1.33161,29.67513,29.67513,0.21197,0.03170
3.60000,1.33235,30.00824,30.00824,0.21434,0.03172
3.64000,1.57245,30.34166,30.34166,0.21673,0.03744
3.68000,1.61342,30.67496,30.67496,0.21911,0.03841
3.72000,1.45398,31.00831,31.00831,0.22149,0.03462
3.76000,1.47056,31.34166,31.34166,0.22387,0.03501
3.80000,1.53724,31.67487,31.67487,0.22625,0.03660
3.84000,1.20196,32.00840,32.00840,0.22863,0.02862
3.88000,1.36737,32.34159,32.34159,0.23101,0.03256
3.92000,1.62460,32.67516,32.67516,0.23339,0.03868
3.96000,1.57710,33.00826,33.00826,0.23577,0.03755
4.00000,1.33123,33.34172,33.34172,0.23816,0.03170
4.04000,1.52383,33.67498,33.67498,0.24054,0.03628
4.08000,1.82763,34.00831,34.00830,0.24292,0.04351
4.12000,1.72909,34.34168,34.34168,0.24530,0.04117
4.16000,1.53556,34.67495,34.67495,0.24768,0.03656
4.20000,1.75517,35.00843,35.00843,0.25006,0.04179
4.24000,1.56369,35.34156,35.34156,0.25244,0.03723
4.28000,1.67191,35.67502,35.67502,0.25482,0.03981
4.32000,1.69463,36.00826,36.00826,0.25720,0.04035
4.36000,1.56481,36.34169,36.34169,0.25958,0.03726
4.40000,1.81366,36.67493,36.67493,0.26196,0.04318
4.44000,2.14204,37.00833,37.00833,0.26435,0.05100
4.48000,1.85687,37.34170,37.34171,0.26673,0.04421
4.52000,1.67061,37.67497,37.67497,0.26911,0.03978
4.56000,1.88220,38.00843,38.00843,0.27149,0.04481
4.60000,1.76113,38.34154,38.34154,0.27387,0.04193
4.64000,1.69296,38.67505,38.67505,0.27625,0.04031
4.68000,1.70395,39.00826,39.00826,0.27863,0.04057
4.72000,1.56499,39.34174,39.34174,0.28101,0.03726
4.76000,1.89263,39.67493,39.67493,0.28339,0.04506
4.80000,1.73654,40.00831,40.00830,0.28577,0.04135
4.84000,2.00775,40.34168,40.34168,0.28815,0.04780
4.88000,1.64118,40.67494,40.67495,0.29054,0.03908
4.92000,1.60709,41.00840,41.00840,0.29292,0.03826
4.96000,1.81813,41.34156,41.34156,0.29530,0.04329
5.00000,2.06884,41.67507,41.67507,0.29768,0.04926
5.04000,1.99191,42.00820,42.00821,0.30006,0.04743
5.08000,2.16365,42.34177,42.34177,0.30244,0.05152
5.12000,2.34190,42.67495,42.67495,0.30482,0.05576
5.16000,2.51681,43.00827,43.00827,0.30720,0.05992
5.20000,2.41175,43.34170,43.34171,0.30958,0.05742
5.24000,2.07294,43.67494,43.67495,0.31196,0.04936
5.28000,2.26870,44.00845,44.00845,0.31435,0.05402
5.32000,2.29608,44.34156,44.34156,0.31673,0.05467
5.36000,2.21729,44.67507,44.67507,0.31911,0.05279
5.40000,2.45478,45.00826,45.00826,0.32149,0.05845
5.44000,2.32272,45.34171,45.34171,0.32387,0.05530
5.48000,2.49874,45.67500,45.67500,0.32625,0.05949
5.52000,2.45292,46.00833,46.00832,0.32863,0.05840
5.56000,2.42963,46.34167,46.34167,0.33101,0.05785
5.60000,2.62428,46.67492,46.67492,0.33339,0.06248
5.64000,2.43708,47.00837,47.00837,0.33577,0.05803
5.68000,2.40281,47.34156,47.34156,0.33815,0.05721
5.72000,2.85450,47.67512,47.67512,0.34054,0.06796
5.76000,2.95527,48.00823,48.00822,0.34292,0.07036
5.80000,2.38288,48.34166,48.34166,0.34530,0.05674
5.84000,2.78708,48.67500,48.67500,0.34768,0.06636
5.88000,2.95527,49.00833,49.00833,0.35006,0.07036
5.92000,2.62074,49.34167,49.34167,0.35244,0.06240
5.96000,2.54996,49.67491,49.67492,0.35482,0.06071
6.00000,2.99681,50.00840,50.00840,0.35720,0.07135
6.04000,2.91038,50.34161,50.34162,0.35958,0.06929
6.08000,2.94521,50.67509,50.67509,0.36196,0.07012
6.12000,2.83401,51.00823,51.00822,0.36434,0.06748
6.16000,3.23579,51.34165,51.34165,0.36673,0.07704
6.20000,3.18699,51.67495,51.67495,0.36911,0.07588
6.24000,3.06703,52.00835,52.00835,0.37149,0.07302
6.28000,3.05641,52.34172,52.34172,0.37387,0.07277
6.32000,3.10540,52.67489,52.67489,0.37625,0.07394
6.36000,3.01562,53.00839,53.00839,0.37863,0.07180
6.40000,2.88542,53.34155,53.34155,0.38101,0.06870
6.44000,2.76845,53.67512,53.67512,0.38339,0.06592
6.48000,2.97595,54.00828,54.00828,0.38577,0.07086
6.52000,3.21567,54.34168,54.34168,0.38815,0.07656
6.56000,3.57460,54.67497,54.67497,0.39054,0.08511
6.60000,3.21735,55.00835,55.00835,0.39292,0.07660
6.64000,3.35053,55.34169,55.34169,0.39530,0.07977
6.68000,3.41944,55.67491,55.67491,0.39768,0.08142
6.72000,3.60720,56.00842,56.00842,0.40006,0.08589
6.76000,3.56585,56.34153,56.34153,0.40244,0.08490
6.80000,3.71225,56.67507,56.67506,0.40482,0.08839
6.84000,3.59137,57.00828,57.00828,0.40720,0.08551
6.88000,3.87263,57.34171,57.34171,0.40958,0.09221
6.92000,4.01121,57.67495,57.67495,0.41196,0.09550
6.96000,3.39597,58.00829,58.00829,0.41434,0.08086
7.00000,3.68170,58.34175,58.34175,0.41673,0.08766
7.04000,3.82233,58.67497,58.67496,0.41911,0.09101
7.08000,4.20138,59.00842,59.00842,0.42149,0.10003
7.12000,3.71542,59.34161,59.34161,0.42387,0.08846
7.16000,4.11849,59.67501,59.67501,0.42625,0.09806
7.20000,4.35915,60.00825,60.00825,0.42863,0.10379
7.24000,4.05200,60.34176,60.34175,0.43101,0.09648
7.28000,4.39659,60.67497,60.67497,0.43339,0.10468
7.32000,4.31407,61.00829,61.00829,0.43577,0.10272
7.36000,4.48003,61.34167,61.34167,0.43815,0.10667
7.40000,4.71827,61.67491,61.67491,0.44054,0.11234
7.44000,4.48842,62.00842,62.00842,0.44292,0.10687
7.48000,4.27142,62.34153,62.34153,0.44530,0.10170
7.52000,4.24832,62.67506,62.67506,0.44768,0.10115
7.56000,4.17829,63.00824,63.00824,0.45006,0.09948
7.60000,3.93540,63.34173,63.34173,0.45244,0.09370
7.64000,4.35691,63.67503,63.67503,0.45482,0.10374
7.68000,4.33605,64.00829,64.00829,0.45720,0.10324
7.72000,4.35375,64.34167,64.34167,0.45958,0.10366
7.76000,4.43067,64.67496,64.67496,0.46196,0.10549
7.80000,4.48618,65.00844,65.00845,0.46435,0.10681
7.84000,4.26415,65.34152,65.34152,0.46673,0.10153
7.88000,4.29563,65.67508,65.67509,0.46911,0.10228
7.92000,4.41521,66.00819,66.00819,0.47149,0.10512
7.96000,4.37144,66.34170,66.34171,0.47387,0.10408
8.00000,4.24162,66.67497,66.67496,0.47625,0.10099
8.04000,4.65661,67.00829,67.00829,0.47863,0.11087
8.08000,4.82090,67.34172,67.34172,0.48101,0.11478
8.12000,4.63035,67.67493,67.67493,0.48339,0.11025
8.16000,4.60241,68.00842,68.00842,0.48577,0.10958
8.20000,4.68176,68.34155,68.34155,0.48815,0.11147
8.24000,4.82313,68.67508,68.67508,0.49054,0.11484
8.28000,4.92558,69.00827,69.00827,0.49292,0.11728
8.32000,4.71696,69.34173,69.34173,0.49530,0.11231
8.36000,4.51151,69.67496,69.67496,0.49768,0.10742
8.40000,4.52511,70.00834,70.00835,0.50006,0.10774
8.44000,5.16735,70.34169,70.34168,0.50244,0.12303
8.48000,4.92427,70.67488,70.67489,0.50482,0.11724
8.52000,4.86206,71.00842,71.00842,0.50720,0.11576
8.56000,4.90546,71.34160,71.34160,0.50958,0.11680
8.60000,4.94253,71.67508,71.67508,0.51196,0.11768
8.64000,4.81997,72.00824,72.00824,0.51434,0.11476
8.68000,4.41875,72.34167,72.34167,0.51673,0.10521
8.72000,4.15742,72.67496,72.67496,0.51911,0.09899
8.76000,4.33885,73.00834,73.00835,0.52149,0.10331
8.80000,4.70076,73.34169,73.34168,0.52387,0.11192
8.84000,4.57056,73.67493,73.67493,0.52625,0.10882
8.88000,4.45768,74.00842,74.00842,0.52863,0.10614
8.92000,4.57689,74.34160,74.34160,0.53101,0.10897
8.96000,4.67617,74.67511,74.67511,0.53339,0.11134
9.00000,4.77713,75.00824,75.00824,0.53577,0.11374
9.04000,4.73615,75.34173,75.34173,0.53816,0.11277
9.08000,4.34387,75.67494,75.67494,0.54054,0.10343
9.12000,4.30774,76.00834,76.00833,0.54292,0.10257
9.16000,4.78961,76.34174,76.34174,0.54530,0.11404
9.20000,4.59719,76.67485,76.67485,0.54768,0.10946
9.24000,4.49661,77.00842,77.00842,0.55006,0.10706
9.28000,4.76092,77.34158,77.34158,0.55244,0.11336
9.32000,4.84474,77.67511,77.67511,0.55482,0.11535
9.36000,4.51598,78.00824,78.00823,0.55720,0.10752
9.40000,4.83338,78.34167,78.34167,0.55958,0.11508
9.44000,5.01499,78.67496,78.67495,0.56196,0.11940
9.48000,5.00698,79.00832,79.00832,0.56435,0.11921
9.52000,5.21895,79.34174,79.34174,0.56673,0.12426
9.56000,5.27371,79.67496,79.67496,0.56911,0.12556
9.60000,5.49592,80.00841,80.00841,0.57149,0.13086
9.64000,5.51976,80.34154,80.34155,0.57387,0.13142
9.68000,5.04442,80.67507,80.67507,0.57625,0.12011
9.72000,4.85945,81.00827,81.00828,0.57863,0.11570
9.76000,5.36870,81.34175,81.34174,0.58101,0.12783
9.80000,5.33890,81.67499,81.67500,0.58339,0.12712
9.84000,5.31003,82.00826,82.00826,0.58577,0.12643
9.88000,5.55720,82.34168,82.34169,0.58815,0.13231
9.92000,5.28134,82.67497,82.67497,0.59054,0.12575
9.96000,5.05373,83.00838,83.00838,0.59292,0.12033
10.00000,5.28023,83.34158,83.34158,0.59530,0.12572
10.04000,5.56950,83.67507,83.67506,0.59768,0.13261
10.08000,5.06602,84.00827,84.00827,0.60006,0.12062
10.12000,5.03045,84.34177,84.34177,0.60244,0.11977
10.16000,5.26719,84.67499,84.67499,0.60482,0.12541
10.20000,4.86616,85.00831,85.00832,0.60720,0.11586
10.24000,5.12190,85.34163,85.34163,0.60958,0.12195
10.28000,5.42998,85.67495,85.67496,0.61196,0.12929
10.32000,5.15934,86.00846,86.00846,0.61435,0.12284
10.36000,5.34859,86.34156,86.34156,0.61673,0.12735
10.40000,5.21541,86.67502,86.67502,0.61911,0.12418
10.44000,5.19156,87.00823,87.00823,0.62149,0.12361
10.48000,5.34505,87.34169,87.34170,0.62387,0.12726
10.52000,5.32176,87.67496,87.67496,0.62625,0.12671
10.56000,5.50691,88.00833,88.00833,0.62863,0.13112
10.60000,5.31524,88.34171,88.34171,0.63101,0.12655
10.64000,5.10942,88.67492,88.67492,0.63339,0.12165
10.68000,5.43576,89.00849,89.00848,0.63577,0.12942
10.72000,5.44488,89.34156,89.34156,0.63815,0.12964
10.76000,6.02920,89.67507,89.67507,0.64054,0.14355
10.80000,6.04726,90.00823,90.00823,0.64292,0.14398
10.84000,6.39744,90.34172,90.34172,0.64530,0.15232
10.88000,6.42650,90.67498,90.67498,0.64768,0.15301
10.92000,6.55632,91.00831,91.00831,0.65006,0.15610
10.96000,6.90427,91.34168,91.34167,0.65244,0.16439
11.00000,6.78375,91.67487,91.67487,0.65482,0.16152
11.04000,6.92811,92.00838,92.00838,0.65720,0.16495
11.08000,6.58948,92.34162,92.34161,0.65958,0.15689
11.12000,6.95139,92.67510,92.67510,0.66197,0.16551
11.16000,7.05533,93.00823,93.00824,0.66434,0.16798
11.20000,7.15721,93.34171,93.34171,0.66673,0.17041
11.24000,6.61947,93.67493,93.67493,0.66911,0.15761
11.28000,6.77854,94.00836,94.00836,0.67149,0.16139
11.32000,7.23265,94.34173,94.34174,0.67387,0.17221
11.36000,7.13896,94.67492,94.67492,0.67625,0.16998
11.40000,6.95940,95.00838,95.00838,0.67863,0.16570
11.44000,6.64368,95.34156,95.34156,0.68101,0.15818
11.48000,7.16299,95.67510,95.67509,0.68339,0.17055
11.52000,6.90948,96.00823,96.00823,0.68577,0.16451
11.56000,7.47684,96.34169,96.34168,0.68815,0.17802
11.60000,7.77133,96.67495,96.67495,0.69054,0.18503
11.64000,7.68155,97.00833,97.00832,0.69292,0.18289
11.68000,7.87303,97.34168,97.34167,0.69530,0.18745
11.72000,7.23712,97.67492,97.67493,0.69768,0.17231
11.76000,7.29822,98.00837,98.00838,0.70006,0.17377
11.80000,7.33621,98.34156,98.34156,0.70244,0.17467
11.84000,7.42041,98.67518,98.67519,0.70482,0.17668
11.88000,7.77543,99.00826,99.00826,0.70720,0.18513
11.92000,7.27158,99.34171,99.34171,0.70958,0.17313
11.96000,7.41854,99.67495,99.67495,0.71196,0.17663
12.00000,7.04210,100.00831,100.00831,0.71435,0.16767
12.04000,7.63200,100.34176,100.34176,0.71673,0.18171
12.08000,7.07917,100.67492,100.67492,0.71911,0.16855
12.12000,7.53533,101.00840,101.00841,0.72149,0.17941
12.16000,7.46138,101.34156,101.34157,0.72387,0.17765
12.20000,7.26543,101.67507,101.67506,0.72625,0.17299
12.24000,7.59847,102.00821,102.00821,0.72863,0.18092
12.28000,7.31722,102.34169,102.34168,0.73101,0.17422
12.32000,7.21514,102.67498,102.67498,0.73339,0.17179
12.36000,7.62548,103.00836,103.00835,0.73577,0.18156
12.40000,7.24848,103.34175,103.34175,0.73816,0.17258
12.44000,7.21570,103.67495,103.67494,0.74054,0.17180
12.48000,7.68676,104.00843,104.00842,0.74292,0.18302
12.52000,7.73892,104.34156,104.34156,0.74530,0.18426
12.56000,7.82963,104.67506,104.67506,0.74768,0.18642
12.60000,7.67335,105.00828,105.00828,0.75006,0.18270
12.64000,7.56513,105.34170,105.34171,0.75244,0.18012
12.68000,7.48448,105.67495,105.67495,0.75482,0.17820
12.72000,7.89203,106.00830,106.00830,0.75720,0.18791
12.76000,7.84770,106.34165,106.34164,0.75958,0.18685
12.80000,7.71955,106.67491,106.67491,0.76196,0.18380
12.84000,7.80020,107.00842,107.00842,0.76435,0.18572
12.88000,7.70893,107.34155,107.34155,0.76673,0.18355
12.92000,7.91848,107.67506,107.67506,0.76911,0.18854
12.96000,7.49137,108.00822,108.00822,0.77149,0.17837
13.00000,7.33808,108.34176,108.34177,0.77387,0.17472
13.04000,7.81696,108.67500,108.67500,0.77625,0.18612
13.08000,7.72346,109.00832,109.00833,0.77863,0.18389
13.12000,7.56588,109.34173,109.34172,0.78101,0.18014
13.16000,7.84677,109.67494,109.67493,0.78339,0.18683
13.20000,7.77151,110.00845,110.00845,0.78577,0.18504
13.24000,7.83801,110.34158,110.34158,0.78815,0.18662
13.28000,7.86912,110.67498,110.67498,0.79054,0.18736
13.32000,7.95648,111.00823,111.00823,0.79292,0.18944
13.36000,8.28560,111.34173,111.34173,0.79530,0.19728
13.40000,7.81156,111.67499,111.67500,0.79768,0.18599
13.44000,7.57966,112.00830,112.00830,0.80006,0.18047
13.48000,7.60090,112.34167,112.34167,0.80244,0.18097
13.52000,8.16993,112.67492,112.67492,0.80482,0.19452
13.56000,7.97249,113.00844,113.00845,0.80720,0.18982
13.60000,7.96132,113.34158,113.34158,0.80958,0.18956
13.64000,7.77524,113.67512,113.67512,0.81197,0.18512
13.68000,7.96132,114.00825,114.00825,0.81434,0.18956
13.72000,8.02241,114.34171,114.34171,0.81673,0.19101
13.76000,7.83317,114.67500,114.67500,0.81911,0.18650
13.80000,7.76611,115.00829,115.00829,0.82149,0.18491
13.84000,7.83838,115.34170,115.34170,0.82387,0.18663
13.88000,7.76574,115.67494,115.67493,0.82625,0.18490
13.92000,8.07233,116.00837,116.00837,0.82863,0.19220
13.96000,8.00118,116.34158,116.34158,0.83101,0.19050
14.00000,7.99280,116.67510,116.67509,0.83339,0.19030
14.04000,7.80430,117.00820,117.00820,0.83577,0.18582
14.08000,7.56849,117.34168,117.34167,0.83815,0.18020
14.12000,7.59531,117.67498,117.67498,0.84054,0.18084
14.16000,7.88569,118.00838,118.00838,0.84292,0.18775
14.20000,8.00733,118.34174,118.34174,0.84530,0.19065
14.24000,7.96765,118.67494,118.67494,0.84768,0.18971
14.28000,8.28858,119.00836,119.00836,0.85006,0.19735
14.32000,7.97436,119.34155,119.34155,0.85244,0.18987
14.36000,7.85980,119.67514,119.67514,0.85482,0.18714
14.40000,7.93878,120.00827,120.00828,0.85720,0.18902
14.44000,7.68397,120.34170,120.34170,0.85958,0.18295
14.48000,8.03545,120.67492,120.67492,0.86196,0.19132
14.52000,8.13585,121.00836,121.00835,0.86435,0.19371
14.56000,8.35005,121.34170,121.34170,0.86673,0.19881
14.60000,8.16025,121.67491,121.67491,0.86911,0.19429
14.64000,7.78809,122.00838,122.00838,0.87149,0.18543
14.68000,8.10735,122.34153,122.34153,0.87387,0.19303
14.72000,8.28300,122.67511,122.67511,0.87625,0.19721
14.76000,8.15336,123.00827,123.00827,0.87863,0.19413
14.80000,8.36998,123.34168,123.34167,0.88101,0.19929
14.84000,8.07531,123.67497,123.67496,0.88339,0.19227
14.88000,8.09096,124.00832,124.00832,0.88577,0.19264
14.92000,8.20700,124.34174,124.34174,0.88816,0.19540
14.96000,7.92705,124.67494,124.67494,0.89054,0.18874
15.00000,8.26083,125.00844,125.00844,0.89292,0.19669
15.04000,7.88700,125.34155,125.34155,0.89530,0.18779
15.08000,7.88514,125.67506,125.67506,0.89768,0.18774
15.12000,8.21371,126.00827,126.00827,0.90006,0.19556
15.16000,7.99615,126.34172,126.34172,0.90244,0.19038
15.20000,8.13175,126.67495,126.67495,0.90482,0.19361
15.24000,8.33906,127.00832,127.00832,0.90720,0.19855
15.28000,8.43499,127.34170,127.34170,0.90958,0.20083
15.32000,8.54563,127.67488,127.67488,0.91196,0.20347
15.36000,8.44877,128.00845,128.00845,0.91435,0.20116
15.40000,8.21799,128.34161,128.34161,0.91673,0.19567
15.44000,8.45511,128.67511,128.67511,0.91911,0.20131
15.48000,8.39159,129.00827,129.00827,0.92149,0.19980
15.52000,8.19601,129.34173,129.34172,0.92387,0.19514
15.56000,8.05482,129.67499,129.67499,0.92625,0.19178
15.60000,8.16286,130.00832,130.00832,0.92863,0.19435
15.64000,8.07829,130.34166,130.34166,0.93101,0.19234
15.68000,8.59331,130.67497,130.67497,0.93339,0.20460
15.72000,8.68216,131.00844,131.00844,0.93577,0.20672
15.76000,9.05059,131.34155,131.34155,0.93815,0.21549
15.80000,8.57227,131.67506,131.67506,0.94054,0.20410
15.84000,8.65273,132.00816,132.00815,0.94292,0.20602
15.88000,8.88128,132.34172,132.34172,0.94530,0.21146
15.92000,8.82447,132.67501,132.67502,0.94768,0.21011
15.96000,8.43853,133.00829,133.00829,0.95006,0.20092
16.00000,8.43257,133.34172,133.34172,0.95244,0.20078
16.04000,8.90400,133.67496,133.67496,0.95482,0.21200
16.08000,8.62498,134.00845,134.00845,0.95720,0.20536
16.12000,8.54731,134.34161,134.34161,0.95958,0.20351
16.16000,9.05618,134.67508,134.67508,0.96196,0.21562
16.20000,9.07797,135.00824,135.00824,0.96434,0.21614
16.24000,8.47802,135.34173,135.34172,0.96673,0.20186
16.28000,8.85110,135.67499,135.67499,0.96911,0.21074
16.32000,9.01259,136.00828,136.00829,0.97149,0.21459
16.36000,9.00794,136.34166,136.34166,0.97387,0.21447
16.40000,8.76114,136.67488,136.67488,0.97625,0.20860
16.44000,8.94684,137.00844,137.00844,0.97863,0.21302
16.48000,9.19867,137.34156,137.34157,0.98101,0.21902
16.52000,8.96398,137.67509,137.67508,0.98339,0.21343
16.56000,9.30429,138.00827,138.00827,0.98577,0.22153
16.60000,9.00496,138.34171,138.34171,0.98816,0.21440
16.64000,8.84123,138.67501,138.67500,0.99054,0.21051
16.68000,8.92822,139.00837,139.00836,0.99292,0.21258
16.72000,8.93380,139.34172,139.34172,0.99530,0.21271
16.76000,9.28212,139.67495,139.67494,0.99768,0.22100
16.80000,8.99583,140.00841,140.00841,1.00006,0.21419
16.84000,9.09735,140.34157,140.34157,1.00244,0.21660
16.88000,9.07853,140.67511,140.67511,1.00482,0.21616
16.92000,9.25828,141.00820,141.00819,1.00720,0.22044
16.96000,9.17353,141.34166,141.34164,1.00958,0.21842
17.00000,9.65819,141.67491,141.67490,1.01196,0.22996
17.04000,9.20482,142.00831,142.00830,1.01435,0.21916
17.08000,9.50098,142.34174,142.34174,1.01673,0.22621
17.12000,9.30186,142.67493,142.67493,1.01911,0.22147
17.16000,8.98466,143.00840,143.00839,1.02149,0.21392
17.20000,9.77516,143.34159,143.34158,1.02387,0.23274
17.24000,9.61088,143.67512,143.67511,1.02625,0.22883
17.28000,9.40468,144.00828,144.00829,1.02863,0.22392
17.32000,9.67178,144.34169,144.34169,1.03101,0.23028
17.36000,9.32068,144.67488,144.67488,1.03339,0.22192
17.40000,9.71090,145.00836,145.00836,1.03577,0.23121
17.44000,10.20916,145.34173,145.34174,1.03816,0.24308
17.48000,9.57306,145.67492,145.67491,1.04054,0.22793
17.52000,9.55351,146.00838,146.00838,1.04292,0.22746
17.56000,9.79286,146.34151,146.34151,1.04530,0.23316
17.60000,9.65390,146.67508,146.67509,1.04768,0.22985
17.64000,9.41698,147.00829,147.00829,1.05006,0.22421
17.68000,9.26927,147.34172,147.34172,1.05244,0.22070
17.72000,9.73716,147.67502,147.67502,1.05482,0.23184
17.76000,9.93013,148.00828,148.00829,1.05720,0.23643
17.80000,9.68520,148.34177,148.34177,1.05958,0.23060
17.84000,9.48608,148.67498,148.67497,1.06196,0.22586
17.88000,9.81223,149.00839,149.00839,1.06435,0.23362
17.92000,9.76827,149.34159,149.34158,1.06673,0.23258
17.96000,9.67719,149.67508,149.67508,1.06911,0.23041
18.00000,9.81875,150.00824,150.00824,1.07149,0.23378
18.04000,9.76250,150.34174,150.34175,1.07387,0.23244
18.08000,9.93498,150.67500,150.67499,1.07625,0.23655
18.12000,9.96459,151.00829,151.00829,1.07863,0.23725
18.16000,10.02531,151.34168,151.34167,1.08101,0.23870
18.20000,10.13875,151.67494,151.67494,1.08339,0.24140
18.24000,10.27286,152.00843,152.00844,1.08577,0.24459
18.28000,9.91710,152.34157,152.34157,1.08815,0.23612
18.32000,9.98098,152.67506,152.67505,1.09054,0.23764
18.36000,9.93237,153.00820,153.00818,1.09292,0.23648
18.40000,10.25815,153.34176,153.34177,1.09530,0.24424
18.44000,10.48278,153.67501,153.67502,1.09768,0.24959
18.48000,9.97316,154.00836,154.00838,1.10006,0.23746
18.52000,10.20543,154.34165,154.34164,1.10244,0.24299
18.56000,10.26504,154.67492,154.67493,1.10482,0.24441
18.60000,10.09032,155.00846,155.00847,1.10720,0.24025
18.64000,9.93758,155.34155,155.34155,1.10958,0.23661
18.68000,9.88357,155.67511,155.67511,1.11197,0.23532
18.72000,9.99309,156.00823,156.00822,1.11434,0.23793
18.76000,10.42951,156.34170,156.34169,1.11673,0.24832
18.80000,10.35593,156.67501,156.67502,1.11911,0.24657
18.84000,10.32967,157.00830,157.00830,1.12149,0.24594
18.88000,10.35146,157.34168,157.34167,1.12387,0.24646
18.92000,10.36990,157.67492,157.67491,1.12625,0.24690
18.96000,10.38611,158.00843,158.00842,1.12863,0.24729
19.00000,10.36786,158.34159,158.34158,1.13101,0.24685
19.04000,10.37922,158.67506,158.67506,1.13339,0.24712
19.08000,10.16315,159.00826,159.00827,1.13577,0.24198
19.12000,10.39747,159.34171,159.34171,1.13816,0.24756
19.16000,10.67463,159.67501,159.67502,1.14054,0.25416
19.20000,10.16743,160.00834,160.00833,1.14292,0.24208
19.24000,10.69251,160.34170,160.34171,1.14530,0.25458
19.28000,10.65042,160.67490,160.67491,1.14768,0.25358
19.32000,10.76981,161.00842,161.00842,1.15006,0.25642
19.36000,10.96483,161.34156,161.34155,1.15244,0.26107
19.40000,10.81992,161.67502,161.67502,1.15482,0.25762
19.44000,10.61354,162.00828,162.00829,1.15720,0.25270
19.48000,11.07343,162.34170,162.34171,1.15958,0.26365
19.52000,10.78006,162.67498,162.67499,1.16196,0.25667
19.56000,10.93987,163.00835,163.00835,1.16435,0.26047
19.60000,11.19655,163.34170,163.34171,1.16673,0.26658
19.64000,11.09317,163.67494,163.67494,1.16911,0.26412
19.68000,11.01140,164.00843,164.00842,1.17149,0.26218
19.72000,10.91640,164.34159,164.34158,1.17387,0.25991
19.76000,11.24814,164.67515,164.67516,1.17625,0.26781
19.80000,11.14123,165.00825,165.00826,1.17863,0.26527
19.84000,11.10286,165.34171,165.34169,1.18101,0.26435
19.88000,11.16842,165.67492,165.67493,1.18339,0.26591
19.92000,10.83780,166.00830,166.00830,1.18577,0.25804
19.96000,11.37555,166.34176,166.34177,1.18816,0.27085
20.00000,11.52735,166.67492,166.67493,1.19054,0.27446
20.04000,11.41317,167.00834,167.00835,1.19292,0.27174
20.08000,11.02295,167.34156,167.34157,1.19530,0.26245
20.12000,11.00209,167.67512,167.67513,1.19768,0.26195
20.16000,11.00823,168.00823,168.00822,1.20006,0.26210
20.20000,11.09522,168.34177,168.34177,1.20244,0.26417
20.24000,11.43273,168.67499,168.67499,1.20482,0.27221
20.28000,11.60428,169.00835,169.00833,1.20720,0.27629
20.32000,11.74677,169.34176,169.34175,1.20958,0.27969
20.36000,11.58714,169.67494,169.67494,1.21196,0.27588
20.40000,11.48507,170.00836,170.00836,1.21435,0.27345
20.44000,11.16376,170.34156,170.34157,1.21673,0.26580
20.48000,11.65960,170.67509,170.67509,1.21911,0.27761
20.52000,11.47203,171.00831,171.00833,1.22149,0.27314
20.56000,11.42826,171.34168,171.34169,1.22387,0.27210
20.60000,11.56032,171.67495,171.67494,1.22625,0.27525
20.64000,11.61862,172.00824,172.00824,1.22863,0.27663
20.68000,11.63185,172.34163,172.34163,1.23101,0.27695
20.72000,11.53667,172.67499,172.67497,1.23339,0.27468
20.76000,11.73243,173.00847,173.00845,1.23577,0.27934
20.80000,11.72330,173.34158,173.34158,1.23815,0.27913
20.84000,11.91404,173.67515,173.67516,1.24054,0.28367
20.88000,12.24745,174.00827,174.00827,1.24292,0.29161
20.92000,12.07143,174.34177,174.34178,1.24530,0.28742
20.96000,12.39125,174.67497,174.67497,1.24768,0.29503
21.00000,12.32792,175.00832,175.00833,1.25006,0.29352
21.04000,12.34543,175.34168,175.34167,1.25244,0.29394
21.08000,12.42738,175.67490,175.67490,1.25482,0.29589
21.12000,12.37541,176.00843,176.00844,1.25720,0.29465
21.16000,12.43502,176.34152,176.34152,1.25958,0.29607
21.20000,12.06044,176.67503,176.67503,1.26196,0.28715
21.24000,12.50040,177.00822,177.00822,1.26434,0.29763
21.28000,12.23516,177.34175,177.34175,1.26673,0.29131
21.32000,12.29998,177.67500,177.67500,1.26911,0.29286
21.36000,12.14687,178.00837,178.00836,1.27149,0.28921
21.40000,12.57136,178.34167,178.34167,1.27387,0.29932
21.44000,12.50412,178.67491,178.67490,1.27625,0.29772
21.48000,12.50599,179.00852,179.00853,1.27863,0.29776
21.52000,12.29066,179.34161,179.34161,1.28101,0.29263
21.56000,12.45141,179.67511,179.67511,1.28339,0.29646
21.60000,12.70343,180.00823,180.00822,1.28577,0.30246
21.64000,12.63637,180.34167,180.34167,1.28815,0.30087
21.68000,12.71740,180.67499,180.67499,1.29054,0.30280
21.72000,12.85244,181.00828,181.00829,1.29292,0.30601
21.76000,12.32885,181.34168,181.34169,1.29530,0.29354
21.80000,12.57490,181.67488,181.67488,1.29768,0.29940
21.84000,12.35418,182.00843,182.00842,1.30006,0.29415
21.88000,12.64047,182.34165,182.34166,1.30244,0.30096
21.92000,12.71367,182.67511,182.67511,1.30482,0.30271
21.96000,12.60769,183.00825,183.00824,1.30720,0.30018
22.00000,12.90161,183.34175,183.34175,1.30958,0.30718
22.04000,13.20317,183.67502,183.67500,1.31196,0.31436
22.08000,12.91856,184.00833,184.00835,1.31435,0.30758
22.12000,13.01263,184.34172,184.34172,1.31673,0.30982
22.16000,13.07353,184.67492,184.67493,1.31911,0.31127
22.20000,13.42744,185.00838,185.00836,1.32149,0.31970
22.24000,12.96066,185.34158,185.34158,1.32387,0.30859
22.28000,12.89025,185.67508,185.67508,1.32625,0.30691
22.32000,13.21714,186.00824,186.00826,1.32863,0.31469
22.36000,13.05081,186.34170,186.34171,1.33101,0.31073
22.40000,13.30506,186.67495,186.67496,1.33339,0.31679
22.44000,13.58800,187.00832,187.00832,1.33577,0.32352
22.48000,13.16834,187.34174,187.34174,1.33816,0.31353
22.52000,13.18492,187.67494,187.67494,1.34054,0.31393
22.56000,13.46804,188.00844,188.00844,1.34292,0.32067
22.60000,13.58893,188.34155,188.34155,1.34530,0.32355
22.64000,14.08029,188.67515,188.67516,1.34768,0.33525
22.68000,13.68467,189.00827,189.00826,1.35006,0.32583
22.72000,13.68783,189.34171,189.34171,1.35244,0.32590
22.76000,13.65952,189.67497,189.67497,1.35482,0.32523
22.80000,13.70329,190.00829,190.00829,1.35720,0.32627
22.84000,13.93501,190.34172,190.34172,1.35958,0.33179
22.88000,13.67088,190.67492,190.67493,1.36196,0.32550
22.92000,13.43098,191.00838,191.00838,1.36435,0.31979
22.96000,13.88416,191.34154,191.34154,1.36673,0.33058
23.00000,13.46935,191.67510,191.67511,1.36911,0.32070
23.04000,13.68262,192.00826,192.00827,1.37149,0.32578
23.08000,13.98958,192.34172,192.34172,1.37387,0.33309
23.12000,13.99945,192.67496,192.67497,1.37625,0.33332
23.16000,14.23340,193.00832,193.00832,1.37863,0.33889
23.20000,14.04211,193.34174,193.34174,1.38101,0.33434
23.24000,14.23620,193.67496,193.67496,1.38339,0.33896
23.28000,14.36360,194.00844,194.00845,1.38577,0.34199
23.32000,13.93054,194.34156,194.34155,1.38815,0.33168
23.36000,13.94991,194.67506,194.67505,1.39054,0.33214
23.40000,14.17249,195.00832,195.00832,1.39292,0.33744
23.44000,14.14213,195.34167,195.34166,1.39530,0.33672
23.48000,13.84187,195.67493,195.67491,1.39768,0.32957
23.52000,14.23173,196.00834,196.00833,1.40006,0.33885
23.56000,14.39173,196.34169,196.34169,1.40244,0.34266
23.60000,14.18404,196.67496,196.67496,1.40482,0.33772
23.64000,14.42693,197.00840,197.00839,1.40720,0.34350
23.68000,14.35205,197.34154,197.34154,1.40958,0.34172
23.72000,14.88868,197.67510,197.67511,1.41197,0.35449
23.76000,14.50125,198.00824,198.00824,1.41434,0.34527
23.80000,14.59680,198.34178,198.34178,1.41673,0.34754
23.84000,14.94996,198.67501,198.67502,1.41911,0.35595
23.88000,14.82125,199.00830,199.00830,1.42149,0.35289
23.92000,14.60146,199.34167,199.34167,1.42387,0.34765
23.96000,14.72123,199.67492,199.67493,1.42625,0.35051
24.00000,14.52621,200.00844,200.00844,1.42863,0.34586
24.04000,14.53869,200.34160,200.34160,1.43101,0.34616
24.08000,14.57073,200.67508,200.67508,1.43339,0.34692
24.12000,14.65045,201.00820,201.00821,1.43577,0.34882
24.16000,14.70726,201.34174,201.34174,1.43816,0.35017
24.20000,14.80114,201.67497,201.67499,1.44054,0.35241
24.24000,14.77245,202.00831,202.00832,1.44292,0.35173
24.28000,14.71993,202.34172,202.34172,1.44530,0.35047
24.32000,15.01590,202.67490,202.67491,1.44768,0.35752
24.36000,15.33590,203.00847,203.00847,1.45006,0.36514
24.40000,15.19267,203.34163,203.34164,1.45244,0.36173
24.44000,15.51528,203.67510,203.67511,1.45482,0.36941
24.48000,15.32845,204.00821,204.00821,1.45720,0.36496
24.52000,15.12114,204.34168,204.34167,1.45958,0.36003
24.56000,15.12431,204.67501,204.67502,1.46196,0.36010
24.60000,15.11816,205.00837,205.00836,1.46435,0.35996
24.64000,15.46424,205.34166,205.34166,1.46673,0.36820
24.68000,15.59313,205.67492,205.67493,1.46911,0.37127
24.72000,14.87825,206.00838,206.00838,1.47149,0.35424
24.76000,15.32771,206.34156,206.34155,1.47387,0.36495
24.80000,15.55830,206.67511,206.67511,1.47625,0.37044
24.84000,15.51230,207.00824,207.00824,1.47863,0.36934
24.88000,15.63672,207.34172,207.34172,1.48101,0.37230
24.92000,15.33516,207.67501,207.67502,1.48339,0.36512
24.96000,15.83248,208.00836,208.00836,1.48577,0.37696
25.00000,15.76841,208.34174,208.34175,1.48816,0.37544
25.04000,15.88613,208.67494,208.67493,1.49054,0.37824
25.08000,16.01521,209.00840,209.00841,1.49292,0.38131
25.12000,15.61884,209.34156,209.34157,1.49530,0.37188
25.16000,15.62573,209.67510,209.67511,1.49768,0.37204
25.20000,16.02843,210.00826,210.00826,1.50006,0.38163
25.24000,16.00981,210.34172,210.34174,1.50244,0.38119
25.28000,15.79076,210.67493,210.67493,1.50482,0.37597
25.32000,15.63821,211.00837,211.00836,1.50720,0.37234
25.36000,15.85912,211.34174,211.34174,1.50958,0.37760
25.40000,15.60375,211.67490,211.67491,1.51196,0.37152
25.44000,16.11728,212.00842,212.00842,1.51435,0.38374
25.48000,15.82801,212.34152,212.34151,1.51673,0.37686
25.52000,15.84888,212.67512,212.67514,1.51911,0.37735
25.56000,15.93493,213.00831,213.00830,1.52149,0.37940
25.60000,16.02601,213.34174,213.34175,1.52387,0.38157
25.64000,15.59239,213.67499,213.67497,1.52625,0.37125
25.68000,15.96920,214.00830,214.00832,1.52863,0.38022
25.72000,16.18806,214.34173,214.34172,1.53101,0.38543
25.76000,16.00254,214.67494,214.67494,1.53339,0.38101
25.80000,16.09102,215.00840,215.00842,1.53577,0.38312
25.84000,15.94480,215.34154,215.34155,1.53815,0.37964
25.88000,15.88296,215.67510,215.67509,1.54054,0.37817
25.92000,16.39239,216.00826,216.00826,1.54292,0.39030
25.96000,16.67663,216.34175,216.34175,1.54530,0.39706
26.00000,16.43226,216.67493,216.67493,1.54768,0.39124
26.04000,16.26387,217.00828,217.00827,1.55006,0.38724
26.08000,16.20576,217.34176,217.34177,1.55244,0.38585
26.12000,16.40618,217.67496,217.67496,1.55482,0.39062
26.16000,16.06047,218.00840,218.00839,1.55720,0.38239
26.20000,16.37582,218.34161,218.34161,1.55958,0.38990
26.24000,16.18527,218.67507,218.67506,1.56196,0.38536
26.28000,16.02396,219.00827,219.00827,1.56434,0.38152
26.32000,16.34993,219.34174,219.34174,1.56673,0.38928
26.36000,16.41829,219.67495,219.67496,1.56911,0.39091
26.40000,16.42685,220.00830,220.00830,1.57149,0.39112
26.44000,16.46597,220.34164,220.34164,1.57387,0.39205
26.48000,16.15658,220.67490,220.67490,1.57625,0.38468
26.52000,16.14671,221.00840,221.00841,1.57863,0.38445
26.56000,16.66714,221.34156,221.34157,1.58101,0.39684
26.60000,16.69824,221.67506,221.67506,1.58339,0.39758
26.64000,16.47733,222.00825,222.00824,1.58577,0.39232
26.68000,16.65689,222.34172,222.34172,1.58816,0.39659
26.72000,16.62467,222.67501,222.67500,1.59054,0.39583
26.76000,16.35458,223.00830,223.00830,1.59292,0.38939
26.80000,16.70737,223.34170,223.34169,1.59530,0.39779
26.84000,16.49000,223.67496,223.67496,1.59768,0.39262
26.88000,16.55184,224.00843,224.00844,1.60006,0.39409
26.92000,16.61014,224.34154,224.34154,1.60244,0.39548
26.96000,16.25307,224.67507,224.67506,1.60482,0.38698
27.00000,16.24841,225.00817,225.00818,1.60720,0.38687
27.04000,16.13609,225.34170,225.34171,1.60958,0.38419
27.08000,16.25866,225.67499,225.67499,1.61196,0.38711
27.12000,16.38699,226.00836,226.00836,1.61435,0.39017
27.16000,16.21079,226.34170,226.34171,1.61673,0.38597
27.20000,16.15956,226.67489,226.67488,1.61911,0.38475
27.24000,16.46858,227.00844,227.00844,1.62149,0.39211
27.28000,16.16869,227.34160,227.34160,1.62387,0.38497
27.32000,15.98559,227.67510,227.67509,1.62625,0.38061
27.36000,16.11505,228.00826,228.00826,1.62863,0.38369
27.40000,15.93828,228.34168,228.34167,1.63101,0.37948
27.44000,16.22383,228.67497,228.67497,1.63339,0.38628
27.48000,15.73004,229.00837,229.00836,1.63577,0.37452
27.52000,15.87737,229.34163,229.34163,1.63815,0.37803
27.56000,16.34732,229.67489,229.67490,1.64053,0.38922
27.60000,16.04669,230.00839,230.00839,1.64292,0.38206
27.64000,15.61008,230.34158,230.34158,1.64530,0.37167
27.68000,16.02322,230.67511,230.67511,1.64768,0.38151
27.72000,15.56948,231.00824,231.00824,1.65006,0.37070
27.76000,15.72110,231.34169,231.34169,1.65244,0.37431
27.80000,15.65348,231.67495,231.67496,1.65482,0.37270
27.84000,16.23202,232.00832,232.00832,1.65720,0.38648
27.88000,16.13274,232.34171,232.34172,1.65958,0.38411
27.92000,16.40115,232.67490,232.67490,1.66196,0.39050
27.96000,16.26872,233.00840,233.00839,1.66435,0.38735
28.00000,16.30541,233.34159,233.34158,1.66673,0.38822
28.04000,16.28399,233.67509,233.67508,1.66911,0.38771
28.08000,15.82652,234.00825,234.00824,1.67149,0.37682
28.12000,16.35626,234.34174,234.34175,1.67387,0.38943
28.16000,16.19589,234.67493,234.67493,1.67625,0.38562
28.20000,15.84329,235.00830,235.00830,1.67863,0.37722
28.24000,16.26834,235.34177,235.34177,1.68101,0.38734
28.28000,16.60101,235.67488,235.67488,1.68339,0.39526
28.32000,16.24711,236.00838,236.00838,1.68577,0.38684
28.36000,16.40376,236.34154,236.34154,1.68815,0.39057
28.40000,16.91133,236.67507,236.67506,1.69054,0.40265
28.44000,16.30411,237.00828,237.00827,1.69292,0.38819
28.48000,16.59468,237.34172,237.34172,1.69530,0.39511
28.52000,16.56860,237.67494,237.67494,1.69768,0.39449
28.56000,16.88041,238.00828,238.00829,1.70006,0.40191
28.60000,17.47496,238.34173,238.34172,1.70244,0.41607
28.64000,16.63081,238.67499,238.67499,1.70482,0.39597
28.68000,16.67961,239.00841,239.00841,1.70720,0.39713
28.72000,17.00073,239.34149,239.34149,1.70958,0.40478
28.76000,16.94784,239.67505,239.67505,1.71196,0.40352
28.80000,17.13969,240.00826,240.00826,1.71434,0.40809
28.84000,16.87985,240.34170,240.34171,1.71673,0.40190
28.88000,17.01340,240.67497,240.67497,1.71911,0.40508
28.92000,17.25759,241.00829,241.00829,1.72149,0.41090
28.96000,17.26653,241.34168,241.34167,1.72387,0.41111
29.00000,17.39059,241.67494,241.67494,1.72625,0.41406
29.04000,17.16372,242.00839,242.00839,1.72863,0.40866
29.08000,17.69494,242.34155,242.34155,1.73101,0.42131
29.12000,17.70239,242.67510,242.67511,1.73339,0.42149
29.16000,17.28162,243.00826,243.00827,1.73577,0.41147
29.20000,17.32279,243.34176,243.34177,1.73816,0.41245
29.24000,17.62211,243.67500,243.67500,1.74054,0.41957
29.28000,17.47422,244.00832,244.00832,1.74292,0.41605
29.32000,17.21270,244.34166,244.34166,1.74530,0.40983
29.36000,17.32670,244.67490,244.67490,1.74768,0.41254
29.40000,17.26840,245.00848,245.00847,1.75006,0.41115
29.44000,17.44609,245.34156,245.34155,1.75244,0.41538
29.48000,17.23841,245.67508,245.67508,1.75482,0.41044
29.52000,17.64484,246.00824,246.00824,1.75720,0.42012
29.56000,17.74672,246.34166,246.34166,1.75958,0.42254
29.60000,17.49899,246.67501,246.67500,1.76196,0.41664
29.64000,17.82216,247.00832,247.00833,1.76435,0.42434
29.68000,18.01588,247.34169,247.34169,1.76673,0.42895
29.72000,18.36028,247.67490,247.67491,1.76911,0.43715
29.76000,18.21332,248.00843,248.00842,1.77149,0.43365
29.80000,17.95758,248.34159,248.34158,1.77387,0.42756
29.84000,17.71096,248.67512,248.67511,1.77625,0.42169
29.88000,17.97993,249.00822,249.00822,1.77863,0.42809
29.92000,18.02091,249.34170,249.34169,1.78101,0.42907
29.96000,17.98440,249.67496,249.67496,1.78339,0.42820
30.00000,17.87245,250.00830,250.00830,1.78577,0.42553
30.04000,17.86314,250.34170,250.34171,1.78815,0.42531
30.08000,18.20195,250.67488,250.67488,1.79053,0.43338
30.12000,18.29751,251.00841,251.00841,1.79292,0.43565
30.16000,18.51786,251.34162,251.34163,1.79530,0.44090
30.20000,18.44782,251.67504,251.67505,1.79768,0.43923
30.24000,18.64135,252.00820,252.00821,1.80006,0.44384
30.28000,18.61565,252.34175,252.34175,1.80244,0.44323
30.32000,18.82408,252.67497,252.67497,1.80482,0.44819
30.36000,18.48061,253.00839,253.00839,1.80720,0.44001
30.40000,18.63800,253.34170,253.34171,1.80958,0.44376
30.44000,18.27832,253.67492,253.67491,1.81196,0.43520
30.48000,18.23176,254.00842,254.00842,1.81435,0.43409
30.52000,18.60969,254.34158,254.34158,1.81673,0.44309
30.56000,18.45229,254.67508,254.67508,1.81911,0.43934
30.60000,18.62478,255.00821,255.00821,1.82149,0.44345
30.64000,18.81514,255.34168,255.34169,1.82387,0.44798
30.68000,19.14930,255.67500,255.67500,1.82625,0.45594
30.72000,19.08522,256.00832,256.00830,1.82863,0.45441
30.76000,19.03865,256.34168,256.34167,1.83101,0.45330
30.80000,19.54194,256.67492,256.67493,1.83339,0.46528
30.84000,19.36033,257.00840,257.00839,1.83577,0.46096
30.88000,19.50208,257.34158,257.34158,1.83815,0.46434
30.92000,19.59857,257.67513,257.67514,1.84054,0.46663
30.96000,19.24019,258.00824,258.00824,1.84292,0.45810
31.00000,18.72666,258.34169,258.34167,1.84530,0.44587
31.04000,19.00457,258.67495,258.67496,1.84768,0.45249
31.08000,19.58236,259.00827,259.00827,1.85006,0.46625
31.12000,19.01314,259.34177,259.34177,1.85244,0.45269
31.16000,19.10441,259.67488,259.67487,1.85482,0.45487
31.20000,19.13123,260.00838,260.00836,1.85720,0.45551
31.24000,19.30632,260.34154,260.34152,1.85958,0.45967
31.28000,19.30296,260.67509,260.67508,1.86196,0.45959
31.32000,19.78986,261.00830,261.00830,1.86434,0.47119
31.36000,19.93496,261.34172,261.34174,1.86673,0.47464
31.40000,19.91242,261.67493,261.67493,1.86911,0.47411
31.44000,19.81203,262.00833,262.00833,1.87149,0.47171
31.48000,19.80644,262.34172,262.34174,1.87387,0.47158
31.52000,19.89063,262.67496,262.67496,1.87625,0.47359
31.56000,19.72914,263.00841,263.00842,1.87863,0.46974
31.60000,19.93738,263.34146,263.34146,1.88101,0.47470
31.64000,19.99680,263.67509,263.67508,1.88339,0.47611
31.68000,19.98879,264.00831,264.00830,1.88577,0.47592
31.72000,19.80681,264.34175,264.34177,1.88816,0.47159
31.76000,19.55293,264.67497,264.67496,1.89054,0.46555
31.80000,19.71573,265.00828,265.00827,1.89292,0.46942
31.84000,20.14432,265.34168,265.34167,1.89530,0.47963
31.88000,20.20821,265.67497,265.67496,1.89768,0.48115
31.92000,20.02791,266.00841,266.00842,1.90006,0.47685
31.96000,20.59899,266.34157,266.34158,1.90244,0.49045
32.00000,20.40043,266.67505,266.67505,1.90482,0.48572
32.04000,20.17412,267.00821,267.00821,1.90720,0.48034
32.08000,20.21957,267.34173,267.34174,1.90958,0.48142
32.12000,20.43005,267.67497,267.67496,1.91196,0.48643
32.16000,20.15382,268.00834,268.00833,1.91435,0.47985
32.20000,20.24714,268.34171,268.34171,1.91673,0.48207
32.24000,20.01058,268.67490,268.67490,1.91911,0.47644
32.28000,20.04001,269.00845,269.00845,1.92149,0.47714
32.32000,19.85580,269.34161,269.34161,1.92387,0.47276
32.36000,19.69431,269.67505,269.67505,1.92625,0.46891
32.40000,19.60285,270.00824,270.00824,1.92863,0.46673
32.44000,20.36188,270.34171,270.34171,1.93101,0.48481
32.48000,20.82940,270.67500,270.67502,1.93339,0.49594
32.52000,20.63941,271.00835,271.00833,1.93577,0.49141
32.56000,20.80556,271.34169,271.34167,1.93815,0.49537
32.60000,20.75117,271.67485,271.67484,1.94053,0.49408
32.64000,20.95774,272.00837,272.00836,1.94292,0.49899
32.68000,20.90111,272.34159,272.34158,1.94530,0.49765
32.72000,21.13264,272.67514,272.67514,1.94768,0.50316
32.76000,20.73050,273.00825,273.00824,1.95006,0.49358
32.80000,20.36244,273.34167,273.34167,1.95244,0.48482
32.84000,20.56547,273.67501,273.67502,1.95482,0.48965
32.88000,20.26167,274.00833,274.00833,1.95720,0.48242
32.92000,20.57645,274.34170,274.34171,1.95958,0.48992
32.96000,20.68263,274.67493,274.67493,1.96196,0.49244
33.00000,20.59806,275.00838,275.00839,1.96435,0.49043
33.04000,20.56360,275.34162,275.34161,1.96673,0.48961
33.08000,20.78377,275.67509,275.67508,1.96911,0.49485
33.12000,21.08496,276.00820,276.00821,1.97149,0.50202
33.16000,21.16319,276.34173,276.34174,1.97387,0.50389
33.20000,21.10843,276.67494,276.67493,1.97625,0.50258
33.24000,21.40906,277.00833,277.00833,1.97863,0.50974
33.28000,21.35336,277.34168,277.34167,1.98101,0.50841
33.32000,21.02740,277.67491,277.67493,1.98339,0.50065
33.36000,21.51690,278.00839,278.00839,1.98577,0.51231
33.40000,20.59676,278.34155,278.34155,1.98815,0.49040
33.44000,20.93818,278.67510,278.67511,1.99054,0.49853
33.48000,20.89366,279.00831,279.00830,1.99292,0.49747
33.52000,21.05255,279.34171,279.34171,1.99530,0.50125
33.56000,20.91862,279.67500,279.67499,1.99768,0.49806
33.60000,21.04696,280.00834,280.00833,2.00006,0.50112
33.64000,21.48468,280.34166,280.34164,2.00244,0.51154
33.68000,21.22167,280.67497,280.67496,2.00482,0.50528
33.72000,21.30922,281.00844,281.00845,2.00720,0.50736
33.76000,21.89670,281.34155,281.34155,2.00958,0.52135
33.80000,21.75197,281.67505,281.67502,2.01196,0.51790
33.84000,21.96413,282.00824,282.00821,2.01434,0.52296
33.88000,21.76277,282.34171,282.34171,2.01673,0.51816
33.92000,21.91346,282.67498,282.67496,2.01911,0.52175
33.96000,21.18554,283.00827,283.00830,2.02149,0.50442
34.00000,21.43960,283.34174,283.34174,2.02387,0.51047
34.04000,20.93222,283.67493,283.67493,2.02625,0.49839
34.08000,21.31183,284.00842,284.00842,2.02863,0.50742
34.12000,21.29078,284.34156,284.34155,2.03101,0.50692
34.16000,21.04547,284.67503,284.67502,2.03339,0.50108
34.20000,21.33474,285.00830,285.00830,2.03577,0.50797
34.24000,21.67411,285.34172,285.34171,2.03816,0.51605
34.28000,21.65213,285.67490,285.67490,2.04053,0.51553
34.32000,21.95630,286.00830,286.00827,2.04292,0.52277
34.36000,21.75476,286.34172,286.34174,2.04530,0.51797
34.40000,7.35912,286.67491,286.67493,2.04768,0.17522
34.42300,-0.16857,286.86665,286.86664,2.04905,-0.00401